5:return {{["x"] = 0, ["y"] = 7, ["z"] = 11, ["name"] = "default:wood"}, {["x"] = 1, ["y"] = 7, ["z"] = 11, ["name"] = "default:wood"}, {["x"] = 2, ["y"] = 7, ["z"] = 11, ["name"] = "default:wood"}, {["x"] = 3, ["y"] = 6, ["z"] = 11, ["name"] = "default:wood"}, {["x"] = 3, ["y"] = 7, ["z"] = 10, ["name"] = "default:wood"}, {["x"] = 3, ["y"] = 7, ["param1"] = 14, ["z"] = 11, ["name"] = "default:wood"}, {["x"] = 3, ["y"] = 7, ["z"] = 12, ["name"] = "default:wood"}, {["x"] = 3, ["y"] = 8, ["param1"] = 206, ["z"] = 10, ["name"] = "default:fence_wood"}, {["x"] = 3, ["y"] = 8, ["param1"] = 191, ["z"] = 11, ["name"] = "default:fence_wood"}, {["x"] = 3, ["y"] = 8, ["param1"] = 206, ["z"] = 12, ["name"] = "default:fence_wood"}, {["x"] = 3, ["param2"] = 1, ["y"] = 9, ["param1"] = 222, ["z"] = 10, ["name"] = "homedecor:glowlight_small_cube_on"}, {["x"] = 3, ["param2"] = 1, ["y"] = 9, ["param1"] = 222, ["z"] = 12, ["name"] = "homedecor:glowlight_small_cube_on"}, {["x"] = 4, ["y"] = 6, ["z"] = 11, ["name"] = "default:wood"}, {["x"] = 4, ["y"] = 7, ["z"] = 10, ["name"] = "default:wood"}, {["x"] = 4, ["y"] = 7, ["param1"] = 14, ["z"] = 11, ["name"] = "default:wood"}, {["x"] = 4, ["y"] = 7, ["z"] = 12, ["name"] = "default:wood"}, {["x"] = 4, ["y"] = 8, ["param1"] = 190, ["z"] = 10, ["name"] = "default:fence_wood"}, {["x"] = 4, ["meta"] = {["fields"] = {["station_name"] = "Air1 Station (North)", ["formspec"] = "size[12,10]label[3.3,0.0;Travelnet-Box:]label[6.3,0.0;Punch box to update target list.]label[0.3,0.4;Name of this station:]label[6.3,0.4;Air1 Station (North)]label[0.3,0.8;Assigned to Network:]label[6.3,0.8;Air1]label[0.3,1.2;Owned by:]label[6.3,1.2;mrg]label[3.3,1.6;Click on target to travel there:]button_exit[4,2.5;4,0.5;target;Air1 Station at Hub]button_exit[4,3.5;1,0.5;open_door;<>]label[4.9,3.35;Air1 Station (North)]", ["infotext"] = "Station 'Air1 Station (North)' on travelnet 'Air1' (owned by mrg) ready for usage. Right-click to travel, punch to update.", ["timestamp"] = "1493153030", ["station_network"] = "Air1", ["owner"] = "mrg"}, ["inventory"] = {}}, ["param2"] = 3, ["y"] = 8, ["param1"] = 174, ["z"] = 11, ["name"] = "travelnet:travelnet"}, {["x"] = 4, ["y"] = 8, ["param1"] = 190, ["z"] = 12, ["name"] = "default:fence_wood"}, {["x"] = 4, ["y"] = 23, ["param1"] = 15, ["z"] = 11, ["name"] = "wool:white"}, {["x"] = 4, ["y"] = 24, ["param1"] = 15, ["z"] = 10, ["name"] = "wool:white"}, {["x"] = 4, ["y"] = 24, ["param1"] = 15, ["z"] = 11, ["name"] = "wool:white"}, {["x"] = 4, ["y"] = 24, ["param1"] = 15, ["z"] = 12, ["name"] = "wool:white"}, {["x"] = 4, ["y"] = 25, ["param1"] = 15, ["z"] = 11, ["name"] = "wool:white"}, {["x"] = 5, ["y"] = 5, ["z"] = 11, ["name"] = "default:wood"}, {["x"] = 5, ["y"] = 6, ["z"] = 10, ["name"] = "default:wood"}, {["x"] = 5, ["y"] = 6, ["z"] = 12, ["name"] = "default:wood"}, {["x"] = 5, ["y"] = 7, ["z"] = 10, ["name"] = "default:wood"}, {["x"] = 5, ["y"] = 7, ["param1"] = 14, ["z"] = 11, ["name"] = "default:wood"}, {["x"] = 5, ["y"] = 7, ["z"] = 12, ["name"] = "default:wood"}, {["x"] = 5, ["y"] = 8, ["param1"] = 173, ["z"] = 10, ["name"] = "default:fence_wood"}, {["x"] = 5, ["y"] = 8, ["param1"] = 173, ["z"] = 12, ["name"] = "default:fence_wood"}, {["x"] = 5, ["y"] = 22, ["param1"] = 15, ["z"] = 10, ["name"] = "wool:white"}, {["x"] = 5, ["y"] = 22, ["param1"] = 15, ["z"] = 11, ["name"] = "wool:white"}, {["x"] = 5, ["y"] = 22, ["param1"] = 15, ["z"] = 12, ["name"] = "wool:white"}, {["x"] = 5, ["y"] = 23, ["param1"] = 15, ["z"] = 9, ["name"] = "wool:white"}, {["x"] = 5, ["y"] = 23, ["param1"] = 15, ["z"] = 10, ["name"] = "wool:white"}, {["x"] = 5, ["y"] = 23, ["param1"] = 15, ["z"] = 12, ["name"] = "wool:white"}, {["x"] = 5, ["y"] = 23, ["param1"] = 15, ["z"] = 13, ["name"] = "wool:white"}, {["x"] = 5, ["y"] = 24, ["param1"] = 15, ["z"] = 9, ["name"] = "wool:white"}, {["x"] = 5, ["y"] = 24, ["param1"] = 15, ["z"] = 13, ["name"] = "wool:white"}, {["x"] = 5, ["y"] = 25, ["param1"] = 15, ["z"] = 9, ["name"] = "wool:white"}, {["x"] = 5, ["y"] = 25, ["param1"] = 15, ["z"] = 10, ["name"] = "wool:white"}, {["x"] = 5, ["y"] = 25, ["param1"] = 15, ["z"] = 12, ["name"] = "wool:white"}, {["x"] = 5, ["y"] = 25, ["param1"] = 15, ["z"] = 13, ["name"] = "wool:white"}, {["x"] = 5, ["y"] = 26, ["param1"] = 15, ["z"] = 10, ["name"] = "wool:white"}, {["x"] = 5, ["y"] = 26, ["param1"] = 15, ["z"] = 11, ["name"] = "wool:white"}, {["x"] = 5, ["y"] = 26, ["param1"] = 15, ["z"] = 12, ["name"] = "wool:white"}, {["x"] = 6, ["y"] = 4, ["z"] = 11, ["name"] = "default:wood"}, {["x"] = 6, ["y"] = 5, ["z"] = 10, ["name"] = "default:wood"}, {["x"] = 6, ["meta"] = {["fields"] = {["owner"] = "thefox963", ["members"] = "yelby mrg", ["infotext"] = "Protection (owned by thefox963)"}, ["inventory"] = {}}, ["y"] = 5, ["param1"] = 68, ["z"] = 11, ["name"] = "protector:protect"}, {["x"] = 6, ["y"] = 5, ["z"] = 12, ["name"] = "default:wood"}, {["x"] = 6, ["y"] = 6, ["z"] = 10, ["name"] = "default:wood"}, {["x"] = 6, ["y"] = 6, ["z"] = 12, ["name"] = "default:wood"}, {["x"] = 6, ["param2"] = 2, ["y"] = 6, ["param1"] = 15, ["z"] = 19, ["name"] = "moreblocks:stair_wood"}, {["x"] = 6, ["y"] = 7, ["z"] = 10, ["name"] = "default:wood"}, {["x"] = 6, ["y"] = 7, ["param1"] = 14, ["z"] = 11, ["name"] = "default:wood"}, {["x"] = 6, ["y"] = 7, ["z"] = 12, ["name"] = "default:wood"}, {["x"] = 6, ["param2"] = 2, ["y"] = 7, ["param1"] = 31, ["z"] = 19, ["name"] = "moreblocks:stair_wood"}, {["x"] = 6, ["y"] = 8, ["param1"] = 157, ["z"] = 10, ["name"] = "default:fence_wood"}, {["x"] = 6, ["y"] = 8, ["param1"] = 157, ["z"] = 12, ["name"] = "default:fence_wood"}, {["x"] = 6, ["param2"] = 2, ["y"] = 8, ["param1"] = 47, ["z"] = 19, ["name"] = "moreblocks:stair_wood"}, {["x"] = 6, ["param2"] = 2, ["y"] = 9, ["param1"] = 63, ["z"] = 19, ["name"] = "moreblocks:stair_wood"}, {["x"] = 6, ["y"] = 18, ["param1"] = 15, ["z"] = 8, ["name"] = "default:fence_wood"}, {["x"] = 6, ["y"] = 18, ["param1"] = 15, ["z"] = 14, ["name"] = "default:fence_wood"}, {["x"] = 6, ["y"] = 19, ["param1"] = 15, ["z"] = 8, ["name"] = "default:fence_wood"}, {["x"] = 6, ["y"] = 19, ["param1"] = 15, ["z"] = 14, ["name"] = "default:fence_wood"}, {["x"] = 6, ["y"] = 20, ["param1"] = 15, ["z"] = 8, ["name"] = "default:fence_wood"}, {["x"] = 6, ["y"] = 20, ["param1"] = 15, ["z"] = 14, ["name"] = "default:fence_wood"}, {["x"] = 6, ["y"] = 21, ["param1"] = 15, ["z"] = 8, ["name"] = "default:fence_wood"}, {["x"] = 6, ["y"] = 21, ["param1"] = 14, ["z"] = 9, ["name"] = "default:fence_wood"}, {["x"] = 6, ["y"] = 21, ["param1"] = 13, ["z"] = 10, ["name"] = "default:fence_wood"}, {["x"] = 6, ["y"] = 21, ["param1"] = 12, ["z"] = 11, ["name"] = "default:fence_wood"}, {["x"] = 6, ["y"] = 21, ["param1"] = 13, ["z"] = 12, ["name"] = "default:fence_wood"}, {["x"] = 6, ["y"] = 21, ["param1"] = 14, ["z"] = 13, ["name"] = "default:fence_wood"}, {["x"] = 6, ["y"] = 21, ["param1"] = 15, ["z"] = 14, ["name"] = "default:fence_wood"}, {["x"] = 6, ["y"] = 22, ["param1"] = 15, ["z"] = 8, ["name"] = "default:fence_wood"}, {["x"] = 6, ["y"] = 22, ["param1"] = 15, ["z"] = 9, ["name"] = "wool:white"}, {["x"] = 6, ["y"] = 22, ["param1"] = 15, ["z"] = 10, ["name"] = "wool:white"}, {["x"] = 6, ["y"] = 22, ["param1"] = 15, ["z"] = 11, ["name"] = "wool:white"}, {["x"] = 6, ["y"] = 22, ["param1"] = 15, ["z"] = 12, ["name"] = "wool:white"}, {["x"] = 6, ["y"] = 22, ["param1"] = 15, ["z"] = 13, ["name"] = "wool:white"}, {["x"] = 6, ["y"] = 22, ["param1"] = 15, ["z"] = 14, ["name"] = "default:fence_wood"}, {["x"] = 6, ["y"] = 23, ["param1"] = 15, ["z"] = 8, ["name"] = "default:fence_wood"}, {["x"] = 6, ["y"] = 23, ["param1"] = 15, ["z"] = 9, ["name"] = "wool:white"}, {["x"] = 6, ["y"] = 23, ["param1"] = 15, ["z"] = 13, ["name"] = "wool:white"}, {["x"] = 6, ["y"] = 23, ["param1"] = 15, ["z"] = 14, ["name"] = "default:fence_wood"}, {["x"] = 6, ["y"] = 24, ["param1"] = 15, ["z"] = 8, ["name"] = "default:fence_wood"}, {["x"] = 6, ["y"] = 24, ["param1"] = 15, ["z"] = 9, ["name"] = "wool:white"}, {["x"] = 6, ["y"] = 24, ["param1"] = 15, ["z"] = 13, ["name"] = "wool:white"}, {["x"] = 6, ["y"] = 24, ["param1"] = 15, ["z"] = 14, ["name"] = "default:fence_wood"}, {["x"] = 6, ["y"] = 25, ["param1"] = 15, ["z"] = 8, ["name"] = "default:fence_wood"}, {["x"] = 6, ["y"] = 25, ["param1"] = 15, ["z"] = 9, ["name"] = "wool:white"}, {["x"] = 6, ["y"] = 25, ["param1"] = 15, ["z"] = 13, ["name"] = "wool:white"}, {["x"] = 6, ["y"] = 25, ["param1"] = 15, ["z"] = 14, ["name"] = "default:fence_wood"}, {["x"] = 6, ["y"] = 26, ["param1"] = 15, ["z"] = 8, ["name"] = "default:fence_wood"}, {["x"] = 6, ["y"] = 26, ["param1"] = 15, ["z"] = 9, ["name"] = "wool:white"}, {["x"] = 6, ["y"] = 26, ["param1"] = 15, ["z"] = 10, ["name"] = "wool:white"}, {["x"] = 6, ["y"] = 26, ["param1"] = 15, ["z"] = 11, ["name"] = "wool:white"}, {["x"] = 6, ["y"] = 26, ["param1"] = 15, ["z"] = 12, ["name"] = "wool:white"}, {["x"] = 6, ["y"] = 26, ["param1"] = 15, ["z"] = 13, ["name"] = "wool:white"}, {["x"] = 6, ["y"] = 26, ["param1"] = 15, ["z"] = 14, ["name"] = "default:fence_wood"}, {["x"] = 6, ["y"] = 27, ["param1"] = 15, ["z"] = 8, ["name"] = "default:fence_wood"}, {["x"] = 6, ["y"] = 27, ["param1"] = 15, ["z"] = 9, ["name"] = "default:fence_wood"}, {["x"] = 6, ["y"] = 27, ["param1"] = 15, ["z"] = 10, ["name"] = "default:fence_wood"}, {["x"] = 6, ["y"] = 27, ["param1"] = 15, ["z"] = 11, ["name"] = "default:fence_wood"}, {["x"] = 6, ["y"] = 27, ["param1"] = 15, ["z"] = 12, ["name"] = "default:fence_wood"}, {["x"] = 6, ["y"] = 27, ["param1"] = 15, ["z"] = 13, ["name"] = "default:fence_wood"}, {["x"] = 6, ["y"] = 27, ["param1"] = 15, ["z"] = 14, ["name"] = "default:fence_wood"}, {["x"] = 7, ["y"] = 3, ["z"] = 11, ["name"] = "default:wood"}, {["x"] = 7, ["y"] = 4, ["z"] = 10, ["name"] = "default:wood"}, {["x"] = 7, ["y"] = 4, ["z"] = 12, ["name"] = "default:wood"}, {["x"] = 7, ["y"] = 5, ["z"] = 9, ["name"] = "default:wood"}, {["x"] = 7, ["y"] = 5, ["z"] = 13, ["name"] = "default:wood"}, {["x"] = 7, ["y"] = 6, ["z"] = 9, ["name"] = "default:wood"}, {["x"] = 7, ["y"] = 6, ["z"] = 13, ["name"] = "default:wood"}, {["x"] = 7, ["y"] = 7, ["z"] = 9, ["name"] = "default:wood"}, {["x"] = 7, ["y"] = 7, ["param1"] = 14, ["z"] = 10, ["name"] = "default:wood"}, {["x"] = 7, ["y"] = 7, ["param1"] = 14, ["z"] = 11, ["name"] = "default:wood"}, {["x"] = 7, ["y"] = 7, ["param1"] = 14, ["z"] = 12, ["name"] = "default:wood"}, {["x"] = 7, ["y"] = 7, ["z"] = 13, ["name"] = "default:wood"}, {["x"] = 7, ["y"] = 8, ["param1"] = 125, ["z"] = 9, ["name"] = "default:fence_wood"}, {["x"] = 7, ["y"] = 8, ["param1"] = 140, ["z"] = 10, ["name"] = "default:fence_wood"}, {["x"] = 7, ["y"] = 8, ["param1"] = 140, ["z"] = 12, ["name"] = "default:fence_wood"}, {["x"] = 7, ["y"] = 8, ["param1"] = 125, ["z"] = 13, ["name"] = "default:fence_wood"}, {["x"] = 7, ["y"] = 9, ["param1"] = 141, ["z"] = 9, ["name"] = "default:fence_wood"}, {["x"] = 7, ["y"] = 9, ["param1"] = 141, ["z"] = 13, ["name"] = "default:fence_wood"}, {["x"] = 7, ["y"] = 10, ["param1"] = 125, ["z"] = 9, ["name"] = "default:fence_wood"}, {["x"] = 7, ["y"] = 10, ["param1"] = 125, ["z"] = 13, ["name"] = "default:fence_wood"}, {["x"] = 7, ["y"] = 11, ["param1"] = 109, ["z"] = 9, ["name"] = "default:fence_wood"}, {["x"] = 7, ["y"] = 11, ["param1"] = 109, ["z"] = 13, ["name"] = "default:fence_wood"}, {["x"] = 7, ["y"] = 12, ["param1"] = 93, ["z"] = 9, ["name"] = "default:fence_wood"}, {["x"] = 7, ["y"] = 12, ["param1"] = 93, ["z"] = 13, ["name"] = "default:fence_wood"}, {["x"] = 7, ["y"] = 13, ["param1"] = 62, ["z"] = 8, ["name"] = "default:fence_wood"}, {["x"] = 7, ["y"] = 13, ["param1"] = 77, ["z"] = 9, ["name"] = "default:fence_wood"}, {["x"] = 7, ["y"] = 13, ["param1"] = 77, ["z"] = 13, ["name"] = "default:fence_wood"}, {["x"] = 7, ["y"] = 13, ["param1"] = 62, ["z"] = 14, ["name"] = "default:fence_wood"}, {["x"] = 7, ["y"] = 14, ["param1"] = 46, ["z"] = 8, ["name"] = "default:fence_wood"}, {["x"] = 7, ["y"] = 14, ["param1"] = 46, ["z"] = 14, ["name"] = "default:fence_wood"}, {["x"] = 7, ["y"] = 15, ["param1"] = 30, ["z"] = 8, ["name"] = "default:fence_wood"}, {["x"] = 7, ["y"] = 15, ["param1"] = 30, ["z"] = 14, ["name"] = "default:fence_wood"}, {["x"] = 7, ["y"] = 16, ["param1"] = 14, ["z"] = 8, ["name"] = "default:fence_wood"}, {["x"] = 7, ["y"] = 16, ["param1"] = 14, ["z"] = 14, ["name"] = "default:fence_wood"}, {["x"] = 7, ["y"] = 17, ["param1"] = 14, ["z"] = 8, ["name"] = "default:fence_wood"}, {["x"] = 7, ["y"] = 17, ["param1"] = 14, ["z"] = 14, ["name"] = "default:fence_wood"}, {["x"] = 7, ["y"] = 18, ["param1"] = 14, ["z"] = 8, ["name"] = "default:fence_wood"}, {["x"] = 7, ["y"] = 18, ["param1"] = 14, ["z"] = 14, ["name"] = "default:fence_wood"}, {["x"] = 7, ["y"] = 21, ["param1"] = 15, ["z"] = 10, ["name"] = "wool:white"}, {["x"] = 7, ["y"] = 21, ["param1"] = 15, ["z"] = 11, ["name"] = "wool:white"}, {["x"] = 7, ["y"] = 21, ["param1"] = 15, ["z"] = 12, ["name"] = "wool:white"}, {["x"] = 7, ["y"] = 22, ["param1"] = 15, ["z"] = 9, ["name"] = "wool:white"}, {["x"] = 7, ["y"] = 22, ["param1"] = 15, ["z"] = 13, ["name"] = "wool:white"}, {["x"] = 7, ["y"] = 23, ["param1"] = 15, ["z"] = 8, ["name"] = "wool:white"}, {["x"] = 7, ["y"] = 23, ["param1"] = 15, ["z"] = 14, ["name"] = "wool:white"}, {["x"] = 7, ["y"] = 24, ["param1"] = 15, ["z"] = 8, ["name"] = "wool:white"}, {["x"] = 7, ["y"] = 24, ["param1"] = 15, ["z"] = 14, ["name"] = "wool:white"}, {["x"] = 7, ["y"] = 25, ["param1"] = 15, ["z"] = 8, ["name"] = "wool:white"}, {["x"] = 7, ["y"] = 25, ["param1"] = 15, ["z"] = 14, ["name"] = "wool:white"}, {["x"] = 7, ["y"] = 26, ["param1"] = 15, ["z"] = 9, ["name"] = "wool:white"}, {["x"] = 7, ["y"] = 26, ["param1"] = 15, ["z"] = 13, ["name"] = "wool:white"}, {["x"] = 7, ["y"] = 27, ["param1"] = 15, ["z"] = 10, ["name"] = "wool:white"}, {["x"] = 7, ["y"] = 27, ["param1"] = 15, ["z"] = 11, ["name"] = "wool:white"}, {["x"] = 7, ["y"] = 27, ["param1"] = 15, ["z"] = 12, ["name"] = "wool:white"}, {["x"] = 8, ["y"] = 3, ["z"] = 11, ["name"] = "default:wood"}, {["x"] = 8, ["y"] = 4, ["z"] = 10, ["name"] = "default:wood"}, {["x"] = 8, ["y"] = 4, ["z"] = 12, ["name"] = "default:wood"}, {["x"] = 8, ["y"] = 5, ["z"] = 9, ["name"] = "default:wood"}, {["x"] = 8, ["y"] = 5, ["z"] = 13, ["name"] = "default:wood"}, {["x"] = 8, ["y"] = 6, ["z"] = 9, ["name"] = "default:wood"}, {["x"] = 8, ["y"] = 6, ["z"] = 13, ["name"] = "default:wood"}, {["x"] = 8, ["y"] = 7, ["z"] = 9, ["name"] = "default:wood"}, {["x"] = 8, ["y"] = 7, ["param1"] = 14, ["z"] = 10, ["name"] = "default:wood"}, {["x"] = 8, ["y"] = 7, ["param1"] = 14, ["z"] = 11, ["name"] = "default:wood"}, {["x"] = 8, ["y"] = 7, ["param1"] = 14, ["z"] = 12, ["name"] = "default:wood"}, {["x"] = 8, ["y"] = 7, ["z"] = 13, ["name"] = "default:wood"}, {["x"] = 8, ["y"] = 8, ["param1"] = 109, ["z"] = 9, ["name"] = "default:fence_wood"}, {["x"] = 8, ["y"] = 8, ["param1"] = 109, ["z"] = 13, ["name"] = "default:fence_wood"}, {["x"] = 8, ["y"] = 21, ["param1"] = 15, ["z"] = 9, ["name"] = "wool:white"}, {["x"] = 8, ["y"] = 21, ["param1"] = 15, ["z"] = 10, ["name"] = "wool:white"}, {["x"] = 8, ["y"] = 21, ["param1"] = 15, ["z"] = 11, ["name"] = "wool:white"}, {["x"] = 8, ["y"] = 21, ["param1"] = 15, ["z"] = 12, ["name"] = "wool:white"}, {["x"] = 8, ["y"] = 21, ["z"] = 13, ["name"] = "wool:white"}, {["x"] = 8, ["y"] = 22, ["param1"] = 15, ["z"] = 8, ["name"] = "wool:white"}, {["x"] = 8, ["y"] = 22, ["param1"] = 15, ["z"] = 14, ["name"] = "wool:white"}, {["x"] = 8, ["y"] = 23, ["param1"] = 15, ["z"] = 8, ["name"] = "wool:white"}, {["x"] = 8, ["y"] = 23, ["param1"] = 15, ["z"] = 14, ["name"] = "wool:white"}, {["x"] = 8, ["y"] = 24, ["param1"] = 15, ["z"] = 8, ["name"] = "wool:white"}, {["x"] = 8, ["y"] = 24, ["param1"] = 221, ["z"] = 11, ["name"] = "caverealms:glow_crystal"}, {["x"] = 8, ["y"] = 24, ["param1"] = 15, ["z"] = 14, ["name"] = "wool:white"}, {["x"] = 8, ["y"] = 25, ["param1"] = 15, ["z"] = 8, ["name"] = "wool:white"}, {["x"] = 8, ["y"] = 25, ["param1"] = 15, ["z"] = 14, ["name"] = "wool:white"}, {["x"] = 8, ["y"] = 26, ["param1"] = 15, ["z"] = 8, ["name"] = "wool:white"}, {["x"] = 8, ["y"] = 26, ["param1"] = 15, ["z"] = 14, ["name"] = "wool:white"}, {["x"] = 8, ["y"] = 27, ["param1"] = 15, ["z"] = 9, ["name"] = "wool:white"}, {["x"] = 8, ["y"] = 27, ["param1"] = 15, ["z"] = 10, ["name"] = "wool:white"}, {["x"] = 8, ["y"] = 27, ["param1"] = 15, ["z"] = 11, ["name"] = "wool:white"}, {["x"] = 8, ["y"] = 27, ["param1"] = 15, ["z"] = 12, ["name"] = "wool:white"}, {["x"] = 8, ["y"] = 27, ["param1"] = 15, ["z"] = 13, ["name"] = "wool:white"}, {["x"] = 9, ["y"] = 2, ["z"] = 11, ["name"] = "default:wood"}, {["x"] = 9, ["y"] = 3, ["z"] = 10, ["name"] = "default:wood"}, {["x"] = 9, ["y"] = 3, ["z"] = 12, ["name"] = "default:wood"}, {["x"] = 9, ["y"] = 4, ["z"] = 10, ["name"] = "default:wood"}, {["x"] = 9, ["y"] = 4, ["z"] = 12, ["name"] = "default:wood"}, {["x"] = 9, ["y"] = 5, ["z"] = 9, ["name"] = "default:wood"}, {["x"] = 9, ["y"] = 5, ["z"] = 13, ["name"] = "default:wood"}, {["x"] = 9, ["y"] = 6, ["z"] = 9, ["name"] = "default:wood"}, {["x"] = 9, ["y"] = 6, ["z"] = 13, ["name"] = "default:wood"}, {["x"] = 9, ["y"] = 7, ["z"] = 9, ["name"] = "default:wood"}, {["x"] = 9, ["y"] = 7, ["param1"] = 14, ["z"] = 10, ["name"] = "default:wood"}, {["x"] = 9, ["y"] = 7, ["param1"] = 14, ["z"] = 11, ["name"] = "default:wood"}, {["x"] = 9, ["y"] = 7, ["param1"] = 14, ["z"] = 12, ["name"] = "default:wood"}, {["x"] = 9, ["y"] = 7, ["z"] = 13, ["name"] = "default:wood"}, {["x"] = 9, ["y"] = 8, ["param1"] = 92, ["z"] = 9, ["name"] = "default:fence_wood"}, {["x"] = 9, ["y"] = 8, ["param1"] = 92, ["z"] = 13, ["name"] = "default:fence_wood"}, {["x"] = 9, ["y"] = 20, ["param1"] = 15, ["z"] = 10, ["name"] = "wool:white"}, {["x"] = 9, ["y"] = 20, ["param1"] = 15, ["z"] = 11, ["name"] = "wool:white"}, {["x"] = 9, ["y"] = 20, ["param1"] = 15, ["z"] = 12, ["name"] = "wool:white"}, {["x"] = 9, ["y"] = 21, ["param1"] = 15, ["z"] = 9, ["name"] = "wool:white"}, {["x"] = 9, ["y"] = 21, ["param1"] = 15, ["z"] = 13, ["name"] = "wool:white"}, {["x"] = 9, ["y"] = 22, ["param1"] = 15, ["z"] = 8, ["name"] = "wool:white"}, {["x"] = 9, ["y"] = 22, ["param1"] = 15, ["z"] = 14, ["name"] = "wool:white"}, {["x"] = 9, ["y"] = 23, ["param1"] = 15, ["z"] = 7, ["name"] = "wool:white"}, {["x"] = 9, ["y"] = 23, ["param1"] = 15, ["z"] = 15, ["name"] = "wool:white"}, {["x"] = 9, ["y"] = 24, ["param1"] = 15, ["z"] = 7, ["name"] = "wool:white"}, {["x"] = 9, ["y"] = 24, ["param1"] = 221, ["z"] = 11, ["name"] = "caverealms:glow_crystal"}, {["x"] = 9, ["y"] = 24, ["param1"] = 15, ["z"] = 15, ["name"] = "wool:white"}, {["x"] = 9, ["y"] = 25, ["param1"] = 15, ["z"] = 7, ["name"] = "wool:white"}, {["x"] = 9, ["y"] = 25, ["param1"] = 15, ["z"] = 15, ["name"] = "wool:white"}, {["x"] = 9, ["y"] = 26, ["param1"] = 15, ["z"] = 8, ["name"] = "wool:white"}, {["x"] = 9, ["y"] = 26, ["param1"] = 15, ["z"] = 14, ["name"] = "wool:white"}, {["x"] = 9, ["y"] = 27, ["param1"] = 15, ["z"] = 9, ["name"] = "wool:white"}, {["x"] = 9, ["y"] = 27, ["param1"] = 15, ["z"] = 13, ["name"] = "wool:white"}, {["x"] = 9, ["y"] = 28, ["param1"] = 15, ["z"] = 10, ["name"] = "wool:white"}, {["x"] = 9, ["y"] = 28, ["param1"] = 15, ["z"] = 11, ["name"] = "wool:white"}, {["x"] = 9, ["y"] = 28, ["param1"] = 15, ["z"] = 12, ["name"] = "wool:white"}, {["x"] = 10, ["y"] = 2, ["z"] = 11, ["name"] = "default:wood"}, {["x"] = 10, ["y"] = 3, ["z"] = 10, ["name"] = "default:wood"}, {["x"] = 10, ["y"] = 3, ["z"] = 12, ["name"] = "default:wood"}, {["x"] = 10, ["y"] = 4, ["z"] = 10, ["name"] = "default:wood"}, {["x"] = 10, ["y"] = 4, ["z"] = 12, ["name"] = "default:wood"}, {["x"] = 10, ["y"] = 5, ["z"] = 9, ["name"] = "default:wood"}, {["x"] = 10, ["y"] = 5, ["z"] = 13, ["name"] = "default:wood"}, {["x"] = 10, ["y"] = 6, ["z"] = 9, ["name"] = "default:wood"}, {["x"] = 10, ["y"] = 6, ["z"] = 13, ["name"] = "default:wood"}, {["x"] = 10, ["y"] = 7, ["z"] = 9, ["name"] = "default:wood"}, {["x"] = 10, ["y"] = 7, ["param1"] = 14, ["z"] = 10, ["name"] = "default:wood"}, {["x"] = 10, ["y"] = 7, ["param1"] = 14, ["z"] = 11, ["name"] = "default:wood"}, {["x"] = 10, ["y"] = 7, ["param1"] = 14, ["z"] = 12, ["name"] = "default:wood"}, {["x"] = 10, ["y"] = 7, ["z"] = 13, ["name"] = "default:wood"}, {["x"] = 10, ["y"] = 8, ["param1"] = 92, ["z"] = 9, ["name"] = "default:fence_wood"}, {["x"] = 10, ["y"] = 8, ["param1"] = 92, ["z"] = 13, ["name"] = "default:fence_wood"}, {["x"] = 10, ["y"] = 20, ["param1"] = 15, ["z"] = 10, ["name"] = "wool:white"}, {["x"] = 10, ["y"] = 20, ["param1"] = 15, ["z"] = 11, ["name"] = "wool:white"}, {["x"] = 10, ["y"] = 20, ["param1"] = 15, ["z"] = 12, ["name"] = "wool:white"}, {["x"] = 10, ["y"] = 21, ["param1"] = 15, ["z"] = 8, ["name"] = "wool:white"}, {["x"] = 10, ["y"] = 21, ["param1"] = 15, ["z"] = 9, ["name"] = "wool:white"}, {["x"] = 10, ["y"] = 21, ["param1"] = 15, ["z"] = 13, ["name"] = "wool:white"}, {["x"] = 10, ["y"] = 21, ["param1"] = 15, ["z"] = 14, ["name"] = "wool:white"}, {["x"] = 10, ["y"] = 22, ["param1"] = 15, ["z"] = 8, ["name"] = "wool:white"}, {["x"] = 10, ["y"] = 22, ["param1"] = 15, ["z"] = 14, ["name"] = "wool:white"}, {["x"] = 10, ["y"] = 23, ["param1"] = 15, ["z"] = 7, ["name"] = "wool:white"}, {["x"] = 10, ["y"] = 23, ["param1"] = 15, ["z"] = 15, ["name"] = "wool:white"}, {["x"] = 10, ["y"] = 24, ["param1"] = 15, ["z"] = 7, ["name"] = "wool:white"}, {["x"] = 10, ["y"] = 24, ["param1"] = 221, ["z"] = 11, ["name"] = "caverealms:glow_crystal"}, {["x"] = 10, ["y"] = 24, ["param1"] = 15, ["z"] = 15, ["name"] = "wool:white"}, {["x"] = 10, ["y"] = 25, ["param1"] = 15, ["z"] = 7, ["name"] = "wool:white"}, {["x"] = 10, ["y"] = 25, ["param1"] = 15, ["z"] = 15, ["name"] = "wool:white"}, {["x"] = 10, ["y"] = 26, ["param1"] = 15, ["z"] = 8, ["name"] = "wool:white"}, {["x"] = 10, ["y"] = 26, ["param1"] = 15, ["z"] = 14, ["name"] = "wool:white"}, {["x"] = 10, ["y"] = 27, ["param1"] = 15, ["z"] = 8, ["name"] = "wool:white"}, {["x"] = 10, ["y"] = 27, ["param1"] = 15, ["z"] = 9, ["name"] = "wool:white"}, {["x"] = 10, ["y"] = 27, ["param1"] = 15, ["z"] = 13, ["name"] = "wool:white"}, {["x"] = 10, ["y"] = 27, ["param1"] = 15, ["z"] = 14, ["name"] = "wool:white"}, {["x"] = 10, ["y"] = 28, ["param1"] = 15, ["z"] = 10, ["name"] = "wool:white"}, {["x"] = 10, ["y"] = 28, ["param1"] = 15, ["z"] = 11, ["name"] = "wool:white"}, {["x"] = 10, ["y"] = 28, ["param1"] = 15, ["z"] = 12, ["name"] = "wool:white"}, {["x"] = 11, ["y"] = 1, ["z"] = 11, ["name"] = "default:wood"}, {["x"] = 11, ["y"] = 2, ["z"] = 10, ["name"] = "default:wood"}, {["x"] = 11, ["y"] = 2, ["z"] = 11, ["name"] = "default:wood"}, {["x"] = 11, ["y"] = 2, ["z"] = 12, ["name"] = "default:wood"}, {["x"] = 11, ["y"] = 3, ["z"] = 9, ["name"] = "default:wood"}, {["x"] = 11, ["y"] = 3, ["z"] = 13, ["name"] = "default:wood"}, {["x"] = 11, ["y"] = 4, ["z"] = 9, ["name"] = "default:wood"}, {["x"] = 11, ["y"] = 4, ["z"] = 13, ["name"] = "default:wood"}, {["x"] = 11, ["y"] = 5, ["z"] = 8, ["name"] = "default:wood"}, {["x"] = 11, ["y"] = 5, ["z"] = 14, ["name"] = "default:wood"}, {["x"] = 11, ["y"] = 6, ["z"] = 8, ["name"] = "default:wood"}, {["x"] = 11, ["y"] = 6, ["z"] = 14, ["name"] = "default:wood"}, {["x"] = 11, ["y"] = 7, ["z"] = 8, ["name"] = "default:wood"}, {["x"] = 11, ["y"] = 7, ["param1"] = 14, ["z"] = 9, ["name"] = "default:wood"}, {["x"] = 11, ["y"] = 7, ["param1"] = 14, ["z"] = 10, ["name"] = "default:wood"}, {["x"] = 11, ["y"] = 7, ["param1"] = 14, ["z"] = 11, ["name"] = "default:wood"}, {["x"] = 11, ["y"] = 7, ["param1"] = 14, ["z"] = 12, ["name"] = "default:wood"}, {["x"] = 11, ["y"] = 7, ["param1"] = 14, ["z"] = 13, ["name"] = "default:wood"}, {["x"] = 11, ["y"] = 7, ["z"] = 14, ["name"] = "default:wood"}, {["x"] = 11, ["y"] = 8, ["param1"] = 125, ["z"] = 8, ["name"] = "default:fence_wood"}, {["x"] = 11, ["y"] = 8, ["param1"] = 108, ["z"] = 9, ["name"] = "default:fence_wood"}, {["x"] = 11, ["y"] = 8, ["param1"] = 108, ["z"] = 13, ["name"] = "default:fence_wood"}, {["x"] = 11, ["y"] = 8, ["param1"] = 125, ["z"] = 14, ["name"] = "default:fence_wood"}, {["x"] = 11, ["y"] = 20, ["param1"] = 15, ["z"] = 9, ["name"] = "wool:white"}, {["x"] = 11, ["y"] = 20, ["param1"] = 15, ["z"] = 10, ["name"] = "wool:white"}, {["x"] = 11, ["y"] = 20, ["param1"] = 15, ["z"] = 11, ["name"] = "wool:white"}, {["x"] = 11, ["y"] = 20, ["param1"] = 15, ["z"] = 12, ["name"] = "wool:white"}, {["x"] = 11, ["y"] = 20, ["param1"] = 15, ["z"] = 13, ["name"] = "wool:white"}, {["x"] = 11, ["y"] = 21, ["param1"] = 15, ["z"] = 8, ["name"] = "wool:white"}, {["x"] = 11, ["y"] = 21, ["param1"] = 15, ["z"] = 14, ["name"] = "wool:white"}, {["x"] = 11, ["y"] = 22, ["param1"] = 15, ["z"] = 7, ["name"] = "wool:white"}, {["x"] = 11, ["y"] = 22, ["param1"] = 15, ["z"] = 15, ["name"] = "wool:white"}, {["x"] = 11, ["y"] = 23, ["param1"] = 15, ["z"] = 7, ["name"] = "wool:white"}, {["x"] = 11, ["y"] = 23, ["param1"] = 15, ["z"] = 15, ["name"] = "wool:white"}, {["x"] = 11, ["y"] = 24, ["param1"] = 15, ["z"] = 7, ["name"] = "wool:white"}, {["x"] = 11, ["meta"] = {["fields"] = {["infotext"] = "Protection (owned by thefox963)", ["members"] = "yelby mrg", ["owner"] = "thefox963"}, ["inventory"] = {}}, ["y"] = 24, ["param1"] = 204, ["z"] = 11, ["name"] = "protector:protect"}, {["x"] = 11, ["y"] = 24, ["param1"] = 15, ["z"] = 15, ["name"] = "wool:white"}, {["x"] = 11, ["y"] = 25, ["param1"] = 15, ["z"] = 7, ["name"] = "wool:white"}, {["x"] = 11, ["y"] = 25, ["param1"] = 15, ["z"] = 15, ["name"] = "wool:white"}, {["x"] = 11, ["y"] = 26, ["param1"] = 15, ["z"] = 7, ["name"] = "wool:white"}, {["x"] = 11, ["y"] = 26, ["param1"] = 15, ["z"] = 15, ["name"] = "wool:white"}, {["x"] = 11, ["y"] = 27, ["param1"] = 15, ["z"] = 8, ["name"] = "wool:white"}, {["x"] = 11, ["y"] = 27, ["param1"] = 15, ["z"] = 14, ["name"] = "wool:white"}, {["x"] = 11, ["y"] = 28, ["param1"] = 15, ["z"] = 9, ["name"] = "wool:white"}, {["x"] = 11, ["y"] = 28, ["param1"] = 15, ["z"] = 10, ["name"] = "wool:white"}, {["x"] = 11, ["y"] = 28, ["param1"] = 15, ["z"] = 11, ["name"] = "wool:white"}, {["x"] = 11, ["y"] = 28, ["param1"] = 15, ["z"] = 12, ["name"] = "wool:white"}, {["x"] = 11, ["y"] = 28, ["param1"] = 15, ["z"] = 13, ["name"] = "wool:white"}, {["x"] = 12, ["y"] = 1, ["z"] = 11, ["name"] = "default:wood"}, {["x"] = 12, ["y"] = 2, ["z"] = 10, ["name"] = "default:wood"}, {["x"] = 12, ["y"] = 2, ["z"] = 12, ["name"] = "default:wood"}, {["x"] = 12, ["y"] = 3, ["z"] = 9, ["name"] = "default:wood"}, {["x"] = 12, ["y"] = 3, ["z"] = 13, ["name"] = "default:wood"}, {["x"] = 12, ["y"] = 4, ["z"] = 9, ["name"] = "default:wood"}, {["x"] = 12, ["y"] = 4, ["z"] = 13, ["name"] = "default:wood"}, {["x"] = 12, ["y"] = 5, ["z"] = 8, ["name"] = "default:wood"}, {["x"] = 12, ["y"] = 5, ["z"] = 14, ["name"] = "default:wood"}, {["x"] = 12, ["y"] = 6, ["z"] = 8, ["name"] = "default:wood"}, {["x"] = 12, ["y"] = 6, ["z"] = 14, ["name"] = "default:wood"}, {["x"] = 12, ["y"] = 7, ["z"] = 8, ["name"] = "default:wood"}, {["x"] = 12, ["y"] = 7, ["param1"] = 14, ["z"] = 9, ["name"] = "default:wood"}, {["x"] = 12, ["y"] = 7, ["param1"] = 14, ["z"] = 10, ["name"] = "default:wood"}, {["x"] = 12, ["y"] = 7, ["param1"] = 14, ["z"] = 11, ["name"] = "default:wood"}, {["x"] = 12, ["y"] = 7, ["param1"] = 14, ["z"] = 12, ["name"] = "default:wood"}, {["x"] = 12, ["y"] = 7, ["param1"] = 14, ["z"] = 13, ["name"] = "default:wood"}, {["x"] = 12, ["y"] = 7, ["z"] = 14, ["name"] = "default:wood"}, {["x"] = 12, ["y"] = 8, ["param1"] = 141, ["z"] = 8, ["name"] = "default:fence_wood"}, {["x"] = 12, ["y"] = 8, ["param1"] = 141, ["z"] = 14, ["name"] = "default:fence_wood"}, {["x"] = 12, ["y"] = 20, ["param1"] = 15, ["z"] = 9, ["name"] = "wool:white"}, {["x"] = 12, ["y"] = 20, ["param1"] = 15, ["z"] = 10, ["name"] = "wool:white"}, {["x"] = 12, ["y"] = 20, ["param1"] = 15, ["z"] = 11, ["name"] = "wool:white"}, {["x"] = 12, ["y"] = 20, ["param1"] = 15, ["z"] = 12, ["name"] = "wool:white"}, {["x"] = 12, ["y"] = 20, ["param1"] = 15, ["z"] = 13, ["name"] = "wool:white"}, {["x"] = 12, ["y"] = 21, ["param1"] = 15, ["z"] = 8, ["name"] = "wool:white"}, {["x"] = 12, ["y"] = 21, ["param1"] = 15, ["z"] = 14, ["name"] = "wool:white"}, {["x"] = 12, ["y"] = 22, ["param1"] = 15, ["z"] = 7, ["name"] = "wool:white"}, {["x"] = 12, ["y"] = 22, ["param1"] = 15, ["z"] = 15, ["name"] = "wool:white"}, {["x"] = 12, ["y"] = 23, ["param1"] = 15, ["z"] = 7, ["name"] = "wool:white"}, {["x"] = 12, ["y"] = 23, ["param1"] = 15, ["z"] = 15, ["name"] = "wool:white"}, {["x"] = 12, ["y"] = 24, ["z"] = 7, ["name"] = "wool:white"}, {["x"] = 12, ["y"] = 24, ["param1"] = 221, ["z"] = 11, ["name"] = "caverealms:glow_crystal"}, {["x"] = 12, ["y"] = 24, ["param1"] = 15, ["z"] = 15, ["name"] = "wool:white"}, {["x"] = 12, ["y"] = 25, ["param1"] = 15, ["z"] = 7, ["name"] = "wool:white"}, {["x"] = 12, ["y"] = 25, ["param1"] = 15, ["z"] = 15, ["name"] = "wool:white"}, {["x"] = 12, ["y"] = 26, ["param1"] = 15, ["z"] = 7, ["name"] = "wool:white"}, {["x"] = 12, ["y"] = 26, ["param1"] = 15, ["z"] = 15, ["name"] = "wool:white"}, {["x"] = 12, ["y"] = 27, ["param1"] = 15, ["z"] = 8, ["name"] = "wool:white"}, {["x"] = 12, ["y"] = 27, ["param1"] = 15, ["z"] = 14, ["name"] = "wool:white"}, {["x"] = 12, ["y"] = 28, ["param1"] = 15, ["z"] = 9, ["name"] = "wool:white"}, {["x"] = 12, ["y"] = 28, ["param1"] = 15, ["z"] = 10, ["name"] = "wool:white"}, {["x"] = 12, ["y"] = 28, ["param1"] = 15, ["z"] = 11, ["name"] = "wool:white"}, {["x"] = 12, ["y"] = 28, ["param1"] = 15, ["z"] = 12, ["name"] = "wool:white"}, {["x"] = 12, ["y"] = 28, ["param1"] = 15, ["z"] = 13, ["name"] = "wool:white"}, {["x"] = 13, ["y"] = 0, ["z"] = 11, ["name"] = "default:wood"}, {["x"] = 13, ["y"] = 1, ["z"] = 10, ["name"] = "default:wood"}, {["x"] = 13, ["y"] = 1, ["z"] = 12, ["name"] = "default:wood"}, {["x"] = 13, ["y"] = 2, ["z"] = 9, ["name"] = "default:wood"}, {["x"] = 13, ["y"] = 2, ["z"] = 13, ["name"] = "default:wood"}, {["x"] = 13, ["y"] = 3, ["z"] = 8, ["name"] = "default:wood"}, {["x"] = 13, ["y"] = 3, ["z"] = 14, ["name"] = "default:wood"}, {["x"] = 13, ["y"] = 4, ["z"] = 8, ["name"] = "default:wood"}, {["x"] = 13, ["y"] = 4, ["z"] = 14, ["name"] = "default:wood"}, {["x"] = 13, ["y"] = 5, ["z"] = 7, ["name"] = "default:wood"}, {["x"] = 13, ["y"] = 5, ["z"] = 15, ["name"] = "default:wood"}, {["x"] = 13, ["y"] = 6, ["z"] = 7, ["name"] = "default:wood"}, {["x"] = 13, ["y"] = 6, ["z"] = 15, ["name"] = "default:wood"}, {["x"] = 13, ["y"] = 7, ["z"] = 7, ["name"] = "default:wood"}, {["x"] = 13, ["y"] = 7, ["param1"] = 14, ["z"] = 8, ["name"] = "default:wood"}, {["x"] = 13, ["y"] = 7, ["param1"] = 14, ["z"] = 9, ["name"] = "default:wood"}, {["x"] = 13, ["y"] = 7, ["param1"] = 14, ["z"] = 10, ["name"] = "default:wood"}, {["x"] = 13, ["y"] = 7, ["param1"] = 14, ["z"] = 11, ["name"] = "default:wood"}, {["x"] = 13, ["y"] = 7, ["param1"] = 14, ["z"] = 12, ["name"] = "default:wood"}, {["x"] = 13, ["y"] = 7, ["param1"] = 14, ["z"] = 13, ["name"] = "default:wood"}, {["x"] = 13, ["y"] = 7, ["param1"] = 14, ["z"] = 14, ["name"] = "default:wood"}, {["x"] = 13, ["y"] = 7, ["z"] = 15, ["name"] = "default:wood"}, {["x"] = 13, ["y"] = 8, ["param1"] = 173, ["z"] = 7, ["name"] = "default:fence_wood"}, {["x"] = 13, ["y"] = 8, ["param1"] = 156, ["z"] = 8, ["name"] = "default:fence_wood"}, {["x"] = 13, ["y"] = 8, ["param1"] = 156, ["z"] = 14, ["name"] = "default:fence_wood"}, {["x"] = 13, ["y"] = 8, ["param1"] = 173, ["z"] = 15, ["name"] = "default:fence_wood"}, {["x"] = 13, ["y"] = 19, ["param1"] = 15, ["z"] = 11, ["name"] = "wool:white"}, {["x"] = 13, ["y"] = 20, ["param1"] = 15, ["z"] = 8, ["name"] = "wool:white"}, {["x"] = 13, ["y"] = 20, ["param1"] = 15, ["z"] = 9, ["name"] = "wool:white"}, {["x"] = 13, ["y"] = 20, ["param1"] = 15, ["z"] = 10, ["name"] = "wool:white"}, {["x"] = 13, ["meta"] = {["fields"] = {["infotext"] = "Protection (owned by thefox963)", ["members"] = "yelby mrg", ["owner"] = "thefox963"}, ["inventory"] = {}}, ["param2"] = 1, ["y"] = 20, ["param1"] = 153, ["z"] = 11, ["name"] = "protector:protect2"}, {["x"] = 13, ["y"] = 20, ["param1"] = 15, ["z"] = 12, ["name"] = "wool:white"}, {["x"] = 13, ["y"] = 20, ["param1"] = 15, ["z"] = 13, ["name"] = "wool:white"}, {["x"] = 13, ["y"] = 20, ["param1"] = 15, ["z"] = 14, ["name"] = "wool:white"}, {["x"] = 13, ["y"] = 21, ["param1"] = 15, ["z"] = 7, ["name"] = "wool:white"}, {["x"] = 13, ["y"] = 21, ["param1"] = 15, ["z"] = 15, ["name"] = "wool:white"}, {["x"] = 13, ["y"] = 22, ["param1"] = 15, ["z"] = 7, ["name"] = "wool:white"}, {["x"] = 13, ["y"] = 22, ["param1"] = 15, ["z"] = 15, ["name"] = "wool:white"}, {["x"] = 13, ["y"] = 23, ["param1"] = 15, ["z"] = 7, ["name"] = "wool:white"}, {["x"] = 13, ["y"] = 23, ["param1"] = 15, ["z"] = 15, ["name"] = "wool:white"}, {["x"] = 13, ["y"] = 24, ["param1"] = 15, ["z"] = 6, ["name"] = "wool:white"}, {["x"] = 13, ["y"] = 24, ["param1"] = 221, ["z"] = 11, ["name"] = "caverealms:glow_crystal"}, {["x"] = 13, ["y"] = 24, ["param1"] = 15, ["z"] = 16, ["name"] = "wool:white"}, {["x"] = 13, ["y"] = 25, ["param1"] = 15, ["z"] = 7, ["name"] = "wool:white"}, {["x"] = 13, ["y"] = 25, ["param1"] = 15, ["z"] = 15, ["name"] = "wool:white"}, {["x"] = 13, ["y"] = 26, ["param1"] = 15, ["z"] = 7, ["name"] = "wool:white"}, {["x"] = 13, ["y"] = 26, ["param1"] = 15, ["z"] = 15, ["name"] = "wool:white"}, {["x"] = 13, ["y"] = 27, ["param1"] = 15, ["z"] = 7, ["name"] = "wool:white"}, {["x"] = 13, ["y"] = 27, ["param1"] = 15, ["z"] = 15, ["name"] = "wool:white"}, {["x"] = 13, ["y"] = 28, ["param1"] = 15, ["z"] = 8, ["name"] = "wool:white"}, {["x"] = 13, ["y"] = 28, ["param1"] = 15, ["z"] = 9, ["name"] = "wool:white"}, {["x"] = 13, ["y"] = 28, ["param1"] = 15, ["z"] = 10, ["name"] = "wool:white"}, {["x"] = 13, ["y"] = 28, ["param1"] = 15, ["z"] = 12, ["name"] = "wool:white"}, {["x"] = 13, ["y"] = 28, ["param1"] = 15, ["z"] = 13, ["name"] = "wool:white"}, {["x"] = 13, ["y"] = 28, ["param1"] = 15, ["z"] = 14, ["name"] = "wool:white"}, {["x"] = 13, ["y"] = 29, ["param1"] = 15, ["z"] = 11, ["name"] = "wool:white"}, {["x"] = 14, ["y"] = 0, ["z"] = 11, ["name"] = "default:wood"}, {["x"] = 14, ["y"] = 1, ["z"] = 10, ["name"] = "default:wood"}, {["x"] = 14, ["y"] = 1, ["z"] = 12, ["name"] = "default:wood"}, {["x"] = 14, ["y"] = 2, ["z"] = 9, ["name"] = "default:wood"}, {["x"] = 14, ["y"] = 2, ["z"] = 13, ["name"] = "default:wood"}, {["x"] = 14, ["y"] = 3, ["z"] = 8, ["name"] = "default:wood"}, {["x"] = 14, ["y"] = 3, ["z"] = 14, ["name"] = "default:wood"}, {["x"] = 14, ["y"] = 4, ["z"] = 8, ["name"] = "default:wood"}, {["x"] = 14, ["y"] = 4, ["z"] = 14, ["name"] = "default:wood"}, {["x"] = 14, ["y"] = 5, ["z"] = 7, ["name"] = "default:wood"}, {["x"] = 14, ["y"] = 5, ["z"] = 15, ["name"] = "default:wood"}, {["x"] = 14, ["y"] = 6, ["z"] = 7, ["name"] = "default:wood"}, {["x"] = 14, ["y"] = 6, ["z"] = 15, ["name"] = "default:wood"}, {["x"] = 14, ["y"] = 7, ["z"] = 7, ["name"] = "default:wood"}, {["x"] = 14, ["y"] = 7, ["param1"] = 14, ["z"] = 8, ["name"] = "default:wood"}, {["x"] = 14, ["y"] = 7, ["param1"] = 14, ["z"] = 9, ["name"] = "default:wood"}, {["x"] = 14, ["y"] = 7, ["param1"] = 14, ["z"] = 10, ["name"] = "default:wood"}, {["x"] = 14, ["y"] = 7, ["param1"] = 14, ["z"] = 11, ["name"] = "default:wood"}, {["x"] = 14, ["y"] = 7, ["param1"] = 14, ["z"] = 12, ["name"] = "default:wood"}, {["x"] = 14, ["y"] = 7, ["param1"] = 14, ["z"] = 13, ["name"] = "default:wood"}, {["x"] = 14, ["y"] = 7, ["param1"] = 14, ["z"] = 14, ["name"] = "default:wood"}, {["x"] = 14, ["y"] = 7, ["z"] = 15, ["name"] = "default:wood"}, {["x"] = 14, ["y"] = 8, ["param1"] = 189, ["z"] = 7, ["name"] = "default:fence_wood"}, {["x"] = 14, ["y"] = 8, ["param1"] = 189, ["z"] = 15, ["name"] = "default:fence_wood"}, {["x"] = 14, ["y"] = 19, ["param1"] = 15, ["z"] = 10, ["name"] = "wool:white"}, {["x"] = 14, ["y"] = 19, ["param1"] = 15, ["z"] = 11, ["name"] = "wool:white"}, {["x"] = 14, ["y"] = 19, ["param1"] = 15, ["z"] = 12, ["name"] = "wool:white"}, {["x"] = 14, ["y"] = 20, ["param1"] = 15, ["z"] = 8, ["name"] = "wool:white"}, {["x"] = 14, ["y"] = 20, ["param1"] = 15, ["z"] = 9, ["name"] = "wool:white"}, {["x"] = 14, ["y"] = 20, ["param1"] = 15, ["z"] = 13, ["name"] = "wool:white"}, {["x"] = 14, ["y"] = 20, ["param1"] = 15, ["z"] = 14, ["name"] = "wool:white"}, {["x"] = 14, ["y"] = 21, ["param1"] = 15, ["z"] = 7, ["name"] = "wool:white"}, {["x"] = 14, ["y"] = 21, ["param1"] = 15, ["z"] = 15, ["name"] = "wool:white"}, {["x"] = 14, ["y"] = 22, ["param1"] = 15, ["z"] = 7, ["name"] = "wool:white"}, {["x"] = 14, ["y"] = 22, ["param1"] = 15, ["z"] = 15, ["name"] = "wool:white"}, {["x"] = 14, ["y"] = 23, ["param1"] = 15, ["z"] = 6, ["name"] = "wool:white"}, {["x"] = 14, ["y"] = 23, ["param1"] = 15, ["z"] = 16, ["name"] = "wool:white"}, {["x"] = 14, ["y"] = 24, ["param1"] = 15, ["z"] = 6, ["name"] = "wool:white"}, {["x"] = 14, ["y"] = 24, ["param1"] = 221, ["z"] = 11, ["name"] = "caverealms:glow_crystal"}, {["x"] = 14, ["y"] = 24, ["param1"] = 15, ["z"] = 16, ["name"] = "wool:white"}, {["x"] = 14, ["y"] = 25, ["param1"] = 15, ["z"] = 6, ["name"] = "wool:white"}, {["x"] = 14, ["y"] = 25, ["param1"] = 15, ["z"] = 16, ["name"] = "wool:white"}, {["x"] = 14, ["y"] = 26, ["param1"] = 15, ["z"] = 7, ["name"] = "wool:white"}, {["x"] = 14, ["y"] = 26, ["param1"] = 15, ["z"] = 15, ["name"] = "wool:white"}, {["x"] = 14, ["y"] = 27, ["param1"] = 15, ["z"] = 7, ["name"] = "wool:white"}, {["x"] = 14, ["y"] = 27, ["param1"] = 15, ["z"] = 15, ["name"] = "wool:white"}, {["x"] = 14, ["y"] = 28, ["param1"] = 15, ["z"] = 8, ["name"] = "wool:white"}, {["x"] = 14, ["y"] = 28, ["param1"] = 15, ["z"] = 9, ["name"] = "wool:white"}, {["x"] = 14, ["y"] = 28, ["param1"] = 15, ["z"] = 13, ["name"] = "wool:white"}, {["x"] = 14, ["y"] = 28, ["param1"] = 15, ["z"] = 14, ["name"] = "wool:white"}, {["x"] = 14, ["y"] = 29, ["param1"] = 15, ["z"] = 10, ["name"] = "wool:white"}, {["x"] = 14, ["y"] = 29, ["param1"] = 15, ["z"] = 11, ["name"] = "wool:white"}, {["x"] = 14, ["y"] = 29, ["param1"] = 15, ["z"] = 12, ["name"] = "wool:white"}, {["x"] = 15, ["y"] = 0, ["z"] = 11, ["name"] = "default:wood"}, {["x"] = 15, ["y"] = 1, ["z"] = 9, ["name"] = "default:wood"}, {["x"] = 15, ["y"] = 1, ["z"] = 10, ["name"] = "default:wood"}, {["x"] = 15, ["y"] = 1, ["z"] = 12, ["name"] = "default:wood"}, {["x"] = 15, ["y"] = 1, ["z"] = 13, ["name"] = "default:wood"}, {["x"] = 15, ["y"] = 2, ["z"] = 8, ["name"] = "default:wood"}, {["x"] = 15, ["y"] = 2, ["z"] = 14, ["name"] = "default:wood"}, {["x"] = 15, ["y"] = 3, ["z"] = 7, ["name"] = "default:wood"}, {["x"] = 15, ["y"] = 3, ["z"] = 15, ["name"] = "default:wood"}, {["x"] = 15, ["y"] = 4, ["z"] = 7, ["name"] = "default:wood"}, {["x"] = 15, ["y"] = 4, ["z"] = 15, ["name"] = "default:wood"}, {["x"] = 15, ["y"] = 5, ["z"] = 6, ["name"] = "default:wood"}, {["x"] = 15, ["y"] = 5, ["z"] = 16, ["name"] = "default:wood"}, {["x"] = 15, ["y"] = 6, ["z"] = 6, ["name"] = "default:wood"}, {["x"] = 15, ["y"] = 6, ["z"] = 16, ["name"] = "default:wood"}, {["x"] = 15, ["y"] = 7, ["z"] = 6, ["name"] = "default:wood"}, {["x"] = 15, ["y"] = 7, ["param1"] = 15, ["z"] = 7, ["name"] = "default:wood"}, {["x"] = 15, ["y"] = 7, ["param1"] = 15, ["z"] = 8, ["name"] = "default:wood"}, {["x"] = 15, ["y"] = 7, ["param1"] = 15, ["z"] = 9, ["name"] = "default:wood"}, {["x"] = 15, ["y"] = 7, ["param1"] = 15, ["z"] = 10, ["name"] = "default:wood"}, {["x"] = 15, ["y"] = 7, ["param1"] = 15, ["z"] = 11, ["name"] = "default:wood"}, {["x"] = 15, ["y"] = 7, ["param1"] = 15, ["z"] = 12, ["name"] = "default:wood"}, {["x"] = 15, ["y"] = 7, ["param1"] = 15, ["z"] = 13, ["name"] = "default:wood"}, {["x"] = 15, ["y"] = 7, ["param1"] = 15, ["z"] = 14, ["name"] = "default:wood"}, {["x"] = 15, ["y"] = 7, ["z"] = 15, ["name"] = "default:wood"}, {["x"] = 15, ["y"] = 7, ["z"] = 16, ["name"] = "default:wood"}, {["x"] = 15, ["y"] = 8, ["param1"] = 190, ["z"] = 6, ["name"] = "default:fence_wood"}, {["x"] = 15, ["y"] = 8, ["param1"] = 205, ["z"] = 7, ["name"] = "default:fence_wood"}, {["x"] = 15, ["y"] = 8, ["param1"] = 205, ["z"] = 15, ["name"] = "default:fence_wood"}, {["x"] = 15, ["y"] = 8, ["param1"] = 190, ["z"] = 16, ["name"] = "default:fence_wood"}, {["x"] = 15, ["param2"] = 1, ["y"] = 9, ["param1"] = 221, ["z"] = 7, ["name"] = "homedecor:glowlight_small_cube_on"}, {["x"] = 15, ["param2"] = 1, ["y"] = 9, ["param1"] = 221, ["z"] = 15, ["name"] = "homedecor:glowlight_small_cube_on"}, {["x"] = 15, ["y"] = 19, ["param1"] = 15, ["z"] = 10, ["name"] = "wool:white"}, {["x"] = 15, ["y"] = 19, ["param1"] = 15, ["z"] = 11, ["name"] = "wool:white"}, {["x"] = 15, ["y"] = 19, ["param1"] = 15, ["z"] = 12, ["name"] = "wool:white"}, {["x"] = 15, ["y"] = 20, ["param1"] = 15, ["z"] = 8, ["name"] = "wool:white"}, {["x"] = 15, ["y"] = 20, ["param1"] = 15, ["z"] = 9, ["name"] = "wool:white"}, {["x"] = 15, ["y"] = 20, ["param1"] = 15, ["z"] = 13, ["name"] = "wool:white"}, {["x"] = 15, ["y"] = 20, ["param1"] = 15, ["z"] = 14, ["name"] = "wool:white"}, {["x"] = 15, ["y"] = 21, ["param1"] = 15, ["z"] = 7, ["name"] = "wool:white"}, {["x"] = 15, ["y"] = 21, ["param1"] = 15, ["z"] = 15, ["name"] = "wool:white"}, {["x"] = 15, ["y"] = 22, ["param1"] = 15, ["z"] = 7, ["name"] = "wool:white"}, {["x"] = 15, ["y"] = 22, ["param1"] = 15, ["z"] = 15, ["name"] = "wool:white"}, {["x"] = 15, ["y"] = 23, ["param1"] = 15, ["z"] = 6, ["name"] = "wool:white"}, {["x"] = 15, ["y"] = 23, ["param1"] = 15, ["z"] = 16, ["name"] = "wool:white"}, {["x"] = 15, ["y"] = 24, ["param1"] = 15, ["z"] = 6, ["name"] = "wool:white"}, {["x"] = 15, ["y"] = 24, ["param1"] = 221, ["z"] = 11, ["name"] = "caverealms:glow_crystal"}, {["x"] = 15, ["y"] = 24, ["param1"] = 15, ["z"] = 16, ["name"] = "wool:white"}, {["x"] = 15, ["y"] = 25, ["param1"] = 15, ["z"] = 6, ["name"] = "wool:white"}, {["x"] = 15, ["y"] = 25, ["param1"] = 15, ["z"] = 16, ["name"] = "wool:white"}, {["x"] = 15, ["y"] = 26, ["param1"] = 15, ["z"] = 7, ["name"] = "wool:white"}, {["x"] = 15, ["y"] = 26, ["param1"] = 15, ["z"] = 15, ["name"] = "wool:white"}, {["x"] = 15, ["y"] = 27, ["param1"] = 15, ["z"] = 7, ["name"] = "wool:white"}, {["x"] = 15, ["y"] = 27, ["param1"] = 15, ["z"] = 15, ["name"] = "wool:white"}, {["x"] = 15, ["y"] = 28, ["param1"] = 15, ["z"] = 8, ["name"] = "wool:white"}, {["x"] = 15, ["y"] = 28, ["param1"] = 15, ["z"] = 9, ["name"] = "wool:white"}, {["x"] = 15, ["y"] = 28, ["param1"] = 15, ["z"] = 13, ["name"] = "wool:white"}, {["x"] = 15, ["y"] = 28, ["param1"] = 15, ["z"] = 14, ["name"] = "wool:white"}, {["x"] = 15, ["y"] = 29, ["param1"] = 15, ["z"] = 10, ["name"] = "wool:white"}, {["x"] = 15, ["y"] = 29, ["param1"] = 15, ["z"] = 11, ["name"] = "wool:white"}, {["x"] = 15, ["y"] = 29, ["param1"] = 15, ["z"] = 12, ["name"] = "wool:white"}, {["x"] = 16, ["y"] = 0, ["z"] = 11, ["name"] = "default:wood"}, {["x"] = 16, ["y"] = 1, ["z"] = 9, ["name"] = "default:wood"}, {["x"] = 16, ["y"] = 1, ["z"] = 10, ["name"] = "default:wood"}, {["x"] = 16, ["y"] = 1, ["z"] = 12, ["name"] = "default:wood"}, {["x"] = 16, ["y"] = 1, ["z"] = 13, ["name"] = "default:wood"}, {["x"] = 16, ["y"] = 2, ["z"] = 8, ["name"] = "default:wood"}, {["x"] = 16, ["y"] = 2, ["z"] = 14, ["name"] = "default:wood"}, {["x"] = 16, ["y"] = 3, ["z"] = 7, ["name"] = "default:wood"}, {["x"] = 16, ["y"] = 3, ["z"] = 15, ["name"] = "default:wood"}, {["x"] = 16, ["y"] = 4, ["z"] = 7, ["name"] = "default:wood"}, {["x"] = 16, ["y"] = 4, ["z"] = 15, ["name"] = "default:wood"}, {["x"] = 16, ["y"] = 5, ["z"] = 6, ["name"] = "default:wood"}, {["x"] = 16, ["meta"] = {["fields"] = {["owner"] = "thefox963", ["members"] = "yelby mrg", ["infotext"] = "Protection (owned by thefox963)"}, ["inventory"] = {}}, ["y"] = 5, ["param1"] = 75, ["z"] = 11, ["name"] = "protector:protect"}, {["x"] = 16, ["y"] = 5, ["z"] = 16, ["name"] = "default:wood"}, {["x"] = 16, ["y"] = 6, ["z"] = 6, ["name"] = "default:wood"}, {["x"] = 16, ["y"] = 6, ["z"] = 16, ["name"] = "default:wood"}, {["x"] = 16, ["y"] = 7, ["z"] = 6, ["name"] = "default:wood"}, {["x"] = 16, ["y"] = 7, ["param1"] = 15, ["z"] = 7, ["name"] = "default:wood"}, {["x"] = 16, ["y"] = 7, ["param1"] = 15, ["z"] = 8, ["name"] = "default:wood"}, {["x"] = 16, ["y"] = 7, ["param1"] = 15, ["z"] = 9, ["name"] = "default:wood"}, {["x"] = 16, ["y"] = 7, ["param1"] = 15, ["z"] = 10, ["name"] = "default:wood"}, {["x"] = 16, ["y"] = 7, ["param1"] = 15, ["z"] = 11, ["name"] = "default:wood"}, {["x"] = 16, ["y"] = 7, ["param1"] = 15, ["z"] = 12, ["name"] = "default:wood"}, {["x"] = 16, ["y"] = 7, ["param1"] = 15, ["z"] = 13, ["name"] = "default:wood"}, {["x"] = 16, ["y"] = 7, ["param1"] = 15, ["z"] = 14, ["name"] = "default:wood"}, {["x"] = 16, ["y"] = 7, ["z"] = 15, ["name"] = "default:wood"}, {["x"] = 16, ["y"] = 7, ["z"] = 16, ["name"] = "default:wood"}, {["x"] = 16, ["y"] = 8, ["param1"] = 174, ["z"] = 6, ["name"] = "default:fence_wood"}, {["x"] = 16, ["meta"] = {["fields"] = {["station_name"] = "Bow at Air 1", ["formspec"] = "size[12,10]label[3.3,0.0;Travelnet-Box:]label[6.3,0.0;Punch box to update target list.]label[0.3,0.4;Name of this station:]label[6.3,0.4;Bow at Air 1]label[0.3,0.8;Assigned to Network:]label[6.3,0.8;Air1b]label[0.3,1.2;Owned by:]label[6.3,1.2;mrg]label[3.3,1.6;Click on target to travel there:]button_exit[4,2.5;1,0.5;open_door;<>]label[4.9,2.35;Bow at Air 1]button_exit[4,3.5;4,0.5;target;Leap of Faith]", ["infotext"] = "Station 'Bow at Air 1' on travelnet 'Air1b' (owned by mrg) ready for usage. Right-click to travel, punch to update.", ["timestamp"] = "1493153732", ["station_network"] = "Air1b", ["owner"] = "mrg"}, ["inventory"] = {}}, ["param2"] = 2, ["y"] = 8, ["param1"] = 189, ["z"] = 7, ["name"] = "travelnet:travelnet"}, {["x"] = 16, ["y"] = 8, ["param1"] = 174, ["z"] = 16, ["name"] = "default:fence_wood"}, {["x"] = 16, ["y"] = 19, ["param1"] = 15, ["z"] = 10, ["name"] = "wool:white"}, {["x"] = 16, ["y"] = 19, ["param1"] = 15, ["z"] = 11, ["name"] = "wool:white"}, {["x"] = 16, ["y"] = 19, ["param1"] = 15, ["z"] = 12, ["name"] = "wool:white"}, {["x"] = 16, ["y"] = 20, ["param1"] = 15, ["z"] = 8, ["name"] = "wool:white"}, {["x"] = 16, ["y"] = 20, ["param1"] = 15, ["z"] = 9, ["name"] = "wool:white"}, {["x"] = 16, ["y"] = 20, ["param1"] = 15, ["z"] = 13, ["name"] = "wool:white"}, {["x"] = 16, ["y"] = 20, ["param1"] = 15, ["z"] = 14, ["name"] = "wool:white"}, {["x"] = 16, ["y"] = 21, ["param1"] = 15, ["z"] = 7, ["name"] = "wool:white"}, {["x"] = 16, ["y"] = 21, ["param1"] = 15, ["z"] = 15, ["name"] = "wool:white"}, {["x"] = 16, ["y"] = 22, ["param1"] = 15, ["z"] = 7, ["name"] = "wool:white"}, {["x"] = 16, ["y"] = 22, ["param1"] = 15, ["z"] = 15, ["name"] = "wool:white"}, {["x"] = 16, ["y"] = 23, ["param1"] = 15, ["z"] = 6, ["name"] = "wool:white"}, {["x"] = 16, ["y"] = 23, ["param1"] = 15, ["z"] = 16, ["name"] = "wool:white"}, {["x"] = 16, ["y"] = 24, ["param1"] = 15, ["z"] = 6, ["name"] = "wool:white"}, {["x"] = 16, ["y"] = 24, ["param1"] = 221, ["z"] = 11, ["name"] = "caverealms:glow_crystal"}, {["x"] = 16, ["y"] = 24, ["param1"] = 15, ["z"] = 16, ["name"] = "wool:white"}, {["x"] = 16, ["y"] = 25, ["param1"] = 15, ["z"] = 6, ["name"] = "wool:white"}, {["x"] = 16, ["y"] = 25, ["param1"] = 15, ["z"] = 16, ["name"] = "wool:white"}, {["x"] = 16, ["y"] = 26, ["param1"] = 15, ["z"] = 7, ["name"] = "wool:white"}, {["x"] = 16, ["y"] = 26, ["param1"] = 15, ["z"] = 15, ["name"] = "wool:white"}, {["x"] = 16, ["y"] = 27, ["param1"] = 15, ["z"] = 7, ["name"] = "wool:white"}, {["x"] = 16, ["y"] = 27, ["param1"] = 15, ["z"] = 15, ["name"] = "wool:white"}, {["x"] = 16, ["y"] = 28, ["param1"] = 15, ["z"] = 8, ["name"] = "wool:white"}, {["x"] = 16, ["y"] = 28, ["param1"] = 15, ["z"] = 9, ["name"] = "wool:white"}, {["x"] = 16, ["y"] = 28, ["param1"] = 15, ["z"] = 13, ["name"] = "wool:white"}, {["x"] = 16, ["y"] = 28, ["param1"] = 15, ["z"] = 14, ["name"] = "wool:white"}, {["x"] = 16, ["y"] = 29, ["param1"] = 15, ["z"] = 10, ["name"] = "wool:white"}, {["x"] = 16, ["y"] = 29, ["param1"] = 15, ["z"] = 11, ["name"] = "wool:white"}, {["x"] = 16, ["y"] = 29, ["param1"] = 15, ["z"] = 12, ["name"] = "wool:white"}, {["x"] = 17, ["y"] = 0, ["z"] = 11, ["name"] = "default:wood"}, {["x"] = 17, ["y"] = 1, ["z"] = 9, ["name"] = "default:wood"}, {["x"] = 17, ["y"] = 1, ["z"] = 10, ["name"] = "default:wood"}, {["x"] = 17, ["y"] = 1, ["z"] = 12, ["name"] = "default:wood"}, {["x"] = 17, ["y"] = 1, ["z"] = 13, ["name"] = "default:wood"}, {["x"] = 17, ["y"] = 2, ["z"] = 8, ["name"] = "default:wood"}, {["x"] = 17, ["y"] = 2, ["z"] = 14, ["name"] = "default:wood"}, {["x"] = 17, ["y"] = 3, ["z"] = 7, ["name"] = "default:wood"}, {["x"] = 17, ["y"] = 3, ["z"] = 15, ["name"] = "default:wood"}, {["x"] = 17, ["y"] = 4, ["z"] = 7, ["name"] = "default:wood"}, {["x"] = 17, ["y"] = 4, ["z"] = 15, ["name"] = "default:wood"}, {["x"] = 17, ["y"] = 5, ["z"] = 6, ["name"] = "default:wood"}, {["x"] = 17, ["y"] = 5, ["z"] = 16, ["name"] = "default:wood"}, {["x"] = 17, ["y"] = 6, ["z"] = 6, ["name"] = "default:wood"}, {["x"] = 17, ["y"] = 6, ["z"] = 16, ["name"] = "default:wood"}, {["x"] = 17, ["y"] = 7, ["z"] = 6, ["name"] = "default:wood"}, {["x"] = 17, ["y"] = 7, ["param1"] = 15, ["z"] = 7, ["name"] = "default:wood"}, {["x"] = 17, ["y"] = 7, ["param1"] = 15, ["z"] = 8, ["name"] = "default:wood"}, {["x"] = 17, ["y"] = 7, ["param1"] = 15, ["z"] = 9, ["name"] = "default:wood"}, {["x"] = 17, ["y"] = 7, ["param1"] = 15, ["z"] = 10, ["name"] = "default:wood"}, {["x"] = 17, ["y"] = 7, ["param1"] = 15, ["z"] = 11, ["name"] = "default:wood"}, {["x"] = 17, ["y"] = 7, ["param1"] = 15, ["z"] = 12, ["name"] = "default:wood"}, {["x"] = 17, ["y"] = 7, ["param1"] = 15, ["z"] = 13, ["name"] = "default:wood"}, {["x"] = 17, ["y"] = 7, ["param1"] = 15, ["z"] = 14, ["name"] = "default:wood"}, {["x"] = 17, ["y"] = 7, ["z"] = 15, ["name"] = "default:wood"}, {["x"] = 17, ["y"] = 7, ["z"] = 16, ["name"] = "default:wood"}, {["x"] = 17, ["y"] = 8, ["param1"] = 158, ["z"] = 6, ["name"] = "default:fence_wood"}, {["x"] = 17, ["y"] = 8, ["param1"] = 158, ["z"] = 16, ["name"] = "default:fence_wood"}, {["x"] = 17, ["y"] = 19, ["param1"] = 15, ["z"] = 9, ["name"] = "wool:white"}, {["x"] = 17, ["y"] = 19, ["param1"] = 15, ["z"] = 10, ["name"] = "wool:white"}, {["x"] = 17, ["y"] = 19, ["param1"] = 15, ["z"] = 11, ["name"] = "wool:white"}, {["x"] = 17, ["y"] = 19, ["param1"] = 15, ["z"] = 12, ["name"] = "wool:white"}, {["x"] = 17, ["y"] = 19, ["param1"] = 15, ["z"] = 13, ["name"] = "wool:white"}, {["x"] = 17, ["y"] = 20, ["param1"] = 15, ["z"] = 8, ["name"] = "wool:white"}, {["x"] = 17, ["y"] = 20, ["param1"] = 15, ["z"] = 14, ["name"] = "wool:white"}, {["x"] = 17, ["y"] = 21, ["param1"] = 15, ["z"] = 7, ["name"] = "wool:white"}, {["x"] = 17, ["y"] = 21, ["param1"] = 15, ["z"] = 15, ["name"] = "wool:white"}, {["x"] = 17, ["y"] = 22, ["param1"] = 15, ["z"] = 6, ["name"] = "wool:white"}, {["x"] = 17, ["y"] = 22, ["param1"] = 15, ["z"] = 16, ["name"] = "wool:white"}, {["x"] = 17, ["y"] = 23, ["param1"] = 15, ["z"] = 6, ["name"] = "wool:white"}, {["x"] = 17, ["y"] = 23, ["param1"] = 15, ["z"] = 16, ["name"] = "wool:white"}, {["x"] = 17, ["y"] = 24, ["param1"] = 15, ["z"] = 6, ["name"] = "wool:white"}, {["x"] = 17, ["y"] = 24, ["param1"] = 221, ["z"] = 11, ["name"] = "caverealms:glow_crystal"}, {["x"] = 17, ["y"] = 24, ["param1"] = 15, ["z"] = 16, ["name"] = "wool:white"}, {["x"] = 17, ["y"] = 25, ["param1"] = 15, ["z"] = 6, ["name"] = "wool:white"}, {["x"] = 17, ["y"] = 25, ["param1"] = 15, ["z"] = 16, ["name"] = "wool:white"}, {["x"] = 17, ["y"] = 26, ["param1"] = 15, ["z"] = 6, ["name"] = "wool:white"}, {["x"] = 17, ["y"] = 26, ["param1"] = 15, ["z"] = 16, ["name"] = "wool:white"}, {["x"] = 17, ["y"] = 27, ["param1"] = 15, ["z"] = 7, ["name"] = "wool:white"}, {["x"] = 17, ["y"] = 27, ["param1"] = 15, ["z"] = 15, ["name"] = "wool:white"}, {["x"] = 17, ["y"] = 28, ["param1"] = 15, ["z"] = 8, ["name"] = "wool:white"}, {["x"] = 17, ["y"] = 28, ["param1"] = 15, ["z"] = 14, ["name"] = "wool:white"}, {["x"] = 17, ["y"] = 29, ["param1"] = 15, ["z"] = 9, ["name"] = "wool:white"}, {["x"] = 17, ["y"] = 29, ["param1"] = 15, ["z"] = 10, ["name"] = "wool:white"}, {["x"] = 17, ["y"] = 29, ["param1"] = 15, ["z"] = 11, ["name"] = "wool:white"}, {["x"] = 17, ["y"] = 29, ["param1"] = 15, ["z"] = 12, ["name"] = "wool:white"}, {["x"] = 17, ["y"] = 29, ["param1"] = 15, ["z"] = 13, ["name"] = "wool:white"}, {["x"] = 18, ["y"] = 0, ["z"] = 11, ["name"] = "default:wood"}, {["x"] = 18, ["y"] = 1, ["z"] = 9, ["name"] = "default:wood"}, {["x"] = 18, ["y"] = 1, ["z"] = 10, ["name"] = "default:wood"}, {["x"] = 18, ["y"] = 1, ["z"] = 12, ["name"] = "default:wood"}, {["x"] = 18, ["y"] = 1, ["z"] = 13, ["name"] = "default:wood"}, {["x"] = 18, ["y"] = 2, ["z"] = 8, ["name"] = "default:wood"}, {["x"] = 18, ["y"] = 2, ["z"] = 14, ["name"] = "default:wood"}, {["x"] = 18, ["y"] = 3, ["z"] = 7, ["name"] = "default:wood"}, {["x"] = 18, ["y"] = 3, ["z"] = 15, ["name"] = "default:wood"}, {["x"] = 18, ["y"] = 4, ["z"] = 7, ["name"] = "default:wood"}, {["x"] = 18, ["y"] = 4, ["z"] = 15, ["name"] = "default:wood"}, {["x"] = 18, ["y"] = 5, ["z"] = 6, ["name"] = "default:wood"}, {["x"] = 18, ["y"] = 5, ["z"] = 16, ["name"] = "default:wood"}, {["x"] = 18, ["y"] = 6, ["z"] = 6, ["name"] = "default:wood"}, {["x"] = 18, ["y"] = 6, ["z"] = 16, ["name"] = "default:wood"}, {["x"] = 18, ["y"] = 7, ["z"] = 6, ["name"] = "default:wood"}, {["x"] = 18, ["y"] = 7, ["param1"] = 15, ["z"] = 7, ["name"] = "default:wood"}, {["x"] = 18, ["y"] = 7, ["param1"] = 15, ["z"] = 8, ["name"] = "default:wood"}, {["x"] = 18, ["y"] = 7, ["param1"] = 15, ["z"] = 9, ["name"] = "default:wood"}, {["x"] = 18, ["y"] = 7, ["param1"] = 15, ["z"] = 10, ["name"] = "default:wood"}, {["x"] = 18, ["y"] = 7, ["param1"] = 15, ["z"] = 11, ["name"] = "default:wood"}, {["x"] = 18, ["y"] = 7, ["param1"] = 15, ["z"] = 12, ["name"] = "default:wood"}, {["x"] = 18, ["y"] = 7, ["param1"] = 15, ["z"] = 13, ["name"] = "default:wood"}, {["x"] = 18, ["y"] = 7, ["param1"] = 15, ["z"] = 14, ["name"] = "default:wood"}, {["x"] = 18, ["y"] = 7, ["z"] = 15, ["name"] = "default:wood"}, {["x"] = 18, ["y"] = 7, ["z"] = 16, ["name"] = "default:wood"}, {["x"] = 18, ["y"] = 8, ["param1"] = 142, ["z"] = 6, ["name"] = "default:fence_wood"}, {["x"] = 18, ["y"] = 8, ["param1"] = 142, ["z"] = 16, ["name"] = "default:fence_wood"}, {["x"] = 18, ["y"] = 19, ["param1"] = 15, ["z"] = 9, ["name"] = "wool:white"}, {["x"] = 18, ["y"] = 19, ["param1"] = 15, ["z"] = 10, ["name"] = "wool:white"}, {["x"] = 18, ["y"] = 19, ["z"] = 11, ["name"] = "wool:white"}, {["x"] = 18, ["y"] = 19, ["param1"] = 15, ["z"] = 12, ["name"] = "wool:white"}, {["x"] = 18, ["y"] = 19, ["param1"] = 15, ["z"] = 13, ["name"] = "wool:white"}, {["x"] = 18, ["y"] = 20, ["param1"] = 15, ["z"] = 8, ["name"] = "wool:white"}, {["x"] = 18, ["y"] = 20, ["param1"] = 15, ["z"] = 14, ["name"] = "wool:white"}, {["x"] = 18, ["y"] = 21, ["param1"] = 15, ["z"] = 7, ["name"] = "wool:white"}, {["x"] = 18, ["y"] = 21, ["param1"] = 15, ["z"] = 15, ["name"] = "wool:white"}, {["x"] = 18, ["y"] = 22, ["param1"] = 15, ["z"] = 6, ["name"] = "wool:white"}, {["x"] = 18, ["y"] = 22, ["param1"] = 15, ["z"] = 16, ["name"] = "wool:white"}, {["x"] = 18, ["y"] = 23, ["param1"] = 15, ["z"] = 6, ["name"] = "wool:white"}, {["x"] = 18, ["y"] = 23, ["param1"] = 15, ["z"] = 16, ["name"] = "wool:white"}, {["x"] = 18, ["y"] = 24, ["param1"] = 15, ["z"] = 6, ["name"] = "wool:white"}, {["x"] = 18, ["y"] = 24, ["param1"] = 221, ["z"] = 11, ["name"] = "caverealms:glow_crystal"}, {["x"] = 18, ["y"] = 24, ["param1"] = 15, ["z"] = 16, ["name"] = "wool:white"}, {["x"] = 18, ["y"] = 25, ["param1"] = 15, ["z"] = 6, ["name"] = "wool:white"}, {["x"] = 18, ["y"] = 25, ["param1"] = 15, ["z"] = 16, ["name"] = "wool:white"}, {["x"] = 18, ["y"] = 26, ["param1"] = 15, ["z"] = 6, ["name"] = "wool:white"}, {["x"] = 18, ["y"] = 26, ["param1"] = 15, ["z"] = 16, ["name"] = "wool:white"}, {["x"] = 18, ["y"] = 27, ["param1"] = 15, ["z"] = 7, ["name"] = "wool:white"}, {["x"] = 18, ["y"] = 27, ["param1"] = 15, ["z"] = 15, ["name"] = "wool:white"}, {["x"] = 18, ["y"] = 28, ["param1"] = 15, ["z"] = 8, ["name"] = "wool:white"}, {["x"] = 18, ["y"] = 28, ["param1"] = 15, ["z"] = 14, ["name"] = "wool:white"}, {["x"] = 18, ["y"] = 29, ["param1"] = 15, ["z"] = 9, ["name"] = "wool:white"}, {["x"] = 18, ["y"] = 29, ["param1"] = 15, ["z"] = 10, ["name"] = "wool:white"}, {["x"] = 18, ["y"] = 29, ["param1"] = 15, ["z"] = 11, ["name"] = "wool:white"}, {["x"] = 18, ["y"] = 29, ["param1"] = 15, ["z"] = 12, ["name"] = "wool:white"}, {["x"] = 18, ["y"] = 29, ["param1"] = 15, ["z"] = 13, ["name"] = "wool:white"}, {["x"] = 19, ["y"] = 0, ["z"] = 11, ["name"] = "default:wood"}, {["x"] = 19, ["y"] = 1, ["z"] = 9, ["name"] = "default:wood"}, {["x"] = 19, ["y"] = 1, ["z"] = 10, ["name"] = "default:wood"}, {["x"] = 19, ["y"] = 1, ["z"] = 12, ["name"] = "default:wood"}, {["x"] = 19, ["y"] = 1, ["z"] = 13, ["name"] = "default:wood"}, {["x"] = 19, ["y"] = 2, ["z"] = 8, ["name"] = "default:wood"}, {["x"] = 19, ["y"] = 2, ["z"] = 14, ["name"] = "default:wood"}, {["x"] = 19, ["y"] = 3, ["z"] = 7, ["name"] = "default:wood"}, {["x"] = 19, ["y"] = 3, ["z"] = 15, ["name"] = "default:wood"}, {["x"] = 19, ["y"] = 4, ["z"] = 7, ["name"] = "default:wood"}, {["x"] = 19, ["y"] = 4, ["z"] = 15, ["name"] = "default:wood"}, {["x"] = 19, ["y"] = 5, ["z"] = 6, ["name"] = "default:wood"}, {["x"] = 19, ["y"] = 5, ["z"] = 16, ["name"] = "default:wood"}, {["x"] = 19, ["y"] = 6, ["z"] = 6, ["name"] = "default:wood"}, {["x"] = 19, ["y"] = 6, ["z"] = 16, ["name"] = "default:wood"}, {["x"] = 19, ["y"] = 7, ["z"] = 6, ["name"] = "default:wood"}, {["x"] = 19, ["y"] = 7, ["param1"] = 15, ["z"] = 7, ["name"] = "default:wood"}, {["x"] = 19, ["y"] = 7, ["param1"] = 15, ["z"] = 8, ["name"] = "default:wood"}, {["x"] = 19, ["y"] = 7, ["param1"] = 15, ["z"] = 9, ["name"] = "default:wood"}, {["x"] = 19, ["y"] = 7, ["param1"] = 15, ["z"] = 10, ["name"] = "default:wood"}, {["x"] = 19, ["y"] = 7, ["param1"] = 15, ["z"] = 11, ["name"] = "default:wood"}, {["x"] = 19, ["y"] = 7, ["param1"] = 15, ["z"] = 12, ["name"] = "default:wood"}, {["x"] = 19, ["y"] = 7, ["param1"] = 15, ["z"] = 13, ["name"] = "default:wood"}, {["x"] = 19, ["y"] = 7, ["param1"] = 15, ["z"] = 14, ["name"] = "default:wood"}, {["x"] = 19, ["y"] = 7, ["z"] = 15, ["name"] = "default:wood"}, {["x"] = 19, ["y"] = 7, ["z"] = 16, ["name"] = "default:wood"}, {["x"] = 19, ["y"] = 8, ["param1"] = 126, ["z"] = 6, ["name"] = "default:fence_wood"}, {["x"] = 19, ["y"] = 8, ["param1"] = 126, ["z"] = 16, ["name"] = "default:fence_wood"}, {["x"] = 19, ["y"] = 19, ["param1"] = 15, ["z"] = 9, ["name"] = "wool:white"}, {["x"] = 19, ["y"] = 19, ["param1"] = 15, ["z"] = 10, ["name"] = "wool:white"}, {["x"] = 19, ["y"] = 19, ["param1"] = 15, ["z"] = 11, ["name"] = "wool:white"}, {["x"] = 19, ["y"] = 19, ["param1"] = 15, ["z"] = 12, ["name"] = "wool:white"}, {["x"] = 19, ["y"] = 19, ["param1"] = 15, ["z"] = 13, ["name"] = "wool:white"}, {["x"] = 19, ["y"] = 20, ["param1"] = 15, ["z"] = 8, ["name"] = "wool:white"}, {["x"] = 19, ["y"] = 20, ["param1"] = 15, ["z"] = 14, ["name"] = "wool:white"}, {["x"] = 19, ["y"] = 21, ["param1"] = 15, ["z"] = 7, ["name"] = "wool:white"}, {["x"] = 19, ["y"] = 21, ["param1"] = 15, ["z"] = 15, ["name"] = "wool:white"}, {["x"] = 19, ["y"] = 22, ["param1"] = 15, ["z"] = 6, ["name"] = "wool:white"}, {["x"] = 19, ["y"] = 22, ["param1"] = 15, ["z"] = 16, ["name"] = "wool:white"}, {["x"] = 19, ["y"] = 23, ["param1"] = 15, ["z"] = 6, ["name"] = "wool:white"}, {["x"] = 19, ["y"] = 23, ["param1"] = 15, ["z"] = 16, ["name"] = "wool:white"}, {["x"] = 19, ["y"] = 24, ["param1"] = 15, ["z"] = 6, ["name"] = "wool:white"}, {["x"] = 19, ["meta"] = {["fields"] = {["infotext"] = "Protection (owned by thefox963)", ["members"] = "yelby mrg", ["owner"] = "thefox963"}, ["inventory"] = {}}, ["y"] = 24, ["param1"] = 204, ["z"] = 11, ["name"] = "protector:protect"}, {["x"] = 19, ["y"] = 24, ["param1"] = 15, ["z"] = 16, ["name"] = "wool:white"}, {["x"] = 19, ["y"] = 25, ["param1"] = 15, ["z"] = 6, ["name"] = "wool:white"}, {["x"] = 19, ["y"] = 25, ["param1"] = 15, ["z"] = 16, ["name"] = "wool:white"}, {["x"] = 19, ["y"] = 26, ["param1"] = 15, ["z"] = 6, ["name"] = "wool:white"}, {["x"] = 19, ["y"] = 26, ["param1"] = 15, ["z"] = 16, ["name"] = "wool:white"}, {["x"] = 19, ["y"] = 27, ["param1"] = 15, ["z"] = 7, ["name"] = "wool:white"}, {["x"] = 19, ["y"] = 27, ["param1"] = 15, ["z"] = 15, ["name"] = "wool:white"}, {["x"] = 19, ["y"] = 28, ["param1"] = 15, ["z"] = 8, ["name"] = "wool:white"}, {["x"] = 19, ["y"] = 28, ["param1"] = 15, ["z"] = 14, ["name"] = "wool:white"}, {["x"] = 19, ["y"] = 29, ["param1"] = 15, ["z"] = 9, ["name"] = "wool:white"}, {["x"] = 19, ["y"] = 29, ["param1"] = 15, ["z"] = 10, ["name"] = "wool:white"}, {["x"] = 19, ["y"] = 29, ["param1"] = 15, ["z"] = 11, ["name"] = "wool:white"}, {["x"] = 19, ["y"] = 29, ["param1"] = 15, ["z"] = 12, ["name"] = "wool:white"}, {["x"] = 19, ["y"] = 29, ["param1"] = 15, ["z"] = 13, ["name"] = "wool:white"}, {["x"] = 20, ["y"] = 0, ["z"] = 11, ["name"] = "default:wood"}, {["x"] = 20, ["y"] = 1, ["z"] = 9, ["name"] = "default:wood"}, {["x"] = 20, ["y"] = 1, ["z"] = 10, ["name"] = "default:wood"}, {["x"] = 20, ["y"] = 1, ["z"] = 12, ["name"] = "default:wood"}, {["x"] = 20, ["y"] = 1, ["z"] = 13, ["name"] = "default:wood"}, {["x"] = 20, ["y"] = 2, ["z"] = 8, ["name"] = "default:wood"}, {["x"] = 20, ["y"] = 2, ["z"] = 14, ["name"] = "default:wood"}, {["x"] = 20, ["y"] = 3, ["z"] = 7, ["name"] = "default:wood"}, {["x"] = 20, ["y"] = 3, ["z"] = 15, ["name"] = "default:wood"}, {["x"] = 20, ["y"] = 4, ["z"] = 7, ["name"] = "default:wood"}, {["x"] = 20, ["y"] = 4, ["z"] = 15, ["name"] = "default:wood"}, {["x"] = 20, ["y"] = 5, ["z"] = 6, ["name"] = "default:wood"}, {["x"] = 20, ["y"] = 5, ["z"] = 16, ["name"] = "default:wood"}, {["x"] = 20, ["y"] = 6, ["z"] = 6, ["name"] = "default:wood"}, {["x"] = 20, ["y"] = 6, ["z"] = 16, ["name"] = "default:wood"}, {["x"] = 20, ["y"] = 7, ["z"] = 6, ["name"] = "default:wood"}, {["x"] = 20, ["y"] = 7, ["param1"] = 15, ["z"] = 7, ["name"] = "default:wood"}, {["x"] = 20, ["y"] = 7, ["param1"] = 15, ["z"] = 8, ["name"] = "default:wood"}, {["x"] = 20, ["y"] = 7, ["param1"] = 15, ["z"] = 9, ["name"] = "default:wood"}, {["x"] = 20, ["y"] = 7, ["param1"] = 15, ["z"] = 10, ["name"] = "default:wood"}, {["x"] = 20, ["y"] = 7, ["param1"] = 15, ["z"] = 11, ["name"] = "default:wood"}, {["x"] = 20, ["y"] = 7, ["param1"] = 15, ["z"] = 12, ["name"] = "default:wood"}, {["x"] = 20, ["y"] = 7, ["param1"] = 15, ["z"] = 13, ["name"] = "default:wood"}, {["x"] = 20, ["y"] = 7, ["param1"] = 15, ["z"] = 14, ["name"] = "default:wood"}, {["x"] = 20, ["y"] = 7, ["z"] = 15, ["name"] = "default:wood"}, {["x"] = 20, ["y"] = 7, ["z"] = 16, ["name"] = "default:wood"}, {["x"] = 20, ["y"] = 8, ["param1"] = 110, ["z"] = 6, ["name"] = "default:fence_wood"}, {["x"] = 20, ["y"] = 8, ["param1"] = 110, ["z"] = 16, ["name"] = "default:fence_wood"}, {["x"] = 20, ["y"] = 19, ["param1"] = 15, ["z"] = 9, ["name"] = "wool:white"}, {["x"] = 20, ["y"] = 19, ["param1"] = 15, ["z"] = 10, ["name"] = "wool:white"}, {["x"] = 20, ["y"] = 19, ["param1"] = 15, ["z"] = 11, ["name"] = "wool:white"}, {["x"] = 20, ["y"] = 19, ["param1"] = 15, ["z"] = 12, ["name"] = "wool:white"}, {["x"] = 20, ["y"] = 19, ["param1"] = 15, ["z"] = 13, ["name"] = "wool:white"}, {["x"] = 20, ["y"] = 20, ["param1"] = 15, ["z"] = 8, ["name"] = "wool:white"}, {["x"] = 20, ["y"] = 20, ["param1"] = 15, ["z"] = 14, ["name"] = "wool:white"}, {["x"] = 20, ["y"] = 21, ["param1"] = 15, ["z"] = 7, ["name"] = "wool:white"}, {["x"] = 20, ["y"] = 21, ["param1"] = 15, ["z"] = 15, ["name"] = "wool:white"}, {["x"] = 20, ["y"] = 22, ["param1"] = 15, ["z"] = 6, ["name"] = "wool:white"}, {["x"] = 20, ["y"] = 22, ["param1"] = 15, ["z"] = 16, ["name"] = "wool:white"}, {["x"] = 20, ["y"] = 23, ["param1"] = 15, ["z"] = 6, ["name"] = "wool:white"}, {["x"] = 20, ["y"] = 23, ["param1"] = 15, ["z"] = 16, ["name"] = "wool:white"}, {["x"] = 20, ["y"] = 24, ["param1"] = 15, ["z"] = 6, ["name"] = "wool:white"}, {["x"] = 20, ["meta"] = {["fields"] = {["infotext"] = "Protection (owned by thefox963)", ["members"] = "yelby mrg", ["owner"] = "thefox963"}, ["inventory"] = {}}, ["y"] = 24, ["param1"] = 204, ["z"] = 11, ["name"] = "protector:protect"}, {["x"] = 20, ["y"] = 24, ["param1"] = 15, ["z"] = 16, ["name"] = "wool:white"}, {["x"] = 20, ["y"] = 25, ["param1"] = 15, ["z"] = 6, ["name"] = "wool:white"}, {["x"] = 20, ["y"] = 25, ["param1"] = 15, ["z"] = 16, ["name"] = "wool:white"}, {["x"] = 20, ["y"] = 26, ["param1"] = 15, ["z"] = 6, ["name"] = "wool:white"}, {["x"] = 20, ["y"] = 26, ["param1"] = 15, ["z"] = 16, ["name"] = "wool:white"}, {["x"] = 20, ["y"] = 27, ["param1"] = 15, ["z"] = 7, ["name"] = "wool:white"}, {["x"] = 20, ["y"] = 27, ["param1"] = 15, ["z"] = 15, ["name"] = "wool:white"}, {["x"] = 20, ["y"] = 28, ["param1"] = 15, ["z"] = 8, ["name"] = "wool:white"}, {["x"] = 20, ["y"] = 28, ["param1"] = 15, ["z"] = 14, ["name"] = "wool:white"}, {["x"] = 20, ["y"] = 29, ["param1"] = 15, ["z"] = 9, ["name"] = "wool:white"}, {["x"] = 20, ["y"] = 29, ["param1"] = 15, ["z"] = 10, ["name"] = "wool:white"}, {["x"] = 20, ["y"] = 29, ["param1"] = 15, ["z"] = 11, ["name"] = "wool:white"}, {["x"] = 20, ["y"] = 29, ["param1"] = 15, ["z"] = 12, ["name"] = "wool:white"}, {["x"] = 20, ["y"] = 29, ["param1"] = 15, ["z"] = 13, ["name"] = "wool:white"}, {["x"] = 21, ["y"] = 0, ["z"] = 11, ["name"] = "default:wood"}, {["x"] = 21, ["y"] = 1, ["z"] = 9, ["name"] = "default:wood"}, {["x"] = 21, ["y"] = 1, ["z"] = 10, ["name"] = "default:wood"}, {["x"] = 21, ["y"] = 1, ["z"] = 12, ["name"] = "default:wood"}, {["x"] = 21, ["y"] = 1, ["z"] = 13, ["name"] = "default:wood"}, {["x"] = 21, ["y"] = 2, ["z"] = 8, ["name"] = "default:wood"}, {["x"] = 21, ["y"] = 2, ["z"] = 14, ["name"] = "default:wood"}, {["x"] = 21, ["y"] = 3, ["z"] = 7, ["name"] = "default:wood"}, {["x"] = 21, ["y"] = 3, ["z"] = 15, ["name"] = "default:wood"}, {["x"] = 21, ["y"] = 4, ["z"] = 7, ["name"] = "default:wood"}, {["x"] = 21, ["y"] = 4, ["z"] = 15, ["name"] = "default:wood"}, {["x"] = 21, ["y"] = 5, ["z"] = 6, ["name"] = "default:wood"}, {["x"] = 21, ["y"] = 5, ["z"] = 16, ["name"] = "default:wood"}, {["x"] = 21, ["y"] = 6, ["z"] = 6, ["name"] = "default:wood"}, {["x"] = 21, ["y"] = 6, ["z"] = 16, ["name"] = "default:wood"}, {["x"] = 21, ["y"] = 7, ["z"] = 6, ["name"] = "default:wood"}, {["x"] = 21, ["y"] = 7, ["param1"] = 15, ["z"] = 7, ["name"] = "default:wood"}, {["x"] = 21, ["y"] = 7, ["param1"] = 15, ["z"] = 8, ["name"] = "default:wood"}, {["x"] = 21, ["y"] = 7, ["param1"] = 15, ["z"] = 9, ["name"] = "default:wood"}, {["x"] = 21, ["y"] = 7, ["param1"] = 15, ["z"] = 10, ["name"] = "default:wood"}, {["x"] = 21, ["y"] = 7, ["param1"] = 15, ["z"] = 11, ["name"] = "default:wood"}, {["x"] = 21, ["y"] = 7, ["param1"] = 15, ["z"] = 12, ["name"] = "default:wood"}, {["x"] = 21, ["y"] = 7, ["param1"] = 15, ["z"] = 13, ["name"] = "default:wood"}, {["x"] = 21, ["y"] = 7, ["param1"] = 15, ["z"] = 14, ["name"] = "default:wood"}, {["x"] = 21, ["y"] = 7, ["z"] = 15, ["name"] = "default:wood"}, {["x"] = 21, ["y"] = 7, ["z"] = 16, ["name"] = "default:wood"}, {["x"] = 21, ["y"] = 8, ["param1"] = 94, ["z"] = 6, ["name"] = "default:fence_wood"}, {["x"] = 21, ["y"] = 8, ["param1"] = 94, ["z"] = 16, ["name"] = "default:fence_wood"}, {["x"] = 21, ["y"] = 19, ["param1"] = 15, ["z"] = 9, ["name"] = "wool:white"}, {["x"] = 21, ["y"] = 19, ["param1"] = 15, ["z"] = 10, ["name"] = "wool:white"}, {["x"] = 21, ["y"] = 19, ["param1"] = 15, ["z"] = 11, ["name"] = "wool:white"}, {["x"] = 21, ["y"] = 19, ["param1"] = 15, ["z"] = 12, ["name"] = "wool:white"}, {["x"] = 21, ["y"] = 19, ["param1"] = 15, ["z"] = 13, ["name"] = "wool:white"}, {["x"] = 21, ["y"] = 20, ["param1"] = 15, ["z"] = 8, ["name"] = "wool:white"}, {["x"] = 21, ["y"] = 20, ["param1"] = 15, ["z"] = 14, ["name"] = "wool:white"}, {["x"] = 21, ["y"] = 21, ["param1"] = 15, ["z"] = 7, ["name"] = "wool:white"}, {["x"] = 21, ["y"] = 21, ["param1"] = 15, ["z"] = 15, ["name"] = "wool:white"}, {["x"] = 21, ["y"] = 22, ["param1"] = 15, ["z"] = 6, ["name"] = "wool:white"}, {["x"] = 21, ["y"] = 22, ["param1"] = 15, ["z"] = 16, ["name"] = "wool:white"}, {["x"] = 21, ["y"] = 23, ["param1"] = 15, ["z"] = 6, ["name"] = "wool:white"}, {["x"] = 21, ["y"] = 23, ["param1"] = 15, ["z"] = 16, ["name"] = "wool:white"}, {["x"] = 21, ["y"] = 24, ["param1"] = 15, ["z"] = 6, ["name"] = "wool:white"}, {["x"] = 21, ["y"] = 24, ["param1"] = 221, ["z"] = 11, ["name"] = "caverealms:glow_crystal"}, {["x"] = 21, ["y"] = 24, ["param1"] = 15, ["z"] = 16, ["name"] = "wool:white"}, {["x"] = 21, ["y"] = 25, ["param1"] = 15, ["z"] = 6, ["name"] = "wool:white"}, {["x"] = 21, ["y"] = 25, ["param1"] = 15, ["z"] = 16, ["name"] = "wool:white"}, {["x"] = 21, ["y"] = 26, ["param1"] = 15, ["z"] = 6, ["name"] = "wool:white"}, {["x"] = 21, ["y"] = 26, ["param1"] = 15, ["z"] = 16, ["name"] = "wool:white"}, {["x"] = 21, ["y"] = 27, ["param1"] = 15, ["z"] = 7, ["name"] = "wool:white"}, {["x"] = 21, ["y"] = 27, ["param1"] = 15, ["z"] = 15, ["name"] = "wool:white"}, {["x"] = 21, ["y"] = 28, ["param1"] = 15, ["z"] = 8, ["name"] = "wool:white"}, {["x"] = 21, ["y"] = 28, ["param1"] = 15, ["z"] = 14, ["name"] = "wool:white"}, {["x"] = 21, ["y"] = 29, ["param1"] = 15, ["z"] = 9, ["name"] = "wool:white"}, {["x"] = 21, ["y"] = 29, ["param1"] = 15, ["z"] = 10, ["name"] = "wool:white"}, {["x"] = 21, ["y"] = 29, ["param1"] = 15, ["z"] = 11, ["name"] = "wool:white"}, {["x"] = 21, ["y"] = 29, ["param1"] = 15, ["z"] = 12, ["name"] = "wool:white"}, {["x"] = 21, ["y"] = 29, ["param1"] = 15, ["z"] = 13, ["name"] = "wool:white"}, {["x"] = 22, ["y"] = 0, ["z"] = 11, ["name"] = "default:wood"}, {["x"] = 22, ["y"] = 1, ["z"] = 9, ["name"] = "default:wood"}, {["x"] = 22, ["y"] = 1, ["z"] = 10, ["name"] = "default:wood"}, {["x"] = 22, ["y"] = 1, ["z"] = 12, ["name"] = "default:wood"}, {["x"] = 22, ["y"] = 1, ["z"] = 13, ["name"] = "default:wood"}, {["x"] = 22, ["y"] = 2, ["param1"] = 14, ["z"] = 2, ["name"] = "default:wood"}, {["x"] = 22, ["y"] = 2, ["param1"] = 14, ["z"] = 3, ["name"] = "default:wood"}, {["x"] = 22, ["y"] = 2, ["param1"] = 14, ["z"] = 4, ["name"] = "default:wood"}, {["x"] = 22, ["y"] = 2, ["z"] = 8, ["name"] = "default:wood"}, {["x"] = 22, ["y"] = 2, ["z"] = 14, ["name"] = "default:wood"}, {["x"] = 22, ["y"] = 2, ["param1"] = 14, ["z"] = 18, ["name"] = "default:wood"}, {["x"] = 22, ["y"] = 2, ["param1"] = 14, ["z"] = 19, ["name"] = "default:wood"}, {["x"] = 22, ["y"] = 2, ["param1"] = 15, ["z"] = 20, ["name"] = "default:wood"}, {["x"] = 22, ["y"] = 3, ["param1"] = 14, ["z"] = 1, ["name"] = "default:wood"}, {["x"] = 22, ["y"] = 3, ["param1"] = 14, ["z"] = 2, ["name"] = "building_blocks:grate"}, {["x"] = 22, ["y"] = 3, ["param1"] = 14, ["z"] = 3, ["name"] = "building_blocks:grate"}, {["x"] = 22, ["y"] = 3, ["param1"] = 14, ["z"] = 4, ["name"] = "building_blocks:grate"}, {["x"] = 22, ["y"] = 3, ["param1"] = 14, ["z"] = 5, ["name"] = "default:wood"}, {["x"] = 22, ["y"] = 3, ["z"] = 7, ["name"] = "default:wood"}, {["x"] = 22, ["y"] = 3, ["z"] = 15, ["name"] = "default:wood"}, {["x"] = 22, ["y"] = 3, ["param1"] = 14, ["z"] = 17, ["name"] = "default:wood"}, {["x"] = 22, ["y"] = 3, ["param1"] = 14, ["z"] = 18, ["name"] = "building_blocks:grate"}, {["x"] = 22, ["y"] = 3, ["param1"] = 14, ["z"] = 19, ["name"] = "building_blocks:grate"}, {["x"] = 22, ["y"] = 3, ["param1"] = 14, ["z"] = 20, ["name"] = "building_blocks:grate"}, {["x"] = 22, ["y"] = 3, ["param1"] = 14, ["z"] = 21, ["name"] = "default:wood"}, {["x"] = 22, ["y"] = 4, ["param1"] = 15, ["z"] = 0, ["name"] = "default:wood"}, {["x"] = 22, ["y"] = 4, ["param1"] = 14, ["z"] = 1, ["name"] = "building_blocks:grate"}, {["x"] = 22, ["y"] = 4, ["param1"] = 14, ["z"] = 2, ["name"] = "building_blocks:grate"}, {["x"] = 22, ["y"] = 4, ["param1"] = 14, ["z"] = 3, ["name"] = "building_blocks:grate"}, {["x"] = 22, ["y"] = 4, ["param1"] = 14, ["z"] = 4, ["name"] = "building_blocks:grate"}, {["x"] = 22, ["y"] = 4, ["param1"] = 14, ["z"] = 5, ["name"] = "building_blocks:grate"}, {["x"] = 22, ["y"] = 4, ["param1"] = 13, ["z"] = 6, ["name"] = "default:wood"}, {["x"] = 22, ["y"] = 4, ["z"] = 7, ["name"] = "default:wood"}, {["x"] = 22, ["y"] = 4, ["z"] = 15, ["name"] = "default:wood"}, {["x"] = 22, ["y"] = 4, ["param1"] = 13, ["z"] = 16, ["name"] = "default:wood"}, {["x"] = 22, ["y"] = 4, ["param1"] = 14, ["z"] = 17, ["name"] = "building_blocks:grate"}, {["x"] = 22, ["y"] = 4, ["param1"] = 14, ["z"] = 18, ["name"] = "building_blocks:grate"}, {["x"] = 22, ["y"] = 4, ["param1"] = 14, ["z"] = 19, ["name"] = "building_blocks:grate"}, {["x"] = 22, ["y"] = 4, ["param1"] = 14, ["z"] = 20, ["name"] = "building_blocks:grate"}, {["x"] = 22, ["y"] = 4, ["param1"] = 14, ["z"] = 21, ["name"] = "building_blocks:grate"}, {["x"] = 22, ["y"] = 4, ["param1"] = 15, ["z"] = 22, ["name"] = "default:wood"}, {["x"] = 22, ["y"] = 5, ["param1"] = 15, ["z"] = 0, ["name"] = "default:wood"}, {["x"] = 22, ["y"] = 5, ["param1"] = 14, ["z"] = 1, ["name"] = "building_blocks:grate"}, {["x"] = 22, ["y"] = 5, ["param1"] = 14, ["z"] = 2, ["name"] = "building_blocks:grate"}, {["x"] = 22, ["y"] = 5, ["param1"] = 14, ["z"] = 3, ["name"] = "building_blocks:grate"}, {["x"] = 22, ["y"] = 5, ["param1"] = 14, ["z"] = 4, ["name"] = "building_blocks:grate"}, {["x"] = 22, ["y"] = 5, ["param1"] = 14, ["z"] = 5, ["name"] = "building_blocks:grate"}, {["x"] = 22, ["y"] = 5, ["z"] = 6, ["name"] = "default:wood"}, {["x"] = 22, ["y"] = 5, ["z"] = 16, ["name"] = "default:wood"}, {["x"] = 22, ["y"] = 5, ["param1"] = 14, ["z"] = 17, ["name"] = "building_blocks:grate"}, {["x"] = 22, ["y"] = 5, ["param1"] = 14, ["z"] = 18, ["name"] = "building_blocks:grate"}, {["x"] = 22, ["y"] = 5, ["param1"] = 14, ["z"] = 19, ["name"] = "building_blocks:grate"}, {["x"] = 22, ["y"] = 5, ["param1"] = 14, ["z"] = 20, ["name"] = "building_blocks:grate"}, {["x"] = 22, ["y"] = 5, ["param1"] = 14, ["z"] = 21, ["name"] = "building_blocks:grate"}, {["x"] = 22, ["y"] = 5, ["param1"] = 15, ["z"] = 22, ["name"] = "default:wood"}, {["x"] = 22, ["y"] = 6, ["param1"] = 15, ["z"] = 0, ["name"] = "default:wood"}, {["x"] = 22, ["y"] = 6, ["param1"] = 14, ["z"] = 1, ["name"] = "building_blocks:grate"}, {["x"] = 22, ["y"] = 6, ["param1"] = 14, ["z"] = 2, ["name"] = "building_blocks:grate"}, {["x"] = 22, ["y"] = 6, ["param1"] = 14, ["z"] = 3, ["name"] = "building_blocks:grate"}, {["x"] = 22, ["y"] = 6, ["param1"] = 14, ["z"] = 4, ["name"] = "building_blocks:grate"}, {["x"] = 22, ["y"] = 6, ["param1"] = 30, ["z"] = 5, ["name"] = "building_blocks:grate"}, {["x"] = 22, ["y"] = 6, ["z"] = 6, ["name"] = "default:wood"}, {["x"] = 22, ["y"] = 6, ["z"] = 16, ["name"] = "default:wood"}, {["x"] = 22, ["y"] = 6, ["param1"] = 30, ["z"] = 17, ["name"] = "building_blocks:grate"}, {["x"] = 22, ["y"] = 6, ["param1"] = 14, ["z"] = 18, ["name"] = "building_blocks:grate"}, {["x"] = 22, ["y"] = 6, ["param1"] = 14, ["z"] = 19, ["name"] = "building_blocks:grate"}, {["x"] = 22, ["y"] = 6, ["param1"] = 14, ["z"] = 20, ["name"] = "building_blocks:grate"}, {["x"] = 22, ["y"] = 6, ["param1"] = 14, ["z"] = 21, ["name"] = "building_blocks:grate"}, {["x"] = 22, ["y"] = 6, ["param1"] = 15, ["z"] = 22, ["name"] = "default:wood"}, {["x"] = 22, ["y"] = 7, ["param1"] = 14, ["z"] = 1, ["name"] = "default:wood"}, {["x"] = 22, ["y"] = 7, ["param1"] = 14, ["z"] = 2, ["name"] = "building_blocks:grate"}, {["x"] = 22, ["y"] = 7, ["param1"] = 14, ["z"] = 3, ["name"] = "building_blocks:grate"}, {["x"] = 22, ["y"] = 7, ["param1"] = 30, ["z"] = 4, ["name"] = "building_blocks:grate"}, {["x"] = 22, ["y"] = 7, ["param1"] = 14, ["z"] = 5, ["name"] = "default:wood"}, {["x"] = 22, ["y"] = 7, ["z"] = 6, ["name"] = "default:wood"}, {["x"] = 22, ["y"] = 7, ["param1"] = 15, ["z"] = 7, ["name"] = "default:wood"}, {["x"] = 22, ["y"] = 7, ["param1"] = 15, ["z"] = 8, ["name"] = "default:wood"}, {["x"] = 22, ["y"] = 7, ["param1"] = 15, ["z"] = 9, ["name"] = "default:wood"}, {["x"] = 22, ["y"] = 7, ["param1"] = 15, ["z"] = 10, ["name"] = "default:wood"}, {["x"] = 22, ["y"] = 7, ["param1"] = 15, ["z"] = 11, ["name"] = "default:wood"}, {["x"] = 22, ["y"] = 7, ["param1"] = 15, ["z"] = 12, ["name"] = "default:wood"}, {["x"] = 22, ["y"] = 7, ["param1"] = 15, ["z"] = 13, ["name"] = "default:wood"}, {["x"] = 22, ["y"] = 7, ["param1"] = 15, ["z"] = 14, ["name"] = "default:wood"}, {["x"] = 22, ["y"] = 7, ["z"] = 15, ["name"] = "default:wood"}, {["x"] = 22, ["y"] = 7, ["z"] = 16, ["name"] = "default:wood"}, {["x"] = 22, ["y"] = 7, ["param1"] = 14, ["z"] = 17, ["name"] = "default:wood"}, {["x"] = 22, ["y"] = 7, ["param1"] = 30, ["z"] = 18, ["name"] = "building_blocks:grate"}, {["x"] = 22, ["y"] = 7, ["param1"] = 14, ["z"] = 19, ["name"] = "building_blocks:grate"}, {["x"] = 22, ["y"] = 7, ["param1"] = 14, ["z"] = 20, ["name"] = "building_blocks:grate"}, {["x"] = 22, ["y"] = 7, ["param1"] = 15, ["z"] = 21, ["name"] = "default:wood"}, {["x"] = 22, ["y"] = 8, ["param1"] = 14, ["z"] = 2, ["name"] = "default:wood"}, {["x"] = 22, ["y"] = 8, ["param1"] = 14, ["z"] = 3, ["name"] = "default:wood"}, {["x"] = 22, ["y"] = 8, ["param1"] = 14, ["z"] = 4, ["name"] = "default:wood"}, {["x"] = 22, ["y"] = 8, ["param1"] = 78, ["z"] = 6, ["name"] = "default:fence_wood"}, {["x"] = 22, ["y"] = 8, ["param1"] = 78, ["z"] = 16, ["name"] = "default:fence_wood"}, {["x"] = 22, ["y"] = 8, ["param1"] = 14, ["z"] = 18, ["name"] = "default:wood"}, {["x"] = 22, ["y"] = 8, ["param1"] = 14, ["z"] = 19, ["name"] = "default:wood"}, {["x"] = 22, ["y"] = 8, ["param1"] = 14, ["z"] = 20, ["name"] = "default:wood"}, {["x"] = 22, ["y"] = 19, ["param1"] = 15, ["z"] = 9, ["name"] = "wool:white"}, {["x"] = 22, ["y"] = 19, ["param1"] = 15, ["z"] = 10, ["name"] = "wool:white"}, {["x"] = 22, ["y"] = 19, ["param1"] = 15, ["z"] = 11, ["name"] = "wool:white"}, {["x"] = 22, ["y"] = 19, ["param1"] = 15, ["z"] = 12, ["name"] = "wool:white"}, {["x"] = 22, ["y"] = 19, ["param1"] = 15, ["z"] = 13, ["name"] = "wool:white"}, {["x"] = 22, ["y"] = 20, ["param1"] = 15, ["z"] = 8, ["name"] = "wool:white"}, {["x"] = 22, ["y"] = 20, ["param1"] = 15, ["z"] = 14, ["name"] = "wool:white"}, {["x"] = 22, ["y"] = 21, ["param1"] = 15, ["z"] = 7, ["name"] = "wool:white"}, {["x"] = 22, ["y"] = 21, ["param1"] = 15, ["z"] = 15, ["name"] = "wool:white"}, {["x"] = 22, ["y"] = 22, ["param1"] = 15, ["z"] = 6, ["name"] = "wool:white"}, {["x"] = 22, ["y"] = 22, ["param1"] = 15, ["z"] = 16, ["name"] = "wool:white"}, {["x"] = 22, ["y"] = 23, ["param1"] = 15, ["z"] = 6, ["name"] = "wool:white"}, {["x"] = 22, ["y"] = 23, ["param1"] = 15, ["z"] = 16, ["name"] = "wool:white"}, {["x"] = 22, ["y"] = 24, ["param1"] = 15, ["z"] = 6, ["name"] = "wool:white"}, {["x"] = 22, ["y"] = 24, ["param1"] = 221, ["z"] = 11, ["name"] = "caverealms:glow_crystal"}, {["x"] = 22, ["y"] = 24, ["param1"] = 15, ["z"] = 16, ["name"] = "wool:white"}, {["x"] = 22, ["y"] = 25, ["param1"] = 15, ["z"] = 6, ["name"] = "wool:white"}, {["x"] = 22, ["y"] = 25, ["param1"] = 15, ["z"] = 16, ["name"] = "wool:white"}, {["x"] = 22, ["y"] = 26, ["param1"] = 15, ["z"] = 6, ["name"] = "wool:white"}, {["x"] = 22, ["y"] = 26, ["param1"] = 15, ["z"] = 16, ["name"] = "wool:white"}, {["x"] = 22, ["y"] = 27, ["param1"] = 15, ["z"] = 7, ["name"] = "wool:white"}, {["x"] = 22, ["y"] = 27, ["param1"] = 15, ["z"] = 15, ["name"] = "wool:white"}, {["x"] = 22, ["y"] = 28, ["param1"] = 15, ["z"] = 8, ["name"] = "wool:white"}, {["x"] = 22, ["y"] = 28, ["param1"] = 15, ["z"] = 14, ["name"] = "wool:white"}, {["x"] = 22, ["y"] = 29, ["param1"] = 15, ["z"] = 9, ["name"] = "wool:white"}, {["x"] = 22, ["y"] = 29, ["param1"] = 15, ["z"] = 10, ["name"] = "wool:white"}, {["x"] = 22, ["y"] = 29, ["param1"] = 15, ["z"] = 11, ["name"] = "wool:white"}, {["x"] = 22, ["y"] = 29, ["param1"] = 15, ["z"] = 12, ["name"] = "wool:white"}, {["x"] = 22, ["y"] = 29, ["param1"] = 15, ["z"] = 13, ["name"] = "wool:white"}, {["x"] = 23, ["y"] = 0, ["z"] = 11, ["name"] = "default:wood"}, {["x"] = 23, ["y"] = 1, ["z"] = 9, ["name"] = "default:wood"}, {["x"] = 23, ["y"] = 1, ["z"] = 10, ["name"] = "default:wood"}, {["x"] = 23, ["y"] = 1, ["z"] = 12, ["name"] = "default:wood"}, {["x"] = 23, ["y"] = 1, ["z"] = 13, ["name"] = "default:wood"}, {["x"] = 23, ["y"] = 2, ["param1"] = 15, ["z"] = 2, ["name"] = "default:wood"}, {["x"] = 23, ["y"] = 2, ["param1"] = 15, ["z"] = 3, ["name"] = "default:wood"}, {["x"] = 23, ["y"] = 2, ["param1"] = 15, ["z"] = 4, ["name"] = "default:wood"}, {["x"] = 23, ["y"] = 2, ["z"] = 8, ["name"] = "default:wood"}, {["x"] = 23, ["y"] = 2, ["z"] = 14, ["name"] = "default:wood"}, {["x"] = 23, ["y"] = 2, ["param1"] = 15, ["z"] = 18, ["name"] = "default:wood"}, {["x"] = 23, ["y"] = 2, ["param1"] = 15, ["z"] = 19, ["name"] = "default:wood"}, {["x"] = 23, ["y"] = 2, ["param1"] = 15, ["z"] = 20, ["name"] = "default:wood"}, {["x"] = 23, ["y"] = 3, ["param1"] = 15, ["z"] = 1, ["name"] = "default:wood"}, {["x"] = 23, ["y"] = 3, ["z"] = 2, ["name"] = "default:steelblock"}, {["x"] = 23, ["y"] = 3, ["z"] = 3, ["name"] = "default:steelblock"}, {["x"] = 23, ["y"] = 3, ["z"] = 4, ["name"] = "default:steelblock"}, {["x"] = 23, ["y"] = 3, ["param1"] = 15, ["z"] = 5, ["name"] = "default:wood"}, {["x"] = 23, ["y"] = 3, ["z"] = 7, ["name"] = "default:wood"}, {["x"] = 23, ["y"] = 3, ["z"] = 15, ["name"] = "default:wood"}, {["x"] = 23, ["y"] = 3, ["param1"] = 15, ["z"] = 17, ["name"] = "default:wood"}, {["x"] = 23, ["y"] = 3, ["z"] = 18, ["name"] = "default:steelblock"}, {["x"] = 23, ["y"] = 3, ["z"] = 19, ["name"] = "default:steelblock"}, {["x"] = 23, ["y"] = 3, ["z"] = 20, ["name"] = "default:steelblock"}, {["x"] = 23, ["y"] = 3, ["param1"] = 15, ["z"] = 21, ["name"] = "default:wood"}, {["x"] = 23, ["y"] = 4, ["param1"] = 15, ["z"] = 0, ["name"] = "default:wood"}, {["x"] = 23, ["y"] = 4, ["z"] = 1, ["name"] = "default:steelblock"}, {["x"] = 23, ["y"] = 4, ["z"] = 2, ["name"] = "default:steelblock"}, {["x"] = 23, ["y"] = 4, ["z"] = 3, ["name"] = "default:steelblock"}, {["x"] = 23, ["y"] = 4, ["z"] = 4, ["name"] = "default:steelblock"}, {["x"] = 23, ["y"] = 4, ["z"] = 5, ["name"] = "default:steelblock"}, {["x"] = 23, ["y"] = 4, ["param1"] = 14, ["z"] = 6, ["name"] = "default:wood"}, {["x"] = 23, ["y"] = 4, ["z"] = 7, ["name"] = "default:wood"}, {["x"] = 23, ["y"] = 4, ["z"] = 15, ["name"] = "default:wood"}, {["x"] = 23, ["y"] = 4, ["param1"] = 14, ["z"] = 16, ["name"] = "default:wood"}, {["x"] = 23, ["y"] = 4, ["z"] = 17, ["name"] = "default:steelblock"}, {["x"] = 23, ["y"] = 4, ["z"] = 18, ["name"] = "default:steelblock"}, {["x"] = 23, ["y"] = 4, ["z"] = 19, ["name"] = "default:steelblock"}, {["x"] = 23, ["y"] = 4, ["z"] = 20, ["name"] = "default:steelblock"}, {["x"] = 23, ["y"] = 4, ["z"] = 21, ["name"] = "default:steelblock"}, {["x"] = 23, ["y"] = 4, ["param1"] = 15, ["z"] = 22, ["name"] = "default:wood"}, {["x"] = 23, ["y"] = 5, ["param1"] = 15, ["z"] = 0, ["name"] = "default:wood"}, {["x"] = 23, ["y"] = 5, ["z"] = 1, ["name"] = "default:steelblock"}, {["x"] = 23, ["y"] = 5, ["z"] = 2, ["name"] = "default:steelblock"}, {["x"] = 23, ["y"] = 5, ["z"] = 3, ["name"] = "default:steelblock"}, {["x"] = 23, ["y"] = 5, ["z"] = 4, ["name"] = "default:steelblock"}, {["x"] = 23, ["y"] = 5, ["z"] = 5, ["name"] = "default:steelblock"}, {["x"] = 23, ["y"] = 5, ["z"] = 6, ["name"] = "default:wood"}, {["x"] = 23, ["y"] = 5, ["z"] = 16, ["name"] = "default:wood"}, {["x"] = 23, ["y"] = 5, ["z"] = 17, ["name"] = "default:steelblock"}, {["x"] = 23, ["y"] = 5, ["z"] = 18, ["name"] = "default:steelblock"}, {["x"] = 23, ["y"] = 5, ["z"] = 19, ["name"] = "default:steelblock"}, {["x"] = 23, ["y"] = 5, ["z"] = 20, ["name"] = "default:steelblock"}, {["x"] = 23, ["y"] = 5, ["z"] = 21, ["name"] = "default:steelblock"}, {["x"] = 23, ["y"] = 5, ["param1"] = 15, ["z"] = 22, ["name"] = "default:wood"}, {["x"] = 23, ["y"] = 6, ["param1"] = 15, ["z"] = 0, ["name"] = "default:wood"}, {["x"] = 23, ["y"] = 6, ["z"] = 1, ["name"] = "default:steelblock"}, {["x"] = 23, ["y"] = 6, ["z"] = 2, ["name"] = "default:steelblock"}, {["x"] = 23, ["y"] = 6, ["z"] = 3, ["name"] = "default:steelblock"}, {["x"] = 23, ["y"] = 6, ["z"] = 4, ["name"] = "default:steelblock"}, {["x"] = 23, ["y"] = 6, ["z"] = 5, ["name"] = "default:steelblock"}, {["x"] = 23, ["y"] = 6, ["z"] = 6, ["name"] = "default:wood"}, {["x"] = 23, ["y"] = 6, ["z"] = 16, ["name"] = "default:wood"}, {["x"] = 23, ["y"] = 6, ["z"] = 17, ["name"] = "default:steelblock"}, {["x"] = 23, ["y"] = 6, ["z"] = 18, ["name"] = "default:steelblock"}, {["x"] = 23, ["y"] = 6, ["z"] = 19, ["name"] = "default:steelblock"}, {["x"] = 23, ["y"] = 6, ["z"] = 20, ["name"] = "default:steelblock"}, {["x"] = 23, ["y"] = 6, ["z"] = 21, ["name"] = "default:steelblock"}, {["x"] = 23, ["y"] = 6, ["param1"] = 15, ["z"] = 22, ["name"] = "default:wood"}, {["x"] = 23, ["y"] = 7, ["param1"] = 14, ["z"] = 1, ["name"] = "default:wood"}, {["x"] = 23, ["y"] = 7, ["z"] = 2, ["name"] = "default:steelblock"}, {["x"] = 23, ["y"] = 7, ["z"] = 3, ["name"] = "default:steelblock"}, {["x"] = 23, ["y"] = 7, ["z"] = 4, ["name"] = "default:steelblock"}, {["x"] = 23, ["y"] = 7, ["param1"] = 14, ["z"] = 5, ["name"] = "default:wood"}, {["x"] = 23, ["y"] = 7, ["z"] = 6, ["name"] = "default:wood"}, {["x"] = 23, ["y"] = 7, ["param1"] = 15, ["z"] = 7, ["name"] = "default:wood"}, {["x"] = 23, ["y"] = 7, ["param1"] = 15, ["z"] = 8, ["name"] = "default:wood"}, {["x"] = 23, ["y"] = 7, ["param1"] = 15, ["z"] = 9, ["name"] = "default:wood"}, {["x"] = 23, ["y"] = 7, ["param1"] = 15, ["z"] = 10, ["name"] = "default:wood"}, {["x"] = 23, ["y"] = 7, ["param1"] = 15, ["z"] = 11, ["name"] = "default:wood"}, {["x"] = 23, ["y"] = 7, ["param1"] = 15, ["z"] = 12, ["name"] = "default:wood"}, {["x"] = 23, ["y"] = 7, ["param1"] = 15, ["z"] = 13, ["name"] = "default:wood"}, {["x"] = 23, ["y"] = 7, ["param1"] = 15, ["z"] = 14, ["name"] = "default:wood"}, {["x"] = 23, ["y"] = 7, ["z"] = 15, ["name"] = "default:wood"}, {["x"] = 23, ["y"] = 7, ["z"] = 16, ["name"] = "default:wood"}, {["x"] = 23, ["y"] = 7, ["param1"] = 14, ["z"] = 17, ["name"] = "default:wood"}, {["x"] = 23, ["y"] = 7, ["z"] = 18, ["name"] = "default:steelblock"}, {["x"] = 23, ["y"] = 7, ["z"] = 19, ["name"] = "default:steelblock"}, {["x"] = 23, ["y"] = 7, ["z"] = 20, ["name"] = "default:steelblock"}, {["x"] = 23, ["y"] = 7, ["param1"] = 15, ["z"] = 21, ["name"] = "default:wood"}, {["x"] = 23, ["y"] = 8, ["param1"] = 14, ["z"] = 2, ["name"] = "default:wood"}, {["x"] = 23, ["y"] = 8, ["param1"] = 14, ["z"] = 3, ["name"] = "default:wood"}, {["x"] = 23, ["y"] = 8, ["param1"] = 14, ["z"] = 4, ["name"] = "default:wood"}, {["x"] = 23, ["y"] = 8, ["param1"] = 78, ["z"] = 6, ["name"] = "default:fence_wood"}, {["x"] = 23, ["y"] = 8, ["param1"] = 78, ["z"] = 16, ["name"] = "default:fence_wood"}, {["x"] = 23, ["y"] = 8, ["param1"] = 14, ["z"] = 18, ["name"] = "default:wood"}, {["x"] = 23, ["y"] = 8, ["param1"] = 14, ["z"] = 19, ["name"] = "default:wood"}, {["x"] = 23, ["y"] = 8, ["param1"] = 14, ["z"] = 20, ["name"] = "default:wood"}, {["x"] = 23, ["y"] = 19, ["param1"] = 15, ["z"] = 10, ["name"] = "wool:white"}, {["x"] = 23, ["y"] = 19, ["param1"] = 15, ["z"] = 11, ["name"] = "wool:white"}, {["x"] = 23, ["y"] = 19, ["param1"] = 15, ["z"] = 12, ["name"] = "wool:white"}, {["x"] = 23, ["y"] = 20, ["param1"] = 15, ["z"] = 8, ["name"] = "wool:white"}, {["x"] = 23, ["y"] = 20, ["param1"] = 15, ["z"] = 9, ["name"] = "wool:white"}, {["x"] = 23, ["y"] = 20, ["param1"] = 15, ["z"] = 13, ["name"] = "wool:white"}, {["x"] = 23, ["y"] = 20, ["param1"] = 15, ["z"] = 14, ["name"] = "wool:white"}, {["x"] = 23, ["y"] = 21, ["param1"] = 15, ["z"] = 7, ["name"] = "wool:white"}, {["x"] = 23, ["y"] = 21, ["param1"] = 15, ["z"] = 15, ["name"] = "wool:white"}, {["x"] = 23, ["y"] = 22, ["param1"] = 15, ["z"] = 7, ["name"] = "wool:white"}, {["x"] = 23, ["y"] = 22, ["param1"] = 15, ["z"] = 15, ["name"] = "wool:white"}, {["x"] = 23, ["y"] = 23, ["param1"] = 15, ["z"] = 6, ["name"] = "wool:white"}, {["x"] = 23, ["y"] = 23, ["param1"] = 15, ["z"] = 16, ["name"] = "wool:white"}, {["x"] = 23, ["y"] = 24, ["param1"] = 15, ["z"] = 6, ["name"] = "wool:white"}, {["x"] = 23, ["y"] = 24, ["param1"] = 221, ["z"] = 11, ["name"] = "caverealms:glow_crystal"}, {["x"] = 23, ["y"] = 24, ["param1"] = 15, ["z"] = 16, ["name"] = "wool:white"}, {["x"] = 23, ["y"] = 25, ["param1"] = 15, ["z"] = 6, ["name"] = "wool:white"}, {["x"] = 23, ["y"] = 25, ["param1"] = 15, ["z"] = 16, ["name"] = "wool:white"}, {["x"] = 23, ["y"] = 26, ["param1"] = 15, ["z"] = 7, ["name"] = "wool:white"}, {["x"] = 23, ["y"] = 26, ["param1"] = 15, ["z"] = 15, ["name"] = "wool:white"}, {["x"] = 23, ["y"] = 27, ["param1"] = 15, ["z"] = 7, ["name"] = "wool:white"}, {["x"] = 23, ["y"] = 27, ["param1"] = 15, ["z"] = 15, ["name"] = "wool:white"}, {["x"] = 23, ["y"] = 28, ["param1"] = 15, ["z"] = 8, ["name"] = "wool:white"}, {["x"] = 23, ["y"] = 28, ["param1"] = 15, ["z"] = 9, ["name"] = "wool:white"}, {["x"] = 23, ["y"] = 28, ["param1"] = 15, ["z"] = 13, ["name"] = "wool:white"}, {["x"] = 23, ["y"] = 28, ["param1"] = 15, ["z"] = 14, ["name"] = "wool:white"}, {["x"] = 23, ["y"] = 29, ["param1"] = 15, ["z"] = 10, ["name"] = "wool:white"}, {["x"] = 23, ["y"] = 29, ["param1"] = 15, ["z"] = 11, ["name"] = "wool:white"}, {["x"] = 23, ["y"] = 29, ["param1"] = 15, ["z"] = 12, ["name"] = "wool:white"}, {["x"] = 24, ["y"] = 0, ["z"] = 11, ["name"] = "default:wood"}, {["x"] = 24, ["y"] = 1, ["z"] = 9, ["name"] = "default:wood"}, {["x"] = 24, ["y"] = 1, ["z"] = 10, ["name"] = "default:wood"}, {["x"] = 24, ["y"] = 1, ["z"] = 12, ["name"] = "default:wood"}, {["x"] = 24, ["y"] = 1, ["z"] = 13, ["name"] = "default:wood"}, {["x"] = 24, ["y"] = 2, ["param1"] = 15, ["z"] = 2, ["name"] = "default:wood"}, {["x"] = 24, ["y"] = 2, ["param1"] = 15, ["z"] = 3, ["name"] = "default:wood"}, {["x"] = 24, ["y"] = 2, ["param1"] = 15, ["z"] = 4, ["name"] = "default:wood"}, {["x"] = 24, ["y"] = 2, ["z"] = 8, ["name"] = "default:wood"}, {["x"] = 24, ["y"] = 2, ["z"] = 14, ["name"] = "default:wood"}, {["x"] = 24, ["y"] = 2, ["param1"] = 15, ["z"] = 18, ["name"] = "default:wood"}, {["x"] = 24, ["y"] = 2, ["param1"] = 15, ["z"] = 19, ["name"] = "default:wood"}, {["x"] = 24, ["y"] = 2, ["param1"] = 15, ["z"] = 20, ["name"] = "default:wood"}, {["x"] = 24, ["y"] = 3, ["param1"] = 15, ["z"] = 1, ["name"] = "default:wood"}, {["x"] = 24, ["y"] = 3, ["param1"] = 15, ["z"] = 5, ["name"] = "default:wood"}, {["x"] = 24, ["y"] = 3, ["z"] = 7, ["name"] = "default:wood"}, {["x"] = 24, ["y"] = 3, ["z"] = 15, ["name"] = "default:wood"}, {["x"] = 24, ["y"] = 3, ["param1"] = 15, ["z"] = 17, ["name"] = "default:wood"}, {["x"] = 24, ["y"] = 3, ["param1"] = 15, ["z"] = 21, ["name"] = "default:wood"}, {["x"] = 24, ["y"] = 4, ["param1"] = 15, ["z"] = 0, ["name"] = "default:wood"}, {["x"] = 24, ["y"] = 4, ["param1"] = 14, ["z"] = 6, ["name"] = "default:wood"}, {["x"] = 24, ["y"] = 4, ["z"] = 7, ["name"] = "default:wood"}, {["x"] = 24, ["y"] = 4, ["z"] = 15, ["name"] = "default:wood"}, {["x"] = 24, ["y"] = 4, ["param1"] = 14, ["z"] = 16, ["name"] = "default:wood"}, {["x"] = 24, ["y"] = 4, ["param1"] = 15, ["z"] = 22, ["name"] = "default:wood"}, {["x"] = 24, ["y"] = 5, ["param1"] = 15, ["z"] = 0, ["name"] = "default:wood"}, {["x"] = 24, ["y"] = 5, ["z"] = 6, ["name"] = "default:wood"}, {["x"] = 24, ["y"] = 5, ["z"] = 16, ["name"] = "default:wood"}, {["x"] = 24, ["y"] = 5, ["param1"] = 15, ["z"] = 22, ["name"] = "default:wood"}, {["x"] = 24, ["y"] = 6, ["param1"] = 15, ["z"] = 0, ["name"] = "default:wood"}, {["x"] = 24, ["y"] = 6, ["z"] = 6, ["name"] = "default:wood"}, {["x"] = 24, ["y"] = 6, ["z"] = 16, ["name"] = "default:wood"}, {["x"] = 24, ["y"] = 6, ["param1"] = 15, ["z"] = 22, ["name"] = "default:wood"}, {["x"] = 24, ["y"] = 7, ["param1"] = 14, ["z"] = 1, ["name"] = "default:wood"}, {["x"] = 24, ["y"] = 7, ["param1"] = 14, ["z"] = 5, ["name"] = "default:wood"}, {["x"] = 24, ["y"] = 7, ["z"] = 6, ["name"] = "default:wood"}, {["x"] = 24, ["y"] = 7, ["param1"] = 15, ["z"] = 7, ["name"] = "default:wood"}, {["x"] = 24, ["y"] = 7, ["param1"] = 15, ["z"] = 8, ["name"] = "default:wood"}, {["x"] = 24, ["y"] = 7, ["param1"] = 15, ["z"] = 9, ["name"] = "default:wood"}, {["x"] = 24, ["y"] = 7, ["param1"] = 15, ["z"] = 10, ["name"] = "default:wood"}, {["x"] = 24, ["y"] = 7, ["param1"] = 15, ["z"] = 11, ["name"] = "default:wood"}, {["x"] = 24, ["y"] = 7, ["param1"] = 15, ["z"] = 12, ["name"] = "default:wood"}, {["x"] = 24, ["y"] = 7, ["param1"] = 15, ["z"] = 13, ["name"] = "default:wood"}, {["x"] = 24, ["y"] = 7, ["param1"] = 15, ["z"] = 14, ["name"] = "default:wood"}, {["x"] = 24, ["y"] = 7, ["z"] = 15, ["name"] = "default:wood"}, {["x"] = 24, ["y"] = 7, ["z"] = 16, ["name"] = "default:wood"}, {["x"] = 24, ["y"] = 7, ["param1"] = 14, ["z"] = 17, ["name"] = "default:wood"}, {["x"] = 24, ["y"] = 7, ["param1"] = 15, ["z"] = 21, ["name"] = "default:wood"}, {["x"] = 24, ["y"] = 8, ["param1"] = 14, ["z"] = 2, ["name"] = "default:wood"}, {["x"] = 24, ["y"] = 8, ["param1"] = 14, ["z"] = 3, ["name"] = "default:wood"}, {["x"] = 24, ["y"] = 8, ["param1"] = 14, ["z"] = 4, ["name"] = "default:wood"}, {["x"] = 24, ["y"] = 8, ["param1"] = 94, ["z"] = 6, ["name"] = "default:fence_wood"}, {["x"] = 24, ["y"] = 8, ["param1"] = 94, ["z"] = 16, ["name"] = "default:fence_wood"}, {["x"] = 24, ["y"] = 8, ["param1"] = 14, ["z"] = 18, ["name"] = "default:wood"}, {["x"] = 24, ["y"] = 8, ["param1"] = 14, ["z"] = 19, ["name"] = "default:wood"}, {["x"] = 24, ["y"] = 8, ["param1"] = 14, ["z"] = 20, ["name"] = "default:wood"}, {["x"] = 24, ["y"] = 19, ["param1"] = 15, ["z"] = 10, ["name"] = "wool:white"}, {["x"] = 24, ["y"] = 19, ["param1"] = 15, ["z"] = 11, ["name"] = "wool:white"}, {["x"] = 24, ["y"] = 19, ["param1"] = 15, ["z"] = 12, ["name"] = "wool:white"}, {["x"] = 24, ["y"] = 20, ["param1"] = 15, ["z"] = 8, ["name"] = "wool:white"}, {["x"] = 24, ["y"] = 20, ["param1"] = 15, ["z"] = 9, ["name"] = "wool:white"}, {["x"] = 24, ["y"] = 20, ["param1"] = 15, ["z"] = 13, ["name"] = "wool:white"}, {["x"] = 24, ["y"] = 20, ["param1"] = 15, ["z"] = 14, ["name"] = "wool:white"}, {["x"] = 24, ["y"] = 21, ["param1"] = 15, ["z"] = 7, ["name"] = "wool:white"}, {["x"] = 24, ["y"] = 21, ["param1"] = 15, ["z"] = 15, ["name"] = "wool:white"}, {["x"] = 24, ["y"] = 22, ["param1"] = 15, ["z"] = 7, ["name"] = "wool:white"}, {["x"] = 24, ["y"] = 22, ["param1"] = 15, ["z"] = 15, ["name"] = "wool:white"}, {["x"] = 24, ["y"] = 23, ["param1"] = 15, ["z"] = 6, ["name"] = "wool:white"}, {["x"] = 24, ["y"] = 23, ["param1"] = 15, ["z"] = 16, ["name"] = "wool:white"}, {["x"] = 24, ["y"] = 24, ["param1"] = 15, ["z"] = 6, ["name"] = "wool:white"}, {["x"] = 24, ["y"] = 24, ["param1"] = 221, ["z"] = 11, ["name"] = "caverealms:glow_crystal"}, {["x"] = 24, ["y"] = 24, ["param1"] = 15, ["z"] = 16, ["name"] = "wool:white"}, {["x"] = 24, ["y"] = 25, ["param1"] = 15, ["z"] = 6, ["name"] = "wool:white"}, {["x"] = 24, ["y"] = 25, ["param1"] = 15, ["z"] = 16, ["name"] = "wool:white"}, {["x"] = 24, ["y"] = 26, ["param1"] = 15, ["z"] = 7, ["name"] = "wool:white"}, {["x"] = 24, ["y"] = 26, ["param1"] = 15, ["z"] = 15, ["name"] = "wool:white"}, {["x"] = 24, ["y"] = 27, ["param1"] = 15, ["z"] = 7, ["name"] = "wool:white"}, {["x"] = 24, ["y"] = 27, ["param1"] = 15, ["z"] = 15, ["name"] = "wool:white"}, {["x"] = 24, ["y"] = 28, ["param1"] = 15, ["z"] = 8, ["name"] = "wool:white"}, {["x"] = 24, ["y"] = 28, ["param1"] = 15, ["z"] = 9, ["name"] = "wool:white"}, {["x"] = 24, ["y"] = 28, ["param1"] = 15, ["z"] = 13, ["name"] = "wool:white"}, {["x"] = 24, ["y"] = 28, ["param1"] = 15, ["z"] = 14, ["name"] = "wool:white"}, {["x"] = 24, ["y"] = 29, ["param1"] = 15, ["z"] = 10, ["name"] = "wool:white"}, {["x"] = 24, ["y"] = 29, ["param1"] = 15, ["z"] = 11, ["name"] = "wool:white"}, {["x"] = 24, ["y"] = 29, ["param1"] = 15, ["z"] = 12, ["name"] = "wool:white"}, {["x"] = 25, ["y"] = 0, ["z"] = 11, ["name"] = "default:wood"}, {["x"] = 25, ["y"] = 1, ["z"] = 9, ["name"] = "default:wood"}, {["x"] = 25, ["y"] = 1, ["z"] = 10, ["name"] = "default:wood"}, {["x"] = 25, ["y"] = 1, ["z"] = 12, ["name"] = "default:wood"}, {["x"] = 25, ["y"] = 1, ["z"] = 13, ["name"] = "default:wood"}, {["x"] = 25, ["y"] = 2, ["param1"] = 15, ["z"] = 2, ["name"] = "default:wood"}, {["x"] = 25, ["y"] = 2, ["param1"] = 15, ["z"] = 3, ["name"] = "default:wood"}, {["x"] = 25, ["y"] = 2, ["param1"] = 15, ["z"] = 4, ["name"] = "default:wood"}, {["x"] = 25, ["y"] = 2, ["z"] = 8, ["name"] = "default:wood"}, {["x"] = 25, ["y"] = 2, ["z"] = 14, ["name"] = "default:wood"}, {["x"] = 25, ["y"] = 2, ["param1"] = 15, ["z"] = 18, ["name"] = "default:wood"}, {["x"] = 25, ["y"] = 2, ["param1"] = 15, ["z"] = 19, ["name"] = "default:wood"}, {["x"] = 25, ["y"] = 2, ["param1"] = 15, ["z"] = 20, ["name"] = "default:wood"}, {["x"] = 25, ["y"] = 3, ["param1"] = 15, ["z"] = 1, ["name"] = "default:wood"}, {["x"] = 25, ["y"] = 3, ["param1"] = 15, ["z"] = 5, ["name"] = "default:wood"}, {["x"] = 25, ["y"] = 3, ["z"] = 7, ["name"] = "default:wood"}, {["x"] = 25, ["y"] = 3, ["z"] = 15, ["name"] = "default:wood"}, {["x"] = 25, ["y"] = 3, ["param1"] = 15, ["z"] = 17, ["name"] = "default:wood"}, {["x"] = 25, ["y"] = 3, ["param1"] = 15, ["z"] = 21, ["name"] = "default:wood"}, {["x"] = 25, ["y"] = 4, ["param1"] = 15, ["z"] = 0, ["name"] = "default:wood"}, {["x"] = 25, ["y"] = 4, ["param1"] = 14, ["z"] = 6, ["name"] = "default:wood"}, {["x"] = 25, ["y"] = 4, ["z"] = 7, ["name"] = "default:wood"}, {["x"] = 25, ["y"] = 4, ["z"] = 15, ["name"] = "default:wood"}, {["x"] = 25, ["y"] = 4, ["param1"] = 14, ["z"] = 16, ["name"] = "default:wood"}, {["x"] = 25, ["y"] = 4, ["param1"] = 15, ["z"] = 22, ["name"] = "default:wood"}, {["x"] = 25, ["y"] = 5, ["param1"] = 15, ["z"] = 0, ["name"] = "default:wood"}, {["x"] = 25, ["y"] = 5, ["z"] = 6, ["name"] = "default:wood"}, {["x"] = 25, ["y"] = 5, ["z"] = 16, ["name"] = "default:wood"}, {["x"] = 25, ["y"] = 5, ["param1"] = 15, ["z"] = 22, ["name"] = "default:wood"}, {["x"] = 25, ["y"] = 6, ["param1"] = 15, ["z"] = 0, ["name"] = "default:wood"}, {["x"] = 25, ["y"] = 6, ["z"] = 6, ["name"] = "default:wood"}, {["x"] = 25, ["y"] = 6, ["z"] = 16, ["name"] = "default:wood"}, {["x"] = 25, ["y"] = 6, ["param1"] = 15, ["z"] = 22, ["name"] = "default:wood"}, {["x"] = 25, ["y"] = 7, ["param1"] = 14, ["z"] = 1, ["name"] = "default:wood"}, {["x"] = 25, ["y"] = 7, ["param1"] = 14, ["z"] = 5, ["name"] = "default:wood"}, {["x"] = 25, ["y"] = 7, ["z"] = 6, ["name"] = "default:wood"}, {["x"] = 25, ["y"] = 7, ["param1"] = 15, ["z"] = 7, ["name"] = "default:wood"}, {["x"] = 25, ["y"] = 7, ["param1"] = 15, ["z"] = 8, ["name"] = "default:wood"}, {["x"] = 25, ["y"] = 7, ["param1"] = 15, ["z"] = 9, ["name"] = "default:wood"}, {["x"] = 25, ["y"] = 7, ["param1"] = 15, ["z"] = 10, ["name"] = "default:wood"}, {["x"] = 25, ["y"] = 7, ["param1"] = 15, ["z"] = 11, ["name"] = "default:wood"}, {["x"] = 25, ["y"] = 7, ["param1"] = 15, ["z"] = 12, ["name"] = "default:wood"}, {["x"] = 25, ["y"] = 7, ["param1"] = 15, ["z"] = 13, ["name"] = "default:wood"}, {["x"] = 25, ["y"] = 7, ["param1"] = 15, ["z"] = 14, ["name"] = "default:wood"}, {["x"] = 25, ["y"] = 7, ["z"] = 15, ["name"] = "default:wood"}, {["x"] = 25, ["y"] = 7, ["z"] = 16, ["name"] = "default:wood"}, {["x"] = 25, ["y"] = 7, ["param1"] = 14, ["z"] = 17, ["name"] = "default:wood"}, {["x"] = 25, ["y"] = 7, ["param1"] = 15, ["z"] = 21, ["name"] = "default:wood"}, {["x"] = 25, ["y"] = 8, ["param1"] = 14, ["z"] = 2, ["name"] = "default:wood"}, {["x"] = 25, ["y"] = 8, ["param1"] = 14, ["z"] = 3, ["name"] = "default:wood"},