5:return {{["x"] = 0, ["y"] = 2, ["z"] = 0, ["name"] = "birthstones:diamondblock"}, {["x"] = 0, ["y"] = 2, ["z"] = 5, ["name"] = "birthstones:diamondblock"}, {["x"] = 0, ["y"] = 2, ["z"] = 6, ["name"] = "birthstones:diamondblock"}, {["x"] = 0, ["y"] = 2, ["z"] = 16, ["name"] = "birthstones:diamondblock"}, {["x"] = 0, ["y"] = 2, ["z"] = 21, ["name"] = "birthstones:diamondblock"}, {["x"] = 0, ["y"] = 2, ["z"] = 22, ["name"] = "birthstones:diamondblock"}, {["x"] = 0, ["y"] = 3, ["z"] = 0, ["name"] = "birthstones:diamondblock"}, {["x"] = 0, ["y"] = 3, ["z"] = 1, ["name"] = "birthstones:diamondblock"}, {["x"] = 0, ["y"] = 3, ["z"] = 4, ["name"] = "birthstones:diamondblock"}, {["x"] = 0, ["y"] = 3, ["z"] = 5, ["name"] = "birthstones:diamondblock"}, {["x"] = 0, ["y"] = 3, ["z"] = 16, ["name"] = "birthstones:diamondblock"}, {["x"] = 0, ["y"] = 3, ["z"] = 17, ["name"] = "birthstones:diamondblock"}, {["x"] = 0, ["y"] = 3, ["z"] = 20, ["name"] = "birthstones:diamondblock"}, {["x"] = 0, ["y"] = 3, ["z"] = 21, ["name"] = "birthstones:diamondblock"}, {["x"] = 0, ["y"] = 4, ["z"] = 1, ["name"] = "birthstones:diamondblock"}, {["x"] = 0, ["y"] = 4, ["z"] = 2, ["name"] = "birthstones:diamondblock"}, {["x"] = 0, ["y"] = 4, ["z"] = 4, ["name"] = "birthstones:diamondblock"}, {["x"] = 0, ["y"] = 4, ["z"] = 17, ["name"] = "birthstones:diamondblock"}, {["x"] = 0, ["y"] = 4, ["z"] = 18, ["name"] = "birthstones:diamondblock"}, {["x"] = 0, ["y"] = 4, ["z"] = 20, ["name"] = "birthstones:diamondblock"}, {["x"] = 0, ["y"] = 5, ["z"] = 3, ["name"] = "birthstones:diamondblock"}, {["x"] = 0, ["y"] = 5, ["z"] = 19, ["name"] = "birthstones:diamondblock"}, {["x"] = 0, ["y"] = 6, ["z"] = 2, ["name"] = "birthstones:diamondblock"}, {["x"] = 0, ["y"] = 6, ["z"] = 4, ["name"] = "birthstones:diamondblock"}, {["x"] = 0, ["y"] = 6, ["z"] = 5, ["name"] = "birthstones:diamondblock"}, {["x"] = 0, ["y"] = 6, ["z"] = 18, ["name"] = "birthstones:diamondblock"}, {["x"] = 0, ["y"] = 6, ["z"] = 20, ["name"] = "birthstones:diamondblock"}, {["x"] = 0, ["y"] = 6, ["z"] = 21, ["name"] = "birthstones:diamondblock"}, {["x"] = 0, ["y"] = 7, ["z"] = 1, ["name"] = "birthstones:diamondblock"}, {["x"] = 0, ["y"] = 7, ["z"] = 2, ["name"] = "birthstones:diamondblock"}, {["x"] = 0, ["y"] = 7, ["z"] = 5, ["name"] = "birthstones:diamondblock"}, {["x"] = 0, ["y"] = 7, ["z"] = 6, ["name"] = "birthstones:diamondblock"}, {["x"] = 0, ["y"] = 7, ["z"] = 17, ["name"] = "birthstones:diamondblock"}, {["x"] = 0, ["y"] = 7, ["z"] = 18, ["name"] = "birthstones:diamondblock"}, {["x"] = 0, ["y"] = 7, ["z"] = 21, ["name"] = "birthstones:diamondblock"}, {["x"] = 0, ["y"] = 7, ["z"] = 22, ["name"] = "birthstones:diamondblock"}, {["x"] = 0, ["y"] = 8, ["z"] = 0, ["name"] = "birthstones:diamondblock"}, {["x"] = 0, ["y"] = 8, ["z"] = 1, ["name"] = "birthstones:diamondblock"}, {["x"] = 0, ["y"] = 8, ["z"] = 6, ["name"] = "birthstones:diamondblock"}, {["x"] = 0, ["y"] = 8, ["z"] = 16, ["name"] = "birthstones:diamondblock"}, {["x"] = 0, ["y"] = 8, ["z"] = 17, ["name"] = "birthstones:diamondblock"}, {["x"] = 0, ["y"] = 8, ["z"] = 22, ["name"] = "birthstones:diamondblock"}, {["x"] = 0, ["y"] = 23, ["z"] = 11, ["name"] = "wool:white"}, {["x"] = 0, ["y"] = 24, ["z"] = 10, ["name"] = "wool:white"}, {["x"] = 0, ["y"] = 24, ["z"] = 11, ["name"] = "wool:white"}, {["x"] = 0, ["y"] = 24, ["z"] = 12, ["name"] = "wool:white"}, {["x"] = 0, ["y"] = 25, ["z"] = 11, ["name"] = "wool:white"}, {["x"] = 1, ["y"] = 5, ["z"] = 3, ["name"] = "birthstones:diamondblock"}, {["x"] = 1, ["y"] = 5, ["z"] = 19, ["name"] = "birthstones:diamondblock"}, {["x"] = 1, ["y"] = 22, ["z"] = 10, ["name"] = "wool:white"}, {["x"] = 1, ["y"] = 22, ["z"] = 11, ["name"] = "wool:white"}, {["x"] = 1, ["y"] = 22, ["z"] = 12, ["name"] = "wool:white"}, {["x"] = 1, ["y"] = 23, ["z"] = 9, ["name"] = "wool:white"}, {["x"] = 1, ["y"] = 23, ["z"] = 10, ["name"] = "wool:white"}, {["x"] = 1, ["y"] = 23, ["z"] = 12, ["name"] = "wool:white"}, {["x"] = 1, ["y"] = 23, ["z"] = 13, ["name"] = "wool:white"}, {["x"] = 1, ["y"] = 24, ["z"] = 9, ["name"] = "wool:white"}, {["x"] = 1, ["y"] = 24, ["z"] = 13, ["name"] = "wool:white"}, {["x"] = 1, ["y"] = 25, ["z"] = 9, ["name"] = "wool:white"}, {["x"] = 1, ["y"] = 25, ["z"] = 10, ["name"] = "wool:white"}, {["x"] = 1, ["y"] = 25, ["z"] = 12, ["name"] = "wool:white"}, {["x"] = 1, ["y"] = 25, ["z"] = 13, ["name"] = "wool:white"}, {["x"] = 1, ["y"] = 26, ["z"] = 10, ["name"] = "wool:white"}, {["x"] = 1, ["y"] = 26, ["z"] = 11, ["name"] = "wool:white"}, {["x"] = 1, ["y"] = 26, ["z"] = 12, ["name"] = "wool:white"}, {["x"] = 2, ["y"] = 2, ["z"] = 2, ["name"] = "default:wood"}, {["x"] = 2, ["y"] = 2, ["z"] = 3, ["name"] = "default:wood"}, {["x"] = 2, ["y"] = 2, ["z"] = 4, ["name"] = "default:wood"}, {["x"] = 2, ["y"] = 2, ["z"] = 18, ["name"] = "default:wood"}, {["x"] = 2, ["y"] = 2, ["z"] = 19, ["name"] = "default:wood"}, {["x"] = 2, ["y"] = 2, ["z"] = 20, ["name"] = "default:wood"}, {["x"] = 2, ["y"] = 3, ["z"] = 1, ["name"] = "default:wood"}, {["x"] = 2, ["y"] = 3, ["z"] = 5, ["name"] = "default:wood"}, {["x"] = 2, ["y"] = 3, ["z"] = 17, ["name"] = "default:wood"}, {["x"] = 2, ["y"] = 3, ["z"] = 21, ["name"] = "default:wood"}, {["x"] = 2, ["y"] = 4, ["z"] = 0, ["name"] = "default:wood"}, {["x"] = 2, ["y"] = 4, ["z"] = 6, ["name"] = "default:wood"}, {["x"] = 2, ["y"] = 4, ["z"] = 16, ["name"] = "default:wood"}, {["x"] = 2, ["y"] = 4, ["z"] = 22, ["name"] = "default:wood"}, {["x"] = 2, ["y"] = 5, ["z"] = 0, ["name"] = "default:wood"}, {["x"] = 2, ["y"] = 5, ["z"] = 3, ["name"] = "birthstones:diamondblock"}, {["x"] = 2, ["y"] = 5, ["z"] = 6, ["name"] = "default:wood"}, {["x"] = 2, ["y"] = 5, ["z"] = 16, ["name"] = "default:wood"}, {["x"] = 2, ["y"] = 5, ["z"] = 19, ["name"] = "birthstones:diamondblock"}, {["x"] = 2, ["y"] = 5, ["z"] = 22, ["name"] = "default:wood"}, {["x"] = 2, ["y"] = 6, ["z"] = 0, ["name"] = "default:wood"}, {["x"] = 2, ["y"] = 6, ["z"] = 6, ["name"] = "default:wood"}, {["x"] = 2, ["y"] = 6, ["z"] = 16, ["name"] = "default:wood"}, {["x"] = 2, ["y"] = 6, ["z"] = 22, ["name"] = "default:wood"}, {["x"] = 2, ["y"] = 7, ["z"] = 1, ["name"] = "default:wood"}, {["x"] = 2, ["y"] = 7, ["z"] = 5, ["name"] = "default:wood"}, {["x"] = 2, ["y"] = 7, ["z"] = 17, ["name"] = "default:wood"}, {["x"] = 2, ["y"] = 7, ["z"] = 21, ["name"] = "default:wood"}, {["x"] = 2, ["y"] = 8, ["z"] = 2, ["name"] = "default:wood"}, {["x"] = 2, ["y"] = 8, ["z"] = 3, ["name"] = "default:wood"}, {["x"] = 2, ["y"] = 8, ["z"] = 4, ["name"] = "default:wood"}, {["x"] = 2, ["y"] = 8, ["z"] = 18, ["name"] = "default:wood"}, {["x"] = 2, ["y"] = 8, ["z"] = 19, ["name"] = "default:wood"}, {["x"] = 2, ["y"] = 8, ["z"] = 20, ["name"] = "default:wood"}, {["x"] = 2, ["y"] = 14, ["param1"] = 127, ["z"] = 7, ["name"] = "default:fence_wood"}, {["x"] = 2, ["y"] = 14, ["param1"] = 127, ["z"] = 15, ["name"] = "default:fence_wood"}, {["x"] = 2, ["y"] = 15, ["param1"] = 111, ["z"] = 7, ["name"] = "default:fence_wood"}, {["x"] = 2, ["y"] = 15, ["param1"] = 111, ["z"] = 15, ["name"] = "default:fence_wood"}, {["x"] = 2, ["y"] = 16, ["param1"] = 95, ["z"] = 7, ["name"] = "default:fence_wood"}, {["x"] = 2, ["y"] = 16, ["param1"] = 95, ["z"] = 15, ["name"] = "default:fence_wood"}, {["x"] = 2, ["y"] = 17, ["param1"] = 79, ["z"] = 7, ["name"] = "default:fence_wood"}, {["x"] = 2, ["y"] = 17, ["param1"] = 63, ["z"] = 8, ["name"] = "default:fence_wood"}, {["x"] = 2, ["y"] = 17, ["param1"] = 63, ["z"] = 14, ["name"] = "default:fence_wood"}, {["x"] = 2, ["y"] = 17, ["param1"] = 79, ["z"] = 15, ["name"] = "default:fence_wood"}, {["x"] = 2, ["y"] = 18, ["param1"] = 47, ["z"] = 8, ["name"] = "default:fence_wood"}, {["x"] = 2, ["y"] = 18, ["param1"] = 47, ["z"] = 14, ["name"] = "default:fence_wood"}, {["x"] = 2, ["y"] = 19, ["param1"] = 31, ["z"] = 8, ["name"] = "default:fence_wood"}, {["x"] = 2, ["y"] = 19, ["param1"] = 31, ["z"] = 14, ["name"] = "default:fence_wood"}, {["x"] = 2, ["y"] = 20, ["param1"] = 15, ["z"] = 8, ["name"] = "default:fence_wood"}, {["x"] = 2, ["y"] = 20, ["param1"] = 15, ["z"] = 14, ["name"] = "default:fence_wood"}, {["x"] = 2, ["y"] = 21, ["param1"] = 15, ["z"] = 8, ["name"] = "default:fence_wood"}, {["x"] = 2, ["y"] = 21, ["param1"] = 14, ["z"] = 9, ["name"] = "default:fence_wood"}, {["x"] = 2, ["y"] = 21, ["param1"] = 13, ["z"] = 10, ["name"] = "default:fence_wood"}, {["x"] = 2, ["y"] = 21, ["param1"] = 12, ["z"] = 11, ["name"] = "default:fence_wood"}, {["x"] = 2, ["y"] = 21, ["param1"] = 13, ["z"] = 12, ["name"] = "default:fence_wood"}, {["x"] = 2, ["y"] = 21, ["param1"] = 14, ["z"] = 13, ["name"] = "default:fence_wood"}, {["x"] = 2, ["y"] = 21, ["param1"] = 15, ["z"] = 14, ["name"] = "default:fence_wood"}, {["x"] = 2, ["y"] = 22, ["param1"] = 15, ["z"] = 8, ["name"] = "default:fence_wood"}, {["x"] = 2, ["y"] = 22, ["param1"] = 15, ["z"] = 9, ["name"] = "wool:white"}, {["x"] = 2, ["y"] = 22, ["param1"] = 15, ["z"] = 10, ["name"] = "wool:white"}, {["x"] = 2, ["y"] = 22, ["param1"] = 15, ["z"] = 11, ["name"] = "wool:white"}, {["x"] = 2, ["y"] = 22, ["param1"] = 15, ["z"] = 12, ["name"] = "wool:white"}, {["x"] = 2, ["y"] = 22, ["param1"] = 15, ["z"] = 13, ["name"] = "wool:white"}, {["x"] = 2, ["y"] = 22, ["param1"] = 15, ["z"] = 14, ["name"] = "default:fence_wood"}, {["x"] = 2, ["y"] = 23, ["param1"] = 15, ["z"] = 8, ["name"] = "default:fence_wood"}, {["x"] = 2, ["y"] = 23, ["param1"] = 15, ["z"] = 9, ["name"] = "wool:white"}, {["x"] = 2, ["y"] = 23, ["param1"] = 15, ["z"] = 13, ["name"] = "wool:white"}, {["x"] = 2, ["y"] = 23, ["param1"] = 15, ["z"] = 14, ["name"] = "default:fence_wood"}, {["x"] = 2, ["y"] = 24, ["param1"] = 15, ["z"] = 8, ["name"] = "default:fence_wood"}, {["x"] = 2, ["y"] = 24, ["param1"] = 15, ["z"] = 9, ["name"] = "wool:white"}, {["x"] = 2, ["y"] = 24, ["param1"] = 15, ["z"] = 13, ["name"] = "wool:white"}, {["x"] = 2, ["y"] = 24, ["param1"] = 15, ["z"] = 14, ["name"] = "default:fence_wood"}, {["x"] = 2, ["y"] = 25, ["param1"] = 15, ["z"] = 8, ["name"] = "default:fence_wood"}, {["x"] = 2, ["y"] = 25, ["param1"] = 15, ["z"] = 9, ["name"] = "wool:white"}, {["x"] = 2, ["y"] = 25, ["param1"] = 15, ["z"] = 13, ["name"] = "wool:white"}, {["x"] = 2, ["y"] = 25, ["param1"] = 15, ["z"] = 14, ["name"] = "default:fence_wood"}, {["x"] = 2, ["y"] = 26, ["param1"] = 15, ["z"] = 8, ["name"] = "default:fence_wood"}, {["x"] = 2, ["y"] = 26, ["param1"] = 15, ["z"] = 9, ["name"] = "wool:white"}, {["x"] = 2, ["y"] = 26, ["param1"] = 15, ["z"] = 10, ["name"] = "wool:white"}, {["x"] = 2, ["y"] = 26, ["param1"] = 15, ["z"] = 11, ["name"] = "wool:white"}, {["x"] = 2, ["y"] = 26, ["param1"] = 15, ["z"] = 12, ["name"] = "wool:white"}, {["x"] = 2, ["y"] = 26, ["param1"] = 15, ["z"] = 13, ["name"] = "wool:white"}, {["x"] = 2, ["y"] = 26, ["param1"] = 15, ["z"] = 14, ["name"] = "default:fence_wood"}, {["x"] = 2, ["y"] = 27, ["param1"] = 15, ["z"] = 8, ["name"] = "default:fence_wood"}, {["x"] = 2, ["y"] = 27, ["param1"] = 15, ["z"] = 9, ["name"] = "default:fence_wood"}, {["x"] = 2, ["y"] = 27, ["param1"] = 15, ["z"] = 10, ["name"] = "default:fence_wood"}, {["x"] = 2, ["y"] = 27, ["param1"] = 15, ["z"] = 11, ["name"] = "default:fence_wood"}, {["x"] = 2, ["y"] = 27, ["param1"] = 15, ["z"] = 12, ["name"] = "default:fence_wood"}, {["x"] = 2, ["y"] = 27, ["param1"] = 15, ["z"] = 13, ["name"] = "default:fence_wood"}, {["x"] = 2, ["y"] = 27, ["param1"] = 15, ["z"] = 14, ["name"] = "default:fence_wood"}, {["x"] = 3, ["y"] = 0, ["z"] = 11, ["name"] = "default:wood"}, {["x"] = 3, ["y"] = 1, ["z"] = 9, ["name"] = "default:wood"}, {["x"] = 3, ["y"] = 1, ["z"] = 10, ["name"] = "default:wood"}, {["x"] = 3, ["y"] = 1, ["z"] = 11, ["name"] = "default:wood"}, {["x"] = 3, ["y"] = 1, ["z"] = 12, ["name"] = "default:wood"}, {["x"] = 3, ["y"] = 1, ["z"] = 13, ["name"] = "default:wood"}, {["x"] = 3, ["y"] = 2, ["z"] = 2, ["name"] = "default:wood"}, {["x"] = 3, ["y"] = 2, ["z"] = 3, ["name"] = "default:wood"}, {["x"] = 3, ["y"] = 2, ["z"] = 4, ["name"] = "default:wood"}, {["x"] = 3, ["y"] = 2, ["z"] = 8, ["name"] = "default:wood"}, {["x"] = 3, ["y"] = 2, ["z"] = 9, ["name"] = "default:wood"}, {["x"] = 3, ["y"] = 2, ["z"] = 10, ["name"] = "default:wood"}, {["x"] = 3, ["y"] = 2, ["z"] = 11, ["name"] = "default:wood"}, {["x"] = 3, ["y"] = 2, ["z"] = 12, ["name"] = "default:wood"}, {["x"] = 3, ["y"] = 2, ["z"] = 13, ["name"] = "default:wood"}, {["x"] = 3, ["y"] = 2, ["z"] = 14, ["name"] = "default:wood"}, {["x"] = 3, ["y"] = 2, ["z"] = 18, ["name"] = "default:wood"}, {["x"] = 3, ["y"] = 2, ["z"] = 19, ["name"] = "default:wood"}, {["x"] = 3, ["y"] = 2, ["z"] = 20, ["name"] = "default:wood"}, {["x"] = 3, ["y"] = 3, ["z"] = 1, ["name"] = "default:wood"}, {["x"] = 3, ["y"] = 3, ["z"] = 2, ["name"] = "default:wood"}, {["x"] = 3, ["y"] = 3, ["z"] = 3, ["name"] = "default:wood"}, {["x"] = 3, ["y"] = 3, ["z"] = 4, ["name"] = "default:wood"}, {["x"] = 3, ["y"] = 3, ["z"] = 5, ["name"] = "default:wood"}, {["x"] = 3, ["y"] = 3, ["z"] = 7, ["name"] = "default:wood"}, {["x"] = 3, ["y"] = 3, ["z"] = 8, ["name"] = "default:wood"}, {["x"] = 3, ["y"] = 3, ["z"] = 9, ["name"] = "default:wood"}, {["x"] = 3, ["y"] = 3, ["z"] = 10, ["name"] = "default:wood"}, {["x"] = 3, ["y"] = 3, ["z"] = 11, ["name"] = "default:wood"}, {["x"] = 3, ["y"] = 3, ["z"] = 12, ["name"] = "default:wood"}, {["x"] = 3, ["y"] = 3, ["z"] = 13, ["name"] = "default:wood"}, {["x"] = 3, ["y"] = 3, ["z"] = 14, ["name"] = "default:wood"}, {["x"] = 3, ["y"] = 3, ["z"] = 15, ["name"] = "default:wood"}, {["x"] = 3, ["y"] = 3, ["z"] = 17, ["name"] = "default:wood"}, {["x"] = 3, ["y"] = 3, ["z"] = 18, ["name"] = "default:wood"}, {["x"] = 3, ["y"] = 3, ["z"] = 19, ["name"] = "default:wood"}, {["x"] = 3, ["y"] = 3, ["z"] = 20, ["name"] = "default:wood"}, {["x"] = 3, ["y"] = 3, ["z"] = 21, ["name"] = "default:wood"}, {["x"] = 3, ["y"] = 4, ["z"] = 0, ["name"] = "default:wood"}, {["x"] = 3, ["y"] = 4, ["z"] = 1, ["name"] = "default:wood"}, {["x"] = 3, ["y"] = 4, ["z"] = 2, ["name"] = "default:wood"}, {["x"] = 3, ["y"] = 4, ["z"] = 3, ["name"] = "default:wood"}, {["x"] = 3, ["y"] = 4, ["z"] = 4, ["name"] = "default:wood"}, {["x"] = 3, ["y"] = 4, ["z"] = 5, ["name"] = "default:wood"}, {["x"] = 3, ["y"] = 4, ["z"] = 6, ["name"] = "default:wood"}, {["x"] = 3, ["y"] = 4, ["z"] = 7, ["name"] = "default:wood"}, {["x"] = 3, ["y"] = 4, ["z"] = 8, ["name"] = "default:wood"}, {["x"] = 3, ["y"] = 4, ["z"] = 9, ["name"] = "default:wood"}, {["x"] = 3, ["y"] = 4, ["z"] = 10, ["name"] = "default:wood"}, {["x"] = 3, ["y"] = 4, ["z"] = 11, ["name"] = "default:wood"}, {["x"] = 3, ["y"] = 4, ["z"] = 12, ["name"] = "default:wood"}, {["x"] = 3, ["y"] = 4, ["z"] = 13, ["name"] = "default:wood"}, {["x"] = 3, ["y"] = 4, ["z"] = 14, ["name"] = "default:wood"}, {["x"] = 3, ["y"] = 4, ["z"] = 15, ["name"] = "default:wood"}, {["x"] = 3, ["y"] = 4, ["z"] = 16, ["name"] = "default:wood"}, {["x"] = 3, ["y"] = 4, ["z"] = 17, ["name"] = "default:wood"}, {["x"] = 3, ["y"] = 4, ["z"] = 18, ["name"] = "default:wood"}, {["x"] = 3, ["y"] = 4, ["z"] = 19, ["name"] = "default:wood"}, {["x"] = 3, ["y"] = 4, ["z"] = 20, ["name"] = "default:wood"}, {["x"] = 3, ["y"] = 4, ["z"] = 21, ["name"] = "default:wood"}, {["x"] = 3, ["y"] = 4, ["z"] = 22, ["name"] = "default:wood"}, {["x"] = 3, ["y"] = 5, ["z"] = 0, ["name"] = "default:wood"}, {["x"] = 3, ["y"] = 5, ["z"] = 1, ["name"] = "default:wood"}, {["x"] = 3, ["y"] = 5, ["z"] = 2, ["name"] = "default:wood"}, {["x"] = 3, ["y"] = 5, ["z"] = 3, ["name"] = "default:wood"}, {["x"] = 3, ["y"] = 5, ["z"] = 4, ["name"] = "default:wood"}, {["x"] = 3, ["y"] = 5, ["z"] = 5, ["name"] = "default:wood"}, {["x"] = 3, ["y"] = 5, ["z"] = 6, ["name"] = "default:wood"}, {["x"] = 3, ["y"] = 5, ["z"] = 7, ["name"] = "default:wood"}, {["x"] = 3, ["y"] = 5, ["z"] = 8, ["name"] = "default:wood"}, {["x"] = 3, ["y"] = 5, ["z"] = 9, ["name"] = "default:wood"}, {["x"] = 3, ["y"] = 5, ["z"] = 10, ["name"] = "default:wood"}, {["x"] = 3, ["y"] = 5, ["z"] = 11, ["name"] = "default:wood"}, {["x"] = 3, ["y"] = 5, ["z"] = 12, ["name"] = "default:wood"}, {["x"] = 3, ["y"] = 5, ["z"] = 13, ["name"] = "default:wood"}, {["x"] = 3, ["y"] = 5, ["z"] = 14, ["name"] = "default:wood"}, {["x"] = 3, ["y"] = 5, ["z"] = 15, ["name"] = "default:wood"}, {["x"] = 3, ["y"] = 5, ["z"] = 16, ["name"] = "default:wood"}, {["x"] = 3, ["y"] = 5, ["z"] = 17, ["name"] = "default:wood"}, {["x"] = 3, ["y"] = 5, ["z"] = 18, ["name"] = "default:wood"}, {["x"] = 3, ["y"] = 5, ["param1"] = 14, ["z"] = 19, ["name"] = "default:wood"}, {["x"] = 3, ["y"] = 5, ["z"] = 20, ["name"] = "default:wood"}, {["x"] = 3, ["y"] = 5, ["z"] = 21, ["name"] = "default:wood"}, {["x"] = 3, ["y"] = 5, ["z"] = 22, ["name"] = "default:wood"}, {["x"] = 3, ["y"] = 6, ["z"] = 0, ["name"] = "default:wood"}, {["x"] = 3, ["y"] = 6, ["z"] = 1, ["name"] = "default:wood"}, {["x"] = 3, ["y"] = 6, ["z"] = 2, ["name"] = "default:wood"}, {["x"] = 3, ["y"] = 6, ["z"] = 3, ["name"] = "default:wood"}, {["x"] = 3, ["y"] = 6, ["z"] = 4, ["name"] = "default:wood"}, {["x"] = 3, ["y"] = 6, ["z"] = 5, ["name"] = "default:wood"}, {["x"] = 3, ["y"] = 6, ["z"] = 6, ["name"] = "default:wood"}, {["x"] = 3, ["y"] = 6, ["z"] = 7, ["name"] = "default:wood"}, {["x"] = 3, ["y"] = 6, ["z"] = 8, ["name"] = "default:wood"}, {["x"] = 3, ["y"] = 6, ["z"] = 9, ["name"] = "default:wood"}, {["x"] = 3, ["y"] = 6, ["z"] = 10, ["name"] = "default:wood"}, {["x"] = 3, ["y"] = 6, ["z"] = 11, ["name"] = "default:wood"}, {["x"] = 3, ["y"] = 6, ["z"] = 12, ["name"] = "default:wood"}, {["x"] = 3, ["y"] = 6, ["z"] = 13, ["name"] = "default:wood"}, {["x"] = 3, ["y"] = 6, ["z"] = 14, ["name"] = "default:wood"}, {["x"] = 3, ["y"] = 6, ["z"] = 15, ["name"] = "default:wood"}, {["x"] = 3, ["y"] = 6, ["z"] = 16, ["name"] = "default:wood"}, {["x"] = 3, ["y"] = 6, ["z"] = 17, ["name"] = "default:wood"}, {["x"] = 3, ["y"] = 6, ["z"] = 18, ["name"] = "default:wood"}, {["x"] = 3, ["y"] = 6, ["z"] = 19, ["name"] = "default:wood"}, {["x"] = 3, ["y"] = 6, ["z"] = 20, ["name"] = "default:wood"}, {["x"] = 3, ["y"] = 6, ["z"] = 21, ["name"] = "default:wood"}, {["x"] = 3, ["y"] = 6, ["z"] = 22, ["name"] = "default:wood"}, {["x"] = 3, ["y"] = 7, ["z"] = 1, ["name"] = "default:wood"}, {["x"] = 3, ["y"] = 7, ["z"] = 2, ["name"] = "default:wood"}, {["x"] = 3, ["y"] = 7, ["z"] = 3, ["name"] = "default:wood"}, {["x"] = 3, ["y"] = 7, ["z"] = 4, ["name"] = "default:wood"}, {["x"] = 3, ["y"] = 7, ["z"] = 5, ["name"] = "default:wood"}, {["x"] = 3, ["y"] = 7, ["z"] = 6, ["name"] = "default:wood"}, {["x"] = 3, ["y"] = 7, ["z"] = 7, ["name"] = "default:wood"}, {["x"] = 3, ["y"] = 7, ["z"] = 8, ["name"] = "default:wood"}, {["x"] = 3, ["y"] = 7, ["z"] = 9, ["name"] = "default:wood"}, {["x"] = 3, ["y"] = 7, ["z"] = 10, ["name"] = "default:wood"}, {["x"] = 3, ["y"] = 7, ["z"] = 11, ["name"] = "default:wood"}, {["x"] = 3, ["y"] = 7, ["z"] = 12, ["name"] = "default:wood"}, {["x"] = 3, ["y"] = 7, ["z"] = 13, ["name"] = "default:wood"}, {["x"] = 3, ["y"] = 7, ["z"] = 14, ["name"] = "default:wood"}, {["x"] = 3, ["y"] = 7, ["z"] = 15, ["name"] = "default:wood"}, {["x"] = 3, ["y"] = 7, ["z"] = 16, ["name"] = "default:wood"}, {["x"] = 3, ["y"] = 7, ["z"] = 17, ["name"] = "default:wood"}, {["x"] = 3, ["y"] = 7, ["z"] = 18, ["name"] = "default:wood"}, {["x"] = 3, ["y"] = 7, ["z"] = 19, ["name"] = "default:wood"}, {["x"] = 3, ["y"] = 7, ["z"] = 20, ["name"] = "default:wood"}, {["x"] = 3, ["y"] = 7, ["z"] = 21, ["name"] = "default:wood"}, {["x"] = 3, ["y"] = 8, ["z"] = 2, ["name"] = "default:wood"}, {["x"] = 3, ["y"] = 8, ["z"] = 3, ["name"] = "default:wood"}, {["x"] = 3, ["y"] = 8, ["z"] = 4, ["name"] = "default:wood"}, {["x"] = 3, ["y"] = 8, ["param1"] = 191, ["z"] = 6, ["name"] = "default:fence_wood"}, {["x"] = 3, ["y"] = 8, ["param1"] = 206, ["z"] = 7, ["name"] = "default:fence_wood"}, {["x"] = 3, ["y"] = 8, ["param1"] = 190, ["z"] = 8, ["name"] = "default:fence_wood"}, {["x"] = 3, ["y"] = 8, ["param1"] = 173, ["z"] = 9, ["name"] = "default:fence_wood"}, {["x"] = 3, ["y"] = 8, ["param1"] = 156, ["z"] = 10, ["name"] = "default:fence_wood"}, {["x"] = 3, ["y"] = 8, ["param1"] = 139, ["z"] = 11, ["name"] = "default:fence_wood"}, {["x"] = 3, ["y"] = 8, ["param1"] = 156, ["z"] = 12, ["name"] = "default:fence_wood"}, {["x"] = 3, ["y"] = 8, ["param1"] = 173, ["z"] = 13, ["name"] = "default:fence_wood"}, {["x"] = 3, ["y"] = 8, ["param1"] = 190, ["z"] = 14, ["name"] = "default:fence_wood"}, {["x"] = 3, ["y"] = 8, ["param1"] = 206, ["z"] = 15, ["name"] = "default:fence_wood"}, {["x"] = 3, ["y"] = 8, ["param1"] = 191, ["z"] = 16, ["name"] = "default:fence_wood"}, {["x"] = 3, ["y"] = 8, ["z"] = 18, ["name"] = "default:wood"}, {["x"] = 3, ["y"] = 8, ["z"] = 19, ["name"] = "default:wood"}, {["x"] = 3, ["y"] = 8, ["z"] = 20, ["name"] = "default:wood"}, {["x"] = 3, ["y"] = 9, ["param1"] = 207, ["z"] = 6, ["name"] = "default:fence_wood"}, {["x"] = 3, ["param2"] = 1, ["y"] = 9, ["param1"] = 222, ["z"] = 7, ["name"] = "homedecor:glowlight_small_cube_on"}, {["x"] = 3, ["param2"] = 1, ["y"] = 9, ["param1"] = 222, ["z"] = 15, ["name"] = "homedecor:glowlight_small_cube_on"}, {["x"] = 3, ["y"] = 9, ["param1"] = 207, ["z"] = 16, ["name"] = "default:fence_wood"}, {["x"] = 3, ["y"] = 10, ["param1"] = 191, ["z"] = 6, ["name"] = "default:fence_wood"}, {["x"] = 3, ["y"] = 10, ["param1"] = 191, ["z"] = 16, ["name"] = "default:fence_wood"}, {["x"] = 3, ["y"] = 11, ["param1"] = 175, ["z"] = 6, ["name"] = "default:fence_wood"}, {["x"] = 3, ["y"] = 11, ["param1"] = 175, ["z"] = 16, ["name"] = "default:fence_wood"}, {["x"] = 3, ["y"] = 12, ["param1"] = 159, ["z"] = 6, ["name"] = "default:fence_wood"}, {["x"] = 3, ["y"] = 12, ["param1"] = 175, ["z"] = 7, ["name"] = "default:fence_wood"}, {["x"] = 3, ["y"] = 12, ["param1"] = 175, ["z"] = 15, ["name"] = "default:fence_wood"}, {["x"] = 3, ["y"] = 12, ["param1"] = 159, ["z"] = 16, ["name"] = "default:fence_wood"}, {["x"] = 3, ["y"] = 13, ["param1"] = 159, ["z"] = 7, ["name"] = "default:fence_wood"}, {["x"] = 3, ["y"] = 13, ["param1"] = 159, ["z"] = 15, ["name"] = "default:fence_wood"}, {["x"] = 3, ["y"] = 14, ["param1"] = 143, ["z"] = 7, ["name"] = "default:fence_wood"}, {["x"] = 3, ["y"] = 14, ["param1"] = 143, ["z"] = 15, ["name"] = "default:fence_wood"}, {["x"] = 3, ["y"] = 15, ["param1"] = 127, ["z"] = 7, ["name"] = "default:fence_wood"}, {["x"] = 3, ["y"] = 15, ["param1"] = 127, ["z"] = 15, ["name"] = "default:fence_wood"}, {["x"] = 3, ["y"] = 21, ["param1"] = 15, ["z"] = 10, ["name"] = "wool:white"}, {["x"] = 3, ["y"] = 21, ["param1"] = 15, ["z"] = 11, ["name"] = "wool:white"}, {["x"] = 3, ["y"] = 21, ["param1"] = 15, ["z"] = 12, ["name"] = "wool:white"}, {["x"] = 3, ["y"] = 22, ["param1"] = 15, ["z"] = 9, ["name"] = "wool:white"}, {["x"] = 3, ["y"] = 22, ["param1"] = 15, ["z"] = 13, ["name"] = "wool:white"}, {["x"] = 3, ["y"] = 23, ["param1"] = 15, ["z"] = 8, ["name"] = "wool:white"}, {["x"] = 3, ["y"] = 23, ["param1"] = 15, ["z"] = 14, ["name"] = "wool:white"}, {["x"] = 3, ["y"] = 24, ["param1"] = 15, ["z"] = 8, ["name"] = "wool:white"}, {["x"] = 3, ["y"] = 24, ["param1"] = 15, ["z"] = 14, ["name"] = "wool:white"}, {["x"] = 3, ["y"] = 25, ["param1"] = 15, ["z"] = 8, ["name"] = "wool:white"}, {["x"] = 3, ["y"] = 25, ["param1"] = 15, ["z"] = 14, ["name"] = "wool:white"}, {["x"] = 3, ["y"] = 26, ["param1"] = 15, ["z"] = 9, ["name"] = "wool:white"}, {["x"] = 3, ["y"] = 26, ["param1"] = 15, ["z"] = 13, ["name"] = "wool:white"}, {["x"] = 3, ["y"] = 27, ["param1"] = 15, ["z"] = 10, ["name"] = "wool:white"}, {["x"] = 3, ["y"] = 27, ["param1"] = 15, ["z"] = 11, ["name"] = "wool:white"}, {["x"] = 3, ["y"] = 27, ["param1"] = 15, ["z"] = 12, ["name"] = "wool:white"}, {["x"] = 4, ["y"] = 0, ["z"] = 11, ["name"] = "default:wood"}, {["x"] = 4, ["y"] = 1, ["z"] = 9, ["name"] = "default:wood"}, {["x"] = 4, ["y"] = 1, ["z"] = 10, ["name"] = "default:wood"}, {["x"] = 4, ["y"] = 1, ["z"] = 12, ["name"] = "default:wood"}, {["x"] = 4, ["y"] = 1, ["z"] = 13, ["name"] = "default:wood"}, {["x"] = 4, ["y"] = 2, ["param1"] = 15, ["z"] = 2, ["name"] = "default:wood"}, {["x"] = 4, ["y"] = 2, ["param1"] = 15, ["z"] = 3, ["name"] = "default:wood"}, {["x"] = 4, ["y"] = 2, ["param1"] = 15, ["z"] = 4, ["name"] = "default:wood"}, {["x"] = 4, ["y"] = 2, ["z"] = 8, ["name"] = "default:wood"}, {["x"] = 4, ["y"] = 2, ["z"] = 14, ["name"] = "default:wood"}, {["x"] = 4, ["y"] = 2, ["param1"] = 15, ["z"] = 18, ["name"] = "default:wood"}, {["x"] = 4, ["y"] = 2, ["param1"] = 15, ["z"] = 19, ["name"] = "default:wood"}, {["x"] = 4, ["y"] = 2, ["param1"] = 15, ["z"] = 20, ["name"] = "default:wood"}, {["x"] = 4, ["y"] = 3, ["param1"] = 15, ["z"] = 1, ["name"] = "default:wood"}, {["x"] = 4, ["y"] = 3, ["param1"] = 15, ["z"] = 5, ["name"] = "default:wood"}, {["x"] = 4, ["y"] = 3, ["z"] = 7, ["name"] = "default:wood"}, {["x"] = 4, ["y"] = 3, ["z"] = 15, ["name"] = "default:wood"}, {["x"] = 4, ["y"] = 3, ["param1"] = 15, ["z"] = 17, ["name"] = "default:wood"}, {["x"] = 4, ["y"] = 3, ["param1"] = 15, ["z"] = 21, ["name"] = "default:wood"}, {["x"] = 4, ["y"] = 4, ["param1"] = 15, ["z"] = 0, ["name"] = "default:wood"}, {["x"] = 4, ["y"] = 4, ["param1"] = 14, ["z"] = 6, ["name"] = "default:wood"}, {["x"] = 4, ["y"] = 4, ["z"] = 7, ["name"] = "default:wood"}, {["x"] = 4, ["y"] = 4, ["z"] = 15, ["name"] = "default:wood"}, {["x"] = 4, ["y"] = 4, ["param1"] = 14, ["z"] = 16, ["name"] = "default:wood"}, {["x"] = 4, ["y"] = 4, ["param1"] = 15, ["z"] = 22, ["name"] = "default:wood"}, {["x"] = 4, ["y"] = 5, ["param1"] = 15, ["z"] = 0, ["name"] = "default:wood"}, {["x"] = 4, ["y"] = 5, ["z"] = 6, ["name"] = "default:wood"}, {["x"] = 4, ["y"] = 5, ["z"] = 16, ["name"] = "default:wood"}, {["x"] = 4, ["y"] = 5, ["param1"] = 15, ["z"] = 22, ["name"] = "default:wood"}, {["x"] = 4, ["y"] = 6, ["param1"] = 15, ["z"] = 0, ["name"] = "default:wood"}, {["x"] = 4, ["y"] = 6, ["z"] = 6, ["name"] = "default:wood"}, {["x"] = 4, ["y"] = 6, ["z"] = 16, ["name"] = "default:wood"}, {["x"] = 4, ["y"] = 6, ["param1"] = 15, ["z"] = 22, ["name"] = "default:wood"}, {["x"] = 4, ["y"] = 7, ["param1"] = 14, ["z"] = 1, ["name"] = "default:wood"}, {["x"] = 4, ["y"] = 7, ["param1"] = 14, ["z"] = 5, ["name"] = "default:wood"}, {["x"] = 4, ["y"] = 7, ["z"] = 6, ["name"] = "default:wood"}, {["x"] = 4, ["y"] = 7, ["param1"] = 15, ["z"] = 7, ["name"] = "default:wood"}, {["x"] = 4, ["y"] = 7, ["param1"] = 15, ["z"] = 8, ["name"] = "default:wood"}, {["x"] = 4, ["y"] = 7, ["param1"] = 15, ["z"] = 9, ["name"] = "default:wood"}, {["x"] = 4, ["y"] = 7, ["param1"] = 15, ["z"] = 10, ["name"] = "default:wood"}, {["x"] = 4, ["y"] = 7, ["param1"] = 15, ["z"] = 11, ["name"] = "default:wood"}, {["x"] = 4, ["y"] = 7, ["param1"] = 15, ["z"] = 12, ["name"] = "default:wood"}, {["x"] = 4, ["y"] = 7, ["z"] = 13, ["name"] = "default:wood"}, {["x"] = 4, ["y"] = 7, ["z"] = 14, ["name"] = "default:wood"}, {["x"] = 4, ["y"] = 7, ["z"] = 15, ["name"] = "default:wood"}, {["x"] = 4, ["y"] = 7, ["z"] = 16, ["name"] = "default:wood"}, {["x"] = 4, ["y"] = 7, ["param1"] = 14, ["z"] = 17, ["name"] = "default:wood"}, {["x"] = 4, ["y"] = 7, ["param1"] = 15, ["z"] = 21, ["name"] = "default:wood"}, {["x"] = 4, ["y"] = 8, ["param1"] = 14, ["z"] = 2, ["name"] = "default:wood"}, {["x"] = 4, ["y"] = 8, ["param1"] = 14, ["z"] = 3, ["name"] = "default:wood"}, {["x"] = 4, ["y"] = 8, ["param1"] = 14, ["z"] = 4, ["name"] = "default:wood"}, {["x"] = 4, ["y"] = 8, ["param1"] = 206, ["z"] = 6, ["name"] = "default:fence_wood"}, {["x"] = 4, ["y"] = 8, ["param1"] = 206, ["z"] = 16, ["name"] = "default:fence_wood"}, {["x"] = 4, ["y"] = 8, ["param1"] = 14, ["z"] = 18, ["name"] = "default:wood"}, {["x"] = 4, ["y"] = 8, ["param1"] = 14, ["z"] = 19, ["name"] = "default:wood"}, {["x"] = 4, ["y"] = 8, ["param1"] = 14, ["z"] = 20, ["name"] = "default:wood"}, {["x"] = 4, ["param2"] = 1, ["y"] = 9, ["param1"] = 222, ["z"] = 6, ["name"] = "homedecor:glowlight_small_cube_on"}, {["x"] = 4, ["param2"] = 1, ["y"] = 9, ["param1"] = 222, ["z"] = 16, ["name"] = "homedecor:glowlight_small_cube_on"}, {["x"] = 4, ["y"] = 21, ["param1"] = 15, ["z"] = 9, ["name"] = "wool:white"}, {["x"] = 4, ["y"] = 21, ["param1"] = 15, ["z"] = 10, ["name"] = "wool:white"}, {["x"] = 4, ["y"] = 21, ["param1"] = 15, ["z"] = 11, ["name"] = "wool:white"}, {["x"] = 4, ["y"] = 21, ["param1"] = 15, ["z"] = 12, ["name"] = "wool:white"}, {["x"] = 4, ["y"] = 21, ["param1"] = 15, ["z"] = 13, ["name"] = "wool:white"}, {["x"] = 4, ["y"] = 22, ["param1"] = 15, ["z"] = 8, ["name"] = "wool:white"}, {["x"] = 4, ["y"] = 22, ["param1"] = 15, ["z"] = 14, ["name"] = "wool:white"}, {["x"] = 4, ["y"] = 23, ["param1"] = 15, ["z"] = 8, ["name"] = "wool:white"}, {["x"] = 4, ["y"] = 23, ["param1"] = 15, ["z"] = 14, ["name"] = "wool:white"}, {["x"] = 4, ["y"] = 24, ["param1"] = 15, ["z"] = 8, ["name"] = "wool:white"}, {["x"] = 4, ["y"] = 24, ["param1"] = 221, ["z"] = 11, ["name"] = "caverealms:glow_crystal"}, {["x"] = 4, ["y"] = 24, ["param1"] = 15, ["z"] = 14, ["name"] = "wool:white"}, {["x"] = 4, ["y"] = 25, ["param1"] = 15, ["z"] = 8, ["name"] = "wool:white"}, {["x"] = 4, ["y"] = 25, ["param1"] = 15, ["z"] = 14, ["name"] = "wool:white"}, {["x"] = 4, ["y"] = 26, ["param1"] = 15, ["z"] = 8, ["name"] = "wool:white"}, {["x"] = 4, ["y"] = 26, ["param1"] = 15, ["z"] = 14, ["name"] = "wool:white"}, {["x"] = 4, ["y"] = 27, ["param1"] = 15, ["z"] = 9, ["name"] = "wool:white"}, {["x"] = 4, ["y"] = 27, ["param1"] = 15, ["z"] = 10, ["name"] = "wool:white"}, {["x"] = 4, ["y"] = 27, ["param1"] = 15, ["z"] = 11, ["name"] = "wool:white"}, {["x"] = 4, ["y"] = 27, ["param1"] = 15, ["z"] = 12, ["name"] = "wool:white"}, {["x"] = 4, ["y"] = 27, ["param1"] = 15, ["z"] = 13, ["name"] = "wool:white"}, {["x"] = 5, ["y"] = 0, ["z"] = 11, ["name"] = "default:wood"}, {["x"] = 5, ["y"] = 1, ["z"] = 9, ["name"] = "default:wood"}, {["x"] = 5, ["y"] = 1, ["z"] = 10, ["name"] = "default:wood"}, {["x"] = 5, ["y"] = 1, ["z"] = 12, ["name"] = "default:wood"}, {["x"] = 5, ["y"] = 1, ["z"] = 13, ["name"] = "default:wood"}, {["x"] = 5, ["y"] = 2, ["param1"] = 15, ["z"] = 2, ["name"] = "default:wood"}, {["x"] = 5, ["y"] = 2, ["param1"] = 15, ["z"] = 3, ["name"] = "default:wood"}, {["x"] = 5, ["y"] = 2, ["param1"] = 15, ["z"] = 4, ["name"] = "default:wood"}, {["x"] = 5, ["y"] = 2, ["z"] = 8, ["name"] = "default:wood"}, {["x"] = 5, ["y"] = 2, ["z"] = 14, ["name"] = "default:wood"}, {["x"] = 5, ["y"] = 2, ["param1"] = 15, ["z"] = 18, ["name"] = "default:wood"}, {["x"] = 5, ["y"] = 2, ["param1"] = 15, ["z"] = 19, ["name"] = "default:wood"}, {["x"] = 5, ["y"] = 2, ["param1"] = 15, ["z"] = 20, ["name"] = "default:wood"}, {["x"] = 5, ["y"] = 3, ["param1"] = 15, ["z"] = 1, ["name"] = "default:wood"}, {["x"] = 5, ["y"] = 3, ["param1"] = 15, ["z"] = 5, ["name"] = "default:wood"}, {["x"] = 5, ["y"] = 3, ["z"] = 7, ["name"] = "default:wood"}, {["x"] = 5, ["y"] = 3, ["z"] = 15, ["name"] = "default:wood"}, {["x"] = 5, ["y"] = 3, ["param1"] = 15, ["z"] = 17, ["name"] = "default:wood"}, {["x"] = 5, ["y"] = 3, ["param1"] = 15, ["z"] = 21, ["name"] = "default:wood"}, {["x"] = 5, ["y"] = 4, ["param1"] = 15, ["z"] = 0, ["name"] = "default:wood"}, {["x"] = 5, ["y"] = 4, ["param1"] = 14, ["z"] = 6, ["name"] = "default:wood"}, {["x"] = 5, ["y"] = 4, ["z"] = 7, ["name"] = "default:wood"}, {["x"] = 5, ["y"] = 4, ["z"] = 15, ["name"] = "default:wood"}, {["x"] = 5, ["y"] = 4, ["param1"] = 14, ["z"] = 16, ["name"] = "default:wood"}, {["x"] = 5, ["y"] = 4, ["param1"] = 15, ["z"] = 22, ["name"] = "default:wood"}, {["x"] = 5, ["y"] = 5, ["param1"] = 15, ["z"] = 0, ["name"] = "default:wood"}, {["x"] = 5, ["y"] = 5, ["z"] = 6, ["name"] = "default:wood"}, {["x"] = 5, ["y"] = 5, ["z"] = 16, ["name"] = "default:wood"}, {["x"] = 5, ["y"] = 5, ["param1"] = 15, ["z"] = 22, ["name"] = "default:wood"}, {["x"] = 5, ["y"] = 6, ["param1"] = 15, ["z"] = 0, ["name"] = "default:wood"}, {["x"] = 5, ["y"] = 6, ["z"] = 6, ["name"] = "default:wood"}, {["x"] = 5, ["y"] = 6, ["z"] = 16, ["name"] = "default:wood"}, {["x"] = 5, ["y"] = 6, ["param1"] = 14, ["z"] = 22, ["name"] = "default:wood"}, {["x"] = 5, ["y"] = 7, ["param1"] = 14, ["z"] = 1, ["name"] = "default:wood"}, {["x"] = 5, ["y"] = 7, ["param1"] = 14, ["z"] = 5, ["name"] = "default:wood"}, {["x"] = 5, ["y"] = 7, ["z"] = 6, ["name"] = "default:wood"}, {["x"] = 5, ["y"] = 7, ["param1"] = 15, ["z"] = 7, ["name"] = "default:wood"}, {["x"] = 5, ["y"] = 7, ["param1"] = 15, ["z"] = 8, ["name"] = "default:wood"}, {["x"] = 5, ["y"] = 7, ["param1"] = 15, ["z"] = 9, ["name"] = "default:wood"}, {["x"] = 5, ["y"] = 7, ["param1"] = 15, ["z"] = 10, ["name"] = "default:wood"}, {["x"] = 5, ["y"] = 7, ["param1"] = 15, ["z"] = 11, ["name"] = "default:wood"}, {["x"] = 5, ["y"] = 7, ["param1"] = 15, ["z"] = 12, ["name"] = "default:wood"}, {["x"] = 5, ["y"] = 7, ["z"] = 13, ["name"] = "default:wood"}, {["x"] = 5, ["y"] = 7, ["param1"] = 15, ["z"] = 14, ["name"] = "default:wood"}, {["x"] = 5, ["y"] = 7, ["z"] = 15, ["name"] = "default:wood"}, {["x"] = 5, ["y"] = 7, ["z"] = 16, ["name"] = "default:wood"}, {["x"] = 5, ["y"] = 7, ["param1"] = 14, ["z"] = 17, ["name"] = "default:wood"}, {["x"] = 5, ["y"] = 7, ["param1"] = 15, ["z"] = 21, ["name"] = "default:wood"}, {["x"] = 5, ["y"] = 8, ["param1"] = 14, ["z"] = 2, ["name"] = "default:wood"}, {["x"] = 5, ["y"] = 8, ["param1"] = 14, ["z"] = 3, ["name"] = "default:wood"}, {["x"] = 5, ["y"] = 8, ["param1"] = 14, ["z"] = 4, ["name"] = "default:wood"}, {["x"] = 5, ["y"] = 8, ["param1"] = 191, ["z"] = 6, ["name"] = "default:fence_wood"}, {["x"] = 5, ["meta"] = {["fields"] = {["timestamp"] = "1493153941", ["station_network"] = "Air1c", ["infotext"] = "Station 'Bow at Air 2' on travelnet 'Air1c' (owned by mrg) ready for usage. Right-click to travel, punch to update.", ["formspec"] = "size[12,10]label[3.3,0.0;Travelnet-Box:]label[6.3,0.0;Punch box to update target list.]label[0.3,0.4;Name of this station:]label[6.3,0.4;Bow at Air 2]label[0.3,0.8;Assigned to Network:]label[6.3,0.8;Air1c]label[0.3,1.2;Owned by:]label[6.3,1.2;mrg]label[3.3,1.6;Click on target to travel there:]button_exit[4,2.5;4,0.5;target;Bow at Air 1]button_exit[4,3.5;1,0.5;open_door;<>]label[4.9,3.35;Bow at Air 2]", ["station_name"] = "Bow at Air 2", ["owner"] = "mrg"}, ["inventory"] = {}}, ["param2"] = 1, ["y"] = 8, ["param1"] = 170, ["z"] = 11, ["name"] = "travelnet:travelnet"}, {["x"] = 5, ["y"] = 8, ["param1"] = 191, ["z"] = 16, ["name"] = "default:fence_wood"}, {["x"] = 5, ["y"] = 8, ["param1"] = 14, ["z"] = 18, ["name"] = "default:wood"}, {["x"] = 5, ["y"] = 8, ["param1"] = 14, ["z"] = 19, ["name"] = "default:wood"}, {["x"] = 5, ["y"] = 8, ["param1"] = 14, ["z"] = 20, ["name"] = "default:wood"}, {["x"] = 5, ["y"] = 20, ["param1"] = 15, ["z"] = 10, ["name"] = "wool:white"}, {["x"] = 5, ["y"] = 20, ["param1"] = 15, ["z"] = 11, ["name"] = "wool:white"}, {["x"] = 5, ["y"] = 20, ["param1"] = 15, ["z"] = 12, ["name"] = "wool:white"}, {["x"] = 5, ["y"] = 21, ["param1"] = 15, ["z"] = 9, ["name"] = "wool:white"}, {["x"] = 5, ["y"] = 21, ["param1"] = 15, ["z"] = 13, ["name"] = "wool:white"}, {["x"] = 5, ["y"] = 22, ["param1"] = 15, ["z"] = 8, ["name"] = "wool:white"}, {["x"] = 5, ["y"] = 22, ["param1"] = 15, ["z"] = 14, ["name"] = "wool:white"}, {["x"] = 5, ["y"] = 23, ["param1"] = 15, ["z"] = 7, ["name"] = "wool:white"}, {["x"] = 5, ["y"] = 23, ["param1"] = 15, ["z"] = 15, ["name"] = "wool:white"}, {["x"] = 5, ["y"] = 24, ["param1"] = 15, ["z"] = 7, ["name"] = "wool:white"}, {["x"] = 5, ["y"] = 24, ["param1"] = 221, ["z"] = 11, ["name"] = "caverealms:glow_crystal"}, {["x"] = 5, ["y"] = 24, ["param1"] = 15, ["z"] = 15, ["name"] = "wool:white"}, {["x"] = 5, ["y"] = 25, ["param1"] = 15, ["z"] = 7, ["name"] = "wool:white"}, {["x"] = 5, ["y"] = 25, ["param1"] = 15, ["z"] = 15, ["name"] = "wool:white"}, {["x"] = 5, ["y"] = 26, ["param1"] = 15, ["z"] = 8, ["name"] = "wool:white"}, {["x"] = 5, ["y"] = 26, ["param1"] = 15, ["z"] = 14, ["name"] = "wool:white"}, {["x"] = 5, ["y"] = 27, ["param1"] = 15, ["z"] = 9, ["name"] = "wool:white"}, {["x"] = 5, ["y"] = 27, ["param1"] = 15, ["z"] = 13, ["name"] = "wool:white"}, {["x"] = 5, ["y"] = 28, ["param1"] = 15, ["z"] = 10, ["name"] = "wool:white"}, {["x"] = 5, ["y"] = 28, ["param1"] = 15, ["z"] = 11, ["name"] = "wool:white"}, {["x"] = 5, ["y"] = 28, ["param1"] = 15, ["z"] = 12, ["name"] = "wool:white"}, {["x"] = 6, ["y"] = 0, ["z"] = 11, ["name"] = "default:wood"}, {["x"] = 6, ["y"] = 1, ["z"] = 9, ["name"] = "default:wood"}, {["x"] = 6, ["y"] = 1, ["z"] = 10, ["name"] = "default:wood"}, {["x"] = 6, ["y"] = 1, ["z"] = 12, ["name"] = "default:wood"}, {["x"] = 6, ["y"] = 1, ["z"] = 13, ["name"] = "default:wood"}, {["x"] = 6, ["y"] = 2, ["param1"] = 15, ["z"] = 2, ["name"] = "default:wood"}, {["x"] = 6, ["y"] = 2, ["param1"] = 15, ["z"] = 3, ["name"] = "default:wood"}, {["x"] = 6, ["y"] = 2, ["param1"] = 15, ["z"] = 4, ["name"] = "default:wood"}, {["x"] = 6, ["y"] = 2, ["z"] = 8, ["name"] = "default:wood"}, {["x"] = 6, ["y"] = 2, ["z"] = 14, ["name"] = "default:wood"}, {["x"] = 6, ["y"] = 2, ["param1"] = 15, ["z"] = 18, ["name"] = "default:wood"}, {["x"] = 6, ["y"] = 2, ["param1"] = 15, ["z"] = 19, ["name"] = "default:wood"}, {["x"] = 6, ["y"] = 2, ["param1"] = 15, ["z"] = 20, ["name"] = "default:wood"}, {["x"] = 6, ["y"] = 3, ["param1"] = 15, ["z"] = 1, ["name"] = "default:wood"}, {["x"] = 6, ["y"] = 3, ["param1"] = 15, ["z"] = 5, ["name"] = "default:wood"}, {["x"] = 6, ["y"] = 3, ["z"] = 7, ["name"] = "default:wood"}, {["x"] = 6, ["y"] = 3, ["z"] = 15, ["name"] = "default:wood"}, {["x"] = 6, ["y"] = 3, ["param1"] = 15, ["z"] = 17, ["name"] = "default:wood"}, {["x"] = 6, ["y"] = 3, ["param1"] = 15, ["z"] = 21, ["name"] = "default:wood"}, {["x"] = 6, ["y"] = 4, ["param1"] = 15, ["z"] = 0, ["name"] = "default:wood"}, {["x"] = 6, ["y"] = 4, ["param1"] = 14, ["z"] = 6, ["name"] = "default:wood"}, {["x"] = 6, ["y"] = 4, ["z"] = 7, ["name"] = "default:wood"}, {["x"] = 6, ["y"] = 4, ["z"] = 15, ["name"] = "default:wood"}, {["x"] = 6, ["y"] = 4, ["param1"] = 14, ["z"] = 16, ["name"] = "default:wood"}, {["x"] = 6, ["y"] = 4, ["param1"] = 15, ["z"] = 22, ["name"] = "default:wood"}, {["x"] = 6, ["y"] = 5, ["param1"] = 15, ["z"] = 0, ["name"] = "default:wood"}, {["x"] = 6, ["y"] = 5, ["param1"] = 221, ["z"] = 3, ["name"] = "caverealms:glow_crystal"}, {["x"] = 6, ["y"] = 5, ["z"] = 6, ["name"] = "default:wood"}, {["x"] = 6, ["y"] = 5, ["z"] = 16, ["name"] = "default:wood"}, {["x"] = 6, ["y"] = 5, ["param1"] = 221, ["z"] = 19, ["name"] = "caverealms:glow_crystal"}, {["x"] = 6, ["y"] = 5, ["param1"] = 15, ["z"] = 22, ["name"] = "default:wood"}, {["x"] = 6, ["y"] = 6, ["param1"] = 15, ["z"] = 0, ["name"] = "default:wood"}, {["x"] = 6, ["y"] = 6, ["z"] = 6, ["name"] = "default:wood"}, {["x"] = 6, ["y"] = 6, ["z"] = 16, ["name"] = "default:wood"}, {["x"] = 6, ["y"] = 6, ["param1"] = 15, ["z"] = 22, ["name"] = "default:wood"}, {["x"] = 6, ["y"] = 7, ["param1"] = 14, ["z"] = 1, ["name"] = "default:wood"}, {["x"] = 6, ["y"] = 7, ["param1"] = 14, ["z"] = 5, ["name"] = "default:wood"}, {["x"] = 6, ["y"] = 7, ["z"] = 6, ["name"] = "default:wood"}, {["x"] = 6, ["y"] = 7, ["param1"] = 15, ["z"] = 7, ["name"] = "default:wood"}, {["x"] = 6, ["y"] = 7, ["param1"] = 15, ["z"] = 8, ["name"] = "default:wood"}, {["x"] = 6, ["y"] = 7, ["param1"] = 15, ["z"] = 9, ["name"] = "default:wood"}, {["x"] = 6, ["y"] = 7, ["param1"] = 15, ["z"] = 10, ["name"] = "default:wood"}, {["x"] = 6, ["y"] = 7, ["param1"] = 15, ["z"] = 11, ["name"] = "default:wood"}, {["x"] = 6, ["y"] = 7, ["param1"] = 15, ["z"] = 12, ["name"] = "default:wood"}, {["x"] = 6, ["y"] = 7, ["param1"] = 15, ["z"] = 13, ["name"] = "default:wood"}, {["x"] = 6, ["y"] = 7, ["param1"] = 15, ["z"] = 14, ["name"] = "default:wood"}, {["x"] = 6, ["y"] = 7, ["z"] = 15, ["name"] = "default:wood"}, {["x"] = 6, ["y"] = 7, ["z"] = 16, ["name"] = "default:wood"}, {["x"] = 6, ["y"] = 7, ["param1"] = 15, ["z"] = 17, ["name"] = "default:wood"}, {["x"] = 6, ["y"] = 7, ["param1"] = 15, ["z"] = 21, ["name"] = "default:wood"}, {["x"] = 6, ["y"] = 8, ["param1"] = 14, ["z"] = 2, ["name"] = "default:wood"}, {["x"] = 6, ["y"] = 8, ["param1"] = 14, ["z"] = 3, ["name"] = "default:wood"}, {["x"] = 6, ["y"] = 8, ["param1"] = 14, ["z"] = 4, ["name"] = "default:wood"}, {["x"] = 6, ["y"] = 8, ["param1"] = 175, ["z"] = 6, ["name"] = "default:fence_wood"}, {["x"] = 6, ["y"] = 8, ["param1"] = 154, ["z"] = 11, ["name"] = "default:fence_wood"}, {["x"] = 6, ["y"] = 8, ["param1"] = 175, ["z"] = 16, ["name"] = "default:fence_wood"}, {["x"] = 6, ["y"] = 8, ["param1"] = 15, ["z"] = 18, ["name"] = "default:wood"}, {["x"] = 6, ["y"] = 8, ["param1"] = 15, ["z"] = 19, ["name"] = "default:wood"}, {["x"] = 6, ["y"] = 8, ["param1"] = 15, ["z"] = 20, ["name"] = "default:wood"}, {["x"] = 6, ["y"] = 9, ["param1"] = 123, ["z"] = 10, ["name"] = "default:fence_wood"}, {["x"] = 6, ["y"] = 9, ["param1"] = 138, ["z"] = 11, ["name"] = "default:fence_wood"}, {["x"] = 6, ["y"] = 9, ["param1"] = 123, ["z"] = 12, ["name"] = "default:fence_wood"}, {["x"] = 6, ["y"] = 10, ["param1"] = 122, ["z"] = 11, ["name"] = "default:fence_wood"}, {["x"] = 6, ["y"] = 20, ["param1"] = 15, ["z"] = 10, ["name"] = "wool:white"}, {["x"] = 6, ["y"] = 20, ["param1"] = 15, ["z"] = 11, ["name"] = "wool:white"}, {["x"] = 6, ["y"] = 20, ["param1"] = 15, ["z"] = 12, ["name"] = "wool:white"}, {["x"] = 6, ["y"] = 21, ["param1"] = 15, ["z"] = 8, ["name"] = "wool:white"}, {["x"] = 6, ["y"] = 21, ["param1"] = 15, ["z"] = 9, ["name"] = "wool:white"}, {["x"] = 6, ["y"] = 21, ["param1"] = 15, ["z"] = 13, ["name"] = "wool:white"}, {["x"] = 6, ["y"] = 21, ["param1"] = 15, ["z"] = 14, ["name"] = "wool:white"}, {["x"] = 6, ["y"] = 22, ["param1"] = 15, ["z"] = 8, ["name"] = "wool:white"}, {["x"] = 6, ["y"] = 22, ["param1"] = 15, ["z"] = 14, ["name"] = "wool:white"}, {["x"] = 6, ["y"] = 23, ["param1"] = 15, ["z"] = 7, ["name"] = "wool:white"}, {["x"] = 6, ["y"] = 23, ["param1"] = 15, ["z"] = 15, ["name"] = "wool:white"}, {["x"] = 6, ["y"] = 24, ["param1"] = 15, ["z"] = 7, ["name"] = "wool:white"}, {["x"] = 6, ["y"] = 24, ["param1"] = 221, ["z"] = 11, ["name"] = "caverealms:glow_crystal"}, {["x"] = 6, ["y"] = 24, ["param1"] = 15, ["z"] = 15, ["name"] = "wool:white"}, {["x"] = 6, ["y"] = 25, ["param1"] = 15, ["z"] = 7, ["name"] = "wool:white"}, {["x"] = 6, ["y"] = 25, ["param1"] = 15, ["z"] = 15, ["name"] = "wool:white"}, {["x"] = 6, ["y"] = 26, ["param1"] = 15, ["z"] = 8, ["name"] = "wool:white"}, {["x"] = 6, ["y"] = 26, ["param1"] = 15, ["z"] = 14, ["name"] = "wool:white"}, {["x"] = 6, ["y"] = 27, ["param1"] = 15, ["z"] = 8, ["name"] = "wool:white"}, {["x"] = 6, ["y"] = 27, ["param1"] = 15, ["z"] = 9, ["name"] = "wool:white"}, {["x"] = 6, ["y"] = 27, ["param1"] = 15, ["z"] = 13, ["name"] = "wool:white"}, {["x"] = 6, ["y"] = 27, ["param1"] = 15, ["z"] = 14, ["name"] = "wool:white"}, {["x"] = 6, ["y"] = 28, ["param1"] = 15, ["z"] = 10, ["name"] = "wool:white"}, {["x"] = 6, ["y"] = 28, ["param1"] = 15, ["z"] = 11, ["name"] = "wool:white"}, {["x"] = 6, ["y"] = 28, ["param1"] = 15, ["z"] = 12, ["name"] = "wool:white"}, {["x"] = 7, ["y"] = 0, ["z"] = 11, ["name"] = "default:wood"}, {["x"] = 7, ["y"] = 1, ["z"] = 9, ["name"] = "default:wood"}, {["x"] = 7, ["y"] = 1, ["z"] = 10, ["name"] = "default:wood"}, {["x"] = 7, ["y"] = 1, ["z"] = 12, ["name"] = "default:wood"}, {["x"] = 7, ["y"] = 1, ["z"] = 13, ["name"] = "default:wood"}, {["x"] = 7, ["y"] = 2, ["param1"] = 15, ["z"] = 2, ["name"] = "default:wood"}, {["x"] = 7, ["y"] = 2, ["param1"] = 15, ["z"] = 3, ["name"] = "default:wood"}, {["x"] = 7, ["y"] = 2, ["param1"] = 15, ["z"] = 4, ["name"] = "default:wood"}, {["x"] = 7, ["y"] = 2, ["z"] = 8, ["name"] = "default:wood"}, {["x"] = 7, ["y"] = 2, ["z"] = 14, ["name"] = "default:wood"}, {["x"] = 7, ["y"] = 2, ["param1"] = 15, ["z"] = 18, ["name"] = "default:wood"}, {["x"] = 7, ["y"] = 2, ["param1"] = 15, ["z"] = 19, ["name"] = "default:wood"}, {["x"] = 7, ["y"] = 2, ["param1"] = 15, ["z"] = 20, ["name"] = "default:wood"}, {["x"] = 7, ["y"] = 3, ["param1"] = 15, ["z"] = 1, ["name"] = "default:wood"}, {["x"] = 7, ["y"] = 3, ["param1"] = 15, ["z"] = 5, ["name"] = "default:wood"}, {["x"] = 7, ["y"] = 3, ["z"] = 7, ["name"] = "default:wood"}, {["x"] = 7, ["y"] = 3, ["z"] = 15, ["name"] = "default:wood"}, {["x"] = 7, ["y"] = 3, ["param1"] = 15, ["z"] = 17, ["name"] = "default:wood"}, {["x"] = 7, ["y"] = 3, ["param1"] = 15, ["z"] = 21, ["name"] = "default:wood"}, {["x"] = 7, ["y"] = 4, ["param1"] = 15, ["z"] = 0, ["name"] = "default:wood"}, {["x"] = 7, ["y"] = 4, ["param1"] = 14, ["z"] = 6, ["name"] = "default:wood"}, {["x"] = 7, ["y"] = 4, ["z"] = 7, ["name"] = "default:wood"}, {["x"] = 7, ["y"] = 4, ["z"] = 15, ["name"] = "default:wood"}, {["x"] = 7, ["y"] = 4, ["param1"] = 14, ["z"] = 16, ["name"] = "default:wood"}, {["x"] = 7, ["y"] = 4, ["param1"] = 15, ["z"] = 22, ["name"] = "default:wood"}, {["x"] = 7, ["y"] = 5, ["param1"] = 15, ["z"] = 0, ["name"] = "default:wood"}, {["x"] = 7, ["meta"] = {["fields"] = {["owner"] = "thefox963", ["members"] = "yelby mrg", ["infotext"] = "Protection (owned by thefox963)"}, ["inventory"] = {}}, ["y"] = 5, ["param1"] = 204, ["z"] = 3, ["name"] = "protector:protect"}, {["x"] = 7, ["y"] = 5, ["z"] = 6, ["name"] = "default:wood"}, {["x"] = 7, ["y"] = 5, ["z"] = 16, ["name"] = "default:wood"}, {["x"] = 7, ["meta"] = {["fields"] = {["owner"] = "thefox963", ["members"] = "yelby mrg", ["infotext"] = "Protection (owned by thefox963)"}, ["inventory"] = {}}, ["y"] = 5, ["param1"] = 204, ["z"] = 19, ["name"] = "protector:protect"}, {["x"] = 7, ["y"] = 5, ["param1"] = 15, ["z"] = 22, ["name"] = "default:wood"}, {["x"] = 7, ["y"] = 6, ["param1"] = 15, ["z"] = 0, ["name"] = "default:wood"}, {["x"] = 7, ["y"] = 6, ["z"] = 6, ["name"] = "default:wood"}, {["x"] = 7, ["y"] = 6, ["z"] = 16, ["name"] = "default:wood"}, {["x"] = 7, ["y"] = 6, ["param1"] = 15, ["z"] = 22, ["name"] = "default:wood"}, {["x"] = 7, ["y"] = 7, ["param1"] = 14, ["z"] = 1, ["name"] = "default:wood"}, {["x"] = 7, ["y"] = 7, ["param1"] = 14, ["z"] = 5, ["name"] = "default:wood"}, {["x"] = 7, ["y"] = 7, ["z"] = 6, ["name"] = "default:wood"}, {["x"] = 7, ["y"] = 7, ["param1"] = 15, ["z"] = 7, ["name"] = "default:wood"}, {["x"] = 7, ["y"] = 7, ["param1"] = 15, ["z"] = 8, ["name"] = "default:wood"}, {["x"] = 7, ["y"] = 7, ["param1"] = 15, ["z"] = 9, ["name"] = "default:wood"}, {["x"] = 7, ["y"] = 7, ["param1"] = 15, ["z"] = 10, ["name"] = "default:wood"}, {["x"] = 7, ["y"] = 7, ["param1"] = 15, ["z"] = 11, ["name"] = "default:wood"}, {["x"] = 7, ["y"] = 7, ["param1"] = 15, ["z"] = 12, ["name"] = "default:wood"}, {["x"] = 7, ["y"] = 7, ["param1"] = 15, ["z"] = 13, ["name"] = "default:wood"}, {["x"] = 7, ["y"] = 7, ["param1"] = 15, ["z"] = 14, ["name"] = "default:wood"}, {["x"] = 7, ["y"] = 7, ["z"] = 15, ["name"] = "default:wood"}, {["x"] = 7, ["y"] = 7, ["z"] = 16, ["name"] = "default:wood"}, {["x"] = 7, ["y"] = 7, ["param1"] = 14, ["z"] = 17, ["name"] = "default:wood"}, {["x"] = 7, ["y"] = 7, ["param1"] = 15, ["z"] = 21, ["name"] = "default:wood"}, {["x"] = 7, ["y"] = 8, ["param1"] = 14, ["z"] = 2, ["name"] = "default:wood"}, {["x"] = 7, ["y"] = 8, ["param1"] = 14, ["z"] = 3, ["name"] = "default:wood"}, {["x"] = 7, ["y"] = 8, ["param1"] = 14, ["z"] = 4, ["name"] = "default:wood"}, {["x"] = 7, ["y"] = 8, ["param1"] = 159, ["z"] = 6, ["name"] = "default:fence_wood"}, {["x"] = 7, ["y"] = 8, ["z"] = 11, ["name"] = "default:wood"}, {["x"] = 7, ["y"] = 8, ["param1"] = 159, ["z"] = 16, ["name"] = "default:fence_wood"}, {["x"] = 7, ["y"] = 8, ["param1"] = 14, ["z"] = 18, ["name"] = "default:wood"}, {["x"] = 7, ["y"] = 8, ["param1"] = 14, ["z"] = 19, ["name"] = "default:wood"}, {["x"] = 7, ["y"] = 8, ["param1"] = 14, ["z"] = 20, ["name"] = "default:wood"}, {["x"] = 7, ["y"] = 9, ["param1"] = 122, ["z"] = 11, ["name"] = "default:fence_wood"}, {["x"] = 7, ["y"] = 20, ["param1"] = 15, ["z"] = 9, ["name"] = "wool:white"}, {["x"] = 7, ["y"] = 20, ["param1"] = 15, ["z"] = 10, ["name"] = "wool:white"}, {["x"] = 7, ["y"] = 20, ["param1"] = 15, ["z"] = 11, ["name"] = "wool:white"}, {["x"] = 7, ["y"] = 20, ["param1"] = 15, ["z"] = 12, ["name"] = "wool:white"}, {["x"] = 7, ["y"] = 20, ["param1"] = 15, ["z"] = 13, ["name"] = "wool:white"}, {["x"] = 7, ["y"] = 21, ["param1"] = 15, ["z"] = 8, ["name"] = "wool:white"}, {["x"] = 7, ["y"] = 21, ["param1"] = 15, ["z"] = 14, ["name"] = "wool:white"}, {["x"] = 7, ["y"] = 22, ["param1"] = 15, ["z"] = 7, ["name"] = "wool:white"}, {["x"] = 7, ["y"] = 22, ["param1"] = 15, ["z"] = 15, ["name"] = "wool:white"}, {["x"] = 7, ["y"] = 23, ["param1"] = 15, ["z"] = 7, ["name"] = "wool:white"}, {["x"] = 7, ["y"] = 23, ["param1"] = 15, ["z"] = 15, ["name"] = "wool:white"}, {["x"] = 7, ["y"] = 24, ["param1"] = 15, ["z"] = 7, ["name"] = "wool:white"}, {["x"] = 7, ["meta"] = {["fields"] = {["owner"] = "thefox963", ["members"] = "yelby mrg", ["infotext"] = "Protection (owned by thefox963)"}, ["inventory"] = {}}, ["y"] = 24, ["param1"] = 204, ["z"] = 11, ["name"] = "protector:protect"}, {["x"] = 7, ["y"] = 24, ["param1"] = 15, ["z"] = 15, ["name"] = "wool:white"}, {["x"] = 7, ["y"] = 25, ["param1"] = 15, ["z"] = 7, ["name"] = "wool:white"}, {["x"] = 7, ["y"] = 25, ["param1"] = 15, ["z"] = 15, ["name"] = "wool:white"}, {["x"] = 7, ["y"] = 26, ["param1"] = 15, ["z"] = 7, ["name"] = "wool:white"}, {["x"] = 7, ["y"] = 26, ["param1"] = 15, ["z"] = 15, ["name"] = "wool:white"}, {["x"] = 7, ["y"] = 27, ["param1"] = 15, ["z"] = 8, ["name"] = "wool:white"}, {["x"] = 7, ["y"] = 27, ["param1"] = 15, ["z"] = 14, ["name"] = "wool:white"}, {["x"] = 7, ["y"] = 28, ["param1"] = 15, ["z"] = 9, ["name"] = "wool:white"}, {["x"] = 7, ["y"] = 28, ["param1"] = 15, ["z"] = 10, ["name"] = "wool:white"}, {["x"] = 7, ["y"] = 28, ["param1"] = 15, ["z"] = 11, ["name"] = "wool:white"}, {["x"] = 7, ["y"] = 28, ["param1"] = 15, ["z"] = 12, ["name"] = "wool:white"}, {["x"] = 7, ["y"] = 28, ["param1"] = 15, ["z"] = 13, ["name"] = "wool:white"}, {["x"] = 8, ["y"] = 0, ["z"] = 11, ["name"] = "default:wood"}, {["x"] = 8, ["y"] = 1, ["z"] = 9, ["name"] = "default:wood"}, {["x"] = 8, ["y"] = 1, ["z"] = 10, ["name"] = "default:wood"}, {["x"] = 8, ["y"] = 1, ["z"] = 12, ["name"] = "default:wood"}, {["x"] = 8, ["y"] = 1, ["z"] = 13, ["name"] = "default:wood"}, {["x"] = 8, ["y"] = 2, ["param1"] = 15, ["z"] = 2, ["name"] = "default:wood"}, {["x"] = 8, ["y"] = 2, ["param1"] = 15, ["z"] = 3, ["name"] = "default:wood"}, {["x"] = 8, ["y"] = 2, ["param1"] = 15, ["z"] = 4, ["name"] = "default:wood"}, {["x"] = 8, ["y"] = 2, ["z"] = 8, ["name"] = "default:wood"}, {["x"] = 8, ["y"] = 2, ["z"] = 14, ["name"] = "default:wood"}, {["x"] = 8, ["y"] = 2, ["param1"] = 15, ["z"] = 18, ["name"] = "default:wood"}, {["x"] = 8, ["y"] = 2, ["param1"] = 15, ["z"] = 19, ["name"] = "default:wood"}, {["x"] = 8, ["y"] = 2, ["param1"] = 15, ["z"] = 20, ["name"] = "default:wood"}, {["x"] = 8, ["y"] = 3, ["param1"] = 15, ["z"] = 1, ["name"] = "default:wood"}, {["x"] = 8, ["y"] = 3, ["param1"] = 15, ["z"] = 5, ["name"] = "default:wood"}, {["x"] = 8, ["y"] = 3, ["z"] = 7, ["name"] = "default:wood"}, {["x"] = 8, ["y"] = 3, ["z"] = 15, ["name"] = "default:wood"}, {["x"] = 8, ["y"] = 3, ["param1"] = 15, ["z"] = 17, ["name"] = "default:wood"}, {["x"] = 8, ["y"] = 3, ["param1"] = 15, ["z"] = 21, ["name"] = "default:wood"}, {["x"] = 8, ["y"] = 4, ["param1"] = 15, ["z"] = 0, ["name"] = "default:wood"}, {["x"] = 8, ["y"] = 4, ["param1"] = 14, ["z"] = 6, ["name"] = "default:wood"}, {["x"] = 8, ["y"] = 4, ["z"] = 7, ["name"] = "default:wood"}, {["x"] = 8, ["y"] = 4, ["param1"] = 221, ["z"] = 11, ["name"] = "caverealms:glow_crystal"}, {["x"] = 8, ["y"] = 4, ["z"] = 15, ["name"] = "default:wood"}, {["x"] = 8, ["y"] = 4, ["param1"] = 14, ["z"] = 16, ["name"] = "default:wood"}, {["x"] = 8, ["y"] = 4, ["param1"] = 15, ["z"] = 22, ["name"] = "default:wood"}, {["x"] = 8, ["y"] = 5, ["param1"] = 15, ["z"] = 0, ["name"] = "default:wood"}, {["x"] = 8, ["y"] = 5, ["param1"] = 221, ["z"] = 3, ["name"] = "caverealms:glow_crystal"}, {["x"] = 8, ["y"] = 5, ["z"] = 6, ["name"] = "default:wood"}, {["x"] = 8, ["y"] = 5, ["z"] = 16, ["name"] = "default:wood"}, {["x"] = 8, ["y"] = 5, ["param1"] = 221, ["z"] = 19, ["name"] = "caverealms:glow_crystal"}, {["x"] = 8, ["y"] = 5, ["param1"] = 15, ["z"] = 22, ["name"] = "default:wood"}, {["x"] = 8, ["y"] = 6, ["param1"] = 15, ["z"] = 0, ["name"] = "default:wood"}, {["x"] = 8, ["y"] = 6, ["z"] = 6, ["name"] = "default:wood"}, {["x"] = 8, ["y"] = 6, ["z"] = 16, ["name"] = "default:wood"}, {["x"] = 8, ["y"] = 6, ["param1"] = 15, ["z"] = 22, ["name"] = "default:wood"}, {["x"] = 8, ["y"] = 7, ["param1"] = 14, ["z"] = 1, ["name"] = "default:wood"}, {["x"] = 8, ["y"] = 7, ["param1"] = 14, ["z"] = 5, ["name"] = "default:wood"}, {["x"] = 8, ["y"] = 7, ["z"] = 6, ["name"] = "default:wood"}, {["x"] = 8, ["y"] = 7, ["param1"] = 15, ["z"] = 7, ["name"] = "default:wood"}, {["x"] = 8, ["y"] = 7, ["param1"] = 15, ["z"] = 8, ["name"] = "default:wood"}, {["x"] = 8, ["y"] = 7, ["param1"] = 15, ["z"] = 9, ["name"] = "default:wood"}, {["x"] = 8, ["y"] = 7, ["param1"] = 15, ["z"] = 10, ["name"] = "default:wood"}, {["x"] = 8, ["y"] = 7, ["param1"] = 15, ["z"] = 11, ["name"] = "default:wood"}, {["x"] = 8, ["y"] = 7, ["param1"] = 15, ["z"] = 12, ["name"] = "default:wood"}, {["x"] = 8, ["y"] = 7, ["param1"] = 15, ["z"] = 13, ["name"] = "default:wood"}, {["x"] = 8, ["y"] = 7, ["param1"] = 15, ["z"] = 14, ["name"] = "default:wood"}, {["x"] = 8, ["y"] = 7, ["z"] = 15, ["name"] = "default:wood"}, {["x"] = 8, ["y"] = 7, ["z"] = 16, ["name"] = "default:wood"}, {["x"] = 8, ["y"] = 7, ["param1"] = 14, ["z"] = 17, ["name"] = "default:wood"}, {["x"] = 8, ["y"] = 7, ["param1"] = 15, ["z"] = 21, ["name"] = "default:wood"}, {["x"] = 8, ["y"] = 8, ["param1"] = 14, ["z"] = 2, ["name"] = "default:wood"}, {["x"] = 8, ["y"] = 8, ["param1"] = 14, ["z"] = 3, ["name"] = "default:wood"}, {["x"] = 8, ["y"] = 8, ["param1"] = 14, ["z"] = 4, ["name"] = "default:wood"}, {["x"] = 8, ["y"] = 8, ["param1"] = 143, ["z"] = 6, ["name"] = "default:fence_wood"}, {["x"] = 8, ["y"] = 8, ["param1"] = 143, ["z"] = 16, ["name"] = "default:fence_wood"}, {["x"] = 8, ["y"] = 8, ["param1"] = 14, ["z"] = 18, ["name"] = "default:wood"}, {["x"] = 8, ["y"] = 8, ["param1"] = 14, ["z"] = 19, ["name"] = "default:wood"}, {["x"] = 8, ["y"] = 8, ["param1"] = 14, ["z"] = 20, ["name"] = "default:wood"}, {["x"] = 8, ["y"] = 20, ["param1"] = 15, ["z"] = 9, ["name"] = "wool:white"}, {["x"] = 8, ["y"] = 20, ["param1"] = 15, ["z"] = 10, ["name"] = "wool:white"}, {["x"] = 8, ["y"] = 20, ["param1"] = 15, ["z"] = 11, ["name"] = "wool:white"}, {["x"] = 8, ["y"] = 20, ["param1"] = 15, ["z"] = 12, ["name"] = "wool:white"}, {["x"] = 8, ["y"] = 20, ["param1"] = 15, ["z"] = 13, ["name"] = "wool:white"}, {["x"] = 8, ["y"] = 21, ["param1"] = 15, ["z"] = 8, ["name"] = "wool:white"}, {["x"] = 8, ["y"] = 21, ["param1"] = 15, ["z"] = 14, ["name"] = "wool:white"}, {["x"] = 8, ["y"] = 22, ["param1"] = 15, ["z"] = 7, ["name"] = "wool:white"}, {["x"] = 8, ["y"] = 22, ["param1"] = 15, ["z"] = 15, ["name"] = "wool:white"}, {["x"] = 8, ["y"] = 23, ["param1"] = 15, ["z"] = 7, ["name"] = "wool:white"}, {["x"] = 8, ["y"] = 23, ["param1"] = 15, ["z"] = 15, ["name"] = "wool:white"}, {["x"] = 8, ["y"] = 24, ["param1"] = 15, ["z"] = 7, ["name"] = "wool:white"}, {["x"] = 8, ["y"] = 24, ["param1"] = 221, ["z"] = 11, ["name"] = "caverealms:glow_crystal"}, {["x"] = 8, ["y"] = 24, ["param1"] = 15, ["z"] = 15, ["name"] = "wool:white"}, {["x"] = 8, ["y"] = 25, ["param1"] = 15, ["z"] = 7, ["name"] = "wool:white"}, {["x"] = 8, ["y"] = 25, ["param1"] = 15, ["z"] = 15, ["name"] = "wool:white"}, {["x"] = 8, ["y"] = 26, ["param1"] = 15, ["z"] = 7, ["name"] = "wool:white"}, {["x"] = 8, ["y"] = 26, ["param1"] = 15, ["z"] = 15, ["name"] = "wool:white"}, {["x"] = 8, ["y"] = 27, ["param1"] = 15, ["z"] = 8, ["name"] = "wool:white"}, {["x"] = 8, ["y"] = 27, ["param1"] = 15, ["z"] = 14, ["name"] = "wool:white"}, {["x"] = 8, ["y"] = 28, ["param1"] = 15, ["z"] = 9, ["name"] = "wool:white"}, {["x"] = 8, ["y"] = 28, ["param1"] = 15, ["z"] = 10, ["name"] = "wool:white"}, {["x"] = 8, ["y"] = 28, ["param1"] = 15, ["z"] = 11, ["name"] = "wool:white"}, {["x"] = 8, ["y"] = 28, ["param1"] = 15, ["z"] = 12, ["name"] = "wool:white"}, {["x"] = 8, ["y"] = 28, ["param1"] = 15, ["z"] = 13, ["name"] = "wool:white"}, {["x"] = 9, ["y"] = 0, ["z"] = 11, ["name"] = "default:wood"}, {["x"] = 9, ["y"] = 1, ["z"] = 9, ["name"] = "default:wood"}, {["x"] = 9, ["y"] = 1, ["z"] = 10, ["name"] = "default:wood"}, {["x"] = 9, ["y"] = 1, ["z"] = 12, ["name"] = "default:wood"}, {["x"] = 9, ["y"] = 1, ["z"] = 13, ["name"] = "default:wood"}, {["x"] = 9, ["y"] = 2, ["param1"] = 15, ["z"] = 2, ["name"] = "default:wood"}, {["x"] = 9, ["y"] = 2, ["param1"] = 15, ["z"] = 3, ["name"] = "default:wood"}, {["x"] = 9, ["y"] = 2, ["param1"] = 15, ["z"] = 4, ["name"] = "default:wood"}, {["x"] = 9, ["y"] = 2, ["z"] = 8, ["name"] = "default:wood"}, {["x"] = 9, ["y"] = 2, ["z"] = 14, ["name"] = "default:wood"}, {["x"] = 9, ["y"] = 2, ["param1"] = 15, ["z"] = 18, ["name"] = "default:wood"}, {["x"] = 9, ["y"] = 2, ["param1"] = 15, ["z"] = 19, ["name"] = "default:wood"}, {["x"] = 9, ["y"] = 2, ["param1"] = 15, ["z"] = 20, ["name"] = "default:wood"}, {["x"] = 9, ["y"] = 3, ["param1"] = 15, ["z"] = 1, ["name"] = "default:wood"}, {["x"] = 9, ["y"] = 3, ["param1"] = 15, ["z"] = 5, ["name"] = "default:wood"}, {["x"] = 9, ["y"] = 3, ["z"] = 7, ["name"] = "default:wood"}, {["x"] = 9, ["y"] = 3, ["z"] = 15, ["name"] = "default:wood"}, {["x"] = 9, ["y"] = 3, ["param1"] = 15, ["z"] = 17, ["name"] = "default:wood"}, {["x"] = 9, ["y"] = 3, ["param1"] = 15, ["z"] = 21, ["name"] = "default:wood"}, {["x"] = 9, ["y"] = 4, ["param1"] = 15, ["z"] = 0, ["name"] = "default:wood"}, {["x"] = 9, ["y"] = 4, ["param1"] = 14, ["z"] = 6, ["name"] = "default:wood"}, {["x"] = 9, ["y"] = 4, ["z"] = 7, ["name"] = "default:wood"}, {["x"] = 9, ["meta"] = {["fields"] = {["owner"] = "thefox963", ["members"] = "yelby mrg", ["infotext"] = "Protection (owned by thefox963)"}, ["inventory"] = {}}, ["y"] = 4, ["param1"] = 204, ["z"] = 11, ["name"] = "protector:protect"}, {["x"] = 9, ["y"] = 4, ["z"] = 15, ["name"] = "default:wood"}, {["x"] = 9, ["y"] = 4, ["param1"] = 14, ["z"] = 16, ["name"] = "default:wood"}, {["x"] = 9, ["y"] = 4, ["param1"] = 15, ["z"] = 22, ["name"] = "default:wood"}, {["x"] = 9, ["y"] = 5, ["param1"] = 15, ["z"] = 0, ["name"] = "default:wood"}, {["x"] = 9, ["y"] = 5, ["z"] = 6, ["name"] = "default:wood"}, {["x"] = 9, ["y"] = 5, ["z"] = 16, ["name"] = "default:wood"}, {["x"] = 9, ["y"] = 5, ["param1"] = 15, ["z"] = 22, ["name"] = "default:wood"}, {["x"] = 9, ["y"] = 6, ["param1"] = 15, ["z"] = 0, ["name"] = "default:wood"}, {["x"] = 9, ["y"] = 6, ["z"] = 6, ["name"] = "default:wood"}, {["x"] = 9, ["y"] = 6, ["z"] = 16, ["name"] = "default:wood"}, {["x"] = 9, ["y"] = 6, ["param1"] = 15, ["z"] = 22, ["name"] = "default:wood"}, {["x"] = 9, ["y"] = 7, ["param1"] = 14, ["z"] = 1, ["name"] = "default:wood"}, {["x"] = 9, ["y"] = 7, ["param1"] = 14, ["z"] = 5, ["name"] = "default:wood"}, {["x"] = 9, ["y"] = 7, ["z"] = 6, ["name"] = "default:wood"}, {["x"] = 9, ["y"] = 7, ["param1"] = 15, ["z"] = 7, ["name"] = "default:wood"}, {["x"] = 9, ["y"] = 7, ["param1"] = 15, ["z"] = 8, ["name"] = "default:wood"}, {["x"] = 9, ["y"] = 7, ["param1"] = 15, ["z"] = 9, ["name"] = "default:wood"}, {["x"] = 9, ["y"] = 7, ["param1"] = 15, ["z"] = 10, ["name"] = "default:wood"}, {["x"] = 9, ["y"] = 7, ["param1"] = 15, ["z"] = 11, ["name"] = "default:wood"}, {["x"] = 9, ["y"] = 7, ["param1"] = 15, ["z"] = 12, ["name"] = "default:wood"}, {["x"] = 9, ["y"] = 7, ["param1"] = 15, ["z"] = 13, ["name"] = "default:wood"}, {["x"] = 9, ["y"] = 7, ["param1"] = 15, ["z"] = 14, ["name"] = "default:wood"}, {["x"] = 9, ["y"] = 7, ["z"] = 15, ["name"] = "default:wood"}, {["x"] = 9, ["y"] = 7, ["z"] = 16, ["name"] = "default:wood"}, {["x"] = 9, ["y"] = 7, ["param1"] = 14, ["z"] = 17, ["name"] = "default:wood"}, {["x"] = 9, ["y"] = 7, ["param1"] = 15, ["z"] = 21, ["name"] = "default:wood"}, {["x"] = 9, ["y"] = 8, ["param1"] = 14, ["z"] = 2, ["name"] = "default:wood"}, {["x"] = 9, ["y"] = 8, ["param1"] = 14, ["z"] = 3, ["name"] = "default:wood"}, {["x"] = 9, ["y"] = 8, ["param1"] = 14, ["z"] = 4, ["name"] = "default:wood"}, {["x"] = 9, ["y"] = 8, ["param1"] = 126, ["z"] = 6, ["name"] = "default:fence_wood"}, {["x"] = 9, ["y"] = 8, ["param1"] = 126, ["z"] = 16, ["name"] = "default:fence_wood"}, {["x"] = 9, ["y"] = 8, ["param1"] = 14, ["z"] = 18, ["name"] = "default:wood"}, {["x"] = 9, ["y"] = 8, ["param1"] = 14, ["z"] = 19, ["name"] = "default:wood"}, {["x"] = 9, ["y"] = 8, ["param1"] = 14, ["z"] = 20, ["name"] = "default:wood"}, {["x"] = 9, ["y"] = 19, ["param1"] = 15, ["z"] = 11, ["name"] = "wool:white"}, {["x"] = 9, ["y"] = 20, ["param1"] = 15, ["z"] = 8, ["name"] = "wool:white"}, {["x"] = 9, ["y"] = 20, ["param1"] = 15, ["z"] = 9, ["name"] = "wool:white"}, {["x"] = 9, ["y"] = 20, ["param1"] = 15, ["z"] = 10, ["name"] = "wool:white"}, {["x"] = 9, ["meta"] = {["fields"] = {["owner"] = "thefox963", ["members"] = "yelby mrg", ["infotext"] = "Protection (owned by thefox963)"}, ["inventory"] = {}}, ["param2"] = 1, ["y"] = 20, ["param1"] = 153, ["z"] = 11, ["name"] = "protector:protect2"}, {["x"] = 9, ["y"] = 20, ["param1"] = 15, ["z"] = 12, ["name"] = "wool:white"}, {["x"] = 9, ["y"] = 20, ["param1"] = 15, ["z"] = 13, ["name"] = "wool:white"}, {["x"] = 9, ["y"] = 20, ["param1"] = 15, ["z"] = 14, ["name"] = "wool:white"}, {["x"] = 9, ["y"] = 21, ["param1"] = 15, ["z"] = 7, ["name"] = "wool:white"}, {["x"] = 9, ["y"] = 21, ["param1"] = 15, ["z"] = 15, ["name"] = "wool:white"}, {["x"] = 9, ["y"] = 22, ["param1"] = 15, ["z"] = 7, ["name"] = "wool:white"}, {["x"] = 9, ["y"] = 22, ["param1"] = 15, ["z"] = 15, ["name"] = "wool:white"}, {["x"] = 9, ["y"] = 23, ["param1"] = 15, ["z"] = 7, ["name"] = "wool:white"}, {["x"] = 9, ["y"] = 23, ["param1"] = 15, ["z"] = 15, ["name"] = "wool:white"}, {["x"] = 9, ["y"] = 24, ["param1"] = 15, ["z"] = 6, ["name"] = "wool:white"}, {["x"] = 9, ["y"] = 24, ["param1"] = 221, ["z"] = 11, ["name"] = "caverealms:glow_crystal"}, {["x"] = 9, ["y"] = 24, ["param1"] = 15, ["z"] = 16, ["name"] = "wool:white"}, {["x"] = 9, ["y"] = 25, ["param1"] = 15, ["z"] = 7, ["name"] = "wool:white"}, {["x"] = 9, ["y"] = 25, ["param1"] = 15, ["z"] = 15, ["name"] = "wool:white"}, {["x"] = 9, ["y"] = 26, ["param1"] = 15, ["z"] = 7, ["name"] = "wool:white"}, {["x"] = 9, ["y"] = 26, ["param1"] = 15, ["z"] = 15, ["name"] = "wool:white"}, {["x"] = 9, ["y"] = 27, ["param1"] = 15, ["z"] = 7, ["name"] = "wool:white"}, {["x"] = 9, ["y"] = 27, ["param1"] = 15, ["z"] = 15, ["name"] = "wool:white"}, {["x"] = 9, ["y"] = 28, ["param1"] = 15, ["z"] = 8, ["name"] = "wool:white"}, {["x"] = 9, ["y"] = 28, ["param1"] = 15, ["z"] = 9, ["name"] = "wool:white"}, {["x"] = 9, ["y"] = 28, ["param1"] = 15, ["z"] = 10, ["name"] = "wool:white"}, {["x"] = 9, ["y"] = 28, ["param1"] = 15, ["z"] = 12, ["name"] = "wool:white"}, {["x"] = 9, ["y"] = 28, ["param1"] = 15, ["z"] = 13, ["name"] = "wool:white"}, {["x"] = 9, ["y"] = 28, ["param1"] = 15, ["z"] = 14, ["name"] = "wool:white"}, {["x"] = 9, ["y"] = 29, ["param1"] = 15, ["z"] = 11, ["name"] = "wool:white"}, {["x"] = 10, ["y"] = 0, ["z"] = 11, ["name"] = "default:wood"}, {["x"] = 10, ["y"] = 1, ["z"] = 9, ["name"] = "default:wood"}, {["x"] = 10, ["y"] = 1, ["z"] = 10, ["name"] = "default:wood"}, {["x"] = 10, ["y"] = 1, ["z"] = 12, ["name"] = "default:wood"}, {["x"] = 10, ["y"] = 1, ["z"] = 13, ["name"] = "default:wood"}, {["x"] = 10, ["y"] = 2, ["param1"] = 15, ["z"] = 2, ["name"] = "default:wood"}, {["x"] = 10, ["y"] = 2, ["param1"] = 15, ["z"] = 3, ["name"] = "default:wood"}, {["x"] = 10, ["y"] = 2, ["param1"] = 15, ["z"] = 4, ["name"] = "default:wood"}, {["x"] = 10, ["y"] = 2, ["z"] = 8, ["name"] = "default:wood"}, {["x"] = 10, ["y"] = 2, ["z"] = 14, ["name"] = "default:wood"}, {["x"] = 10, ["y"] = 2, ["param1"] = 15, ["z"] = 18, ["name"] = "default:wood"}, {["x"] = 10, ["y"] = 2, ["param1"] = 15, ["z"] = 19, ["name"] = "default:wood"}, {["x"] = 10, ["y"] = 2, ["param1"] = 15, ["z"] = 20, ["name"] = "default:wood"}, {["x"] = 10, ["y"] = 3, ["param1"] = 15, ["z"] = 1, ["name"] = "default:wood"}, {["x"] = 10, ["y"] = 3, ["param1"] = 15, ["z"] = 5, ["name"] = "default:wood"}, {["x"] = 10, ["y"] = 3, ["z"] = 7, ["name"] = "default:wood"}, {["x"] = 10, ["y"] = 3, ["z"] = 15, ["name"] = "default:wood"}, {["x"] = 10, ["y"] = 3, ["param1"] = 15, ["z"] = 17, ["name"] = "default:wood"}, {["x"] = 10, ["y"] = 3, ["param1"] = 15, ["z"] = 21, ["name"] = "default:wood"}, {["x"] = 10, ["y"] = 4, ["param1"] = 15, ["z"] = 0, ["name"] = "default:wood"}, {["x"] = 10, ["y"] = 4, ["param1"] = 14, ["z"] = 6, ["name"] = "default:wood"}, {["x"] = 10, ["y"] = 4, ["z"] = 7, ["name"] = "default:wood"}, {["x"] = 10, ["y"] = 4, ["param1"] = 221, ["z"] = 11, ["name"] = "caverealms:glow_crystal"}, {["x"] = 10, ["y"] = 4, ["z"] = 15, ["name"] = "default:wood"}, {["x"] = 10, ["y"] = 4, ["param1"] = 14, ["z"] = 16, ["name"] = "default:wood"}, {["x"] = 10, ["y"] = 4, ["param1"] = 15, ["z"] = 22, ["name"] = "default:wood"}, {["x"] = 10, ["y"] = 5, ["param1"] = 15, ["z"] = 0, ["name"] = "default:wood"}, {["x"] = 10, ["y"] = 5, ["z"] = 6, ["name"] = "default:wood"}, {["x"] = 10, ["y"] = 5, ["z"] = 16, ["name"] = "default:wood"}, {["x"] = 10, ["y"] = 5, ["param1"] = 15, ["z"] = 22, ["name"] = "default:wood"}, {["x"] = 10, ["y"] = 6, ["param1"] = 15, ["z"] = 0, ["name"] = "default:wood"}, {["x"] = 10, ["y"] = 6, ["z"] = 6, ["name"] = "default:wood"}, {["x"] = 10, ["y"] = 6, ["z"] = 16, ["name"] = "default:wood"}, {["x"] = 10, ["y"] = 6, ["param1"] = 15, ["z"] = 22, ["name"] = "default:wood"}, {["x"] = 10, ["y"] = 7, ["param1"] = 14, ["z"] = 1, ["name"] = "default:wood"}, {["x"] = 10, ["y"] = 7, ["param1"] = 14, ["z"] = 5, ["name"] = "default:wood"}, {["x"] = 10, ["y"] = 7, ["z"] = 6, ["name"] = "default:wood"}, {["x"] = 10, ["y"] = 7, ["param1"] = 15, ["z"] = 7, ["name"] = "default:wood"}, {["x"] = 10, ["y"] = 7, ["param1"] = 15, ["z"] = 8, ["name"] = "default:wood"}, {["x"] = 10, ["y"] = 7, ["param1"] = 15, ["z"] = 9, ["name"] = "default:wood"}, {["x"] = 10, ["y"] = 7, ["param1"] = 15, ["z"] = 10, ["name"] = "default:wood"}, {["x"] = 10, ["y"] = 7, ["param1"] = 15, ["z"] = 11, ["name"] = "default:wood"}, {["x"] = 10, ["y"] = 7, ["param1"] = 15, ["z"] = 12, ["name"] = "default:wood"}, {["x"] = 10, ["y"] = 7, ["param1"] = 15, ["z"] = 13, ["name"] = "default:wood"}, {["x"] = 10, ["y"] = 7, ["param1"] = 15, ["z"] = 14, ["name"] = "default:wood"}, {["x"] = 10, ["y"] = 7, ["z"] = 15, ["name"] = "default:wood"}, {["x"] = 10, ["y"] = 7, ["z"] = 16, ["name"] = "default:wood"}, {["x"] = 10, ["y"] = 7, ["param1"] = 14, ["z"] = 17, ["name"] = "default:wood"}, {["x"] = 10, ["y"] = 7, ["param1"] = 15, ["z"] = 21, ["name"] = "default:wood"}, {["x"] = 10, ["y"] = 8, ["param1"] = 14, ["z"] = 2, ["name"] = "default:wood"}, {["x"] = 10, ["y"] = 8, ["param1"] = 14, ["z"] = 3, ["name"] = "default:wood"}, {["x"] = 10, ["y"] = 8, ["param1"] = 14, ["z"] = 4, ["name"] = "default:wood"}, {["x"] = 10, ["y"] = 8, ["param1"] = 110, ["z"] = 6, ["name"] = "default:fence_wood"}, {["x"] = 10, ["y"] = 8, ["param1"] = 110, ["z"] = 16, ["name"] = "default:fence_wood"}, {["x"] = 10, ["y"] = 8, ["param1"] = 14, ["z"] = 18, ["name"] = "default:wood"}, {["x"] = 10, ["y"] = 8, ["param1"] = 14, ["z"] = 19, ["name"] = "default:wood"}, {["x"] = 10, ["y"] = 8, ["param1"] = 14, ["z"] = 20, ["name"] = "default:wood"}, {["x"] = 10, ["y"] = 19, ["param1"] = 15, ["z"] = 10, ["name"] = "wool:white"}, {["x"] = 10, ["y"] = 19, ["param1"] = 15, ["z"] = 11, ["name"] = "wool:white"}, {["x"] = 10, ["y"] = 19, ["param1"] = 15, ["z"] = 12, ["name"] = "wool:white"}, {["x"] = 10, ["y"] = 20, ["param1"] = 15, ["z"] = 8, ["name"] = "wool:white"}, {["x"] = 10, ["y"] = 20, ["param1"] = 15, ["z"] = 9, ["name"] = "wool:white"}, {["x"] = 10, ["y"] = 20, ["param1"] = 15, ["z"] = 13, ["name"] = "wool:white"}, {["x"] = 10, ["y"] = 20, ["param1"] = 15, ["z"] = 14, ["name"] = "wool:white"}, {["x"] = 10, ["y"] = 21, ["param1"] = 15, ["z"] = 7, ["name"] = "wool:white"}, {["x"] = 10, ["y"] = 21, ["param1"] = 15, ["z"] = 15, ["name"] = "wool:white"}, {["x"] = 10, ["y"] = 22, ["param1"] = 15, ["z"] = 7, ["name"] = "wool:white"}, {["x"] = 10, ["y"] = 22, ["param1"] = 15, ["z"] = 15, ["name"] = "wool:white"}, {["x"] = 10, ["y"] = 23, ["param1"] = 15, ["z"] = 6, ["name"] = "wool:white"}, {["x"] = 10, ["y"] = 23, ["param1"] = 15, ["z"] = 16, ["name"] = "wool:white"}, {["x"] = 10, ["y"] = 24, ["param1"] = 15, ["z"] = 6, ["name"] = "wool:white"}, {["x"] = 10, ["y"] = 24, ["param1"] = 221, ["z"] = 11, ["name"] = "caverealms:glow_crystal"}, {["x"] = 10, ["y"] = 24, ["param1"] = 15, ["z"] = 16, ["name"] = "wool:white"}, {["x"] = 10, ["y"] = 25, ["param1"] = 15, ["z"] = 6, ["name"] = "wool:white"}, {["x"] = 10, ["y"] = 25, ["param1"] = 15, ["z"] = 16, ["name"] = "wool:white"}, {["x"] = 10, ["y"] = 26, ["param1"] = 15, ["z"] = 7, ["name"] = "wool:white"}, {["x"] = 10, ["y"] = 26, ["param1"] = 15, ["z"] = 15, ["name"] = "wool:white"}, {["x"] = 10, ["y"] = 27, ["param1"] = 15, ["z"] = 7, ["name"] = "wool:white"}, {["x"] = 10, ["y"] = 27, ["param1"] = 15, ["z"] = 15, ["name"] = "wool:white"}, {["x"] = 10, ["y"] = 28, ["param1"] = 15, ["z"] = 8, ["name"] = "wool:white"}, {["x"] = 10, ["y"] = 28, ["param1"] = 15, ["z"] = 9, ["name"] = "wool:white"}, {["x"] = 10, ["y"] = 28, ["param1"] = 15, ["z"] = 13, ["name"] = "wool:white"}, {["x"] = 10, ["y"] = 28, ["param1"] = 15, ["z"] = 14, ["name"] = "wool:white"}, {["x"] = 10, ["y"] = 29, ["param1"] = 15, ["z"] = 10, ["name"] = "wool:white"}, {["x"] = 10, ["y"] = 29, ["param1"] = 15, ["z"] = 11, ["name"] = "wool:white"}, {["x"] = 10, ["y"] = 29, ["param1"] = 15, ["z"] = 12, ["name"] = "wool:white"}, {["x"] = 11, ["y"] = 0, ["z"] = 11, ["name"] = "default:wood"}, {["x"] = 11, ["y"] = 1, ["z"] = 9, ["name"] = "default:wood"}, {["x"] = 11, ["y"] = 1, ["z"] = 10, ["name"] = "default:wood"}, {["x"] = 11, ["y"] = 1, ["z"] = 12, ["name"] = "default:wood"}, {["x"] = 11, ["y"] = 1, ["z"] = 13, ["name"] = "default:wood"}, {["x"] = 11, ["y"] = 2, ["param1"] = 15, ["z"] = 2, ["name"] = "default:wood"}, {["x"] = 11, ["y"] = 2, ["param1"] = 15, ["z"] = 3, ["name"] = "default:wood"}, {["x"] = 11, ["y"] = 2, ["param1"] = 15, ["z"] = 4, ["name"] = "default:wood"}, {["x"] = 11, ["y"] = 2, ["z"] = 8, ["name"] = "default:wood"}, {["x"] = 11, ["y"] = 2, ["z"] = 14, ["name"] = "default:wood"}, {["x"] = 11, ["y"] = 2, ["param1"] = 15, ["z"] = 18, ["name"] = "default:wood"}, {["x"] = 11, ["y"] = 2, ["param1"] = 15, ["z"] = 19, ["name"] = "default:wood"}, {["x"] = 11, ["y"] = 2, ["param1"] = 15, ["z"] = 20, ["name"] = "default:wood"}, {["x"] = 11, ["y"] = 3, ["param1"] = 15, ["z"] = 1, ["name"] = "default:wood"}, {["x"] = 11, ["y"] = 3, ["param1"] = 15, ["z"] = 5, ["name"] = "default:wood"}, {["x"] = 11, ["y"] = 3, ["z"] = 7, ["name"] = "default:wood"}, {["x"] = 11, ["y"] = 3, ["z"] = 15, ["name"] = "default:wood"}, {["x"] = 11, ["y"] = 3, ["param1"] = 15, ["z"] = 17, ["name"] = "default:wood"}, {["x"] = 11, ["y"] = 3, ["param1"] = 15, ["z"] = 21, ["name"] = "default:wood"}, {["x"] = 11, ["y"] = 4, ["param1"] = 15, ["z"] = 0, ["name"] = "default:wood"}, {["x"] = 11, ["y"] = 4, ["param1"] = 14, ["z"] = 6, ["name"] = "default:wood"}, {["x"] = 11, ["y"] = 4, ["z"] = 7, ["name"] = "default:wood"}, {["x"] = 11, ["y"] = 4, ["z"] = 15, ["name"] = "default:wood"}, {["x"] = 11, ["y"] = 4, ["param1"] = 14, ["z"] = 16, ["name"] = "default:wood"}, {["x"] = 11, ["y"] = 4, ["param1"] = 15, ["z"] = 22, ["name"] = "default:wood"}, {["x"] = 11, ["y"] = 5, ["param1"] = 15, ["z"] = 0, ["name"] = "default:wood"}, {["x"] = 11, ["y"] = 5, ["z"] = 6, ["name"] = "default:wood"}, {["x"] = 11, ["y"] = 5, ["z"] = 16, ["name"] = "default:wood"}, {["x"] = 11, ["y"] = 5, ["param1"] = 15, ["z"] = 22, ["name"] = "default:wood"}, {["x"] = 11, ["y"] = 6, ["param1"] = 15, ["z"] = 0, ["name"] = "default:wood"}, {["x"] = 11, ["y"] = 6, ["z"] = 6, ["name"] = "default:wood"}, {["x"] = 11, ["y"] = 6, ["z"] = 16, ["name"] = "default:wood"}, {["x"] = 11, ["y"] = 6, ["param1"] = 15, ["z"] = 22, ["name"] = "default:wood"}, {["x"] = 11, ["y"] = 7, ["param1"] = 14, ["z"] = 1, ["name"] = "default:wood"}, {["x"] = 11, ["y"] = 7, ["param1"] = 14, ["z"] = 5, ["name"] = "default:wood"}, {["x"] = 11, ["y"] = 7, ["z"] = 6, ["name"] = "default:wood"}, {["x"] = 11, ["y"] = 7, ["param1"] = 15, ["z"] = 7, ["name"] = "default:wood"}, {["x"] = 11, ["y"] = 7, ["param1"] = 15, ["z"] = 8, ["name"] = "default:wood"}, {["x"] = 11, ["y"] = 7, ["param1"] = 15, ["z"] = 9, ["name"] = "default:wood"}, {["x"] = 11, ["y"] = 7, ["param1"] = 15, ["z"] = 10, ["name"] = "default:wood"}, {["x"] = 11, ["y"] = 7, ["param1"] = 15, ["z"] = 11, ["name"] = "default:wood"}, {["x"] = 11, ["y"] = 7, ["param1"] = 15, ["z"] = 12, ["name"] = "default:wood"}, {["x"] = 11, ["y"] = 7, ["param1"] = 15, ["z"] = 13, ["name"] = "default:wood"}, {["x"] = 11, ["y"] = 7, ["param1"] = 15, ["z"] = 14, ["name"] = "default:wood"}, {["x"] = 11, ["y"] = 7, ["z"] = 15, ["name"] = "default:wood"}, {["x"] = 11, ["y"] = 7, ["z"] = 16, ["name"] = "default:wood"}, {["x"] = 11, ["y"] = 7, ["param1"] = 14, ["z"] = 17, ["name"] = "default:wood"}, {["x"] = 11, ["y"] = 7, ["param1"] = 15, ["z"] = 21, ["name"] = "default:wood"}, {["x"] = 11, ["y"] = 8, ["param1"] = 14, ["z"] = 2, ["name"] = "default:wood"}, {["x"] = 11, ["y"] = 8, ["param1"] = 14, ["z"] = 3, ["name"] = "default:wood"}, {["x"] = 11, ["y"] = 8, ["param1"] = 14, ["z"] = 4, ["name"] = "default:wood"}, {["x"] = 11, ["y"] = 8, ["param1"] = 94, ["z"] = 6, ["name"] = "default:fence_wood"}, {["x"] = 11, ["y"] = 8, ["param1"] = 94, ["z"] = 16, ["name"] = "default:fence_wood"}, {["x"] = 11, ["y"] = 8, ["param1"] = 14, ["z"] = 18, ["name"] = "default:wood"}, {["x"] = 11, ["y"] = 8, ["param1"] = 14, ["z"] = 19, ["name"] = "default:wood"}, {["x"] = 11, ["y"] = 8, ["param1"] = 14, ["z"] = 20, ["name"] = "default:wood"}, {["x"] = 11, ["y"] = 19, ["param1"] = 15, ["z"] = 10, ["name"] = "wool:white"}, {["x"] = 11, ["y"] = 19, ["param1"] = 15, ["z"] = 11, ["name"] = "wool:white"}, {["x"] = 11, ["y"] = 19, ["param1"] = 15, ["z"] = 12, ["name"] = "wool:white"}, {["x"] = 11, ["y"] = 20, ["param1"] = 15, ["z"] = 8, ["name"] = "wool:white"}, {["x"] = 11, ["y"] = 20, ["param1"] = 15, ["z"] = 9, ["name"] = "wool:white"}, {["x"] = 11, ["y"] = 20, ["param1"] = 15, ["z"] = 13, ["name"] = "wool:white"}, {["x"] = 11, ["y"] = 20, ["param1"] = 15, ["z"] = 14, ["name"] = "wool:white"}, {["x"] = 11, ["y"] = 21, ["param1"] = 15, ["z"] = 7, ["name"] = "wool:white"}, {["x"] = 11, ["y"] = 21, ["param1"] = 15, ["z"] = 15, ["name"] = "wool:white"}, {["x"] = 11, ["y"] = 22, ["param1"] = 15, ["z"] = 7, ["name"] = "wool:white"}, {["x"] = 11, ["y"] = 22, ["param1"] = 15, ["z"] = 15, ["name"] = "wool:white"}, {["x"] = 11, ["y"] = 23, ["param1"] = 15, ["z"] = 6, ["name"] = "wool:white"}, {["x"] = 11, ["y"] = 23, ["param1"] = 15, ["z"] = 16, ["name"] = "wool:white"}, {["x"] = 11, ["y"] = 24, ["param1"] = 15, ["z"] = 6, ["name"] = "wool:white"}, {["x"] = 11, ["y"] = 24, ["param1"] = 221, ["z"] = 11, ["name"] = "caverealms:glow_crystal"}, {["x"] = 11, ["y"] = 24, ["param1"] = 15, ["z"] = 16, ["name"] = "wool:white"}, {["x"] = 11, ["y"] = 25, ["param1"] = 15, ["z"] = 6, ["name"] = "wool:white"}, {["x"] = 11, ["y"] = 25, ["param1"] = 15, ["z"] = 16, ["name"] = "wool:white"}, {["x"] = 11, ["y"] = 26, ["param1"] = 15, ["z"] = 7, ["name"] = "wool:white"}, {["x"] = 11, ["y"] = 26, ["param1"] = 15, ["z"] = 15, ["name"] = "wool:white"}, {["x"] = 11, ["y"] = 27, ["param1"] = 15, ["z"] = 7, ["name"] = "wool:white"}, {["x"] = 11, ["y"] = 27, ["param1"] = 15, ["z"] = 15, ["name"] = "wool:white"}, {["x"] = 11, ["y"] = 28, ["param1"] = 15, ["z"] = 8, ["name"] = "wool:white"}, {["x"] = 11, ["y"] = 28, ["param1"] = 15, ["z"] = 9, ["name"] = "wool:white"}, {["x"] = 11, ["y"] = 28, ["param1"] = 15, ["z"] = 13, ["name"] = "wool:white"}, {["x"] = 11, ["y"] = 28, ["param1"] = 15, ["z"] = 14, ["name"] = "wool:white"}, {["x"] = 11, ["y"] = 29, ["param1"] = 15, ["z"] = 10, ["name"] = "wool:white"}, {["x"] = 11, ["y"] = 29, ["param1"] = 15, ["z"] = 11, ["name"] = "wool:white"}, {["x"] = 11, ["y"] = 29, ["param1"] = 15, ["z"] = 12, ["name"] = "wool:white"}, {["x"] = 12, ["y"] = 0, ["z"] = 11, ["name"] = "default:wood"}, {["x"] = 12, ["y"] = 1, ["z"] = 9, ["name"] = "default:wood"}, {["x"] = 12, ["y"] = 1, ["z"] = 10, ["name"] = "default:wood"}, {["x"] = 12, ["y"] = 1, ["z"] = 12, ["name"] = "default:wood"}, {["x"] = 12, ["y"] = 1, ["z"] = 13, ["name"] = "default:wood"}, {["x"] = 12, ["y"] = 2, ["param1"] = 15, ["z"] = 2, ["name"] = "default:wood"}, {["x"] = 12, ["y"] = 2, ["param1"] = 15, ["z"] = 3, ["name"] = "default:wood"}, {["x"] = 12, ["y"] = 2, ["param1"] = 15, ["z"] = 4, ["name"] = "default:wood"}, {["x"] = 12, ["y"] = 2, ["z"] = 8, ["name"] = "default:wood"}, {["x"] = 12, ["y"] = 2, ["z"] = 14, ["name"] = "default:wood"}, {["x"] = 12, ["y"] = 2, ["param1"] = 15, ["z"] = 18, ["name"] = "default:wood"}, {["x"] = 12, ["y"] = 2, ["param1"] = 15, ["z"] = 19, ["name"] = "default:wood"}, {["x"] = 12, ["y"] = 2, ["param1"] = 15, ["z"] = 20, ["name"] = "default:wood"}, {["x"] = 12, ["y"] = 3, ["param1"] = 15, ["z"] = 1, ["name"] = "default:wood"}, {["x"] = 12, ["y"] = 3, ["z"] = 2, ["name"] = "default:steelblock"}, {["x"] = 12, ["y"] = 3, ["z"] = 3, ["name"] = "default:steelblock"}, {["x"] = 12, ["y"] = 3, ["z"] = 4, ["name"] = "default:steelblock"}, {["x"] = 12, ["y"] = 3, ["param1"] = 15, ["z"] = 5, ["name"] = "default:wood"}, {["x"] = 12, ["y"] = 3, ["z"] = 7, ["name"] = "default:wood"}, {["x"] = 12, ["y"] = 3, ["z"] = 15, ["name"] = "default:wood"}, {["x"] = 12, ["y"] = 3, ["param1"] = 15, ["z"] = 17, ["name"] = "default:wood"}, {["x"] = 12, ["y"] = 3, ["z"] = 18, ["name"] = "default:steelblock"}, {["x"] = 12, ["y"] = 3, ["z"] = 19, ["name"] = "default:steelblock"}, {["x"] = 12, ["y"] = 3, ["z"] = 20, ["name"] = "default:steelblock"}, {["x"] = 12, ["y"] = 3, ["param1"] = 15, ["z"] = 21, ["name"] = "default:wood"}, {["x"] = 12, ["y"] = 4, ["param1"] = 15, ["z"] = 0, ["name"] = "default:wood"}, {["x"] = 12, ["y"] = 4, ["z"] = 1, ["name"] = "default:steelblock"}, {["x"] = 12, ["y"] = 4, ["z"] = 2, ["name"] = "default:steelblock"}, {["x"] = 12, ["y"] = 4, ["z"] = 3, ["name"] = "default:steelblock"}, {["x"] = 12, ["y"] = 4, ["z"] = 4, ["name"] = "default:steelblock"}, {["x"] = 12, ["y"] = 4, ["z"] = 5, ["name"] = "default:steelblock"}, {["x"] = 12, ["y"] = 4, ["param1"] = 14, ["z"] = 6, ["name"] = "default:wood"}, {["x"] = 12, ["y"] = 4, ["z"] = 7, ["name"] = "default:wood"}, {["x"] = 12, ["y"] = 4, ["z"] = 15, ["name"] = "default:wood"}, {["x"] = 12, ["y"] = 4, ["param1"] = 14, ["z"] = 16, ["name"] = "default:wood"}, {["x"] = 12, ["y"] = 4, ["z"] = 17, ["name"] = "default:steelblock"}, {["x"] = 12, ["y"] = 4, ["z"] = 18, ["name"] = "default:steelblock"}, {["x"] = 12, ["y"] = 4, ["z"] = 19, ["name"] = "default:steelblock"}, {["x"] = 12, ["y"] = 4, ["z"] = 20, ["name"] = "default:steelblock"}, {["x"] = 12, ["y"] = 4, ["z"] = 21, ["name"] = "default:steelblock"}, {["x"] = 12, ["y"] = 4, ["param1"] = 15, ["z"] = 22, ["name"] = "default:wood"}, {["x"] = 12, ["y"] = 5, ["param1"] = 15, ["z"] = 0, ["name"] = "default:wood"}, {["x"] = 12, ["y"] = 5, ["z"] = 1, ["name"] = "default:steelblock"}, {["x"] = 12, ["y"] = 5, ["z"] = 2, ["name"] = "default:steelblock"}, {["x"] = 12, ["y"] = 5, ["z"] = 3, ["name"] = "default:steelblock"}, {["x"] = 12, ["y"] = 5, ["z"] = 4, ["name"] = "default:steelblock"}, {["x"] = 12, ["y"] = 5, ["z"] = 5, ["name"] = "default:steelblock"}, {["x"] = 12, ["y"] = 5, ["z"] = 6, ["name"] = "default:wood"}, {["x"] = 12, ["y"] = 5, ["z"] = 16, ["name"] = "default:wood"}, {["x"] = 12, ["y"] = 5, ["z"] = 17, ["name"] = "default:steelblock"}, {["x"] = 12, ["y"] = 5, ["z"] = 18, ["name"] = "default:steelblock"}, {["x"] = 12, ["y"] = 5, ["z"] = 19, ["name"] = "default:steelblock"}, {["x"] = 12, ["y"] = 5, ["z"] = 20, ["name"] = "default:steelblock"}, {["x"] = 12, ["y"] = 5, ["z"] = 21, ["name"] = "default:steelblock"}, {["x"] = 12, ["y"] = 5, ["param1"] = 15, ["z"] = 22, ["name"] = "default:wood"}, {["x"] = 12, ["y"] = 6, ["param1"] = 15, ["z"] = 0, ["name"] = "default:wood"}, {["x"] = 12, ["y"] = 6, ["z"] = 1, ["name"] = "default:steelblock"}, {["x"] = 12, ["y"] = 6, ["z"] = 2, ["name"] = "default:steelblock"}, {["x"] = 12, ["y"] = 6, ["z"] = 3, ["name"] = "default:steelblock"}, {["x"] = 12, ["y"] = 6, ["z"] = 4, ["name"] = "default:steelblock"}, {["x"] = 12, ["y"] = 6, ["z"] = 5, ["name"] = "default:steelblock"}, {["x"] = 12, ["y"] = 6, ["z"] = 6, ["name"] = "default:wood"}, {["x"] = 12, ["y"] = 6, ["z"] = 16, ["name"] = "default:wood"}, {["x"] = 12, ["y"] = 6, ["z"] = 17, ["name"] = "default:steelblock"}, {["x"] = 12, ["y"] = 6, ["z"] = 18, ["name"] = "default:steelblock"}, {["x"] = 12, ["y"] = 6, ["z"] = 19, ["name"] = "default:steelblock"}, {["x"] = 12, ["y"] = 6, ["z"] = 20, ["name"] = "default:steelblock"}, {["x"] = 12, ["y"] = 6, ["z"] = 21, ["name"] = "default:steelblock"}, {["x"] = 12, ["y"] = 6, ["param1"] = 15, ["z"] = 22, ["name"] = "default:wood"}, {["x"] = 12, ["y"] = 7, ["param1"] = 14, ["z"] = 1, ["name"] = "default:wood"}, {["x"] = 12, ["y"] = 7, ["z"] = 2, ["name"] = "default:steelblock"}, {["x"] = 12, ["y"] = 7, ["z"] = 3, ["name"] = "default:steelblock"}, {["x"] = 12, ["y"] = 7, ["z"] = 4, ["name"] = "default:steelblock"}, {["x"] = 12, ["y"] = 7, ["param1"] = 14, ["z"] = 5, ["name"] = "default:wood"}, {["x"] = 12, ["y"] = 7, ["z"] = 6, ["name"] = "default:wood"}, {["x"] = 12, ["y"] = 7, ["param1"] = 15, ["z"] = 7, ["name"] = "default:wood"}, {["x"] = 12, ["y"] = 7, ["param1"] = 15, ["z"] = 8, ["name"] = "default:wood"}, {["x"] = 12, ["y"] = 7, ["param1"] = 15, ["z"] = 9, ["name"] = "default:wood"}, {["x"] = 12, ["y"] = 7, ["param1"] = 15, ["z"] = 10, ["name"] = "default:wood"}, {["x"] = 12, ["y"] = 7, ["param1"] = 15, ["z"] = 11, ["name"] = "default:wood"}, {["x"] = 12, ["y"] = 7, ["param1"] = 15, ["z"] = 12, ["name"] = "default:wood"}, {["x"] = 12, ["y"] = 7, ["param1"] = 15, ["z"] = 13, ["name"] = "default:wood"}, {["x"] = 12, ["y"] = 7, ["param1"] = 15, ["z"] = 14, ["name"] = "default:wood"}, {["x"] = 12, ["y"] = 7, ["z"] = 15, ["name"] = "default:wood"}, {["x"] = 12, ["y"] = 7, ["z"] = 16, ["name"] = "default:wood"}, {["x"] = 12, ["y"] = 7, ["param1"] = 14, ["z"] = 17, ["name"] = "default:wood"}, {["x"] = 12, ["y"] = 7, ["z"] = 18, ["name"] = "default:steelblock"}, {["x"] = 12, ["y"] = 7, ["z"] = 19, ["name"] = "default:steelblock"}, {["x"] = 12, ["y"] = 7, ["z"] = 20, ["name"] = "default:steelblock"}, {["x"] = 12, ["y"] = 7, ["param1"] = 15, ["z"] = 21, ["name"] = "default:wood"}, {["x"] = 12, ["y"] = 8, ["param1"] = 14, ["z"] = 2, ["name"] = "default:wood"}, {["x"] = 12, ["y"] = 8, ["param1"] = 14, ["z"] = 3, ["name"] = "default:wood"}, {["x"] = 12, ["y"] = 8, ["param1"] = 14, ["z"] = 4, ["name"] = "default:wood"}, {["x"] = 12, ["y"] = 8, ["param1"] = 78, ["z"] = 6, ["name"] = "default:fence_wood"}, {["x"] = 12, ["y"] = 8, ["param1"] = 78, ["z"] = 16, ["name"] = "default:fence_wood"}, {["x"] = 12, ["y"] = 8, ["param1"] = 14, ["z"] = 18, ["name"] = "default:wood"}, {["x"] = 12, ["y"] = 8, ["param1"] = 14, ["z"] = 19, ["name"] = "default:wood"}, {["x"] = 12, ["y"] = 8, ["param1"] = 14, ["z"] = 20, ["name"] = "default:wood"}, {["x"] = 12, ["y"] = 19, ["param1"] = 15, ["z"] = 10, ["name"] = "wool:white"}, {["x"] = 12, ["y"] = 19, ["param1"] = 15, ["z"] = 11, ["name"] = "wool:white"}, {["x"] = 12, ["y"] = 19, ["param1"] = 15, ["z"] = 12, ["name"] = "wool:white"}, {["x"] = 12, ["y"] = 20, ["param1"] = 15, ["z"] = 8, ["name"] = "wool:white"}, {["x"] = 12, ["y"] = 20, ["param1"] = 15, ["z"] = 9, ["name"] = "wool:white"}, {["x"] = 12, ["y"] = 20, ["param1"] = 15, ["z"] = 13, ["name"] = "wool:white"}, {["x"] = 12, ["y"] = 20, ["param1"] = 15, ["z"] = 14, ["name"] = "wool:white"}, {["x"] = 12, ["y"] = 21, ["param1"] = 15, ["z"] = 7, ["name"] = "wool:white"}, {["x"] = 12, ["y"] = 21, ["param1"] = 15, ["z"] = 15, ["name"] = "wool:white"}, {["x"] = 12, ["y"] = 22, ["param1"] = 15, ["z"] = 7, ["name"] = "wool:white"}, {["x"] = 12, ["y"] = 22, ["param1"] = 15, ["z"] = 15, ["name"] = "wool:white"}, {["x"] = 12, ["y"] = 23, ["param1"] = 15, ["z"] = 6, ["name"] = "wool:white"}, {["x"] = 12, ["y"] = 23, ["param1"] = 15, ["z"] = 16, ["name"] = "wool:white"}, {["x"] = 12, ["y"] = 24, ["param1"] = 15, ["z"] = 6, ["name"] = "wool:white"}, {["x"] = 12, ["y"] = 24, ["param1"] = 221, ["z"] = 11, ["name"] = "caverealms:glow_crystal"}, {["x"] = 12, ["y"] = 24, ["param1"] = 15, ["z"] = 16, ["name"] = "wool:white"}, {["x"] = 12, ["y"] = 25, ["param1"] = 15, ["z"] = 6, ["name"] = "wool:white"}, {["x"] = 12, ["y"] = 25, ["param1"] = 15, ["z"] = 16, ["name"] = "wool:white"}, {["x"] = 12, ["y"] = 26, ["param1"] = 15, ["z"] = 7, ["name"] = "wool:white"}, {["x"] = 12, ["y"] = 26, ["param1"] = 15, ["z"] = 15, ["name"] = "wool:white"}, {["x"] = 12, ["y"] = 27, ["param1"] = 15, ["z"] = 7, ["name"] = "wool:white"}, {["x"] = 12, ["y"] = 27, ["param1"] = 15, ["z"] = 15, ["name"] = "wool:white"}, {["x"] = 12, ["y"] = 28, ["param1"] = 15, ["z"] = 8, ["name"] = "wool:white"}, {["x"] = 12, ["y"] = 28, ["param1"] = 15, ["z"] = 9, ["name"] = "wool:white"}, {["x"] = 12, ["y"] = 28, ["param1"] = 15, ["z"] = 13, ["name"] = "wool:white"}, {["x"] = 12, ["y"] = 28, ["param1"] = 15, ["z"] = 14, ["name"] = "wool:white"}, {["x"] = 12, ["y"] = 29, ["param1"] = 15, ["z"] = 10, ["name"] = "wool:white"}, {["x"] = 12, ["y"] = 29, ["param1"] = 15, ["z"] = 11, ["name"] = "wool:white"}, {["x"] = 12, ["y"] = 29, ["param1"] = 15, ["z"] = 12, ["name"] = "wool:white"}, {["x"] = 13, ["y"] = 0, ["z"] = 11, ["name"] = "default:wood"}, {["x"] = 13, ["y"] = 1, ["z"] = 9, ["name"] = "default:wood"}, {["x"] = 13, ["y"] = 1, ["z"] = 10, ["name"] = "default:wood"}, {["x"] = 13, ["y"] = 1, ["z"] = 12, ["name"] = "default:wood"}, {["x"] = 13, ["y"] = 1, ["z"] = 13, ["name"] = "default:wood"}, {["x"] = 13, ["y"] = 2, ["param1"] = 14, ["z"] = 2, ["name"] = "default:wood"}, {["x"] = 13, ["y"] = 2, ["param1"] = 14, ["z"] = 3, ["name"] = "default:wood"}, {["x"] = 13, ["y"] = 2, ["param1"] = 14, ["z"] = 4, ["name"] = "default:wood"}, {["x"] = 13, ["y"] = 2, ["z"] = 8, ["name"] = "default:wood"}, {["x"] = 13, ["y"] = 2, ["z"] = 14, ["name"] = "default:wood"}, {["x"] = 13, ["y"] = 2, ["param1"] = 14, ["z"] = 18, ["name"] = "default:wood"}, {["x"] = 13, ["y"] = 2, ["param1"] = 14, ["z"] = 19, ["name"] = "default:wood"}, {["x"] = 13, ["y"] = 2, ["param1"] = 15, ["z"] = 20, ["name"] = "default:wood"}, {["x"] = 13, ["y"] = 3, ["param1"] = 14, ["z"] = 1, ["name"] = "default:wood"}, {["x"] = 13, ["y"] = 3, ["param1"] = 14, ["z"] = 2, ["name"] = "building_blocks:grate"}, {["x"] = 13, ["y"] = 3, ["param1"] = 14, ["z"] = 3, ["name"] = "building_blocks:grate"}, {["x"] = 13, ["y"] = 3, ["param1"] = 14, ["z"] = 4, ["name"] = "building_blocks:grate"}, {["x"] = 13, ["y"] = 3, ["param1"] = 14, ["z"] = 5, ["name"] = "default:wood"}, {["x"] = 13, ["y"] = 3, ["z"] = 7, ["name"] = "default:wood"}, {["x"] = 13, ["y"] = 3, ["z"] = 15, ["name"] = "default:wood"}, {["x"] = 13, ["y"] = 3, ["param1"] = 14, ["z"] = 17, ["name"] = "default:wood"}, {["x"] = 13, ["y"] = 3, ["param1"] = 14, ["z"] = 18, ["name"] = "building_blocks:grate"}, {["x"] = 13, ["y"] = 3, ["param1"] = 14, ["z"] = 19, ["name"] = "building_blocks:grate"}, {["x"] = 13, ["y"] = 3, ["param1"] = 14, ["z"] = 20, ["name"] = "building_blocks:grate"}, {["x"] = 13, ["y"] = 3, ["param1"] = 14, ["z"] = 21, ["name"] = "default:wood"}, {["x"] = 13, ["y"] = 4, ["param1"] = 15, ["z"] = 0, ["name"] = "default:wood"}, {["x"] = 13, ["y"] = 4, ["param1"] = 14, ["z"] = 1, ["name"] = "building_blocks:grate"}, {["x"] = 13, ["y"] = 4, ["param1"] = 14, ["z"] = 2, ["name"] = "building_blocks:grate"}, {["x"] = 13, ["y"] = 4, ["param1"] = 14, ["z"] = 3, ["name"] = "building_blocks:grate"}, {["x"] = 13, ["y"] = 4, ["param1"] = 14, ["z"] = 4, ["name"] = "building_blocks:grate"}, {["x"] = 13, ["y"] = 4, ["param1"] = 14, ["z"] = 5, ["name"] = "building_blocks:grate"}, {["x"] = 13, ["y"] = 4, ["param1"] = 13, ["z"] = 6, ["name"] = "default:wood"}, {["x"] = 13, ["y"] = 4, ["z"] = 7, ["name"] = "default:wood"}, {["x"] = 13, ["y"] = 4, ["z"] = 15, ["name"] = "default:wood"}, {["x"] = 13, ["y"] = 4, ["param1"] = 13, ["z"] = 16, ["name"] = "default:wood"}, {["x"] = 13, ["y"] = 4, ["param1"] = 14, ["z"] = 17, ["name"] = "building_blocks:grate"}, {["x"] = 13, ["y"] = 4, ["param1"] = 14, ["z"] = 18, ["name"] = "building_blocks:grate"}, {["x"] = 13, ["y"] = 4, ["param1"] = 14, ["z"] = 19, ["name"] = "building_blocks:grate"}, {["x"] = 13, ["y"] = 4, ["param1"] = 14, ["z"] = 20, ["name"] = "building_blocks:grate"}, {["x"] = 13, ["y"] = 4, ["param1"] = 14, ["z"] = 21, ["name"] = "building_blocks:grate"}, {["x"] = 13, ["y"] = 4, ["param1"] = 15, ["z"] = 22, ["name"] = "default:wood"}, {["x"] = 13, ["y"] = 5, ["param1"] = 15, ["z"] = 0, ["name"] = "default:wood"}, {["x"] = 13, ["y"] = 5, ["param1"] = 14, ["z"] = 1, ["name"] = "building_blocks:grate"}, {["x"] = 13, ["y"] = 5, ["param1"] = 14, ["z"] = 2, ["name"] = "building_blocks:grate"}, {["x"] = 13, ["y"] = 5, ["param1"] = 14, ["z"] = 3, ["name"] = "building_blocks:grate"}, {["x"] = 13, ["y"] = 5, ["param1"] = 14, ["z"] = 4, ["name"] = "building_blocks:grate"}, {["x"] = 13, ["y"] = 5, ["param1"] = 14, ["z"] = 5, ["name"] = "building_blocks:grate"}, {["x"] = 13, ["y"] = 5, ["z"] = 6, ["name"] = "default:wood"}, {["x"] = 13, ["y"] = 5, ["z"] = 16, ["name"] = "default:wood"}, {["x"] = 13, ["y"] = 5, ["param1"] = 14, ["z"] = 17, ["name"] = "building_blocks:grate"}, {["x"] = 13, ["y"] = 5, ["param1"] = 14, ["z"] = 18, ["name"] = "building_blocks:grate"}, {["x"] = 13, ["y"] = 5, ["param1"] = 14, ["z"] = 19, ["name"] = "building_blocks:grate"}, {["x"] = 13, ["y"] = 5, ["param1"] = 14, ["z"] = 20, ["name"] = "building_blocks:grate"}, {["x"] = 13, ["y"] = 5, ["param1"] = 14, ["z"] = 21, ["name"] = "building_blocks:grate"}, {["x"] = 13, ["y"] = 5, ["param1"] = 15, ["z"] = 22, ["name"] = "default:wood"}, {["x"] = 13, ["y"] = 6, ["param1"] = 15, ["z"] = 0, ["name"] = "default:wood"}, {["x"] = 13, ["y"] = 6, ["param1"] = 14, ["z"] = 1, ["name"] = "building_blocks:grate"}, {["x"] = 13, ["y"] = 6, ["param1"] = 14, ["z"] = 2, ["name"] = "building_blocks:grate"}, {["x"] = 13, ["y"] = 6, ["param1"] = 14, ["z"] = 3, ["name"] = "building_blocks:grate"}, {["x"] = 13, ["y"] = 6, ["param1"] = 14, ["z"] = 4, ["name"] = "building_blocks:grate"}, {["x"] = 13, ["y"] = 6, ["param1"] = 30, ["z"] = 5, ["name"] = "building_blocks:grate"}, {["x"] = 13, ["y"] = 6, ["z"] = 6, ["name"] = "default:wood"}, {["x"] = 13, ["y"] = 6, ["z"] = 16, ["name"] = "default:wood"}, {["x"] = 13, ["y"] = 6, ["param1"] = 30, ["z"] = 17, ["name"] = "building_blocks:grate"}, {["x"] = 13, ["y"] = 6, ["param1"] = 14, ["z"] = 18, ["name"] = "building_blocks:grate"}, {["x"] = 13, ["y"] = 6, ["param1"] = 14, ["z"] = 19, ["name"] = "building_blocks:grate"}, {["x"] = 13, ["y"] = 6, ["param1"] = 14, ["z"] = 20, ["name"] = "building_blocks:grate"}, {["x"] = 13, ["y"] = 6, ["param1"] = 14, ["z"] = 21, ["name"] = "building_blocks:grate"}, {["x"] = 13, ["y"] = 6, ["param1"] = 15, ["z"] = 22, ["name"] = "default:wood"}, {["x"] = 13, ["y"] = 7, ["param1"] = 14, ["z"] = 1, ["name"] = "default:wood"}, {["x"] = 13, ["y"] = 7, ["param1"] = 14, ["z"] = 2, ["name"] = "building_blocks:grate"}, {["x"] = 13, ["y"] = 7, ["param1"] = 14, ["z"] = 3, ["name"] = "building_blocks:grate"}, {["x"] = 13, ["y"] = 7, ["param1"] = 30, ["z"] = 4, ["name"] = "building_blocks:grate"}, {["x"] = 13, ["y"] = 7, ["param1"] = 14, ["z"] = 5, ["name"] = "default:wood"}, {["x"] = 13, ["y"] = 7, ["z"] = 6, ["name"] = "default:wood"}, {["x"] = 13, ["y"] = 7, ["param1"] = 15, ["z"] = 7, ["name"] = "default:wood"}, {["x"] = 13, ["y"] = 7, ["param1"] = 15, ["z"] = 8, ["name"] = "default:wood"}, {["x"] = 13, ["y"] = 7, ["param1"] = 15, ["z"] = 9, ["name"] = "default:wood"}, {["x"] = 13, ["y"] = 7, ["param1"] = 15, ["z"] = 10, ["name"] = "default:wood"}, {["x"] = 13, ["y"] = 7, ["param1"] = 15, ["z"] = 11, ["name"] = "default:wood"}, {["x"] = 13, ["y"] = 7, ["param1"] = 15, ["z"] = 12, ["name"] = "default:wood"}, {["x"] = 13, ["y"] = 7, ["param1"] = 15, ["z"] = 13, ["name"] = "default:wood"}, {["x"] = 13, ["y"] = 7, ["param1"] = 15, ["z"] = 14, ["name"] = "default:wood"}, {["x"] = 13, ["y"] = 7, ["z"] = 15, ["name"] = "default:wood"}, {["x"] = 13, ["y"] = 7, ["z"] = 16, ["name"] = "default:wood"}, {["x"] = 13, ["y"] = 7, ["param1"] = 14, ["z"] = 17, ["name"] = "default:wood"}, {["x"] = 13, ["y"] = 7, ["param1"] = 30, ["z"] = 18, ["name"] = "building_blocks:grate"}, {["x"] = 13, ["y"] = 7, ["param1"] = 14, ["z"] = 19, ["name"] = "building_blocks:grate"}, {["x"] = 13, ["y"] = 7, ["param1"] = 14, ["z"] = 20, ["name"] = "building_blocks:grate"}, {["x"] = 13, ["y"] = 7, ["param1"] = 15, ["z"] = 21, ["name"] = "default:wood"}, {["x"] = 13, ["y"] = 8, ["param1"] = 14, ["z"] = 2, ["name"] = "default:wood"}, {["x"] = 13, ["y"] = 8, ["param1"] = 14, ["z"] = 3, ["name"] = "default:wood"}, {["x"] = 13, ["y"] = 8, ["param1"] = 14, ["z"] = 4, ["name"] = "default:wood"}, {["x"] = 13, ["y"] = 8, ["param1"] = 78, ["z"] = 6, ["name"] = "default:fence_wood"}, {["x"] = 13, ["y"] = 8, ["param1"] = 78, ["z"] = 16, ["name"] = "default:fence_wood"}, {["x"] = 13, ["y"] = 8, ["param1"] = 14, ["z"] = 18, ["name"] = "default:wood"}, {["x"] = 13, ["y"] = 8, ["param1"] = 14, ["z"] = 19, ["name"] = "default:wood"}, {["x"] = 13, ["y"] = 8, ["param1"] = 14, ["z"] = 20, ["name"] = "default:wood"}, {["x"] = 13, ["y"] = 19, ["param1"] = 15, ["z"] = 9, ["name"] = "wool:white"}, {["x"] = 13, ["y"] = 19, ["param1"] = 15, ["z"] = 10, ["name"] = "wool:white"}, {["x"] = 13, ["y"] = 19, ["param1"] = 15, ["z"] = 11, ["name"] = "wool:white"}, {["x"] = 13, ["y"] = 19, ["param1"] = 15, ["z"] = 12, ["name"] = "wool:white"}, {["x"] = 13, ["y"] = 19, ["param1"] = 15, ["z"] = 13, ["name"] = "wool:white"}, {["x"] = 13, ["y"] = 20, ["param1"] = 15, ["z"] = 8, ["name"] = "wool:white"}, {["x"] = 13, ["y"] = 20, ["param1"] = 15, ["z"] = 14, ["name"] = "wool:white"}, {["x"] = 13, ["y"] = 21, ["param1"] = 15, ["z"] = 7, ["name"] = "wool:white"}, {["x"] = 13, ["y"] = 21, ["param1"] = 15, ["z"] = 15, ["name"] = "wool:white"}, {["x"] = 13, ["y"] = 22, ["param1"] = 15, ["z"] = 6, ["name"] = "wool:white"}, {["x"] = 13, ["y"] = 22, ["param1"] = 15, ["z"] = 16, ["name"] = "wool:white"}, {["x"] = 13, ["y"] = 23, ["param1"] = 15, ["z"] = 6, ["name"] = "wool:white"}, {["x"] = 13, ["y"] = 23, ["param1"] = 15, ["z"] = 16, ["name"] = "wool:white"}, {["x"] = 13, ["y"] = 24, ["param1"] = 15, ["z"] = 6, ["name"] = "wool:white"}, {["x"] = 13, ["y"] = 24, ["param1"] = 221, ["z"] = 11, ["name"] = "caverealms:glow_crystal"}, {["x"] = 13, ["y"] = 24, ["param1"] = 15, ["z"] = 16, ["name"] = "wool:white"}, {["x"] = 13, ["y"] = 25, ["param1"] = 15, ["z"] = 6, ["name"] = "wool:white"}, {["x"] = 13, ["y"] = 25, ["param1"] = 15, ["z"] = 16, ["name"] = "wool:white"}, {["x"] = 13, ["y"] = 26, ["param1"] = 15, ["z"] = 6, ["name"] = "wool:white"}, {["x"] = 13, ["y"] = 26, ["param1"] = 15, ["z"] = 16, ["name"] = "wool:white"}, {["x"] = 13, ["y"] = 27, ["param1"] = 15, ["z"] = 7, ["name"] = "wool:white"}, {["x"] = 13, ["y"] = 27, ["param1"] = 15, ["z"] = 15, ["name"] = "wool:white"}, {["x"] = 13, ["y"] = 28, ["param1"] = 15, ["z"] = 8, ["name"] = "wool:white"}, {["x"] = 13, ["y"] = 28, ["param1"] = 15, ["z"] = 14, ["name"] = "wool:white"}, {["x"] = 13, ["y"] = 29, ["param1"] = 15, ["z"] = 9, ["name"] = "wool:white"}, {["x"] = 13, ["y"] = 29, ["param1"] = 15, ["z"] = 10, ["name"] = "wool:white"}, {["x"] = 13, ["y"] = 29, ["param1"] = 15, ["z"] = 11, ["name"] = "wool:white"}, {["x"] = 13, ["y"] = 29, ["param1"] = 15, ["z"] = 12, ["name"] = "wool:white"}, {["x"] = 13, ["y"] = 29, ["param1"] = 15, ["z"] = 13, ["name"] = "wool:white"}, {["x"] = 14, ["y"] = 0, ["z"] = 11, ["name"] = "default:wood"}, {["x"] = 14, ["y"] = 1, ["z"] = 9, ["name"] = "default:wood"}, {["x"] = 14, ["y"] = 1, ["z"] = 10, ["name"] = "default:wood"}, {["x"] = 14, ["y"] = 1, ["z"] = 12, ["name"] = "default:wood"}, {["x"] = 14, ["y"] = 1, ["z"] = 13, ["name"] = "default:wood"}, {["x"] = 14, ["y"] = 2, ["z"] = 8, ["name"] = "default:wood"}, {["x"] = 14, ["y"] = 2, ["z"] = 14, ["name"] = "default:wood"}, {["x"] = 14, ["y"] = 3, ["z"] = 7, ["name"] = "default:wood"}, {["x"] = 14, ["y"] = 3, ["z"] = 15, ["name"] = "default:wood"}, {["x"] = 14, ["y"] = 4, ["z"] = 7, ["name"] = "default:wood"}, {["x"] = 14, ["y"] = 4, ["z"] = 15, ["name"] = "default:wood"}, {["x"] = 14, ["y"] = 5, ["z"] = 6, ["name"] = "default:wood"}, {["x"] = 14, ["y"] = 5, ["z"] = 16, ["name"] = "default:wood"}, {["x"] = 14, ["y"] = 6, ["z"] = 6, ["name"] = "default:wood"}, {["x"] = 14, ["y"] = 6, ["z"] = 16, ["name"] = "default:wood"}, {["x"] = 14, ["y"] = 7, ["z"] = 6, ["name"] = "default:wood"}, {["x"] = 14, ["y"] = 7, ["param1"] = 15, ["z"] = 7, ["name"] = "default:wood"}, {["x"] = 14, ["y"] = 7, ["param1"] = 15, ["z"] = 8, ["name"] = "default:wood"}, {["x"] = 14, ["y"] = 7, ["param1"] = 15, ["z"] = 9, ["name"] = "default:wood"}, {["x"] = 14, ["y"] = 7, ["param1"] = 15, ["z"] = 10, ["name"] = "default:wood"}, {["x"] = 14, ["y"] = 7, ["param1"] = 15, ["z"] = 11, ["name"] = "default:wood"}, {["x"] = 14, ["y"] = 7, ["param1"] = 15, ["z"] = 12, ["name"] = "default:wood"}, {["x"] = 14, ["y"] = 7, ["param1"] = 15, ["z"] = 13, ["name"] = "default:wood"}, {["x"] = 14, ["y"] = 7, ["param1"] = 15, ["z"] = 14, ["name"] = "default:wood"}, {["x"] = 14, ["y"] = 7, ["z"] = 15, ["name"] = "default:wood"}, {["x"] = 14, ["y"] = 7, ["z"] = 16, ["name"] = "default:wood"}, {["x"] = 14, ["y"] = 8, ["param1"] = 94, ["z"] = 6, ["name"] = "default:fence_wood"}, {["x"] = 14, ["y"] = 8, ["param1"] = 94, ["z"] = 16, ["name"] = "default:fence_wood"}, {["x"] = 14, ["y"] = 19, ["param1"] = 15, ["z"] = 9, ["name"] = "wool:white"}, {["x"] = 14, ["y"] = 19, ["param1"] = 15, ["z"] = 10, ["name"] = "wool:white"}, {["x"] = 14, ["y"] = 19, ["param1"] = 15, ["z"] = 11, ["name"] = "wool:white"}, {["x"] = 14, ["y"] = 19, ["param1"] = 15, ["z"] = 12, ["name"] = "wool:white"}, {["x"] = 14, ["y"] = 19, ["param1"] = 15, ["z"] = 13, ["name"] = "wool:white"}, {["x"] = 14, ["y"] = 20, ["param1"] = 15, ["z"] = 8, ["name"] = "wool:white"}, {["x"] = 14, ["y"] = 20, ["param1"] = 15, ["z"] = 14, ["name"] = "wool:white"}, {["x"] = 14, ["y"] = 21, ["param1"] = 15, ["z"] = 7, ["name"] = "wool:white"}, {["x"] = 14, ["y"] = 21, ["param1"] = 15, ["z"] = 15, ["name"] = "wool:white"}, {["x"] = 14, ["y"] = 22, ["param1"] = 15, ["z"] = 6, ["name"] = "wool:white"}, {["x"] = 14, ["y"] = 22, ["param1"] = 15, ["z"] = 16, ["name"] = "wool:white"}, {["x"] = 14, ["y"] = 23, ["param1"] = 15, ["z"] = 6, ["name"] = "wool:white"}, {["x"] = 14, ["y"] = 23, ["param1"] = 15, ["z"] = 16, ["name"] = "wool:white"}, {["x"] = 14, ["y"] = 24, ["param1"] = 15, ["z"] = 6, ["name"] = "wool:white"}, {["x"] = 14, ["y"] = 24, ["param1"] = 221, ["z"] = 11, ["name"] = "caverealms:glow_crystal"}, {["x"] = 14, ["y"] = 24, ["param1"] = 15, ["z"] = 16, ["name"] = "wool:white"}, {["x"] = 14, ["y"] = 25, ["param1"] = 15, ["z"] = 6, ["name"] = "wool:white"}, {["x"] = 14, ["y"] = 25, ["param1"] = 15, ["z"] = 16, ["name"] = "wool:white"}, {["x"] = 14, ["y"] = 26, ["param1"] = 15, ["z"] = 6, ["name"] = "wool:white"}, {["x"] = 14, ["y"] = 26, ["param1"] = 15, ["z"] = 16, ["name"] = "wool:white"}, {["x"] = 14, ["y"] = 27, ["param1"] = 15, ["z"] = 7, ["name"] = "wool:white"},