5:return {{["x"] = 0, ["y"] = 9, ["param1"] = 31, ["z"] = 0, ["name"] = "default:brick"}, {["x"] = 0, ["y"] = 9, ["param1"] = 31, ["z"] = 1, ["name"] = "default:brick"}, {["x"] = 0, ["y"] = 9, ["param1"] = 31, ["z"] = 2, ["name"] = "default:brick"}, {["x"] = 0, ["y"] = 9, ["param1"] = 47, ["z"] = 3, ["name"] = "default:brick"}, {["x"] = 0, ["y"] = 9, ["param1"] = 47, ["z"] = 4, ["name"] = "default:brick"}, {["x"] = 0, ["y"] = 9, ["param1"] = 47, ["z"] = 5, ["name"] = "default:brick"}, {["x"] = 0, ["y"] = 9, ["param1"] = 47, ["z"] = 6, ["name"] = "default:brick"}, {["x"] = 0, ["y"] = 9, ["param1"] = 31, ["z"] = 7, ["name"] = "default:brick"}, {["x"] = 0, ["y"] = 9, ["param1"] = 31, ["z"] = 8, ["name"] = "default:brick"}, {["x"] = 0, ["y"] = 9, ["param1"] = 31, ["z"] = 9, ["name"] = "default:brick"}, {["x"] = 0, ["y"] = 10, ["param1"] = 15, ["z"] = 0, ["name"] = "technic:marble"}, {["x"] = 0, ["y"] = 10, ["param1"] = 94, ["z"] = 1, ["name"] = "lapis:lapis_cobble"}, {["x"] = 0, ["y"] = 10, ["param1"] = 15, ["z"] = 2, ["name"] = "spawners_mobs:deco_stone_sun"}, {["x"] = 0, ["y"] = 10, ["param1"] = 62, ["z"] = 3, ["name"] = "lapis:lapis_cobble"}, {["x"] = 0, ["y"] = 10, ["param1"] = 15, ["z"] = 4, ["name"] = "spawners_mobs:deco_stone_sun"}, {["x"] = 0, ["y"] = 10, ["param1"] = 15, ["z"] = 5, ["name"] = "spawners_mobs:deco_stone_sun"}, {["x"] = 0, ["y"] = 10, ["param1"] = 62, ["z"] = 6, ["name"] = "lapis:lapis_cobble"}, {["x"] = 0, ["y"] = 10, ["param1"] = 15, ["z"] = 7, ["name"] = "spawners_mobs:deco_stone_sun"}, {["x"] = 0, ["y"] = 10, ["param1"] = 94, ["z"] = 8, ["name"] = "lapis:lapis_cobble"}, {["x"] = 0, ["y"] = 10, ["param1"] = 15, ["z"] = 9, ["name"] = "technic:marble"}, {["x"] = 0, ["y"] = 11, ["param1"] = 126, ["z"] = 0, ["name"] = "xpanes:pane"}, {["x"] = 0, ["param2"] = 3, ["y"] = 11, ["param1"] = 110, ["z"] = 1, ["name"] = "xpanes:pane_flat"}, {["x"] = 0, ["param2"] = 3, ["y"] = 11, ["param1"] = 94, ["z"] = 2, ["name"] = "xpanes:pane_flat"}, {["x"] = 0, ["param2"] = 3, ["y"] = 11, ["param1"] = 78, ["z"] = 3, ["name"] = "xpanes:pane_flat"}, {["x"] = 0, ["param2"] = 3, ["y"] = 11, ["param1"] = 62, ["z"] = 4, ["name"] = "xpanes:pane_flat"}, {["x"] = 0, ["param2"] = 3, ["y"] = 11, ["param1"] = 62, ["z"] = 5, ["name"] = "xpanes:pane_flat"}, {["x"] = 0, ["param2"] = 3, ["y"] = 11, ["param1"] = 78, ["z"] = 6, ["name"] = "xpanes:pane_flat"}, {["x"] = 0, ["param2"] = 3, ["y"] = 11, ["param1"] = 94, ["z"] = 7, ["name"] = "xpanes:pane_flat"}, {["x"] = 0, ["param2"] = 3, ["y"] = 11, ["param1"] = 110, ["z"] = 8, ["name"] = "xpanes:pane_flat"}, {["x"] = 0, ["y"] = 11, ["param1"] = 126, ["z"] = 9, ["name"] = "xpanes:pane"}, {["x"] = 0, ["y"] = 12, ["param1"] = 15, ["z"] = 0, ["name"] = "default:goldblock"}, {["x"] = 0, ["y"] = 12, ["param1"] = 15, ["z"] = 1, ["name"] = "default:goldblock"}, {["x"] = 0, ["y"] = 12, ["param1"] = 15, ["z"] = 2, ["name"] = "default:goldblock"}, {["x"] = 0, ["y"] = 12, ["param1"] = 15, ["z"] = 3, ["name"] = "default:goldblock"}, {["x"] = 0, ["y"] = 12, ["param1"] = 15, ["z"] = 4, ["name"] = "default:goldblock"}, {["x"] = 0, ["y"] = 12, ["param1"] = 15, ["z"] = 5, ["name"] = "default:goldblock"}, {["x"] = 0, ["y"] = 12, ["param1"] = 15, ["z"] = 6, ["name"] = "default:goldblock"}, {["x"] = 0, ["y"] = 12, ["param1"] = 15, ["z"] = 7, ["name"] = "default:goldblock"}, {["x"] = 0, ["y"] = 12, ["param1"] = 15, ["z"] = 8, ["name"] = "default:goldblock"}, {["x"] = 0, ["y"] = 12, ["param1"] = 15, ["z"] = 9, ["name"] = "default:goldblock"}, {["x"] = 0, ["param2"] = 1, ["y"] = 13, ["param1"] = 15, ["z"] = 0, ["name"] = "bones:bones"}, {["x"] = 0, ["y"] = 13, ["param1"] = 15, ["z"] = 1, ["name"] = "bones:bones"}, {["x"] = 0, ["y"] = 13, ["param1"] = 15, ["z"] = 2, ["name"] = "bones:bones"}, {["x"] = 0, ["y"] = 13, ["param1"] = 15, ["z"] = 3, ["name"] = "bones:bones"}, {["x"] = 0, ["y"] = 13, ["param1"] = 15, ["z"] = 4, ["name"] = "default:cobble"}, {["x"] = 0, ["y"] = 13, ["param1"] = 15, ["z"] = 5, ["name"] = "default:cobble"}, {["x"] = 0, ["param2"] = 2, ["y"] = 13, ["param1"] = 15, ["z"] = 6, ["name"] = "bones:bones"}, {["x"] = 0, ["param2"] = 2, ["y"] = 13, ["param1"] = 15, ["z"] = 7, ["name"] = "bones:bones"}, {["x"] = 0, ["param2"] = 2, ["y"] = 13, ["param1"] = 15, ["z"] = 8, ["name"] = "bones:bones"}, {["x"] = 0, ["param2"] = 1, ["y"] = 13, ["param1"] = 15, ["z"] = 9, ["name"] = "bones:bones"}, {["x"] = 0, ["param2"] = 1, ["y"] = 14, ["param1"] = 207, ["z"] = 0, ["name"] = "default:torch"}, {["x"] = 0, ["param2"] = 1, ["y"] = 14, ["param1"] = 207, ["z"] = 9, ["name"] = "default:torch"}, {["x"] = 1, ["param2"] = 2, ["y"] = 0, ["param1"] = 125, ["z"] = 3, ["name"] = "lapis:base_lazurite_block"}, {["x"] = 1, ["param2"] = 3, ["y"] = 0, ["param1"] = 125, ["z"] = 6, ["name"] = "lapis:base_lazurite_block"}, {["x"] = 1, ["meta"] = {["fields"] = {["infotext"] = "by n ", ["text"] = "by n", ["__signslib_new_format"] = "1", ["formspec"] = "size[6,4]textarea[0,-0.3;6.5,3;text;;${text}]button_exit[2,3.4;2,1;ok;Write]background[-0.5,-0.5;7,5;bg_signs_lib.jpg]"}, ["inventory"] = {}}, ["param2"] = 1, ["y"] = 0, ["param1"] = 142, ["z"] = 9, ["name"] = "signs:sign_yard"}, {["x"] = 1, ["param2"] = 3, ["y"] = 1, ["param1"] = 125, ["z"] = 3, ["name"] = "lapis:column_lazurite_block"}, {["x"] = 1, ["param2"] = 1, ["y"] = 1, ["param1"] = 125, ["z"] = 6, ["name"] = "lapis:column_lazurite_block"}, {["x"] = 1, ["param2"] = 3, ["y"] = 2, ["param1"] = 141, ["z"] = 3, ["name"] = "lapis:column_lazurite_block"}, {["x"] = 1, ["param2"] = 1, ["y"] = 2, ["param1"] = 141, ["z"] = 6, ["name"] = "lapis:column_lazurite_block"}, {["x"] = 1, ["param2"] = 3, ["y"] = 3, ["param1"] = 157, ["z"] = 3, ["name"] = "lapis:column_lazurite_block"}, {["x"] = 1, ["param2"] = 1, ["y"] = 3, ["param1"] = 157, ["z"] = 6, ["name"] = "lapis:column_lazurite_block"}, {["x"] = 1, ["param2"] = 3, ["y"] = 4, ["param1"] = 141, ["z"] = 3, ["name"] = "lapis:column_lazurite_block"}, {["x"] = 1, ["param2"] = 3, ["y"] = 4, ["param1"] = 141, ["z"] = 6, ["name"] = "lapis:column_lazurite_block"}, {["x"] = 1, ["param2"] = 3, ["y"] = 5, ["param1"] = 125, ["z"] = 3, ["name"] = "lapis:column_lazurite_block"}, {["x"] = 1, ["param2"] = 3, ["y"] = 5, ["param1"] = 125, ["z"] = 6, ["name"] = "lapis:column_lazurite_block"}, {["x"] = 1, ["param2"] = 3, ["y"] = 6, ["param1"] = 109, ["z"] = 3, ["name"] = "lapis:column_lazurite_block"}, {["x"] = 1, ["param2"] = 1, ["y"] = 6, ["param1"] = 109, ["z"] = 6, ["name"] = "lapis:column_lazurite_block"}, {["x"] = 1, ["param2"] = 3, ["y"] = 7, ["param1"] = 92, ["z"] = 3, ["name"] = "lapis:column_lazurite_block"}, {["x"] = 1, ["param2"] = 1, ["y"] = 7, ["param1"] = 92, ["z"] = 6, ["name"] = "lapis:column_lazurite_block"}, {["x"] = 1, ["param2"] = 21, ["y"] = 8, ["param1"] = 77, ["z"] = 3, ["name"] = "lapis:base_lazurite_block"}, {["x"] = 1, ["param2"] = 23, ["y"] = 8, ["param1"] = 77, ["z"] = 6, ["name"] = "lapis:base_lazurite_block"}, {["x"] = 1, ["y"] = 9, ["param1"] = 47, ["z"] = 0, ["name"] = "default:brick"}, {["x"] = 1, ["y"] = 9, ["param1"] = 47, ["z"] = 1, ["name"] = "default:brick"}, {["x"] = 1, ["y"] = 9, ["param1"] = 47, ["z"] = 2, ["name"] = "default:brick"}, {["x"] = 1, ["y"] = 9, ["param1"] = 63, ["z"] = 3, ["name"] = "default:brick"}, {["x"] = 1, ["y"] = 9, ["param1"] = 63, ["z"] = 4, ["name"] = "default:brick"}, {["x"] = 1, ["y"] = 9, ["param1"] = 63, ["z"] = 5, ["name"] = "default:brick"}, {["x"] = 1, ["y"] = 9, ["param1"] = 63, ["z"] = 6, ["name"] = "default:brick"}, {["x"] = 1, ["y"] = 9, ["param1"] = 47, ["z"] = 7, ["name"] = "default:brick"}, {["x"] = 1, ["y"] = 9, ["param1"] = 47, ["z"] = 8, ["name"] = "default:brick"}, {["x"] = 1, ["y"] = 9, ["param1"] = 47, ["z"] = 9, ["name"] = "default:brick"}, {["x"] = 1, ["y"] = 10, ["param1"] = 15, ["z"] = 0, ["name"] = "technic:granite"}, {["x"] = 1, ["param2"] = 3, ["y"] = 10, ["param1"] = 60, ["z"] = 7, ["name"] = "trunks:twig_2"}, {["x"] = 1, ["y"] = 10, ["param1"] = 15, ["z"] = 9, ["name"] = "technic:granite"}, {["x"] = 1, ["y"] = 11, ["param1"] = 110, ["z"] = 0, ["name"] = "xpanes:pane_flat"}, {["x"] = 1, ["y"] = 11, ["param1"] = 110, ["z"] = 9, ["name"] = "xpanes:pane_flat"}, {["x"] = 1, ["y"] = 12, ["param1"] = 15, ["z"] = 0, ["name"] = "default:goldblock"}, {["x"] = 1, ["y"] = 12, ["param1"] = 15, ["z"] = 9, ["name"] = "default:goldblock"}, {["x"] = 1, ["param2"] = 1, ["y"] = 13, ["param1"] = 15, ["z"] = 0, ["name"] = "bones:bones"}, {["x"] = 1, ["y"] = 13, ["param1"] = 15, ["z"] = 1, ["name"] = "moreores:silver_block"}, {["x"] = 1, ["y"] = 13, ["param1"] = 15, ["z"] = 2, ["name"] = "technic:chromium_block"}, {["x"] = 1, ["y"] = 13, ["param1"] = 15, ["z"] = 3, ["name"] = "technic:chromium_block"}, {["x"] = 1, ["y"] = 13, ["param1"] = 15, ["z"] = 4, ["name"] = "technic:chromium_block"}, {["x"] = 1, ["y"] = 13, ["param1"] = 15, ["z"] = 5, ["name"] = "technic:chromium_block"}, {["x"] = 1, ["y"] = 13, ["param1"] = 15, ["z"] = 6, ["name"] = "technic:chromium_block"}, {["x"] = 1, ["y"] = 13, ["param1"] = 15, ["z"] = 7, ["name"] = "technic:chromium_block"}, {["x"] = 1, ["y"] = 13, ["param1"] = 15, ["z"] = 8, ["name"] = "moreores:silver_block"}, {["x"] = 1, ["param2"] = 1, ["y"] = 13, ["param1"] = 15, ["z"] = 9, ["name"] = "bones:bones"}, {["x"] = 2, ["y"] = 9, ["param1"] = 63, ["z"] = 0, ["name"] = "default:brick"}, {["x"] = 2, ["y"] = 9, ["param1"] = 63, ["z"] = 1, ["name"] = "default:brick"}, {["x"] = 2, ["y"] = 9, ["param1"] = 63, ["z"] = 2, ["name"] = "default:brick"}, {["x"] = 2, ["y"] = 9, ["param1"] = 79, ["z"] = 3, ["name"] = "default:brick"}, {["x"] = 2, ["y"] = 9, ["param1"] = 79, ["z"] = 4, ["name"] = "default:brick"}, {["x"] = 2, ["y"] = 9, ["param1"] = 79, ["z"] = 5, ["name"] = "default:brick"}, {["x"] = 2, ["y"] = 9, ["param1"] = 79, ["z"] = 6, ["name"] = "default:brick"}, {["x"] = 2, ["y"] = 9, ["param1"] = 63, ["z"] = 7, ["name"] = "default:brick"}, {["x"] = 2, ["y"] = 9, ["param1"] = 63, ["z"] = 8, ["name"] = "default:brick"}, {["x"] = 2, ["y"] = 9, ["param1"] = 63, ["z"] = 9, ["name"] = "default:brick"}, {["x"] = 2, ["y"] = 10, ["param1"] = 31, ["z"] = 0, ["name"] = "default:brick"}, {["x"] = 2, ["y"] = 10, ["param1"] = 31, ["z"] = 9, ["name"] = "default:brick"}, {["x"] = 2, ["y"] = 11, ["param1"] = 94, ["z"] = 0, ["name"] = "xpanes:pane_flat"}, {["x"] = 2, ["y"] = 11, ["param1"] = 94, ["z"] = 9, ["name"] = "xpanes:pane_flat"}, {["x"] = 2, ["y"] = 12, ["param1"] = 15, ["z"] = 0, ["name"] = "default:goldblock"}, {["x"] = 2, ["y"] = 12, ["param1"] = 15, ["z"] = 9, ["name"] = "default:goldblock"}, {["x"] = 2, ["param2"] = 1, ["y"] = 13, ["param1"] = 15, ["z"] = 0, ["name"] = "bones:bones"}, {["x"] = 2, ["param2"] = 1, ["y"] = 13, ["param1"] = 15, ["z"] = 1, ["name"] = "bones:bones"}, {["x"] = 2, ["param2"] = 1, ["y"] = 13, ["param1"] = 15, ["z"] = 2, ["name"] = "bones:bones"}, {["x"] = 2, ["param2"] = 1, ["y"] = 13, ["param1"] = 15, ["z"] = 3, ["name"] = "bones:bones"}, {["x"] = 2, ["param2"] = 1, ["y"] = 13, ["param1"] = 15, ["z"] = 4, ["name"] = "bones:bones"}, {["x"] = 2, ["param2"] = 1, ["y"] = 13, ["param1"] = 15, ["z"] = 5, ["name"] = "bones:bones"}, {["x"] = 2, ["param2"] = 1, ["y"] = 13, ["param1"] = 15, ["z"] = 6, ["name"] = "bones:bones"}, {["x"] = 2, ["param2"] = 1, ["y"] = 13, ["param1"] = 15, ["z"] = 7, ["name"] = "bones:bones"}, {["x"] = 2, ["param2"] = 1, ["y"] = 13, ["param1"] = 15, ["z"] = 8, ["name"] = "bones:bones"}, {["x"] = 2, ["param2"] = 1, ["y"] = 13, ["param1"] = 15, ["z"] = 9, ["name"] = "bones:bones"}, {["x"] = 3, ["param2"] = 3, ["y"] = 0, ["param1"] = 142, ["z"] = 0, ["name"] = "cavestuff:pebble_1"}, {["x"] = 3, ["param2"] = 3, ["y"] = 0, ["param1"] = 157, ["z"] = 1, ["name"] = "cavestuff:pebble_2"}, {["x"] = 3, ["param2"] = 3, ["y"] = 0, ["param1"] = 172, ["z"] = 2, ["name"] = "cavestuff:pebble_1"}, {["x"] = 3, ["param2"] = 3, ["y"] = 0, ["param1"] = 155, ["z"] = 3, ["name"] = "cavestuff:pebble_1"}, {["x"] = 3, ["param2"] = 3, ["y"] = 0, ["param1"] = 139, ["z"] = 4, ["name"] = "cavestuff:pebble_1"}, {["x"] = 3, ["param2"] = 3, ["y"] = 0, ["param1"] = 139, ["z"] = 5, ["name"] = "cavestuff:pebble_1"}, {["x"] = 3, ["param2"] = 3, ["y"] = 0, ["param1"] = 155, ["z"] = 6, ["name"] = "cavestuff:pebble_1"}, {["x"] = 3, ["param2"] = 3, ["y"] = 0, ["param1"] = 172, ["z"] = 7, ["name"] = "cavestuff:pebble_1"}, {["x"] = 3, ["param2"] = 3, ["y"] = 0, ["param1"] = 157, ["z"] = 8, ["name"] = "cavestuff:pebble_2"}, {["x"] = 3, ["param2"] = 3, ["y"] = 0, ["param1"] = 174, ["z"] = 9, ["name"] = "cavestuff:pebble_1"}, {["x"] = 3, ["y"] = 9, ["param1"] = 79, ["z"] = 0, ["name"] = "default:brick"}, {["x"] = 3, ["y"] = 9, ["param1"] = 79, ["z"] = 1, ["name"] = "default:brick"}, {["x"] = 3, ["y"] = 9, ["param1"] = 79, ["z"] = 2, ["name"] = "default:brick"}, {["x"] = 3, ["y"] = 9, ["param1"] = 95, ["z"] = 3, ["name"] = "default:brick"}, {["x"] = 3, ["y"] = 9, ["param1"] = 95, ["z"] = 4, ["name"] = "default:brick"}, {["x"] = 3, ["y"] = 9, ["param1"] = 95, ["z"] = 5, ["name"] = "default:brick"}, {["x"] = 3, ["y"] = 9, ["param1"] = 95, ["z"] = 6, ["name"] = "default:brick"}, {["x"] = 3, ["y"] = 9, ["param1"] = 79, ["z"] = 7, ["name"] = "default:brick"}, {["x"] = 3, ["y"] = 9, ["param1"] = 79, ["z"] = 8, ["name"] = "default:brick"}, {["x"] = 3, ["y"] = 9, ["param1"] = 79, ["z"] = 9, ["name"] = "default:brick"}, {["x"] = 3, ["y"] = 10, ["param1"] = 47, ["z"] = 0, ["name"] = "default:brick"}, {["x"] = 3, ["y"] = 10, ["param1"] = 47, ["z"] = 9, ["name"] = "default:brick"}, {["x"] = 3, ["y"] = 11, ["param1"] = 78, ["z"] = 0, ["name"] = "xpanes:pane_flat"}, {["x"] = 3, ["y"] = 11, ["param1"] = 78, ["z"] = 9, ["name"] = "xpanes:pane_flat"}, {["x"] = 3, ["y"] = 12, ["param1"] = 15, ["z"] = 0, ["name"] = "default:goldblock"}, {["x"] = 3, ["y"] = 12, ["param1"] = 15, ["z"] = 9, ["name"] = "default:goldblock"}, {["x"] = 3, ["param2"] = 1, ["y"] = 13, ["param1"] = 15, ["z"] = 0, ["name"] = "bones:bones"}, {["x"] = 3, ["param2"] = 3, ["y"] = 13, ["param1"] = 15, ["z"] = 1, ["name"] = "bones:bones"}, {["x"] = 3, ["param2"] = 3, ["y"] = 13, ["param1"] = 15, ["z"] = 2, ["name"] = "bones:bones"}, {["x"] = 3, ["param2"] = 3, ["y"] = 13, ["param1"] = 15, ["z"] = 3, ["name"] = "bones:bones"}, {["x"] = 3, ["param2"] = 3, ["y"] = 13, ["param1"] = 31, ["z"] = 4, ["name"] = "bones:bones"}, {["x"] = 3, ["param2"] = 3, ["y"] = 13, ["param1"] = 15, ["z"] = 5, ["name"] = "bones:bones"}, {["x"] = 3, ["param2"] = 3, ["y"] = 13, ["param1"] = 15, ["z"] = 6, ["name"] = "bones:bones"}, {["x"] = 3, ["param2"] = 3, ["y"] = 13, ["param1"] = 15, ["z"] = 7, ["name"] = "bones:bones"}, {["x"] = 3, ["param2"] = 3, ["y"] = 13, ["param1"] = 15, ["z"] = 8, ["name"] = "bones:bones"}, {["x"] = 3, ["param2"] = 1, ["y"] = 13, ["param1"] = 15, ["z"] = 9, ["name"] = "bones:bones"}, {["x"] = 4, ["y"] = 0, ["param1"] = 190, ["z"] = 0, ["name"] = "caverealms:glow_gem_4"}, {["x"] = 4, ["y"] = 0, ["param1"] = 173, ["z"] = 1, ["name"] = "caverealms:icicle_up"}, {["x"] = 4, ["y"] = 0, ["param1"] = 188, ["z"] = 2, ["name"] = "caverealms:glow_gem_5"}, {["x"] = 4, ["param2"] = 3, ["y"] = 0, ["param1"] = 154, ["z"] = 4, ["name"] = "doors:trapdoor_open"}, {["x"] = 4, ["param2"] = 3, ["y"] = 0, ["param1"] = 154, ["z"] = 5, ["name"] = "doors:trapdoor_open"}, {["x"] = 4, ["y"] = 0, ["param1"] = 188, ["z"] = 7, ["name"] = "caverealms:glow_gem_5"}, {["x"] = 4, ["y"] = 0, ["param1"] = 173, ["z"] = 8, ["name"] = "caverealms:icicle_up"}, {["x"] = 4, ["y"] = 0, ["param1"] = 190, ["z"] = 9, ["name"] = "caverealms:glow_gem_4"}, {["x"] = 4, ["y"] = 9, ["param1"] = 95, ["z"] = 0, ["name"] = "default:brick"}, {["x"] = 4, ["y"] = 9, ["param1"] = 95, ["z"] = 1, ["name"] = "default:brick"}, {["x"] = 4, ["y"] = 9, ["param1"] = 95, ["z"] = 2, ["name"] = "default:brick"}, {["x"] = 4, ["y"] = 9, ["param1"] = 111, ["z"] = 3, ["name"] = "default:desert_cobble"}, {["x"] = 4, ["y"] = 9, ["param1"] = 111, ["z"] = 4, ["name"] = "birthstones:alexandriteblock"}, {["x"] = 4, ["y"] = 9, ["param1"] = 111, ["z"] = 5, ["name"] = "birthstones:alexandriteblock"}, {["x"] = 4, ["y"] = 9, ["param1"] = 111, ["z"] = 6, ["name"] = "default:desert_cobble"}, {["x"] = 4, ["y"] = 9, ["param1"] = 95, ["z"] = 7, ["name"] = "default:brick"}, {["x"] = 4, ["y"] = 9, ["param1"] = 95, ["z"] = 8, ["name"] = "default:brick"}, {["x"] = 4, ["y"] = 9, ["param1"] = 95, ["z"] = 9, ["name"] = "default:brick"}, {["x"] = 4, ["y"] = 10, ["param1"] = 47, ["z"] = 0, ["name"] = "default:brick"}, {["x"] = 4, ["y"] = 10, ["param1"] = 63, ["z"] = 9, ["name"] = "default:brick"}, {["x"] = 4, ["param2"] = 2, ["y"] = 11, ["param1"] = 62, ["z"] = 0, ["name"] = "xpanes:pane_flat"}, {["x"] = 4, ["param2"] = 2, ["y"] = 11, ["param1"] = 62, ["z"] = 9, ["name"] = "xpanes:pane_flat"}, {["x"] = 4, ["y"] = 12, ["param1"] = 31, ["z"] = 0, ["name"] = "default:goldblock"}, {["x"] = 4, ["y"] = 12, ["param1"] = 31, ["z"] = 9, ["name"] = "default:goldblock"}, {["x"] = 4, ["param2"] = 1, ["y"] = 13, ["param1"] = 15, ["z"] = 0, ["name"] = "bones:bones"}, {["x"] = 4, ["y"] = 13, ["param1"] = 31, ["z"] = 1, ["name"] = "moreores:silver_block"}, {["x"] = 4, ["y"] = 13, ["param1"] = 15, ["z"] = 2, ["name"] = "technic:chromium_block"}, {["x"] = 4, ["param2"] = 3, ["y"] = 13, ["param1"] = 31, ["z"] = 3, ["name"] = "bones:bones"}, {["x"] = 4, ["y"] = 13, ["param1"] = 47, ["z"] = 4, ["name"] = "moreores:silver_block"}, {["x"] = 4, ["y"] = 13, ["param1"] = 31, ["z"] = 5, ["name"] = "moreores:silver_block"}, {["x"] = 4, ["param2"] = 3, ["y"] = 13, ["param1"] = 15, ["z"] = 6, ["name"] = "bones:bones"}, {["x"] = 4, ["y"] = 13, ["param1"] = 15, ["z"] = 7, ["name"] = "technic:chromium_block"}, {["x"] = 4, ["y"] = 13, ["param1"] = 31, ["z"] = 8, ["name"] = "moreores:silver_block"}, {["x"] = 4, ["param2"] = 1, ["y"] = 13, ["param1"] = 15, ["z"] = 9, ["name"] = "bones:bones"}, {["x"] = 5, ["y"] = 0, ["param1"] = 159, ["z"] = 0, ["name"] = "moretrees:rubber_tree_planks"}, {["x"] = 5, ["y"] = 0, ["param1"] = 143, ["z"] = 1, ["name"] = "moretrees:rubber_tree_planks"}, {["x"] = 5, ["y"] = 0, ["param1"] = 127, ["z"] = 2, ["name"] = "moretrees:rubber_tree_planks"}, {["x"] = 5, ["y"] = 0, ["param1"] = 111, ["z"] = 3, ["name"] = "moretrees:rubber_tree_planks"}, {["x"] = 5, ["y"] = 0, ["param1"] = 95, ["z"] = 4, ["name"] = "moretrees:rubber_tree_planks"}, {["x"] = 5, ["y"] = 0, ["param1"] = 95, ["z"] = 5, ["name"] = "moretrees:rubber_tree_planks"}, {["x"] = 5, ["y"] = 0, ["param1"] = 111, ["z"] = 6, ["name"] = "moretrees:rubber_tree_planks"}, {["x"] = 5, ["y"] = 0, ["param1"] = 127, ["z"] = 7, ["name"] = "moretrees:rubber_tree_planks"}, {["x"] = 5, ["y"] = 0, ["param1"] = 143, ["z"] = 8, ["name"] = "moretrees:rubber_tree_planks"}, {["x"] = 5, ["y"] = 0, ["param1"] = 159, ["z"] = 9, ["name"] = "moretrees:rubber_tree_planks"}, {["x"] = 5, ["y"] = 1, ["param1"] = 175, ["z"] = 0, ["name"] = "default:desert_cobble"}, {["x"] = 5, ["y"] = 1, ["param1"] = 172, ["z"] = 1, ["name"] = "caverealms:glow_ore"}, {["x"] = 5, ["y"] = 1, ["param1"] = 171, ["z"] = 2, ["name"] = "caverealms:glow_ore"}, {["x"] = 5, ["y"] = 1, ["param1"] = 187, ["z"] = 3, ["name"] = "caverealms:glow_ore"}, {["x"] = 5, ["y"] = 1, ["param1"] = 170, ["z"] = 4, ["name"] = "doors:bedroom_a"}, {["x"] = 5, ["param2"] = 2, ["y"] = 1, ["param1"] = 170, ["z"] = 5, ["name"] = "doors:bedroom_b"}, {["x"] = 5, ["y"] = 1, ["param1"] = 187, ["z"] = 6, ["name"] = "caverealms:glow_ore"}, {["x"] = 5, ["y"] = 1, ["param1"] = 172, ["z"] = 7, ["name"] = "caverealms:glow_ore"}, {["x"] = 5, ["y"] = 1, ["param1"] = 173, ["z"] = 8, ["name"] = "caverealms:glow_ore"}, {["x"] = 5, ["y"] = 1, ["param1"] = 174, ["z"] = 9, ["name"] = "lapis:lapis_cobble"}, {["x"] = 5, ["y"] = 2, ["param1"] = 190, ["z"] = 0, ["name"] = "lapis:lapis_tile"}, {["x"] = 5, ["y"] = 2, ["param1"] = 173, ["z"] = 1, ["name"] = "lapis:lapis_tile"}, {["x"] = 5, ["y"] = 2, ["param1"] = 188, ["z"] = 2, ["name"] = "lapis:lapis_tile"}, {["x"] = 5, ["y"] = 2, ["param1"] = 204, ["z"] = 3, ["name"] = "lapis:lapis_tile"}, {["x"] = 5, ["y"] = 2, ["param1"] = 187, ["z"] = 4, ["name"] = "doors:hidden"}, {["x"] = 5, ["y"] = 2, ["param1"] = 187, ["z"] = 5, ["name"] = "doors:hidden"}, {["x"] = 5, ["y"] = 2, ["param1"] = 204, ["z"] = 6, ["name"] = "lapis:lapis_tile"}, {["x"] = 5, ["y"] = 2, ["param1"] = 188, ["z"] = 7, ["name"] = "lapis:lapis_tile"}, {["x"] = 5, ["y"] = 2, ["param1"] = 173, ["z"] = 8, ["name"] = "lapis:lapis_tile"}, {["x"] = 5, ["y"] = 2, ["param1"] = 190, ["z"] = 9, ["name"] = "lapis:lapis_tile"}, {["x"] = 5, ["y"] = 3, ["param1"] = 206, ["z"] = 0, ["name"] = "lapis:lapis_tile"}, {["x"] = 5, ["y"] = 3, ["param1"] = 189, ["z"] = 1, ["name"] = "lapis:lapis_tile"}, {["x"] = 5, ["y"] = 3, ["param1"] = 204, ["z"] = 2, ["name"] = "lapis:lapis_tile"}, {["x"] = 5, ["y"] = 3, ["param1"] = 221, ["z"] = 3, ["name"] = "caverealms:glow_crystal"}, {["x"] = 5, ["y"] = 3, ["param1"] = 221, ["z"] = 4, ["name"] = "caverealms:glow_crystal"}, {["x"] = 5, ["y"] = 3, ["param1"] = 221, ["z"] = 5, ["name"] = "caverealms:glow_crystal"}, {["x"] = 5, ["y"] = 3, ["param1"] = 221, ["z"] = 6, ["name"] = "caverealms:glow_crystal"}, {["x"] = 5, ["y"] = 3, ["param1"] = 204, ["z"] = 7, ["name"] = "lapis:lapis_tile"}, {["x"] = 5, ["y"] = 3, ["param1"] = 189, ["z"] = 8, ["name"] = "lapis:lapis_tile"}, {["x"] = 5, ["y"] = 3, ["param1"] = 206, ["z"] = 9, ["name"] = "lapis:lapis_tile"}, {["x"] = 5, ["y"] = 4, ["param1"] = 190, ["z"] = 0, ["name"] = "caverealms:glow_ore"}, {["x"] = 5, ["y"] = 4, ["param1"] = 188, ["z"] = 2, ["name"] = "caverealms:glow_ore"}, {["x"] = 5, ["y"] = 4, ["param1"] = 204, ["z"] = 3, ["name"] = "caverealms:glow_ore"}, {["x"] = 5, ["y"] = 4, ["param1"] = 207, ["z"] = 4, ["name"] = "default:sandstonebrick"}, {["x"] = 5, ["y"] = 4, ["param1"] = 207, ["z"] = 5, ["name"] = "default:sandstonebrick"}, {["x"] = 5, ["y"] = 4, ["param1"] = 204, ["z"] = 6, ["name"] = "caverealms:glow_ore"}, {["x"] = 5, ["y"] = 4, ["param1"] = 188, ["z"] = 7, ["name"] = "caverealms:glow_ore"}, {["x"] = 5, ["y"] = 4, ["param1"] = 190, ["z"] = 9, ["name"] = "caverealms:glow_ore"}, {["x"] = 5, ["y"] = 5, ["param1"] = 175, ["z"] = 0, ["name"] = "technic:granite"}, {["x"] = 5, ["y"] = 5, ["param1"] = 175, ["z"] = 1, ["name"] = "default:desert_cobble"}, {["x"] = 5, ["y"] = 5, ["param1"] = 175, ["z"] = 2, ["name"] = "default:diamondblock"}, {["x"] = 5, ["y"] = 5, ["param1"] = 191, ["z"] = 3, ["name"] = "default:diamondblock"}, {["x"] = 5, ["y"] = 5, ["param1"] = 159, ["z"] = 4, ["name"] = "default:diamondblock"}, {["x"] = 5, ["y"] = 5, ["param1"] = 175, ["z"] = 5, ["name"] = "default:diamondblock"}, {["x"] = 5, ["y"] = 5, ["param1"] = 191, ["z"] = 6, ["name"] = "default:diamondblock"}, {["x"] = 5, ["y"] = 5, ["param1"] = 175, ["z"] = 7, ["name"] = "default:diamondblock"}, {["x"] = 5, ["y"] = 5, ["param1"] = 175, ["z"] = 8, ["name"] = "default:desert_cobble"}, {["x"] = 5, ["y"] = 5, ["param1"] = 175, ["z"] = 9, ["name"] = "technic:granite"}, {["x"] = 5, ["y"] = 6, ["param1"] = 143, ["z"] = 0, ["name"] = "default:desert_cobble"}, {["x"] = 5, ["y"] = 6, ["param1"] = 159, ["z"] = 1, ["name"] = "default:diamondblock"}, {["x"] = 5, ["y"] = 6, ["param1"] = 139, ["z"] = 2, ["name"] = "default:mese"}, {["x"] = 5, ["y"] = 6, ["param1"] = 138, ["z"] = 3, ["name"] = "default:mese"}, {["x"] = 5, ["y"] = 6, ["param1"] = 138, ["z"] = 4, ["name"] = "default:mese"}, {["x"] = 5, ["y"] = 6, ["param1"] = 138, ["z"] = 5, ["name"] = "default:mese"}, {["x"] = 5, ["y"] = 6, ["param1"] = 138, ["z"] = 6, ["name"] = "default:mese"}, {["x"] = 5, ["y"] = 6, ["param1"] = 139, ["z"] = 7, ["name"] = "default:mese"}, {["x"] = 5, ["y"] = 6, ["param1"] = 159, ["z"] = 8, ["name"] = "default:diamondblock"}, {["x"] = 5, ["y"] = 6, ["param1"] = 127, ["z"] = 9, ["name"] = "default:desert_cobble"}, {["x"] = 5, ["y"] = 7, ["param1"] = 127, ["z"] = 0, ["name"] = "default:obsidian"}, {["x"] = 5, ["y"] = 7, ["param1"] = 140, ["z"] = 1, ["name"] = "default:mese"}, {["x"] = 5, ["y"] = 7, ["param1"] = 123, ["z"] = 2, ["name"] = "default:mese"}, {["x"] = 5, ["y"] = 7, ["param1"] = 122, ["z"] = 3, ["name"] = "default:mese"}, {["x"] = 5, ["y"] = 7, ["param1"] = 123, ["z"] = 4, ["name"] = "default:mese"}, {["x"] = 5, ["y"] = 7, ["param1"] = 123, ["z"] = 5, ["name"] = "default:mese"}, {["x"] = 5, ["y"] = 7, ["param1"] = 122, ["z"] = 6, ["name"] = "default:mese"}, {["x"] = 5, ["y"] = 7, ["param1"] = 123, ["z"] = 7, ["name"] = "default:mese"}, {["x"] = 5, ["y"] = 7, ["param1"] = 140, ["z"] = 8, ["name"] = "default:mese"}, {["x"] = 5, ["y"] = 7, ["param1"] = 127, ["z"] = 9, ["name"] = "default:obsidian"}, {["x"] = 5, ["y"] = 8, ["param1"] = 111, ["z"] = 0, ["name"] = "default:desert_cobble"}, {["x"] = 5, ["y"] = 8, ["param1"] = 127, ["z"] = 1, ["name"] = "default:desert_cobble"}, {["x"] = 5, ["y"] = 8, ["param1"] = 111, ["z"] = 2, ["name"] = "default:desert_cobble"}, {["x"] = 5, ["y"] = 8, ["param1"] = 111, ["z"] = 3, ["name"] = "technic:marble"}, {["x"] = 5, ["y"] = 8, ["param1"] = 108, ["z"] = 4, ["name"] = "default:mese"}, {["x"] = 5, ["y"] = 8, ["param1"] = 108, ["z"] = 5, ["name"] = "default:mese"}, {["x"] = 5, ["y"] = 8, ["param1"] = 111, ["z"] = 6, ["name"] = "technic:marble"}, {["x"] = 5, ["y"] = 8, ["param1"] = 111, ["z"] = 7, ["name"] = "default:desert_cobble"}, {["x"] = 5, ["y"] = 8, ["param1"] = 127, ["z"] = 8, ["name"] = "default:desert_cobble"}, {["x"] = 5, ["y"] = 8, ["param1"] = 95, ["z"] = 9, ["name"] = "default:desert_cobble"}, {["x"] = 5, ["y"] = 9, ["param1"] = 79, ["z"] = 0, ["name"] = "technic:marble"}, {["x"] = 5, ["y"] = 9, ["param1"] = 51, ["z"] = 1, ["name"] = "default:mese"}, {["x"] = 5, ["y"] = 9, ["param1"] = 79, ["z"] = 2, ["name"] = "default:sandstonebrick"}, {["x"] = 5, ["y"] = 9, ["param1"] = 76, ["z"] = 3, ["name"] = "default:mese"}, {["x"] = 5, ["y"] = 9, ["param1"] = 93, ["z"] = 4, ["name"] = "lapis:pyrite_block"}, {["x"] = 5, ["y"] = 9, ["param1"] = 93, ["z"] = 5, ["name"] = "lapis:pyrite_block"}, {["x"] = 5, ["y"] = 9, ["param1"] = 76, ["z"] = 6, ["name"] = "default:mese"}, {["x"] = 5, ["y"] = 9, ["param1"] = 79, ["z"] = 7, ["name"] = "default:sandstonebrick"}, {["x"] = 5, ["y"] = 9, ["param1"] = 51, ["z"] = 8, ["name"] = "default:mese"}, {["x"] = 5, ["y"] = 9, ["param1"] = 79, ["z"] = 9, ["name"] = "technic:marble"}, {["x"] = 5, ["meta"] = {["fields"] = {["infotext"] = "Itemwise Filter-Injector", ["owner"] = "n", ["formspec"] = "size[8,8.5]item_image[0,0;1,1;pipeworks:filter]label[1,0;Itemwise Filter-Injector]label[0,1;Prefer item types:]list[context;main;0,1.5;8,2;]button[0,3.5;4,1;fs_helpers_cycling:1:slotseq_mode;Sequence slots by Priority]list[current_player;main;0,4.5;8,4;]listring[]"}, ["inventory"] = {["main"] = {"", "", "", "", "", "", "", "", "", "", "", "", "", "", "", ""}}}, ["param2"] = 1, ["y"] = 10, ["param1"] = 63, ["z"] = 0, ["name"] = "pipeworks:filter"}, {["x"] = 5, ["y"] = 10, ["param1"] = 63, ["z"] = 1, ["name"] = "default:steelblock"}, {["x"] = 5, ["y"] = 10, ["param1"] = 63, ["z"] = 2, ["name"] = "default:steelblock"}, {["x"] = 5, ["y"] = 10, ["param1"] = 79, ["z"] = 3, ["name"] = "default:steelblock"}, {["x"] = 5, ["y"] = 10, ["param1"] = 79, ["z"] = 6, ["name"] = "default:steelblock"}, {["x"] = 5, ["y"] = 10, ["param1"] = 63, ["z"] = 7, ["name"] = "default:steelblock"}, {["x"] = 5, ["y"] = 10, ["param1"] = 63, ["z"] = 8, ["name"] = "default:steelblock"}, {["x"] = 5, ["y"] = 10, ["z"] = 9, ["name"] = "default:brick"}, {["x"] = 5, ["y"] = 11, ["param1"] = 47, ["z"] = 0, ["name"] = "spawners_mobs:deco_stone_men"}, {["x"] = 5, ["y"] = 11, ["param1"] = 47, ["z"] = 1, ["name"] = "technic:zinc_block"}, {["x"] = 5, ["y"] = 11, ["param1"] = 47, ["z"] = 2, ["name"] = "technic:zinc_block"}, {["x"] = 5, ["y"] = 11, ["param1"] = 63, ["z"] = 3, ["name"] = "spawners_mobs:deco_stone_men"}, {["x"] = 5, ["y"] = 11, ["param1"] = 63, ["z"] = 6, ["name"] = "spawners_mobs:deco_stone_men"}, {["x"] = 5, ["y"] = 11, ["param1"] = 47, ["z"] = 7, ["name"] = "technic:zinc_block"}, {["x"] = 5, ["y"] = 11, ["param1"] = 47, ["z"] = 8, ["name"] = "technic:zinc_block"}, {["x"] = 5, ["y"] = 11, ["param1"] = 63, ["z"] = 9, ["name"] = "spawners_mobs:deco_stone_men"}, {["x"] = 5, ["y"] = 12, ["param1"] = 31, ["z"] = 0, ["name"] = "technic:zinc_block"}, {["x"] = 5, ["y"] = 12, ["param1"] = 31, ["z"] = 1, ["name"] = "default:goldblock"}, {["x"] = 5, ["y"] = 12, ["param1"] = 31, ["z"] = 2, ["name"] = "default:goldblock"}, {["x"] = 5, ["y"] = 12, ["param1"] = 47, ["z"] = 3, ["name"] = "technic:zinc_block"}, {["x"] = 5, ["y"] = 12, ["param1"] = 47, ["z"] = 6, ["name"] = "technic:zinc_block"}, {["x"] = 5, ["y"] = 12, ["param1"] = 31, ["z"] = 7, ["name"] = "default:goldblock"}, {["x"] = 5, ["y"] = 12, ["param1"] = 31, ["z"] = 8, ["name"] = "default:goldblock"}, {["x"] = 5, ["y"] = 12, ["param1"] = 31, ["z"] = 9, ["name"] = "technic:zinc_block"}, {["x"] = 5, ["y"] = 13, ["param1"] = 31, ["z"] = 0, ["name"] = "default:tinblock"}, {["x"] = 5, ["y"] = 13, ["param1"] = 15, ["z"] = 1, ["name"] = "default:tinblock"}, {["x"] = 5, ["y"] = 13, ["param1"] = 15, ["z"] = 2, ["name"] = "default:tinblock"}, {["x"] = 5, ["y"] = 13, ["param1"] = 31, ["z"] = 3, ["name"] = "default:tinblock"}, {["x"] = 5, ["y"] = 13, ["param1"] = 31, ["z"] = 4, ["name"] = "default:tinblock"}, {["x"] = 5, ["y"] = 13, ["param1"] = 31, ["z"] = 5, ["name"] = "default:tinblock"}, {["x"] = 5, ["y"] = 13, ["param1"] = 31, ["z"] = 6, ["name"] = "default:tinblock"}, {["x"] = 5, ["y"] = 13, ["param1"] = 15, ["z"] = 7, ["name"] = "default:tinblock"}, {["x"] = 5, ["y"] = 13, ["param1"] = 15, ["z"] = 8, ["name"] = "default:tinblock"}, {["x"] = 5, ["y"] = 13, ["param1"] = 31, ["z"] = 9, ["name"] = "default:tinblock"}, {["x"] = 6, ["y"] = 0, ["param1"] = 143, ["z"] = 0, ["name"] = "moretrees:rubber_tree_planks"}, {["x"] = 6, ["y"] = 0, ["param1"] = 127, ["z"] = 1, ["name"] = "moretrees:rubber_tree_planks"}, {["x"] = 6, ["y"] = 0, ["param1"] = 111, ["z"] = 2, ["name"] = "moretrees:rubber_tree_planks"}, {["x"] = 6, ["y"] = 0, ["param1"] = 95, ["z"] = 3, ["name"] = "moretrees:rubber_tree_planks"}, {["x"] = 6, ["y"] = 0, ["param1"] = 79, ["z"] = 4, ["name"] = "moretrees:rubber_tree_planks"}, {["x"] = 6, ["y"] = 0, ["param1"] = 79, ["z"] = 5, ["name"] = "moretrees:rubber_tree_planks"}, {["x"] = 6, ["y"] = 0, ["param1"] = 95, ["z"] = 6, ["name"] = "moretrees:rubber_tree_planks"}, {["x"] = 6, ["y"] = 0, ["param1"] = 111, ["z"] = 7, ["name"] = "moretrees:rubber_tree_planks"}, {["x"] = 6, ["y"] = 0, ["param1"] = 127, ["z"] = 8, ["name"] = "moretrees:rubber_tree_planks"}, {["x"] = 6, ["y"] = 0, ["param1"] = 143, ["z"] = 9, ["name"] = "moretrees:rubber_tree_planks"}, {["x"] = 6, ["y"] = 1, ["param1"] = 190, ["z"] = 0, ["name"] = "caverealms:glow_ore"}, {["x"] = 6, ["meta"] = {["fields"] = {["tetris"] = "return {[\"x\"] = 4, [\"board\"] = {{{5, 4}}, {{4, 4}, {5, 4}}, {{4, 4}}, {{4, 3}}, {{4, 3}, {5, 3}}, {{4, 3}, {5, 3}}, {{4, 3}, {5, 3}}, {{5, 3}}, {{5, 5}, {6, 5}}, {{5, 5}}, {{5, 5}}, {{4, 1}, {5, 1}}, {{4, 1}, {5, 1}}, {{4, 3}}, {{4, 3}, {5, 3}}, {{5, 3}}, {{5, 5}, {6, 5}}, {{5, 5}}, {{5, 5}}}, [\"y\"] = 0, [\"rot\"] = 1, [\"boardstring\"] = \"image[1.45,0.29;0.31,0.31;computer_blue.png]image[1.16,0.58;0.31,0.31;computer_blue.png]image[1.45,0.58;0.31,0.31;computer_blue.png]image[1.16,0.87;0.31,0.31;computer_blue.png]image[1.16,1.16;0.31,0.31;computer_red.png]image[1.16,1.45;0.31,0.31;computer_red.png]image[1.45,1.45;0.31,0.31;computer_red.png]image[1.16,1.74;0.31,0.31;computer_red.png]image[1.45,1.74;0.31,0.31;computer_red.png]image[1.16,2.03;0.31,0.31;computer_red.png]image[1.45,2.03;0.31,0.31;computer_red.png]image[1.45,2.32;0.31,0.31;computer_red.png]image[1.45,2.61;0.31,0.31;computer_green.png]image[1.74,2.61;0.31,0.31;computer_green.png]image[1.45,2.9;0.31,0.31;computer_green.png]image[1.45,3.19;0.31,0.31;computer_green.png]image[1.16,3.48;0.31,0.31;computer_cyan.png]image[1.45,3.48;0.31,0.31;computer_cyan.png]image[1.16,3.77;0.31,0.31;computer_cyan.png]image[1.45,3.77;0.31,0.31;computer_cyan.png]image[1.16,4.06;0.31,0.31;computer_red.png]image[1.16,4.35;0.31,0.31;computer_red.png]image[1.45,4.35;0.31,0.31;computer_red.png]image[1.45,4.64;0.31,0.31;computer_red.png]image[1.45,4.93;0.31,0.31;computer_green.png]image[1.74,4.93;0.31,0.31;computer_green.png]image[1.45,5.22;0.31,0.31;computer_green.png]image[1.45,5.51;0.31,0.31;computer_green.png]\", [\"previewstring\"] = \"image[4.39,0.6;0.31,0.31;computer_yellow.png]image[4.1,0.89;0.31,0.31;computer_yellow.png]image[4.39,0.89;0.31,0.31;computer_yellow.png]image[4.68,0.89;0.31,0.31;computer_yellow.png]\", [\"cur\"] = 4, [\"nex\"] = 7, [\"score\"] = 0}", ["formspec"] = "size[5.9,5.7]image[0,0;3.55,6.66;computer_black.png]image[1.45,0.29;0.31,0.31;computer_blue.png]image[1.16,0.58;0.31,0.31;computer_blue.png]image[1.45,0.58;0.31,0.31;computer_blue.png]image[1.16,0.87;0.31,0.31;computer_blue.png]image[1.16,1.16;0.31,0.31;computer_red.png]image[1.16,1.45;0.31,0.31;computer_red.png]image[1.45,1.45;0.31,0.31;computer_red.png]image[1.16,1.74;0.31,0.31;computer_red.png]image[1.45,1.74;0.31,0.31;computer_red.png]image[1.16,2.03;0.31,0.31;computer_red.png]image[1.45,2.03;0.31,0.31;computer_red.png]image[1.45,2.32;0.31,0.31;computer_red.png]image[1.45,2.61;0.31,0.31;computer_green.png]image[1.74,2.61;0.31,0.31;computer_green.png]image[1.45,2.9;0.31,0.31;computer_green.png]image[1.45,3.19;0.31,0.31;computer_green.png]image[1.16,3.48;0.31,0.31;computer_cyan.png]image[1.45,3.48;0.31,0.31;computer_cyan.png]image[1.16,3.77;0.31,0.31;computer_cyan.png]image[1.45,3.77;0.31,0.31;computer_cyan.png]image[1.16,4.06;0.31,0.31;computer_red.png]image[1.16,4.35;0.31,0.31;computer_red.png]image[1.45,4.35;0.31,0.31;computer_red.png]image[1.45,4.64;0.31,0.31;computer_red.png]image[1.45,4.93;0.31,0.31;computer_green.png]image[1.74,4.93;0.31,0.31;computer_green.png]image[1.45,5.22;0.31,0.31;computer_green.png]image[1.45,5.51;0.31,0.31;computer_green.png]image[4.39,0.6;0.31,0.31;computer_yellow.png]image[4.1,0.89;0.31,0.31;computer_yellow.png]image[4.39,0.89;0.31,0.31;computer_yellow.png]image[4.68,0.89;0.31,0.31;computer_yellow.png]image[1.45,0;0.31,0.31;computer_blue.png]image[1.16,0.29;0.31,0.31;computer_blue.png]image[1.45,0.29;0.31,0.31;computer_blue.png]image[1.16,0.58;0.31,0.31;computer_blue.png]label[3.8,0.1;Next...]label[3.8,2.7;Score: 0]button[3,4.5;0.6,0.6;left;<]button[3.6,4.5;0.6,0.6;rotateleft;L]button[4.2,4.5;0.6,0.6;down;v]button[4.2,5.3;0.6,0.6;drop;V]button[4.8,4.5;0.6,0.6;rotateright;R]button[5.4,4.5;0.6,0.6;right;>]button[3.5,3;2,2;new;New Game]bgcolor[#080808BB;true]background[5,5;1,1;gui_formbg.png;true]listcolors[#00000069;#5A5A5A;#141318;#30434C;#FFF]"}, ["inventory"] = {}}, ["param2"] = 3, ["y"] = 1, ["param1"] = 173, ["z"] = 1, ["name"] = "computer:tetris_arcade"}, {["x"] = 6, ["meta"] = {["fields"] = {["formspec"] = "size[8,8.5]bgcolor[#080808BB;true]background[5,5;1,1;gui_formbg.png;true]listcolors[#00000069;#5A5A5A;#141318;#30434C;#FFF]list[current_name;src;2.75,0.5;1,1;]list[current_name;fuel;2.75,2.5;1,1;]image[2.75,1.5;1,1;default_furnace_fire_bg.png]image[3.75,1.5;1,1;gui_furnace_arrow_bg.png^[transformR270]list[current_name;dst;4.75,0.96;2,2;]list[current_player;main;0,4.25;8,1;]list[current_player;main;0,5.5;8,3;8]listring[current_name;dst]listring[current_player;main]listring[current_name;src]listring[current_player;main]listring[current_name;fuel]listring[current_player;main]image[0,4.25;1,1;gui_hb_bg.png]image[1,4.25;1,1;gui_hb_bg.png]image[2,4.25;1,1;gui_hb_bg.png]image[3,4.25;1,1;gui_hb_bg.png]image[4,4.25;1,1;gui_hb_bg.png]image[5,4.25;1,1;gui_hb_bg.png]image[6,4.25;1,1;gui_hb_bg.png]image[7,4.25;1,1;gui_hb_bg.png]"}, ["inventory"] = {["fuel"] = {""}, ["dst"] = {"", "", "", ""}, ["src"] = {""}}}, ["param2"] = 3, ["y"] = 1, ["z"] = 2, ["name"] = "default:furnace"}, {["x"] = 6, ["meta"] = {["fields"] = {["infotext"] = "Wooden Chest"}, ["inventory"] = {["main"] = {"", "", "", "", "", "", "", "", "", "", "", "", "", "", "", "", "", "", "", "", "", "", "", "", "", "", "", "", "", "", "", ""}}}, ["param2"] = 3, ["y"] = 1, ["param1"] = 170, ["z"] = 3, ["name"] = "default:chest"}, {["x"] = 6, ["param2"] = 3, ["y"] = 1, ["param1"] = 153, ["z"] = 4, ["name"] = "homedecor:wood_table_small_round"}, {["x"] = 6, ["param2"] = 3, ["y"] = 1, ["param1"] = 153, ["z"] = 5, ["name"] = "homedecor:wood_table_small_round"}, {["x"] = 6, ["meta"] = {["fields"] = {["infotext"] = "Wooden Chest"}, ["inventory"] = {["main"] = {"", "", "", "", "", "", "", "", "", "", "", "", "", "", "", "", "", "", "", "", "", "", "", "", "", "", "", "", "", "", "", ""}}}, ["param2"] = 3, ["y"] = 1, ["param1"] = 136, ["z"] = 6, ["name"] = "default:chest"}, {["x"] = 6, ["meta"] = {["fields"] = {["infotext"] = "Wooden Chest"}, ["inventory"] = {["main"] = {"", "", "", "", "", "", "", "", "", "", "", "", "", "", "", "", "", "", "", "", "", "", "", "", "", "", "", "", "", "", "", ""}}}, ["param2"] = 3, ["y"] = 1, ["param1"] = 119, ["z"] = 7, ["name"] = "default:chest"}, {["x"] = 6, ["param2"] = 3, ["y"] = 1, ["param1"] = 173, ["z"] = 8, ["name"] = "homedecor:soda_machine"}, {["x"] = 6, ["y"] = 1, ["param1"] = 190, ["z"] = 9, ["name"] = "caverealms:glow_ore"}, {["x"] = 6, ["y"] = 2, ["param1"] = 206, ["z"] = 0, ["name"] = "lapis:lapis_tile"}, {["x"] = 6, ["param2"] = 3, ["y"] = 2, ["param1"] = 172, ["z"] = 2, ["name"] = "computer:vanio"}, {["x"] = 6, ["param2"] = 3, ["y"] = 2, ["param1"] = 187, ["z"] = 3, ["name"] = "computer:slaystation2_off"}, {["x"] = 6, ["param2"] = 1, ["y"] = 2, ["param1"] = 187, ["z"] = 6, ["name"] = "homedecor:plasma_ball_on"}, {["x"] = 6, ["param2"] = 3, ["y"] = 2, ["param1"] = 172, ["z"] = 7, ["name"] = "homedecor:drink_tap"}, {["x"] = 6, ["y"] = 2, ["param1"] = 206, ["z"] = 9, ["name"] = "lapis:lapis_tile"}, {["x"] = 6, ["y"] = 3, ["param1"] = 222, ["z"] = 0, ["name"] = "caverealms:glow_crystal"}, {["x"] = 6, ["y"] = 3, ["param1"] = 205, ["z"] = 1, ["name"] = "caverealms:glow_worm"}, {["x"] = 6, ["y"] = 3, ["param1"] = 188, ["z"] = 2, ["name"] = "caverealms:glow_worm"}, {["x"] = 6, ["y"] = 3, ["param1"] = 204, ["z"] = 3, ["name"] = "caverealms:glow_worm"}, {["x"] = 6, ["y"] = 3, ["param1"] = 204, ["z"] = 4, ["name"] = "caverealms:glow_worm"}, {["x"] = 6, ["y"] = 3, ["param1"] = 204, ["z"] = 5, ["name"] = "caverealms:glow_worm"}, {["x"] = 6, ["y"] = 3, ["param1"] = 204, ["z"] = 6, ["name"] = "caverealms:glow_worm"}, {["x"] = 6, ["y"] = 3, ["param1"] = 188, ["z"] = 7, ["name"] = "caverealms:glow_worm"}, {["x"] = 6, ["y"] = 3, ["param1"] = 222, ["z"] = 9, ["name"] = "caverealms:glow_crystal"}, {["x"] = 6, ["y"] = 4, ["param1"] = 191, ["z"] = 1, ["name"] = "birthstones:alexandriteblock"}, {["x"] = 6, ["y"] = 4, ["param1"] = 175, ["z"] = 2, ["name"] = "technic:chromium_block"}, {["x"] = 6, ["y"] = 4, ["param1"] = 159, ["z"] = 3, ["name"] = "birthstones:alexandriteblock"}, {["x"] = 6, ["y"] = 4, ["param1"] = 143, ["z"] = 4, ["name"] = "technic:chromium_block"}, {["x"] = 6, ["y"] = 4, ["param1"] = 143, ["z"] = 5, ["name"] = "technic:chromium_block"}, {["x"] = 6, ["y"] = 4, ["param1"] = 159, ["z"] = 6, ["name"] = "birthstones:alexandriteblock"}, {["x"] = 6, ["y"] = 4, ["param1"] = 175, ["z"] = 7, ["name"] = "technic:chromium_block"}, {["x"] = 6, ["y"] = 4, ["param1"] = 191, ["z"] = 8, ["name"] = "birthstones:alexandriteblock"}, {["x"] = 6, ["y"] = 5, ["param1"] = 191, ["z"] = 0, ["name"] = "default:desert_cobble"}, {["x"] = 6, ["y"] = 5, ["param1"] = 187, ["z"] = 1, ["name"] = "caverealms:glow_gem_2"}, {["x"] = 6, ["param2"] = 3, ["y"] = 5, ["param1"] = 136, ["z"] = 4, ["name"] = "homedecor:toilet_open"}, {["x"] = 6, ["param2"] = 3, ["y"] = 5, ["param1"] = 136, ["z"] = 5, ["name"] = "homedecor:toilet_paper"}, {["x"] = 6, ["y"] = 5, ["param1"] = 187, ["z"] = 8, ["name"] = "caverealms:glow_gem_2"}, {["x"] = 6, ["y"] = 5, ["param1"] = 191, ["z"] = 9, ["name"] = "default:desert_cobble"}, {["x"] = 6, ["y"] = 6, ["param1"] = 159, ["z"] = 0, ["name"] = "default:diamondblock"}, {["x"] = 6, ["y"] = 6, ["param1"] = 159, ["z"] = 9, ["name"] = "default:diamondblock"}, {["x"] = 6, ["y"] = 7, ["param1"] = 142, ["z"] = 0, ["name"] = "default:mese"}, {["x"] = 6, ["y"] = 7, ["param1"] = 142, ["z"] = 9, ["name"] = "default:mese"}, {["x"] = 6, ["y"] = 8, ["param1"] = 127, ["z"] = 0, ["name"] = "default:desert_cobble"}, {["x"] = 6, ["y"] = 8, ["param1"] = 127, ["z"] = 9, ["name"] = "default:desert_cobble"}, {["x"] = 6, ["y"] = 9, ["param1"] = 111, ["z"] = 0, ["name"] = "default:brick"}, {["x"] = 6, ["y"] = 9, ["param1"] = 127, ["z"] = 1, ["name"] = "default:brick"}, {["x"] = 6, ["y"] = 9, ["param1"] = 111, ["z"] = 2, ["name"] = "default:brick"}, {["x"] = 6, ["y"] = 9, ["param1"] = 95, ["z"] = 3, ["name"] = "default:brick"}, {["x"] = 6, ["y"] = 9, ["param1"] = 79, ["z"] = 4, ["name"] = "default:brick"}, {["x"] = 6, ["y"] = 9, ["param1"] = 79, ["z"] = 5, ["name"] = "default:brick"}, {["x"] = 6, ["y"] = 9, ["param1"] = 95, ["z"] = 6, ["name"] = "default:brick"}, {["x"] = 6, ["y"] = 9, ["param1"] = 111, ["z"] = 7, ["name"] = "default:brick"}, {["x"] = 6, ["y"] = 9, ["param1"] = 127, ["z"] = 8, ["name"] = "default:brick"}, {["x"] = 6, ["y"] = 9, ["param1"] = 95, ["z"] = 9, ["name"] = "default:brick"}, {["x"] = 6, ["y"] = 10, ["param1"] = 79, ["z"] = 0, ["name"] = "default:brick"}, {["x"] = 6, ["y"] = 10, ["param1"] = 79, ["z"] = 9, ["name"] = "default:brick"}, {["x"] = 6, ["y"] = 11, ["param1"] = 63, ["z"] = 0, ["name"] = "technic:zinc_block"}, {["x"] = 6, ["y"] = 11, ["param1"] = 63, ["z"] = 9, ["name"] = "technic:zinc_block"}, {["x"] = 6, ["param2"] = 1, ["y"] = 12, ["param1"] = 47, ["z"] = 0, ["name"] = "bones:bones"}, {["x"] = 6, ["param2"] = 1, ["y"] = 12, ["param1"] = 47, ["z"] = 9, ["name"] = "bones:bones"}, {["x"] = 6, ["param2"] = 1, ["y"] = 13, ["param1"] = 47, ["z"] = 0, ["name"] = "bones:bones"}, {["x"] = 6, ["param2"] = 1, ["y"] = 13, ["param1"] = 47, ["z"] = 9, ["name"] = "bones:bones"}, {["x"] = 7, ["y"] = 0, ["param1"] = 159, ["z"] = 0, ["name"] = "moretrees:rubber_tree_planks"}, {["x"] = 7, ["y"] = 0, ["param1"] = 143, ["z"] = 1, ["name"] = "moretrees:rubber_tree_planks"}, {["x"] = 7, ["y"] = 0, ["param1"] = 127, ["z"] = 2, ["name"] = "moretrees:rubber_tree_planks"}, {["x"] = 7, ["y"] = 0, ["param1"] = 111, ["z"] = 3, ["name"] = "moretrees:rubber_tree_planks"}, {["x"] = 7, ["y"] = 0, ["param1"] = 95, ["z"] = 4, ["name"] = "moretrees:rubber_tree_planks"}, {["x"] = 7, ["y"] = 0, ["param1"] = 95, ["z"] = 5, ["name"] = "moretrees:rubber_tree_planks"}, {["x"] = 7, ["y"] = 0, ["param1"] = 111, ["z"] = 6, ["name"] = "moretrees:rubber_tree_planks"}, {["x"] = 7, ["y"] = 0, ["param1"] = 127, ["z"] = 7, ["name"] = "moretrees:rubber_tree_planks"}, {["x"] = 7, ["y"] = 0, ["param1"] = 143, ["z"] = 8, ["name"] = "moretrees:rubber_tree_planks"}, {["x"] = 7, ["y"] = 0, ["param1"] = 159, ["z"] = 9, ["name"] = "moretrees:rubber_tree_planks"}, {["x"] = 7, ["y"] = 1, ["param1"] = 174, ["z"] = 0, ["name"] = "caverealms:glow_ore"}, {["x"] = 7, ["y"] = 1, ["param1"] = 174, ["z"] = 9, ["name"] = "caverealms:glow_ore"}, {["x"] = 7, ["y"] = 2, ["param1"] = 190, ["z"] = 0, ["name"] = "lapis:lapis_tile"}, {["x"] = 7, ["y"] = 2, ["param1"] = 190, ["z"] = 9, ["name"] = "lapis:lapis_tile"}, {["x"] = 7, ["y"] = 3, ["param1"] = 206, ["z"] = 0, ["name"] = "lapis:lapis_tile"}, {["x"] = 7, ["y"] = 3, ["param1"] = 189, ["z"] = 1, ["name"] = "caverealms:glow_worm"}, {["x"] = 7, ["y"] = 3, ["param1"] = 189, ["z"] = 8, ["name"] = "caverealms:glow_worm"}, {["x"] = 7, ["y"] = 3, ["param1"] = 206, ["z"] = 9, ["name"] = "lapis:lapis_tile"}, {["x"] = 7, ["y"] = 4, ["param1"] = 190, ["z"] = 0, ["name"] = "caverealms:glow_ore"}, {["x"] = 7, ["y"] = 4, ["param1"] = 175, ["z"] = 1, ["name"] = "technic:chromium_block"}, {["x"] = 7, ["y"] = 4, ["param1"] = 159, ["z"] = 2, ["name"] = "technic:marble"}, {["x"] = 7, ["y"] = 4, ["param1"] = 143, ["z"] = 3, ["name"] = "technic:marble"}, {["x"] = 7, ["y"] = 4, ["param1"] = 127, ["z"] = 4, ["name"] = "technic:marble"}, {["x"] = 7, ["y"] = 4, ["param1"] = 127, ["z"] = 5, ["name"] = "technic:marble"}, {["x"] = 7, ["y"] = 4, ["param1"] = 143, ["z"] = 6, ["name"] = "technic:marble"}, {["x"] = 7, ["y"] = 4, ["param1"] = 159, ["z"] = 7, ["name"] = "technic:marble"}, {["x"] = 7, ["y"] = 4, ["param1"] = 175, ["z"] = 8, ["name"] = "technic:chromium_block"}, {["x"] = 7, ["y"] = 4, ["param1"] = 190, ["z"] = 9, ["name"] = "caverealms:glow_ore"}, {["x"] = 7, ["y"] = 5, ["param1"] = 175, ["z"] = 0, ["name"] = "default:diamondblock"}, {["x"] = 7, ["y"] = 5, ["param1"] = 175, ["z"] = 9, ["name"] = "default:diamondblock"}, {["x"] = 7, ["y"] = 6, ["param1"] = 142, ["z"] = 0, ["name"] = "default:mese"}, {["x"] = 7, ["y"] = 6, ["param1"] = 142, ["z"] = 9, ["name"] = "default:mese"}, {["x"] = 7, ["y"] = 7, ["param1"] = 126, ["z"] = 0, ["name"] = "default:mese"}, {["x"] = 7, ["y"] = 7, ["param1"] = 126, ["z"] = 9, ["name"] = "default:mese"}, {["x"] = 7, ["y"] = 8, ["param1"] = 95, ["z"] = 0, ["name"] = "default:desert_cobble"}, {["x"] = 7, ["y"] = 8, ["param1"] = 95, ["z"] = 9, ["name"] = "default:desert_cobble"}, {["x"] = 7, ["y"] = 9, ["param1"] = 111, ["z"] = 0, ["name"] = "default:brick"}, {["x"] = 7, ["y"] = 9, ["param1"] = 95, ["z"] = 1, ["name"] = "default:brick"}, {["x"] = 7, ["y"] = 9, ["param1"] = 79, ["z"] = 2, ["name"] = "default:brick"}, {["x"] = 7, ["y"] = 9, ["param1"] = 63, ["z"] = 3, ["name"] = "default:brick"}, {["x"] = 7, ["y"] = 9, ["param1"] = 47, ["z"] = 4, ["name"] = "default:brick"}, {["x"] = 7, ["y"] = 9, ["param1"] = 47, ["z"] = 5, ["name"] = "default:brick"}, {["x"] = 7, ["y"] = 9, ["param1"] = 63, ["z"] = 6, ["name"] = "default:brick"}, {["x"] = 7, ["y"] = 9, ["param1"] = 79, ["z"] = 7, ["name"] = "default:brick"}, {["x"] = 7, ["y"] = 9, ["param1"] = 95, ["z"] = 8, ["name"] = "default:brick"}, {["x"] = 7, ["y"] = 9, ["param1"] = 111, ["z"] = 9, ["name"] = "default:brick"}, {["x"] = 7, ["y"] = 10, ["param1"] = 95, ["z"] = 0, ["name"] = "default:brick"}, {["x"] = 7, ["y"] = 10, ["param1"] = 95, ["z"] = 9, ["name"] = "default:brick"}, {["x"] = 7, ["param2"] = 1, ["y"] = 11, ["param1"] = 79, ["z"] = 0, ["name"] = "bones:bones"}, {["x"] = 7, ["param2"] = 1, ["y"] = 11, ["param1"] = 79, ["z"] = 9, ["name"] = "bones:bones"}, {["x"] = 7, ["param2"] = 1, ["y"] = 12, ["param1"] = 63, ["z"] = 0, ["name"] = "bones:bones"}, {["x"] = 7, ["param2"] = 1, ["y"] = 12, ["param1"] = 63, ["z"] = 9, ["name"] = "bones:bones"}, {["x"] = 7, ["param2"] = 1, ["y"] = 13, ["param1"] = 63, ["z"] = 0, ["name"] = "bones:bones"}, {["x"] = 7, ["param2"] = 1, ["y"] = 13, ["param1"] = 63, ["z"] = 9, ["name"] = "bones:bones"}, {["x"] = 8, ["y"] = 0, ["param1"] = 143, ["z"] = 0, ["name"] = "moretrees:rubber_tree_planks"}, {["x"] = 8, ["y"] = 0, ["param1"] = 127, ["z"] = 1, ["name"] = "moretrees:rubber_tree_planks"}, {["x"] = 8, ["y"] = 0, ["param1"] = 111, ["z"] = 2, ["name"] = "moretrees:rubber_tree_planks"}, {["x"] = 8, ["y"] = 0, ["param1"] = 95, ["z"] = 3, ["name"] = "moretrees:rubber_tree_planks"}, {["x"] = 8, ["y"] = 0, ["param1"] = 79, ["z"] = 4, ["name"] = "moretrees:rubber_tree_planks"}, {["x"] = 8, ["y"] = 0, ["param1"] = 79, ["z"] = 5, ["name"] = "moretrees:rubber_tree_planks"}, {["x"] = 8, ["y"] = 0, ["param1"] = 95, ["z"] = 6, ["name"] = "moretrees:rubber_tree_planks"}, {["x"] = 8, ["y"] = 0, ["param1"] = 111, ["z"] = 7, ["name"] = "moretrees:rubber_tree_planks"}, {["x"] = 8, ["y"] = 0, ["param1"] = 127, ["z"] = 8, ["name"] = "moretrees:rubber_tree_planks"}, {["x"] = 8, ["y"] = 0, ["param1"] = 143, ["z"] = 9, ["name"] = "moretrees:rubber_tree_planks"}, {["x"] = 8, ["y"] = 1, ["param1"] = 190, ["z"] = 0, ["name"] = "caverealms:glow_ore"}, {["x"] = 8, ["y"] = 1, ["param1"] = 190, ["z"] = 9, ["name"] = "caverealms:glow_ore"}, {["x"] = 8, ["y"] = 2, ["param1"] = 206, ["z"] = 0, ["name"] = "lapis:lapis_tile"}, {["x"] = 8, ["y"] = 2, ["param1"] = 206, ["z"] = 9, ["name"] = "lapis:lapis_tile"}, {["x"] = 8, ["y"] = 3, ["param1"] = 222, ["z"] = 0, ["name"] = "caverealms:glow_crystal"}, {["x"] = 8, ["y"] = 3, ["param1"] = 205, ["z"] = 1, ["name"] = "caverealms:glow_worm"}, {["x"] = 8, ["y"] = 3, ["param1"] = 205, ["z"] = 8, ["name"] = "caverealms:glow_worm"}, {["x"] = 8, ["y"] = 3, ["param1"] = 222, ["z"] = 9, ["name"] = "caverealms:glow_crystal"}, {["x"] = 8, ["y"] = 4, ["param1"] = 191, ["z"] = 1, ["name"] = "birthstones:alexandriteblock"}, {["x"] = 8, ["y"] = 4, ["param1"] = 175, ["z"] = 2, ["name"] = "technic:marble"}, {["x"] = 8, ["y"] = 4, ["param1"] = 159, ["z"] = 3, ["name"] = "technic:marble"}, {["x"] = 8, ["y"] = 4, ["param1"] = 143, ["z"] = 4, ["name"] = "technic:marble"}, {["x"] = 8, ["y"] = 4, ["param1"] = 143, ["z"] = 5, ["name"] = "technic:marble"}, {["x"] = 8, ["y"] = 4, ["param1"] = 159, ["z"] = 6, ["name"] = "technic:marble"}, {["x"] = 8, ["y"] = 4, ["param1"] = 175, ["z"] = 7, ["name"] = "technic:marble"}, {["x"] = 8, ["y"] = 4, ["param1"] = 191, ["z"] = 8, ["name"] = "birthstones:alexandriteblock"}, {["x"] = 8, ["y"] = 5, ["param1"] = 191, ["z"] = 0, ["name"] = "default:diamondblock"}, {["x"] = 8, ["y"] = 5, ["param1"] = 191, ["z"] = 9, ["name"] = "default:diamondblock"}, {["x"] = 8, ["y"] = 6, ["param1"] = 142, ["z"] = 0, ["name"] = "default:mese"}, {["x"] = 8, ["y"] = 6, ["param1"] = 142, ["z"] = 9, ["name"] = "default:mese"}, {["x"] = 8, ["y"] = 7, ["param1"] = 126, ["z"] = 0, ["name"] = "default:mese"}, {["x"] = 8, ["y"] = 7, ["param1"] = 126, ["z"] = 9, ["name"] = "default:mese"}, {["x"] = 8, ["y"] = 8, ["param1"] = 111, ["z"] = 0, ["name"] = "technic:marble"}, {["x"] = 8, ["y"] = 8, ["param1"] = 111, ["z"] = 9, ["name"] = "technic:marble"}, {["x"] = 8, ["y"] = 9, ["param1"] = 127, ["z"] = 0, ["name"] = "default:brick"}, {["x"] = 8, ["y"] = 9, ["param1"] = 111, ["z"] = 1, ["name"] = "default:brick"}, {["x"] = 8, ["y"] = 9, ["param1"] = 95, ["z"] = 2, ["name"] = "default:brick"}, {["x"] = 8, ["y"] = 9, ["param1"] = 79, ["z"] = 3, ["name"] = "default:brick"}, {["x"] = 8, ["y"] = 9, ["param1"] = 63, ["z"] = 4, ["name"] = "default:brick"}, {["x"] = 8, ["y"] = 9, ["param1"] = 63, ["z"] = 5, ["name"] = "default:brick"}, {["x"] = 8, ["y"] = 9, ["param1"] = 79, ["z"] = 6, ["name"] = "default:brick"}, {["x"] = 8, ["y"] = 9, ["param1"] = 95, ["z"] = 7, ["name"] = "default:brick"}, {["x"] = 8, ["y"] = 9, ["param1"] = 111, ["z"] = 8, ["name"] = "default:brick"}, {["x"] = 8, ["y"] = 9, ["param1"] = 127, ["z"] = 9, ["name"] = "default:brick"}, {["x"] = 8, ["y"] = 10, ["param1"] = 111, ["z"] = 0, ["name"] = "default:brick"}, {["x"] = 8, ["y"] = 10, ["param1"] = 111, ["z"] = 9, ["name"] = "default:brick"}, {["x"] = 8, ["param2"] = 1, ["y"] = 11, ["param1"] = 95, ["z"] = 0, ["name"] = "bones:bones"}, {["x"] = 8, ["param2"] = 1, ["y"] = 11, ["param1"] = 95, ["z"] = 9, ["name"] = "bones:bones"}, {["x"] = 8, ["param2"] = 1, ["y"] = 12, ["param1"] = 79, ["z"] = 0, ["name"] = "bones:bones"}, {["x"] = 8, ["param2"] = 1, ["y"] = 12, ["param1"] = 79, ["z"] = 9, ["name"] = "bones:bones"}, {["x"] = 8, ["param2"] = 1, ["y"] = 13, ["param1"] = 79, ["z"] = 0, ["name"] = "bones:bones"}, {["x"] = 8, ["param2"] = 1, ["y"] = 13, ["param1"] = 79, ["z"] = 9, ["name"] = "bones:bones"}, {["x"] = 9, ["y"] = 0, ["param1"] = 159, ["z"] = 0, ["name"] = "moretrees:rubber_tree_planks"}, {["x"] = 9, ["y"] = 0, ["param1"] = 143, ["z"] = 1, ["name"] = "moretrees:rubber_tree_planks"}, {["x"] = 9, ["y"] = 0, ["param1"] = 127, ["z"] = 2, ["name"] = "moretrees:rubber_tree_planks"}, {["x"] = 9, ["y"] = 0, ["param1"] = 111, ["z"] = 3, ["name"] = "moretrees:rubber_tree_planks"}, {["x"] = 9, ["y"] = 0, ["param1"] = 95, ["z"] = 4, ["name"] = "moretrees:rubber_tree_planks"}, {["x"] = 9, ["y"] = 0, ["param1"] = 95, ["z"] = 5, ["name"] = "moretrees:rubber_tree_planks"}, {["x"] = 9, ["y"] = 0, ["param1"] = 111, ["z"] = 6, ["name"] = "moretrees:rubber_tree_planks"}, {["x"] = 9, ["y"] = 0, ["param1"] = 127, ["z"] = 7, ["name"] = "moretrees:rubber_tree_planks"}, {["x"] = 9, ["y"] = 0, ["param1"] = 143, ["z"] = 8, ["name"] = "moretrees:rubber_tree_planks"}, {["x"] = 9, ["y"] = 0, ["param1"] = 159, ["z"] = 9, ["name"] = "moretrees:rubber_tree_planks"}, {["x"] = 9, ["y"] = 1, ["param1"] = 174, ["z"] = 0, ["name"] = "caverealms:glow_ore"}, {["x"] = 9, ["y"] = 1, ["param1"] = 174, ["z"] = 9, ["name"] = "caverealms:glow_ore"}, {["x"] = 9, ["y"] = 2, ["param1"] = 190, ["z"] = 0, ["name"] = "lapis:lapis_tile"}, {["x"] = 9, ["y"] = 2, ["param1"] = 190, ["z"] = 9, ["name"] = "lapis:lapis_tile"}, {["x"] = 9, ["y"] = 3, ["param1"] = 206, ["z"] = 0, ["name"] = "lapis:lapis_tile"}, {["x"] = 9, ["y"] = 3, ["param1"] = 189, ["z"] = 1, ["name"] = "caverealms:glow_worm"}, {["x"] = 9, ["y"] = 3, ["param1"] = 189, ["z"] = 8, ["name"] = "caverealms:glow_worm"}, {["x"] = 9, ["y"] = 3, ["param1"] = 206, ["z"] = 9, ["name"] = "lapis:lapis_tile"}, {["x"] = 9, ["y"] = 4, ["param1"] = 190, ["z"] = 0, ["name"] = "caverealms:glow_ore"}, {["x"] = 9, ["y"] = 4, ["param1"] = 175, ["z"] = 1, ["name"] = "technic:chromium_block"}, {["x"] = 9, ["y"] = 4, ["param1"] = 159, ["z"] = 2, ["name"] = "technic:marble"}, {["x"] = 9, ["y"] = 4, ["param1"] = 143, ["z"] = 3, ["name"] = "technic:marble"}, {["x"] = 9, ["y"] = 4, ["param1"] = 127, ["z"] = 4, ["name"] = "technic:marble"}, {["x"] = 9, ["y"] = 4, ["param1"] = 127, ["z"] = 5, ["name"] = "technic:marble"}, {["x"] = 9, ["y"] = 4, ["param1"] = 143, ["z"] = 6, ["name"] = "technic:marble"}, {["x"] = 9, ["y"] = 4, ["param1"] = 159, ["z"] = 7, ["name"] = "technic:marble"}, {["x"] = 9, ["y"] = 4, ["param1"] = 175, ["z"] = 8, ["name"] = "technic:chromium_block"}, {["x"] = 9, ["y"] = 4, ["param1"] = 190, ["z"] = 9, ["name"] = "caverealms:glow_ore"}, {["x"] = 9, ["y"] = 5, ["param1"] = 175, ["z"] = 0, ["name"] = "default:diamondblock"}, {["x"] = 9, ["y"] = 5, ["param1"] = 175, ["z"] = 9, ["name"] = "default:diamondblock"}, {["x"] = 9, ["y"] = 6, ["param1"] = 126, ["z"] = 0, ["name"] = "default:mese"}, {["x"] = 9, ["y"] = 6, ["param1"] = 126, ["z"] = 9, ["name"] = "default:mese"}, {["x"] = 9, ["y"] = 7, ["param1"] = 110, ["z"] = 0, ["name"] = "default:mese"}, {["x"] = 9, ["y"] = 7, ["param1"] = 110, ["z"] = 9, ["name"] = "default:mese"}, {["x"] = 9, ["meta"] = {["fields"] = {["infotext"] = "Itemwise Filter-Injector", ["owner"] = "n", ["formspec"] = "size[8,8.5]item_image[0,0;1,1;pipeworks:filter]label[1,0;Itemwise Filter-Injector]label[0,1;Prefer item types:]list[context;main;0,1.5;8,2;]button[0,3.5;4,1;fs_helpers_cycling:1:slotseq_mode;Sequence slots by Priority]list[current_player;main;0,4.5;8,4;]listring[]"}, ["inventory"] = {["main"] = {"", "", "", "", "", "", "", "", "", "", "", "", "", "", "", ""}}}, ["param2"] = 3, ["y"] = 8, ["param1"] = 159, ["z"] = 0, ["name"] = "pipeworks:filter"}, {["x"] = 9, ["meta"] = {["fields"] = {["infotext"] = "Itemwise Filter-Injector", ["owner"] = "n", ["formspec"] = "size[8,8.5]item_image[0,0;1,1;pipeworks:filter]label[1,0;Itemwise Filter-Injector]label[0,1;Prefer item types:]list[context;main;0,1.5;8,2;]button[0,3.5;4,1;fs_helpers_cycling:1:slotseq_mode;Sequence slots by Priority]list[current_player;main;0,4.5;8,4;]listring[]"}, ["inventory"] = {["main"] = {"", "", "", "", "", "", "", "", "", "", "", "", "", "", "", ""}}}, ["param2"] = 1, ["y"] = 8, ["param1"] = 159, ["z"] = 9, ["name"] = "pipeworks:filter"}, {["x"] = 9, ["y"] = 9, ["param1"] = 175, ["z"] = 0, ["name"] = "default:brick"}, {["x"] = 9, ["y"] = 9, ["param1"] = 127, ["z"] = 1, ["name"] = "default:brick"}, {["x"] = 9, ["y"] = 9, ["param1"] = 111, ["z"] = 2, ["name"] = "default:brick"}, {["x"] = 9, ["y"] = 9, ["param1"] = 95, ["z"] = 3, ["name"] = "default:brick"}, {["x"] = 9, ["y"] = 9, ["param1"] = 95, ["z"] = 4, ["name"] = "default:brick"}, {["x"] = 9, ["y"] = 9, ["param1"] = 111, ["z"] = 5, ["name"] = "default:brick"}, {["x"] = 9, ["y"] = 9, ["param1"] = 127, ["z"] = 6, ["name"] = "default:brick"}, {["x"] = 9, ["y"] = 9, ["param1"] = 143, ["z"] = 7, ["name"] = "default:brick"}, {["x"] = 9, ["y"] = 9, ["param1"] = 159, ["z"] = 8, ["name"] = "default:brick"}, {["x"] = 9, ["y"] = 9, ["param1"] = 175, ["z"] = 9, ["name"] = "default:brick"}, {["x"] = 9, ["y"] = 10, ["param1"] = 127, ["z"] = 0, ["name"] = "default:brick"}, {["x"] = 9, ["y"] = 10, ["param1"] = 127, ["z"] = 9, ["name"] = "default:brick"}, {["x"] = 9, ["param2"] = 1, ["y"] = 11, ["param1"] = 111, ["z"] = 0, ["name"] = "bones:bones"}, {["x"] = 9, ["param2"] = 1, ["y"] = 11, ["param1"] = 111, ["z"] = 9, ["name"] = "bones:bones"}, {["x"] = 9, ["param2"] = 1, ["y"] = 12, ["param1"] = 95, ["z"] = 0, ["name"] = "bones:bones"}, {["x"] = 9, ["param2"] = 1, ["y"] = 12, ["param1"] = 95, ["z"] = 9, ["name"] = "bones:bones"}, {["x"] = 9, ["param2"] = 1, ["y"] = 13, ["param1"] = 95, ["z"] = 0, ["name"] = "bones:bones"}, {["x"] = 9, ["param2"] = 1, ["y"] = 13, ["param1"] = 95, ["z"] = 9, ["name"] = "bones:bones"}, {["x"] = 10, ["y"] = 0, ["param1"] = 143, ["z"] = 0, ["name"] = "moretrees:rubber_tree_planks"}, {["x"] = 10, ["y"] = 0, ["param1"] = 127, ["z"] = 1, ["name"] = "moretrees:rubber_tree_planks"}, {["x"] = 10, ["y"] = 0, ["param1"] = 111, ["z"] = 2, ["name"] = "moretrees:rubber_tree_planks"}, {["x"] = 10, ["y"] = 0, ["param1"] = 95, ["z"] = 3, ["name"] = "moretrees:rubber_tree_planks"}, {["x"] = 10, ["y"] = 0, ["param1"] = 79, ["z"] = 4, ["name"] = "moretrees:rubber_tree_planks"}, {["x"] = 10, ["y"] = 0, ["param1"] = 79, ["z"] = 5, ["name"] = "moretrees:rubber_tree_planks"}, {["x"] = 10, ["y"] = 0, ["param1"] = 95, ["z"] = 6, ["name"] = "moretrees:rubber_tree_planks"}, {["x"] = 10, ["y"] = 0, ["param1"] = 111, ["z"] = 7, ["name"] = "moretrees:rubber_tree_planks"}, {["x"] = 10, ["y"] = 0, ["param1"] = 127, ["z"] = 8, ["name"] = "moretrees:rubber_tree_planks"}, {["x"] = 10, ["y"] = 0, ["param1"] = 143, ["z"] = 9, ["name"] = "moretrees:rubber_tree_planks"}, {["x"] = 10, ["y"] = 1, ["param1"] = 190, ["z"] = 0, ["name"] = "caverealms:glow_ore"}, {["x"] = 10, ["y"] = 1, ["param1"] = 190, ["z"] = 9, ["name"] = "caverealms:glow_ore"}, {["x"] = 10, ["y"] = 2, ["param1"] = 206, ["z"] = 0, ["name"] = "lapis:lapis_tile"}, {["x"] = 10, ["y"] = 2, ["param1"] = 206, ["z"] = 9, ["name"] = "lapis:lapis_tile"}, {["x"] = 10, ["y"] = 3, ["param1"] = 222, ["z"] = 0, ["name"] = "caverealms:glow_crystal"}, {["x"] = 10, ["y"] = 3, ["param1"] = 205, ["z"] = 1, ["name"] = "caverealms:glow_worm"}, {["x"] = 10, ["y"] = 3, ["param1"] = 205, ["z"] = 8, ["name"] = "caverealms:glow_worm"}, {["x"] = 10, ["y"] = 3, ["param1"] = 222, ["z"] = 9, ["name"] = "caverealms:glow_crystal"}, {["x"] = 10, ["y"] = 4, ["param1"] = 191, ["z"] = 1, ["name"] = "birthstones:alexandriteblock"}, {["x"] = 10, ["y"] = 4, ["param1"] = 175, ["z"] = 2, ["name"] = "technic:marble"}, {["x"] = 10, ["y"] = 4, ["param1"] = 159, ["z"] = 3, ["name"] = "technic:marble"}, {["x"] = 10, ["y"] = 4, ["param1"] = 143, ["z"] = 4, ["name"] = "technic:marble"}, {["x"] = 10, ["y"] = 4, ["param1"] = 143, ["z"] = 5, ["name"] = "technic:marble"}, {["x"] = 10, ["y"] = 4, ["param1"] = 159, ["z"] = 6, ["name"] = "technic:marble"}, {["x"] = 10, ["y"] = 4, ["param1"] = 175, ["z"] = 7, ["name"] = "technic:marble"}, {["x"] = 10, ["y"] = 4, ["param1"] = 191, ["z"] = 8, ["name"] = "birthstones:alexandriteblock"}, {["x"] = 10, ["y"] = 5, ["param1"] = 191, ["z"] = 0, ["name"] = "default:diamondblock"}, {["x"] = 10, ["y"] = 5, ["param1"] = 191, ["z"] = 9, ["name"] = "default:diamondblock"}, {["x"] = 10, ["y"] = 6, ["param1"] = 142, ["z"] = 0, ["name"] = "default:mese"}, {["x"] = 10, ["y"] = 6, ["param1"] = 142, ["z"] = 9, ["name"] = "default:mese"}, {["x"] = 10, ["y"] = 7, ["param1"] = 126, ["z"] = 0, ["name"] = "default:mese"}, {["x"] = 10, ["y"] = 7, ["param1"] = 126, ["z"] = 9, ["name"] = "default:mese"}, {["x"] = 10, ["y"] = 8, ["z"] = 0, ["name"] = "default:brick"}, {["x"] = 10, ["y"] = 8, ["z"] = 9, ["name"] = "default:brick"}, {["x"] = 10, ["y"] = 9, ["param1"] = 190, ["z"] = 0, ["name"] = "caverealms:glow_gem"}, {["x"] = 10, ["y"] = 9, ["param1"] = 175, ["z"] = 1, ["name"] = "default:brick"}, {["x"] = 10, ["y"] = 9, ["param1"] = 127, ["z"] = 2, ["name"] = "default:brick"}, {["x"] = 10, ["y"] = 9, ["param1"] = 111, ["z"] = 3, ["name"] = "default:brick"}, {["x"] = 10, ["y"] = 9, ["param1"] = 95, ["z"] = 4, ["name"] = "default:brick"}, {["x"] = 10, ["y"] = 9, ["param1"] = 79, ["z"] = 5, ["name"] = "default:brick"}, {["x"] = 10, ["y"] = 9, ["param1"] = 63, ["z"] = 6, ["name"] = "default:brick"}, {["x"] = 10, ["y"] = 9, ["param1"] = 63, ["z"] = 7, ["name"] = "default:brick"}, {["x"] = 10, ["y"] = 9, ["param1"] = 79, ["z"] = 8, ["name"] = "default:brick"}, {["x"] = 10, ["y"] = 9, ["param1"] = 190, ["z"] = 9, ["name"] = "caverealms:glow_gem"}, {["x"] = 10, ["y"] = 10, ["param1"] = 175, ["z"] = 0, ["name"] = "default:brick"}, {["x"] = 10, ["y"] = 10, ["param1"] = 175, ["z"] = 9, ["name"] = "default:brick"}, {["x"] = 10, ["param2"] = 1, ["y"] = 11, ["param1"] = 127, ["z"] = 0, ["name"] = "bones:bones"}, {["x"] = 10, ["param2"] = 1, ["y"] = 11, ["param1"] = 127, ["z"] = 9, ["name"] = "bones:bones"}, {["x"] = 10, ["param2"] = 1, ["y"] = 12, ["param1"] = 111, ["z"] = 0, ["name"] = "bones:bones"}, {["x"] = 10, ["param2"] = 1, ["y"] = 12, ["param1"] = 111, ["z"] = 9, ["name"] = "bones:bones"}, {["x"] = 10, ["param2"] = 1, ["y"] = 13, ["param1"] = 111, ["z"] = 0, ["name"] = "bones:bones"}, {["x"] = 10, ["param2"] = 1, ["y"] = 13, ["param1"] = 111, ["z"] = 9, ["name"] = "bones:bones"}, {["x"] = 11, ["y"] = 0, ["param1"] = 159, ["z"] = 0, ["name"] = "moretrees:rubber_tree_planks"}, {["x"] = 11, ["y"] = 0, ["param1"] = 143, ["z"] = 1, ["name"] = "moretrees:rubber_tree_planks"}, {["x"] = 11, ["y"] = 0, ["param1"] = 127, ["z"] = 2, ["name"] = "moretrees:rubber_tree_planks"}, {["x"] = 11, ["y"] = 0, ["param1"] = 111, ["z"] = 3, ["name"] = "moretrees:rubber_tree_planks"}, {["x"] = 11, ["y"] = 0, ["param1"] = 95, ["z"] = 4, ["name"] = "moretrees:rubber_tree_planks"}, {["x"] = 11, ["y"] = 0, ["param1"] = 95, ["z"] = 5, ["name"] = "moretrees:rubber_tree_planks"}, {["x"] = 11, ["y"] = 0, ["param1"] = 111, ["z"] = 6, ["name"] = "moretrees:rubber_tree_planks"}, {["x"] = 11, ["y"] = 0, ["param1"] = 127, ["z"] = 7, ["name"] = "moretrees:rubber_tree_planks"}, {["x"] = 11, ["y"] = 0, ["param1"] = 143, ["z"] = 8, ["name"] = "moretrees:rubber_tree_planks"}, {["x"] = 11, ["y"] = 0, ["param1"] = 159, ["z"] = 9, ["name"] = "moretrees:rubber_tree_planks"}, {["x"] = 11, ["y"] = 1, ["param1"] = 174, ["z"] = 0, ["name"] = "caverealms:glow_ore"}, {["x"] = 11, ["y"] = 1, ["param1"] = 174, ["z"] = 9, ["name"] = "caverealms:glow_ore"}, {["x"] = 11, ["y"] = 2, ["param1"] = 190, ["z"] = 0, ["name"] = "lapis:lapis_tile"}, {["x"] = 11, ["y"] = 2, ["param1"] = 190, ["z"] = 9, ["name"] = "lapis:lapis_tile"}, {["x"] = 11, ["y"] = 3, ["param1"] = 206, ["z"] = 0, ["name"] = "lapis:lapis_tile"}, {["x"] = 11, ["y"] = 3, ["param1"] = 189, ["z"] = 1, ["name"] = "caverealms:glow_worm"}, {["x"] = 11, ["y"] = 3, ["param1"] = 189, ["z"] = 8, ["name"] = "caverealms:glow_worm"}, {["x"] = 11, ["y"] = 3, ["param1"] = 206, ["z"] = 9, ["name"] = "lapis:lapis_tile"}, {["x"] = 11, ["y"] = 4, ["param1"] = 190, ["z"] = 0, ["name"] = "caverealms:glow_ore"}, {["x"] = 11, ["y"] = 4, ["param1"] = 175, ["z"] = 1, ["name"] = "technic:chromium_block"}, {["x"] = 11, ["y"] = 4, ["param1"] = 159, ["z"] = 2, ["name"] = "technic:marble"}, {["x"] = 11, ["y"] = 4, ["param1"] = 143, ["z"] = 3, ["name"] = "technic:chromium_block"}, {["x"] = 11, ["y"] = 4, ["param1"] = 127, ["z"] = 4, ["name"] = "technic:chromium_block"}, {["x"] = 11, ["y"] = 4, ["param1"] = 127, ["z"] = 5, ["name"] = "technic:chromium_block"}, {["x"] = 11, ["y"] = 4, ["param1"] = 143, ["z"] = 6, ["name"] = "technic:chromium_block"}, {["x"] = 11, ["y"] = 4, ["param1"] = 159, ["z"] = 7, ["name"] = "technic:chromium_block"}, {["x"] = 11, ["y"] = 4, ["param1"] = 175, ["z"] = 8, ["name"] = "technic:chromium_block"}, {["x"] = 11, ["y"] = 4, ["param1"] = 190, ["z"] = 9, ["name"] = "caverealms:glow_ore"}, {["x"] = 11, ["y"] = 5, ["param1"] = 175, ["z"] = 0, ["name"] = "default:diamondblock"}, {["x"] = 11, ["y"] = 5, ["param1"] = 175, ["z"] = 9, ["name"] = "default:diamondblock"}, {["x"] = 11, ["y"] = 6, ["param1"] = 126, ["z"] = 0, ["name"] = "default:mese"}, {["x"] = 11, ["y"] = 6, ["param1"] = 126, ["z"] = 9, ["name"] = "default:mese"}, {["x"] = 11, ["y"] = 7, ["param1"] = 110, ["z"] = 0, ["name"] = "default:mese"}, {["x"] = 11, ["y"] = 7, ["param1"] = 110, ["z"] = 9, ["name"] = "default:mese"}, {["x"] = 11, ["meta"] = {["fields"] = {["owner"] = "n", ["infotext"] = "Itemwise Filter-Injector", ["slotseq_index"] = "1", ["formspec"] = "size[8,8.5]item_image[0,0;1,1;pipeworks:filter]label[1,0;Itemwise Filter-Injector]label[0,1;Prefer item types:]list[context;main;0,1.5;8,2;]button[0,3.5;4,1;fs_helpers_cycling:1:slotseq_mode;Sequence slots by Priority]list[current_player;main;0,4.5;8,4;]listring[]"}, ["inventory"] = {["main"] = {"", "", "", "", "", "", "", "", "", "", "", "", "", "", "", ""}}}, ["param2"] = 3, ["y"] = 8, ["param1"] = 95, ["z"] = 0, ["name"] = "pipeworks:filter"}, {["x"] = 11, ["meta"] = {["fields"] = {["owner"] = "n", ["infotext"] = "Itemwise Filter-Injector", ["slotseq_index"] = "1", ["formspec"] = "size[8,8.5]item_image[0,0;1,1;pipeworks:filter]label[1,0;Itemwise Filter-Injector]label[0,1;Prefer item types:]list[context;main;0,1.5;8,2;]button[0,3.5;4,1;fs_helpers_cycling:1:slotseq_mode;Sequence slots by Priority]list[current_player;main;0,4.5;8,4;]listring[]"}, ["inventory"] = {["main"] = {"", "", "", "", "", "", "", "", "", "", "", "", "", "", "", ""}}}, ["param2"] = 1, ["y"] = 8, ["param1"] = 95, ["z"] = 9, ["name"] = "pipeworks:filter"}, {["x"] = 11, ["y"] = 9, ["param1"] = 79, ["z"] = 0, ["name"] = "default:brick"}, {["x"] = 11, ["y"] = 9, ["param1"] = 79, ["z"] = 1, ["name"] = "default:brick"}, {["x"] = 11, ["y"] = 9, ["param1"] = 63, ["z"] = 2, ["name"] = "default:brick"}, {["x"] = 11, ["y"] = 9, ["param1"] = 47, ["z"] = 3, ["name"] = "default:brick"}, {["x"] = 11, ["y"] = 9, ["param1"] = 47, ["z"] = 4, ["name"] = "default:brick"}, {["x"] = 11, ["y"] = 9, ["param1"] = 47, ["z"] = 5, ["name"] = "default:brick"}, {["x"] = 11, ["y"] = 9, ["param1"] = 63, ["z"] = 6, ["name"] = "default:brick"}, {["x"] = 11, ["y"] = 9, ["param1"] = 79, ["z"] = 7, ["name"] = "default:brick"}, {["x"] = 11, ["y"] = 9, ["param1"] = 79, ["z"] = 8, ["name"] = "default:brick"}, {["x"] = 11, ["y"] = 9, ["param1"] = 79, ["z"] = 9, ["name"] = "default:brick"}, {["x"] = 11, ["y"] = 10, ["param1"] = 79, ["z"] = 0, ["name"] = "default:brick"}, {["x"] = 11, ["y"] = 10, ["param1"] = 79, ["z"] = 9, ["name"] = "default:brick"}, {["x"] = 11, ["param2"] = 1, ["y"] = 11, ["param1"] = 95, ["z"] = 0, ["name"] = "bones:bones"}, {["x"] = 11, ["param2"] = 1, ["y"] = 11, ["param1"] = 95, ["z"] = 9, ["name"] = "bones:bones"}, {["x"] = 11, ["param2"] = 1, ["y"] = 12, ["param1"] = 111, ["z"] = 0, ["name"] = "bones:bones"}, {["x"] = 11, ["param2"] = 1, ["y"] = 12, ["param1"] = 111, ["z"] = 9, ["name"] = "bones:bones"}, {["x"] = 11, ["param2"] = 1, ["y"] = 13, ["param1"] = 127, ["z"] = 0, ["name"] = "bones:bones"}, {["x"] = 11, ["param2"] = 1, ["y"] = 13, ["param1"] = 127, ["z"] = 9, ["name"] = "bones:bones"}, {["x"] = 12, ["y"] = 0, ["param1"] = 143, ["z"] = 0, ["name"] = "moretrees:rubber_tree_planks"}, {["x"] = 12, ["y"] = 0, ["param1"] = 127, ["z"] = 1, ["name"] = "moretrees:rubber_tree_planks"}, {["x"] = 12, ["y"] = 0, ["param1"] = 111, ["z"] = 2, ["name"] = "moretrees:rubber_tree_planks"}, {["x"] = 12, ["y"] = 0, ["param1"] = 111, ["z"] = 3, ["name"] = "moretrees:rubber_tree_planks"}, {["x"] = 12, ["y"] = 0, ["param1"] = 111, ["z"] = 4, ["name"] = "moretrees:rubber_tree_planks"}, {["x"] = 12, ["y"] = 0, ["z"] = 5, ["name"] = "moretrees:rubber_tree_planks"}, {["x"] = 12, ["y"] = 0, ["param1"] = 111, ["z"] = 6, ["name"] = "moretrees:rubber_tree_planks"}, {["x"] = 12, ["y"] = 0, ["z"] = 7, ["name"] = "moretrees:rubber_tree_planks"}, {["x"] = 12, ["y"] = 0, ["param1"] = 127, ["z"] = 8, ["name"] = "moretrees:rubber_tree_planks"}, {["x"] = 12, ["y"] = 0, ["param1"] = 143, ["z"] = 9, ["name"] = "moretrees:rubber_tree_planks"}, {["x"] = 12, ["y"] = 1, ["param1"] = 190, ["z"] = 0, ["name"] = "caverealms:glow_ore"}, {["x"] = 12, ["param2"] = 1, ["y"] = 1, ["param1"] = 123, ["z"] = 4, ["name"] = "trunks:twig_1"}, {["x"] = 12, ["y"] = 1, ["param1"] = 190, ["z"] = 9, ["name"] = "caverealms:glow_ore"}, {["x"] = 12, ["y"] = 2, ["param1"] = 206, ["z"] = 0, ["name"] = "lapis:lapis_tile"}, {["x"] = 12, ["meta"] = {["fields"] = {["owner"] = "n", ["infotext"] = "Consult n's Awards\
Right-click to open"}, ["inventory"] = {}}, ["param2"] = 4, ["y"] = 2, ["param1"] = 190, ["z"] = 8, ["name"] = "awards_board:board"}, {["x"] = 12, ["y"] = 2, ["param1"] = 206, ["z"] = 9, ["name"] = "lapis:lapis_tile"}, {["x"] = 12, ["y"] = 3, ["param1"] = 222, ["z"] = 0, ["name"] = "caverealms:glow_crystal"}, {["x"] = 12, ["y"] = 3, ["param1"] = 205, ["z"] = 1, ["name"] = "caverealms:glow_worm"}, {["x"] = 12, ["y"] = 3, ["param1"] = 222, ["z"] = 9, ["name"] = "caverealms:glow_crystal"}, {["x"] = 12, ["y"] = 4, ["param1"] = 191, ["z"] = 1, ["name"] = "birthstones:alexandriteblock"}, {["x"] = 12, ["y"] = 4, ["param1"] = 175, ["z"] = 2, ["name"] = "technic:marble"}, {["x"] = 12, ["y"] = 4, ["param1"] = 159, ["z"] = 3, ["name"] = "technic:chromium_block"}, {["x"] = 12, ["y"] = 4, ["z"] = 4, ["name"] = "technic:chromium_block"}, {["x"] = 12, ["y"] = 4, ["param1"] = 138, ["z"] = 5, ["name"] = "lapis:lapis_tile"}, {["x"] = 12, ["y"] = 4, ["param1"] = 159, ["z"] = 6, ["name"] = "birthstones:alexandriteblock"}, {["x"] = 12, ["y"] = 4, ["param1"] = 172, ["z"] = 7, ["name"] = "lapis:lapis_tile"}, {["x"] = 12, ["y"] = 4, ["param1"] = 191, ["z"] = 8, ["name"] = "birthstones:alexandriteblock"}, {["x"] = 12, ["y"] = 5, ["param1"] = 191, ["z"] = 0, ["name"] = "default:diamondblock"}, {["x"] = 12, ["y"] = 5, ["param1"] = 191, ["z"] = 9, ["name"] = "default:diamondblock"}, {["x"] = 12, ["y"] = 6, ["param1"] = 142, ["z"] = 0, ["name"] = "default:mese"}, {["x"] = 12, ["y"] = 6, ["param1"] = 142, ["z"] = 9, ["name"] = "default:mese"}, {["x"] = 12, ["y"] = 7, ["param1"] = 126, ["z"] = 0, ["name"] = "default:mese"}, {["x"] = 12, ["y"] = 7, ["param1"] = 126, ["z"] = 9, ["name"] = "default:mese"}, {["x"] = 12, ["y"] = 8, ["param1"] = 111, ["z"] = 0, ["name"] = "technic:marble"}, {["x"] = 12, ["y"] = 8, ["param1"] = 111, ["z"] = 9, ["name"] = "technic:marble"}, {["x"] = 12, ["y"] = 9, ["param1"] = 95, ["z"] = 0, ["name"] = "default:brick"}, {["x"] = 12, ["y"] = 9, ["param1"] = 95, ["z"] = 1, ["name"] = "default:brick"}, {["x"] = 12, ["y"] = 9, ["param1"] = 79, ["z"] = 2, ["name"] = "default:brick"}, {["x"] = 12, ["y"] = 9, ["param1"] = 63, ["z"] = 3, ["name"] = "default:brick"}, {["x"] = 12, ["y"] = 9, ["param1"] = 63, ["z"] = 4, ["name"] = "default:brick"}, {["x"] = 12, ["y"] = 9, ["param1"] = 63, ["z"] = 5, ["name"] = "default:brick"}, {["x"] = 12, ["y"] = 9, ["param1"] = 79, ["z"] = 6, ["name"] = "default:brick"}, {["x"] = 12, ["y"] = 9, ["param1"] = 95, ["z"] = 7, ["name"] = "default:brick"}, {["x"] = 12, ["y"] = 9, ["param1"] = 95, ["z"] = 8, ["name"] = "default:brick"}, {["x"] = 12, ["y"] = 9, ["param1"] = 95, ["z"] = 9, ["name"] = "default:brick"}, {["x"] = 12, ["y"] = 10, ["param1"] = 95, ["z"] = 0, ["name"] = "default:brick"}, {["x"] = 12, ["y"] = 10, ["param1"] = 95, ["z"] = 9, ["name"] = "default:brick"}, {["x"] = 12, ["param2"] = 1, ["y"] = 11, ["param1"] = 111, ["z"] = 0, ["name"] = "bones:bones"}, {["x"] = 12, ["param2"] = 1, ["y"] = 11, ["param1"] = 111, ["z"] = 9, ["name"] = "bones:bones"}, {["x"] = 12, ["param2"] = 1, ["y"] = 12, ["param1"] = 127, ["z"] = 0, ["name"] = "bones:bones"}, {["x"] = 12, ["param2"] = 1, ["y"] = 12, ["param1"] = 127, ["z"] = 9, ["name"] = "bones:bones"}, {["x"] = 12, ["param2"] = 1, ["y"] = 13, ["param1"] = 143, ["z"] = 0, ["name"] = "bones:bones"}, {["x"] = 12, ["param2"] = 1, ["y"] = 13, ["param1"] = 143, ["z"] = 9, ["name"] = "bones:bones"}, {["x"] = 13, ["y"] = 0, ["param1"] = 159, ["z"] = 0, ["name"] = "moretrees:rubber_tree_planks"}, {["x"] = 13, ["y"] = 0, ["param1"] = 143, ["z"] = 1, ["name"] = "moretrees:rubber_tree_planks"}, {["x"] = 13, ["y"] = 0, ["param1"] = 127, ["z"] = 2, ["name"] = "moretrees:rubber_tree_planks"}, {["x"] = 13, ["y"] = 0, ["param1"] = 127, ["z"] = 3, ["name"] = "moretrees:rubber_tree_planks"}, {["x"] = 13, ["y"] = 0, ["param1"] = 127, ["z"] = 4, ["name"] = "moretrees:rubber_tree_planks"}, {["x"] = 13, ["y"] = 0, ["param1"] = 127, ["z"] = 5, ["name"] = "moretrees:rubber_tree_planks"}, {["x"] = 13, ["y"] = 0, ["param1"] = 127, ["z"] = 6, ["name"] = "moretrees:rubber_tree_planks"}, {["x"] = 13, ["y"] = 0, ["param1"] = 127, ["z"] = 7, ["name"] = "moretrees:rubber_tree_planks"}, {["x"] = 13, ["y"] = 0, ["param1"] = 143, ["z"] = 8, ["name"] = "moretrees:rubber_tree_planks"}, {["x"] = 13, ["y"] = 0, ["param1"] = 159, ["z"] = 9, ["name"] = "moretrees:rubber_tree_planks"}, {["x"] = 13, ["y"] = 1, ["param1"] = 174, ["z"] = 0, ["name"] = "caverealms:glow_ore"}, {["x"] = 13, ["param2"] = 4, ["y"] = 1, ["param1"] = 159, ["z"] = 8, ["name"] = "default:ladder_wood"}, {["x"] = 13, ["y"] = 1, ["param1"] = 174, ["z"] = 9, ["name"] = "caverealms:glow_ore"}, {["x"] = 13, ["y"] = 2, ["param1"] = 190, ["z"] = 0, ["name"] = "lapis:lapis_tile"}, {["x"] = 13, ["param2"] = 4, ["y"] = 2, ["param1"] = 175, ["z"] = 8, ["name"] = "default:ladder_wood"}, {["x"] = 13, ["y"] = 2, ["param1"] = 190, ["z"] = 9, ["name"] = "lapis:lapis_tile"}, {["x"] = 13, ["y"] = 3, ["param1"] = 206, ["z"] = 0, ["name"] = "lapis:lapis_tile"}, {["x"] = 13, ["y"] = 3, ["param1"] = 189, ["z"] = 1, ["name"] = "caverealms:glow_worm"}, {["x"] = 13, ["param2"] = 4, ["y"] = 3, ["param1"] = 191, ["z"] = 8, ["name"] = "default:ladder_wood"}, {["x"] = 13, ["y"] = 3, ["param1"] = 206, ["z"] = 9, ["name"] = "lapis:lapis_tile"}, {["x"] = 13, ["y"] = 4, ["param1"] = 190, ["z"] = 0, ["name"] = "caverealms:glow_ore"}, {["x"] = 13, ["y"] = 4, ["param1"] = 175, ["z"] = 1, ["name"] = "technic:chromium_block"}, {["x"] = 13, ["y"] = 4, ["param1"] = 159, ["z"] = 2, ["name"] = "technic:marble"}, {["x"] = 13, ["y"] = 4, ["param1"] = 143, ["z"] = 3, ["name"] = "technic:chromium_block"}, {["x"] = 13, ["y"] = 4, ["param1"] = 127, ["z"] = 4, ["name"] = "technic:chromium_block"}, {["x"] = 13, ["y"] = 4, ["param1"] = 143, ["z"] = 5, ["name"] = "birthstones:alexandriteblock"}, {["x"] = 13, ["y"] = 4, ["param1"] = 143, ["z"] = 6, ["name"] = "technic:chromium_block"}, {["x"] = 13, ["y"] = 4, ["param1"] = 159, ["z"] = 7, ["name"] = "birthstones:alexandriteblock"}, {["x"] = 13, ["param2"] = 4, ["y"] = 4, ["param1"] = 175, ["z"] = 8, ["name"] = "default:ladder_wood"}, {["x"] = 13, ["y"] = 4, ["param1"] = 190, ["z"] = 9, ["name"] = "caverealms:glow_ore"}, {["x"] = 13, ["y"] = 5, ["param1"] = 175, ["z"] = 0, ["name"] = "default:diamondblock"}, {["x"] = 13, ["param2"] = 4, ["y"] = 5, ["param1"] = 175, ["z"] = 8, ["name"] = "default:ladder_wood"}, {["x"] = 13, ["y"] = 5, ["param1"] = 175, ["z"] = 9, ["name"] = "default:diamondblock"}, {["x"] = 13, ["y"] = 6, ["param1"] = 142, ["z"] = 0, ["name"] = "default:mese"}, {["x"] = 13, ["param2"] = 4, ["y"] = 6, ["param1"] = 159, ["z"] = 8, ["name"] = "default:ladder_wood"}, {["x"] = 13, ["y"] = 6, ["param1"] = 142, ["z"] = 9, ["name"] = "default:mese"}, {["x"] = 13, ["y"] = 7, ["param1"] = 126, ["z"] = 0, ["name"] = "default:mese"}, {["x"] = 13, ["param2"] = 4, ["y"] = 7, ["param1"] = 142, ["z"] = 8, ["name"] = "default:ladder_wood"}, {["x"] = 13, ["y"] = 7, ["param1"] = 126, ["z"] = 9, ["name"] = "default:mese"}, {["x"] = 13, ["y"] = 8, ["param1"] = 111, ["z"] = 0, ["name"] = "default:desert_cobble"}, {["x"] = 13, ["param2"] = 4, ["y"] = 8, ["param1"] = 127, ["z"] = 8, ["name"] = "default:ladder_wood"}, {["x"] = 13, ["y"] = 8, ["param1"] = 111, ["z"] = 9, ["name"] = "default:desert_cobble"}, {["x"] = 13, ["y"] = 9, ["param1"] = 95, ["z"] = 0, ["name"] = "default:brick"}, {["x"] = 13, ["y"] = 9, ["param1"] = 111, ["z"] = 1, ["name"] = "default:brick"}, {["x"] = 13, ["y"] = 9, ["param1"] = 95, ["z"] = 2, ["name"] = "default:brick"}, {["x"] = 13, ["y"] = 9, ["param1"] = 79, ["z"] = 3, ["name"] = "default:brick"}, {["x"] = 13, ["y"] = 9, ["param1"] = 63, ["z"] = 4, ["name"] = "default:brick"}, {["x"] = 13, ["y"] = 9, ["param1"] = 63, ["z"] = 5, ["name"] = "default:brick"}, {["x"] = 13, ["y"] = 9, ["param1"] = 79, ["z"] = 6, ["name"] = "default:brick"}, {["x"] = 13, ["y"] = 9, ["param1"] = 95, ["z"] = 7, ["name"] = "default:brick"}, {["x"] = 13, ["param2"] = 4, ["y"] = 9, ["param1"] = 111, ["z"] = 8, ["name"] = "default:ladder_wood"}, {["x"] = 13, ["y"] = 9, ["param1"] = 95, ["z"] = 9, ["name"] = "default:brick"}, {["x"] = 13, ["y"] = 10, ["param1"] = 111, ["z"] = 0, ["name"] = "default:brick"}, {["x"] = 13, ["param2"] = 4, ["y"] = 10, ["param1"] = 95, ["z"] = 8, ["name"] = "default:ladder_wood"}, {["x"] = 13, ["y"] = 10, ["param1"] = 111, ["z"] = 9, ["name"] = "default:brick"}, {["x"] = 13, ["param2"] = 1, ["y"] = 11, ["param1"] = 127, ["z"] = 0, ["name"] = "bones:bones"}, {["x"] = 13, ["param2"] = 4, ["y"] = 11, ["param1"] = 111, ["z"] = 8, ["name"] = "default:ladder_wood"}, {["x"] = 13, ["param2"] = 1, ["y"] = 11, ["param1"] = 127, ["z"] = 9, ["name"] = "bones:bones"}, {["x"] = 13, ["param2"] = 1, ["y"] = 12, ["param1"] = 143, ["z"] = 0, ["name"] = "bones:bones"}, {["x"] = 13, ["param2"] = 4, ["y"] = 12, ["param1"] = 127, ["z"] = 8, ["name"] = "default:ladder_wood"}, {["x"] = 13, ["param2"] = 1, ["y"] = 12, ["param1"] = 143, ["z"] = 9, ["name"] = "bones:bones"}, {["x"] = 13, ["param2"] = 1, ["y"] = 13, ["param1"] = 159, ["z"] = 0, ["name"] = "bones:bones"}, {["x"] = 13, ["param2"] = 4, ["y"] = 13, ["param1"] = 143, ["z"] = 8, ["name"] = "default:ladder_wood"}, {["x"] = 13, ["param2"] = 1, ["y"] = 13, ["param1"] = 159, ["z"] = 9, ["name"] = "bones:bones"}, {["x"] = 14, ["y"] = 0, ["param1"] = 127, ["z"] = 0, ["name"] = "moretrees:rubber_tree_planks"}, {["x"] = 14, ["y"] = 0, ["param1"] = 143, ["z"] = 1, ["name"] = "moretrees:rubber_tree_planks"}, {["x"] = 14, ["y"] = 0, ["z"] = 2, ["name"] = "moretrees:rubber_tree_planks"}, {["x"] = 14, ["y"] = 0, ["param1"] = 143, ["z"] = 3, ["name"] = "moretrees:rubber_tree_planks"}, {["x"] = 14, ["y"] = 0, ["param1"] = 143, ["z"] = 4, ["name"] = "moretrees:rubber_tree_planks"}, {["x"] = 14, ["y"] = 0, ["param1"] = 143, ["z"] = 5, ["name"] = "moretrees:rubber_tree_planks"}, {["x"] = 14, ["y"] = 0, ["param1"] = 143, ["z"] = 6, ["name"] = "moretrees:rubber_tree_planks"}, {["x"] = 14, ["y"] = 0, ["param1"] = 143, ["z"] = 7, ["name"] = "moretrees:rubber_tree_planks"}, {["x"] = 14, ["y"] = 0, ["param1"] = 143, ["z"] = 8, ["name"] = "moretrees:rubber_tree_planks"}, {["x"] = 14, ["y"] = 0, ["param1"] = 127, ["z"] = 9, ["name"] = "moretrees:rubber_tree_planks"}, {["x"] = 14, ["y"] = 1, ["param1"] = 190, ["z"] = 0, ["name"] = "caverealms:glow_ore"}, {["x"] = 14, ["param2"] = 2, ["y"] = 1, ["param1"] = 173, ["z"] = 1, ["name"] = "homedecor:wood_table_small_round"}, {["x"] = 14, ["param2"] = 2, ["y"] = 1, ["param1"] = 157, ["z"] = 2, ["name"] = "beds:bed_top"}, {["x"] = 14, ["param2"] = 2, ["y"] = 1, ["param1"] = 157, ["z"] = 3, ["name"] = "beds:bed_bottom"}, {["x"] = 14, ["y"] = 1, ["param1"] = 157, ["z"] = 4, ["name"] = "default:glass"}, {["x"] = 14, ["y"] = 1, ["param1"] = 157, ["z"] = 5, ["name"] = "default:glass"}, {["x"] = 14, ["y"] = 1, ["param1"] = 157, ["z"] = 6, ["name"] = "beds:bed_bottom"}, {["x"] = 14, ["y"] = 1, ["param1"] = 157, ["z"] = 7, ["name"] = "beds:bed_top"}, {["x"] = 14, ["param2"] = 3, ["y"] = 1, ["param1"] = 174, ["z"] = 8, ["name"] = "homedecor:wood_table_small_round"}, {["x"] = 14, ["y"] = 1, ["param1"] = 190, ["z"] = 9, ["name"] = "caverealms:glow_ore"}, {["x"] = 14, ["y"] = 2, ["param1"] = 206, ["z"] = 0, ["name"] = "lapis:lapis_tile"}, {["x"] = 14, ["meta"] = {["fields"] = {["x"] = "0", ["formspec"] = "size[12,10]label[3.3,0.0;Travelnet-Box:]label[6.3,0.0;Punch box to update target list.]label[0.3,0.4;Name of this station:]label[6.3,0.4;Blue 87]label[0.3,0.8;Assigned to Network:]label[6.3,0.8;6464]label[0.3,1.2;Owned by:]label[6.3,1.2;s]label[3.3,1.6;Click on target to travel there:]button_exit[4,2.5;1,0.5;open_door;<>]label[4.9,2.35;Blue 87]", ["y"] = "0", ["text"] = "0,0,0,Spawn", ["station_name"] = "Blue 87", ["timestamp"] = "1496850091", ["station_network"] = "6464", ["infotext"] = "Station 'Blue 87' on travelnet '6464' (owned by s) ready for usage. Right-click to travel, punch to update.", ["enabled"] = "1", ["z"] = "0", ["owner"] = "s"}, ["inventory"] = {}}, ["param2"] = 1, ["y"] = 2, ["param1"] = 173, ["z"] = 4, ["name"] = "travelnet:travelnet"}, {["x"] = 14, ["y"] = 2, ["param1"] = 206, ["z"] = 9, ["name"] = "lapis:lapis_tile"}, {["x"] = 14, ["y"] = 3, ["param1"] = 222, ["z"] = 0, ["name"] = "caverealms:glow_crystal"}, {["x"] = 14, ["param2"] = 1, ["y"] = 3, ["param1"] = 206, ["z"] = 8, ["name"] = "homedecor:analog_clock_wood"}, {["x"] = 14, ["y"] = 3, ["param1"] = 222, ["z"] = 9, ["name"] = "caverealms:glow_crystal"}, {["x"] = 14, ["y"] = 4, ["param1"] = 191, ["z"] = 1, ["name"] = "birthstones:alexandriteblock"}, {["x"] = 14, ["y"] = 4, ["param1"] = 175, ["z"] = 2, ["name"] = "technic:chromium_block"}, {["x"] = 14, ["y"] = 4, ["param1"] = 159, ["z"] = 3, ["name"] = "birthstones:alexandriteblock"}, {["x"] = 14, ["y"] = 4, ["param1"] = 159, ["z"] = 4, ["name"] = "technic:chromium_block"}, {["x"] = 14, ["y"] = 4, ["param1"] = 157, ["z"] = 5, ["name"] = "lapis:lapis_tile"}, {["x"] = 14, ["y"] = 4, ["param1"] = 159, ["z"] = 6, ["name"] = "birthstones:alexandriteblock"}, {["x"] = 14, ["y"] = 4, ["param1"] = 173, ["z"] = 7, ["name"] = "lapis:lapis_tile"}, {["x"] = 14, ["param2"] = 2, ["y"] = 4, ["param1"] = 191, ["z"] = 8, ["name"] = "bones:bones"}, {["x"] = 14, ["y"] = 5, ["param1"] = 191, ["z"] = 0, ["name"] = "default:desert_cobble"}, {["x"] = 14, ["y"] = 5, ["param1"] = 187, ["z"] = 1, ["name"] = "caverealms:glow_gem_2"}, {["x"] = 14, ["y"] = 5, ["param1"] = 190, ["z"] = 8, ["name"] = "caverealms:glow_gem_3"}, {["x"] = 14, ["y"] = 5, ["param1"] = 191, ["z"] = 9, ["name"] = "default:desert_cobble"}, {["x"] = 14, ["y"] = 6, ["param1"] = 159, ["z"] = 0, ["name"] = "default:diamondblock"}, {["x"] = 14, ["y"] = 6, ["param1"] = 159, ["z"] = 9, ["name"] = "default:diamondblock"}, {["x"] = 14, ["y"] = 7, ["param1"] = 142, ["z"] = 0, ["name"] = "default:mese"}, {["x"] = 14, ["param2"] = 1, ["y"] = 7, ["param1"] = 109, ["z"] = 5, ["name"] = "homedecor:analog_clock_wood"}, {["x"] = 14, ["y"] = 7, ["param1"] = 142, ["z"] = 9, ["name"] = "default:mese"}, {["x"] = 14, ["y"] = 8, ["param1"] = 127, ["z"] = 0, ["name"] = "default:desert_cobble"}, {["x"] = 14, ["y"] = 8, ["param1"] = 127, ["z"] = 9, ["name"] = "default:desert_cobble"}, {["x"] = 14, ["y"] = 9, ["param1"] = 111, ["z"] = 0, ["name"] = "default:brick"}, {["x"] = 14, ["y"] = 9, ["param1"] = 127, ["z"] = 1, ["name"] = "default:brick"}, {["x"] = 14, ["y"] = 9, ["param1"] = 111, ["z"] = 2, ["name"] = "default:brick"}, {["x"] = 14, ["y"] = 9, ["param1"] = 95, ["z"] = 3, ["name"] = "default:brick"}, {["x"] = 14, ["y"] = 9, ["param1"] = 79, ["z"] = 4, ["name"] = "default:brick"}, {["x"] = 14, ["y"] = 9, ["param1"] = 79, ["z"] = 5, ["name"] = "default:brick"}, {["x"] = 14, ["y"] = 9, ["param1"] = 95, ["z"] = 6, ["name"] = "default:brick"}, {["x"] = 14, ["y"] = 9, ["param1"] = 111, ["z"] = 7, ["name"] = "default:brick"}, {["x"] = 14, ["y"] = 9, ["param1"] = 127, ["z"] = 8, ["name"] = "default:brick"}, {["x"] = 14, ["y"] = 9, ["param1"] = 111, ["z"] = 9, ["name"] = "default:brick"}, {["x"] = 14, ["y"] = 10, ["param1"] = 127, ["z"] = 0, ["name"] = "default:brick"}, {["x"] = 14, ["y"] = 10, ["param1"] = 127, ["z"] = 9, ["name"] = "default:brick"}, {["x"] = 14, ["param2"] = 1, ["y"] = 11, ["param1"] = 143, ["z"] = 0, ["name"] = "bones:bones"}, {["x"] = 14, ["param2"] = 1, ["y"] = 11, ["param1"] = 143, ["z"] = 9, ["name"] = "bones:bones"}, {["x"] = 14, ["param2"] = 1, ["y"] = 12, ["param1"] = 159, ["z"] = 0, ["name"] = "bones:bones"}, {["x"] = 14, ["param2"] = 1, ["y"] = 12, ["param1"] = 159, ["z"] = 9, ["name"] = "bones:bones"}, {["x"] = 14, ["param2"] = 1, ["y"] = 13, ["param1"] = 175, ["z"] = 0, ["name"] = "bones:bones"}, {["x"] = 14, ["param2"] = 1, ["y"] = 13, ["param1"] = 175, ["z"] = 9, ["name"] = "bones:bones"}, {["x"] = 15, ["y"] = 0, ["param1"] = 47, ["z"] = 0, ["name"] = "moretrees:rubber_tree_planks"}, {["x"] = 15, ["y"] = 0, ["param1"] = 31, ["z"] = 1, ["name"] = "moretrees:rubber_tree_planks"}, {["x"] = 15, ["y"] = 0, ["param1"] = 15, ["z"] = 2, ["name"] = "moretrees:rubber_tree_planks"}, {["x"] = 15, ["y"] = 0, ["param1"] = 15, ["z"] = 3, ["name"] = "moretrees:rubber_tree_planks"}, {["x"] = 15, ["y"] = 0, ["param1"] = 15, ["z"] = 4, ["name"] = "moretrees:rubber_tree_planks"}, {["x"] = 15, ["y"] = 0, ["param1"] = 15, ["z"] = 5, ["name"] = "moretrees:rubber_tree_planks"}, {["x"] = 15, ["y"] = 0, ["param1"] = 15, ["z"] = 6, ["name"] = "moretrees:rubber_tree_planks"}, {["x"] = 15, ["y"] = 0, ["param1"] = 15, ["z"] = 7, ["name"] = "moretrees:rubber_tree_planks"}, {["x"] = 15, ["y"] = 0, ["param1"] = 15, ["z"] = 8, ["name"] = "moretrees:rubber_tree_planks"}, {["x"] = 15, ["y"] = 0, ["param1"] = 15, ["z"] = 9, ["name"] = "moretrees:rubber_tree_planks"}, {["x"] = 15, ["y"] = 1, ["param1"] = 174, ["z"] = 0, ["name"] = "lapis:lapis_cobble"}, {["x"] = 15, ["y"] = 1, ["param1"] = 174, ["z"] = 1, ["name"] = "caverealms:glow_ore"}, {["x"] = 15, ["y"] = 1, ["param1"] = 174, ["z"] = 2, ["name"] = "caverealms:glow_ore"}, {["x"] = 15, ["y"] = 1, ["param1"] = 174, ["z"] = 3, ["name"] = "caverealms:glow_ore"}, {["x"] = 15, ["y"] = 1, ["param1"] = 174, ["z"] = 4, ["name"] = "caverealms:glow_ore"}, {["x"] = 15, ["y"] = 1, ["param1"] = 174, ["z"] = 5, ["name"] = "caverealms:glow_ore"}, {["x"] = 15, ["y"] = 1, ["param1"] = 174, ["z"] = 6, ["name"] = "caverealms:glow_ore"}, {["x"] = 15, ["y"] = 1, ["param1"] = 174, ["z"] = 7, ["name"] = "caverealms:glow_ore"}, {["x"] = 15, ["y"] = 1, ["param1"] = 174, ["z"] = 8, ["name"] = "caverealms:glow_ore"}, {["x"] = 15, ["y"] = 1, ["param1"] = 174, ["z"] = 9, ["name"] = "lapis:lapis_cobble"}, {["x"] = 15, ["y"] = 2, ["param1"] = 190, ["z"] = 0, ["name"] = "lapis:lapis_tile"}, {["x"] = 15, ["y"] = 2, ["param1"] = 174, ["z"] = 1, ["name"] = "lapis:lapis_tile"}, {["x"] = 15, ["y"] = 2, ["param1"] = 158, ["z"] = 2, ["name"] = "lapis:lapis_tile"}, {["x"] = 15, ["y"] = 2, ["param1"] = 158, ["z"] = 3, ["name"] = "lapis:lapis_tile"}, {["x"] = 15, ["y"] = 2, ["param1"] = 158, ["z"] = 4, ["name"] = "lapis:lapis_tile"}, {["x"] = 15, ["y"] = 2, ["param1"] = 158, ["z"] = 5, ["name"] = "lapis:lapis_tile"}, {["x"] = 15, ["y"] = 2, ["param1"] = 158, ["z"] = 6, ["name"] = "lapis:lapis_tile"}, {["x"] = 15, ["y"] = 2, ["param1"] = 158, ["z"] = 7, ["name"] = "lapis:lapis_tile"}, {["x"] = 15, ["y"] = 2, ["param1"] = 174, ["z"] = 8, ["name"] = "lapis:lapis_tile"}, {["x"] = 15, ["y"] = 2, ["param1"] = 190, ["z"] = 9, ["name"] = "lapis:lapis_tile"}, {["x"] = 15, ["y"] = 3, ["param1"] = 206, ["z"] = 0, ["name"] = "lapis:lapis_tile"}, {["x"] = 15, ["y"] = 3, ["param1"] = 190, ["z"] = 1, ["name"] = "lapis:lapis_tile"}, {["x"] = 15, ["y"] = 3, ["param1"] = 174, ["z"] = 2, ["name"] = "lapis:lapis_tile"}, {["x"] = 15, ["y"] = 3, ["param1"] = 158, ["z"] = 3, ["name"] = "lapis:lapis_tile"}, {["x"] = 15, ["y"] = 3, ["param1"] = 158, ["z"] = 4, ["name"] = "lapis:lapis_tile"}, {["x"] = 15, ["y"] = 3, ["param1"] = 158, ["z"] = 5, ["name"] = "lapis:lapis_tile"}, {["x"] = 15, ["y"] = 3, ["param1"] = 158, ["z"] = 6, ["name"] = "lapis:lapis_tile"}, {["x"] = 15, ["y"] = 3, ["param1"] = 174, ["z"] = 7, ["name"] = "lapis:lapis_tile"}, {["x"] = 15, ["y"] = 3, ["param1"] = 190, ["z"] = 8, ["name"] = "lapis:lapis_tile"}, {["x"] = 15, ["y"] = 3, ["param1"] = 206, ["z"] = 9, ["name"] = "lapis:lapis_tile"}, {["x"] = 15, ["y"] = 4, ["param1"] = 190, ["z"] = 0, ["name"] = "caverealms:glow_ore"}, {["x"] = 15, ["param2"] = 3, ["y"] = 4, ["param1"] = 174, ["z"] = 1, ["name"] = "lapis:column_lazurite_block"}, {["x"] = 15, ["y"] = 4, ["param1"] = 174, ["z"] = 2, ["name"] = "caverealms:glow_ore"}, {["x"] = 15, ["param2"] = 2, ["y"] = 4, ["param1"] = 158, ["z"] = 3, ["name"] = "lapis:column_lazurite_block"}, {["x"] = 15, ["y"] = 4, ["param1"] = 174, ["z"] = 4, ["name"] = "caverealms:glow_ore"}, {["x"] = 15, ["y"] = 4, ["param1"] = 174, ["z"] = 5, ["name"] = "caverealms:glow_ore"}, {["x"] = 15, ["param2"] = 2, ["y"] = 4, ["param1"] = 158, ["z"] = 6, ["name"] = "lapis:column_lazurite_block"}, {["x"] = 15, ["y"] = 4, ["param1"] = 174, ["z"] = 7, ["name"] = "caverealms:glow_ore"}, {["x"] = 15, ["param2"] = 3, ["y"] = 4, ["param1"] = 174, ["z"] = 8, ["name"] = "lapis:column_lazurite_block"}, {["x"] = 15, ["y"] = 4, ["param1"] = 190, ["z"] = 9, ["name"] = "caverealms:glow_ore"}, {["x"] = 15, ["y"] = 5, ["param1"] = 159, ["z"] = 0, ["name"] = "technic:granite"}, {["x"] = 15, ["y"] = 5, ["param1"] = 143, ["z"] = 1, ["name"] = "default:desert_cobble"}, {["x"] = 15, ["y"] = 5, ["param1"] = 159, ["z"] = 2, ["name"] = "default:diamondblock"}, {["x"] = 15, ["y"] = 5, ["param1"] = 143, ["z"] = 3, ["name"] = "default:diamondblock"}, {["x"] = 15, ["y"] = 5, ["param1"] = 159, ["z"] = 4, ["name"] = "default:diamondblock"}, {["x"] = 15, ["y"] = 5, ["param1"] = 159, ["z"] = 5, ["name"] = "default:diamondblock"}, {["x"] = 15, ["y"] = 5, ["param1"] = 143, ["z"] = 6, ["name"] = "default:diamondblock"}, {["x"] = 15, ["y"] = 5, ["param1"] = 159, ["z"] = 7, ["name"] = "default:diamondblock"}, {["x"] = 15, ["y"] = 5, ["param1"] = 143, ["z"] = 8, ["name"] = "default:desert_cobble"}, {["x"] = 15, ["y"] = 5, ["param1"] = 159, ["z"] = 9, ["name"] = "technic:granite"}, {["x"] = 15, ["y"] = 6, ["param1"] = 111, ["z"] = 0, ["name"] = "default:desert_cobble"}, {["x"] = 15, ["y"] = 6, ["param1"] = 95, ["z"] = 1, ["name"] = "default:diamondblock"}, {["x"] = 15, ["y"] = 6, ["param1"] = 142, ["z"] = 2, ["name"] = "default:mese"}, {["x"] = 15, ["y"] = 6, ["param1"] = 126, ["z"] = 3, ["name"] = "default:mese"}, {["x"] = 15, ["y"] = 6, ["param1"] = 110, ["z"] = 4, ["name"] = "default:mese"}, {["x"] = 15, ["y"] = 6, ["param1"] = 110, ["z"] = 5, ["name"] = "default:mese"}, {["x"] = 15, ["y"] = 6, ["param1"] = 126, ["z"] = 6, ["name"] = "default:mese"}, {["x"] = 15, ["y"] = 6, ["param1"] = 142, ["z"] = 7, ["name"] = "default:mese"}, {["x"] = 15, ["y"] = 6, ["param1"] = 95, ["z"] = 8, ["name"] = "default:diamondblock"}, {["x"] = 15, ["y"] = 6, ["param1"] = 111, ["z"] = 9, ["name"] = "default:desert_cobble"}, {["x"] = 15, ["y"] = 7, ["param1"] = 95, ["z"] = 0, ["name"] = "default:obsidian"}, {["x"] = 15, ["y"] = 7, ["param1"] = 142, ["z"] = 1, ["name"] = "default:mese"}, {["x"] = 15, ["y"] = 7, ["param1"] = 126, ["z"] = 2, ["name"] = "default:mese"}, {["x"] = 15, ["y"] = 7, ["param1"] = 110, ["z"] = 3, ["name"] = "default:mese"}, {["x"] = 15, ["y"] = 7, ["param1"] = 94, ["z"] = 4, ["name"] = "default:mese"}, {["x"] = 15, ["y"] = 7, ["param1"] = 94, ["z"] = 5, ["name"] = "default:mese"}, {["x"] = 15, ["y"] = 7, ["param1"] = 110, ["z"] = 6, ["name"] = "default:mese"}, {["x"] = 15, ["y"] = 7, ["param1"] = 126, ["z"] = 7, ["name"] = "default:mese"}, {["x"] = 15, ["y"] = 7, ["param1"] = 142, ["z"] = 8, ["name"] = "default:mese"}, {["x"] = 15, ["y"] = 7, ["param1"] = 95, ["z"] = 9, ["name"] = "default:obsidian"}, {["x"] = 15, ["y"] = 8, ["param1"] = 79, ["z"] = 0, ["name"] = "default:desert_cobble"}, {["x"] = 15, ["y"] = 8, ["param1"] = 63, ["z"] = 1, ["name"] = "default:desert_cobble"}, {["x"] = 15, ["y"] = 8, ["param1"] = 79, ["z"] = 2, ["name"] = "default:desert_cobble"}, {["x"] = 15, ["y"] = 8, ["param1"] = 63, ["z"] = 3, ["name"] = "technic:marble"}, {["x"] = 15, ["y"] = 8, ["param1"] = 78, ["z"] = 4, ["name"] = "default:mese"}, {["x"] = 15, ["y"] = 8, ["param1"] = 78, ["z"] = 5, ["name"] = "default:mese"}, {["x"] = 15, ["y"] = 8, ["param1"] = 63, ["z"] = 6, ["name"] = "technic:marble"}, {["x"] = 15, ["y"] = 8, ["param1"] = 79, ["z"] = 7, ["name"] = "default:desert_cobble"}, {["x"] = 15, ["y"] = 8, ["param1"] = 63, ["z"] = 8, ["name"] = "default:desert_cobble"}, {["x"] = 15, ["y"] = 8, ["param1"] = 79, ["z"] = 9, ["name"] = "default:desert_cobble"}, {["x"] = 15, ["y"] = 9, ["param1"] = 63, ["z"] = 0, ["name"] = "technic:marble"}, {["x"] = 15, ["y"] = 9, ["param1"] = 78, ["z"] = 1, ["name"] = "default:mese"}, {["x"] = 15, ["y"] = 9, ["param1"] = 63, ["z"] = 2, ["name"] = "default:sandstonebrick"}, {["x"] = 15, ["y"] = 9, ["param1"] = 62, ["z"] = 3, ["name"] = "default:mese"}, {["x"] = 15, ["y"] = 9, ["param1"] = 63, ["z"] = 4, ["name"] = "default:obsidian"}, {["x"] = 15, ["y"] = 9, ["param1"] = 63, ["z"] = 5, ["name"] = "default:obsidian"}, {["x"] = 15, ["y"] = 9, ["param1"] = 62, ["z"] = 6, ["name"] = "default:mese"}, {["x"] = 15, ["y"] = 9, ["param1"] = 63, ["z"] = 7, ["name"] = "default:sandstonebrick"}, {["x"] = 15, ["y"] = 9, ["param1"] = 78, ["z"] = 8, ["name"] = "default:mese"}, {["x"] = 15, ["y"] = 9, ["param1"] = 63, ["z"] = 9, ["name"] = "technic:marble"}, {["x"] = 15, ["meta"] = {["fields"] = {["owner"] = "n", ["infotext"] = "Itemwise Filter-Injector", ["slotseq_index"] = "1", ["formspec"] = "size[8,8.5]item_image[0,0;1,1;pipeworks:filter]label[1,0;Itemwise Filter-Injector]label[0,1;Prefer item types:]list[context;main;0,1.5;8,2;]button[0,3.5;4,1;fs_helpers_cycling:1:slotseq_mode;Sequence slots by Priority]list[current_player;main;0,4.5;8,4;]listring[]"}, ["inventory"] = {["main"] = {"", "", "", "", "", "", "", "", "", "", "", "", "", "", "", ""}}}, ["param2"] = 3, ["y"] = 10, ["param1"] = 47, ["z"] = 0, ["name"] = "pipeworks:filter"}, {["x"] = 15, ["y"] = 10, ["param1"] = 47, ["z"] = 1, ["name"] = "default:brick"}, {["x"] = 15, ["y"] = 10, ["param1"] = 47, ["z"] = 2, ["name"] = "default:brick"}, {["x"] = 15, ["y"] = 10, ["param1"] = 47, ["z"] = 3, ["name"] = "default:brick"}, {["x"] = 15, ["y"] = 10, ["param1"] = 47, ["z"] = 4, ["name"] = "default:brick"}, {["x"] = 15, ["y"] = 10, ["param1"] = 47, ["z"] = 5, ["name"] = "default:brick"}, {["x"] = 15, ["y"] = 10, ["param1"] = 47, ["z"] = 6, ["name"] = "default:brick"}, {["x"] = 15, ["y"] = 10, ["param1"] = 47, ["z"] = 7, ["name"] = "default:brick"}, {["x"] = 15, ["y"] = 10, ["param1"] = 47, ["z"] = 8, ["name"] = "default:brick"}, {["x"] = 15, ["meta"] = {["fields"] = {["owner"] = "n", ["infotext"] = "Itemwise Filter-Injector", ["slotseq_index"] = "1", ["formspec"] = "size[8,8.5]item_image[0,0;1,1;pipeworks:filter]label[1,0;Itemwise Filter-Injector]label[0,1;Prefer item types:]list[context;main;0,1.5;8,2;]button[0,3.5;4,1;fs_helpers_cycling:1:slotseq_mode;Sequence slots by Priority]list[current_player;main;0,4.5;8,4;]listring[]"}, ["inventory"] = {["main"] = {"", "", "", "", "", "", "", "", "", "", "", "", "", "", "", ""}}}, ["param2"] = 3, ["y"] = 10, ["param1"] = 47, ["z"] = 9, ["name"] = "pipeworks:filter"}, {["x"] = 15, ["param2"] = 2, ["y"] = 11, ["param1"] = 31, ["z"] = 0, ["name"] = "bones:bones"}, {["x"] = 15, ["param2"] = 2, ["y"] = 11, ["param1"] = 15, ["z"] = 1, ["name"] = "bones:bones"}, {["x"] = 15, ["param2"] = 2, ["y"] = 11, ["param1"] = 31, ["z"] = 2, ["name"] = "bones:bones"}, {["x"] = 15, ["param2"] = 2, ["y"] = 11, ["param1"] = 15, ["z"] = 3, ["name"] = "bones:bones"}, {["x"] = 15, ["param2"] = 3, ["y"] = 11, ["param1"] = 31, ["z"] = 4, ["name"] = "bones:bones"}, {["x"] = 15, ["param2"] = 3, ["y"] = 11, ["param1"] = 31, ["z"] = 5, ["name"] = "bones:bones"}, {["x"] = 15, ["y"] = 11, ["param1"] = 15, ["z"] = 6, ["name"] = "bones:bones"}, {["x"] = 15, ["y"] = 11, ["param1"] = 31, ["z"] = 7, ["name"] = "bones:bones"}, {["x"] = 15, ["y"] = 11, ["param1"] = 15, ["z"] = 8, ["name"] = "bones:bones"}, {["x"] = 15, ["y"] = 11, ["param1"] = 31, ["z"] = 9, ["name"] = "bones:bones"}, {["x"] = 15, ["param2"] = 2, ["y"] = 12, ["param1"] = 15, ["z"] = 0, ["name"] = "bones:bones"}, {["x"] = 15, ["param2"] = 2, ["y"] = 12, ["param1"] = 15, ["z"] = 1, ["name"] = "bones:bones"}, {["x"] = 15, ["param2"] = 2, ["y"] = 12, ["param1"] = 15, ["z"] = 2, ["name"] = "bones:bones"}, {["x"] = 15, ["param2"] = 2, ["y"] = 12, ["param1"] = 15, ["z"] = 3, ["name"] = "bones:bones"}, {["x"] = 15, ["y"] = 12, ["z"] = 4, ["name"] = "birthstones:alexandriteblock"}, {["x"] = 15, ["y"] = 12, ["param1"] = 63, ["z"] = 5, ["name"] = "birthstones:alexandriteblock"}, {["x"] = 15, ["y"] = 12, ["param1"] = 15, ["z"] = 6, ["name"] = "bones:bones"}, {["x"] = 15, ["y"] = 12, ["param1"] = 15, ["z"] = 7, ["name"] = "bones:bones"}, {["x"] = 15, ["y"] = 12, ["param1"] = 15, ["z"] = 8, ["name"] = "bones:bones"}, {["x"] = 15, ["y"] = 12, ["param1"] = 15, ["z"] = 9, ["name"] = "bones:bones"}, {["x"] = 15, ["param2"] = 2, ["y"] = 13, ["param1"] = 15, ["z"] = 0, ["name"] = "bones:bones"}, {["x"] = 15, ["param2"] = 2, ["y"] = 13, ["param1"] = 15, ["z"] = 1, ["name"] = "bones:bones"}, {["x"] = 15, ["param2"] = 2, ["y"] = 13, ["param1"] = 31, ["z"] = 2, ["name"] = "bones:bones"}, {["x"] = 15, ["param2"] = 2, ["y"] = 13, ["param1"] = 47, ["z"] = 3, ["name"] = "bones:bones"}, {["x"] = 15, ["param2"] = 2, ["y"] = 13, ["param1"] = 63, ["z"] = 4, ["name"] = "bones:bones"}, {["x"] = 15, ["y"] = 13, ["param1"] = 15, ["z"] = 5, ["name"] = "bones:bones"}, {["x"] = 15, ["y"] = 13, ["param1"] = 15, ["z"] = 6, ["name"] = "bones:bones"}, {["x"] = 15, ["y"] = 13, ["param1"] = 15, ["z"] = 7, ["name"] = "bones:bones"}, {["x"] = 15, ["y"] = 13, ["param1"] = 15, ["z"] = 8, ["name"] = "bones:bones"}, {["x"] = 15, ["y"] = 13, ["param1"] = 15, ["z"] = 9, ["name"] = "bones:bones"}, {["x"] = 15, ["param2"] = 1, ["y"] = 14, ["param1"] = 207, ["z"] = 0, ["name"] = "default:torch"}, {["x"] = 15, ["param2"] = 1, ["y"] = 14, ["param1"] = 207, ["z"] = 9, ["name"] = "default:torch"}}
