5:return {{["x"] = 0, ["y"] = 0, ["param1"] = 158, ["z"] = 0, ["name"] = "default:glass"}, {["x"] = 0, ["y"] = 0, ["param1"] = 173, ["z"] = 1, ["name"] = "default:glass"}, {["x"] = 0, ["y"] = 0, ["param1"] = 157, ["z"] = 2, ["name"] = "default:glass"}, {["x"] = 0, ["param2"] = 3, ["y"] = 0, ["param1"] = 141, ["z"] = 3, ["name"] = "default:glass"}, {["x"] = 0, ["param2"] = 12, ["y"] = 0, ["param1"] = 140, ["z"] = 4, ["name"] = "default:glass"}, {["x"] = 0, ["param2"] = 1, ["y"] = 0, ["param1"] = 156, ["z"] = 5, ["name"] = "default:glass"}, {["x"] = 0, ["param2"] = 2, ["y"] = 0, ["param1"] = 157, ["z"] = 6, ["name"] = "default:glass"}, {["x"] = 0, ["param2"] = 3, ["y"] = 0, ["param1"] = 173, ["z"] = 7, ["name"] = "default:glass"}, {["x"] = 0, ["param2"] = 4, ["y"] = 0, ["param1"] = 173, ["z"] = 8, ["name"] = "default:glass"}, {["x"] = 0, ["param2"] = 4, ["y"] = 0, ["param1"] = 173, ["z"] = 9, ["name"] = "default:glass"}, {["x"] = 0, ["param2"] = 4, ["y"] = 0, ["param1"] = 173, ["z"] = 10, ["name"] = "default:glass"}, {["x"] = 0, ["param2"] = 4, ["y"] = 0, ["param1"] = 173, ["z"] = 11, ["name"] = "default:glass"}, {["x"] = 0, ["y"] = 0, ["param1"] = 173, ["z"] = 12, ["name"] = "default:glass"}, {["x"] = 0, ["param2"] = 4, ["y"] = 0, ["param1"] = 173, ["z"] = 13, ["name"] = "default:glass"}, {["x"] = 0, ["param2"] = 3, ["y"] = 0, ["param1"] = 173, ["z"] = 14, ["name"] = "default:glass"}, {["x"] = 0, ["param2"] = 4, ["y"] = 0, ["param1"] = 173, ["z"] = 15, ["name"] = "default:glass"}, {["x"] = 0, ["param2"] = 4, ["y"] = 0, ["param1"] = 173, ["z"] = 16, ["name"] = "default:glass"}, {["x"] = 0, ["param2"] = 4, ["y"] = 0, ["param1"] = 173, ["z"] = 17, ["name"] = "default:glass"}, {["x"] = 0, ["param2"] = 4, ["y"] = 0, ["param1"] = 173, ["z"] = 18, ["name"] = "default:glass"}, {["x"] = 0, ["param2"] = 3, ["y"] = 0, ["param1"] = 173, ["z"] = 19, ["name"] = "default:glass"}, {["x"] = 0, ["param2"] = 4, ["y"] = 0, ["param1"] = 172, ["z"] = 20, ["name"] = "default:glass"}, {["x"] = 0, ["param2"] = 4, ["y"] = 0, ["param1"] = 172, ["z"] = 21, ["name"] = "default:glass"}, {["x"] = 0, ["param2"] = 4, ["y"] = 0, ["param1"] = 173, ["z"] = 22, ["name"] = "default:glass"}, {["x"] = 0, ["param2"] = 3, ["y"] = 0, ["param1"] = 157, ["z"] = 23, ["name"] = "default:glass"}, {["x"] = 0, ["y"] = 0, ["param1"] = 141, ["z"] = 24, ["name"] = "default:glass"}, {["x"] = 0, ["y"] = 0, ["param1"] = 125, ["z"] = 25, ["name"] = "default:glass"}, {["x"] = 0, ["y"] = 0, ["param1"] = 109, ["z"] = 26, ["name"] = "default:glass"}, {["x"] = 0, ["y"] = 0, ["param1"] = 92, ["z"] = 27, ["name"] = "default:glass"}, {["x"] = 0, ["y"] = 0, ["param1"] = 77, ["z"] = 28, ["name"] = "default:glass"}, {["x"] = 0, ["y"] = 0, ["param1"] = 62, ["z"] = 29, ["name"] = "default:glass"}, {["x"] = 0, ["y"] = 1, ["param1"] = 174, ["z"] = 0, ["name"] = "default:glass"}, {["x"] = 0, ["y"] = 1, ["param1"] = 189, ["z"] = 1, ["name"] = "default:glass"}, {["x"] = 0, ["y"] = 1, ["param1"] = 173, ["z"] = 2, ["name"] = "default:glass"}, {["x"] = 0, ["y"] = 1, ["param1"] = 157, ["z"] = 3, ["name"] = "default:glass"}, {["x"] = 0, ["y"] = 1, ["param1"] = 156, ["z"] = 4, ["name"] = "default:glass"}, {["x"] = 0, ["y"] = 1, ["param1"] = 172, ["z"] = 5, ["name"] = "default:glass"}, {["x"] = 0, ["y"] = 1, ["param1"] = 173, ["z"] = 6, ["name"] = "default:glass"}, {["x"] = 0, ["y"] = 1, ["param1"] = 189, ["z"] = 7, ["name"] = "default:glass"}, {["x"] = 0, ["y"] = 1, ["param1"] = 189, ["z"] = 8, ["name"] = "default:glass"}, {["x"] = 0, ["y"] = 1, ["param1"] = 189, ["z"] = 9, ["name"] = "default:glass"}, {["x"] = 0, ["y"] = 1, ["param1"] = 189, ["z"] = 10, ["name"] = "default:glass"}, {["x"] = 0, ["y"] = 1, ["param1"] = 189, ["z"] = 11, ["name"] = "default:glass"}, {["x"] = 0, ["y"] = 1, ["param1"] = 189, ["z"] = 12, ["name"] = "default:glass"}, {["x"] = 0, ["y"] = 1, ["param1"] = 189, ["z"] = 13, ["name"] = "default:glass"}, {["x"] = 0, ["y"] = 1, ["param1"] = 189, ["z"] = 14, ["name"] = "default:glass"}, {["x"] = 0, ["y"] = 1, ["param1"] = 189, ["z"] = 15, ["name"] = "default:glass"}, {["x"] = 0, ["y"] = 1, ["param1"] = 189, ["z"] = 16, ["name"] = "default:glass"}, {["x"] = 0, ["y"] = 1, ["param1"] = 189, ["z"] = 17, ["name"] = "default:glass"}, {["x"] = 0, ["y"] = 1, ["param1"] = 189, ["z"] = 18, ["name"] = "default:glass"}, {["x"] = 0, ["y"] = 1, ["param1"] = 189, ["z"] = 19, ["name"] = "default:glass"}, {["x"] = 0, ["y"] = 1, ["param1"] = 188, ["z"] = 20, ["name"] = "default:glass"}, {["x"] = 0, ["y"] = 1, ["param1"] = 188, ["z"] = 21, ["name"] = "default:glass"}, {["x"] = 0, ["y"] = 1, ["param1"] = 189, ["z"] = 22, ["name"] = "default:glass"}, {["x"] = 0, ["y"] = 1, ["param1"] = 173, ["z"] = 23, ["name"] = "default:glass"}, {["x"] = 0, ["y"] = 1, ["param1"] = 157, ["z"] = 24, ["name"] = "default:glass"}, {["x"] = 0, ["y"] = 1, ["param1"] = 141, ["z"] = 25, ["name"] = "default:glass"}, {["x"] = 0, ["y"] = 1, ["param1"] = 125, ["z"] = 26, ["name"] = "default:glass"}, {["x"] = 0, ["y"] = 1, ["param1"] = 108, ["z"] = 27, ["name"] = "default:glass"}, {["x"] = 0, ["y"] = 1, ["param1"] = 93, ["z"] = 28, ["name"] = "default:glass"}, {["x"] = 0, ["y"] = 1, ["param1"] = 78, ["z"] = 29, ["name"] = "default:glass"}, {["x"] = 0, ["y"] = 2, ["param1"] = 190, ["z"] = 0, ["name"] = "default:glass"}, {["x"] = 0, ["y"] = 2, ["param1"] = 205, ["z"] = 1, ["name"] = "default:glass"}, {["x"] = 0, ["y"] = 2, ["param1"] = 189, ["z"] = 2, ["name"] = "default:glass"}, {["x"] = 0, ["y"] = 2, ["param1"] = 156, ["z"] = 4, ["name"] = "default:glass"}, {["x"] = 0, ["y"] = 2, ["param1"] = 172, ["z"] = 5, ["name"] = "default:glass"}, {["x"] = 0, ["y"] = 2, ["param1"] = 189, ["z"] = 6, ["name"] = "default:glass"}, {["x"] = 0, ["y"] = 2, ["param1"] = 205, ["z"] = 7, ["name"] = "default:glass"}, {["x"] = 0, ["y"] = 2, ["param1"] = 205, ["z"] = 8, ["name"] = "default:glass"}, {["x"] = 0, ["y"] = 2, ["param1"] = 205, ["z"] = 9, ["name"] = "default:glass"}, {["x"] = 0, ["y"] = 2, ["param1"] = 205, ["z"] = 10, ["name"] = "default:glass"}, {["x"] = 0, ["y"] = 2, ["param1"] = 205, ["z"] = 11, ["name"] = "default:glass"}, {["x"] = 0, ["y"] = 2, ["param1"] = 205, ["z"] = 12, ["name"] = "default:glass"}, {["x"] = 0, ["y"] = 2, ["param1"] = 205, ["z"] = 13, ["name"] = "default:glass"}, {["x"] = 0, ["y"] = 2, ["param1"] = 205, ["z"] = 14, ["name"] = "default:glass"}, {["x"] = 0, ["y"] = 2, ["param1"] = 205, ["z"] = 15, ["name"] = "default:glass"}, {["x"] = 0, ["y"] = 2, ["param1"] = 205, ["z"] = 16, ["name"] = "default:glass"}, {["x"] = 0, ["y"] = 2, ["param1"] = 205, ["z"] = 17, ["name"] = "default:glass"}, {["x"] = 0, ["y"] = 2, ["param1"] = 205, ["z"] = 18, ["name"] = "default:glass"}, {["x"] = 0, ["y"] = 2, ["param1"] = 205, ["z"] = 19, ["name"] = "default:glass"}, {["x"] = 0, ["y"] = 2, ["param1"] = 204, ["z"] = 20, ["name"] = "default:glass"}, {["x"] = 0, ["y"] = 2, ["param1"] = 204, ["z"] = 21, ["name"] = "default:glass"}, {["x"] = 0, ["y"] = 2, ["param1"] = 205, ["z"] = 22, ["name"] = "default:glass"}, {["x"] = 0, ["y"] = 2, ["param1"] = 189, ["z"] = 23, ["name"] = "default:glass"}, {["x"] = 0, ["y"] = 2, ["param1"] = 173, ["z"] = 24, ["name"] = "default:glass"}, {["x"] = 0, ["y"] = 2, ["param1"] = 157, ["z"] = 25, ["name"] = "default:glass"}, {["x"] = 0, ["y"] = 2, ["param1"] = 141, ["z"] = 26, ["name"] = "default:glass"}, {["x"] = 0, ["y"] = 2, ["param1"] = 124, ["z"] = 27, ["name"] = "default:glass"}, {["x"] = 0, ["y"] = 2, ["param1"] = 109, ["z"] = 28, ["name"] = "default:glass"}, {["x"] = 0, ["y"] = 2, ["param1"] = 94, ["z"] = 29, ["name"] = "default:glass"}, {["x"] = 0, ["y"] = 3, ["param1"] = 174, ["z"] = 0, ["name"] = "default:glass"}, {["x"] = 0, ["y"] = 3, ["param1"] = 189, ["z"] = 1, ["name"] = "default:glass"}, {["x"] = 0, ["y"] = 3, ["param1"] = 173, ["z"] = 2, ["name"] = "default:glass"}, {["x"] = 0, ["y"] = 3, ["param1"] = 157, ["z"] = 3, ["name"] = "default:glass"}, {["x"] = 0, ["y"] = 3, ["param1"] = 156, ["z"] = 4, ["name"] = "default:glass"}, {["x"] = 0, ["y"] = 3, ["param1"] = 172, ["z"] = 5, ["name"] = "default:glass"}, {["x"] = 0, ["y"] = 3, ["param1"] = 189, ["z"] = 6, ["name"] = "default:glass"}, {["x"] = 0, ["y"] = 3, ["param1"] = 205, ["z"] = 7, ["name"] = "default:glass"}, {["x"] = 0, ["y"] = 3, ["param1"] = 189, ["z"] = 8, ["name"] = "default:glass"}, {["x"] = 0, ["y"] = 3, ["param1"] = 189, ["z"] = 9, ["name"] = "default:glass"}, {["x"] = 0, ["y"] = 3, ["param1"] = 189, ["z"] = 10, ["name"] = "default:glass"}, {["x"] = 0, ["y"] = 3, ["param1"] = 189, ["z"] = 11, ["name"] = "default:glass"}, {["x"] = 0, ["y"] = 3, ["param1"] = 189, ["z"] = 12, ["name"] = "default:glass"}, {["x"] = 0, ["y"] = 3, ["param1"] = 189, ["z"] = 13, ["name"] = "default:glass"}, {["x"] = 0, ["y"] = 3, ["param1"] = 189, ["z"] = 14, ["name"] = "default:glass"}, {["x"] = 0, ["y"] = 3, ["param1"] = 189, ["z"] = 15, ["name"] = "default:glass"}, {["x"] = 0, ["y"] = 3, ["param1"] = 189, ["z"] = 16, ["name"] = "default:glass"}, {["x"] = 0, ["y"] = 3, ["param1"] = 189, ["z"] = 17, ["name"] = "default:glass"}, {["x"] = 0, ["y"] = 3, ["param1"] = 189, ["z"] = 18, ["name"] = "default:glass"}, {["x"] = 0, ["y"] = 3, ["param1"] = 189, ["z"] = 19, ["name"] = "default:glass"}, {["x"] = 0, ["y"] = 3, ["param1"] = 188, ["z"] = 20, ["name"] = "default:glass"}, {["x"] = 0, ["y"] = 3, ["param1"] = 188, ["z"] = 21, ["name"] = "default:glass"}, {["x"] = 0, ["y"] = 3, ["param1"] = 189, ["z"] = 22, ["name"] = "default:glass"}, {["x"] = 0, ["y"] = 3, ["param1"] = 173, ["z"] = 23, ["name"] = "default:glass"}, {["x"] = 0, ["y"] = 3, ["param1"] = 157, ["z"] = 24, ["name"] = "default:glass"}, {["x"] = 0, ["y"] = 3, ["param1"] = 141, ["z"] = 25, ["name"] = "default:glass"}, {["x"] = 0, ["y"] = 3, ["param1"] = 125, ["z"] = 26, ["name"] = "default:glass"}, {["x"] = 0, ["y"] = 3, ["param1"] = 108, ["z"] = 27, ["name"] = "default:glass"}, {["x"] = 0, ["y"] = 3, ["param1"] = 93, ["z"] = 28, ["name"] = "default:glass"}, {["x"] = 0, ["y"] = 3, ["param1"] = 110, ["z"] = 29, ["name"] = "default:glass"}, {["x"] = 0, ["y"] = 4, ["param1"] = 158, ["z"] = 0, ["name"] = "default:glass"}, {["x"] = 0, ["y"] = 4, ["param1"] = 173, ["z"] = 1, ["name"] = "default:glass"}, {["x"] = 0, ["y"] = 4, ["param1"] = 157, ["z"] = 2, ["name"] = "default:glass"}, {["x"] = 0, ["y"] = 4, ["param1"] = 141, ["z"] = 3, ["name"] = "default:glass"}, {["x"] = 0, ["y"] = 4, ["param1"] = 140, ["z"] = 4, ["name"] = "default:glass"}, {["x"] = 0, ["y"] = 4, ["param1"] = 156, ["z"] = 5, ["name"] = "default:glass"}, {["x"] = 0, ["y"] = 4, ["param1"] = 173, ["z"] = 6, ["name"] = "default:glass"}, {["x"] = 0, ["y"] = 4, ["param1"] = 189, ["z"] = 7, ["name"] = "default:glass"}, {["x"] = 0, ["y"] = 4, ["param1"] = 173, ["z"] = 8, ["name"] = "default:glass"}, {["x"] = 0, ["y"] = 4, ["param1"] = 173, ["z"] = 9, ["name"] = "default:glass"}, {["x"] = 0, ["y"] = 4, ["param1"] = 173, ["z"] = 10, ["name"] = "default:glass"}, {["x"] = 0, ["y"] = 4, ["param1"] = 173, ["z"] = 11, ["name"] = "default:glass"}, {["x"] = 0, ["y"] = 4, ["param1"] = 173, ["z"] = 12, ["name"] = "default:glass"}, {["x"] = 0, ["y"] = 4, ["param1"] = 173, ["z"] = 13, ["name"] = "default:glass"}, {["x"] = 0, ["y"] = 4, ["param1"] = 173, ["z"] = 14, ["name"] = "default:glass"}, {["x"] = 0, ["y"] = 4, ["param1"] = 173, ["z"] = 15, ["name"] = "default:glass"}, {["x"] = 0, ["y"] = 4, ["param1"] = 173, ["z"] = 16, ["name"] = "default:glass"}, {["x"] = 0, ["y"] = 4, ["param1"] = 173, ["z"] = 17, ["name"] = "default:glass"}, {["x"] = 0, ["y"] = 4, ["param1"] = 173, ["z"] = 18, ["name"] = "default:glass"}, {["x"] = 0, ["y"] = 4, ["param1"] = 173, ["z"] = 19, ["name"] = "default:glass"}, {["x"] = 0, ["y"] = 4, ["param1"] = 172, ["z"] = 20, ["name"] = "default:glass"}, {["x"] = 0, ["y"] = 4, ["param1"] = 172, ["z"] = 21, ["name"] = "default:glass"}, {["x"] = 0, ["y"] = 4, ["param1"] = 173, ["z"] = 22, ["name"] = "default:glass"}, {["x"] = 0, ["y"] = 4, ["param1"] = 157, ["z"] = 23, ["name"] = "default:glass"}, {["x"] = 0, ["y"] = 4, ["param1"] = 141, ["z"] = 24, ["name"] = "default:glass"}, {["x"] = 0, ["y"] = 4, ["param1"] = 125, ["z"] = 25, ["name"] = "default:glass"}, {["x"] = 0, ["y"] = 4, ["param1"] = 109, ["z"] = 26, ["name"] = "default:glass"}, {["x"] = 0, ["y"] = 4, ["param1"] = 92, ["z"] = 27, ["name"] = "default:glass"}, {["x"] = 0, ["y"] = 4, ["param1"] = 109, ["z"] = 28, ["name"] = "default:glass"}, {["x"] = 0, ["y"] = 4, ["param1"] = 126, ["z"] = 29, ["name"] = "default:glass"}, {["x"] = 0, ["y"] = 5, ["param1"] = 143, ["z"] = 0, ["name"] = "default:wood"}, {["x"] = 0, ["y"] = 5, ["param1"] = 159, ["z"] = 1, ["name"] = "default:wood"}, {["x"] = 0, ["y"] = 5, ["param1"] = 143, ["z"] = 2, ["name"] = "default:wood"}, {["x"] = 0, ["y"] = 5, ["param1"] = 127, ["z"] = 3, ["name"] = "default:wood"}, {["x"] = 0, ["y"] = 5, ["param1"] = 127, ["z"] = 4, ["name"] = "default:wood"}, {["x"] = 0, ["y"] = 5, ["param1"] = 143, ["z"] = 5, ["name"] = "default:wood"}, {["x"] = 0, ["y"] = 5, ["param1"] = 159, ["z"] = 6, ["name"] = "default:wood"}, {["x"] = 0, ["y"] = 5, ["param1"] = 175, ["z"] = 7, ["name"] = "default:wood"}, {["x"] = 0, ["y"] = 5, ["param1"] = 159, ["z"] = 8, ["name"] = "default:wood"}, {["x"] = 0, ["y"] = 5, ["param1"] = 159, ["z"] = 9, ["name"] = "default:wood"}, {["x"] = 0, ["y"] = 5, ["param1"] = 159, ["z"] = 10, ["name"] = "default:wood"}, {["x"] = 0, ["y"] = 5, ["param1"] = 159, ["z"] = 11, ["name"] = "default:wood"}, {["x"] = 0, ["y"] = 5, ["param1"] = 159, ["z"] = 12, ["name"] = "default:wood"}, {["x"] = 0, ["y"] = 5, ["param1"] = 159, ["z"] = 13, ["name"] = "default:wood"}, {["x"] = 0, ["y"] = 5, ["param1"] = 159, ["z"] = 14, ["name"] = "default:wood"}, {["x"] = 0, ["y"] = 5, ["param1"] = 159, ["z"] = 15, ["name"] = "default:wood"}, {["x"] = 0, ["y"] = 5, ["param1"] = 159, ["z"] = 16, ["name"] = "default:wood"}, {["x"] = 0, ["y"] = 5, ["param1"] = 159, ["z"] = 17, ["name"] = "default:wood"}, {["x"] = 0, ["y"] = 5, ["param1"] = 159, ["z"] = 18, ["name"] = "default:wood"}, {["x"] = 0, ["y"] = 5, ["param1"] = 159, ["z"] = 19, ["name"] = "default:wood"}, {["x"] = 0, ["y"] = 5, ["param1"] = 159, ["z"] = 20, ["name"] = "default:wood"}, {["x"] = 0, ["y"] = 5, ["param1"] = 159, ["z"] = 21, ["name"] = "default:wood"}, {["x"] = 0, ["y"] = 5, ["param1"] = 159, ["z"] = 22, ["name"] = "default:wood"}, {["x"] = 0, ["y"] = 5, ["param1"] = 143, ["z"] = 23, ["name"] = "default:wood"}, {["x"] = 0, ["y"] = 5, ["param1"] = 127, ["z"] = 24, ["name"] = "default:wood"}, {["x"] = 0, ["y"] = 5, ["param1"] = 111, ["z"] = 25, ["name"] = "default:wood"}, {["x"] = 0, ["y"] = 5, ["param1"] = 95, ["z"] = 26, ["name"] = "default:wood"}, {["x"] = 0, ["y"] = 5, ["param1"] = 79, ["z"] = 27, ["name"] = "default:wood"}, {["x"] = 0, ["y"] = 5, ["param1"] = 63, ["z"] = 28, ["name"] = "default:wood"}, {["x"] = 0, ["y"] = 5, ["param1"] = 79, ["z"] = 29, ["name"] = "default:wood"}, {["x"] = 0, ["y"] = 6, ["param1"] = 190, ["z"] = 0, ["name"] = "default:fence_wood"}, {["x"] = 0, ["y"] = 6, ["param1"] = 173, ["z"] = 1, ["name"] = "default:fence_wood"}, {["x"] = 0, ["y"] = 6, ["param1"] = 157, ["z"] = 2, ["name"] = "default:fence_wood"}, {["x"] = 0, ["y"] = 6, ["param1"] = 157, ["z"] = 3, ["name"] = "default:fence_wood"}, {["x"] = 0, ["y"] = 6, ["param1"] = 172, ["z"] = 4, ["name"] = "default:fence_wood"}, {["x"] = 0, ["y"] = 6, ["param1"] = 188, ["z"] = 5, ["name"] = "default:fence_wood"}, {["x"] = 0, ["param2"] = 2, ["y"] = 6, ["param1"] = 173, ["z"] = 6, ["name"] = "default:ladder_steel"}, {["x"] = 0, ["y"] = 6, ["param1"] = 189, ["z"] = 19, ["name"] = "default:fence_wood"}, {["x"] = 0, ["y"] = 6, ["param1"] = 172, ["z"] = 20, ["name"] = "default:fence_wood"}, {["x"] = 0, ["y"] = 6, ["param1"] = 156, ["z"] = 21, ["name"] = "default:fence_wood"}, {["x"] = 0, ["y"] = 6, ["param1"] = 173, ["z"] = 22, ["name"] = "default:fence_wood"}, {["x"] = 0, ["y"] = 6, ["param1"] = 189, ["z"] = 23, ["name"] = "default:fence_wood"}, {["x"] = 0, ["y"] = 6, ["param1"] = 173, ["z"] = 24, ["name"] = "default:fence_wood"}, {["x"] = 0, ["y"] = 6, ["param1"] = 157, ["z"] = 25, ["name"] = "default:fence_wood"}, {["x"] = 0, ["y"] = 6, ["param1"] = 141, ["z"] = 26, ["name"] = "default:fence_wood"}, {["x"] = 0, ["y"] = 6, ["param1"] = 157, ["z"] = 27, ["name"] = "default:fence_wood"}, {["x"] = 0, ["y"] = 6, ["param1"] = 173, ["z"] = 28, ["name"] = "default:fence_wood"}, {["x"] = 0, ["y"] = 6, ["param1"] = 190, ["z"] = 29, ["name"] = "default:fence_wood"}, {["x"] = 0, ["param2"] = 1, ["y"] = 7, ["param1"] = 206, ["z"] = 0, ["name"] = "default:torch"}, {["x"] = 0, ["param2"] = 1, ["y"] = 7, ["param1"] = 204, ["z"] = 5, ["name"] = "default:torch"}, {["x"] = 0, ["param2"] = 2, ["y"] = 7, ["param1"] = 189, ["z"] = 6, ["name"] = "default:ladder_steel"}, {["x"] = 0, ["param2"] = 1, ["y"] = 7, ["param1"] = 205, ["z"] = 19, ["name"] = "default:torch"}, {["x"] = 0, ["param2"] = 1, ["y"] = 7, ["param1"] = 205, ["z"] = 23, ["name"] = "default:torch"}, {["x"] = 0, ["param2"] = 1, ["y"] = 7, ["param1"] = 206, ["z"] = 29, ["name"] = "default:torch"}, {["x"] = 0, ["param2"] = 2, ["y"] = 8, ["param1"] = 173, ["z"] = 6, ["name"] = "default:ladder_steel"}, {["x"] = 0, ["param2"] = 2, ["y"] = 9, ["param1"] = 157, ["z"] = 6, ["name"] = "default:ladder_steel"}, {["x"] = 0, ["param2"] = 2, ["y"] = 10, ["param1"] = 141, ["z"] = 6, ["name"] = "default:ladder_steel"}, {["x"] = 0, ["param2"] = 2, ["y"] = 11, ["param1"] = 125, ["z"] = 6, ["name"] = "default:ladder_steel"}, {["x"] = 0, ["param2"] = 2, ["y"] = 12, ["param1"] = 109, ["z"] = 6, ["name"] = "default:ladder_steel"}, {["x"] = 0, ["param2"] = 2, ["y"] = 12, ["param1"] = 205, ["z"] = 28, ["name"] = "default:torch_wall"}, {["x"] = 0, ["param2"] = 2, ["y"] = 13, ["param1"] = 126, ["z"] = 6, ["name"] = "default:ladder_steel"}, {["x"] = 0, ["param2"] = 2, ["y"] = 14, ["param1"] = 143, ["z"] = 6, ["name"] = "default:ladder_steel"}, {["x"] = 1, ["y"] = 0, ["param1"] = 175, ["z"] = 0, ["name"] = "default:glass"}, {["x"] = 1, ["y"] = 0, ["param1"] = 190, ["z"] = 1, ["name"] = "default:glass"}, {["x"] = 1, ["y"] = 0, ["param1"] = 174, ["z"] = 2, ["name"] = "default:glass"}, {["x"] = 1, ["param2"] = 4, ["y"] = 0, ["param1"] = 158, ["z"] = 3, ["name"] = "default:glass"}, {["x"] = 1, ["param2"] = 5, ["y"] = 0, ["param1"] = 157, ["z"] = 4, ["name"] = "default:glass"}, {["x"] = 1, ["param2"] = 1, ["y"] = 0, ["param1"] = 173, ["z"] = 5, ["name"] = "default:glass"}, {["x"] = 1, ["param2"] = 1, ["y"] = 0, ["param1"] = 174, ["z"] = 6, ["name"] = "default:glass"}, {["x"] = 1, ["param2"] = 4, ["y"] = 0, ["param1"] = 190, ["z"] = 7, ["name"] = "default:glass"}, {["x"] = 1, ["param2"] = 5, ["y"] = 0, ["param1"] = 190, ["z"] = 8, ["name"] = "default:glass"}, {["x"] = 1, ["param2"] = 5, ["y"] = 0, ["param1"] = 190, ["z"] = 9, ["name"] = "default:glass"}, {["x"] = 1, ["param2"] = 5, ["y"] = 0, ["param1"] = 190, ["z"] = 10, ["name"] = "default:glass"}, {["x"] = 1, ["param2"] = 5, ["y"] = 0, ["param1"] = 190, ["z"] = 11, ["name"] = "default:glass"}, {["x"] = 1, ["y"] = 0, ["param1"] = 190, ["z"] = 12, ["name"] = "default:glass"}, {["x"] = 1, ["param2"] = 5, ["y"] = 0, ["param1"] = 190, ["z"] = 13, ["name"] = "default:glass"}, {["x"] = 1, ["param2"] = 4, ["y"] = 0, ["param1"] = 190, ["z"] = 14, ["name"] = "default:glass"}, {["x"] = 1, ["param2"] = 5, ["y"] = 0, ["param1"] = 190, ["z"] = 15, ["name"] = "default:glass"}, {["x"] = 1, ["param2"] = 5, ["y"] = 0, ["param1"] = 190, ["z"] = 16, ["name"] = "default:glass"}, {["x"] = 1, ["param2"] = 5, ["y"] = 0, ["param1"] = 190, ["z"] = 17, ["name"] = "default:glass"}, {["x"] = 1, ["param2"] = 5, ["y"] = 0, ["param1"] = 190, ["z"] = 18, ["name"] = "default:glass"}, {["x"] = 1, ["param2"] = 12, ["y"] = 0, ["param1"] = 190, ["z"] = 19, ["name"] = "default:glass"}, {["x"] = 1, ["param2"] = 5, ["y"] = 0, ["param1"] = 189, ["z"] = 20, ["name"] = "default:glass"}, {["x"] = 1, ["param2"] = 5, ["y"] = 0, ["param1"] = 189, ["z"] = 21, ["name"] = "default:glass"}, {["x"] = 1, ["param2"] = 5, ["y"] = 0, ["param1"] = 190, ["z"] = 22, ["name"] = "default:glass"}, {["x"] = 1, ["param2"] = 4, ["y"] = 0, ["param1"] = 174, ["z"] = 23, ["name"] = "default:glass"}, {["x"] = 1, ["y"] = 0, ["param1"] = 158, ["z"] = 24, ["name"] = "default:glass"}, {["x"] = 1, ["y"] = 0, ["param1"] = 142, ["z"] = 25, ["name"] = "default:glass"}, {["x"] = 1, ["param2"] = 1, ["y"] = 0, ["param1"] = 126, ["z"] = 26, ["name"] = "default:glass"}, {["x"] = 1, ["y"] = 0, ["param1"] = 109, ["z"] = 27, ["name"] = "default:glass"}, {["x"] = 1, ["y"] = 0, ["param1"] = 94, ["z"] = 28, ["name"] = "default:glass"}, {["x"] = 1, ["y"] = 0, ["param1"] = 79, ["z"] = 29, ["name"] = "default:glass"}, {["x"] = 1, ["y"] = 1, ["param1"] = 191, ["z"] = 0, ["name"] = "default:glass"}, {["x"] = 1, ["y"] = 1, ["param1"] = 206, ["z"] = 1, ["name"] = "default:glass"}, {["x"] = 1, ["y"] = 1, ["param1"] = 190, ["z"] = 2, ["name"] = "default:glass"}, {["x"] = 1, ["y"] = 1, ["param1"] = 174, ["z"] = 3, ["name"] = "default:glass"}, {["x"] = 1, ["y"] = 1, ["param1"] = 173, ["z"] = 4, ["name"] = "default:glass"}, {["x"] = 1, ["y"] = 1, ["param1"] = 189, ["z"] = 5, ["name"] = "default:glass"}, {["x"] = 1, ["y"] = 1, ["param1"] = 190, ["z"] = 6, ["name"] = "default:glass"}, {["x"] = 1, ["y"] = 1, ["param1"] = 206, ["z"] = 7, ["name"] = "default:glass"}, {["x"] = 1, ["y"] = 1, ["param1"] = 206, ["z"] = 8, ["name"] = "default:glass"}, {["x"] = 1, ["y"] = 1, ["param1"] = 206, ["z"] = 9, ["name"] = "default:glass"}, {["x"] = 1, ["y"] = 1, ["param1"] = 206, ["z"] = 10, ["name"] = "default:glass"}, {["x"] = 1, ["y"] = 1, ["param1"] = 206, ["z"] = 11, ["name"] = "default:glass"}, {["x"] = 1, ["y"] = 1, ["param1"] = 206, ["z"] = 12, ["name"] = "default:glass"}, {["x"] = 1, ["y"] = 1, ["param1"] = 206, ["z"] = 13, ["name"] = "default:glass"}, {["x"] = 1, ["y"] = 1, ["param1"] = 206, ["z"] = 14, ["name"] = "default:glass"}, {["x"] = 1, ["y"] = 1, ["param1"] = 206, ["z"] = 15, ["name"] = "default:glass"}, {["x"] = 1, ["y"] = 1, ["param1"] = 206, ["z"] = 16, ["name"] = "default:glass"}, {["x"] = 1, ["y"] = 1, ["param1"] = 206, ["z"] = 17, ["name"] = "default:glass"}, {["x"] = 1, ["y"] = 1, ["param1"] = 206, ["z"] = 18, ["name"] = "default:glass"}, {["x"] = 1, ["y"] = 1, ["param1"] = 206, ["z"] = 19, ["name"] = "default:glass"}, {["x"] = 1, ["y"] = 1, ["param1"] = 205, ["z"] = 20, ["name"] = "default:glass"}, {["x"] = 1, ["y"] = 1, ["param1"] = 205, ["z"] = 21, ["name"] = "default:glass"}, {["x"] = 1, ["y"] = 1, ["param1"] = 206, ["z"] = 22, ["name"] = "default:glass"}, {["x"] = 1, ["y"] = 1, ["param1"] = 190, ["z"] = 23, ["name"] = "default:glass"}, {["x"] = 1, ["y"] = 1, ["param1"] = 174, ["z"] = 24, ["name"] = "default:glass"}, {["x"] = 1, ["y"] = 1, ["param1"] = 158, ["z"] = 25, ["name"] = "default:glass"}, {["x"] = 1, ["y"] = 1, ["param1"] = 142, ["z"] = 26, ["name"] = "default:glass"}, {["x"] = 1, ["y"] = 1, ["param1"] = 125, ["z"] = 27, ["name"] = "default:glass"}, {["x"] = 1, ["y"] = 1, ["param1"] = 110, ["z"] = 28, ["name"] = "default:glass"}, {["x"] = 1, ["y"] = 1, ["param1"] = 95, ["z"] = 29, ["name"] = "default:glass"}, {["x"] = 1, ["y"] = 2, ["param1"] = 207, ["z"] = 0, ["name"] = "default:glass"}, {["x"] = 1, ["param2"] = 2, ["y"] = 2, ["param1"] = 222, ["z"] = 1, ["name"] = "default:lava_flowing"}, {["x"] = 1, ["y"] = 2, ["param1"] = 206, ["z"] = 2, ["name"] = "walls:cobble"}, {["x"] = 1, ["y"] = 2, ["param1"] = 173, ["z"] = 4, ["name"] = "walls:cobble"}, {["x"] = 1, ["y"] = 2, ["z"] = 5, ["name"] = "magma_conduits:hot_cobble"}, {["x"] = 1, ["y"] = 2, ["z"] = 6, ["name"] = "magma_conduits:hot_cobble"}, {["x"] = 1, ["y"] = 2, ["param1"] = 222, ["z"] = 7, ["name"] = "default:lava_source"}, {["x"] = 1, ["y"] = 2, ["param1"] = 222, ["z"] = 8, ["name"] = "default:lava_source"}, {["x"] = 1, ["y"] = 2, ["param1"] = 222, ["z"] = 9, ["name"] = "default:lava_source"}, {["x"] = 1, ["y"] = 2, ["param1"] = 222, ["z"] = 10, ["name"] = "default:lava_source"}, {["x"] = 1, ["y"] = 2, ["param1"] = 222, ["z"] = 11, ["name"] = "default:lava_source"}, {["x"] = 1, ["y"] = 2, ["param1"] = 222, ["z"] = 12, ["name"] = "default:lava_source"}, {["x"] = 1, ["y"] = 2, ["param1"] = 222, ["z"] = 13, ["name"] = "default:lava_source"}, {["x"] = 1, ["y"] = 2, ["param1"] = 222, ["z"] = 14, ["name"] = "default:lava_source"}, {["x"] = 1, ["y"] = 2, ["param1"] = 222, ["z"] = 15, ["name"] = "default:lava_source"}, {["x"] = 1, ["y"] = 2, ["param1"] = 222, ["z"] = 16, ["name"] = "default:lava_source"}, {["x"] = 1, ["y"] = 2, ["param1"] = 222, ["z"] = 17, ["name"] = "default:lava_source"}, {["x"] = 1, ["y"] = 2, ["param1"] = 222, ["z"] = 18, ["name"] = "default:lava_source"}, {["x"] = 1, ["y"] = 2, ["param1"] = 222, ["z"] = 19, ["name"] = "default:lava_source"}, {["x"] = 1, ["y"] = 2, ["param1"] = 221, ["z"] = 20, ["name"] = "default:lava_source"}, {["x"] = 1, ["y"] = 2, ["param1"] = 221, ["z"] = 21, ["name"] = "default:lava_source"}, {["x"] = 1, ["y"] = 2, ["param1"] = 222, ["z"] = 22, ["name"] = "default:lava_source"}, {["x"] = 1, ["y"] = 2, ["z"] = 23, ["name"] = "magma_conduits:hot_cobble"}, {["x"] = 1, ["y"] = 2, ["z"] = 24, ["name"] = "default:stone"}, {["x"] = 1, ["y"] = 2, ["z"] = 25, ["name"] = "default:gravel"}, {["x"] = 1, ["y"] = 2, ["z"] = 26, ["name"] = "default:gravel"}, {["x"] = 1, ["y"] = 2, ["z"] = 27, ["name"] = "default:gravel"}, {["x"] = 1, ["y"] = 2, ["z"] = 28, ["name"] = "default:gravel"}, {["x"] = 1, ["y"] = 2, ["param1"] = 111, ["z"] = 29, ["name"] = "default:glass"}, {["x"] = 1, ["y"] = 3, ["param1"] = 191, ["z"] = 0, ["name"] = "default:glass"}, {["x"] = 1, ["y"] = 3, ["param1"] = 190, ["z"] = 2, ["name"] = "walls:cobble"}, {["x"] = 1, ["y"] = 3, ["param1"] = 173, ["z"] = 4, ["name"] = "walls:cobble"}, {["x"] = 1, ["y"] = 3, ["z"] = 5, ["name"] = "technic:marble"}, {["x"] = 1, ["y"] = 3, ["z"] = 6, ["name"] = "technic:marble"}, {["x"] = 1, ["param2"] = 1, ["y"] = 3, ["param1"] = 221, ["z"] = 7, ["name"] = "default:lava_flowing"}, {["x"] = 1, ["y"] = 3, ["z"] = 8, ["name"] = "magma_conduits:hot_cobble"}, {["x"] = 1, ["y"] = 3, ["z"] = 9, ["name"] = "magma_conduits:hot_cobble"}, {["x"] = 1, ["y"] = 3, ["z"] = 10, ["name"] = "magma_conduits:hot_cobble"}, {["x"] = 1, ["y"] = 3, ["z"] = 11, ["name"] = "magma_conduits:hot_cobble"}, {["x"] = 1, ["y"] = 3, ["z"] = 12, ["name"] = "magma_conduits:hot_cobble"}, {["x"] = 1, ["y"] = 3, ["z"] = 13, ["name"] = "magma_conduits:hot_cobble"}, {["x"] = 1, ["y"] = 3, ["z"] = 14, ["name"] = "magma_conduits:hot_cobble"}, {["x"] = 1, ["y"] = 3, ["z"] = 15, ["name"] = "magma_conduits:hot_cobble"}, {["x"] = 1, ["y"] = 3, ["z"] = 16, ["name"] = "magma_conduits:hot_cobble"}, {["x"] = 1, ["y"] = 3, ["z"] = 17, ["name"] = "magma_conduits:hot_cobble"}, {["x"] = 1, ["y"] = 3, ["z"] = 18, ["name"] = "magma_conduits:hot_cobble"}, {["x"] = 1, ["y"] = 3, ["z"] = 19, ["name"] = "magma_conduits:hot_cobble"}, {["x"] = 1, ["y"] = 3, ["z"] = 20, ["name"] = "magma_conduits:hot_cobble"}, {["x"] = 1, ["y"] = 3, ["z"] = 21, ["name"] = "magma_conduits:hot_cobble"}, {["x"] = 1, ["y"] = 3, ["z"] = 22, ["name"] = "magma_conduits:hot_cobble"}, {["x"] = 1, ["y"] = 3, ["z"] = 23, ["name"] = "magma_conduits:hot_cobble"}, {["x"] = 1, ["y"] = 3, ["z"] = 24, ["name"] = "default:stone"}, {["x"] = 1, ["y"] = 3, ["z"] = 25, ["name"] = "default:stone"}, {["x"] = 1, ["y"] = 3, ["z"] = 26, ["name"] = "default:gravel"}, {["x"] = 1, ["y"] = 3, ["z"] = 27, ["name"] = "default:gravel"}, {["x"] = 1, ["y"] = 3, ["z"] = 28, ["name"] = "default:gravel"}, {["x"] = 1, ["y"] = 3, ["param1"] = 127, ["z"] = 29, ["name"] = "default:glass"}, {["x"] = 1, ["y"] = 4, ["param1"] = 190, ["z"] = 1, ["name"] = "walls:cobble"}, {["x"] = 1, ["y"] = 4, ["param1"] = 174, ["z"] = 2, ["name"] = "walls:cobble"}, {["x"] = 1, ["y"] = 4, ["param1"] = 157, ["z"] = 4, ["name"] = "walls:cobble"}, {["x"] = 1, ["y"] = 4, ["z"] = 5, ["name"] = "technic:marble"}, {["x"] = 1, ["y"] = 4, ["z"] = 6, ["name"] = "technic:marble"}, {["x"] = 1, ["y"] = 4, ["z"] = 8, ["name"] = "magma_conduits:hot_cobble"}, {["x"] = 1, ["y"] = 4, ["z"] = 9, ["name"] = "magma_conduits:hot_cobble"}, {["x"] = 1, ["y"] = 4, ["z"] = 10, ["name"] = "magma_conduits:hot_cobble"}, {["x"] = 1, ["y"] = 4, ["z"] = 11, ["name"] = "default:stone"}, {["x"] = 1, ["y"] = 4, ["z"] = 12, ["name"] = "magma_conduits:hot_cobble"}, {["x"] = 1, ["y"] = 4, ["z"] = 13, ["name"] = "magma_conduits:hot_cobble"}, {["x"] = 1, ["y"] = 4, ["z"] = 14, ["name"] = "magma_conduits:hot_cobble"}, {["x"] = 1, ["y"] = 4, ["z"] = 15, ["name"] = "default:stone"}, {["x"] = 1, ["y"] = 4, ["z"] = 16, ["name"] = "magma_conduits:hot_cobble"}, {["x"] = 1, ["y"] = 4, ["z"] = 17, ["name"] = "magma_conduits:hot_cobble"}, {["x"] = 1, ["y"] = 4, ["z"] = 18, ["name"] = "default:stone"}, {["x"] = 1, ["y"] = 4, ["z"] = 19, ["name"] = "magma_conduits:hot_cobble"}, {["x"] = 1, ["y"] = 4, ["z"] = 20, ["name"] = "magma_conduits:hot_cobble"}, {["x"] = 1, ["y"] = 4, ["z"] = 21, ["name"] = "default:stone"}, {["x"] = 1, ["y"] = 4, ["z"] = 22, ["name"] = "technic:marble"}, {["x"] = 1, ["y"] = 4, ["z"] = 23, ["name"] = "technic:marble"}, {["x"] = 1, ["y"] = 4, ["z"] = 24, ["name"] = "technic:marble"}, {["x"] = 1, ["y"] = 4, ["z"] = 25, ["name"] = "technic:marble"}, {["x"] = 1, ["y"] = 4, ["z"] = 26, ["name"] = "technic:marble"}, {["x"] = 1, ["y"] = 4, ["z"] = 27, ["name"] = "technic:marble"}, {["x"] = 1, ["y"] = 4, ["z"] = 28, ["name"] = "default:stone"}, {["x"] = 1, ["y"] = 4, ["param1"] = 143, ["z"] = 29, ["name"] = "default:glass"}, {["x"] = 1, ["y"] = 5, ["z"] = 1, ["name"] = "technic:marble"}, {["x"] = 1, ["y"] = 5, ["param1"] = 157, ["z"] = 2, ["name"] = "walls:cobble"}, {["x"] = 1, ["y"] = 5, ["param1"] = 140, ["z"] = 4, ["name"] = "walls:cobble"}, {["x"] = 1, ["y"] = 5, ["z"] = 5, ["name"] = "technic:marble"}, {["x"] = 1, ["y"] = 5, ["z"] = 6, ["name"] = "technic:marble"}, {["x"] = 1, ["y"] = 5, ["z"] = 7, ["name"] = "default:dirt"}, {["x"] = 1, ["y"] = 5, ["z"] = 8, ["name"] = "default:dirt"}, {["x"] = 1, ["y"] = 5, ["z"] = 9, ["name"] = "default:sand"}, {["x"] = 1, ["y"] = 5, ["z"] = 10, ["name"] = "default:dirt"}, {["x"] = 1, ["y"] = 5, ["z"] = 11, ["name"] = "default:dirt"}, {["x"] = 1, ["y"] = 5, ["z"] = 12, ["name"] = "default:sand"}, {["x"] = 1, ["y"] = 5, ["z"] = 13, ["name"] = "default:sand"}, {["x"] = 1, ["y"] = 5, ["z"] = 14, ["name"] = "default:sand"}, {["x"] = 1, ["y"] = 5, ["z"] = 15, ["name"] = "default:dirt"}, {["x"] = 1, ["y"] = 5, ["z"] = 16, ["name"] = "default:sand"}, {["x"] = 1, ["y"] = 5, ["z"] = 17, ["name"] = "default:dirt"}, {["x"] = 1, ["y"] = 5, ["z"] = 19, ["name"] = "default:stone"}, {["x"] = 1, ["y"] = 5, ["z"] = 20, ["name"] = "default:stone"}, {["x"] = 1, ["y"] = 5, ["z"] = 21, ["name"] = "technic:marble"}, {["x"] = 1, ["y"] = 5, ["z"] = 22, ["name"] = "default:stone"}, {["x"] = 1, ["y"] = 5, ["z"] = 23, ["name"] = "default:stone"}, {["x"] = 1, ["y"] = 5, ["z"] = 24, ["name"] = "default:stone"}, {["x"] = 1, ["y"] = 5, ["z"] = 25, ["name"] = "default:stone"}, {["x"] = 1, ["y"] = 5, ["z"] = 26, ["name"] = "default:stone"}, {["x"] = 1, ["y"] = 5, ["z"] = 27, ["name"] = "default:stone"}, {["x"] = 1, ["y"] = 5, ["z"] = 28, ["name"] = "technic:marble"}, {["x"] = 1, ["y"] = 6, ["z"] = 1, ["name"] = "technic:marble"}, {["x"] = 1, ["y"] = 6, ["param1"] = 142, ["z"] = 2, ["name"] = "walls:cobble"}, {["x"] = 1, ["y"] = 6, ["param1"] = 142, ["z"] = 3, ["name"] = "walls:cobble"}, {["x"] = 1, ["y"] = 6, ["param1"] = 157, ["z"] = 4, ["name"] = "walls:cobble"}, {["x"] = 1, ["y"] = 6, ["z"] = 5, ["name"] = "technic:marble"}, {["x"] = 1, ["y"] = 6, ["z"] = 6, ["name"] = "technic:marble"}, {["x"] = 1, ["y"] = 6, ["z"] = 18, ["name"] = "technic:marble"}, {["x"] = 1, ["y"] = 6, ["z"] = 19, ["name"] = "technic:marble"}, {["x"] = 1, ["y"] = 6, ["z"] = 20, ["name"] = "default:stone"}, {["x"] = 1, ["y"] = 6, ["z"] = 21, ["name"] = "technic:marble"}, {["x"] = 1, ["y"] = 6, ["z"] = 23, ["name"] = "default:stone"}, {["x"] = 1, ["y"] = 6, ["z"] = 24, ["name"] = "default:stone"}, {["x"] = 1, ["y"] = 6, ["z"] = 25, ["name"] = "default:stone"}, {["x"] = 1, ["y"] = 6, ["z"] = 26, ["name"] = "default:stone"}, {["x"] = 1, ["y"] = 6, ["z"] = 28, ["name"] = "technic:marble"}, {["x"] = 1, ["y"] = 7, ["z"] = 1, ["name"] = "default:stone"}, {["x"] = 1, ["y"] = 7, ["z"] = 2, ["name"] = "default:stone"}, {["x"] = 1, ["y"] = 7, ["z"] = 3, ["name"] = "default:stone"}, {["x"] = 1, ["y"] = 7, ["z"] = 4, ["name"] = "default:stone"}, {["x"] = 1, ["y"] = 7, ["z"] = 5, ["name"] = "technic:marble"}, {["x"] = 1, ["y"] = 7, ["z"] = 6, ["name"] = "technic:marble"}, {["x"] = 1, ["y"] = 7, ["z"] = 18, ["name"] = "technic:marble"}, {["x"] = 1, ["y"] = 7, ["z"] = 19, ["name"] = "technic:marble"}, {["x"] = 1, ["y"] = 7, ["z"] = 20, ["name"] = "default:stone"}, {["x"] = 1, ["y"] = 7, ["z"] = 21, ["name"] = "default:stone"}, {["x"] = 1, ["y"] = 7, ["z"] = 22, ["name"] = "technic:marble"}, {["x"] = 1, ["y"] = 7, ["z"] = 23, ["name"] = "technic:marble"}, {["x"] = 1, ["y"] = 7, ["z"] = 24, ["name"] = "technic:marble"}, {["x"] = 1, ["y"] = 7, ["z"] = 25, ["name"] = "technic:marble"}, {["x"] = 1, ["y"] = 7, ["z"] = 26, ["name"] = "technic:marble"}, {["x"] = 1, ["y"] = 7, ["z"] = 27, ["name"] = "technic:marble"}, {["x"] = 1, ["y"] = 7, ["z"] = 28, ["name"] = "default:stone"}, {["x"] = 1, ["y"] = 8, ["z"] = 1, ["name"] = "default:stone_with_gold"}, {["x"] = 1, ["y"] = 8, ["z"] = 2, ["name"] = "default:stone"}, {["x"] = 1, ["y"] = 8, ["z"] = 3, ["name"] = "default:stone"}, {["x"] = 1, ["y"] = 8, ["z"] = 4, ["name"] = "default:stone"}, {["x"] = 1, ["y"] = 8, ["z"] = 5, ["name"] = "default:stone"}, {["x"] = 1, ["y"] = 8, ["z"] = 6, ["name"] = "technic:marble"}, {["x"] = 1, ["y"] = 8, ["z"] = 18, ["name"] = "technic:marble"}, {["x"] = 1, ["y"] = 8, ["z"] = 19, ["name"] = "technic:marble"}, {["x"] = 1, ["y"] = 8, ["z"] = 20, ["name"] = "default:stone"}, {["x"] = 1, ["y"] = 8, ["z"] = 21, ["name"] = "default:stone"}, {["x"] = 1, ["y"] = 8, ["z"] = 22, ["name"] = "default:stone"}, {["x"] = 1, ["y"] = 8, ["z"] = 23, ["name"] = "default:stone"}, {["x"] = 1, ["y"] = 8, ["z"] = 24, ["name"] = "default:stone"}, {["x"] = 1, ["y"] = 8, ["z"] = 25, ["name"] = "default:stone"}, {["x"] = 1, ["y"] = 8, ["z"] = 26, ["name"] = "default:stone"}, {["x"] = 1, ["y"] = 8, ["z"] = 27, ["name"] = "default:stone"}, {["x"] = 1, ["y"] = 8, ["z"] = 28, ["name"] = "default:stone"}, {["x"] = 1, ["y"] = 9, ["z"] = 1, ["name"] = "default:stone"}, {["x"] = 1, ["y"] = 9, ["z"] = 2, ["name"] = "default:stone"}, {["x"] = 1, ["y"] = 9, ["z"] = 3, ["name"] = "default:stone"}, {["x"] = 1, ["y"] = 9, ["z"] = 4, ["name"] = "default:stone"}, {["x"] = 1, ["y"] = 9, ["z"] = 5, ["name"] = "default:stone"}, {["x"] = 1, ["y"] = 9, ["z"] = 6, ["name"] = "technic:marble"}, {["x"] = 1, ["y"] = 9, ["z"] = 7, ["name"] = "technic:marble"}, {["x"] = 1, ["y"] = 9, ["z"] = 8, ["name"] = "technic:marble"}, {["x"] = 1, ["y"] = 9, ["z"] = 9, ["name"] = "technic:marble"}, {["x"] = 1, ["y"] = 9, ["z"] = 10, ["name"] = "technic:marble"}, {["x"] = 1, ["y"] = 9, ["z"] = 11, ["name"] = "technic:marble"}, {["x"] = 1, ["y"] = 9, ["z"] = 12, ["name"] = "technic:marble"}, {["x"] = 1, ["y"] = 9, ["z"] = 13, ["name"] = "technic:marble"}, {["x"] = 1, ["y"] = 9, ["z"] = 14, ["name"] = "technic:marble"}, {["x"] = 1, ["y"] = 9, ["z"] = 15, ["name"] = "technic:marble"}, {["x"] = 1, ["y"] = 9, ["z"] = 16, ["name"] = "technic:marble"}, {["x"] = 1, ["y"] = 9, ["z"] = 17, ["name"] = "technic:marble"}, {["x"] = 1, ["y"] = 9, ["z"] = 18, ["name"] = "default:stone"}, {["x"] = 1, ["y"] = 9, ["z"] = 19, ["name"] = "default:stone"}, {["x"] = 1, ["y"] = 9, ["z"] = 20, ["name"] = "default:stone"}, {["x"] = 1, ["y"] = 9, ["z"] = 21, ["name"] = "default:stone"}, {["x"] = 1, ["y"] = 9, ["z"] = 22, ["name"] = "default:stone"}, {["x"] = 1, ["y"] = 9, ["z"] = 23, ["name"] = "default:stone"}, {["x"] = 1, ["y"] = 9, ["z"] = 24, ["name"] = "default:stone"}, {["x"] = 1, ["y"] = 9, ["z"] = 25, ["name"] = "default:stone"}, {["x"] = 1, ["y"] = 9, ["z"] = 26, ["name"] = "default:stone"}, {["x"] = 1, ["y"] = 9, ["z"] = 27, ["name"] = "default:stone"}, {["x"] = 1, ["y"] = 9, ["z"] = 28, ["name"] = "default:stone"}, {["x"] = 1, ["y"] = 10, ["z"] = 1, ["name"] = "default:stone"}, {["x"] = 1, ["y"] = 10, ["z"] = 2, ["name"] = "default:stone"}, {["x"] = 1, ["y"] = 10, ["z"] = 3, ["name"] = "default:stone"}, {["x"] = 1, ["y"] = 10, ["z"] = 4, ["name"] = "default:stone"}, {["x"] = 1, ["y"] = 10, ["z"] = 5, ["name"] = "default:stone"}, {["x"] = 1, ["y"] = 10, ["z"] = 6, ["name"] = "default:stone"}, {["x"] = 1, ["y"] = 10, ["z"] = 7, ["name"] = "technic:marble"}, {["x"] = 1, ["y"] = 10, ["z"] = 8, ["name"] = "technic:marble"}, {["x"] = 1, ["y"] = 10, ["z"] = 9, ["name"] = "default:stone"}, {["x"] = 1, ["y"] = 10, ["z"] = 10, ["name"] = "default:stone"}, {["x"] = 1, ["y"] = 10, ["z"] = 11, ["name"] = "default:stone_with_tin"}, {["x"] = 1, ["y"] = 10, ["z"] = 12, ["name"] = "default:stone"}, {["x"] = 1, ["y"] = 10, ["z"] = 13, ["name"] = "default:stone"}, {["x"] = 1, ["y"] = 10, ["z"] = 14, ["name"] = "technic:mineral_lead"}, {["x"] = 1, ["y"] = 10, ["z"] = 15, ["name"] = "default:stone"}, {["x"] = 1, ["y"] = 10, ["z"] = 16, ["name"] = "default:stone"}, {["x"] = 1, ["y"] = 10, ["z"] = 17, ["name"] = "default:stone"}, {["x"] = 1, ["y"] = 10, ["z"] = 18, ["name"] = "default:stone"}, {["x"] = 1, ["y"] = 10, ["z"] = 19, ["name"] = "default:stone"}, {["x"] = 1, ["y"] = 10, ["z"] = 20, ["name"] = "default:stone"}, {["x"] = 1, ["y"] = 10, ["z"] = 21, ["name"] = "default:stone"}, {["x"] = 1, ["y"] = 10, ["z"] = 22, ["name"] = "default:stone"}, {["x"] = 1, ["y"] = 10, ["z"] = 23, ["name"] = "default:stone"}, {["x"] = 1, ["y"] = 10, ["z"] = 24, ["name"] = "default:stone"}, {["x"] = 1, ["y"] = 10, ["z"] = 25, ["name"] = "default:stone"}, {["x"] = 1, ["y"] = 10, ["z"] = 26, ["name"] = "default:stone"}, {["x"] = 1, ["y"] = 10, ["z"] = 27, ["name"] = "default:stone"}, {["x"] = 1, ["y"] = 10, ["z"] = 28, ["name"] = "default:stone"}, {["x"] = 1, ["y"] = 11, ["z"] = 1, ["name"] = "default:stone"}, {["x"] = 1, ["y"] = 11, ["z"] = 2, ["name"] = "default:stone"}, {["x"] = 1, ["y"] = 11, ["z"] = 3, ["name"] = "default:stone"}, {["x"] = 1, ["y"] = 11, ["z"] = 4, ["name"] = "default:stone"}, {["x"] = 1, ["y"] = 11, ["z"] = 5, ["name"] = "default:stone"}, {["x"] = 1, ["y"] = 11, ["z"] = 6, ["name"] = "default:stone"}, {["x"] = 1, ["y"] = 11, ["z"] = 7, ["name"] = "default:stone"}, {["x"] = 1, ["y"] = 11, ["z"] = 8, ["name"] = "default:stone"}, {["x"] = 1, ["y"] = 11, ["z"] = 9, ["name"] = "default:stone"}, {["x"] = 1, ["y"] = 11, ["z"] = 10, ["name"] = "default:stone"}, {["x"] = 1, ["y"] = 11, ["z"] = 11, ["name"] = "default:stone"}, {["x"] = 1, ["y"] = 11, ["z"] = 12, ["name"] = "default:stone_with_coal"}, {["x"] = 1, ["y"] = 11, ["z"] = 13, ["name"] = "default:stone"}, {["x"] = 1, ["y"] = 11, ["z"] = 14, ["name"] = "default:stone_with_coal"}, {["x"] = 1, ["y"] = 11, ["z"] = 15, ["name"] = "default:stone"}, {["x"] = 1, ["y"] = 11, ["z"] = 16, ["name"] = "default:stone"}, {["x"] = 1, ["y"] = 11, ["z"] = 17, ["name"] = "default:stone"}, {["x"] = 1, ["y"] = 11, ["z"] = 18, ["name"] = "default:stone"}, {["x"] = 1, ["y"] = 11, ["z"] = 19, ["name"] = "default:stone"}, {["x"] = 1, ["y"] = 11, ["z"] = 20, ["name"] = "default:stone"}, {["x"] = 1, ["y"] = 11, ["z"] = 21, ["name"] = "default:stone"}, {["x"] = 1, ["y"] = 11, ["z"] = 22, ["name"] = "default:stone"}, {["x"] = 1, ["y"] = 11, ["z"] = 23, ["name"] = "default:stone"}, {["x"] = 1, ["y"] = 11, ["z"] = 24, ["name"] = "default:stone"}, {["x"] = 1, ["y"] = 11, ["z"] = 25, ["name"] = "default:stone"}, {["x"] = 1, ["y"] = 11, ["z"] = 26, ["name"] = "default:stone"}, {["x"] = 1, ["y"] = 11, ["z"] = 27, ["name"] = "default:stone"}, {["x"] = 1, ["y"] = 11, ["z"] = 28, ["name"] = "default:stone"}, {["x"] = 1, ["y"] = 12, ["z"] = 1, ["name"] = "default:stone"}, {["x"] = 1, ["y"] = 12, ["z"] = 2, ["name"] = "default:stone"}, {["x"] = 1, ["y"] = 12, ["z"] = 3, ["name"] = "default:stone"}, {["x"] = 1, ["y"] = 12, ["z"] = 4, ["name"] = "default:stone"}, {["x"] = 1, ["y"] = 12, ["z"] = 5, ["name"] = "default:stone"}, {["x"] = 1, ["y"] = 12, ["z"] = 6, ["name"] = "default:stone"}, {["x"] = 1, ["y"] = 12, ["z"] = 7, ["name"] = "default:stone"}, {["x"] = 1, ["y"] = 12, ["z"] = 8, ["name"] = "default:stone"}, {["x"] = 1, ["y"] = 12, ["z"] = 9, ["name"] = "default:stone"}, {["x"] = 1, ["y"] = 12, ["z"] = 10, ["name"] = "default:stone"}, {["x"] = 1, ["y"] = 12, ["z"] = 11, ["name"] = "default:stone"}, {["x"] = 1, ["y"] = 12, ["z"] = 12, ["name"] = "technic:mineral_lead"}, {["x"] = 1, ["y"] = 12, ["z"] = 13, ["name"] = "default:stone"}, {["x"] = 1, ["y"] = 12, ["z"] = 14, ["name"] = "default:stone"}, {["x"] = 1, ["y"] = 12, ["z"] = 15, ["name"] = "default:stone"}, {["x"] = 1, ["y"] = 12, ["z"] = 16, ["name"] = "default:stone"}, {["x"] = 1, ["y"] = 12, ["z"] = 17, ["name"] = "default:stone"}, {["x"] = 1, ["y"] = 12, ["z"] = 18, ["name"] = "default:stone"}, {["x"] = 1, ["y"] = 12, ["z"] = 19, ["name"] = "default:stone"}, {["x"] = 1, ["y"] = 12, ["z"] = 20, ["name"] = "default:stone"}, {["x"] = 1, ["y"] = 12, ["z"] = 21, ["name"] = "default:stone"}, {["x"] = 1, ["y"] = 12, ["z"] = 22, ["name"] = "default:stone"}, {["x"] = 1, ["y"] = 12, ["z"] = 23, ["name"] = "default:stone"}, {["x"] = 1, ["y"] = 12, ["z"] = 24, ["name"] = "default:stone"}, {["x"] = 1, ["y"] = 12, ["z"] = 25, ["name"] = "default:stone"}, {["x"] = 1, ["y"] = 12, ["z"] = 26, ["name"] = "default:stone"}, {["x"] = 1, ["y"] = 12, ["z"] = 27, ["name"] = "default:stone"}, {["x"] = 1, ["y"] = 12, ["z"] = 28, ["name"] = "default:stone"}, {["x"] = 1, ["y"] = 13, ["z"] = 1, ["name"] = "default:stone"}, {["x"] = 1, ["y"] = 13, ["z"] = 2, ["name"] = "default:stone"}, {["x"] = 1, ["y"] = 13, ["z"] = 3, ["name"] = "default:stone"}, {["x"] = 1, ["y"] = 13, ["z"] = 4, ["name"] = "default:stone"}, {["x"] = 1, ["y"] = 13, ["z"] = 5, ["name"] = "default:stone"}, {["x"] = 1, ["y"] = 13, ["z"] = 6, ["name"] = "default:stone"}, {["x"] = 1, ["y"] = 13, ["z"] = 7, ["name"] = "default:stone"}, {["x"] = 1, ["y"] = 13, ["z"] = 8, ["name"] = "default:stone"}, {["x"] = 1, ["y"] = 13, ["z"] = 9, ["name"] = "default:stone"}, {["x"] = 1, ["y"] = 13, ["z"] = 10, ["name"] = "default:stone"}, {["x"] = 1, ["y"] = 13, ["z"] = 11, ["name"] = "default:stone"}, {["x"] = 1, ["y"] = 13, ["z"] = 12, ["name"] = "default:stone"}, {["x"] = 1, ["y"] = 13, ["z"] = 13, ["name"] = "default:stone"}, {["x"] = 1, ["y"] = 13, ["z"] = 14, ["name"] = "default:stone"}, {["x"] = 1, ["y"] = 13, ["z"] = 15, ["name"] = "default:stone"}, {["x"] = 1, ["y"] = 13, ["z"] = 16, ["name"] = "default:stone"}, {["x"] = 1, ["y"] = 13, ["z"] = 17, ["name"] = "default:stone"}, {["x"] = 1, ["y"] = 13, ["z"] = 18, ["name"] = "default:stone"}, {["x"] = 1, ["y"] = 13, ["z"] = 19, ["name"] = "default:stone"}, {["x"] = 1, ["y"] = 13, ["z"] = 20, ["name"] = "default:stone"}, {["x"] = 1, ["y"] = 13, ["z"] = 21, ["name"] = "default:stone_with_coal"}, {["x"] = 1, ["y"] = 13, ["z"] = 22, ["name"] = "default:stone_with_coal"}, {["x"] = 1, ["y"] = 13, ["z"] = 23, ["name"] = "default:stone_with_coal"}, {["x"] = 1, ["y"] = 13, ["z"] = 24, ["name"] = "default:stone"}, {["x"] = 1, ["y"] = 13, ["z"] = 25, ["name"] = "default:stone"}, {["x"] = 1, ["y"] = 13, ["z"] = 26, ["name"] = "default:stone"}, {["x"] = 1, ["y"] = 13, ["z"] = 27, ["name"] = "default:stone_with_iron"}, {["x"] = 1, ["y"] = 13, ["z"] = 28, ["name"] = "default:cobble"}, {["x"] = 1, ["y"] = 14, ["z"] = 1, ["name"] = "default:stone"}, {["x"] = 1, ["y"] = 14, ["z"] = 2, ["name"] = "default:stone"}, {["x"] = 1, ["y"] = 14, ["z"] = 3, ["name"] = "default:stone"}, {["x"] = 1, ["y"] = 14, ["z"] = 4, ["name"] = "default:stone"}, {["x"] = 1, ["y"] = 14, ["z"] = 5, ["name"] = "default:stone"}, {["x"] = 1, ["y"] = 14, ["z"] = 6, ["name"] = "default:stone"}, {["x"] = 1, ["y"] = 14, ["z"] = 7, ["name"] = "default:gravel"}, {["x"] = 1, ["y"] = 14, ["z"] = 8, ["name"] = "default:gravel"}, {["x"] = 1, ["y"] = 14, ["z"] = 9, ["name"] = "default:gravel"}, {["x"] = 1, ["y"] = 14, ["z"] = 10, ["name"] = "default:stone"}, {["x"] = 1, ["y"] = 14, ["z"] = 11, ["name"] = "technic:mineral_lead"}, {["x"] = 1, ["y"] = 14, ["z"] = 12, ["name"] = "default:stone"}, {["x"] = 1, ["y"] = 14, ["z"] = 13, ["name"] = "default:stone"}, {["x"] = 1, ["y"] = 14, ["z"] = 14, ["name"] = "default:stone"}, {["x"] = 1, ["y"] = 14, ["z"] = 15, ["name"] = "default:stone"}, {["x"] = 1, ["y"] = 14, ["z"] = 16, ["name"] = "default:stone"}, {["x"] = 1, ["y"] = 14, ["z"] = 17, ["name"] = "default:stone"}, {["x"] = 1, ["y"] = 14, ["z"] = 18, ["name"] = "default:stone"}, {["x"] = 1, ["y"] = 14, ["z"] = 19, ["name"] = "default:stone"}, {["x"] = 1, ["y"] = 14, ["z"] = 20, ["name"] = "default:stone"}, {["x"] = 1, ["y"] = 14, ["z"] = 21, ["name"] = "default:stone"}, {["x"] = 1, ["y"] = 14, ["z"] = 22, ["name"] = "default:stone"}, {["x"] = 1, ["y"] = 14, ["z"] = 23, ["name"] = "default:stone_with_coal"}, {["x"] = 1, ["y"] = 14, ["z"] = 24, ["name"] = "default:stone"}, {["x"] = 1, ["y"] = 14, ["z"] = 25, ["name"] = "default:stone"}, {["x"] = 1, ["y"] = 14, ["z"] = 26, ["name"] = "default:stone"}, {["x"] = 1, ["y"] = 14, ["z"] = 27, ["name"] = "default:stone"}, {["x"] = 1, ["y"] = 14, ["z"] = 28, ["name"] = "default:cobble"}, {["x"] = 1, ["y"] = 15, ["param1"] = 159, ["z"] = 5, ["name"] = "default:fence_wood"}, {["x"] = 1, ["y"] = 15, ["param1"] = 159, ["z"] = 7, ["name"] = "default:fence_wood"}, {["x"] = 2, ["y"] = 0, ["param1"] = 175, ["z"] = 0, ["name"] = "default:glass"}, {["x"] = 2, ["param2"] = 3, ["y"] = 0, ["param1"] = 190, ["z"] = 1, ["name"] = "default:glass"}, {["x"] = 2, ["param2"] = 4, ["y"] = 0, ["param1"] = 173, ["z"] = 2, ["name"] = "default:glass"}, {["x"] = 2, ["param2"] = 5, ["y"] = 0, ["param1"] = 173, ["z"] = 3, ["name"] = "default:glass"}, {["x"] = 2, ["param2"] = 6, ["y"] = 0, ["param1"] = 172, ["z"] = 4, ["name"] = "default:glass"}, {["x"] = 2, ["param2"] = 6, ["y"] = 0, ["param1"] = 188, ["z"] = 5, ["name"] = "default:glass"}, {["x"] = 2, ["param2"] = 5, ["y"] = 0, ["param1"] = 189, ["z"] = 6, ["name"] = "default:glass"}, {["x"] = 2, ["param2"] = 5, ["y"] = 0, ["param1"] = 173, ["z"] = 7, ["name"] = "default:glass"}, {["x"] = 2, ["param2"] = 6, ["y"] = 0, ["param1"] = 189, ["z"] = 8, ["name"] = "default:glass"}, {["x"] = 2, ["param2"] = 6, ["y"] = 0, ["param1"] = 189, ["z"] = 9, ["name"] = "default:glass"}, {["x"] = 2, ["param2"] = 6, ["y"] = 0, ["param1"] = 189, ["z"] = 10, ["name"] = "default:glass"}, {["x"] = 2, ["param2"] = 6, ["y"] = 0, ["param1"] = 189, ["z"] = 11, ["name"] = "default:glass"}, {["x"] = 2, ["param2"] = 6, ["y"] = 0, ["param1"] = 189, ["z"] = 12, ["name"] = "default:glass"}, {["x"] = 2, ["param2"] = 6, ["y"] = 0, ["param1"] = 189, ["z"] = 13, ["name"] = "default:glass"}, {["x"] = 2, ["param2"] = 5, ["y"] = 0, ["param1"] = 189, ["z"] = 14, ["name"] = "default:glass"}, {["x"] = 2, ["param2"] = 6, ["y"] = 0, ["param1"] = 189, ["z"] = 15, ["name"] = "default:glass"}, {["x"] = 2, ["param2"] = 6, ["y"] = 0, ["param1"] = 189, ["z"] = 16, ["name"] = "default:glass"}, {["x"] = 2, ["param2"] = 6, ["y"] = 0, ["param1"] = 189, ["z"] = 17, ["name"] = "default:glass"}, {["x"] = 2, ["param2"] = 6, ["y"] = 0, ["param1"] = 189, ["z"] = 18, ["name"] = "default:glass"}, {["x"] = 2, ["param2"] = 14, ["y"] = 0, ["param1"] = 189, ["z"] = 19, ["name"] = "default:glass"}, {["x"] = 2, ["param2"] = 6, ["y"] = 0, ["param1"] = 188, ["z"] = 20, ["name"] = "default:glass"}, {["x"] = 2, ["param2"] = 6, ["y"] = 0, ["param1"] = 188, ["z"] = 21, ["name"] = "default:glass"}, {["x"] = 2, ["param2"] = 6, ["y"] = 0, ["param1"] = 189, ["z"] = 22, ["name"] = "default:glass"}, {["x"] = 2, ["param2"] = 5, ["y"] = 0, ["param1"] = 173, ["z"] = 23, ["name"] = "default:glass"}, {["x"] = 2, ["y"] = 0, ["param1"] = 157, ["z"] = 24, ["name"] = "default:glass"}, {["x"] = 2, ["y"] = 0, ["param1"] = 141, ["z"] = 25, ["name"] = "default:glass"}, {["x"] = 2, ["y"] = 0, ["param1"] = 125, ["z"] = 26, ["name"] = "default:glass"}, {["x"] = 2, ["y"] = 0, ["param1"] = 109, ["z"] = 27, ["name"] = "default:glass"}, {["x"] = 2, ["y"] = 0, ["param1"] = 94, ["z"] = 28, ["name"] = "default:glass"}, {["x"] = 2, ["y"] = 0, ["param1"] = 79, ["z"] = 29, ["name"] = "default:glass"}, {["x"] = 2, ["y"] = 1, ["param1"] = 191, ["z"] = 0, ["name"] = "default:glass"}, {["x"] = 2, ["y"] = 1, ["param1"] = 206, ["z"] = 1, ["name"] = "default:glass"}, {["x"] = 2, ["y"] = 1, ["param1"] = 189, ["z"] = 2, ["name"] = "default:glass"}, {["x"] = 2, ["y"] = 1, ["param1"] = 189, ["z"] = 3, ["name"] = "default:glass"}, {["x"] = 2, ["y"] = 1, ["param1"] = 188, ["z"] = 4, ["name"] = "default:glass"}, {["x"] = 2, ["y"] = 1, ["param1"] = 204, ["z"] = 5, ["name"] = "default:glass"}, {["x"] = 2, ["y"] = 1, ["param1"] = 205, ["z"] = 6, ["name"] = "default:glass"}, {["x"] = 2, ["y"] = 1, ["param1"] = 189, ["z"] = 7, ["name"] = "default:glass"}, {["x"] = 2, ["y"] = 1, ["param1"] = 205, ["z"] = 8, ["name"] = "default:glass"}, {["x"] = 2, ["y"] = 1, ["param1"] = 205, ["z"] = 9, ["name"] = "default:glass"}, {["x"] = 2, ["y"] = 1, ["param1"] = 205, ["z"] = 10, ["name"] = "default:glass"}, {["x"] = 2, ["y"] = 1, ["param1"] = 205, ["z"] = 11, ["name"] = "default:glass"}, {["x"] = 2, ["y"] = 1, ["param1"] = 205, ["z"] = 12, ["name"] = "default:glass"}, {["x"] = 2, ["y"] = 1, ["param1"] = 205, ["z"] = 13, ["name"] = "default:glass"}, {["x"] = 2, ["y"] = 1, ["param1"] = 205, ["z"] = 14, ["name"] = "default:glass"}, {["x"] = 2, ["y"] = 1, ["param1"] = 205, ["z"] = 15, ["name"] = "default:glass"}, {["x"] = 2, ["y"] = 1, ["param1"] = 205, ["z"] = 16, ["name"] = "default:glass"}, {["x"] = 2, ["y"] = 1, ["param1"] = 205, ["z"] = 17, ["name"] = "default:glass"}, {["x"] = 2, ["y"] = 1, ["param1"] = 205, ["z"] = 18, ["name"] = "default:glass"}, {["x"] = 2, ["y"] = 1, ["param1"] = 205, ["z"] = 19, ["name"] = "default:glass"}, {["x"] = 2, ["y"] = 1, ["param1"] = 204, ["z"] = 20, ["name"] = "default:glass"}, {["x"] = 2, ["y"] = 1, ["param1"] = 204, ["z"] = 21, ["name"] = "default:glass"}, {["x"] = 2, ["y"] = 1, ["param1"] = 205, ["z"] = 22, ["name"] = "default:glass"}, {["x"] = 2, ["y"] = 1, ["param1"] = 189, ["z"] = 23, ["name"] = "default:glass"}, {["x"] = 2, ["y"] = 1, ["param1"] = 173, ["z"] = 24, ["name"] = "default:glass"}, {["x"] = 2, ["y"] = 1, ["param1"] = 157, ["z"] = 25, ["name"] = "default:glass"}, {["x"] = 2, ["y"] = 1, ["param1"] = 141, ["z"] = 26, ["name"] = "default:glass"}, {["x"] = 2, ["y"] = 1, ["param1"] = 125, ["z"] = 27, ["name"] = "default:glass"}, {["x"] = 2, ["y"] = 1, ["param1"] = 110, ["z"] = 28, ["name"] = "default:glass"}, {["x"] = 2, ["y"] = 1, ["param1"] = 95, ["z"] = 29, ["name"] = "default:glass"}, {["x"] = 2, ["y"] = 2, ["param1"] = 207, ["z"] = 0, ["name"] = "default:glass"}, {["x"] = 2, ["param2"] = 3, ["y"] = 2, ["param1"] = 222, ["z"] = 1, ["name"] = "default:lava_flowing"}, {["x"] = 2, ["y"] = 2, ["z"] = 2, ["name"] = "magma_conduits:hot_cobble"}, {["x"] = 2, ["y"] = 2, ["param1"] = 205, ["z"] = 3, ["name"] = "default:obsidian_glass"}, {["x"] = 2, ["y"] = 2, ["z"] = 4, ["name"] = "magma_conduits:hot_cobble"}, {["x"] = 2, ["param2"] = 7, ["y"] = 2, ["param1"] = 221, ["z"] = 5, ["name"] = "default:lava_flowing"}, {["x"] = 2, ["y"] = 2, ["param1"] = 221, ["z"] = 6, ["name"] = "default:lava_source"}, {["x"] = 2, ["y"] = 2, ["z"] = 7, ["name"] = "default:sand"}, {["x"] = 2, ["y"] = 2, ["param1"] = 221, ["z"] = 8, ["name"] = "default:lava_source"}, {["x"] = 2, ["y"] = 2, ["param1"] = 221, ["z"] = 9, ["name"] = "default:lava_source"}, {["x"] = 2, ["y"] = 2, ["param1"] = 221, ["z"] = 10, ["name"] = "default:lava_source"}, {["x"] = 2, ["y"] = 2, ["param1"] = 221, ["z"] = 11, ["name"] = "default:lava_source"}, {["x"] = 2, ["y"] = 2, ["param1"] = 221, ["z"] = 12, ["name"] = "default:lava_source"}, {["x"] = 2, ["y"] = 2, ["param1"] = 221, ["z"] = 13, ["name"] = "default:lava_source"}, {["x"] = 2, ["y"] = 2, ["param1"] = 221, ["z"] = 14, ["name"] = "default:lava_source"}, {["x"] = 2, ["y"] = 2, ["param1"] = 221, ["z"] = 15, ["name"] = "default:lava_source"}, {["x"] = 2, ["y"] = 2, ["param1"] = 221, ["z"] = 16, ["name"] = "default:lava_source"}, {["x"] = 2, ["y"] = 2, ["param1"] = 221, ["z"] = 17, ["name"] = "default:lava_source"}, {["x"] = 2, ["y"] = 2, ["param1"] = 221, ["z"] = 18, ["name"] = "default:lava_source"}, {["x"] = 2, ["y"] = 2, ["param1"] = 221, ["z"] = 19, ["name"] = "default:lava_source"}, {["x"] = 2, ["y"] = 2, ["param1"] = 221, ["z"] = 20, ["name"] = "default:lava_source"}, {["x"] = 2, ["y"] = 2, ["param1"] = 221, ["z"] = 21, ["name"] = "default:lava_source"}, {["x"] = 2, ["y"] = 2, ["param1"] = 221, ["z"] = 22, ["name"] = "default:lava_source"}, {["x"] = 2, ["y"] = 2, ["z"] = 23, ["name"] = "magma_conduits:hot_cobble"}, {["x"] = 2, ["y"] = 2, ["z"] = 24, ["name"] = "default:stone"}, {["x"] = 2, ["y"] = 2, ["z"] = 25, ["name"] = "default:gravel"}, {["x"] = 2, ["y"] = 2, ["z"] = 26, ["name"] = "default:gravel"}, {["x"] = 2, ["y"] = 2, ["z"] = 27, ["name"] = "default:gravel"}, {["x"] = 2, ["y"] = 2, ["z"] = 28, ["name"] = "default:gravel"}, {["x"] = 2, ["y"] = 2, ["param1"] = 95, ["z"] = 29, ["name"] = "default:glass"}, {["x"] = 2, ["y"] = 3, ["param1"] = 191, ["z"] = 0, ["name"] = "default:glass"}, {["x"] = 2, ["y"] = 3, ["param1"] = 189, ["z"] = 2, ["name"] = "walls:cobble"}, {["x"] = 2, ["y"] = 3, ["param1"] = 188, ["z"] = 4, ["name"] = "walls:cobble"}, {["x"] = 2, ["y"] = 3, ["z"] = 5, ["name"] = "technic:marble"}, {["x"] = 2, ["param2"] = 1, ["y"] = 3, ["param1"] = 221, ["z"] = 6, ["name"] = "default:lava_flowing"}, {["x"] = 2, ["param2"] = 2, ["y"] = 3, ["param1"] = 221, ["z"] = 7, ["name"] = "default:lava_flowing"}, {["x"] = 2, ["y"] = 3, ["z"] = 8, ["name"] = "magma_conduits:hot_cobble"}, {["x"] = 2, ["y"] = 3, ["z"] = 9, ["name"] = "magma_conduits:hot_cobble"}, {["x"] = 2, ["y"] = 3, ["z"] = 10, ["name"] = "magma_conduits:hot_cobble"}, {["x"] = 2, ["y"] = 3, ["z"] = 11, ["name"] = "magma_conduits:hot_cobble"}, {["x"] = 2, ["y"] = 3, ["z"] = 12, ["name"] = "magma_conduits:hot_cobble"}, {["x"] = 2, ["y"] = 3, ["z"] = 13, ["name"] = "magma_conduits:hot_cobble"}, {["x"] = 2, ["y"] = 3, ["z"] = 14, ["name"] = "magma_conduits:hot_cobble"}, {["x"] = 2, ["y"] = 3, ["z"] = 15, ["name"] = "magma_conduits:hot_cobble"}, {["x"] = 2, ["y"] = 3, ["z"] = 16, ["name"] = "magma_conduits:hot_cobble"}, {["x"] = 2, ["y"] = 3, ["z"] = 17, ["name"] = "magma_conduits:hot_cobble"}, {["x"] = 2, ["y"] = 3, ["z"] = 18, ["name"] = "magma_conduits:hot_cobble"}, {["x"] = 2, ["y"] = 3, ["z"] = 19, ["name"] = "magma_conduits:hot_cobble"}, {["x"] = 2, ["y"] = 3, ["z"] = 20, ["name"] = "magma_conduits:hot_cobble"}, {["x"] = 2, ["y"] = 3, ["z"] = 21, ["name"] = "magma_conduits:hot_cobble"}, {["x"] = 2, ["y"] = 3, ["z"] = 22, ["name"] = "magma_conduits:hot_cobble"}, {["x"] = 2, ["y"] = 3, ["z"] = 23, ["name"] = "magma_conduits:hot_cobble"}, {["x"] = 2, ["y"] = 3, ["z"] = 24, ["name"] = "default:stone"}, {["x"] = 2, ["y"] = 3, ["z"] = 25, ["name"] = "default:stone"}, {["x"] = 2, ["y"] = 3, ["z"] = 26, ["name"] = "default:gravel"}, {["x"] = 2, ["y"] = 3, ["z"] = 27, ["name"] = "default:gravel"}, {["x"] = 2, ["y"] = 3, ["z"] = 28, ["name"] = "default:gravel"}, {["x"] = 2, ["y"] = 3, ["param1"] = 111, ["z"] = 29, ["name"] = "default:glass"}, {["x"] = 2, ["y"] = 4, ["z"] = 1, ["name"] = "technic:marble"}, {["x"] = 2, ["y"] = 4, ["param1"] = 173, ["z"] = 2, ["name"] = "walls:cobble"}, {["x"] = 2, ["y"] = 4, ["param1"] = 172, ["z"] = 4, ["name"] = "walls:cobble"}, {["x"] = 2, ["y"] = 4, ["z"] = 5, ["name"] = "technic:marble"}, {["x"] = 2, ["y"] = 4, ["z"] = 9, ["name"] = "default:sand"}, {["x"] = 2, ["y"] = 4, ["param1"] = 85, ["z"] = 10, ["name"] = "vines:root_end"}, {["x"] = 2, ["y"] = 4, ["z"] = 13, ["name"] = "default:sand"}, {["x"] = 2, ["y"] = 4, ["z"] = 14, ["name"] = "default:sand"}, {["x"] = 2, ["y"] = 4, ["z"] = 15, ["name"] = "default:sand"}, {["x"] = 2, ["y"] = 4, ["z"] = 16, ["name"] = "default:sand"}, {["x"] = 2, ["y"] = 4, ["z"] = 17, ["name"] = "default:stone"}, {["x"] = 2, ["y"] = 4, ["z"] = 18, ["name"] = "default:stone"}, {["x"] = 2, ["y"] = 4, ["z"] = 19, ["name"] = "magma_conduits:hot_cobble"}, {["x"] = 2, ["y"] = 4, ["z"] = 22, ["name"] = "technic:marble"}, {["x"] = 2, ["y"] = 4, ["z"] = 23, ["name"] = "farming:soil_wet"}, {["x"] = 2, ["y"] = 4, ["z"] = 24, ["name"] = "farming:soil_wet"}, {["x"] = 2, ["y"] = 4, ["z"] = 25, ["name"] = "farming:soil_wet"}, {["x"] = 2, ["y"] = 4, ["z"] = 26, ["name"] = "farming:soil_wet"}, {["x"] = 2, ["y"] = 4, ["z"] = 27, ["name"] = "technic:marble"}, {["x"] = 2, ["y"] = 4, ["z"] = 28, ["name"] = "default:stone"}, {["x"] = 2, ["y"] = 4, ["param1"] = 127, ["z"] = 29, ["name"] = "default:glass"}, {["x"] = 2, ["y"] = 5, ["z"] = 1, ["name"] = "technic:marble"}, {["x"] = 2, ["y"] = 5, ["param1"] = 156, ["z"] = 2, ["name"] = "walls:cobble"}, {["x"] = 2, ["y"] = 5, ["param1"] = 155, ["z"] = 4, ["name"] = "walls:cobble"}, {["x"] = 2, ["y"] = 5, ["z"] = 5, ["name"] = "technic:marble"}, {["x"] = 2, ["y"] = 5, ["param1"] = 187, ["z"] = 6, ["name"] = "walls:cobble"}, {["x"] = 2, ["y"] = 5, ["z"] = 8, ["name"] = "default:dirt"}, {["x"] = 2, ["y"] = 5, ["z"] = 10, ["name"] = "default:dirt"}, {["x"] = 2, ["y"] = 5, ["z"] = 11, ["name"] = "default:dirt"}, {["x"] = 2, ["y"] = 5, ["z"] = 12, ["name"] = "default:dirt"}, {["x"] = 2, ["y"] = 5, ["z"] = 17, ["name"] = "default:dirt"}, {["x"] = 2, ["y"] = 5, ["z"] = 18, ["name"] = "default:dirt"}, {["x"] = 2, ["y"] = 5, ["z"] = 19, ["name"] = "default:dirt"}, {["x"] = 2, ["y"] = 5, ["z"] = 20, ["name"] = "default:stone"}, {["x"] = 2, ["y"] = 5, ["z"] = 21, ["name"] = "technic:marble"}, {["x"] = 2, ["y"] = 5, ["z"] = 22, ["name"] = "magma_conduits:hot_cobble"}, {["x"] = 2, ["param2"] = 1, ["y"] = 5, ["param1"] = 119, ["z"] = 23, ["name"] = "farming:cotton_1"}, {["x"] = 2, ["param2"] = 1, ["y"] = 5, ["param1"] = 102, ["z"] = 24, ["name"] = "farming:cotton_1"}, {["x"] = 2, ["param2"] = 1, ["y"] = 5, ["param1"] = 85, ["z"] = 25, ["name"] = "farming:cotton_1"}, {["x"] = 2, ["param2"] = 1, ["y"] = 5, ["param1"] = 85, ["z"] = 26, ["name"] = "farming:cotton_1"}, {["x"] = 2, ["y"] = 5, ["z"] = 27, ["name"] = "default:stone"}, {["x"] = 2, ["y"] = 5, ["z"] = 28, ["name"] = "technic:marble"}, {["x"] = 2, ["y"] = 6, ["z"] = 1, ["name"] = "technic:marble"}, {["x"] = 2, ["y"] = 6, ["param1"] = 141, ["z"] = 2, ["name"] = "walls:cobble"}, {["x"] = 2, ["y"] = 6, ["param1"] = 141, ["z"] = 3, ["name"] = "walls:cobble"}, {["x"] = 2, ["y"] = 6, ["param1"] = 140, ["z"] = 4, ["name"] = "walls:cobble"}, {["x"] = 2, ["y"] = 6, ["param1"] = 155, ["z"] = 5, ["name"] = "walls:cobble"}, {["x"] = 2, ["y"] = 6, ["param1"] = 172, ["z"] = 6, ["name"] = "walls:cobble"}, {["x"] = 2, ["y"] = 6, ["z"] = 20, ["name"] = "technic:marble"}, {["x"] = 2, ["y"] = 6, ["z"] = 21, ["name"] = "technic:marble"}, {["x"] = 2, ["y"] = 6, ["z"] = 22, ["name"] = "default:stone"}, {["x"] = 2, ["y"] = 6, ["z"] = 23, ["name"] = "default:stone"}, {["x"] = 2, ["y"] = 6, ["z"] = 24, ["name"] = "default:stone"}, {["x"] = 2, ["y"] = 6, ["z"] = 25, ["name"] = "default:stone"}, {["x"] = 2, ["y"] = 6, ["z"] = 26, ["name"] = "default:stone"}, {["x"] = 2, ["y"] = 6, ["z"] = 27, ["name"] = "default:stone"}, {["x"] = 2, ["y"] = 6, ["z"] = 28, ["name"] = "technic:marble"}, {["x"] = 2, ["y"] = 7, ["z"] = 1, ["name"] = "technic:mineral_lead"}, {["x"] = 2, ["y"] = 7, ["z"] = 2, ["name"] = "technic:marble"}, {["x"] = 2, ["y"] = 7, ["z"] = 3, ["name"] = "technic:marble"}, {["x"] = 2, ["y"] = 7, ["z"] = 4, ["name"] = "technic:marble"}, {["x"] = 2, ["y"] = 7, ["z"] = 5, ["name"] = "technic:marble"}, {["x"] = 2, ["y"] = 7, ["z"] = 20, ["name"] = "technic:marble"}, {["x"] = 2, ["y"] = 7, ["z"] = 21, ["name"] = "default:stone"}, {["x"] = 2, ["y"] = 7, ["z"] = 22, ["name"] = "technic:marble"}, {["x"] = 2, ["y"] = 7, ["z"] = 23, ["name"] = "technic:marble"}, {["x"] = 2, ["y"] = 7, ["z"] = 24, ["name"] = "technic:marble"}, {["x"] = 2, ["y"] = 7, ["z"] = 25, ["name"] = "technic:marble"}, {["x"] = 2, ["y"] = 7, ["z"] = 26, ["name"] = "technic:marble"}, {["x"] = 2, ["y"] = 7, ["z"] = 27, ["name"] = "technic:marble"}, {["x"] = 2, ["y"] = 7, ["z"] = 28, ["name"] = "default:stone"}, {["x"] = 2, ["y"] = 8, ["z"] = 1, ["name"] = "default:stone"}, {["x"] = 2, ["y"] = 8, ["z"] = 2, ["name"] = "default:stone"}, {["x"] = 2, ["y"] = 8, ["z"] = 3, ["name"] = "default:stone"}, {["x"] = 2, ["y"] = 8, ["z"] = 4, ["name"] = "default:stone"}, {["x"] = 2, ["y"] = 8, ["z"] = 5, ["name"] = "technic:marble"}, {["x"] = 2, ["y"] = 8, ["z"] = 20, ["name"] = "technic:marble"}, {["x"] = 2, ["y"] = 8, ["z"] = 21, ["name"] = "default:stone"}, {["x"] = 2, ["y"] = 8, ["z"] = 22, ["name"] = "default:stone"}, {["x"] = 2, ["y"] = 8, ["z"] = 23, ["name"] = "default:stone"}, {["x"] = 2, ["y"] = 8, ["z"] = 24, ["name"] = "default:stone"}, {["x"] = 2, ["y"] = 8, ["z"] = 25, ["name"] = "default:stone"}, {["x"] = 2, ["y"] = 8, ["z"] = 26, ["name"] = "default:stone"}, {["x"] = 2, ["y"] = 8, ["z"] = 27, ["name"] = "default:stone"}, {["x"] = 2, ["y"] = 8, ["z"] = 28, ["name"] = "default:stone"}, {["x"] = 2, ["y"] = 9, ["z"] = 1, ["name"] = "default:stone"}, {["x"] = 2, ["y"] = 9, ["z"] = 2, ["name"] = "default:stone"}, {["x"] = 2, ["y"] = 9, ["z"] = 3, ["name"] = "default:stone"}, {["x"] = 2, ["y"] = 9, ["z"] = 4, ["name"] = "default:stone"}, {["x"] = 2, ["y"] = 9, ["z"] = 5, ["name"] = "technic:marble"}, {["x"] = 2, ["param2"] = 3, ["y"] = 9, ["param1"] = 204, ["z"] = 10, ["name"] = "default:torch_wall"}, {["x"] = 2, ["meta"] = {["fields"] = {["owner"] = "p", ["infotext"] = "Wooden Locked Chest (owned by p)"}, ["inventory"] = {["main"] = {"bushes:blackberry 4", "", "", "", "", "", "", "", "", "", "", "", "", "", "", "", "", "", "", "", "", "", "", "", "", "", "", "", "", "", "", ""}}}, ["param2"] = 1, ["y"] = 9, ["param1"] = 144, ["z"] = 13, ["name"] = "default:chest_locked"}, {["x"] = 2, ["param2"] = 3, ["y"] = 9, ["param1"] = 204, ["z"] = 16, ["name"] = "default:torch_wall"}, {["x"] = 2, ["y"] = 9, ["z"] = 17, ["name"] = "technic:marble"}, {["x"] = 2, ["y"] = 9, ["z"] = 18, ["name"] = "technic:marble"}, {["x"] = 2, ["y"] = 9, ["z"] = 19, ["name"] = "technic:marble"}, {["x"] = 2, ["y"] = 9, ["z"] = 20, ["name"] = "default:stone"}, {["x"] = 2, ["y"] = 9, ["z"] = 21, ["name"] = "default:stone"}, {["x"] = 2, ["y"] = 9, ["z"] = 22, ["name"] = "default:stone"}, {["x"] = 2, ["y"] = 9, ["z"] = 23, ["name"] = "default:stone"}, {["x"] = 2, ["y"] = 9, ["z"] = 24, ["name"] = "default:gravel"}, {["x"] = 2, ["y"] = 9, ["z"] = 25, ["name"] = "default:gravel"}, {["x"] = 2, ["y"] = 9, ["z"] = 26, ["name"] = "default:gravel"}, {["x"] = 2, ["y"] = 9, ["z"] = 27, ["name"] = "default:stone"}, {["x"] = 2, ["y"] = 9, ["z"] = 28, ["name"] = "default:stone"}, {["x"] = 2, ["y"] = 10, ["z"] = 1, ["name"] = "default:stone"}, {["x"] = 2, ["y"] = 10, ["z"] = 2, ["name"] = "default:stone"}, {["x"] = 2, ["y"] = 10, ["z"] = 3, ["name"] = "default:stone"}, {["x"] = 2, ["y"] = 10, ["z"] = 4, ["name"] = "default:stone"}, {["x"] = 2, ["y"] = 10, ["z"] = 5, ["name"] = "default:stone"}, {["x"] = 2, ["y"] = 10, ["z"] = 6, ["name"] = "technic:marble"}, {["x"] = 2, ["y"] = 10, ["z"] = 7, ["name"] = "technic:marble"}, {["x"] = 2, ["y"] = 10, ["z"] = 8, ["name"] = "technic:marble"}, {["x"] = 2, ["y"] = 10, ["z"] = 9, ["name"] = "technic:marble"}, {["x"] = 2, ["y"] = 10, ["z"] = 10, ["name"] = "technic:marble"}, {["x"] = 2, ["y"] = 10, ["z"] = 11, ["name"] = "technic:marble"}, {["x"] = 2, ["y"] = 10, ["z"] = 12, ["name"] = "technic:marble"}, {["x"] = 2, ["y"] = 10, ["z"] = 13, ["name"] = "technic:marble"}, {["x"] = 2, ["y"] = 10, ["z"] = 14, ["name"] = "technic:marble"}, {["x"] = 2, ["y"] = 10, ["z"] = 15, ["name"] = "technic:marble"}, {["x"] = 2, ["y"] = 10, ["z"] = 16, ["name"] = "technic:marble"}, {["x"] = 2, ["y"] = 10, ["z"] = 17, ["name"] = "default:stone"}, {["x"] = 2, ["y"] = 10, ["z"] = 18, ["name"] = "default:stone"}, {["x"] = 2, ["y"] = 10, ["z"] = 19, ["name"] = "default:stone"}, {["x"] = 2, ["y"] = 10, ["z"] = 20, ["name"] = "default:stone"}, {["x"] = 2, ["y"] = 10, ["z"] = 21, ["name"] = "default:stone"}, {["x"] = 2, ["y"] = 10, ["z"] = 22, ["name"] = "default:stone"}, {["x"] = 2, ["y"] = 10, ["z"] = 23, ["name"] = "default:gravel"}, {["x"] = 2, ["y"] = 10, ["z"] = 24, ["name"] = "default:gravel"}, {["x"] = 2, ["y"] = 10, ["z"] = 25, ["name"] = "default:gravel"}, {["x"] = 2, ["y"] = 10, ["z"] = 26, ["name"] = "default:gravel"}, {["x"] = 2, ["y"] = 10, ["z"] = 27, ["name"] = "default:gravel"}, {["x"] = 2, ["y"] = 10, ["z"] = 28, ["name"] = "default:stone"}, {["x"] = 2, ["y"] = 11, ["z"] = 1, ["name"] = "default:stone_with_gold"}, {["x"] = 2, ["y"] = 11, ["z"] = 2, ["name"] = "default:stone"}, {["x"] = 2, ["y"] = 11, ["z"] = 3, ["name"] = "default:stone_with_tin"}, {["x"] = 2, ["y"] = 11, ["z"] = 4, ["name"] = "default:stone"}, {["x"] = 2, ["y"] = 11, ["z"] = 5, ["name"] = "default:stone"}, {["x"] = 2, ["y"] = 11, ["z"] = 6, ["name"] = "default:stone"}, {["x"] = 2, ["y"] = 11, ["z"] = 7, ["name"] = "default:stone"}, {["x"] = 2, ["y"] = 11, ["z"] = 8, ["name"] = "default:stone"}, {["x"] = 2, ["y"] = 11, ["z"] = 9, ["name"] = "default:stone"}, {["x"] = 2, ["y"] = 11, ["z"] = 10, ["name"] = "default:stone"}, {["x"] = 2, ["y"] = 11, ["z"] = 11, ["name"] = "default:stone"}, {["x"] = 2, ["y"] = 11, ["z"] = 12, ["name"] = "default:stone"}, {["x"] = 2, ["y"] = 11, ["z"] = 13, ["name"] = "default:stone"}, {["x"] = 2, ["y"] = 11, ["z"] = 14, ["name"] = "default:stone"}, {["x"] = 2, ["y"] = 11, ["z"] = 15, ["name"] = "default:stone"}, {["x"] = 2, ["y"] = 11, ["z"] = 16, ["name"] = "default:stone"}, {["x"] = 2, ["y"] = 11, ["z"] = 17, ["name"] = "default:stone"}, {["x"] = 2, ["y"] = 11, ["z"] = 18, ["name"] = "default:stone"}, {["x"] = 2, ["y"] = 11, ["z"] = 19, ["name"] = "default:stone"}, {["x"] = 2, ["y"] = 11, ["z"] = 20, ["name"] = "default:stone"}, {["x"] = 2, ["y"] = 11, ["z"] = 21, ["name"] = "default:stone"}, {["x"] = 2, ["y"] = 11, ["z"] = 22, ["name"] = "default:stone_with_iron"}, {["x"] = 2, ["y"] = 11, ["z"] = 23, ["name"] = "default:gravel"}, {["x"] = 2, ["y"] = 11, ["z"] = 24, ["name"] = "default:gravel"}, {["x"] = 2, ["y"] = 11, ["z"] = 25, ["name"] = "default:gravel"}, {["x"] = 2, ["y"] = 11, ["z"] = 26, ["name"] = "default:gravel"}, {["x"] = 2, ["y"] = 11, ["z"] = 27, ["name"] = "default:gravel"}, {["x"] = 2, ["y"] = 11, ["z"] = 28, ["name"] = "default:stone"}, {["x"] = 2, ["y"] = 12, ["z"] = 1, ["name"] = "default:stone"}, {["x"] = 2, ["y"] = 12, ["z"] = 2, ["name"] = "default:stone_with_gold"}, {["x"] = 2, ["y"] = 12, ["z"] = 3, ["name"] = "default:stone_with_gold"}, {["x"] = 2, ["y"] = 12, ["z"] = 4, ["name"] = "default:stone"}, {["x"] = 2, ["y"] = 12, ["z"] = 5, ["name"] = "default:stone"}, {["x"] = 2, ["y"] = 12, ["z"] = 6, ["name"] = "default:stone"}, {["x"] = 2, ["y"] = 12, ["z"] = 7, ["name"] = "default:stone"}, {["x"] = 2, ["y"] = 12, ["z"] = 8, ["name"] = "default:stone"}, {["x"] = 2, ["y"] = 12, ["z"] = 9, ["name"] = "default:stone"}, {["x"] = 2, ["y"] = 12, ["z"] = 10, ["name"] = "default:stone"}, {["x"] = 2, ["y"] = 12, ["z"] = 11, ["name"] = "default:stone"}, {["x"] = 2, ["y"] = 12, ["z"] = 12, ["name"] = "default:stone"}, {["x"] = 2, ["y"] = 12, ["z"] = 13, ["name"] = "default:stone"}, {["x"] = 2, ["y"] = 12, ["z"] = 14, ["name"] = "default:stone"}, {["x"] = 2, ["y"] = 12, ["z"] = 15, ["name"] = "default:stone"}, {["x"] = 2, ["y"] = 12, ["z"] = 16, ["name"] = "default:stone"}, {["x"] = 2, ["y"] = 12, ["z"] = 17, ["name"] = "default:stone"}, {["x"] = 2, ["y"] = 12, ["z"] = 18, ["name"] = "default:stone"}, {["x"] = 2, ["y"] = 12, ["z"] = 19, ["name"] = "default:stone"}, {["x"] = 2, ["y"] = 12, ["z"] = 20, ["name"] = "default:stone"}, {["x"] = 2, ["y"] = 12, ["z"] = 21, ["name"] = "default:stone"}, {["x"] = 2, ["y"] = 12, ["z"] = 22, ["name"] = "default:stone"}, {["x"] = 2, ["y"] = 12, ["z"] = 23, ["name"] = "default:stone"}, {["x"] = 2, ["y"] = 12, ["z"] = 24, ["name"] = "default:stone"}, {["x"] = 2, ["y"] = 12, ["z"] = 25, ["name"] = "default:gravel"}, {["x"] = 2, ["y"] = 12, ["z"] = 26, ["name"] = "default:gravel"}, {["x"] = 2, ["y"] = 12, ["z"] = 27, ["name"] = "default:stone"}, {["x"] = 2, ["y"] = 12, ["z"] = 28, ["name"] = "default:stone_with_iron"}, {["x"] = 2, ["y"] = 13, ["z"] = 1, ["name"] = "default:stone"}, {["x"] = 2, ["y"] = 13, ["z"] = 2, ["name"] = "default:stone_with_iron"}, {["x"] = 2, ["y"] = 13, ["z"] = 3, ["name"] = "default:stone"}, {["x"] = 2, ["y"] = 13, ["z"] = 4, ["name"] = "default:stone"}, {["x"] = 2, ["y"] = 13, ["z"] = 5, ["name"] = "default:stone"}, {["x"] = 2, ["y"] = 13, ["z"] = 6, ["name"] = "default:stone"}, {["x"] = 2, ["y"] = 13, ["z"] = 7, ["name"] = "default:stone"}, {["x"] = 2, ["y"] = 13, ["z"] = 8, ["name"] = "default:stone"}, {["x"] = 2, ["y"] = 13, ["z"] = 9, ["name"] = "default:stone"}, {["x"] = 2, ["y"] = 13, ["z"] = 10, ["name"] = "default:stone"}, {["x"] = 2, ["y"] = 13, ["z"] = 11, ["name"] = "default:stone"}, {["x"] = 2, ["y"] = 13, ["z"] = 12, ["name"] = "default:stone"}, {["x"] = 2, ["y"] = 13, ["z"] = 13, ["name"] = "default:stone"}, {["x"] = 2, ["y"] = 13, ["z"] = 14, ["name"] = "default:stone"}, {["x"] = 2, ["y"] = 13, ["z"] = 15, ["name"] = "default:stone"}, {["x"] = 2, ["y"] = 13, ["z"] = 16, ["name"] = "default:stone"}, {["x"] = 2, ["y"] = 13, ["z"] = 17, ["name"] = "default:stone"}, {["x"] = 2, ["y"] = 13, ["z"] = 18, ["name"] = "default:stone"}, {["x"] = 2, ["y"] = 13, ["z"] = 19, ["name"] = "default:stone"}, {["x"] = 2, ["y"] = 13, ["z"] = 20, ["name"] = "default:stone"}, {["x"] = 2, ["y"] = 13, ["z"] = 21, ["name"] = "default:stone"}, {["x"] = 2, ["y"] = 13, ["z"] = 22, ["name"] = "default:stone"}, {["x"] = 2, ["y"] = 13, ["z"] = 23, ["name"] = "default:stone"}, {["x"] = 2, ["y"] = 13, ["z"] = 24, ["name"] = "default:stone"}, {["x"] = 2, ["y"] = 13, ["z"] = 25, ["name"] = "default:stone"}, {["x"] = 2, ["y"] = 13, ["z"] = 26, ["name"] = "default:stone"}, {["x"] = 2, ["y"] = 13, ["z"] = 27, ["name"] = "default:stone_with_iron"}, {["x"] = 2, ["y"] = 13, ["z"] = 28, ["name"] = "default:stone"}, {["x"] = 2, ["y"] = 14, ["z"] = 1, ["name"] = "default:stone"}, {["x"] = 2, ["y"] = 14, ["z"] = 2, ["name"] = "default:stone"}, {["x"] = 2, ["y"] = 14, ["z"] = 3, ["name"] = "default:stone"}, {["x"] = 2, ["y"] = 14, ["z"] = 4, ["name"] = "default:stone"}, {["x"] = 2, ["y"] = 14, ["z"] = 5, ["name"] = "technic:mineral_lead"}, {["x"] = 2, ["y"] = 14, ["z"] = 6, ["name"] = "default:stone"}, {["x"] = 2, ["y"] = 14, ["z"] = 7, ["name"] = "default:stone"}, {["x"] = 2, ["y"] = 14, ["z"] = 8, ["name"] = "default:stone"}, {["x"] = 2, ["y"] = 14, ["z"] = 9, ["name"] = "default:stone"}, {["x"] = 2, ["y"] = 14, ["z"] = 10, ["name"] = "default:stone"}, {["x"] = 2, ["y"] = 14, ["z"] = 11, ["name"] = "technic:mineral_lead"}, {["x"] = 2, ["y"] = 14, ["z"] = 12, ["name"] = "default:stone"}, {["x"] = 2, ["y"] = 14, ["z"] = 13, ["name"] = "technic:mineral_lead"}, {["x"] = 2, ["y"] = 14, ["z"] = 14, ["name"] = "default:stone"}, {["x"] = 2, ["y"] = 14, ["z"] = 15, ["name"] = "default:stone"}, {["x"] = 2, ["y"] = 14, ["z"] = 16, ["name"] = "default:stone"}, {["x"] = 2, ["y"] = 14, ["z"] = 17, ["name"] = "default:stone"}, {["x"] = 2, ["y"] = 14, ["z"] = 18, ["name"] = "default:stone"}, {["x"] = 2, ["y"] = 14, ["z"] = 19, ["name"] = "default:stone"}, {["x"] = 2, ["y"] = 14, ["z"] = 20, ["name"] = "default:stone"}, {["x"] = 2, ["y"] = 14, ["z"] = 21, ["name"] = "default:stone"}, {["x"] = 2, ["y"] = 14, ["z"] = 22, ["name"] = "default:stone"}, {["x"] = 2, ["y"] = 14, ["z"] = 23, ["name"] = "default:stone"}, {["x"] = 2, ["y"] = 14, ["z"] = 24, ["name"] = "default:stone"}, {["x"] = 2, ["y"] = 14, ["z"] = 25, ["name"] = "default:stone"}, {["x"] = 2, ["y"] = 14, ["z"] = 26, ["name"] = "default:stone_with_iron"}, {["x"] = 2, ["y"] = 14, ["z"] = 27, ["name"] = "default:stone"}, {["x"] = 2, ["y"] = 14, ["z"] = 28, ["name"] = "default:stone"}, {["x"] = 2, ["param2"] = 1, ["y"] = 15, ["param1"] = 207, ["z"] = 10, ["name"] = "default:torch"}, {["x"] = 2, ["param2"] = 1, ["y"] = 15, ["param1"] = 207, ["z"] = 12, ["name"] = "default:torch"}, {["x"] = 2, ["param2"] = 1, ["y"] = 15, ["param1"] = 207, ["z"] = 15, ["name"] = "default:torch"}, {["x"] = 2, ["param2"] = 1, ["y"] = 15, ["param1"] = 207, ["z"] = 17, ["name"] = "default:torch"}, {["x"] = 2, ["param2"] = 1, ["y"] = 15, ["param1"] = 207, ["z"] = 21, ["name"] = "default:torch"}, {["x"] = 2, ["param2"] = 1, ["y"] = 15, ["param1"] = 207, ["z"] = 25, ["name"] = "default:torch"}, {["x"] = 2, ["param2"] = 1, ["y"] = 15, ["param1"] = 207, ["z"] = 27, ["name"] = "default:torch"}, {["x"] = 3, ["y"] = 0, ["param1"] = 175, ["z"] = 0, ["name"] = "default:glass"}, {["x"] = 3, ["param2"] = 4, ["y"] = 0, ["param1"] = 190, ["z"] = 1, ["name"] = "default:glass"}, {["x"] = 3, ["param2"] = 5, ["y"] = 0, ["param1"] = 189, ["z"] = 2, ["name"] = "default:glass"}, {["x"] = 3, ["param2"] = 6, ["y"] = 0, ["param1"] = 188, ["z"] = 3, ["name"] = "default:glass"}, {["x"] = 3, ["param2"] = 7, ["y"] = 0, ["param1"] = 187, ["z"] = 4, ["name"] = "default:glass"}, {["x"] = 3, ["param2"] = 7, ["y"] = 0, ["param1"] = 187, ["z"] = 5, ["name"] = "default:glass"}, {["x"] = 3, ["param2"] = 1, ["y"] = 0, ["param1"] = 188, ["z"] = 6, ["name"] = "default:glass"}, {["x"] = 3, ["param2"] = 1, ["y"] = 0, ["param1"] = 172, ["z"] = 7, ["name"] = "default:glass"}, {["x"] = 3, ["param2"] = 7, ["y"] = 0, ["param1"] = 188, ["z"] = 8, ["name"] = "default:glass"}, {["x"] = 3, ["param2"] = 7, ["y"] = 0, ["param1"] = 188, ["z"] = 9, ["name"] = "default:glass"}, {["x"] = 3, ["param2"] = 7, ["y"] = 0, ["param1"] = 188, ["z"] = 10, ["name"] = "default:glass"}, {["x"] = 3, ["param2"] = 7, ["y"] = 0, ["param1"] = 188, ["z"] = 11, ["name"] = "default:glass"}, {["x"] = 3, ["param2"] = 7, ["y"] = 0, ["param1"] = 188, ["z"] = 12, ["name"] = "default:glass"}, {["x"] = 3, ["param2"] = 7, ["y"] = 0, ["param1"] = 188, ["z"] = 13, ["name"] = "default:glass"}, {["x"] = 3, ["y"] = 0, ["param1"] = 188, ["z"] = 14, ["name"] = "default:glass"}, {["x"] = 3, ["param2"] = 7, ["y"] = 0, ["param1"] = 188, ["z"] = 15, ["name"] = "default:glass"}, {["x"] = 3, ["param2"] = 7, ["y"] = 0, ["param1"] = 188, ["z"] = 16, ["name"] = "default:glass"}, {["x"] = 3, ["param2"] = 7, ["y"] = 0, ["param1"] = 188, ["z"] = 17, ["name"] = "default:glass"}, {["x"] = 3, ["param2"] = 7, ["y"] = 0, ["param1"] = 188, ["z"] = 18, ["name"] = "default:glass"}, {["x"] = 3, ["param2"] = 7, ["y"] = 0, ["param1"] = 188, ["z"] = 19, ["name"] = "default:glass"}, {["x"] = 3, ["param2"] = 7, ["y"] = 0, ["param1"] = 187, ["z"] = 20, ["name"] = "default:glass"}, {["x"] = 3, ["param2"] = 7, ["y"] = 0, ["param1"] = 187, ["z"] = 21, ["name"] = "default:glass"}, {["x"] = 3, ["param2"] = 7, ["y"] = 0, ["param1"] = 188, ["z"] = 22, ["name"] = "default:glass"}, {["x"] = 3, ["param2"] = 6, ["y"] = 0, ["param1"] = 172, ["z"] = 23, ["name"] = "default:glass"}, {["x"] = 3, ["y"] = 0, ["param1"] = 156, ["z"] = 24, ["name"] = "default:glass"}, {["x"] = 3, ["param2"] = 4, ["y"] = 0, ["param1"] = 140, ["z"] = 25, ["name"] = "default:glass"}, {["x"] = 3, ["param2"] = 1, ["y"] = 0, ["param1"] = 124, ["z"] = 26, ["name"] = "default:glass"}, {["x"] = 3, ["param2"] = 1, ["y"] = 0, ["param1"] = 109, ["z"] = 27, ["name"] = "default:glass"}, {["x"] = 3, ["y"] = 0, ["param1"] = 94, ["z"] = 28, ["name"] = "default:glass"}, {["x"] = 3, ["y"] = 0, ["param1"] = 79, ["z"] = 29, ["name"] = "default:glass"}, {["x"] = 3, ["y"] = 1, ["param1"] = 191, ["z"] = 0, ["name"] = "default:glass"}, {["x"] = 3, ["y"] = 1, ["param1"] = 206, ["z"] = 1, ["name"] = "default:glass"}, {["x"] = 3, ["y"] = 1, ["param1"] = 205, ["z"] = 2, ["name"] = "default:glass"}, {["x"] = 3, ["y"] = 1, ["param1"] = 204, ["z"] = 3, ["name"] = "default:glass"}, {["x"] = 3, ["param2"] = 15, ["y"] = 1, ["param1"] = 204, ["z"] = 4, ["name"] = "default:glass"}, {["x"] = 3, ["param2"] = 15, ["y"] = 1, ["param1"] = 204, ["z"] = 5, ["name"] = "default:glass"}, {["x"] = 3, ["param2"] = 7, ["y"] = 1, ["param1"] = 204, ["z"] = 6, ["name"] = "default:glass"}, {["x"] = 3, ["param2"] = 7, ["y"] = 1, ["param1"] = 188, ["z"] = 7, ["name"] = "default:glass"}, {["x"] = 3, ["param2"] = 15, ["y"] = 1, ["param1"] = 204, ["z"] = 8, ["name"] = "default:glass"}, {["x"] = 3, ["param2"] = 15, ["y"] = 1, ["param1"] = 204, ["z"] = 9, ["name"] = "default:glass"}, {["x"] = 3, ["param2"] = 15, ["y"] = 1, ["param1"] = 204, ["z"] = 10, ["name"] = "default:glass"}, {["x"] = 3, ["param2"] = 15, ["y"] = 1, ["param1"] = 204, ["z"] = 11, ["name"] = "default:glass"}, {["x"] = 3, ["param2"] = 15, ["y"] = 1, ["param1"] = 204, ["z"] = 12, ["name"] = "default:glass"}, {["x"] = 3, ["param2"] = 15, ["y"] = 1, ["param1"] = 204, ["z"] = 13, ["name"] = "default:glass"}, {["x"] = 3, ["param2"] = 7, ["y"] = 1, ["param1"] = 204, ["z"] = 14, ["name"] = "default:glass"}, {["x"] = 3, ["param2"] = 15, ["y"] = 1, ["param1"] = 204, ["z"] = 15, ["name"] = "default:glass"}, {["x"] = 3, ["param2"] = 15, ["y"] = 1, ["param1"] = 204, ["z"] = 16, ["name"] = "default:glass"}, {["x"] = 3, ["param2"] = 15, ["y"] = 1, ["param1"] = 204, ["z"] = 17, ["name"] = "default:glass"}, {["x"] = 3, ["param2"] = 15, ["y"] = 1, ["param1"] = 204, ["z"] = 18, ["name"] = "default:glass"}, {["x"] = 3, ["param2"] = 15, ["y"] = 1, ["param1"] = 204, ["z"] = 19, ["name"] = "default:glass"}, {["x"] = 3, ["param2"] = 15, ["y"] = 1, ["param1"] = 204, ["z"] = 20, ["name"] = "default:glass"}, {["x"] = 3, ["param2"] = 15, ["y"] = 1, ["param1"] = 204, ["z"] = 21, ["name"] = "default:glass"}, {["x"] = 3, ["param2"] = 15, ["y"] = 1, ["param1"] = 204, ["z"] = 22, ["name"] = "default:glass"}, {["x"] = 3, ["param2"] = 8, ["y"] = 1, ["param1"] = 188, ["z"] = 23, ["name"] = "default:glass"}, {["x"] = 3, ["param2"] = 1, ["y"] = 1, ["param1"] = 172, ["z"] = 24, ["name"] = "default:glass"}, {["x"] = 3, ["param2"] = 8, ["y"] = 1, ["param1"] = 156, ["z"] = 25, ["name"] = "default:glass"}, {["x"] = 3, ["y"] = 1, ["param1"] = 140, ["z"] = 26, ["name"] = "default:glass"}, {["x"] = 3, ["y"] = 1, ["param1"] = 125, ["z"] = 27, ["name"] = "default:glass"}, {["x"] = 3, ["y"] = 1, ["param1"] = 110, ["z"] = 28, ["name"] = "default:glass"}, {["x"] = 3, ["y"] = 1, ["param1"] = 95, ["z"] = 29, ["name"] = "default:glass"}, {["x"] = 3, ["y"] = 2, ["param1"] = 207, ["z"] = 0, ["name"] = "default:glass"}, {["x"] = 3, ["param2"] = 4, ["y"] = 2, ["param1"] = 222, ["z"] = 1, ["name"] = "default:lava_flowing"}, {["x"] = 3, ["param2"] = 5, ["y"] = 2, ["param1"] = 221, ["z"] = 2, ["name"] = "default:lava_flowing"}, {["x"] = 3, ["param2"] = 6, ["y"] = 2, ["param1"] = 221, ["z"] = 3, ["name"] = "default:lava_flowing"}, {["x"] = 3, ["param2"] = 7, ["y"] = 2, ["param1"] = 221, ["z"] = 4, ["name"] = "default:lava_flowing"}, {["x"] = 3, ["y"] = 2, ["param1"] = 221, ["z"] = 5, ["name"] = "default:lava_source"}, {["x"] = 3, ["y"] = 2, ["param1"] = 221, ["z"] = 6, ["name"] = "default:lava_source"}, {["x"] = 3, ["y"] = 2, ["z"] = 7, ["name"] = "default:sand"}, {["x"] = 3, ["y"] = 2, ["param1"] = 221, ["z"] = 8, ["name"] = "default:lava_source"}, {["x"] = 3, ["y"] = 2, ["param1"] = 221, ["z"] = 9, ["name"] = "default:lava_source"}, {["x"] = 3, ["y"] = 2, ["param1"] = 221, ["z"] = 10, ["name"] = "default:lava_source"}, {["x"] = 3, ["y"] = 2, ["param1"] = 221, ["z"] = 11, ["name"] = "default:lava_source"}, {["x"] = 3, ["y"] = 2, ["param1"] = 221, ["z"] = 12, ["name"] = "default:lava_source"}, {["x"] = 3, ["y"] = 2, ["param1"] = 221, ["z"] = 13, ["name"] = "default:lava_source"}, {["x"] = 3, ["y"] = 2, ["param1"] = 221, ["z"] = 14, ["name"] = "default:lava_source"}, {["x"] = 3, ["y"] = 2, ["param1"] = 221, ["z"] = 15, ["name"] = "default:lava_source"}, {["x"] = 3, ["y"] = 2, ["param1"] = 221, ["z"] = 16, ["name"] = "default:lava_source"}, {["x"] = 3, ["y"] = 2, ["param1"] = 221, ["z"] = 17, ["name"] = "default:lava_source"}, {["x"] = 3, ["y"] = 2, ["param1"] = 221, ["z"] = 18, ["name"] = "default:lava_source"}, {["x"] = 3, ["y"] = 2, ["param1"] = 221, ["z"] = 19, ["name"] = "default:lava_source"}, {["x"] = 3, ["y"] = 2, ["param1"] = 221, ["z"] = 20, ["name"] = "default:lava_source"}, {["x"] = 3, ["y"] = 2, ["param1"] = 221, ["z"] = 21, ["name"] = "default:lava_source"}, {["x"] = 3, ["y"] = 2, ["param1"] = 221, ["z"] = 22, ["name"] = "default:lava_source"}, {["x"] = 3, ["y"] = 2, ["z"] = 23, ["name"] = "magma_conduits:hot_cobble"}, {["x"] = 3, ["y"] = 2, ["z"] = 24, ["name"] = "magma_conduits:hot_cobble"}, {["x"] = 3, ["y"] = 2, ["z"] = 25, ["name"] = "default:gravel"}, {["x"] = 3, ["y"] = 2, ["z"] = 26, ["name"] = "default:gravel"}, {["x"] = 3, ["y"] = 2, ["z"] = 27, ["name"] = "default:gravel"}, {["x"] = 3, ["y"] = 2, ["z"] = 28, ["name"] = "default:gravel"}, {["x"] = 3, ["y"] = 2, ["param1"] = 79, ["z"] = 29, ["name"] = "default:glass"}, {["x"] = 3, ["y"] = 3, ["param1"] = 191, ["z"] = 0, ["name"] = "default:glass"}, {["x"] = 3, ["y"] = 3, ["param1"] = 205, ["z"] = 2, ["name"] = "walls:cobble"}, {["x"] = 3, ["y"] = 3, ["param1"] = 204, ["z"] = 3, ["name"] = "default:obsidian_glass"}, {["x"] = 3, ["y"] = 3, ["param1"] = 204, ["z"] = 4, ["name"] = "default:obsidian_glass"}, {["x"] = 3, ["param2"] = 1, ["y"] = 3, ["param1"] = 221, ["z"] = 5, ["name"] = "default:lava_flowing"}, {["x"] = 3, ["param2"] = 2, ["y"] = 3, ["param1"] = 221, ["z"] = 6, ["name"] = "default:lava_flowing"}, {["x"] = 3, ["param2"] = 3, ["y"] = 3, ["param1"] = 221, ["z"] = 7, ["name"] = "default:lava_flowing"}, {["x"] = 3, ["param2"] = 4, ["y"] = 3, ["param1"] = 221, ["z"] = 8, ["name"] = "default:lava_flowing"}, {["x"] = 3, ["y"] = 3, ["z"] = 9, ["name"] = "magma_conduits:hot_cobble"}, {["x"] = 3, ["y"] = 3, ["z"] = 10, ["name"] = "magma_conduits:hot_cobble"}, {["x"] = 3, ["y"] = 3, ["z"] = 11, ["name"] = "magma_conduits:hot_cobble"}, {["x"] = 3, ["y"] = 3, ["z"] = 12, ["name"] = "magma_conduits:hot_cobble"}, {["x"] = 3, ["y"] = 3, ["z"] = 13, ["name"] = "magma_conduits:hot_cobble"}, {["x"] = 3, ["y"] = 3, ["z"] = 14, ["name"] = "magma_conduits:hot_cobble"}, {["x"] = 3, ["y"] = 3, ["z"] = 15, ["name"] = "magma_conduits:hot_cobble"}, {["x"] = 3, ["y"] = 3, ["z"] = 16, ["name"] = "magma_conduits:hot_cobble"}, {["x"] = 3, ["y"] = 3, ["z"] = 17, ["name"] = "magma_conduits:hot_cobble"}, {["x"] = 3, ["y"] = 3, ["z"] = 18, ["name"] = "magma_conduits:hot_cobble"}, {["x"] = 3, ["y"] = 3, ["z"] = 19, ["name"] = "magma_conduits:hot_cobble"}, {["x"] = 3, ["y"] = 3, ["z"] = 20, ["name"] = "magma_conduits:hot_cobble"}, {["x"] = 3, ["y"] = 3, ["z"] = 21, ["name"] = "magma_conduits:hot_cobble"}, {["x"] = 3, ["y"] = 3, ["z"] = 22, ["name"] = "magma_conduits:hot_cobble"}, {["x"] = 3, ["y"] = 3, ["z"] = 23, ["name"] = "magma_conduits:hot_cobble"}, {["x"] = 3, ["y"] = 3, ["z"] = 24, ["name"] = "magma_conduits:hot_cobble"}, {["x"] = 3, ["y"] = 3, ["z"] = 25, ["name"] = "default:stone"}, {["x"] = 3, ["y"] = 3, ["z"] = 26, ["name"] = "default:gravel"}, {["x"] = 3, ["y"] = 3, ["z"] = 27, ["name"] = "default:gravel"}, {["x"] = 3, ["y"] = 3, ["z"] = 28, ["name"] = "default:gravel"}, {["x"] = 3, ["y"] = 3, ["param1"] = 95, ["z"] = 29, ["name"] = "default:glass"}, {["x"] = 3, ["y"] = 4, ["z"] = 1, ["name"] = "technic:marble"}, {["x"] = 3, ["y"] = 4, ["param1"] = 188, ["z"] = 2, ["name"] = "walls:cobble"}, {["x"] = 3, ["param2"] = 1, ["y"] = 4, ["param1"] = 188, ["z"] = 3, ["name"] = "protector:door_steel_b_1"}, {["x"] = 3, ["y"] = 4, ["param1"] = 187, ["z"] = 4, ["name"] = "walls:cobble"}, {["x"] = 3, ["y"] = 4, ["param1"] = 204, ["z"] = 5, ["name"] = "default:obsidian_glass"}, {["x"] = 3, ["y"] = 4, ["z"] = 9, ["name"] = "default:sand"}, {["x"] = 3, ["y"] = 4, ["z"] = 11, ["name"] = "default:sand"}, {["x"] = 3, ["y"] = 4, ["z"] = 12, ["name"] = "default:sand"}, {["x"] = 3, ["y"] = 4, ["z"] = 14, ["name"] = "default:sand"}, {["x"] = 3, ["y"] = 4, ["z"] = 15, ["name"] = "default:sand"}, {["x"] = 3, ["y"] = 4, ["z"] = 16, ["name"] = "default:sand"}, {["x"] = 3, ["y"] = 4, ["z"] = 17, ["name"] = "default:sand"}, {["x"] = 3, ["y"] = 4, ["z"] = 18, ["name"] = "default:sand"}, {["x"] = 3, ["y"] = 4, ["z"] = 19, ["name"] = "default:sand"}, {["x"] = 3, ["y"] = 4, ["z"] = 22, ["name"] = "technic:marble"}, {["x"] = 3, ["y"] = 4, ["z"] = 23, ["name"] = "farming:soil_wet"}, {["x"] = 3, ["param2"] = 240, ["y"] = 4, ["param1"] = 102, ["z"] = 24, ["name"] = "default:water_source"}, {["x"] = 3, ["param2"] = 240, ["y"] = 4, ["param1"] = 85, ["z"] = 25, ["name"] = "default:water_source"}, {["x"] = 3, ["y"] = 4, ["z"] = 26, ["name"] = "farming:soil_wet"}, {["x"] = 3, ["y"] = 4, ["z"] = 27, ["name"] = "technic:marble"}, {["x"] = 3, ["y"] = 4, ["z"] = 28, ["name"] = "default:stone"}, {["x"] = 3, ["y"] = 4, ["param1"] = 111, ["z"] = 29, ["name"] = "default:glass"}, {["x"] = 3, ["y"] = 5, ["z"] = 1, ["name"] = "technic:marble"}, {["x"] = 3, ["y"] = 5, ["param1"] = 171, ["z"] = 2, ["name"] = "walls:cobble"}, {["x"] = 3, ["param2"] = 1, ["y"] = 5, ["param1"] = 171, ["z"] = 3, ["name"] = "protector:door_steel_t_1"}, {["x"] = 3, ["y"] = 5, ["param1"] = 170, ["z"] = 4, ["name"] = "walls:cobble"}, {["x"] = 3, ["y"] = 5, ["param1"] = 187, ["z"] = 5, ["name"] = "walls:cobble"}, {["x"] = 3, ["y"] = 5, ["param1"] = 187, ["z"] = 6, ["name"] = "walls:cobble"}, {["x"] = 3, ["y"] = 5, ["z"] = 8, ["name"] = "default:dirt"}, {["x"] = 3, ["y"] = 5, ["z"] = 10, ["name"] = "default:dirt"}, {["x"] = 3, ["y"] = 5, ["z"] = 13, ["name"] = "default:dirt"}, {["x"] = 3, ["y"] = 5, ["z"] = 21, ["name"] = "technic:marble"}, {["x"] = 3, ["y"] = 5, ["z"] = 22, ["name"] = "default:stone"}, {["x"] = 3, ["param2"] = 1, ["y"] = 5, ["param1"] = 136, ["z"] = 23, ["name"] = "farming:cotton_1"}, {["x"] = 3, ["y"] = 5, ["z"] = 24, ["name"] = "default:stone"}, {["x"] = 3, ["y"] = 5, ["z"] = 25, ["name"] = "default:stone"}, {["x"] = 3, ["param2"] = 1, ["y"] = 5, ["param1"] = 102, ["z"] = 26, ["name"] = "farming:cotton_1"}, {["x"] = 3, ["y"] = 5, ["z"] = 27, ["name"] = "default:stone"}, {["x"] = 3, ["y"] = 5, ["z"] = 28, ["name"] = "technic:marble"}, {["x"] = 3, ["y"] = 6, ["z"] = 1, ["name"] = "technic:marble"}, {["x"] = 3, ["y"] = 6, ["param1"] = 156, ["z"] = 2, ["name"] = "walls:cobble"}, {["x"] = 3, ["y"] = 6, ["param1"] = 155, ["z"] = 4, ["name"] = "walls:cobble"}, {["x"] = 3, ["y"] = 6, ["param1"] = 170, ["z"] = 5, ["name"] = "walls:cobble"}, {["x"] = 3, ["y"] = 6, ["param1"] = 171, ["z"] = 6, ["name"] = "walls:cobble"}, {["x"] = 3, ["y"] = 6, ["z"] = 20, ["name"] = "technic:marble"}, {["x"] = 3, ["y"] = 6, ["z"] = 21, ["name"] = "technic:marble"}, {["x"] = 3, ["y"] = 6, ["z"] = 22, ["name"] = "default:stone"}, {["x"] = 3, ["y"] = 6, ["z"] = 23, ["name"] = "default:stone"}, {["x"] = 3, ["y"] = 6, ["z"] = 24, ["name"] = "default:stone"}, {["x"] = 3, ["y"] = 6, ["z"] = 25, ["name"] = "default:stone"}, {["x"] = 3, ["y"] = 6, ["z"] = 26, ["name"] = "default:stone"}, {["x"] = 3, ["y"] = 6, ["z"] = 27, ["name"] = "default:stone"}, {["x"] = 3, ["y"] = 6, ["z"] = 28, ["name"] = "technic:marble"}, {["x"] = 3, ["y"] = 7, ["z"] = 1, ["name"] = "technic:marble"}, {["x"] = 3, ["y"] = 7, ["z"] = 2, ["name"] = "technic:marble"}, {["x"] = 3, ["y"] = 7, ["z"] = 20, ["name"] = "technic:marble"}, {["x"] = 3, ["y"] = 7, ["z"] = 21, ["name"] = "technic:marble"}, {["x"] = 3, ["y"] = 7, ["z"] = 22, ["name"] = "technic:marble"}, {["x"] = 3, ["y"] = 7, ["z"] = 23, ["name"] = "technic:marble"}, {["x"] = 3, ["y"] = 7, ["z"] = 24, ["name"] = "technic:marble"}, {["x"] = 3, ["y"] = 7, ["z"] = 25, ["name"] = "technic:marble"}, {["x"] = 3, ["y"] = 7, ["z"] = 26, ["name"] = "technic:marble"}, {["x"] = 3, ["y"] = 7, ["z"] = 27, ["name"] = "technic:marble"}, {["x"] = 3, ["y"] = 7, ["z"] = 28, ["name"] = "default:stone"}, {["x"] = 3, ["y"] = 8, ["z"] = 1, ["name"] = "default:stone"}, {["x"] = 3, ["y"] = 8, ["z"] = 2, ["name"] = "default:stone"}, {["x"] = 3, ["y"] = 8, ["z"] = 3, ["name"] = "technic:marble"}, {["x"] = 3, ["y"] = 8, ["z"] = 4, ["name"] = "technic:marble"}, {["x"] = 3, ["y"] = 8, ["z"] = 20, ["name"] = "technic:marble"}, {["x"] = 3, ["y"] = 8, ["z"] = 21, ["name"] = "technic:marble"}, {["x"] = 3, ["y"] = 8, ["z"] = 22, ["name"] = "technic:marble"}, {["x"] = 3, ["y"] = 8, ["z"] = 23, ["name"] = "technic:marble"}, {["x"] = 3, ["y"] = 8, ["z"] = 24, ["name"] = "default:cobble"}, {["x"] = 3, ["y"] = 8, ["z"] = 25, ["name"] = "default:cobble"}, {["x"] = 3, ["y"] = 8, ["z"] = 26, ["name"] = "default:cobble"}, {["x"] = 3, ["y"] = 8, ["z"] = 27, ["name"] = "default:stone"}, {["x"] = 3, ["y"] = 8, ["z"] = 28, ["name"] = "default:stone"}, {["x"] = 3, ["y"] = 9, ["z"] = 1, ["name"] = "default:stone"}, {["x"] = 3, ["y"] = 9, ["z"] = 2, ["name"] = "default:stone"}, {["x"] = 3, ["y"] = 9, ["z"] = 3, ["name"] = "default:stone"}, {["x"] = 3, ["y"] = 9, ["z"] = 4, ["name"] = "technic:marble"}, {["x"] = 3, ["y"] = 9, ["z"] = 17, ["name"] = "technic:marble"}, {["x"] = 3, ["y"] = 9, ["z"] = 18, ["name"] = "technic:marble"}, {["x"] = 3, ["y"] = 9, ["z"] = 19, ["name"] = "technic:marble"}, {["x"] = 3, ["y"] = 9, ["z"] = 20, ["name"] = "technic:marble"}, {["x"] = 3, ["y"] = 9, ["z"] = 21, ["name"] = "technic:marble"}, {["x"] = 3, ["y"] = 9, ["z"] = 22, ["name"] = "technic:marble"}, {["x"] = 3, ["y"] = 9, ["z"] = 23, ["name"] = "technic:marble"}, {["x"] = 3, ["y"] = 9, ["z"] = 24, ["name"] = "default:stone"}, {["x"] = 3, ["y"] = 9, ["z"] = 25, ["name"] = "default:cobble"}, {["x"] = 3, ["y"] = 9, ["z"] = 26, ["name"] = "default:cobble"}, {["x"] = 3, ["y"] = 9, ["z"] = 27, ["name"] = "default:gravel"}, {["x"] = 3, ["y"] = 9, ["z"] = 28, ["name"] = "default:stone"}, {["x"] = 3, ["y"] = 10, ["z"] = 1, ["name"] = "default:stone"}, {["x"] = 3, ["y"] = 10, ["z"] = 2, ["name"] = "default:stone"}, {["x"] = 3, ["y"] = 10, ["z"] = 3, ["name"] = "default:stone"}, {["x"] = 3, ["y"] = 10, ["z"] = 4, ["name"] = "default:stone"}, {["x"] = 3, ["y"] = 10, ["z"] = 5, ["name"] = "technic:marble"}, {["x"] = 3, ["param2"] = 5, ["y"] = 10, ["param1"] = 204, ["z"] = 6, ["name"] = "default:torch_wall"}, {["x"] = 3, ["y"] = 10, ["z"] = 17, ["name"] = "technic:marble"}, {["x"] = 3, ["y"] = 10, ["z"] = 18, ["name"] = "default:stone"}, {["x"] = 3, ["y"] = 10, ["z"] = 19, ["name"] = "default:stone"}, {["x"] = 3, ["y"] = 10, ["z"] = 20, ["name"] = "default:stone"}, {["x"] = 3, ["y"] = 10, ["z"] = 21, ["name"] = "default:stone"}, {["x"] = 3, ["y"] = 10, ["z"] = 22, ["name"] = "default:stone"}, {["x"] = 3, ["y"] = 10, ["z"] = 23, ["name"] = "default:stone"}, {["x"] = 3, ["y"] = 10, ["z"] = 24, ["name"] = "default:stone"}, {["x"] = 3, ["y"] = 10, ["z"] = 25, ["name"] = "default:cobble"}, {["x"] = 3, ["y"] = 10, ["z"] = 26, ["name"] = "default:cobble"}, {["x"] = 3, ["y"] = 10, ["z"] = 27, ["name"] = "default:gravel"}, {["x"] = 3, ["y"] = 10, ["z"] = 28, ["name"] = "default:stone"}, {["x"] = 3, ["y"] = 11, ["z"] = 1, ["name"] = "default:stone"}, {["x"] = 3, ["y"] = 11, ["z"] = 2, ["name"] = "default:stone"}, {["x"] = 3, ["y"] = 11, ["z"] = 3, ["name"] = "default:stone"}, {["x"] = 3, ["y"] = 11, ["z"] = 4, ["name"] = "default:stone"}, {["x"] = 3, ["y"] = 11, ["z"] = 5, ["name"] = "default:stone"}, {["x"] = 3, ["y"] = 11, ["z"] = 6, ["name"] = "technic:marble"}, {["x"] = 3, ["y"] = 11, ["z"] = 7, ["name"] = "technic:marble"}, {["x"] = 3, ["y"] = 11, ["z"] = 8, ["name"] = "technic:marble"}, {["x"] = 3, ["y"] = 11, ["z"] = 9, ["name"] = "technic:marble"}, {["x"] = 3, ["y"] = 11, ["z"] = 10, ["name"] = "technic:marble"}, {["x"] = 3, ["y"] = 11, ["z"] = 11, ["name"] = "technic:marble"}, {["x"] = 3, ["y"] = 11, ["z"] = 12, ["name"] = "technic:marble"}, {["x"] = 3, ["y"] = 11, ["z"] = 13, ["name"] = "technic:marble"}, {["x"] = 3, ["y"] = 11, ["z"] = 14, ["name"] = "technic:marble"}, {["x"] = 3, ["y"] = 11, ["z"] = 15, ["name"] = "technic:marble"}, {["x"] = 3, ["y"] = 11, ["z"] = 16, ["name"] = "technic:marble"}, {["x"] = 3, ["y"] = 11, ["z"] = 17, ["name"] = "default:stone"}, {["x"] = 3, ["y"] = 11, ["z"] = 18, ["name"] = "default:stone"}, {["x"] = 3, ["y"] = 11, ["z"] = 19, ["name"] = "default:stone"}, {["x"] = 3, ["y"] = 11, ["z"] = 20, ["name"] = "default:stone"}, {["x"] = 3, ["y"] = 11, ["z"] = 21, ["name"] = "default:stone"}, {["x"] = 3, ["y"] = 11, ["z"] = 22, ["name"] = "default:stone"}, {["x"] = 3, ["y"] = 11, ["z"] = 23, ["name"] = "default:stone"}, {["x"] = 3, ["y"] = 11, ["z"] = 24, ["name"] = "default:cobble"}, {["x"] = 3, ["y"] = 11, ["z"] = 25, ["name"] = "default:cobble"}, {["x"] = 3, ["y"] = 11, ["z"] = 26, ["name"] = "default:cobble"}, {["x"] = 3, ["y"] = 11, ["z"] = 27, ["name"] = "default:gravel"}, {["x"] = 3, ["y"] = 11, ["z"] = 28, ["name"] = "default:stone"}, {["x"] = 3, ["y"] = 12, ["z"] = 1, ["name"] = "default:stone"}, {["x"] = 3, ["y"] = 12, ["z"] = 2, ["name"] = "default:stone"}, {["x"] = 3, ["y"] = 12, ["z"] = 3, ["name"] = "default:stone"}, {["x"] = 3, ["y"] = 12, ["z"] = 4, ["name"] = "default:stone_with_coal"}, {["x"] = 3, ["y"] = 12, ["z"] = 5, ["name"] = "default:stone"}, {["x"] = 3, ["y"] = 12, ["z"] = 6, ["name"] = "default:stone"}, {["x"] = 3, ["y"] = 12, ["z"] = 7, ["name"] = "default:stone"}, {["x"] = 3, ["y"] = 12, ["z"] = 8, ["name"] = "default:stone"}, {["x"] = 3, ["y"] = 12, ["z"] = 9, ["name"] = "default:stone"}, {["x"] = 3, ["y"] = 12, ["z"] = 10, ["name"] = "default:stone"}, {["x"] = 3, ["y"] = 12, ["z"] = 11, ["name"] = "default:stone"}, {["x"] = 3, ["y"] = 12, ["z"] = 12, ["name"] = "default:stone"}, {["x"] = 3, ["y"] = 12, ["z"] = 13, ["name"] = "default:stone"}, {["x"] = 3, ["y"] = 12, ["z"] = 14, ["name"] = "default:stone"}, {["x"] = 3, ["y"] = 12, ["z"] = 15, ["name"] = "default:stone"}, {["x"] = 3, ["y"] = 12, ["z"] = 16, ["name"] = "default:stone"}, {["x"] = 3, ["y"] = 12, ["z"] = 17, ["name"] = "default:stone"}, {["x"] = 3, ["y"] = 12, ["z"] = 18, ["name"] = "default:stone"}, {["x"] = 3, ["y"] = 12, ["z"] = 19, ["name"] = "default:stone"}, {["x"] = 3, ["y"] = 12, ["z"] = 20, ["name"] = "default:stone"}, {["x"] = 3, ["y"] = 12, ["z"] = 21, ["name"] = "default:stone"}, {["x"] = 3, ["y"] = 12, ["z"] = 22, ["name"] = "default:stone_with_iron"}, {["x"] = 3, ["y"] = 12, ["z"] = 23, ["name"] = "default:stone"}, {["x"] = 3, ["y"] = 12, ["z"] = 24, ["name"] = "default:cobble"}, {["x"] = 3, ["y"] = 12, ["z"] = 25, ["name"] = "default:cobble"}, {["x"] = 3, ["y"] = 12, ["z"] = 26, ["name"] = "default:cobble"}, {["x"] = 3, ["y"] = 12, ["z"] = 27, ["name"] = "default:stone"}, {["x"] = 3, ["y"] = 12, ["z"] = 28, ["name"] = "default:stone"}, {["x"] = 3, ["y"] = 13, ["z"] = 1, ["name"] = "default:stone_with_iron"}, {["x"] = 3, ["y"] = 13, ["z"] = 2, ["name"] = "default:stone"}, {["x"] = 3, ["y"] = 13, ["z"] = 3, ["name"] = "default:stone"}, {["x"] = 3, ["y"] = 13, ["z"] = 4, ["name"] = "default:stone"}, {["x"] = 3, ["y"] = 13, ["z"] = 5, ["name"] = "default:stone"}, {["x"] = 3, ["y"] = 13, ["z"] = 6, ["name"] = "default:stone"}, {["x"] = 3, ["y"] = 13, ["z"] = 7, ["name"] = "default:stone"}, {["x"] = 3, ["y"] = 13, ["z"] = 8, ["name"] = "default:stone"}, {["x"] = 3, ["y"] = 13, ["z"] = 9, ["name"] = "default:stone"}, {["x"] = 3, ["y"] = 13, ["z"] = 10, ["name"] = "default:stone"}, {["x"] = 3, ["y"] = 13, ["z"] = 11, ["name"] = "default:stone"}, {["x"] = 3, ["y"] = 13, ["z"] = 12, ["name"] = "default:stone"}, {["x"] = 3, ["y"] = 13, ["z"] = 13, ["name"] = "default:stone"}, {["x"] = 3, ["y"] = 13, ["z"] = 14, ["name"] = "default:stone"}, {["x"] = 3, ["y"] = 13, ["z"] = 15, ["name"] = "default:stone"}, {["x"] = 3, ["y"] = 13, ["z"] = 16, ["name"] = "default:stone"}, {["x"] = 3, ["y"] = 13, ["z"] = 17, ["name"] = "default:stone"}, {["x"] = 3, ["y"] = 13, ["z"] = 18, ["name"] = "default:stone"}, {["x"] = 3, ["y"] = 13, ["z"] = 19, ["name"] = "default:stone"}, {["x"] = 3, ["y"] = 13, ["z"] = 20, ["name"] = "default:stone"}, {["x"] = 3, ["y"] = 13, ["z"] = 21, ["name"] = "default:stone"}, {["x"] = 3, ["y"] = 13, ["z"] = 22, ["name"] = "default:stone"}, {["x"] = 3, ["y"] = 13, ["z"] = 23, ["name"] = "default:stone"}, {["x"] = 3, ["y"] = 13, ["z"] = 24, ["name"] = "default:stone"}, {["x"] = 3, ["y"] = 13, ["z"] = 25, ["name"] = "default:stone"}, {["x"] = 3, ["y"] = 13, ["z"] = 26, ["name"] = "default:stone"}, {["x"] = 3, ["y"] = 13, ["z"] = 27, ["name"] = "default:stone"}, {["x"] = 3, ["y"] = 13, ["z"] = 28, ["name"] = "default:stone"}, {["x"] = 3, ["y"] = 14, ["z"] = 1, ["name"] = "default:stone"}, {["x"] = 3, ["y"] = 14, ["z"] = 2, ["name"] = "default:stone"}, {["x"] = 3, ["y"] = 14, ["z"] = 3, ["name"] = "default:stone"}, {["x"] = 3, ["y"] = 14, ["z"] = 4, ["name"] = "default:stone"}, {["x"] = 3, ["y"] = 14, ["z"] = 5, ["name"] = "default:stone"}, {["x"] = 3, ["y"] = 14, ["z"] = 6, ["name"] = "default:stone"}, {["x"] = 3, ["y"] = 14, ["z"] = 7, ["name"] = "default:stone"}, {["x"] = 3, ["y"] = 14, ["z"] = 8, ["name"] = "default:stone"}, {["x"] = 3, ["y"] = 14, ["z"] = 9, ["name"] = "default:stone"}, {["x"] = 3, ["y"] = 14, ["z"] = 10, ["name"] = "default:stone"}, {["x"] = 3, ["y"] = 14, ["z"] = 11, ["name"] = "default:stone"}, {["x"] = 3, ["y"] = 14, ["z"] = 12, ["name"] = "technic:mineral_lead"}, {["x"] = 3, ["y"] = 14, ["z"] = 13, ["name"] = "default:stone"}, {["x"] = 3, ["y"] = 14, ["z"] = 14, ["name"] = "default:stone"}, {["x"] = 3, ["y"] = 14, ["z"] = 15, ["name"] = "default:stone"}, {["x"] = 3, ["y"] = 14, ["z"] = 16, ["name"] = "default:stone"}, {["x"] = 3, ["y"] = 14, ["z"] = 17, ["name"] = "default:stone"}, {["x"] = 3, ["y"] = 14, ["z"] = 18, ["name"] = "default:stone"}, {["x"] = 3, ["y"] = 14, ["z"] = 19, ["name"] = "default:stone"}, {["x"] = 3, ["y"] = 14, ["z"] = 20, ["name"] = "default:stone"}, {["x"] = 3, ["y"] = 14, ["z"] = 21, ["name"] = "default:stone"}, {["x"] = 3, ["y"] = 14, ["z"] = 22, ["name"] = "default:stone"}, {["x"] = 3, ["y"] = 14, ["z"] = 23, ["name"] = "default:stone"}, {["x"] = 3, ["y"] = 14, ["z"] = 24, ["name"] = "default:stone"}, {["x"] = 3, ["y"] = 14, ["z"] = 25, ["name"] = "default:stone"}, {["x"] = 3, ["y"] = 14, ["z"] = 26, ["name"] = "default:stone"}, {["x"] = 3, ["y"] = 14, ["z"] = 27, ["name"] = "default:stone"}, {["x"] = 3, ["y"] = 14, ["z"] = 28, ["name"] = "default:stone"}, {["x"] = 3, ["param2"] = 1, ["y"] = 15, ["param1"] = 207, ["z"] = 3, ["name"] = "default:torch"}, {["x"] = 3, ["param2"] = 1, ["y"] = 15, ["param1"] = 207, ["z"] = 6, ["name"] = "default:torch"}, {["x"] = 4, ["y"] = 0, ["param1"] = 175, ["z"] = 0, ["name"] = "default:glass"}, {["x"] = 4, ["param2"] = 5, ["y"] = 0, ["param1"] = 190, ["z"] = 1, ["name"] = "default:glass"}, {["x"] = 4, ["param2"] = 6, ["y"] = 0, ["param1"] = 189, ["z"] = 2, ["name"] = "default:glass"}, {["x"] = 4, ["param2"] = 7, ["y"] = 0, ["param1"] = 188, ["z"] = 3, ["name"] = "default:glass"}, {["x"] = 4, ["param2"] = 7, ["y"] = 0, ["param1"] = 187, ["z"] = 4, ["name"] = "default:glass"}, {["x"] = 4, ["param2"] = 7, ["y"] = 0, ["param1"] = 187, ["z"] = 5, ["name"] = "default:glass"}, {["x"] = 4, ["param2"] = 7, ["y"] = 0, ["param1"] = 187, ["z"] = 6, ["name"] = "default:glass"}, {["x"] = 4, ["param2"] = 7, ["y"] = 0, ["param1"] = 187, ["z"] = 7, ["name"] = "default:glass"}, {["x"] = 4, ["param2"] = 1, ["y"] = 0, ["param1"] = 187, ["z"] = 8, ["name"] = "default:glass"}, {["x"] = 4, ["param2"] = 7, ["y"] = 0, ["param1"] = 171, ["z"] = 9, ["name"] = "default:glass"}, {["x"] = 4, ["param2"] = 7, ["y"] = 0, ["param1"] = 187, ["z"] = 10, ["name"] = "default:glass"}, {["x"] = 4, ["param2"] = 7, ["y"] = 0, ["param1"] = 187, ["z"] = 11, ["name"] = "default:glass"}, {["x"] = 4, ["param2"] = 7, ["y"] = 0, ["param1"] = 187, ["z"] = 12, ["name"] = "default:glass"}, {["x"] = 4, ["param2"] = 7, ["y"] = 0, ["param1"] = 187, ["z"] = 13, ["name"] = "default:glass"}, {["x"] = 4, ["param2"] = 7, ["y"] = 0, ["param1"] = 187, ["z"] = 14, ["name"] = "default:glass"}, {["x"] = 4, ["param2"] = 7, ["y"] = 0, ["param1"] = 187, ["z"] = 15, ["name"] = "default:glass"},