5:return {{["x"] = 0, ["y"] = 0, ["param1"] = 126, ["z"] = 2, ["name"] = "lapis:lapis_cobble"}, {["x"] = 0, ["y"] = 0, ["param1"] = 142, ["z"] = 3, ["name"] = "lapis:lapis_cobble"}, {["x"] = 0, ["y"] = 0, ["param1"] = 126, ["z"] = 4, ["name"] = "lapis:lapis_cobble"}, {["x"] = 0, ["y"] = 0, ["param1"] = 110, ["z"] = 5, ["name"] = "lapis:lapis_cobble"}, {["x"] = 0, ["y"] = 0, ["param1"] = 94, ["z"] = 6, ["name"] = "lapis:lapis_cobble"}, {["x"] = 0, ["y"] = 0, ["param1"] = 94, ["z"] = 7, ["name"] = "lapis:lapis_cobble"}, {["x"] = 0, ["y"] = 0, ["param1"] = 110, ["z"] = 8, ["name"] = "lapis:lapis_cobble"}, {["x"] = 0, ["y"] = 0, ["param1"] = 110, ["z"] = 9, ["name"] = "lapis:lapis_cobble"}, {["x"] = 0, ["y"] = 0, ["param1"] = 126, ["z"] = 10, ["name"] = "lapis:lapis_cobble"}, {["x"] = 0, ["y"] = 0, ["param1"] = 142, ["z"] = 11, ["name"] = "lapis:lapis_cobble"}, {["x"] = 0, ["y"] = 0, ["param1"] = 158, ["z"] = 12, ["name"] = "lapis:lapis_cobble"}, {["x"] = 0, ["y"] = 0, ["param1"] = 142, ["z"] = 13, ["name"] = "lapis:lapis_cobble"}, {["x"] = 0, ["y"] = 0, ["param1"] = 126, ["z"] = 14, ["name"] = "lapis:lapis_cobble"}, {["x"] = 0, ["y"] = 0, ["param1"] = 110, ["z"] = 15, ["name"] = "lapis:lapis_cobble"}, {["x"] = 0, ["y"] = 0, ["param1"] = 110, ["z"] = 16, ["name"] = "lapis:lapis_cobble"}, {["x"] = 0, ["y"] = 0, ["param1"] = 126, ["z"] = 17, ["name"] = "lapis:lapis_cobble"}, {["x"] = 0, ["y"] = 0, ["param1"] = 142, ["z"] = 18, ["name"] = "lapis:lapis_cobble"}, {["x"] = 0, ["y"] = 0, ["param1"] = 126, ["z"] = 19, ["name"] = "lapis:lapis_cobble"}, {["x"] = 0, ["y"] = 1, ["param1"] = 143, ["z"] = 2, ["name"] = "xpanes:pane"}, {["x"] = 0, ["param2"] = 3, ["y"] = 1, ["param1"] = 159, ["z"] = 3, ["name"] = "xpanes:pane_flat"}, {["x"] = 0, ["param2"] = 3, ["y"] = 1, ["param1"] = 143, ["z"] = 4, ["name"] = "xpanes:pane_flat"}, {["x"] = 0, ["param2"] = 3, ["y"] = 1, ["param1"] = 127, ["z"] = 5, ["name"] = "xpanes:pane_flat"}, {["x"] = 0, ["param2"] = 3, ["y"] = 1, ["param1"] = 111, ["z"] = 6, ["name"] = "xpanes:pane_flat"}, {["x"] = 0, ["param2"] = 3, ["y"] = 1, ["param1"] = 111, ["z"] = 7, ["name"] = "xpanes:pane_flat"}, {["x"] = 0, ["param2"] = 3, ["y"] = 1, ["param1"] = 127, ["z"] = 8, ["name"] = "xpanes:pane_flat"}, {["x"] = 0, ["param2"] = 3, ["y"] = 1, ["param1"] = 127, ["z"] = 9, ["name"] = "xpanes:pane_flat"}, {["x"] = 0, ["param2"] = 3, ["y"] = 1, ["param1"] = 143, ["z"] = 10, ["name"] = "xpanes:pane_flat"}, {["x"] = 0, ["param2"] = 3, ["y"] = 1, ["param1"] = 159, ["z"] = 11, ["name"] = "xpanes:pane_flat"}, {["x"] = 0, ["param2"] = 3, ["y"] = 1, ["param1"] = 175, ["z"] = 12, ["name"] = "xpanes:pane_flat"}, {["x"] = 0, ["param2"] = 3, ["y"] = 1, ["param1"] = 159, ["z"] = 13, ["name"] = "xpanes:pane_flat"}, {["x"] = 0, ["param2"] = 3, ["y"] = 1, ["param1"] = 143, ["z"] = 14, ["name"] = "xpanes:pane_flat"}, {["x"] = 0, ["param2"] = 3, ["y"] = 1, ["param1"] = 127, ["z"] = 15, ["name"] = "xpanes:pane_flat"}, {["x"] = 0, ["param2"] = 3, ["y"] = 1, ["param1"] = 127, ["z"] = 16, ["name"] = "xpanes:pane_flat"}, {["x"] = 0, ["param2"] = 3, ["y"] = 1, ["param1"] = 143, ["z"] = 17, ["name"] = "xpanes:pane_flat"}, {["x"] = 0, ["param2"] = 3, ["y"] = 1, ["param1"] = 159, ["z"] = 18, ["name"] = "xpanes:pane_flat"}, {["x"] = 0, ["y"] = 1, ["param1"] = 143, ["z"] = 19, ["name"] = "xpanes:pane"}, {["x"] = 0, ["y"] = 2, ["param1"] = 159, ["z"] = 2, ["name"] = "xpanes:pane"}, {["x"] = 0, ["param2"] = 3, ["y"] = 2, ["param1"] = 175, ["z"] = 3, ["name"] = "xpanes:pane_flat"}, {["x"] = 0, ["param2"] = 3, ["y"] = 2, ["param1"] = 159, ["z"] = 4, ["name"] = "xpanes:pane_flat"}, {["x"] = 0, ["param2"] = 3, ["y"] = 2, ["param1"] = 143, ["z"] = 5, ["name"] = "xpanes:pane_flat"}, {["x"] = 0, ["param2"] = 3, ["y"] = 2, ["param1"] = 127, ["z"] = 6, ["name"] = "xpanes:pane_flat"}, {["x"] = 0, ["param2"] = 3, ["y"] = 2, ["param1"] = 127, ["z"] = 7, ["name"] = "xpanes:pane_flat"}, {["x"] = 0, ["param2"] = 3, ["y"] = 2, ["param1"] = 143, ["z"] = 8, ["name"] = "xpanes:pane_flat"}, {["x"] = 0, ["param2"] = 3, ["y"] = 2, ["param1"] = 143, ["z"] = 9, ["name"] = "xpanes:pane_flat"}, {["x"] = 0, ["param2"] = 3, ["y"] = 2, ["param1"] = 159, ["z"] = 10, ["name"] = "xpanes:pane_flat"}, {["x"] = 0, ["param2"] = 3, ["y"] = 2, ["param1"] = 175, ["z"] = 11, ["name"] = "xpanes:pane_flat"}, {["x"] = 0, ["param2"] = 3, ["y"] = 2, ["param1"] = 191, ["z"] = 12, ["name"] = "xpanes:pane_flat"}, {["x"] = 0, ["param2"] = 3, ["y"] = 2, ["param1"] = 175, ["z"] = 13, ["name"] = "xpanes:pane_flat"}, {["x"] = 0, ["param2"] = 3, ["y"] = 2, ["param1"] = 159, ["z"] = 14, ["name"] = "xpanes:pane_flat"}, {["x"] = 0, ["param2"] = 3, ["y"] = 2, ["param1"] = 143, ["z"] = 15, ["name"] = "xpanes:pane_flat"}, {["x"] = 0, ["param2"] = 3, ["y"] = 2, ["param1"] = 143, ["z"] = 16, ["name"] = "xpanes:pane_flat"}, {["x"] = 0, ["param2"] = 3, ["y"] = 2, ["param1"] = 159, ["z"] = 17, ["name"] = "xpanes:pane_flat"}, {["x"] = 0, ["param2"] = 3, ["y"] = 2, ["param1"] = 175, ["z"] = 18, ["name"] = "xpanes:pane_flat"}, {["x"] = 0, ["y"] = 2, ["param1"] = 159, ["z"] = 19, ["name"] = "xpanes:pane"}, {["x"] = 0, ["y"] = 3, ["param1"] = 175, ["z"] = 2, ["name"] = "xpanes:pane"}, {["x"] = 0, ["param2"] = 3, ["y"] = 3, ["param1"] = 191, ["z"] = 3, ["name"] = "xpanes:pane_flat"}, {["x"] = 0, ["param2"] = 3, ["y"] = 3, ["param1"] = 175, ["z"] = 4, ["name"] = "xpanes:pane_flat"}, {["x"] = 0, ["param2"] = 3, ["y"] = 3, ["param1"] = 159, ["z"] = 5, ["name"] = "xpanes:pane_flat"}, {["x"] = 0, ["param2"] = 3, ["y"] = 3, ["param1"] = 143, ["z"] = 6, ["name"] = "xpanes:pane_flat"}, {["x"] = 0, ["param2"] = 3, ["y"] = 3, ["param1"] = 143, ["z"] = 7, ["name"] = "xpanes:pane_flat"}, {["x"] = 0, ["param2"] = 3, ["y"] = 3, ["param1"] = 159, ["z"] = 8, ["name"] = "xpanes:pane_flat"}, {["x"] = 0, ["param2"] = 3, ["y"] = 3, ["param1"] = 143, ["z"] = 9, ["name"] = "xpanes:pane_flat"}, {["x"] = 0, ["param2"] = 3, ["y"] = 3, ["param1"] = 143, ["z"] = 10, ["name"] = "xpanes:pane_flat"}, {["x"] = 0, ["param2"] = 3, ["y"] = 3, ["param1"] = 159, ["z"] = 11, ["name"] = "xpanes:pane_flat"}, {["x"] = 0, ["param2"] = 3, ["y"] = 3, ["param1"] = 175, ["z"] = 12, ["name"] = "xpanes:pane_flat"}, {["x"] = 0, ["param2"] = 3, ["y"] = 3, ["param1"] = 159, ["z"] = 13, ["name"] = "xpanes:pane_flat"}, {["x"] = 0, ["param2"] = 3, ["y"] = 3, ["param1"] = 143, ["z"] = 14, ["name"] = "xpanes:pane_flat"}, {["x"] = 0, ["param2"] = 3, ["y"] = 3, ["param1"] = 159, ["z"] = 15, ["name"] = "xpanes:pane_flat"}, {["x"] = 0, ["param2"] = 3, ["y"] = 3, ["param1"] = 159, ["z"] = 16, ["name"] = "xpanes:pane_flat"}, {["x"] = 0, ["param2"] = 3, ["y"] = 3, ["param1"] = 175, ["z"] = 17, ["name"] = "xpanes:pane_flat"}, {["x"] = 0, ["param2"] = 3, ["y"] = 3, ["param1"] = 191, ["z"] = 18, ["name"] = "xpanes:pane_flat"}, {["x"] = 0, ["y"] = 3, ["param1"] = 175, ["z"] = 19, ["name"] = "xpanes:pane"}, {["x"] = 1, ["y"] = 0, ["param1"] = 142, ["z"] = 2, ["name"] = "lapis:lapis_cobble"}, {["x"] = 1, ["y"] = 0, ["z"] = 3, ["name"] = "default:stonebrick"}, {["x"] = 1, ["y"] = 0, ["z"] = 4, ["name"] = "default:stonebrick"}, {["x"] = 1, ["y"] = 0, ["z"] = 5, ["name"] = "default:stonebrick"}, {["x"] = 1, ["y"] = 0, ["z"] = 6, ["name"] = "default:stonebrick"}, {["x"] = 1, ["y"] = 0, ["z"] = 7, ["name"] = "default:stonebrick"}, {["x"] = 1, ["y"] = 0, ["z"] = 8, ["name"] = "default:stonebrick"}, {["x"] = 1, ["y"] = 0, ["z"] = 9, ["name"] = "moretrees:sequoia_planks"}, {["x"] = 1, ["y"] = 0, ["z"] = 10, ["name"] = "moretrees:sequoia_planks"}, {["x"] = 1, ["y"] = 0, ["z"] = 11, ["name"] = "moretrees:sequoia_planks"}, {["x"] = 1, ["y"] = 0, ["z"] = 12, ["name"] = "moretrees:sequoia_planks"}, {["x"] = 1, ["y"] = 0, ["z"] = 13, ["name"] = "moretrees:sequoia_planks"}, {["x"] = 1, ["y"] = 0, ["z"] = 14, ["name"] = "moretrees:sequoia_planks"}, {["x"] = 1, ["y"] = 0, ["z"] = 15, ["name"] = "moretrees:sequoia_planks"}, {["x"] = 1, ["y"] = 0, ["z"] = 16, ["name"] = "moretrees:sequoia_planks"}, {["x"] = 1, ["y"] = 0, ["z"] = 17, ["name"] = "moretrees:sequoia_planks"}, {["x"] = 1, ["y"] = 0, ["z"] = 18, ["name"] = "moretrees:sequoia_planks"}, {["x"] = 1, ["y"] = 0, ["param1"] = 142, ["z"] = 19, ["name"] = "lapis:lapis_cobble"}, {["x"] = 1, ["y"] = 1, ["param1"] = 159, ["z"] = 2, ["name"] = "xpanes:pane_flat"}, {["x"] = 1, ["y"] = 1, ["param1"] = 159, ["z"] = 19, ["name"] = "xpanes:pane_flat"}, {["x"] = 1, ["y"] = 2, ["param1"] = 175, ["z"] = 2, ["name"] = "xpanes:pane_flat"}, {["x"] = 1, ["param2"] = 3, ["y"] = 2, ["param1"] = 206, ["z"] = 12, ["name"] = "default:torch_wall"}, {["x"] = 1, ["y"] = 2, ["param1"] = 175, ["z"] = 19, ["name"] = "xpanes:pane_flat"}, {["x"] = 1, ["y"] = 3, ["param1"] = 191, ["z"] = 2, ["name"] = "xpanes:pane_flat"}, {["x"] = 1, ["param2"] = 3, ["y"] = 3, ["param1"] = 206, ["z"] = 3, ["name"] = "default:torch_wall"}, {["x"] = 1, ["param2"] = 4, ["y"] = 3, ["param1"] = 206, ["z"] = 18, ["name"] = "default:torch_wall"}, {["x"] = 1, ["y"] = 3, ["param1"] = 191, ["z"] = 19, ["name"] = "xpanes:pane_flat"}, {["x"] = 1, ["y"] = 4, ["z"] = 3, ["name"] = "default:cobble"}, {["x"] = 1, ["y"] = 4, ["z"] = 4, ["name"] = "default:cobble"}, {["x"] = 1, ["y"] = 4, ["z"] = 5, ["name"] = "default:cobble"}, {["x"] = 1, ["y"] = 4, ["z"] = 6, ["name"] = "default:cobble"}, {["x"] = 1, ["y"] = 4, ["z"] = 7, ["name"] = "default:cobble"}, {["x"] = 1, ["y"] = 4, ["z"] = 8, ["name"] = "default:cobble"}, {["x"] = 1, ["y"] = 4, ["z"] = 9, ["name"] = "default:cobble"}, {["x"] = 1, ["y"] = 4, ["z"] = 10, ["name"] = "default:cobble"}, {["x"] = 1, ["y"] = 4, ["z"] = 11, ["name"] = "default:cobble"}, {["x"] = 1, ["y"] = 4, ["z"] = 12, ["name"] = "default:cobble"}, {["x"] = 1, ["y"] = 4, ["z"] = 13, ["name"] = "default:cobble"}, {["x"] = 1, ["y"] = 4, ["z"] = 14, ["name"] = "default:cobble"}, {["x"] = 1, ["y"] = 4, ["z"] = 15, ["name"] = "default:cobble"}, {["x"] = 1, ["y"] = 4, ["z"] = 16, ["name"] = "default:cobble"}, {["x"] = 1, ["y"] = 4, ["z"] = 17, ["name"] = "default:cobble"}, {["x"] = 1, ["y"] = 4, ["z"] = 18, ["name"] = "default:cobble"}, {["x"] = 1, ["y"] = 5, ["param1"] = 158, ["z"] = 3, ["name"] = "xpanes:pane"}, {["x"] = 1, ["param2"] = 3, ["y"] = 5, ["param1"] = 174, ["z"] = 4, ["name"] = "xpanes:pane_flat"}, {["x"] = 1, ["param2"] = 3, ["y"] = 5, ["param1"] = 158, ["z"] = 5, ["name"] = "xpanes:pane_flat"}, {["x"] = 1, ["param2"] = 3, ["y"] = 5, ["param1"] = 142, ["z"] = 6, ["name"] = "xpanes:pane_flat"}, {["x"] = 1, ["param2"] = 3, ["y"] = 5, ["param1"] = 126, ["z"] = 7, ["name"] = "xpanes:pane_flat"}, {["x"] = 1, ["param2"] = 3, ["y"] = 5, ["param1"] = 126, ["z"] = 8, ["name"] = "xpanes:pane_flat"}, {["x"] = 1, ["param2"] = 3, ["y"] = 5, ["param1"] = 142, ["z"] = 9, ["name"] = "xpanes:pane_flat"}, {["x"] = 1, ["param2"] = 3, ["y"] = 5, ["param1"] = 158, ["z"] = 10, ["name"] = "xpanes:pane_flat"}, {["x"] = 1, ["param2"] = 3, ["y"] = 5, ["param1"] = 174, ["z"] = 11, ["name"] = "xpanes:pane_flat"}, {["x"] = 1, ["param2"] = 3, ["y"] = 5, ["param1"] = 158, ["z"] = 12, ["name"] = "xpanes:pane_flat"}, {["x"] = 1, ["param2"] = 3, ["y"] = 5, ["param1"] = 142, ["z"] = 13, ["name"] = "xpanes:pane_flat"}, {["x"] = 1, ["param2"] = 3, ["y"] = 5, ["param1"] = 126, ["z"] = 14, ["name"] = "xpanes:pane_flat"}, {["x"] = 1, ["param2"] = 3, ["y"] = 5, ["param1"] = 142, ["z"] = 15, ["name"] = "xpanes:pane_flat"}, {["x"] = 1, ["param2"] = 3, ["y"] = 5, ["param1"] = 158, ["z"] = 16, ["name"] = "xpanes:pane_flat"}, {["x"] = 1, ["param2"] = 3, ["y"] = 5, ["param1"] = 174, ["z"] = 17, ["name"] = "xpanes:pane_flat"}, {["x"] = 1, ["y"] = 5, ["param1"] = 158, ["z"] = 18, ["name"] = "xpanes:pane"}, {["x"] = 1, ["y"] = 6, ["param1"] = 174, ["z"] = 3, ["name"] = "xpanes:pane"}, {["x"] = 1, ["param2"] = 3, ["y"] = 6, ["param1"] = 190, ["z"] = 4, ["name"] = "xpanes:pane_flat"}, {["x"] = 1, ["param2"] = 3, ["y"] = 6, ["param1"] = 174, ["z"] = 5, ["name"] = "xpanes:pane_flat"}, {["x"] = 1, ["param2"] = 3, ["y"] = 6, ["param1"] = 158, ["z"] = 6, ["name"] = "xpanes:pane_flat"}, {["x"] = 1, ["param2"] = 3, ["y"] = 6, ["param1"] = 142, ["z"] = 7, ["name"] = "xpanes:pane_flat"}, {["x"] = 1, ["param2"] = 3, ["y"] = 6, ["param1"] = 142, ["z"] = 8, ["name"] = "xpanes:pane_flat"}, {["x"] = 1, ["param2"] = 3, ["y"] = 6, ["param1"] = 158, ["z"] = 9, ["name"] = "xpanes:pane_flat"}, {["x"] = 1, ["param2"] = 3, ["y"] = 6, ["param1"] = 174, ["z"] = 10, ["name"] = "xpanes:pane_flat"}, {["x"] = 1, ["param2"] = 3, ["y"] = 6, ["param1"] = 190, ["z"] = 11, ["name"] = "xpanes:pane_flat"}, {["x"] = 1, ["param2"] = 3, ["y"] = 6, ["param1"] = 174, ["z"] = 12, ["name"] = "xpanes:pane_flat"}, {["x"] = 1, ["param2"] = 3, ["y"] = 6, ["param1"] = 158, ["z"] = 13, ["name"] = "xpanes:pane_flat"}, {["x"] = 1, ["param2"] = 3, ["y"] = 6, ["param1"] = 142, ["z"] = 14, ["name"] = "xpanes:pane_flat"}, {["x"] = 1, ["param2"] = 3, ["y"] = 6, ["param1"] = 158, ["z"] = 15, ["name"] = "xpanes:pane_flat"}, {["x"] = 1, ["param2"] = 3, ["y"] = 6, ["param1"] = 174, ["z"] = 16, ["name"] = "xpanes:pane_flat"}, {["x"] = 1, ["param2"] = 3, ["y"] = 6, ["param1"] = 190, ["z"] = 17, ["name"] = "xpanes:pane_flat"}, {["x"] = 1, ["y"] = 6, ["param1"] = 174, ["z"] = 18, ["name"] = "xpanes:pane"}, {["x"] = 1, ["y"] = 7, ["param1"] = 158, ["z"] = 3, ["name"] = "xpanes:pane"}, {["x"] = 1, ["param2"] = 3, ["y"] = 7, ["param1"] = 174, ["z"] = 4, ["name"] = "xpanes:pane_flat"}, {["x"] = 1, ["param2"] = 3, ["y"] = 7, ["param1"] = 158, ["z"] = 5, ["name"] = "xpanes:pane_flat"}, {["x"] = 1, ["param2"] = 3, ["y"] = 7, ["param1"] = 142, ["z"] = 6, ["name"] = "xpanes:pane_flat"}, {["x"] = 1, ["param2"] = 3, ["y"] = 7, ["param1"] = 126, ["z"] = 7, ["name"] = "xpanes:pane_flat"}, {["x"] = 1, ["param2"] = 3, ["y"] = 7, ["param1"] = 126, ["z"] = 8, ["name"] = "xpanes:pane_flat"}, {["x"] = 1, ["param2"] = 3, ["y"] = 7, ["param1"] = 142, ["z"] = 9, ["name"] = "xpanes:pane_flat"}, {["x"] = 1, ["param2"] = 3, ["y"] = 7, ["param1"] = 158, ["z"] = 10, ["name"] = "xpanes:pane_flat"}, {["x"] = 1, ["param2"] = 3, ["y"] = 7, ["param1"] = 174, ["z"] = 11, ["name"] = "xpanes:pane_flat"}, {["x"] = 1, ["param2"] = 3, ["y"] = 7, ["param1"] = 158, ["z"] = 12, ["name"] = "xpanes:pane_flat"}, {["x"] = 1, ["param2"] = 3, ["y"] = 7, ["param1"] = 142, ["z"] = 13, ["name"] = "xpanes:pane_flat"}, {["x"] = 1, ["param2"] = 3, ["y"] = 7, ["param1"] = 126, ["z"] = 14, ["name"] = "xpanes:pane_flat"}, {["x"] = 1, ["param2"] = 3, ["y"] = 7, ["param1"] = 142, ["z"] = 15, ["name"] = "xpanes:pane_flat"}, {["x"] = 1, ["param2"] = 3, ["y"] = 7, ["param1"] = 158, ["z"] = 16, ["name"] = "xpanes:pane_flat"}, {["x"] = 1, ["param2"] = 3, ["y"] = 7, ["param1"] = 174, ["z"] = 17, ["name"] = "xpanes:pane_flat"}, {["x"] = 1, ["y"] = 7, ["param1"] = 158, ["z"] = 18, ["name"] = "xpanes:pane"}, {["x"] = 1, ["y"] = 8, ["param1"] = 142, ["z"] = 3, ["name"] = "xpanes:pane"}, {["x"] = 1, ["param2"] = 3, ["y"] = 8, ["param1"] = 158, ["z"] = 4, ["name"] = "xpanes:pane_flat"}, {["x"] = 1, ["param2"] = 3, ["y"] = 8, ["param1"] = 142, ["z"] = 5, ["name"] = "xpanes:pane_flat"}, {["x"] = 1, ["param2"] = 3, ["y"] = 8, ["param1"] = 126, ["z"] = 6, ["name"] = "xpanes:pane_flat"}, {["x"] = 1, ["param2"] = 3, ["y"] = 8, ["param1"] = 110, ["z"] = 7, ["name"] = "xpanes:pane_flat"}, {["x"] = 1, ["param2"] = 3, ["y"] = 8, ["param1"] = 110, ["z"] = 8, ["name"] = "xpanes:pane_flat"}, {["x"] = 1, ["param2"] = 3, ["y"] = 8, ["param1"] = 126, ["z"] = 9, ["name"] = "xpanes:pane_flat"}, {["x"] = 1, ["param2"] = 3, ["y"] = 8, ["param1"] = 142, ["z"] = 10, ["name"] = "xpanes:pane_flat"}, {["x"] = 1, ["param2"] = 3, ["y"] = 8, ["param1"] = 158, ["z"] = 11, ["name"] = "xpanes:pane_flat"}, {["x"] = 1, ["param2"] = 3, ["y"] = 8, ["param1"] = 142, ["z"] = 12, ["name"] = "xpanes:pane_flat"}, {["x"] = 1, ["param2"] = 3, ["y"] = 8, ["param1"] = 126, ["z"] = 13, ["name"] = "xpanes:pane_flat"}, {["x"] = 1, ["param2"] = 3, ["y"] = 8, ["param1"] = 110, ["z"] = 14, ["name"] = "xpanes:pane_flat"}, {["x"] = 1, ["param2"] = 3, ["y"] = 8, ["param1"] = 126, ["z"] = 15, ["name"] = "xpanes:pane_flat"}, {["x"] = 1, ["param2"] = 3, ["y"] = 8, ["param1"] = 142, ["z"] = 16, ["name"] = "xpanes:pane_flat"}, {["x"] = 1, ["param2"] = 3, ["y"] = 8, ["param1"] = 158, ["z"] = 17, ["name"] = "xpanes:pane_flat"}, {["x"] = 1, ["y"] = 8, ["param1"] = 142, ["z"] = 18, ["name"] = "xpanes:pane"}, {["x"] = 1, ["y"] = 9, ["param1"] = 126, ["z"] = 3, ["name"] = "xpanes:pane"}, {["x"] = 1, ["param2"] = 3, ["y"] = 9, ["param1"] = 142, ["z"] = 4, ["name"] = "xpanes:pane_flat"}, {["x"] = 1, ["param2"] = 3, ["y"] = 9, ["param1"] = 126, ["z"] = 5, ["name"] = "xpanes:pane_flat"}, {["x"] = 1, ["param2"] = 3, ["y"] = 9, ["param1"] = 110, ["z"] = 6, ["name"] = "xpanes:pane_flat"}, {["x"] = 1, ["param2"] = 3, ["y"] = 9, ["param1"] = 126, ["z"] = 7, ["name"] = "xpanes:pane_flat"}, {["x"] = 1, ["param2"] = 3, ["y"] = 9, ["param1"] = 110, ["z"] = 8, ["name"] = "xpanes:pane_flat"}, {["x"] = 1, ["param2"] = 3, ["y"] = 9, ["param1"] = 110, ["z"] = 9, ["name"] = "xpanes:pane_flat"}, {["x"] = 1, ["param2"] = 3, ["y"] = 9, ["param1"] = 126, ["z"] = 10, ["name"] = "xpanes:pane_flat"}, {["x"] = 1, ["param2"] = 3, ["y"] = 9, ["param1"] = 142, ["z"] = 11, ["name"] = "xpanes:pane_flat"}, {["x"] = 1, ["param2"] = 3, ["y"] = 9, ["param1"] = 126, ["z"] = 12, ["name"] = "xpanes:pane_flat"}, {["x"] = 1, ["param2"] = 3, ["y"] = 9, ["param1"] = 110, ["z"] = 13, ["name"] = "xpanes:pane_flat"}, {["x"] = 1, ["param2"] = 3, ["y"] = 9, ["param1"] = 110, ["z"] = 14, ["name"] = "xpanes:pane_flat"}, {["x"] = 1, ["param2"] = 3, ["y"] = 9, ["param1"] = 110, ["z"] = 15, ["name"] = "xpanes:pane_flat"}, {["x"] = 1, ["param2"] = 3, ["y"] = 9, ["param1"] = 126, ["z"] = 16, ["name"] = "xpanes:pane_flat"}, {["x"] = 1, ["param2"] = 3, ["y"] = 9, ["param1"] = 142, ["z"] = 17, ["name"] = "xpanes:pane_flat"}, {["x"] = 1, ["y"] = 9, ["param1"] = 126, ["z"] = 18, ["name"] = "xpanes:pane"}, {["x"] = 1, ["y"] = 10, ["param1"] = 110, ["z"] = 3, ["name"] = "lapis:lapis_cobble"}, {["x"] = 1, ["y"] = 10, ["param1"] = 126, ["z"] = 4, ["name"] = "lapis:lapis_cobble"}, {["x"] = 1, ["y"] = 10, ["param1"] = 126, ["z"] = 5, ["name"] = "lapis:lapis_cobble"}, {["x"] = 1, ["y"] = 10, ["param1"] = 126, ["z"] = 6, ["name"] = "lapis:lapis_cobble"}, {["x"] = 1, ["y"] = 10, ["param1"] = 142, ["z"] = 7, ["name"] = "lapis:lapis_cobble"}, {["x"] = 1, ["y"] = 10, ["param1"] = 126, ["z"] = 8, ["name"] = "lapis:lapis_cobble"}, {["x"] = 1, ["y"] = 10, ["param1"] = 110, ["z"] = 9, ["name"] = "lapis:lapis_cobble"}, {["x"] = 1, ["y"] = 10, ["param1"] = 126, ["z"] = 10, ["name"] = "lapis:lapis_cobble"}, {["x"] = 1, ["y"] = 10, ["param1"] = 142, ["z"] = 11, ["name"] = "lapis:lapis_cobble"}, {["x"] = 1, ["y"] = 10, ["param1"] = 126, ["z"] = 12, ["name"] = "lapis:lapis_cobble"}, {["x"] = 1, ["y"] = 10, ["param1"] = 110, ["z"] = 13, ["name"] = "lapis:lapis_cobble"}, {["x"] = 1, ["y"] = 10, ["param1"] = 126, ["z"] = 14, ["name"] = "lapis:lapis_cobble"}, {["x"] = 1, ["y"] = 10, ["param1"] = 126, ["z"] = 15, ["name"] = "lapis:lapis_cobble"}, {["x"] = 1, ["y"] = 10, ["param1"] = 110, ["z"] = 16, ["name"] = "lapis:lapis_cobble"}, {["x"] = 1, ["y"] = 10, ["param1"] = 126, ["z"] = 17, ["name"] = "lapis:lapis_cobble"}, {["x"] = 1, ["y"] = 10, ["param1"] = 110, ["z"] = 18, ["name"] = "lapis:lapis_cobble"}, {["x"] = 2, ["y"] = 0, ["param1"] = 142, ["z"] = 2, ["name"] = "lapis:lapis_cobble"}, {["x"] = 2, ["y"] = 0, ["z"] = 3, ["name"] = "default:stonebrick"}, {["x"] = 2, ["y"] = 0, ["z"] = 4, ["name"] = "default:stonebrick"}, {["x"] = 2, ["y"] = 0, ["z"] = 5, ["name"] = "default:stonebrick"}, {["x"] = 2, ["y"] = 0, ["z"] = 6, ["name"] = "default:stonebrick"}, {["x"] = 2, ["y"] = 0, ["z"] = 7, ["name"] = "default:stonebrick"}, {["x"] = 2, ["y"] = 0, ["z"] = 8, ["name"] = "default:stonebrick"}, {["x"] = 2, ["y"] = 0, ["z"] = 9, ["name"] = "moretrees:sequoia_planks"}, {["x"] = 2, ["y"] = 0, ["z"] = 10, ["name"] = "moretrees:sequoia_planks"}, {["x"] = 2, ["y"] = 0, ["z"] = 11, ["name"] = "moretrees:sequoia_planks"}, {["x"] = 2, ["y"] = 0, ["z"] = 12, ["name"] = "moretrees:sequoia_planks"}, {["x"] = 2, ["y"] = 0, ["z"] = 13, ["name"] = "moretrees:sequoia_planks"}, {["x"] = 2, ["y"] = 0, ["z"] = 14, ["name"] = "moretrees:sequoia_planks"}, {["x"] = 2, ["y"] = 0, ["z"] = 15, ["name"] = "moretrees:sequoia_planks"}, {["x"] = 2, ["y"] = 0, ["z"] = 16, ["name"] = "moretrees:sequoia_planks"}, {["x"] = 2, ["y"] = 0, ["z"] = 17, ["name"] = "moretrees:sequoia_planks"}, {["x"] = 2, ["y"] = 0, ["z"] = 18, ["name"] = "moretrees:sequoia_planks"}, {["x"] = 2, ["y"] = 0, ["param1"] = 126, ["z"] = 19, ["name"] = "lapis:lapis_cobble"}, {["x"] = 2, ["y"] = 1, ["param1"] = 159, ["z"] = 2, ["name"] = "xpanes:pane_flat"}, {["x"] = 2, ["y"] = 1, ["param1"] = 143, ["z"] = 19, ["name"] = "xpanes:pane_flat"}, {["x"] = 2, ["y"] = 2, ["param1"] = 175, ["z"] = 2, ["name"] = "xpanes:pane_flat"}, {["x"] = 2, ["y"] = 2, ["param1"] = 159, ["z"] = 19, ["name"] = "xpanes:pane_flat"}, {["x"] = 2, ["y"] = 3, ["param1"] = 175, ["z"] = 2, ["name"] = "xpanes:pane_flat"}, {["x"] = 2, ["y"] = 3, ["param1"] = 175, ["z"] = 19, ["name"] = "xpanes:pane_flat"}, {["x"] = 2, ["y"] = 4, ["z"] = 3, ["name"] = "default:cobble"}, {["x"] = 2, ["y"] = 4, ["z"] = 4, ["name"] = "default:cobble"}, {["x"] = 2, ["y"] = 4, ["z"] = 5, ["name"] = "default:cobble"}, {["x"] = 2, ["y"] = 4, ["z"] = 6, ["name"] = "default:cobble"}, {["x"] = 2, ["y"] = 4, ["z"] = 7, ["name"] = "default:cobble"}, {["x"] = 2, ["y"] = 4, ["z"] = 8, ["name"] = "default:cobble"}, {["x"] = 2, ["y"] = 4, ["z"] = 9, ["name"] = "default:cobble"}, {["x"] = 2, ["y"] = 4, ["z"] = 10, ["name"] = "default:cobble"}, {["x"] = 2, ["y"] = 4, ["z"] = 11, ["name"] = "default:cobble"}, {["x"] = 2, ["y"] = 4, ["z"] = 12, ["name"] = "default:cobble"}, {["x"] = 2, ["y"] = 4, ["z"] = 13, ["name"] = "default:cobble"}, {["x"] = 2, ["y"] = 4, ["z"] = 14, ["name"] = "default:cobble"}, {["x"] = 2, ["y"] = 4, ["z"] = 15, ["name"] = "default:cobble"}, {["x"] = 2, ["y"] = 4, ["z"] = 16, ["name"] = "default:cobble"}, {["x"] = 2, ["y"] = 4, ["z"] = 17, ["name"] = "default:cobble"}, {["x"] = 2, ["y"] = 4, ["z"] = 18, ["name"] = "default:cobble"}, {["x"] = 2, ["y"] = 5, ["param1"] = 174, ["z"] = 3, ["name"] = "xpanes:pane_flat"}, {["x"] = 2, ["y"] = 5, ["param1"] = 174, ["z"] = 18, ["name"] = "xpanes:pane_flat"}, {["x"] = 2, ["y"] = 6, ["param1"] = 190, ["z"] = 3, ["name"] = "xpanes:pane_flat"}, {["x"] = 2, ["param2"] = 3, ["y"] = 6, ["param1"] = 205, ["z"] = 4, ["name"] = "default:torch_wall"}, {["x"] = 2, ["param2"] = 3, ["y"] = 6, ["param1"] = 205, ["z"] = 11, ["name"] = "default:torch_wall"}, {["x"] = 2, ["param2"] = 3, ["y"] = 6, ["param1"] = 205, ["z"] = 17, ["name"] = "default:torch_wall"}, {["x"] = 2, ["y"] = 6, ["param1"] = 190, ["z"] = 18, ["name"] = "xpanes:pane_flat"}, {["x"] = 2, ["y"] = 7, ["param1"] = 174, ["z"] = 3, ["name"] = "xpanes:pane_flat"}, {["x"] = 2, ["y"] = 7, ["param1"] = 174, ["z"] = 18, ["name"] = "xpanes:pane_flat"}, {["x"] = 2, ["y"] = 8, ["param1"] = 158, ["z"] = 3, ["name"] = "xpanes:pane_flat"}, {["x"] = 2, ["y"] = 8, ["param1"] = 158, ["z"] = 18, ["name"] = "xpanes:pane_flat"}, {["x"] = 2, ["y"] = 9, ["param1"] = 142, ["z"] = 3, ["name"] = "xpanes:pane_flat"}, {["x"] = 2, ["y"] = 9, ["param1"] = 142, ["z"] = 18, ["name"] = "xpanes:pane_flat"}, {["x"] = 2, ["y"] = 10, ["param1"] = 126, ["z"] = 3, ["name"] = "lapis:lapis_cobble"}, {["x"] = 2, ["y"] = 10, ["param1"] = 141, ["z"] = 4, ["name"] = "default:glass"}, {["x"] = 2, ["y"] = 10, ["param1"] = 141, ["z"] = 5, ["name"] = "default:glass"}, {["x"] = 2, ["y"] = 10, ["param1"] = 141, ["z"] = 6, ["name"] = "default:glass"}, {["x"] = 2, ["y"] = 10, ["param1"] = 157, ["z"] = 7, ["name"] = "default:glass"}, {["x"] = 2, ["y"] = 10, ["param1"] = 141, ["z"] = 8, ["name"] = "default:glass"}, {["x"] = 2, ["y"] = 10, ["param1"] = 125, ["z"] = 9, ["name"] = "default:glass"}, {["x"] = 2, ["y"] = 10, ["param1"] = 141, ["z"] = 10, ["name"] = "default:glass"}, {["x"] = 2, ["y"] = 10, ["param1"] = 157, ["z"] = 11, ["name"] = "default:glass"}, {["x"] = 2, ["y"] = 10, ["param1"] = 141, ["z"] = 12, ["name"] = "default:glass"}, {["x"] = 2, ["y"] = 10, ["param1"] = 125, ["z"] = 13, ["name"] = "default:glass"}, {["x"] = 2, ["y"] = 10, ["param1"] = 141, ["z"] = 14, ["name"] = "default:glass"}, {["x"] = 2, ["y"] = 10, ["param1"] = 141, ["z"] = 15, ["name"] = "default:glass"}, {["x"] = 2, ["y"] = 10, ["param1"] = 125, ["z"] = 16, ["name"] = "default:glass"}, {["x"] = 2, ["y"] = 10, ["param1"] = 141, ["z"] = 17, ["name"] = "default:glass"}, {["x"] = 2, ["y"] = 10, ["param1"] = 126, ["z"] = 18, ["name"] = "lapis:lapis_cobble"}, {["x"] = 2, ["y"] = 11, ["z"] = 4, ["name"] = "default:stonebrick"}, {["x"] = 2, ["y"] = 11, ["z"] = 5, ["name"] = "default:stonebrick"}, {["x"] = 2, ["y"] = 11, ["z"] = 6, ["name"] = "default:stonebrick"}, {["x"] = 2, ["y"] = 11, ["z"] = 7, ["name"] = "default:stonebrick"}, {["x"] = 2, ["y"] = 11, ["z"] = 8, ["name"] = "default:stonebrick"}, {["x"] = 2, ["y"] = 11, ["z"] = 9, ["name"] = "default:stonebrick"}, {["x"] = 2, ["y"] = 11, ["z"] = 10, ["name"] = "default:stonebrick"}, {["x"] = 2, ["y"] = 11, ["z"] = 11, ["name"] = "default:stonebrick"}, {["x"] = 2, ["y"] = 11, ["z"] = 12, ["name"] = "default:stonebrick"}, {["x"] = 2, ["y"] = 11, ["z"] = 13, ["name"] = "default:stonebrick"}, {["x"] = 2, ["y"] = 11, ["z"] = 14, ["name"] = "default:stonebrick"}, {["x"] = 2, ["y"] = 11, ["z"] = 15, ["name"] = "default:stonebrick"}, {["x"] = 2, ["y"] = 11, ["z"] = 16, ["name"] = "default:stonebrick"}, {["x"] = 2, ["y"] = 11, ["z"] = 17, ["name"] = "default:stonebrick"}, {["x"] = 2, ["y"] = 12, ["z"] = 4, ["name"] = "default:stonebrick"}, {["x"] = 2, ["y"] = 12, ["z"] = 5, ["name"] = "default:stonebrick"}, {["x"] = 2, ["y"] = 12, ["z"] = 6, ["name"] = "default:stonebrick"}, {["x"] = 2, ["y"] = 12, ["z"] = 7, ["name"] = "default:stonebrick"}, {["x"] = 2, ["y"] = 12, ["z"] = 8, ["name"] = "default:stonebrick"}, {["x"] = 2, ["y"] = 12, ["z"] = 9, ["name"] = "default:stonebrick"}, {["x"] = 2, ["y"] = 12, ["z"] = 10, ["name"] = "default:stonebrick"}, {["x"] = 2, ["y"] = 12, ["z"] = 11, ["name"] = "default:stonebrick"}, {["x"] = 2, ["y"] = 12, ["z"] = 12, ["name"] = "default:stonebrick"}, {["x"] = 2, ["y"] = 12, ["z"] = 13, ["name"] = "default:stonebrick"}, {["x"] = 2, ["y"] = 12, ["z"] = 14, ["name"] = "default:stonebrick"}, {["x"] = 2, ["y"] = 12, ["z"] = 15, ["name"] = "default:stonebrick"}, {["x"] = 2, ["y"] = 12, ["z"] = 16, ["name"] = "default:stonebrick"}, {["x"] = 2, ["y"] = 13, ["z"] = 4, ["name"] = "default:stonebrick"}, {["x"] = 2, ["y"] = 13, ["z"] = 5, ["name"] = "default:stonebrick"}, {["x"] = 2, ["y"] = 13, ["z"] = 6, ["name"] = "default:stonebrick"}, {["x"] = 2, ["y"] = 13, ["z"] = 7, ["name"] = "default:stonebrick"}, {["x"] = 2, ["y"] = 13, ["z"] = 8, ["name"] = "default:stonebrick"}, {["x"] = 2, ["y"] = 13, ["z"] = 9, ["name"] = "default:stonebrick"}, {["x"] = 2, ["y"] = 13, ["z"] = 10, ["name"] = "default:stonebrick"}, {["x"] = 2, ["y"] = 13, ["z"] = 11, ["name"] = "default:stonebrick"}, {["x"] = 2, ["y"] = 13, ["z"] = 12, ["name"] = "default:stonebrick"}, {["x"] = 2, ["y"] = 13, ["z"] = 13, ["name"] = "default:stonebrick"}, {["x"] = 2, ["y"] = 13, ["z"] = 14, ["name"] = "default:stonebrick"}, {["x"] = 2, ["y"] = 13, ["z"] = 15, ["name"] = "default:stonebrick"}, {["x"] = 2, ["y"] = 13, ["z"] = 16, ["name"] = "default:stonebrick"}, {["x"] = 2, ["y"] = 14, ["z"] = 4, ["name"] = "default:stonebrick"}, {["x"] = 2, ["y"] = 14, ["z"] = 5, ["name"] = "default:stonebrick"}, {["x"] = 2, ["y"] = 14, ["z"] = 6, ["name"] = "default:stonebrick"}, {["x"] = 2, ["y"] = 14, ["z"] = 7, ["name"] = "default:stonebrick"}, {["x"] = 2, ["y"] = 14, ["z"] = 8, ["name"] = "default:stonebrick"}, {["x"] = 2, ["y"] = 14, ["z"] = 9, ["name"] = "default:stonebrick"}, {["x"] = 2, ["y"] = 14, ["z"] = 10, ["name"] = "default:stonebrick"}, {["x"] = 2, ["y"] = 14, ["z"] = 11, ["name"] = "default:stonebrick"}, {["x"] = 2, ["y"] = 14, ["z"] = 12, ["name"] = "default:stonebrick"}, {["x"] = 2, ["y"] = 14, ["z"] = 13, ["name"] = "default:stonebrick"}, {["x"] = 2, ["y"] = 14, ["z"] = 14, ["name"] = "default:stonebrick"}, {["x"] = 2, ["y"] = 14, ["z"] = 15, ["name"] = "default:stonebrick"}, {["x"] = 2, ["y"] = 14, ["z"] = 16, ["name"] = "default:stonebrick"}, {["x"] = 2, ["y"] = 14, ["z"] = 17, ["name"] = "default:stonebrick"}, {["x"] = 3, ["y"] = 0, ["param1"] = 158, ["z"] = 2, ["name"] = "lapis:lapis_cobble"}, {["x"] = 3, ["y"] = 0, ["z"] = 3, ["name"] = "default:stonebrick"}, {["x"] = 3, ["y"] = 0, ["z"] = 4, ["name"] = "default:stonebrick"}, {["x"] = 3, ["y"] = 0, ["z"] = 5, ["name"] = "default:stonebrick"}, {["x"] = 3, ["y"] = 0, ["z"] = 6, ["name"] = "default:stonebrick"}, {["x"] = 3, ["y"] = 0, ["z"] = 7, ["name"] = "default:stonebrick"}, {["x"] = 3, ["y"] = 0, ["z"] = 8, ["name"] = "default:stonebrick"}, {["x"] = 3, ["y"] = 0, ["z"] = 9, ["name"] = "moretrees:sequoia_planks"}, {["x"] = 3, ["y"] = 0, ["z"] = 10, ["name"] = "moretrees:sequoia_planks"}, {["x"] = 3, ["y"] = 0, ["z"] = 11, ["name"] = "moretrees:fir_planks"}, {["x"] = 3, ["y"] = 0, ["z"] = 12, ["name"] = "default:stonebrick"}, {["x"] = 3, ["y"] = 0, ["z"] = 13, ["name"] = "default:stonebrick"}, {["x"] = 3, ["y"] = 0, ["z"] = 14, ["name"] = "default:stonebrick"}, {["x"] = 3, ["y"] = 0, ["z"] = 15, ["name"] = "default:stonebrick"}, {["x"] = 3, ["y"] = 0, ["z"] = 16, ["name"] = "moretrees:fir_planks"}, {["x"] = 3, ["y"] = 0, ["z"] = 17, ["name"] = "moretrees:sequoia_planks"}, {["x"] = 3, ["y"] = 0, ["z"] = 18, ["name"] = "moretrees:sequoia_planks"}, {["x"] = 3, ["y"] = 0, ["param1"] = 110, ["z"] = 19, ["name"] = "lapis:lapis_cobble"}, {["x"] = 3, ["y"] = 1, ["param1"] = 175, ["z"] = 2, ["name"] = "xpanes:pane_flat"}, {["x"] = 3, ["meta"] = {["fields"] = {["formspec"] = "size[8,8.5]bgcolor[#080808BB;true]background[5,5;1,1;gui_formbg.png;true]listcolors[#00000069;#5A5A5A;#141318;#30434C;#FFF]list[current_name;src;2.75,0.5;1,1;]list[current_name;fuel;2.75,2.5;1,1;]image[2.75,1.5;1,1;default_furnace_fire_bg.png]image[3.75,1.5;1,1;gui_furnace_arrow_bg.png^[transformR270]list[current_name;dst;4.75,0.96;2,2;]list[current_player;main;0,4.25;8,1;]list[current_player;main;0,5.5;8,3;8]listring[current_name;dst]listring[current_player;main]listring[current_name;src]listring[current_player;main]listring[current_name;fuel]listring[current_player;main]image[0,4.25;1,1;gui_hb_bg.png]image[1,4.25;1,1;gui_hb_bg.png]image[2,4.25;1,1;gui_hb_bg.png]image[3,4.25;1,1;gui_hb_bg.png]image[4,4.25;1,1;gui_hb_bg.png]image[5,4.25;1,1;gui_hb_bg.png]image[6,4.25;1,1;gui_hb_bg.png]image[7,4.25;1,1;gui_hb_bg.png]", ["fuel_time"] = "0", ["fuel_totaltime"] = "0", ["src_time"] = "0", ["infotext"] = "Furnace inactive (Item: 0%; Fuel: Empty)"}, ["inventory"] = {["fuel"] = {""}, ["dst"] = {"", "", "", ""}, ["src"] = {""}}}, ["param2"] = 3, ["y"] = 1, ["z"] = 12, ["name"] = "default:furnace"}, {["x"] = 3, ["meta"] = {["fields"] = {["formspec"] = "size[8,8.5]bgcolor[#080808BB;true]background[5,5;1,1;gui_formbg.png;true]listcolors[#00000069;#5A5A5A;#141318;#30434C;#FFF]list[current_name;src;2.75,0.5;1,1;]list[current_name;fuel;2.75,2.5;1,1;]image[2.75,1.5;1,1;default_furnace_fire_bg.png]image[3.75,1.5;1,1;gui_furnace_arrow_bg.png^[transformR270]list[current_name;dst;4.75,0.96;2,2;]list[current_player;main;0,4.25;8,1;]list[current_player;main;0,5.5;8,3;8]listring[current_name;dst]listring[current_player;main]listring[current_name;src]listring[current_player;main]listring[current_name;fuel]listring[current_player;main]image[0,4.25;1,1;gui_hb_bg.png]image[1,4.25;1,1;gui_hb_bg.png]image[2,4.25;1,1;gui_hb_bg.png]image[3,4.25;1,1;gui_hb_bg.png]image[4,4.25;1,1;gui_hb_bg.png]image[5,4.25;1,1;gui_hb_bg.png]image[6,4.25;1,1;gui_hb_bg.png]image[7,4.25;1,1;gui_hb_bg.png]", ["fuel_time"] = "0", ["fuel_totaltime"] = "0", ["src_time"] = "0", ["infotext"] = "Furnace inactive (Item: Empty; Fuel: Empty)"}, ["inventory"] = {["fuel"] = {""}, ["dst"] = {"", "", "", ""}, ["src"] = {""}}}, ["param2"] = 3, ["y"] = 1, ["z"] = 13, ["name"] = "default:furnace"}, {["x"] = 3, ["y"] = 1, ["param1"] = 127, ["z"] = 19, ["name"] = "xpanes:pane_flat"}, {["x"] = 3, ["y"] = 2, ["param1"] = 191, ["z"] = 2, ["name"] = "xpanes:pane_flat"}, {["x"] = 3, ["param2"] = 5, ["y"] = 2, ["param1"] = 206, ["z"] = 3, ["name"] = "default:torch_wall"}, {["x"] = 3, ["y"] = 2, ["param1"] = 143, ["z"] = 19, ["name"] = "xpanes:pane_flat"}, {["x"] = 3, ["y"] = 3, ["param1"] = 175, ["z"] = 2, ["name"] = "xpanes:pane_flat"}, {["x"] = 3, ["y"] = 3, ["param1"] = 204, ["z"] = 8, ["name"] = "default:torch_ceiling"}, {["x"] = 3, ["y"] = 3, ["param1"] = 204, ["z"] = 15, ["name"] = "default:torch_ceiling"}, {["x"] = 3, ["y"] = 3, ["param1"] = 159, ["z"] = 19, ["name"] = "xpanes:pane_flat"}, {["x"] = 3, ["y"] = 4, ["z"] = 3, ["name"] = "default:cobble"}, {["x"] = 3, ["y"] = 4, ["z"] = 4, ["name"] = "default:cobble"}, {["x"] = 3, ["y"] = 4, ["z"] = 5, ["name"] = "default:cobble"}, {["x"] = 3, ["y"] = 4, ["z"] = 6, ["name"] = "default:cobble"}, {["x"] = 3, ["y"] = 4, ["z"] = 7, ["name"] = "default:cobble"}, {["x"] = 3, ["y"] = 4, ["z"] = 8, ["name"] = "default:cobble"}, {["x"] = 3, ["y"] = 4, ["z"] = 9, ["name"] = "default:cobble"}, {["x"] = 3, ["y"] = 4, ["z"] = 10, ["name"] = "default:cobble"}, {["x"] = 3, ["y"] = 4, ["z"] = 11, ["name"] = "default:cobble"}, {["x"] = 3, ["y"] = 4, ["z"] = 12, ["name"] = "default:cobble"}, {["x"] = 3, ["y"] = 4, ["z"] = 13, ["name"] = "default:cobble"}, {["x"] = 3, ["y"] = 4, ["z"] = 14, ["name"] = "default:cobble"}, {["x"] = 3, ["y"] = 4, ["z"] = 15, ["name"] = "default:cobble"}, {["x"] = 3, ["y"] = 4, ["z"] = 16, ["name"] = "default:cobble"}, {["x"] = 3, ["y"] = 4, ["z"] = 17, ["name"] = "default:cobble"}, {["x"] = 3, ["y"] = 4, ["z"] = 18, ["name"] = "default:cobble"}, {["x"] = 3, ["y"] = 5, ["param1"] = 158, ["z"] = 3, ["name"] = "xpanes:pane_flat"}, {["x"] = 3, ["y"] = 5, ["param1"] = 158, ["z"] = 18, ["name"] = "xpanes:pane_flat"}, {["x"] = 3, ["y"] = 6, ["param1"] = 174, ["z"] = 3, ["name"] = "xpanes:pane_flat"}, {["x"] = 3, ["y"] = 6, ["param1"] = 174, ["z"] = 18, ["name"] = "xpanes:pane_flat"}, {["x"] = 3, ["y"] = 7, ["param1"] = 158, ["z"] = 3, ["name"] = "xpanes:pane_flat"}, {["x"] = 3, ["y"] = 7, ["param1"] = 158, ["z"] = 18, ["name"] = "xpanes:pane_flat"}, {["x"] = 3, ["y"] = 8, ["param1"] = 142, ["z"] = 3, ["name"] = "xpanes:pane_flat"}, {["x"] = 3, ["y"] = 8, ["param1"] = 142, ["z"] = 18, ["name"] = "xpanes:pane_flat"}, {["x"] = 3, ["y"] = 9, ["param1"] = 126, ["z"] = 3, ["name"] = "xpanes:pane_flat"}, {["x"] = 3, ["y"] = 9, ["param1"] = 126, ["z"] = 18, ["name"] = "xpanes:pane_flat"}, {["x"] = 3, ["y"] = 10, ["param1"] = 126, ["z"] = 3, ["name"] = "lapis:lapis_cobble"}, {["x"] = 3, ["y"] = 10, ["param1"] = 141, ["z"] = 4, ["name"] = "default:glass"}, {["x"] = 3, ["y"] = 10, ["param1"] = 156, ["z"] = 5, ["name"] = "default:glass"}, {["x"] = 3, ["y"] = 10, ["param1"] = 156, ["z"] = 6, ["name"] = "default:glass"}, {["x"] = 3, ["y"] = 10, ["param1"] = 172, ["z"] = 7, ["name"] = "default:glass"}, {["x"] = 3, ["y"] = 10, ["param1"] = 156, ["z"] = 8, ["name"] = "default:glass"}, {["x"] = 3, ["y"] = 10, ["param1"] = 140, ["z"] = 9, ["name"] = "default:glass"}, {["x"] = 3, ["y"] = 10, ["param1"] = 156, ["z"] = 10, ["name"] = "default:glass"}, {["x"] = 3, ["y"] = 10, ["param1"] = 172, ["z"] = 11, ["name"] = "default:glass"}, {["x"] = 3, ["y"] = 10, ["param1"] = 157, ["z"] = 12, ["name"] = "default:glass"}, {["x"] = 3, ["y"] = 10, ["param1"] = 142, ["z"] = 13, ["name"] = "default:glass"}, {["x"] = 3, ["y"] = 10, ["param1"] = 157, ["z"] = 14, ["name"] = "default:glass"}, {["x"] = 3, ["y"] = 10, ["param1"] = 156, ["z"] = 15, ["name"] = "default:glass"}, {["x"] = 3, ["y"] = 10, ["param1"] = 140, ["z"] = 16, ["name"] = "default:glass"}, {["x"] = 3, ["y"] = 10, ["param1"] = 125, ["z"] = 17, ["name"] = "default:glass"}, {["x"] = 3, ["y"] = 10, ["param1"] = 110, ["z"] = 18, ["name"] = "lapis:lapis_cobble"}, {["x"] = 3, ["meta"] = {["fields"] = {["closed"] = "0"}, ["inventory"] = {}}, ["param2"] = 3, ["y"] = 11, ["param1"] = 158, ["z"] = 4, ["name"] = "homedecor:door_exterior_fancy_right"}, {["x"] = 3, ["y"] = 11, ["z"] = 12, ["name"] = "default:stonebrick"}, {["x"] = 3, ["y"] = 11, ["z"] = 17, ["name"] = "default:stonebrick"}, {["x"] = 3, ["param2"] = 3, ["y"] = 12, ["param1"] = 204, ["z"] = 7, ["name"] = "default:torch_wall"}, {["x"] = 3, ["param2"] = 3, ["y"] = 12, ["param1"] = 204, ["z"] = 11, ["name"] = "default:torch_wall"}, {["x"] = 3, ["y"] = 12, ["z"] = 12, ["name"] = "default:stonebrick"}, {["x"] = 3, ["y"] = 12, ["z"] = 17, ["name"] = "default:stonebrick"}, {["x"] = 3, ["y"] = 13, ["z"] = 4, ["name"] = "default:stonebrick"}, {["x"] = 3, ["y"] = 13, ["z"] = 12, ["name"] = "default:stonebrick"}, {["x"] = 3, ["param2"] = 3, ["y"] = 13, ["param1"] = 205, ["z"] = 14, ["name"] = "default:torch_wall"}, {["x"] = 3, ["param2"] = 3, ["y"] = 13, ["param1"] = 204, ["z"] = 15, ["name"] = "default:torch_wall"}, {["x"] = 3, ["y"] = 13, ["z"] = 17, ["name"] = "default:stonebrick"}, {["x"] = 3, ["y"] = 14, ["z"] = 4, ["name"] = "default:stonebrick"}, {["x"] = 3, ["y"] = 14, ["z"] = 5, ["name"] = "default:stonebrick"}, {["x"] = 3, ["y"] = 14, ["z"] = 6, ["name"] = "default:stonebrick"}, {["x"] = 3, ["y"] = 14, ["z"] = 7, ["name"] = "default:stonebrick"}, {["x"] = 3, ["y"] = 14, ["z"] = 8, ["name"] = "default:stonebrick"}, {["x"] = 3, ["y"] = 14, ["z"] = 9, ["name"] = "default:stonebrick"}, {["x"] = 3, ["y"] = 14, ["z"] = 10, ["name"] = "default:stonebrick"}, {["x"] = 3, ["y"] = 14, ["z"] = 11, ["name"] = "default:stonebrick"}, {["x"] = 3, ["y"] = 14, ["z"] = 12, ["name"] = "default:stonebrick"}, {["x"] = 3, ["y"] = 14, ["z"] = 13, ["name"] = "default:stonebrick"}, {["x"] = 3, ["y"] = 14, ["z"] = 14, ["name"] = "default:stonebrick"}, {["x"] = 3, ["y"] = 14, ["z"] = 15, ["name"] = "default:stonebrick"}, {["x"] = 3, ["y"] = 14, ["z"] = 16, ["name"] = "default:stonebrick"}, {["x"] = 3, ["y"] = 14, ["z"] = 17, ["name"] = "default:stonebrick"}, {["x"] = 3, ["y"] = 15, ["param1"] = 127, ["z"] = 7, ["name"] = "xpanes:pane"}, {["x"] = 3, ["param2"] = 3, ["y"] = 15, ["param1"] = 143, ["z"] = 8, ["name"] = "xpanes:pane_flat"}, {["x"] = 3, ["param2"] = 3, ["y"] = 15, ["param1"] = 143, ["z"] = 9, ["name"] = "xpanes:pane_flat"}, {["x"] = 3, ["param2"] = 3, ["y"] = 15, ["param1"] = 159, ["z"] = 10, ["name"] = "xpanes:pane_flat"}, {["x"] = 3, ["param2"] = 3, ["y"] = 15, ["param1"] = 175, ["z"] = 11, ["name"] = "xpanes:pane_flat"}, {["x"] = 3, ["param2"] = 3, ["y"] = 15, ["param1"] = 159, ["z"] = 12, ["name"] = "xpanes:pane_flat"}, {["x"] = 3, ["param2"] = 3, ["y"] = 15, ["param1"] = 143, ["z"] = 13, ["name"] = "xpanes:pane_flat"}, {["x"] = 3, ["y"] = 15, ["param1"] = 127, ["z"] = 14, ["name"] = "xpanes:pane"}, {["x"] = 3, ["y"] = 16, ["param1"] = 143, ["z"] = 7, ["name"] = "xpanes:pane"}, {["x"] = 3, ["param2"] = 3, ["y"] = 16, ["param1"] = 159, ["z"] = 8, ["name"] = "xpanes:pane_flat"}, {["x"] = 3, ["param2"] = 3, ["y"] = 16, ["param1"] = 159, ["z"] = 9, ["name"] = "xpanes:pane_flat"}, {["x"] = 3, ["param2"] = 3, ["y"] = 16, ["param1"] = 175, ["z"] = 10, ["name"] = "xpanes:pane_flat"}, {["x"] = 3, ["param2"] = 3, ["y"] = 16, ["param1"] = 191, ["z"] = 11, ["name"] = "xpanes:pane_flat"}, {["x"] = 3, ["param2"] = 3, ["y"] = 16, ["param1"] = 175, ["z"] = 12, ["name"] = "xpanes:pane_flat"}, {["x"] = 3, ["param2"] = 3, ["y"] = 16, ["param1"] = 159, ["z"] = 13, ["name"] = "xpanes:pane_flat"}, {["x"] = 3, ["y"] = 16, ["param1"] = 143, ["z"] = 14, ["name"] = "xpanes:pane"}, {["x"] = 3, ["y"] = 17, ["param1"] = 127, ["z"] = 7, ["name"] = "xpanes:pane"}, {["x"] = 3, ["param2"] = 3, ["y"] = 17, ["param1"] = 143, ["z"] = 8, ["name"] = "xpanes:pane_flat"}, {["x"] = 3, ["param2"] = 3, ["y"] = 17, ["param1"] = 143, ["z"] = 9, ["name"] = "xpanes:pane_flat"}, {["x"] = 3, ["param2"] = 3, ["y"] = 17, ["param1"] = 159, ["z"] = 10, ["name"] = "xpanes:pane_flat"}, {["x"] = 3, ["param2"] = 3, ["y"] = 17, ["param1"] = 175, ["z"] = 11, ["name"] = "xpanes:pane_flat"}, {["x"] = 3, ["param2"] = 3, ["y"] = 17, ["param1"] = 159, ["z"] = 12, ["name"] = "xpanes:pane_flat"}, {["x"] = 3, ["param2"] = 3, ["y"] = 17, ["param1"] = 143, ["z"] = 13, ["name"] = "xpanes:pane_flat"}, {["x"] = 3, ["y"] = 17, ["param1"] = 127, ["z"] = 14, ["name"] = "xpanes:pane"}, {["x"] = 4, ["y"] = 0, ["param1"] = 142, ["z"] = 2, ["name"] = "lapis:lapis_cobble"}, {["x"] = 4, ["y"] = 0, ["z"] = 3, ["name"] = "default:stonebrick"}, {["x"] = 4, ["y"] = 0, ["z"] = 4, ["name"] = "default:stonebrick"}, {["x"] = 4, ["y"] = 0, ["z"] = 5, ["name"] = "default:stonebrick"}, {["x"] = 4, ["y"] = 0, ["z"] = 6, ["name"] = "default:stonebrick"}, {["x"] = 4, ["y"] = 0, ["z"] = 7, ["name"] = "default:stonebrick"}, {["x"] = 4, ["y"] = 0, ["z"] = 8, ["name"] = "default:stonebrick"}, {["x"] = 4, ["y"] = 0, ["z"] = 9, ["name"] = "moretrees:sequoia_planks"}, {["x"] = 4, ["y"] = 0, ["z"] = 10, ["name"] = "moretrees:sequoia_planks"}, {["x"] = 4, ["y"] = 0, ["z"] = 11, ["name"] = "moretrees:fir_planks"}, {["x"] = 4, ["y"] = 0, ["z"] = 12, ["name"] = "default:stonebrick"}, {["x"] = 4, ["y"] = 0, ["z"] = 13, ["name"] = "default:stonebrick"}, {["x"] = 4, ["y"] = 0, ["z"] = 14, ["name"] = "default:stonebrick"}, {["x"] = 4, ["y"] = 0, ["z"] = 15, ["name"] = "default:stonebrick"}, {["x"] = 4, ["y"] = 0, ["z"] = 16, ["name"] = "moretrees:fir_planks"}, {["x"] = 4, ["y"] = 0, ["z"] = 17, ["name"] = "moretrees:sequoia_planks"}, {["x"] = 4, ["y"] = 0, ["z"] = 18, ["name"] = "moretrees:sequoia_planks"}, {["x"] = 4, ["y"] = 0, ["param1"] = 110, ["z"] = 19, ["name"] = "lapis:lapis_cobble"}, {["x"] = 4, ["y"] = 1, ["param1"] = 159, ["z"] = 2, ["name"] = "xpanes:pane_flat"}, {["x"] = 4, ["y"] = 1, ["param1"] = 127, ["z"] = 19, ["name"] = "xpanes:pane_flat"}, {["x"] = 4, ["y"] = 2, ["param1"] = 175, ["z"] = 2, ["name"] = "xpanes:pane_flat"}, {["x"] = 4, ["y"] = 2, ["param1"] = 143, ["z"] = 19, ["name"] = "xpanes:pane_flat"}, {["x"] = 4, ["y"] = 3, ["param1"] = 159, ["z"] = 2, ["name"] = "xpanes:pane_flat"}, {["x"] = 4, ["y"] = 3, ["param1"] = 159, ["z"] = 19, ["name"] = "xpanes:pane_flat"}, {["x"] = 4, ["y"] = 4, ["z"] = 3, ["name"] = "default:cobble"}, {["x"] = 4, ["y"] = 4, ["z"] = 4, ["name"] = "default:cobble"}, {["x"] = 4, ["y"] = 4, ["z"] = 5, ["name"] = "default:cobble"}, {["x"] = 4, ["y"] = 4, ["z"] = 6, ["name"] = "default:cobble"}, {["x"] = 4, ["y"] = 4, ["z"] = 7, ["name"] = "default:cobble"}, {["x"] = 4, ["y"] = 4, ["z"] = 8, ["name"] = "default:cobble"}, {["x"] = 4, ["y"] = 4, ["z"] = 9, ["name"] = "default:cobble"}, {["x"] = 4, ["y"] = 4, ["z"] = 10, ["name"] = "default:cobble"}, {["x"] = 4, ["y"] = 4, ["z"] = 11, ["name"] = "default:cobble"}, {["x"] = 4, ["y"] = 4, ["z"] = 12, ["name"] = "default:cobble"}, {["x"] = 4, ["y"] = 4, ["z"] = 13, ["name"] = "default:cobble"}, {["x"] = 4, ["y"] = 4, ["z"] = 14, ["name"] = "default:cobble"}, {["x"] = 4, ["y"] = 4, ["z"] = 15, ["name"] = "default:cobble"}, {["x"] = 4, ["y"] = 4, ["z"] = 16, ["name"] = "default:cobble"}, {["x"] = 4, ["y"] = 4, ["z"] = 17, ["name"] = "default:cobble"}, {["x"] = 4, ["y"] = 4, ["z"] = 18, ["name"] = "default:cobble"}, {["x"] = 4, ["y"] = 5, ["param1"] = 142, ["z"] = 3, ["name"] = "xpanes:pane_flat"}, {["x"] = 4, ["param2"] = 1, ["y"] = 5, ["param1"] = 123, ["z"] = 9, ["name"] = "moreblocks:stair_wood"}, {["x"] = 4, ["y"] = 5, ["param1"] = 142, ["z"] = 18, ["name"] = "xpanes:pane_flat"}, {["x"] = 4, ["y"] = 6, ["param1"] = 158, ["z"] = 3, ["name"] = "xpanes:pane_flat"}, {["x"] = 4, ["param2"] = 1, ["y"] = 6, ["param1"] = 139, ["z"] = 9, ["name"] = "moreblocks:stair_wood"}, {["x"] = 4, ["y"] = 6, ["param1"] = 158, ["z"] = 18, ["name"] = "xpanes:pane_flat"}, {["x"] = 4, ["y"] = 7, ["param1"] = 142, ["z"] = 3, ["name"] = "xpanes:pane_flat"}, {["x"] = 4, ["param2"] = 1, ["y"] = 7, ["param1"] = 123, ["z"] = 9, ["name"] = "moreblocks:stair_wood"}, {["x"] = 4, ["y"] = 7, ["param1"] = 142, ["z"] = 18, ["name"] = "xpanes:pane_flat"}, {["x"] = 4, ["y"] = 8, ["param1"] = 126, ["z"] = 3, ["name"] = "xpanes:pane_flat"}, {["x"] = 4, ["param2"] = 1, ["y"] = 8, ["param1"] = 107, ["z"] = 9, ["name"] = "moreblocks:stair_wood"}, {["x"] = 4, ["y"] = 8, ["param1"] = 126, ["z"] = 18, ["name"] = "xpanes:pane_flat"}, {["x"] = 4, ["y"] = 9, ["param1"] = 126, ["z"] = 3, ["name"] = "xpanes:pane_flat"}, {["x"] = 4, ["param2"] = 3, ["y"] = 9, ["param1"] = 107, ["z"] = 9, ["name"] = "moreblocks:stair_wood"}, {["x"] = 4, ["y"] = 9, ["param1"] = 110, ["z"] = 18, ["name"] = "xpanes:pane_flat"}, {["x"] = 4, ["y"] = 10, ["param1"] = 142, ["z"] = 3, ["name"] = "lapis:lapis_cobble"}, {["x"] = 4, ["y"] = 10, ["param1"] = 157, ["z"] = 4, ["name"] = "default:glass"}, {["x"] = 4, ["y"] = 10, ["param1"] = 172, ["z"] = 5, ["name"] = "default:glass"}, {["x"] = 4, ["y"] = 10, ["param1"] = 155, ["z"] = 6, ["name"] = "default:glass"}, {["x"] = 4, ["y"] = 10, ["param1"] = 155, ["z"] = 7, ["name"] = "default:glass"}, {["x"] = 4, ["y"] = 10, ["param1"] = 139, ["z"] = 8, ["name"] = "default:glass"}, {["x"] = 4, ["y"] = 10, ["param1"] = 140, ["z"] = 10, ["name"] = "default:glass"}, {["x"] = 4, ["y"] = 10, ["param1"] = 157, ["z"] = 11, ["name"] = "default:glass"}, {["x"] = 4, ["y"] = 10, ["param1"] = 142, ["z"] = 12, ["name"] = "default:glass"}, {["x"] = 4, ["y"] = 10, ["param1"] = 127, ["z"] = 13, ["name"] = "default:glass"}, {["x"] = 4, ["y"] = 10, ["param1"] = 142, ["z"] = 14, ["name"] = "default:glass"}, {["x"] = 4, ["y"] = 10, ["param1"] = 141, ["z"] = 15, ["name"] = "default:glass"}, {["x"] = 4, ["y"] = 10, ["param1"] = 124, ["z"] = 16, ["name"] = "default:glass"}, {["x"] = 4, ["y"] = 10, ["param1"] = 109, ["z"] = 17, ["name"] = "default:glass"}, {["x"] = 4, ["y"] = 10, ["param1"] = 94, ["z"] = 18, ["name"] = "lapis:lapis_cobble"}, {["x"] = 4, ["y"] = 11, ["z"] = 4, ["name"] = "default:stonebrick"}, {["x"] = 4, ["y"] = 11, ["z"] = 12, ["name"] = "default:stonebrick"}, {["x"] = 4, ["param2"] = 5, ["y"] = 11, ["param1"] = 143, ["z"] = 13, ["name"] = "default:ladder_wood"}, {["x"] = 4, ["y"] = 11, ["z"] = 17, ["name"] = "default:stonebrick"}, {["x"] = 4, ["y"] = 12, ["z"] = 4, ["name"] = "default:stonebrick"}, {["x"] = 4, ["param2"] = 5, ["y"] = 12, ["param1"] = 204, ["z"] = 5, ["name"] = "default:torch_wall"}, {["x"] = 4, ["y"] = 12, ["z"] = 12, ["name"] = "default:stonebrick"}, {["x"] = 4, ["param2"] = 5, ["y"] = 12, ["param1"] = 159, ["z"] = 13, ["name"] = "default:ladder_wood"}, {["x"] = 4, ["y"] = 12, ["z"] = 17, ["name"] = "default:stonebrick"}, {["x"] = 4, ["y"] = 13, ["z"] = 4, ["name"] = "default:stonebrick"}, {["x"] = 4, ["y"] = 13, ["z"] = 12, ["name"] = "default:stonebrick"}, {["x"] = 4, ["param2"] = 5, ["y"] = 13, ["param1"] = 175, ["z"] = 13, ["name"] = "default:ladder_wood"}, {["x"] = 4, ["y"] = 13, ["z"] = 17, ["name"] = "default:stonebrick"}, {["x"] = 4, ["y"] = 14, ["z"] = 4, ["name"] = "default:stonebrick"}, {["x"] = 4, ["y"] = 14, ["z"] = 5, ["name"] = "default:stonebrick"}, {["x"] = 4, ["y"] = 14, ["z"] = 6, ["name"] = "default:stonebrick"}, {["x"] = 4, ["y"] = 14, ["z"] = 7, ["name"] = "default:stonebrick"}, {["x"] = 4, ["y"] = 14, ["z"] = 8, ["name"] = "default:stonebrick"}, {["x"] = 4, ["y"] = 14, ["z"] = 9, ["name"] = "default:stonebrick"}, {["x"] = 4, ["y"] = 14, ["z"] = 10, ["name"] = "default:stonebrick"}, {["x"] = 4, ["y"] = 14, ["z"] = 11, ["name"] = "default:stonebrick"}, {["x"] = 4, ["y"] = 14, ["z"] = 12, ["name"] = "default:stonebrick"}, {["x"] = 4, ["param2"] = 5, ["y"] = 14, ["param1"] = 159, ["z"] = 13, ["name"] = "default:ladder_wood"}, {["x"] = 4, ["y"] = 14, ["z"] = 14, ["name"] = "default:stonebrick"}, {["x"] = 4, ["y"] = 14, ["z"] = 15, ["name"] = "default:stonebrick"}, {["x"] = 4, ["y"] = 14, ["z"] = 16, ["name"] = "default:stonebrick"}, {["x"] = 4, ["y"] = 14, ["z"] = 17, ["name"] = "default:stonebrick"}, {["x"] = 4, ["y"] = 15, ["param1"] = 143, ["z"] = 7, ["name"] = "xpanes:pane_flat"}, {["x"] = 4, ["y"] = 15, ["param1"] = 143, ["z"] = 14, ["name"] = "xpanes:pane_flat"}, {["x"] = 4, ["y"] = 16, ["param1"] = 159, ["z"] = 7, ["name"] = "xpanes:pane_flat"}, {["x"] = 4, ["param2"] = 3, ["y"] = 16, ["param1"] = 207, ["z"] = 11, ["name"] = "default:torch_wall"}, {["x"] = 4, ["y"] = 16, ["param1"] = 159, ["z"] = 14, ["name"] = "xpanes:pane_flat"}, {["x"] = 4, ["y"] = 17, ["param1"] = 143, ["z"] = 7, ["name"] = "xpanes:pane_flat"}, {["x"] = 4, ["y"] = 17, ["param1"] = 143, ["z"] = 14, ["name"] = "xpanes:pane_flat"}, {["x"] = 5, ["y"] = 0, ["param1"] = 126, ["z"] = 2, ["name"] = "lapis:lapis_cobble"}, {["x"] = 5, ["y"] = 0, ["z"] = 3, ["name"] = "default:stonebrick"}, {["x"] = 5, ["y"] = 0, ["z"] = 4, ["name"] = "default:stonebrick"}, {["x"] = 5, ["y"] = 0, ["z"] = 5, ["name"] = "default:stonebrick"}, {["x"] = 5, ["y"] = 0, ["z"] = 6, ["name"] = "default:stonebrick"}, {["x"] = 5, ["y"] = 0, ["z"] = 7, ["name"] = "default:stonebrick"}, {["x"] = 5, ["y"] = 0, ["z"] = 8, ["name"] = "default:stonebrick"}, {["x"] = 5, ["y"] = 0, ["z"] = 9, ["name"] = "moretrees:sequoia_planks"}, {["x"] = 5, ["y"] = 0, ["z"] = 10, ["name"] = "moretrees:sequoia_planks"}, {["x"] = 5, ["y"] = 0, ["z"] = 11, ["name"] = "moretrees:fir_planks"}, {["x"] = 5, ["y"] = 0, ["z"] = 12, ["name"] = "default:stonebrick"}, {["x"] = 5, ["y"] = 0, ["z"] = 13, ["name"] = "default:stonebrick"}, {["x"] = 5, ["y"] = 0, ["z"] = 14, ["name"] = "default:stonebrick"}, {["x"] = 5, ["y"] = 0, ["z"] = 15, ["name"] = "default:stonebrick"}, {["x"] = 5, ["y"] = 0, ["z"] = 16, ["name"] = "moretrees:fir_planks"}, {["x"] = 5, ["y"] = 0, ["z"] = 17, ["name"] = "moretrees:sequoia_planks"}, {["x"] = 5, ["y"] = 0, ["z"] = 18, ["name"] = "moretrees:sequoia_planks"}, {["x"] = 5, ["y"] = 0, ["param1"] = 126, ["z"] = 19, ["name"] = "lapis:lapis_cobble"}, {["x"] = 5, ["y"] = 1, ["param1"] = 143, ["z"] = 2, ["name"] = "xpanes:pane_flat"}, {["x"] = 5, ["meta"] = {["fields"] = {["infotext"] = "Wooden Locked Chest (owned by k)", ["owner"] = "k", ["formspec"] = "size[8,10]label[0,0;Wooden Chest]list[context;main;0,1;8,4;]list[current_player;main;0,6;8,4;]background[-0.19,-0.25;8.4,10.75;technic_chest_form_bg.png]background[0,1;8,4;technic_wooden_chest_inventory.png]background[0,6;8,4;technic_main_inventory.png]listring[]"}, ["inventory"] = {["main"] = {"default:cobble 99", "default:cobble 99", "default:cobble 99", "default:cobble 99", "default:cobble 99", "technic:lead_ingot", "default:tin_ingot", "lapis:lapis_stone 9", "default:cobble 99", "default:pick_steel 1 30212", "technic:granite 10", "default:cobble 99", "default:coal_lump 90", "default:steel_ingot 11", "lapis:pyrite_ingot 2", "moretrees:stair_sequoia_planks 6", "default:cobble 99", "", "", "", "default:cobble 99", "default:copper_ingot 12", "default:cobble 60", "", "", "technic:granite 7", "mesecons:wire_00000000_off 25", "", "", "", "", ""}}}, ["param2"] = 2, ["y"] = 1, ["z"] = 3, ["name"] = "default:chest_locked"}, {["x"] = 5, ["param2"] = 1, ["y"] = 1, ["param1"] = 124, ["z"] = 16, ["name"] = "moretrees:stair_sequoia_planks"}, {["x"] = 5, ["y"] = 1, ["param1"] = 143, ["z"] = 19, ["name"] = "xpanes:pane_flat"}, {["x"] = 5, ["y"] = 2, ["param1"] = 159, ["z"] = 2, ["name"] = "xpanes:pane_flat"}, {["x"] = 5, ["meta"] = {["fields"] = {["infotext"] = "Wooden Locked Chest (owned by k)", ["owner"] = "k", ["formspec"] = "size[8,10]label[0,0;Wooden Chest]list[context;main;0,1;8,4;]list[current_player;main;0,6;8,4;]background[-0.19,-0.25;8.4,10.75;technic_chest_form_bg.png]background[0,1;8,4;technic_wooden_chest_inventory.png]background[0,6;8,4;technic_main_inventory.png]listring[]"}, ["inventory"] = {["main"] = {"default:cobble 99", "default:cobble 99", "default:cobble 99", "default:sword_stone 1 10368", "default:axe_stone 1 4032", "", "", "", "", "", "", "", "", "", "", "", "", "", "", "", "", "", "", "", "", "", "", "", "", "", "", ""}}}, ["param2"] = 2, ["y"] = 2, ["z"] = 3, ["name"] = "default:chest_locked"}, {["x"] = 5, ["y"] = 2, ["param1"] = 159, ["z"] = 19, ["name"] = "xpanes:pane_flat"}, {["x"] = 5, ["y"] = 3, ["param1"] = 143, ["z"] = 2, ["name"] = "xpanes:pane_flat"}, {["x"] = 5, ["y"] = 3, ["param1"] = 175, ["z"] = 19, ["name"] = "xpanes:pane_flat"}, {["x"] = 5, ["y"] = 4, ["z"] = 3, ["name"] = "default:cobble"}, {["x"] = 5, ["y"] = 4, ["z"] = 4, ["name"] = "default:cobble"}, {["x"] = 5, ["y"] = 4, ["z"] = 5, ["name"] = "default:cobble"}, {["x"] = 5, ["y"] = 4, ["z"] = 6, ["name"] = "default:cobble"}, {["x"] = 5, ["y"] = 4, ["z"] = 7, ["name"] = "default:cobble"}, {["x"] = 5, ["y"] = 4, ["z"] = 8, ["name"] = "default:cobble"}, {["x"] = 5, ["y"] = 4, ["z"] = 9, ["name"] = "default:cobble"}, {["x"] = 5, ["y"] = 4, ["z"] = 10, ["name"] = "default:cobble"}, {["x"] = 5, ["y"] = 4, ["z"] = 11, ["name"] = "default:cobble"}, {["x"] = 5, ["y"] = 4, ["z"] = 12, ["name"] = "default:cobble"}, {["x"] = 5, ["y"] = 4, ["z"] = 13, ["name"] = "default:cobble"}, {["x"] = 5, ["y"] = 4, ["z"] = 14, ["name"] = "default:cobble"}, {["x"] = 5, ["y"] = 4, ["z"] = 15, ["name"] = "default:cobble"}, {["x"] = 5, ["y"] = 4, ["z"] = 17, ["name"] = "default:cobble"}, {["x"] = 5, ["y"] = 4, ["z"] = 18, ["name"] = "default:cobble"}, {["x"] = 5, ["y"] = 5, ["param1"] = 158, ["z"] = 3, ["name"] = "xpanes:pane_flat"}, {["x"] = 5, ["param2"] = 3, ["y"] = 5, ["param1"] = 106, ["z"] = 9, ["name"] = "moreblocks:stair_wood"}, {["x"] = 5, ["y"] = 5, ["param1"] = 142, ["z"] = 18, ["name"] = "xpanes:pane_flat"}, {["x"] = 5, ["y"] = 6, ["param1"] = 174, ["z"] = 3, ["name"] = "xpanes:pane_flat"}, {["x"] = 5, ["param2"] = 3, ["y"] = 6, ["param1"] = 122, ["z"] = 9, ["name"] = "moreblocks:stair_wood"}, {["x"] = 5, ["y"] = 6, ["param1"] = 158, ["z"] = 18, ["name"] = "xpanes:pane_flat"}, {["x"] = 5, ["y"] = 7, ["param1"] = 158, ["z"] = 3, ["name"] = "xpanes:pane_flat"}, {["x"] = 5, ["param2"] = 3, ["y"] = 7, ["param1"] = 106, ["z"] = 9, ["name"] = "moreblocks:stair_wood"}, {["x"] = 5, ["y"] = 7, ["param1"] = 142, ["z"] = 18, ["name"] = "xpanes:pane_flat"}, {["x"] = 5, ["y"] = 8, ["param1"] = 142, ["z"] = 3, ["name"] = "xpanes:pane_flat"}, {["x"] = 5, ["param2"] = 3, ["y"] = 8, ["param1"] = 90, ["z"] = 9, ["name"] = "moreblocks:stair_wood"}, {["x"] = 5, ["y"] = 8, ["param1"] = 126, ["z"] = 18, ["name"] = "xpanes:pane_flat"}, {["x"] = 5, ["y"] = 9, ["param1"] = 126, ["z"] = 3, ["name"] = "xpanes:pane_flat"}, {["x"] = 5, ["y"] = 9, ["param1"] = 110, ["z"] = 18, ["name"] = "xpanes:pane_flat"}, {["x"] = 5, ["y"] = 10, ["param1"] = 126, ["z"] = 3, ["name"] = "lapis:lapis_cobble"}, {["x"] = 5, ["y"] = 10, ["param1"] = 141, ["z"] = 4, ["name"] = "default:glass"}, {["x"] = 5, ["y"] = 10, ["param1"] = 156, ["z"] = 5, ["name"] = "default:glass"}, {["x"] = 5, ["y"] = 10, ["param1"] = 139, ["z"] = 6, ["name"] = "default:glass"}, {["x"] = 5, ["y"] = 10, ["param1"] = 138, ["z"] = 7, ["name"] = "default:glass"}, {["x"] = 5, ["y"] = 10, ["param1"] = 122, ["z"] = 8, ["name"] = "default:glass"}, {["x"] = 5, ["y"] = 10, ["param1"] = 139, ["z"] = 10, ["name"] = "default:glass"}, {["x"] = 5, ["y"] = 10, ["param1"] = 156, ["z"] = 11, ["name"] = "default:glass"}, {["x"] = 5, ["y"] = 10, ["param1"] = 141, ["z"] = 12, ["name"] = "default:glass"}, {["x"] = 5, ["y"] = 10, ["param1"] = 142, ["z"] = 13, ["name"] = "default:glass"}, {["x"] = 5, ["y"] = 10, ["param1"] = 125, ["z"] = 14, ["name"] = "default:glass"}, {["x"] = 5, ["y"] = 10, ["param1"] = 124, ["z"] = 15, ["name"] = "default:glass"}, {["x"] = 5, ["y"] = 10, ["param1"] = 140, ["z"] = 16, ["name"] = "default:glass"}, {["x"] = 5, ["y"] = 10, ["param1"] = 125, ["z"] = 17, ["name"] = "default:glass"}, {["x"] = 5, ["y"] = 10, ["param1"] = 110, ["z"] = 18, ["name"] = "lapis:lapis_cobble"}, {["x"] = 5, ["y"] = 11, ["z"] = 4, ["name"] = "default:stonebrick"}, {["x"] = 5, ["y"] = 11, ["z"] = 12, ["name"] = "default:stonebrick"}, {["x"] = 5, ["y"] = 11, ["z"] = 17, ["name"] = "default:stonebrick"}, {["x"] = 5, ["y"] = 12, ["z"] = 4, ["name"] = "default:stonebrick"}, {["x"] = 5, ["y"] = 12, ["z"] = 12, ["name"] = "default:stonebrick"}, {["x"] = 5, ["y"] = 12, ["z"] = 17, ["name"] = "default:stonebrick"}, {["x"] = 5, ["y"] = 13, ["z"] = 4, ["name"] = "default:stonebrick"}, {["x"] = 5, ["y"] = 13, ["z"] = 12, ["name"] = "default:stonebrick"}, {["x"] = 5, ["y"] = 13, ["z"] = 17, ["name"] = "default:stonebrick"}, {["x"] = 5, ["y"] = 14, ["z"] = 4, ["name"] = "default:stonebrick"}, {["x"] = 5, ["y"] = 14, ["z"] = 5, ["name"] = "default:stonebrick"}, {["x"] = 5, ["y"] = 14, ["z"] = 6, ["name"] = "default:stonebrick"}, {["x"] = 5, ["y"] = 14, ["z"] = 7, ["name"] = "default:stonebrick"}, {["x"] = 5, ["y"] = 14, ["z"] = 8, ["name"] = "default:stonebrick"}, {["x"] = 5, ["y"] = 14, ["z"] = 9, ["name"] = "default:stonebrick"}, {["x"] = 5, ["y"] = 14, ["z"] = 10, ["name"] = "default:stonebrick"}, {["x"] = 5, ["y"] = 14, ["z"] = 11, ["name"] = "default:stonebrick"}, {["x"] = 5, ["y"] = 14, ["z"] = 12, ["name"] = "default:stonebrick"}, {["x"] = 5, ["y"] = 14, ["z"] = 13, ["name"] = "default:stonebrick"}, {["x"] = 5, ["y"] = 14, ["z"] = 14, ["name"] = "default:stonebrick"}, {["x"] = 5, ["y"] = 14, ["z"] = 15, ["name"] = "default:stonebrick"}, {["x"] = 5, ["y"] = 14, ["z"] = 16, ["name"] = "default:stonebrick"}, {["x"] = 5, ["y"] = 14, ["z"] = 17, ["name"] = "default:stonebrick"}, {["x"] = 5, ["y"] = 15, ["param1"] = 159, ["z"] = 7, ["name"] = "xpanes:pane_flat"}, {["x"] = 5, ["y"] = 15, ["param1"] = 159, ["z"] = 14, ["name"] = "xpanes:pane_flat"}, {["x"] = 5, ["y"] = 16, ["param1"] = 175, ["z"] = 7, ["name"] = "xpanes:pane_flat"}, {["x"] = 5, ["y"] = 16, ["param1"] = 175, ["z"] = 14, ["name"] = "xpanes:pane_flat"}, {["x"] = 5, ["y"] = 17, ["param1"] = 159, ["z"] = 7, ["name"] = "xpanes:pane_flat"}, {["x"] = 5, ["y"] = 17, ["param1"] = 159, ["z"] = 14, ["name"] = "xpanes:pane_flat"}, {["x"] = 6, ["y"] = 0, ["param1"] = 110, ["z"] = 2, ["name"] = "lapis:lapis_cobble"}, {["x"] = 6, ["y"] = 0, ["z"] = 3, ["name"] = "default:stonebrick"}, {["x"] = 6, ["y"] = 0, ["z"] = 4, ["name"] = "default:stonebrick"}, {["x"] = 6, ["y"] = 0, ["z"] = 5, ["name"] = "default:stonebrick"}, {["x"] = 6, ["y"] = 0, ["z"] = 6, ["name"] = "default:stonebrick"}, {["x"] = 6, ["y"] = 0, ["z"] = 7, ["name"] = "default:stonebrick"}, {["x"] = 6, ["y"] = 0, ["z"] = 8, ["name"] = "default:stonebrick"}, {["x"] = 6, ["y"] = 0, ["z"] = 9, ["name"] = "moretrees:sequoia_planks"}, {["x"] = 6, ["y"] = 0, ["z"] = 10, ["name"] = "moretrees:sequoia_planks"}, {["x"] = 6, ["y"] = 0, ["z"] = 11, ["name"] = "moretrees:fir_planks"}, {["x"] = 6, ["y"] = 0, ["z"] = 12, ["name"] = "default:stonebrick"}, {["x"] = 6, ["y"] = 0, ["z"] = 13, ["name"] = "default:stonebrick"}, {["x"] = 6, ["y"] = 0, ["z"] = 14, ["name"] = "default:stonebrick"}, {["x"] = 6, ["y"] = 0, ["z"] = 15, ["name"] = "default:stonebrick"}, {["x"] = 6, ["y"] = 0, ["z"] = 16, ["name"] = "moretrees:fir_planks"}, {["x"] = 6, ["y"] = 0, ["z"] = 17, ["name"] = "moretrees:sequoia_planks"}, {["x"] = 6, ["y"] = 0, ["z"] = 18, ["name"] = "moretrees:sequoia_planks"}, {["x"] = 6, ["y"] = 0, ["param1"] = 142, ["z"] = 19, ["name"] = "lapis:lapis_cobble"}, {["x"] = 6, ["y"] = 1, ["param1"] = 127, ["z"] = 2, ["name"] = "xpanes:pane_flat"}, {["x"] = 6, ["meta"] = {["fields"] = {["infotext"] = "Wooden Locked Chest (owned by k)", ["owner"] = "k", ["formspec"] = "size[8,10]label[0,0;Wooden Chest]list[context;main;0,1;8,4;]list[current_player;main;0,6;8,4;]background[-0.19,-0.25;8.4,10.75;technic_chest_form_bg.png]background[0,1;8,4;technic_wooden_chest_inventory.png]background[0,6;8,4;technic_main_inventory.png]listring[]"}, ["inventory"] = {["main"] = {"", "", "", "", "", "", "", "", "", "", "", "", "", "", "", "", "", "", "", "", "", "", "", "", "", "", "", "", "", "", "", ""}}}, ["param2"] = 2, ["y"] = 1, ["z"] = 3, ["name"] = "default:chest_locked"}, {["x"] = 6, ["meta"] = {["fields"] = {["infotext"] = "Protection (owned by k)", ["owner"] = "k"}, ["inventory"] = {}}, ["y"] = 1, ["param1"] = 153, ["z"] = 9, ["name"] = "protector:protect"}, {["x"] = 6, ["meta"] = {["fields"] = {["infotext"] = "Protection (owned by k)", ["owner"] = "k"}, ["inventory"] = {}}, ["y"] = 1, ["param1"] = 137, ["z"] = 10, ["name"] = "protector:protect"}, {["x"] = 6, ["param2"] = 1, ["y"] = 1, ["param1"] = 140, ["z"] = 16, ["name"] = "moretrees:stair_sequoia_planks"}, {["x"] = 6, ["y"] = 1, ["param1"] = 159, ["z"] = 19, ["name"] = "xpanes:pane_flat"}, {["x"] = 6, ["y"] = 2, ["param1"] = 143, ["z"] = 2, ["name"] = "xpanes:pane_flat"}, {["x"] = 6, ["meta"] = {["fields"] = {["infotext"] = "Wooden Locked Chest (owned by k)", ["owner"] = "k", ["formspec"] = "size[8,10]label[0,0;Wooden Chest]list[context;main;0,1;8,4;]list[current_player;main;0,6;8,4;]background[-0.19,-0.25;8.4,10.75;technic_chest_form_bg.png]background[0,1;8,4;technic_wooden_chest_inventory.png]background[0,6;8,4;technic_main_inventory.png]listring[]"}, ["inventory"] = {["main"] = {"default:shovel_stone 1 5460", "default:pick_steel", "homedecor:door_exterior_fancy_left", "lapis:lapis_cobble 10", "default:sword_stone 1 6012", "mobs:leather", "technic:cast_iron_ingot", "throwing:arrow_stone 2", "", "", "", "", "", "", "", "", "", "", "", "", "", "", "", "", "", "", "", "", "", "", "", ""}}}, ["param2"] = 2, ["y"] = 2, ["z"] = 3, ["name"] = "default:chest_locked"}, {["x"] = 6, ["param2"] = 1, ["y"] = 2, ["param1"] = 156, ["z"] = 16, ["name"] = "moretrees:stair_sequoia_planks"}, {["x"] = 6, ["y"] = 2, ["param1"] = 175, ["z"] = 19, ["name"] = "xpanes:pane_flat"}, {["x"] = 6, ["y"] = 3, ["param1"] = 127, ["z"] = 2, ["name"] = "xpanes:pane_flat"}, {["x"] = 6, ["y"] = 3, ["param1"] = 204, ["z"] = 8, ["name"] = "default:torch_ceiling"}, {["x"] = 6, ["param2"] = 4, ["y"] = 3, ["param1"] = 206, ["z"] = 18, ["name"] = "default:torch_wall"}, {["x"] = 6, ["y"] = 3, ["param1"] = 191, ["z"] = 19, ["name"] = "xpanes:pane_flat"}, {["x"] = 6, ["y"] = 4, ["z"] = 3, ["name"] = "default:cobble"}, {["x"] = 6, ["y"] = 4, ["z"] = 4, ["name"] = "default:cobble"}, {["x"] = 6, ["y"] = 4, ["z"] = 5, ["name"] = "default:cobble"}, {["x"] = 6, ["y"] = 4, ["z"] = 6, ["name"] = "default:cobble"}, {["x"] = 6, ["y"] = 4, ["z"] = 7, ["name"] = "default:cobble"}, {["x"] = 6, ["y"] = 4, ["z"] = 8, ["name"] = "default:cobble"}, {["x"] = 6, ["y"] = 4, ["z"] = 9, ["name"] = "default:cobble"}, {["x"] = 6, ["y"] = 4, ["z"] = 10, ["name"] = "default:cobble"}, {["x"] = 6, ["y"] = 4, ["z"] = 11, ["name"] = "default:cobble"}, {["x"] = 6, ["y"] = 4, ["z"] = 12, ["name"] = "default:cobble"}, {["x"] = 6, ["y"] = 4, ["z"] = 13, ["name"] = "default:cobble"}, {["x"] = 6, ["y"] = 4, ["z"] = 14, ["name"] = "default:cobble"}, {["x"] = 6, ["y"] = 4, ["z"] = 15, ["name"] = "default:cobble"}, {["x"] = 6, ["y"] = 4, ["z"] = 17, ["name"] = "default:cobble"}, {["x"] = 6, ["y"] = 4, ["z"] = 18, ["name"] = "default:cobble"}, {["x"] = 6, ["y"] = 5, ["param1"] = 174, ["z"] = 3, ["name"] = "xpanes:pane_flat"}, {["x"] = 6, ["param2"] = 3, ["y"] = 5, ["param1"] = 105, ["z"] = 9, ["name"] = "moreblocks:stair_wood"}, {["x"] = 6, ["meta"] = {["fields"] = {["owner"] = "k", ["members"] = "Saw s", ["infotext"] = "Protection (owned by k)"}, ["inventory"] = {}}, ["y"] = 5, ["param1"] = 106, ["z"] = 10, ["name"] = "protector:protect"}, {["x"] = 6, ["meta"] = {["fields"] = {["owner"] = "k", ["members"] = "Saw", ["infotext"] = "Protection (owned by k)"}, ["inventory"] = {}}, ["y"] = 5, ["param1"] = 123, ["z"] = 11, ["name"] = "protector:protect"}, {["x"] = 6, ["y"] = 5, ["param1"] = 158, ["z"] = 18, ["name"] = "xpanes:pane_flat"}, {["x"] = 6, ["y"] = 6, ["param1"] = 190, ["z"] = 3, ["name"] = "xpanes:pane_flat"}, {["x"] = 6, ["param2"] = 5, ["y"] = 6, ["param1"] = 205, ["z"] = 4, ["name"] = "default:torch_wall"}, {["x"] = 6, ["param2"] = 3, ["y"] = 6, ["param1"] = 121, ["z"] = 9, ["name"] = "moreblocks:stair_wood"}, {["x"] = 6, ["y"] = 6, ["param1"] = 174, ["z"] = 18, ["name"] = "xpanes:pane_flat"}, {["x"] = 6, ["y"] = 7, ["param1"] = 174, ["z"] = 3, ["name"] = "xpanes:pane_flat"}, {["x"] = 6, ["param2"] = 3, ["y"] = 7, ["param1"] = 105, ["z"] = 9, ["name"] = "moreblocks:stair_wood"}, {["x"] = 6, ["y"] = 7, ["param1"] = 158, ["z"] = 18, ["name"] = "xpanes:pane_flat"}, {["x"] = 6, ["y"] = 8, ["param1"] = 158, ["z"] = 3, ["name"] = "xpanes:pane_flat"}, {["x"] = 6, ["y"] = 8, ["param1"] = 142, ["z"] = 18, ["name"] = "xpanes:pane_flat"}, {["x"] = 6, ["y"] = 9, ["param1"] = 142, ["z"] = 3, ["name"] = "xpanes:pane_flat"}, {["x"] = 6, ["y"] = 9, ["param1"] = 126, ["z"] = 18, ["name"] = "xpanes:pane_flat"}, {["x"] = 6, ["y"] = 10, ["param1"] = 126, ["z"] = 3, ["name"] = "lapis:lapis_cobble"}, {["x"] = 6, ["y"] = 10, ["param1"] = 141, ["z"] = 4, ["name"] = "default:glass"}, {["x"] = 6, ["y"] = 10, ["param1"] = 140, ["z"] = 5, ["name"] = "default:glass"}, {["x"] = 6, ["y"] = 10, ["param1"] = 123, ["z"] = 6, ["name"] = "default:glass"}, {["x"] = 6, ["y"] = 10, ["param1"] = 122, ["z"] = 7, ["name"] = "default:glass"}, {["x"] = 6, ["y"] = 10, ["param1"] = 121, ["z"] = 8, ["name"] = "default:glass"}, {["x"] = 6, ["y"] = 10, ["param1"] = 154, ["z"] = 10, ["name"] = "default:glass"}, {["x"] = 6, ["y"] = 10, ["param1"] = 171, ["z"] = 11, ["name"] = "default:glass"}, {["x"] = 6, ["y"] = 10, ["param1"] = 156, ["z"] = 12, ["name"] = "default:glass"}, {["x"] = 6, ["y"] = 10, ["param1"] = 157, ["z"] = 13, ["name"] = "default:glass"}, {["x"] = 6, ["y"] = 10, ["param1"] = 140, ["z"] = 14, ["name"] = "default:glass"}, {["x"] = 6, ["y"] = 10, ["param1"] = 139, ["z"] = 15, ["name"] = "default:glass"}, {["x"] = 6, ["y"] = 10, ["param1"] = 156, ["z"] = 16, ["name"] = "default:glass"}, {["x"] = 6, ["y"] = 10, ["param1"] = 141, ["z"] = 17, ["name"] = "default:glass"}, {["x"] = 6, ["y"] = 10, ["param1"] = 126, ["z"] = 18, ["name"] = "lapis:lapis_cobble"}, {["x"] = 6, ["y"] = 11, ["z"] = 4, ["name"] = "default:stonebrick"}, {["x"] = 6, ["y"] = 11, ["z"] = 12, ["name"] = "default:stonebrick"}, {["x"] = 6, ["y"] = 11, ["z"] = 17, ["name"] = "default:stonebrick"}, {["x"] = 6, ["y"] = 12, ["z"] = 4, ["name"] = "default:stonebrick"}, {["x"] = 6, ["param2"] = 4, ["y"] = 12, ["param1"] = 204, ["z"] = 11, ["name"] = "default:torch_wall"}, {["x"] = 6, ["y"] = 12, ["z"] = 12, ["name"] = "default:stonebrick"}, {["x"] = 6, ["y"] = 12, ["z"] = 17, ["name"] = "default:stonebrick"}, {["x"] = 6, ["y"] = 13, ["z"] = 4, ["name"] = "default:stonebrick"}, {["x"] = 6, ["y"] = 13, ["z"] = 12, ["name"] = "default:stonebrick"}, {["x"] = 6, ["param2"] = 5, ["y"] = 13, ["param1"] = 205, ["z"] = 13, ["name"] = "default:torch_wall"}, {["x"] = 6, ["param2"] = 4, ["y"] = 13, ["param1"] = 204, ["z"] = 16, ["name"] = "default:torch_wall"}, {["x"] = 6, ["y"] = 13, ["z"] = 17, ["name"] = "default:stonebrick"}, {["x"] = 6, ["y"] = 14, ["z"] = 4, ["name"] = "default:stonebrick"}, {["x"] = 6, ["y"] = 14, ["z"] = 5, ["name"] = "default:stonebrick"}, {["x"] = 6, ["y"] = 14, ["z"] = 6, ["name"] = "default:stonebrick"}, {["x"] = 6, ["y"] = 14, ["z"] = 7, ["name"] = "default:stonebrick"}, {["x"] = 6, ["y"] = 14, ["z"] = 8, ["name"] = "default:stonebrick"}, {["x"] = 6, ["y"] = 14, ["z"] = 9, ["name"] = "default:stonebrick"}, {["x"] = 6, ["y"] = 14, ["z"] = 10, ["name"] = "default:stonebrick"}, {["x"] = 6, ["y"] = 14, ["z"] = 11, ["name"] = "default:stonebrick"}, {["x"] = 6, ["y"] = 14, ["z"] = 12, ["name"] = "default:stonebrick"}, {["x"] = 6, ["y"] = 14, ["z"] = 13, ["name"] = "default:stonebrick"}, {["x"] = 6, ["y"] = 14, ["z"] = 14, ["name"] = "default:stonebrick"}, {["x"] = 6, ["y"] = 14, ["z"] = 15, ["name"] = "default:stonebrick"}, {["x"] = 6, ["y"] = 14, ["z"] = 16, ["name"] = "default:stonebrick"}, {["x"] = 6, ["y"] = 14, ["z"] = 17, ["name"] = "default:stonebrick"}, {["x"] = 6, ["y"] = 15, ["param1"] = 175, ["z"] = 7, ["name"] = "xpanes:pane_flat"}, {["x"] = 6, ["y"] = 15, ["param1"] = 175, ["z"] = 14, ["name"] = "xpanes:pane_flat"}, {["x"] = 6, ["y"] = 16, ["param1"] = 191, ["z"] = 7, ["name"] = "xpanes:pane_flat"}, {["x"] = 6, ["param2"] = 5, ["y"] = 16, ["param1"] = 207, ["z"] = 8, ["name"] = "default:torch_wall"}, {["x"] = 6, ["param2"] = 4, ["y"] = 16, ["param1"] = 207, ["z"] = 13, ["name"] = "default:torch_wall"}, {["x"] = 6, ["y"] = 16, ["param1"] = 191, ["z"] = 14, ["name"] = "xpanes:pane_flat"}, {["x"] = 6, ["y"] = 17, ["param1"] = 175, ["z"] = 7, ["name"] = "xpanes:pane_flat"}, {["x"] = 6, ["y"] = 17, ["param1"] = 175, ["z"] = 14, ["name"] = "xpanes:pane_flat"}, {["x"] = 7, ["y"] = 0, ["param1"] = 110, ["z"] = 2, ["name"] = "lapis:lapis_cobble"}, {["x"] = 7, ["y"] = 0, ["z"] = 3, ["name"] = "default:stonebrick"}, {["x"] = 7, ["y"] = 0, ["z"] = 4, ["name"] = "default:stonebrick"}, {["x"] = 7, ["y"] = 0, ["z"] = 5, ["name"] = "default:stonebrick"}, {["x"] = 7, ["y"] = 0, ["z"] = 6, ["name"] = "default:stonebrick"}, {["x"] = 7, ["y"] = 0, ["z"] = 7, ["name"] = "default:stonebrick"}, {["x"] = 7, ["y"] = 0, ["z"] = 8, ["name"] = "default:stonebrick"}, {["x"] = 7, ["y"] = 0, ["z"] = 9, ["name"] = "moretrees:sequoia_planks"}, {["x"] = 7, ["y"] = 0, ["z"] = 10, ["name"] = "moretrees:sequoia_planks"}, {["x"] = 7, ["y"] = 0, ["z"] = 11, ["name"] = "moretrees:fir_planks"}, {["x"] = 7, ["y"] = 0, ["z"] = 12, ["name"] = "default:stonebrick"}, {["x"] = 7, ["y"] = 0, ["z"] = 13, ["name"] = "default:stonebrick"}, {["x"] = 7, ["y"] = 0, ["z"] = 14, ["name"] = "default:stonebrick"}, {["x"] = 7, ["y"] = 0, ["z"] = 15, ["name"] = "default:stonebrick"}, {["x"] = 7, ["y"] = 0, ["z"] = 16, ["name"] = "moretrees:fir_planks"}, {["x"] = 7, ["y"] = 0, ["z"] = 17, ["name"] = "moretrees:sequoia_planks"}, {["x"] = 7, ["y"] = 0, ["z"] = 18, ["name"] = "moretrees:sequoia_planks"}, {["x"] = 7, ["y"] = 0, ["param1"] = 126, ["z"] = 19, ["name"] = "lapis:lapis_cobble"}, {["x"] = 7, ["y"] = 1, ["param1"] = 127, ["z"] = 2, ["name"] = "xpanes:pane_flat"}, {["x"] = 7, ["param2"] = 1, ["y"] = 1, ["param1"] = 156, ["z"] = 16, ["name"] = "moretrees:stair_sequoia_planks"}, {["x"] = 7, ["y"] = 1, ["param1"] = 143, ["z"] = 19, ["name"] = "xpanes:pane_flat"}, {["x"] = 7, ["y"] = 2, ["param1"] = 143, ["z"] = 2, ["name"] = "xpanes:pane_flat"}, {["x"] = 7, ["param2"] = 1, ["y"] = 2, ["param1"] = 172, ["z"] = 16, ["name"] = "moretrees:stair_sequoia_planks"}, {["x"] = 7, ["y"] = 2, ["param1"] = 159, ["z"] = 19, ["name"] = "xpanes:pane_flat"}, {["x"] = 7, ["y"] = 3, ["param1"] = 127, ["z"] = 2, ["name"] = "xpanes:pane_flat"}, {["x"] = 7, ["y"] = 3, ["param1"] = 204, ["z"] = 15, ["name"] = "default:torch_ceiling"}, {["x"] = 7, ["param2"] = 1, ["y"] = 3, ["param1"] = 188, ["z"] = 16, ["name"] = "moretrees:stair_sequoia_planks"}, {["x"] = 7, ["y"] = 3, ["param1"] = 175, ["z"] = 19, ["name"] = "xpanes:pane_flat"}, {["x"] = 7, ["y"] = 4, ["z"] = 3, ["name"] = "default:cobble"}, {["x"] = 7, ["y"] = 4, ["z"] = 4, ["name"] = "default:cobble"}, {["x"] = 7, ["y"] = 4, ["z"] = 5, ["name"] = "default:cobble"}, {["x"] = 7, ["y"] = 4, ["z"] = 6, ["name"] = "default:cobble"}, {["x"] = 7, ["y"] = 4, ["z"] = 7, ["name"] = "default:cobble"}, {["x"] = 7, ["y"] = 4, ["z"] = 8, ["name"] = "default:cobble"}, {["x"] = 7, ["y"] = 4, ["z"] = 9, ["name"] = "default:cobble"}, {["x"] = 7, ["y"] = 4, ["z"] = 10, ["name"] = "default:cobble"}, {["x"] = 7, ["y"] = 4, ["z"] = 11, ["name"] = "default:cobble"}, {["x"] = 7, ["y"] = 4, ["z"] = 12, ["name"] = "default:cobble"}, {["x"] = 7, ["y"] = 4, ["z"] = 13, ["name"] = "default:cobble"}, {["x"] = 7, ["y"] = 4, ["z"] = 14, ["name"] = "default:cobble"}, {["x"] = 7, ["y"] = 4, ["z"] = 15, ["name"] = "default:cobble"}, {["x"] = 7, ["y"] = 4, ["z"] = 17, ["name"] = "default:cobble"}, {["x"] = 7, ["y"] = 4, ["z"] = 18, ["name"] = "default:cobble"}, {["x"] = 7, ["y"] = 5, ["param1"] = 158, ["z"] = 3, ["name"] = "xpanes:pane_flat"}, {["x"] = 7, ["param2"] = 3, ["y"] = 5, ["param1"] = 104, ["z"] = 9, ["name"] = "moreblocks:stair_wood"}, {["x"] = 7, ["y"] = 5, ["param1"] = 174, ["z"] = 18, ["name"] = "xpanes:pane_flat"}, {["x"] = 7, ["y"] = 6, ["param1"] = 174, ["z"] = 3, ["name"] = "xpanes:pane_flat"}, {["x"] = 7, ["param2"] = 3, ["y"] = 6, ["param1"] = 120, ["z"] = 9, ["name"] = "moreblocks:stair_wood"}, {["x"] = 7, ["param2"] = 4, ["y"] = 6, ["param1"] = 205, ["z"] = 17, ["name"] = "default:torch_wall"}, {["x"] = 7, ["y"] = 6, ["param1"] = 190, ["z"] = 18, ["name"] = "xpanes:pane_flat"}, {["x"] = 7, ["y"] = 7, ["param1"] = 158, ["z"] = 3, ["name"] = "xpanes:pane_flat"}, {["x"] = 7, ["y"] = 7, ["param1"] = 174, ["z"] = 18, ["name"] = "xpanes:pane_flat"}, {["x"] = 7, ["y"] = 8, ["param1"] = 142, ["z"] = 3, ["name"] = "xpanes:pane_flat"}, {["x"] = 7, ["y"] = 8, ["param1"] = 158, ["z"] = 18, ["name"] = "xpanes:pane_flat"}, {["x"] = 7, ["y"] = 9, ["param1"] = 126, ["z"] = 3, ["name"] = "xpanes:pane_flat"}, {["x"] = 7, ["y"] = 9, ["param1"] = 142, ["z"] = 18, ["name"] = "xpanes:pane_flat"}, {["x"] = 7, ["y"] = 10, ["param1"] = 110, ["z"] = 3, ["name"] = "lapis:lapis_cobble"}, {["x"] = 7, ["y"] = 10, ["param1"] = 125, ["z"] = 4, ["name"] = "default:glass"}, {["x"] = 7, ["y"] = 10, ["param1"] = 140, ["z"] = 5, ["name"] = "default:glass"}, {["x"] = 7, ["y"] = 10, ["param1"] = 123, ["z"] = 6, ["name"] = "default:glass"}, {["x"] = 7, ["y"] = 10, ["param1"] = 138, ["z"] = 7, ["name"] = "default:glass"}, {["x"] = 7, ["y"] = 10, ["param1"] = 121, ["z"] = 8, ["name"] = "default:glass"}, {["x"] = 7, ["y"] = 10, ["param1"] = 120, ["z"] = 9, ["name"] = "default:glass"}, {["x"] = 7, ["y"] = 10, ["param1"] = 137, ["z"] = 10, ["name"] = "default:glass"}, {["x"] = 7, ["y"] = 10, ["param1"] = 154, ["z"] = 11, ["name"] = "default:glass"}, {["x"] = 7, ["y"] = 10, ["param1"] = 139, ["z"] = 12, ["name"] = "default:glass"}, {["x"] = 7, ["y"] = 10, ["param1"] = 156, ["z"] = 13, ["name"] = "default:glass"}, {["x"] = 7, ["y"] = 10, ["param1"] = 139, ["z"] = 14, ["name"] = "default:glass"}, {["x"] = 7, ["y"] = 10, ["param1"] = 139, ["z"] = 15, ["name"] = "default:glass"}, {["x"] = 7, ["y"] = 10, ["param1"] = 156, ["z"] = 16, ["name"] = "default:glass"}, {["x"] = 7, ["y"] = 10, ["param1"] = 141, ["z"] = 17, ["name"] = "default:glass"}, {["x"] = 7, ["y"] = 10, ["param1"] = 126, ["z"] = 18, ["name"] = "lapis:lapis_cobble"}, {["x"] = 7, ["y"] = 11, ["z"] = 4, ["name"] = "default:stonebrick"}, {["x"] = 7, ["meta"] = {["fields"] = {["owner"] = "k", ["members"] = "Saw f", ["infotext"] = "Protection (owned by k)"}, ["inventory"] = {}}, ["y"] = 11, ["param1"] = 136, ["z"] = 9, ["name"] = "protector:protect"}, {["x"] = 7, ["y"] = 11, ["z"] = 12, ["name"] = "default:stonebrick"}, {["x"] = 7, ["y"] = 11, ["z"] = 17, ["name"] = "default:stonebrick"}, {["x"] = 7, ["y"] = 12, ["z"] = 4, ["name"] = "default:stonebrick"}, {["x"] = 7, ["y"] = 12, ["z"] = 12, ["name"] = "default:stonebrick"}, {["x"] = 7, ["y"] = 12, ["z"] = 17, ["name"] = "default:stonebrick"}, {["x"] = 7, ["y"] = 13, ["z"] = 4, ["name"] = "default:stonebrick"}, {["x"] = 7, ["y"] = 13, ["z"] = 12, ["name"] = "default:stonebrick"}, {["x"] = 7, ["param2"] = 5, ["y"] = 13, ["param1"] = 204, ["z"] = 13, ["name"] = "default:torch_wall"}, {["x"] = 7, ["param2"] = 4, ["y"] = 13, ["param1"] = 204, ["z"] = 16, ["name"] = "default:torch_wall"}, {["x"] = 7, ["y"] = 13, ["z"] = 17, ["name"] = "default:stonebrick"}, {["x"] = 7, ["y"] = 14, ["z"] = 4, ["name"] = "default:stonebrick"}, {["x"] = 7, ["y"] = 14, ["z"] = 5, ["name"] = "default:stonebrick"}, {["x"] = 7, ["y"] = 14, ["z"] = 6, ["name"] = "default:stonebrick"}, {["x"] = 7, ["y"] = 14, ["z"] = 7, ["name"] = "default:stonebrick"}, {["x"] = 7, ["y"] = 14, ["z"] = 8, ["name"] = "default:stonebrick"}, {["x"] = 7, ["y"] = 14, ["z"] = 9, ["name"] = "default:stonebrick"}, {["x"] = 7, ["y"] = 14, ["z"] = 10, ["name"] = "default:stonebrick"}, {["x"] = 7, ["y"] = 14, ["z"] = 11, ["name"] = "default:stonebrick"}, {["x"] = 7, ["y"] = 14, ["z"] = 12, ["name"] = "default:stonebrick"}, {["x"] = 7, ["y"] = 14, ["z"] = 13, ["name"] = "default:stonebrick"}, {["x"] = 7, ["y"] = 14, ["z"] = 14, ["name"] = "default:stonebrick"}, {["x"] = 7, ["y"] = 14, ["z"] = 15, ["name"] = "default:stonebrick"}, {["x"] = 7, ["y"] = 14, ["z"] = 16, ["name"] = "default:stonebrick"}, {["x"] = 7, ["y"] = 14, ["z"] = 17, ["name"] = "default:stonebrick"}, {["x"] = 7, ["y"] = 15, ["param1"] = 159, ["z"] = 7, ["name"] = "xpanes:pane_flat"}, {["x"] = 7, ["y"] = 15, ["param1"] = 159, ["z"] = 14, ["name"] = "xpanes:pane_flat"}, {["x"] = 7, ["y"] = 16, ["param1"] = 175, ["z"] = 7, ["name"] = "xpanes:pane_flat"}, {["x"] = 7, ["y"] = 16, ["param1"] = 175, ["z"] = 14, ["name"] = "xpanes:pane_flat"}, {["x"] = 7, ["y"] = 17, ["param1"] = 159, ["z"] = 7, ["name"] = "xpanes:pane_flat"}, {["x"] = 7, ["y"] = 17, ["param1"] = 159, ["z"] = 14, ["name"] = "xpanes:pane_flat"}, {["x"] = 8, ["y"] = 0, ["param1"] = 126, ["z"] = 2, ["name"] = "lapis:lapis_cobble"}, {["x"] = 8, ["y"] = 0, ["z"] = 3, ["name"] = "default:stonebrick"}, {["x"] = 8, ["y"] = 0, ["z"] = 4, ["name"] = "default:stonebrick"}, {["x"] = 8, ["y"] = 0, ["z"] = 5, ["name"] = "default:stonebrick"}, {["x"] = 8, ["y"] = 0, ["z"] = 6, ["name"] = "default:stonebrick"}, {["x"] = 8, ["y"] = 0, ["z"] = 7, ["name"] = "default:stonebrick"}, {["x"] = 8, ["y"] = 0, ["z"] = 8, ["name"] = "default:stonebrick"}, {["x"] = 8, ["y"] = 0, ["z"] = 9, ["name"] = "moretrees:sequoia_planks"}, {["x"] = 8, ["y"] = 0, ["z"] = 10, ["name"] = "moretrees:sequoia_planks"}, {["x"] = 8, ["y"] = 0, ["z"] = 11, ["name"] = "moretrees:fir_planks"}, {["x"] = 8, ["y"] = 0, ["z"] = 12, ["name"] = "default:stonebrick"}, {["x"] = 8, ["y"] = 0, ["z"] = 13, ["name"] = "default:stonebrick"}, {["x"] = 8, ["y"] = 0, ["z"] = 14, ["name"] = "default:stonebrick"}, {["x"] = 8, ["y"] = 0, ["z"] = 15, ["name"] = "default:stonebrick"}, {["x"] = 8, ["y"] = 0, ["z"] = 16, ["name"] = "moretrees:fir_planks"}, {["x"] = 8, ["y"] = 0, ["z"] = 17, ["name"] = "moretrees:sequoia_planks"}, {["x"] = 8, ["y"] = 0, ["z"] = 18, ["name"] = "moretrees:sequoia_planks"}, {["x"] = 8, ["y"] = 0, ["param1"] = 126, ["z"] = 19, ["name"] = "lapis:lapis_cobble"}, {["x"] = 8, ["y"] = 1, ["param1"] = 143, ["z"] = 2, ["name"] = "xpanes:pane_flat"}, {["x"] = 8, ["param2"] = 1, ["y"] = 1, ["param1"] = 140, ["z"] = 16, ["name"] = "moretrees:stair_sequoia_planks"}, {["x"] = 8, ["y"] = 1, ["param1"] = 127, ["z"] = 19, ["name"] = "xpanes:pane_flat"}, {["x"] = 8, ["y"] = 2, ["param1"] = 159, ["z"] = 2, ["name"] = "xpanes:pane_flat"}, {["x"] = 8, ["param2"] = 1, ["y"] = 2, ["param1"] = 156, ["z"] = 16, ["name"] = "moretrees:stair_sequoia_planks"}, {["x"] = 8, ["y"] = 2, ["param1"] = 143, ["z"] = 19, ["name"] = "xpanes:pane_flat"}, {["x"] = 8, ["y"] = 3, ["param1"] = 143, ["z"] = 2, ["name"] = "xpanes:pane_flat"}, {["x"] = 8, ["param2"] = 1, ["y"] = 3, ["param1"] = 172, ["z"] = 16, ["name"] = "moretrees:stair_sequoia_planks"}, {["x"] = 8, ["y"] = 3, ["param1"] = 159, ["z"] = 19, ["name"] = "xpanes:pane_flat"}, {["x"] = 8, ["y"] = 4, ["z"] = 3, ["name"] = "default:cobble"}, {["x"] = 8, ["y"] = 4, ["z"] = 4, ["name"] = "default:cobble"}, {["x"] = 8, ["y"] = 4, ["z"] = 5, ["name"] = "default:cobble"}, {["x"] = 8, ["y"] = 4, ["z"] = 6, ["name"] = "default:cobble"}, {["x"] = 8, ["y"] = 4, ["z"] = 7, ["name"] = "default:cobble"}, {["x"] = 8, ["y"] = 4, ["z"] = 8, ["name"] = "default:cobble"}, {["x"] = 8, ["y"] = 4, ["z"] = 9, ["name"] = "default:cobble"}, {["x"] = 8, ["y"] = 4, ["z"] = 10, ["name"] = "default:cobble"}, {["x"] = 8, ["y"] = 4, ["z"] = 11, ["name"] = "default:cobble"}, {["x"] = 8, ["y"] = 4, ["z"] = 12, ["name"] = "default:cobble"}, {["x"] = 8, ["y"] = 4, ["z"] = 13, ["name"] = "default:cobble"}, {["x"] = 8, ["y"] = 4, ["z"] = 14, ["name"] = "default:cobble"}, {["x"] = 8, ["y"] = 4, ["z"] = 15, ["name"] = "default:cobble"}, {["x"] = 8, ["param2"] = 1, ["y"] = 4, ["param1"] = 155, ["z"] = 16, ["name"] = "moretrees:stair_sequoia_planks"}, {["x"] = 8, ["y"] = 4, ["z"] = 17, ["name"] = "default:cobble"}, {["x"] = 8, ["y"] = 4, ["z"] = 18, ["name"] = "default:cobble"}, {["x"] = 8, ["y"] = 5, ["param1"] = 142, ["z"] = 3, ["name"] = "xpanes:pane_flat"}, {["x"] = 8, ["param2"] = 3, ["y"] = 5, ["param1"] = 120, ["z"] = 9, ["name"] = "moreblocks:stair_wood"}, {["x"] = 8, ["y"] = 5, ["param1"] = 158, ["z"] = 18, ["name"] = "xpanes:pane_flat"}, {["x"] = 8, ["y"] = 6, ["param1"] = 158, ["z"] = 3, ["name"] = "xpanes:pane_flat"}, {["x"] = 8, ["y"] = 6, ["param1"] = 174, ["z"] = 18, ["name"] = "xpanes:pane_flat"}, {["x"] = 8, ["y"] = 7, ["param1"] = 142, ["z"] = 3, ["name"] = "xpanes:pane_flat"}, {["x"] = 8, ["y"] = 7, ["param1"] = 158, ["z"] = 18, ["name"] = "xpanes:pane_flat"}, {["x"] = 8, ["y"] = 8, ["param1"] = 126, ["z"] = 3, ["name"] = "xpanes:pane_flat"}, {["x"] = 8, ["y"] = 8, ["param1"] = 142, ["z"] = 18, ["name"] = "xpanes:pane_flat"}, {["x"] = 8, ["y"] = 9, ["param1"] = 110, ["z"] = 3, ["name"] = "xpanes:pane_flat"}, {["x"] = 8, ["y"] = 9, ["param1"] = 126, ["z"] = 18, ["name"] = "xpanes:pane_flat"}, {["x"] = 8, ["y"] = 10, ["param1"] = 126, ["z"] = 3, ["name"] = "lapis:lapis_cobble"}, {["x"] = 8, ["y"] = 10, ["param1"] = 141, ["z"] = 4, ["name"] = "default:glass"}, {["x"] = 8, ["y"] = 10, ["param1"] = 156, ["z"] = 5, ["name"] = "default:glass"}, {["x"] = 8, ["y"] = 10, ["param1"] = 139, ["z"] = 6, ["name"] = "default:glass"}, {["x"] = 8, ["y"] = 10, ["param1"] = 154, ["z"] = 7, ["name"] = "default:glass"}, {["x"] = 8, ["y"] = 10, ["param1"] = 137, ["z"] = 8, ["name"] = "default:glass"}, {["x"] = 8, ["y"] = 10, ["param1"] = 136, ["z"] = 9, ["name"] = "default:glass"}, {["x"] = 8, ["y"] = 10, ["param1"] = 136, ["z"] = 10, ["name"] = "default:glass"}, {["x"] = 8, ["y"] = 10, ["param1"] = 153, ["z"] = 11, ["name"] = "default:glass"}, {["x"] = 8, ["y"] = 10, ["param1"] = 138, ["z"] = 12, ["name"] = "default:glass"}, {["x"] = 8, ["y"] = 10, ["param1"] = 139, ["z"] = 13, ["name"] = "default:glass"}, {["x"] = 8, ["y"] = 10, ["param1"] = 138, ["z"] = 14, ["name"] = "default:glass"}, {["x"] = 8, ["y"] = 10, ["param1"] = 139, ["z"] = 15, ["name"] = "default:glass"}, {["x"] = 8, ["y"] = 10, ["param1"] = 140, ["z"] = 16, ["name"] = "default:glass"}, {["x"] = 8, ["y"] = 10, ["param1"] = 125, ["z"] = 17, ["name"] = "default:glass"}, {["x"] = 8, ["y"] = 10, ["param1"] = 110, ["z"] = 18, ["name"] = "lapis:lapis_cobble"}, {["x"] = 8, ["y"] = 11, ["z"] = 4, ["name"] = "default:stonebrick"}, {["x"] = 8, ["y"] = 11, ["z"] = 12, ["name"] = "default:stonebrick"}, {["x"] = 8, ["y"] = 11, ["z"] = 17, ["name"] = "default:stonebrick"}, {["x"] = 8, ["y"] = 12, ["z"] = 4, ["name"] = "default:stonebrick"}, {["x"] = 8, ["y"] = 12, ["z"] = 12, ["name"] = "default:stonebrick"}, {["x"] = 8, ["y"] = 12, ["z"] = 17, ["name"] = "default:stonebrick"}, {["x"] = 8, ["y"] = 13, ["z"] = 4, ["name"] = "default:stonebrick"}, {["x"] = 8, ["y"] = 13, ["z"] = 12, ["name"] = "default:stonebrick"}, {["x"] = 8, ["y"] = 13, ["z"] = 17, ["name"] = "default:stonebrick"}, {["x"] = 8, ["y"] = 14, ["z"] = 4, ["name"] = "default:stonebrick"}, {["x"] = 8, ["y"] = 14, ["z"] = 5, ["name"] = "default:stonebrick"}, {["x"] = 8, ["y"] = 14, ["z"] = 6, ["name"] = "default:stonebrick"}, {["x"] = 8, ["y"] = 14, ["z"] = 7, ["name"] = "default:stonebrick"}, {["x"] = 8, ["y"] = 14, ["z"] = 8, ["name"] = "default:stonebrick"}, {["x"] = 8, ["y"] = 14, ["z"] = 9, ["name"] = "default:stonebrick"}, {["x"] = 8, ["y"] = 14, ["z"] = 10, ["name"] = "default:stonebrick"}, {["x"] = 8, ["y"] = 14, ["z"] = 11, ["name"] = "default:stonebrick"}, {["x"] = 8, ["y"] = 14, ["z"] = 12, ["name"] = "default:stonebrick"}, {["x"] = 8, ["y"] = 14, ["z"] = 13, ["name"] = "default:stonebrick"}, {["x"] = 8, ["y"] = 14, ["z"] = 14, ["name"] = "default:stonebrick"}, {["x"] = 8, ["y"] = 14, ["z"] = 15, ["name"] = "default:stonebrick"}, {["x"] = 8, ["y"] = 14, ["z"] = 16, ["name"] = "default:stonebrick"}, {["x"] = 8, ["y"] = 14, ["z"] = 17, ["name"] = "default:stonebrick"}, {["x"] = 8, ["y"] = 15, ["param1"] = 143, ["z"] = 7, ["name"] = "xpanes:pane_flat"}, {["x"] = 8, ["y"] = 15, ["param1"] = 143, ["z"] = 14, ["name"] = "xpanes:pane_flat"}, {["x"] = 8, ["y"] = 16, ["param1"] = 159, ["z"] = 7, ["name"] = "xpanes:pane_flat"}, {["x"] = 8, ["y"] = 16, ["param1"] = 159, ["z"] = 14, ["name"] = "xpanes:pane_flat"}, {["x"] = 8, ["y"] = 17, ["param1"] = 143, ["z"] = 7, ["name"] = "xpanes:pane_flat"}, {["x"] = 8, ["y"] = 17, ["param1"] = 143, ["z"] = 14, ["name"] = "xpanes:pane_flat"}, {["x"] = 9, ["y"] = 0, ["param1"] = 142, ["z"] = 2, ["name"] = "lapis:lapis_cobble"}, {["x"] = 9, ["y"] = 0, ["z"] = 3, ["name"] = "default:stonebrick"}, {["x"] = 9, ["y"] = 0, ["z"] = 4, ["name"] = "default:stonebrick"}, {["x"] = 9, ["y"] = 0, ["z"] = 5, ["name"] = "default:stonebrick"}, {["x"] = 9, ["y"] = 0, ["z"] = 6, ["name"] = "default:stonebrick"}, {["x"] = 9, ["y"] = 0, ["z"] = 7, ["name"] = "default:stonebrick"}, {["x"] = 9, ["y"] = 0, ["z"] = 8, ["name"] = "default:stonebrick"}, {["x"] = 9, ["y"] = 0, ["z"] = 9, ["name"] = "moretrees:sequoia_planks"}, {["x"] = 9, ["y"] = 0, ["z"] = 10, ["name"] = "moretrees:sequoia_planks"}, {["x"] = 9, ["y"] = 0, ["z"] = 11, ["name"] = "moretrees:fir_planks"}, {["x"] = 9, ["y"] = 0, ["z"] = 12, ["name"] = "default:stonebrick"}, {["x"] = 9, ["y"] = 0, ["z"] = 13, ["name"] = "default:stonebrick"}, {["x"] = 9, ["y"] = 0, ["z"] = 14, ["name"] = "default:stonebrick"}, {["x"] = 9, ["y"] = 0, ["z"] = 15, ["name"] = "default:stonebrick"}, {["x"] = 9, ["y"] = 0, ["z"] = 16, ["name"] = "moretrees:fir_planks"}, {["x"] = 9, ["y"] = 0, ["z"] = 17, ["name"] = "moretrees:sequoia_planks"}, {["x"] = 9, ["y"] = 0, ["z"] = 18, ["name"] = "moretrees:sequoia_planks"}, {["x"] = 9, ["y"] = 0, ["param1"] = 142, ["z"] = 19, ["name"] = "lapis:lapis_cobble"}, {["x"] = 9, ["y"] = 1, ["param1"] = 159, ["z"] = 2, ["name"] = "xpanes:pane_flat"}, {["x"] = 9, ["meta"] = {["fields"] = {["infotext"] = "Wooden Locked Chest (owned by k)", ["owner"] = "k", ["formspec"] = "size[8,10]label[0,0;Wooden Chest]list[context;main;0,1;8,4;]list[current_player;main;0,6;8,4;]background[-0.19,-0.25;8.4,10.75;technic_chest_form_bg.png]background[0,1;8,4;technic_wooden_chest_inventory.png]background[0,6;8,4;technic_main_inventory.png]listring[]"}, ["inventory"] = {["main"] = {"default:cobble 99", "default:cobble 99", "default:cobble 99", "technic:granite 6", "default:cobble 99", "mobs:leather 3", "", "3d_armor:leggings_diamond 1 14700", "bucket:bucket_water", "default:cobble 99", "bucket:bucket_lava", "default:cobble 20", "default:torch 99", "default:pick_mese 1 32186", "", "3d_armor:boots_diamond 1 14000", "cavestuff:pebble_1 31", "default:cobble 99", "bucket:bucket_lava", "default:cobble 99", "default:torch 4", "default:pick_mese 1 26699", "", "shields:shield_diamond 1 27700", "default:cobble 99", "default:cobble 99", "default:dirt 72", "bones:bones", "default:stick 99", "default:sword_diamond 1 17513", "3d_armor:helmet_diamond 1 16600", "3d_armor:chestplate_diamond 1 26000"}}}, ["param2"] = 3, ["y"] = 1, ["z"] = 16, ["name"] = "default:chest_locked"}, {["x"] = 9, ["y"] = 1, ["param1"] = 143, ["z"] = 19, ["name"] = "xpanes:pane_flat"}, {["x"] = 9, ["y"] = 2, ["param1"] = 175, ["z"] = 2, ["name"] = "xpanes:pane_flat"}, {["x"] = 9, ["meta"] = {["fields"] = {["infotext"] = "Wooden Locked Chest (owned by k)", ["owner"] = "k", ["formspec"] = "size[8,10]label[0,0;Wooden Chest]list[context;main;0,1;8,4;]list[current_player;main;0,6;8,4;]background[-0.19,-0.25;8.4,10.75;technic_chest_form_bg.png]background[0,1;8,4;technic_wooden_chest_inventory.png]background[0,6;8,4;technic_main_inventory.png]listring[]"}, ["inventory"] = {["main"] = {"default:cobble 99", "default:cobble 99", "default:cobble 99", "default:cobble 4", "technic:lead_lump 34", "default:tin_lump 65", "technic:zinc_lump 54", "technic:chromium_lump 3", "default:copper_lump 41", "default:gold_lump 47", "default:diamond 28", "technic:uranium_lump 6", "default:sword_steel 1 6720", "default:clay_lump 99", "default:clay_lump 17", "moreores:silver_lump 16", "default:flint 8", "default:iron_lump 99", "lapis:lapis_stone 7", "moreores:silver_ingot", "default:mese_crystal 24", "technic:sulfur_lump 2", "birthstones:alexandrite 2", "default:cobble 99", "default:gold_ingot 6", "default:steel_ingot 10", "default:coal_lump 38", "technic:sulfur_lump 99", "", "", "", "default:cobble 34"}}}, ["param2"] = 3, ["y"] = 2, ["z"] = 16, ["name"] = "default:chest_locked"}, {["x"] = 9, ["y"] = 2, ["param1"] = 143, ["z"] = 19, ["name"] = "xpanes:pane_flat"}, {["x"] = 9, ["y"] = 3, ["param1"] = 159, ["z"] = 2, ["name"] = "xpanes:pane_flat"}, {["x"] = 9, ["y"] = 3, ["param1"] = 204, ["z"] = 8, ["name"] = "default:torch_ceiling"}, {["x"] = 9, ["y"] = 3, ["param1"] = 159, ["z"] = 19, ["name"] = "xpanes:pane_flat"}, {["x"] = 9, ["y"] = 4, ["z"] = 3, ["name"] = "default:cobble"}, {["x"] = 9, ["y"] = 4, ["z"] = 4, ["name"] = "default:cobble"}, {["x"] = 9, ["y"] = 4, ["z"] = 5, ["name"] = "default:cobble"}, {["x"] = 9, ["y"] = 4, ["z"] = 6, ["name"] = "default:cobble"}, {["x"] = 9, ["y"] = 4, ["z"] = 7, ["name"] = "default:cobble"}, {["x"] = 9, ["y"] = 4, ["z"] = 8, ["name"] = "default:cobble"}, {["x"] = 9, ["y"] = 4, ["z"] = 9, ["name"] = "default:cobble"}, {["x"] = 9, ["y"] = 4, ["z"] = 10, ["name"] = "default:cobble"}, {["x"] = 9, ["y"] = 4, ["z"] = 11, ["name"] = "default:cobble"}, {["x"] = 9, ["y"] = 4, ["z"] = 12, ["name"] = "default:cobble"}, {["x"] = 9, ["y"] = 4, ["z"] = 13, ["name"] = "default:cobble"}, {["x"] = 9, ["y"] = 4, ["z"] = 14, ["name"] = "default:cobble"}, {["x"] = 9, ["y"] = 4, ["z"] = 15, ["name"] = "default:cobble"}, {["x"] = 9, ["y"] = 4, ["z"] = 16, ["name"] = "default:cobble"}, {["x"] = 9, ["y"] = 4, ["z"] = 17, ["name"] = "default:cobble"}, {["x"] = 9, ["y"] = 4, ["z"] = 18, ["name"] = "default:cobble"}, {["x"] = 9, ["y"] = 5, ["param1"] = 142, ["z"] = 3, ["name"] = "xpanes:pane_flat"}, {["x"] = 9, ["y"] = 5, ["param1"] = 142, ["z"] = 18, ["name"] = "xpanes:pane_flat"}, {["x"] = 9, ["y"] = 6, ["param1"] = 158, ["z"] = 3, ["name"] = "xpanes:pane_flat"}, {["x"] = 9, ["y"] = 6, ["param1"] = 158, ["z"] = 18, ["name"] = "xpanes:pane_flat"}, {["x"] = 9, ["y"] = 7, ["param1"] = 142, ["z"] = 3, ["name"] = "xpanes:pane_flat"}, {["x"] = 9, ["y"] = 7, ["param1"] = 142, ["z"] = 18, ["name"] = "xpanes:pane_flat"}, {["x"] = 9, ["y"] = 8, ["param1"] = 126, ["z"] = 3, ["name"] = "xpanes:pane_flat"}, {["x"] = 9, ["y"] = 8, ["param1"] = 126, ["z"] = 18, ["name"] = "xpanes:pane_flat"}, {["x"] = 9, ["y"] = 9, ["param1"] = 126, ["z"] = 3, ["name"] = "xpanes:pane_flat"}, {["x"] = 9, ["y"] = 9, ["param1"] = 110, ["z"] = 18, ["name"] = "xpanes:pane_flat"}, {["x"] = 9, ["y"] = 10, ["param1"] = 142, ["z"] = 3, ["name"] = "lapis:lapis_cobble"}, {["x"] = 9, ["y"] = 10, ["param1"] = 157, ["z"] = 4, ["name"] = "default:glass"}, {["x"] = 9, ["y"] = 10, ["param1"] = 172, ["z"] = 5, ["name"] = "default:glass"}, {["x"] = 9, ["y"] = 10, ["param1"] = 155, ["z"] = 6, ["name"] = "default:glass"}, {["x"] = 9, ["y"] = 10, ["param1"] = 170, ["z"] = 7, ["name"] = "default:glass"}, {["x"] = 9, ["y"] = 10, ["param1"] = 153, ["z"] = 8, ["name"] = "default:glass"}, {["x"] = 9, ["y"] = 10, ["param1"] = 153, ["z"] = 9, ["name"] = "default:glass"}, {["x"] = 9, ["y"] = 10, ["param1"] = 153, ["z"] = 10, ["name"] = "default:glass"}, {["x"] = 9, ["y"] = 10, ["param1"] = 170, ["z"] = 11, ["name"] = "default:glass"}, {["x"] = 9, ["y"] = 10, ["param1"] = 153, ["z"] = 12, ["name"] = "default:glass"}, {["x"] = 9, ["y"] = 10, ["param1"] = 154, ["z"] = 13, ["name"] = "default:glass"}, {["x"] = 9, ["y"] = 10, ["param1"] = 154, ["z"] = 14, ["name"] = "default:glass"}, {["x"] = 9, ["y"] = 10, ["param1"] = 155, ["z"] = 15, ["name"] = "default:glass"}, {["x"] = 9, ["y"] = 10, ["param1"] = 140, ["z"] = 16, ["name"] = "default:glass"}, {["x"] = 9, ["y"] = 10, ["param1"] = 125, ["z"] = 17, ["name"] = "default:glass"}, {["x"] = 9, ["y"] = 10, ["param1"] = 110, ["z"] = 18, ["name"] = "lapis:lapis_cobble"}, {["x"] = 9, ["y"] = 11, ["z"] = 4, ["name"] = "default:stonebrick"}, {["x"] = 9, ["meta"] = {["fields"] = {["closed"] = "0"}, ["inventory"] = {}}, ["param2"] = 1, ["y"] = 11, ["param1"] = 170, ["z"] = 12, ["name"] = "homedecor:door_exterior_fancy_right"}, {["x"] = 9, ["y"] = 11, ["z"] = 17, ["name"] = "default:stonebrick"}, {["x"] = 9, ["y"] = 12, ["z"] = 4, ["name"] = "default:stonebrick"}, {["x"] = 9, ["param2"] = 5, ["y"] = 12, ["param1"] = 204, ["z"] = 5, ["name"] = "default:torch_wall"}, {["x"] = 9, ["param2"] = 2, ["y"] = 12, ["param1"] = 204, ["z"] = 7, ["name"] = "default:torch_wall"}, {["x"] = 9, ["param2"] = 2, ["y"] = 12, ["param1"] = 204, ["z"] = 11, ["name"] = "default:torch_wall"}, {["x"] = 9, ["y"] = 12, ["z"] = 17, ["name"] = "default:stonebrick"}, {["x"] = 9, ["y"] = 13, ["z"] = 4, ["name"] = "default:stonebrick"}, {["x"] = 9, ["y"] = 13, ["z"] = 12, ["name"] = "default:stonebrick"}, {["x"] = 9, ["param2"] = 2, ["y"] = 13, ["param1"] = 204, ["z"] = 14, ["name"] = "default:torch_wall"}, {["x"] = 9, ["param2"] = 2, ["y"] = 13, ["param1"] = 204, ["z"] = 15, ["name"] = "default:torch_wall"}, {["x"] = 9, ["y"] = 13, ["z"] = 17, ["name"] = "default:stonebrick"}, {["x"] = 9, ["y"] = 14, ["z"] = 4, ["name"] = "default:stonebrick"}, {["x"] = 9, ["y"] = 14, ["z"] = 5, ["name"] = "default:stonebrick"}, {["x"] = 9, ["y"] = 14, ["z"] = 6, ["name"] = "default:stonebrick"}, {["x"] = 9, ["y"] = 14, ["z"] = 7, ["name"] = "default:stonebrick"}, {["x"] = 9, ["y"] = 14, ["z"] = 8, ["name"] = "default:stonebrick"}, {["x"] = 9, ["y"] = 14, ["z"] = 9, ["name"] = "default:stonebrick"}, {["x"] = 9, ["y"] = 14, ["z"] = 10, ["name"] = "default:stonebrick"}, {["x"] = 9, ["y"] = 14, ["z"] = 11, ["name"] = "default:stonebrick"}, {["x"] = 9, ["y"] = 14, ["z"] = 12, ["name"] = "default:stonebrick"}, {["x"] = 9, ["y"] = 14, ["z"] = 13, ["name"] = "default:stonebrick"}, {["x"] = 9, ["y"] = 14, ["z"] = 14, ["name"] = "default:stonebrick"}, {["x"] = 9, ["y"] = 14, ["z"] = 15, ["name"] = "default:stonebrick"}, {["x"] = 9, ["y"] = 14, ["z"] = 16, ["name"] = "default:stonebrick"}, {["x"] = 9, ["y"] = 14, ["z"] = 17, ["name"] = "default:stonebrick"}, {["x"] = 9, ["y"] = 15, ["param1"] = 127, ["z"] = 7, ["name"] = "xpanes:pane"}, {["x"] = 9, ["param2"] = 3, ["y"] = 15, ["param1"] = 143, ["z"] = 8, ["name"] = "xpanes:pane_flat"}, {["x"] = 9, ["param2"] = 3, ["y"] = 15, ["param1"] = 127, ["z"] = 9, ["name"] = "xpanes:pane_flat"}, {["x"] = 9, ["param2"] = 3, ["y"] = 15, ["param1"] = 111, ["z"] = 10, ["name"] = "xpanes:pane_flat"}, {["x"] = 9, ["param2"] = 2, ["y"] = 15, ["param1"] = 110, ["z"] = 11, ["name"] = "homedecor:door_exterior_fancy_right"}, {["x"] = 9, ["param2"] = 1, ["y"] = 15, ["param1"] = 127, ["z"] = 12, ["name"] = "xpanes:pane_flat"}, {["x"] = 9, ["param2"] = 3, ["y"] = 15, ["param1"] = 143, ["z"] = 13, ["name"] = "xpanes:pane_flat"}, {["x"] = 9, ["y"] = 15, ["param1"] = 127, ["z"] = 14, ["name"] = "xpanes:pane"}, {["x"] = 9, ["y"] = 16, ["param1"] = 143, ["z"] = 7, ["name"] = "xpanes:pane"}, {["x"] = 9, ["param2"] = 3, ["y"] = 16, ["param1"] = 159, ["z"] = 8, ["name"] = "xpanes:pane_flat"}, {["x"] = 9, ["param2"] = 3, ["y"] = 16, ["param1"] = 143, ["z"] = 9, ["name"] = "xpanes:pane_flat"}, {["x"] = 9, ["param2"] = 3, ["y"] = 16, ["param1"] = 127, ["z"] = 10, ["name"] = "xpanes:pane_flat"}, {["x"] = 9, ["param2"] = 1, ["y"] = 16, ["param1"] = 143, ["z"] = 12, ["name"] = "xpanes:pane_flat"}, {["x"] = 9, ["param2"] = 3, ["y"] = 16, ["param1"] = 159, ["z"] = 13, ["name"] = "xpanes:pane_flat"}, {["x"] = 9, ["y"] = 16, ["param1"] = 143, ["z"] = 14, ["name"] = "xpanes:pane"}, {["x"] = 9, ["y"] = 17, ["param1"] = 127, ["z"] = 7, ["name"] = "xpanes:pane"}, {["x"] = 9, ["param2"] = 3, ["y"] = 17, ["param1"] = 143, ["z"] = 8, ["name"] = "xpanes:pane_flat"}, {["x"] = 9, ["param2"] = 3, ["y"] = 17, ["param1"] = 127, ["z"] = 9, ["name"] = "xpanes:pane_flat"}, {["x"] = 9, ["param2"] = 3, ["y"] = 17, ["param1"] = 111, ["z"] = 10, ["name"] = "xpanes:pane_flat"}, {["x"] = 9, ["param2"] = 3, ["y"] = 17, ["param1"] = 111, ["z"] = 11, ["name"] = "xpanes:pane_flat"}, {["x"] = 9, ["param2"] = 3, ["y"] = 17, ["param1"] = 127, ["z"] = 12, ["name"] = "xpanes:pane_flat"}, {["x"] = 9, ["param2"] = 3, ["y"] = 17, ["param1"] = 143, ["z"] = 13, ["name"] = "xpanes:pane_flat"}, {["x"] = 9, ["y"] = 17, ["param1"] = 127, ["z"] = 14, ["name"] = "xpanes:pane"}, {["x"] = 10, ["y"] = 0, ["param1"] = 158, ["z"] = 2, ["name"] = "lapis:lapis_cobble"}, {["x"] = 10, ["y"] = 0, ["z"] = 3, ["name"] = "default:stonebrick"}, {["x"] = 10, ["y"] = 0, ["z"] = 4, ["name"] = "default:stonebrick"}, {["x"] = 10, ["y"] = 0, ["z"] = 5, ["name"] = "default:stonebrick"}, {["x"] = 10, ["y"] = 0, ["z"] = 6, ["name"] = "default:stonebrick"}, {["x"] = 10, ["y"] = 0, ["z"] = 7, ["name"] = "default:stonebrick"}, {["x"] = 10, ["y"] = 0, ["z"] = 8, ["name"] = "default:stonebrick"}, {["x"] = 10, ["y"] = 0, ["z"] = 9, ["name"] = "moretrees:sequoia_planks"}, {["x"] = 10, ["y"] = 0, ["z"] = 10, ["name"] = "moretrees:sequoia_planks"}, {["x"] = 10, ["y"] = 0, ["z"] = 11, ["name"] = "moretrees:fir_planks"}, {["x"] = 10, ["y"] = 0, ["z"] = 12, ["name"] = "moretrees:fir_planks"}, {["x"] = 10, ["y"] = 0, ["z"] = 13, ["name"] = "moretrees:fir_planks"}, {["x"] = 10, ["y"] = 0, ["z"] = 14, ["name"] = "moretrees:fir_planks"}, {["x"] = 10, ["y"] = 0, ["z"] = 15, ["name"] = "moretrees:fir_planks"}, {["x"] = 10, ["y"] = 0, ["z"] = 16, ["name"] = "moretrees:fir_planks"}, {["x"] = 10, ["y"] = 0, ["z"] = 17, ["name"] = "moretrees:sequoia_planks"}, {["x"] = 10, ["y"] = 0, ["z"] = 18, ["name"] = "moretrees:sequoia_planks"}, {["x"] = 10, ["y"] = 0, ["param1"] = 158, ["z"] = 19, ["name"] = "lapis:lapis_cobble"}, {["x"] = 10, ["y"] = 1, ["param1"] = 175, ["z"] = 2, ["name"] = "xpanes:pane_flat"}, {["x"] = 10, ["y"] = 1, ["param1"] = 159, ["z"] = 19, ["name"] = "xpanes:pane_flat"}, {["x"] = 10, ["y"] = 2, ["param1"] = 191, ["z"] = 2, ["name"] = "xpanes:pane_flat"}, {["x"] = 10, ["param2"] = 5, ["y"] = 2, ["param1"] = 206, ["z"] = 3, ["name"] = "default:torch_wall"}, {["x"] = 10, ["y"] = 2, ["param1"] = 159, ["z"] = 19, ["name"] = "xpanes:pane_flat"}, {["x"] = 10, ["y"] = 3, ["param1"] = 175, ["z"] = 2, ["name"] = "xpanes:pane_flat"}, {["x"] = 10, ["y"] = 3, ["param1"] = 175, ["z"] = 19, ["name"] = "xpanes:pane_flat"}, {["x"] = 10, ["y"] = 4, ["z"] = 3, ["name"] = "default:cobble"}, {["x"] = 10, ["y"] = 4, ["z"] = 4, ["name"] = "default:cobble"}, {["x"] = 10, ["y"] = 4, ["z"] = 5, ["name"] = "default:cobble"}, {["x"] = 10, ["y"] = 4, ["z"] = 6, ["name"] = "default:cobble"}, {["x"] = 10, ["y"] = 4, ["z"] = 7, ["name"] = "default:cobble"}, {["x"] = 10, ["y"] = 4, ["z"] = 8, ["name"] = "default:cobble"}, {["x"] = 10, ["y"] = 4, ["z"] = 9, ["name"] = "default:cobble"}, {["x"] = 10, ["y"] = 4, ["z"] = 10, ["name"] = "default:cobble"}, {["x"] = 10, ["y"] = 4, ["z"] = 11, ["name"] = "default:cobble"}, {["x"] = 10, ["y"] = 4, ["z"] = 12, ["name"] = "default:cobble"}, {["x"] = 10, ["y"] = 4, ["z"] = 13, ["name"] = "default:cobble"}, {["x"] = 10, ["y"] = 4, ["z"] = 14, ["name"] = "default:cobble"}, {["x"] = 10, ["y"] = 4, ["z"] = 15, ["name"] = "default:cobble"}, {["x"] = 10, ["y"] = 4, ["z"] = 16, ["name"] = "default:cobble"}, {["x"] = 10, ["y"] = 4, ["z"] = 17, ["name"] = "default:cobble"}, {["x"] = 10, ["y"] = 4, ["z"] = 18, ["name"] = "default:cobble"}, {["x"] = 10, ["y"] = 5, ["param1"] = 158, ["z"] = 3, ["name"] = "xpanes:pane_flat"}, {["x"] = 10, ["y"] = 5, ["param1"] = 158, ["z"] = 18, ["name"] = "xpanes:pane_flat"}, {["x"] = 10, ["y"] = 6, ["param1"] = 174, ["z"] = 3, ["name"] = "xpanes:pane_flat"}, {["x"] = 10, ["y"] = 6, ["param1"] = 174, ["z"] = 18, ["name"] = "xpanes:pane_flat"}, {["x"] = 10, ["y"] = 7, ["param1"] = 158, ["z"] = 3, ["name"] = "xpanes:pane_flat"}, {["x"] = 10, ["y"] = 7, ["param1"] = 158, ["z"] = 18, ["name"] = "xpanes:pane_flat"}, {["x"] = 10, ["y"] = 8, ["param1"] = 142, ["z"] = 3, ["name"] = "xpanes:pane_flat"}, {["x"] = 10, ["y"] = 8, ["param1"] = 142, ["z"] = 18, ["name"] = "xpanes:pane_flat"}, {["x"] = 10, ["y"] = 9, ["param1"] = 126, ["z"] = 3, ["name"] = "xpanes:pane_flat"},