5:return {{["x"] = 0, ["meta"] = {["fields"] = {}, ["inventory"] = {}}, ["y"] = 1, ["z"] = 116, ["name"] = "codersea:dirt"}, {["x"] = 0, ["meta"] = {["fields"] = {}, ["inventory"] = {}}, ["y"] = 2, ["z"] = 16, ["name"] = "codersea:dirt"}, {["x"] = 0, ["meta"] = {["fields"] = {}, ["inventory"] = {}}, ["y"] = 2, ["z"] = 50, ["name"] = "codersea:dirt"}, {["x"] = 0, ["meta"] = {["fields"] = {}, ["inventory"] = {}}, ["y"] = 2, ["z"] = 66, ["name"] = "codersea:dirt"}, {["x"] = 0, ["meta"] = {["fields"] = {}, ["inventory"] = {}}, ["y"] = 2, ["z"] = 100, ["name"] = "codersea:dirt"}, {["x"] = 0, ["meta"] = {["fields"] = {}, ["inventory"] = {}}, ["y"] = 2, ["z"] = 116, ["name"] = "codersea:dirt"}, {["x"] = 0, ["meta"] = {["fields"] = {}, ["inventory"] = {}}, ["y"] = 3, ["z"] = 3, ["name"] = "codersea:dirt"}, {["x"] = 0, ["meta"] = {["fields"] = {}, ["inventory"] = {}}, ["y"] = 3, ["z"] = 4, ["name"] = "codersea:dirt"}, {["x"] = 0, ["meta"] = {["fields"] = {}, ["inventory"] = {}}, ["y"] = 3, ["z"] = 5, ["name"] = "codersea:dirt"}, {["x"] = 0, ["meta"] = {["fields"] = {}, ["inventory"] = {}}, ["y"] = 3, ["z"] = 6, ["name"] = "codersea:dirt"}, {["x"] = 0, ["meta"] = {["fields"] = {}, ["inventory"] = {}}, ["y"] = 3, ["z"] = 8, ["name"] = "codersea:dirt"}, {["x"] = 0, ["meta"] = {["fields"] = {}, ["inventory"] = {}}, ["y"] = 3, ["z"] = 9, ["name"] = "codersea:dirt"}, {["x"] = 0, ["meta"] = {["fields"] = {}, ["inventory"] = {}}, ["y"] = 3, ["z"] = 10, ["name"] = "codersea:dirt"}, {["x"] = 0, ["meta"] = {["fields"] = {}, ["inventory"] = {}}, ["y"] = 3, ["z"] = 11, ["name"] = "codersea:dirt"}, {["x"] = 0, ["meta"] = {["fields"] = {}, ["inventory"] = {}}, ["y"] = 3, ["z"] = 12, ["name"] = "codersea:dirt"}, {["x"] = 0, ["meta"] = {["fields"] = {}, ["inventory"] = {}}, ["y"] = 3, ["z"] = 16, ["name"] = "codersea:dirt"}, {["x"] = 0, ["meta"] = {["fields"] = {}, ["inventory"] = {}}, ["y"] = 3, ["z"] = 50, ["name"] = "codersea:dirt"}, {["x"] = 0, ["meta"] = {["fields"] = {}, ["inventory"] = {}}, ["y"] = 3, ["z"] = 52, ["name"] = "codersea:dirt"}, {["x"] = 0, ["meta"] = {["fields"] = {}, ["inventory"] = {}}, ["y"] = 3, ["z"] = 53, ["name"] = "codersea:dirt"}, {["x"] = 0, ["meta"] = {["fields"] = {}, ["inventory"] = {}}, ["y"] = 3, ["z"] = 54, ["name"] = "codersea:dirt"}, {["x"] = 0, ["meta"] = {["fields"] = {}, ["inventory"] = {}}, ["y"] = 3, ["z"] = 56, ["name"] = "codersea:dirt"}, {["x"] = 0, ["meta"] = {["fields"] = {}, ["inventory"] = {}}, ["y"] = 3, ["z"] = 58, ["name"] = "codersea:dirt"}, {["x"] = 0, ["meta"] = {["fields"] = {}, ["inventory"] = {}}, ["y"] = 3, ["z"] = 59, ["name"] = "codersea:dirt"}, {["x"] = 0, ["meta"] = {["fields"] = {}, ["inventory"] = {}}, ["y"] = 3, ["z"] = 62, ["name"] = "codersea:dirt"}, {["x"] = 0, ["meta"] = {["fields"] = {}, ["inventory"] = {}}, ["y"] = 3, ["z"] = 63, ["name"] = "codersea:dirt"}, {["x"] = 0, ["meta"] = {["fields"] = {}, ["inventory"] = {}}, ["y"] = 3, ["z"] = 64, ["name"] = "codersea:dirt"}, {["x"] = 0, ["meta"] = {["fields"] = {}, ["inventory"] = {}}, ["y"] = 3, ["z"] = 65, ["name"] = "codersea:dirt"}, {["x"] = 0, ["meta"] = {["fields"] = {}, ["inventory"] = {}}, ["y"] = 3, ["z"] = 66, ["name"] = "codersea:dirt"}, {["x"] = 0, ["meta"] = {["fields"] = {}, ["inventory"] = {}}, ["y"] = 3, ["z"] = 101, ["name"] = "codersea:dirt"}, {["x"] = 0, ["meta"] = {["fields"] = {}, ["inventory"] = {}}, ["y"] = 3, ["z"] = 109, ["name"] = "codersea:dirt"}, {["x"] = 0, ["meta"] = {["fields"] = {}, ["inventory"] = {}}, ["y"] = 3, ["z"] = 111, ["name"] = "codersea:dirt"}, {["x"] = 0, ["meta"] = {["fields"] = {}, ["inventory"] = {}}, ["y"] = 3, ["z"] = 112, ["name"] = "codersea:dirt"}, {["x"] = 0, ["meta"] = {["fields"] = {}, ["inventory"] = {}}, ["y"] = 3, ["z"] = 113, ["name"] = "codersea:dirt"}, {["x"] = 0, ["meta"] = {["fields"] = {}, ["inventory"] = {}}, ["y"] = 3, ["z"] = 114, ["name"] = "codersea:dirt"}, {["x"] = 0, ["meta"] = {["fields"] = {}, ["inventory"] = {}}, ["y"] = 3, ["z"] = 115, ["name"] = "codersea:dirt"}, {["x"] = 0, ["meta"] = {["fields"] = {}, ["inventory"] = {}}, ["y"] = 3, ["z"] = 116, ["name"] = "codersea:dirt"}, {["x"] = 0, ["meta"] = {["fields"] = {}, ["inventory"] = {}}, ["y"] = 5, ["param1"] = 14, ["z"] = 0, ["name"] = "stairs:slab_desert_stonebrick"}, {["x"] = 0, ["meta"] = {["fields"] = {}, ["inventory"] = {}}, ["y"] = 5, ["param1"] = 30, ["z"] = 1, ["name"] = "stairs:slab_desert_stonebrick"}, {["x"] = 0, ["meta"] = {["fields"] = {}, ["inventory"] = {}}, ["y"] = 5, ["param1"] = 46, ["z"] = 2, ["name"] = "stairs:slab_desert_stonebrick"}, {["x"] = 0, ["meta"] = {["fields"] = {}, ["inventory"] = {}}, ["y"] = 5, ["param1"] = 62, ["z"] = 3, ["name"] = "stairs:slab_desert_stonebrick"}, {["x"] = 0, ["meta"] = {["fields"] = {}, ["inventory"] = {}}, ["y"] = 5, ["param1"] = 78, ["z"] = 4, ["name"] = "stairs:slab_desert_stonebrick"}, {["x"] = 0, ["meta"] = {["fields"] = {}, ["inventory"] = {}}, ["y"] = 5, ["param1"] = 94, ["z"] = 5, ["name"] = "stairs:slab_desert_stonebrick"}, {["x"] = 0, ["meta"] = {["fields"] = {}, ["inventory"] = {}}, ["y"] = 5, ["param1"] = 110, ["z"] = 6, ["name"] = "stairs:slab_desert_stonebrick"}, {["x"] = 0, ["meta"] = {["fields"] = {}, ["inventory"] = {}}, ["y"] = 5, ["param1"] = 126, ["z"] = 7, ["name"] = "stairs:slab_desert_stonebrick"}, {["x"] = 0, ["meta"] = {["fields"] = {}, ["inventory"] = {}}, ["y"] = 5, ["param1"] = 142, ["z"] = 8, ["name"] = "stairs:slab_desert_stonebrick"}, {["x"] = 0, ["meta"] = {["fields"] = {}, ["inventory"] = {}}, ["y"] = 5, ["param1"] = 126, ["z"] = 9, ["name"] = "stairs:slab_desert_stonebrick"}, {["x"] = 0, ["meta"] = {["fields"] = {}, ["inventory"] = {}}, ["y"] = 5, ["param1"] = 110, ["z"] = 10, ["name"] = "stairs:slab_desert_stonebrick"}, {["x"] = 0, ["meta"] = {["fields"] = {}, ["inventory"] = {}}, ["y"] = 5, ["param1"] = 94, ["z"] = 11, ["name"] = "stairs:slab_desert_stonebrick"}, {["x"] = 0, ["meta"] = {["fields"] = {}, ["inventory"] = {}}, ["y"] = 5, ["param1"] = 78, ["z"] = 12, ["name"] = "stairs:slab_desert_stonebrick"}, {["x"] = 0, ["meta"] = {["fields"] = {}, ["inventory"] = {}}, ["y"] = 5, ["param1"] = 62, ["z"] = 13, ["name"] = "stairs:slab_desert_stonebrick"}, {["x"] = 0, ["meta"] = {["fields"] = {}, ["inventory"] = {}}, ["y"] = 5, ["param1"] = 46, ["z"] = 14, ["name"] = "stairs:slab_desert_stonebrick"}, {["x"] = 0, ["meta"] = {["fields"] = {}, ["inventory"] = {}}, ["y"] = 5, ["param1"] = 46, ["z"] = 15, ["name"] = "stairs:slab_desert_stonebrick"}, {["x"] = 0, ["meta"] = {["fields"] = {}, ["inventory"] = {}}, ["y"] = 5, ["param1"] = 62, ["z"] = 16, ["name"] = "stairs:slab_desert_stonebrick"}, {["x"] = 0, ["meta"] = {["fields"] = {}, ["inventory"] = {}}, ["y"] = 5, ["param1"] = 78, ["z"] = 17, ["name"] = "stairs:slab_desert_stonebrick"}, {["x"] = 0, ["meta"] = {["fields"] = {}, ["inventory"] = {}}, ["y"] = 5, ["param1"] = 94, ["z"] = 18, ["name"] = "stairs:slab_desert_stonebrick"}, {["x"] = 0, ["meta"] = {["fields"] = {}, ["inventory"] = {}}, ["y"] = 5, ["param1"] = 110, ["z"] = 19, ["name"] = "stairs:slab_desert_stonebrick"}, {["x"] = 0, ["meta"] = {["fields"] = {}, ["inventory"] = {}}, ["y"] = 5, ["param1"] = 94, ["z"] = 20, ["name"] = "stairs:slab_desert_stonebrick"}, {["x"] = 0, ["meta"] = {["fields"] = {}, ["inventory"] = {}}, ["y"] = 5, ["param1"] = 78, ["z"] = 21, ["name"] = "stairs:slab_desert_stonebrick"}, {["x"] = 0, ["meta"] = {["fields"] = {}, ["inventory"] = {}}, ["y"] = 5, ["param1"] = 62, ["z"] = 22, ["name"] = "stairs:slab_desert_stonebrick"}, {["x"] = 0, ["meta"] = {["fields"] = {}, ["inventory"] = {}}, ["y"] = 5, ["param1"] = 46, ["z"] = 23, ["name"] = "stairs:slab_desert_stonebrick"}, {["x"] = 0, ["meta"] = {["fields"] = {}, ["inventory"] = {}}, ["y"] = 5, ["param1"] = 30, ["z"] = 24, ["name"] = "stairs:slab_desert_stonebrick"}, {["x"] = 0, ["meta"] = {["fields"] = {}, ["inventory"] = {}}, ["y"] = 5, ["param1"] = 14, ["z"] = 25, ["name"] = "stairs:slab_desert_stonebrick"}, {["x"] = 0, ["meta"] = {["fields"] = {}, ["inventory"] = {}}, ["y"] = 5, ["param1"] = 14, ["z"] = 26, ["name"] = "stairs:slab_desert_stonebrick"}, {["x"] = 0, ["meta"] = {["fields"] = {}, ["inventory"] = {}}, ["y"] = 5, ["param1"] = 14, ["z"] = 27, ["name"] = "stairs:slab_desert_stonebrick"}, {["x"] = 0, ["meta"] = {["fields"] = {}, ["inventory"] = {}}, ["y"] = 5, ["param1"] = 30, ["z"] = 28, ["name"] = "stairs:slab_desert_stonebrick"}, {["x"] = 0, ["meta"] = {["fields"] = {}, ["inventory"] = {}}, ["y"] = 5, ["param1"] = 46, ["z"] = 29, ["name"] = "stairs:slab_desert_stonebrick"}, {["x"] = 0, ["meta"] = {["fields"] = {}, ["inventory"] = {}}, ["y"] = 5, ["param1"] = 62, ["z"] = 30, ["name"] = "stairs:slab_desert_stonebrick"}, {["x"] = 0, ["meta"] = {["fields"] = {}, ["inventory"] = {}}, ["y"] = 5, ["param1"] = 78, ["z"] = 31, ["name"] = "stairs:slab_desert_stonebrick"}, {["x"] = 0, ["meta"] = {["fields"] = {}, ["inventory"] = {}}, ["y"] = 5, ["param1"] = 94, ["z"] = 32, ["name"] = "stairs:slab_desert_stonebrick"}, {["x"] = 0, ["meta"] = {["fields"] = {}, ["inventory"] = {}}, ["y"] = 5, ["param1"] = 110, ["z"] = 33, ["name"] = "stairs:slab_desert_stonebrick"}, {["x"] = 0, ["meta"] = {["fields"] = {}, ["inventory"] = {}}, ["y"] = 5, ["param1"] = 94, ["z"] = 34, ["name"] = "stairs:slab_desert_stonebrick"}, {["x"] = 0, ["meta"] = {["fields"] = {}, ["inventory"] = {}}, ["y"] = 5, ["param1"] = 78, ["z"] = 35, ["name"] = "stairs:slab_desert_stonebrick"}, {["x"] = 0, ["meta"] = {["fields"] = {}, ["inventory"] = {}}, ["y"] = 5, ["param1"] = 62, ["z"] = 36, ["name"] = "stairs:slab_desert_stonebrick"}, {["x"] = 0, ["meta"] = {["fields"] = {}, ["inventory"] = {}}, ["y"] = 5, ["param1"] = 46, ["z"] = 37, ["name"] = "stairs:slab_desert_stonebrick"}, {["x"] = 0, ["meta"] = {["fields"] = {}, ["inventory"] = {}}, ["y"] = 5, ["param1"] = 30, ["z"] = 38, ["name"] = "stairs:slab_desert_stonebrick"}, {["x"] = 0, ["meta"] = {["fields"] = {}, ["inventory"] = {}}, ["y"] = 5, ["param1"] = 14, ["z"] = 39, ["name"] = "stairs:slab_desert_stonebrick"}, {["x"] = 0, ["meta"] = {["fields"] = {}, ["inventory"] = {}}, ["y"] = 5, ["param1"] = 14, ["z"] = 40, ["name"] = "stairs:slab_desert_stonebrick"}, {["x"] = 0, ["meta"] = {["fields"] = {}, ["inventory"] = {}}, ["y"] = 5, ["param1"] = 14, ["z"] = 41, ["name"] = "stairs:slab_desert_stonebrick"}, {["x"] = 0, ["meta"] = {["fields"] = {}, ["inventory"] = {}}, ["y"] = 5, ["param1"] = 30, ["z"] = 42, ["name"] = "stairs:slab_desert_stonebrick"}, {["x"] = 0, ["meta"] = {["fields"] = {}, ["inventory"] = {}}, ["y"] = 5, ["param1"] = 46, ["z"] = 43, ["name"] = "stairs:slab_desert_stonebrick"}, {["x"] = 0, ["meta"] = {["fields"] = {}, ["inventory"] = {}}, ["y"] = 5, ["param1"] = 62, ["z"] = 44, ["name"] = "stairs:slab_desert_stonebrick"}, {["x"] = 0, ["meta"] = {["fields"] = {}, ["inventory"] = {}}, ["y"] = 5, ["param1"] = 78, ["z"] = 45, ["name"] = "stairs:slab_desert_stonebrick"}, {["x"] = 0, ["meta"] = {["fields"] = {}, ["inventory"] = {}}, ["y"] = 5, ["param1"] = 94, ["z"] = 46, ["name"] = "stairs:slab_desert_stonebrick"}, {["x"] = 0, ["meta"] = {["fields"] = {}, ["inventory"] = {}}, ["y"] = 5, ["param1"] = 110, ["z"] = 47, ["name"] = "stairs:slab_desert_stonebrick"}, {["x"] = 0, ["meta"] = {["fields"] = {}, ["inventory"] = {}}, ["y"] = 5, ["param1"] = 94, ["z"] = 48, ["name"] = "stairs:slab_desert_stonebrick"}, {["x"] = 0, ["meta"] = {["fields"] = {}, ["inventory"] = {}}, ["y"] = 5, ["param1"] = 78, ["z"] = 49, ["name"] = "stairs:slab_desert_stonebrick"}, {["x"] = 0, ["meta"] = {["fields"] = {}, ["inventory"] = {}}, ["y"] = 5, ["param1"] = 62, ["z"] = 50, ["name"] = "stairs:slab_desert_stonebrick"}, {["x"] = 0, ["meta"] = {["fields"] = {}, ["inventory"] = {}}, ["y"] = 5, ["param1"] = 46, ["z"] = 51, ["name"] = "stairs:slab_desert_stonebrick"}, {["x"] = 0, ["meta"] = {["fields"] = {}, ["inventory"] = {}}, ["y"] = 5, ["param1"] = 46, ["z"] = 52, ["name"] = "stairs:slab_desert_stonebrick"}, {["x"] = 0, ["meta"] = {["fields"] = {}, ["inventory"] = {}}, ["y"] = 5, ["param1"] = 62, ["z"] = 53, ["name"] = "stairs:slab_desert_stonebrick"}, {["x"] = 0, ["meta"] = {["fields"] = {}, ["inventory"] = {}}, ["y"] = 5, ["param1"] = 78, ["z"] = 54, ["name"] = "stairs:slab_desert_stonebrick"}, {["x"] = 0, ["meta"] = {["fields"] = {}, ["inventory"] = {}}, ["y"] = 5, ["param1"] = 94, ["z"] = 55, ["name"] = "stairs:slab_desert_stonebrick"}, {["x"] = 0, ["meta"] = {["fields"] = {}, ["inventory"] = {}}, ["y"] = 5, ["param1"] = 110, ["z"] = 56, ["name"] = "stairs:slab_desert_stonebrick"}, {["x"] = 0, ["meta"] = {["fields"] = {}, ["inventory"] = {}}, ["y"] = 5, ["param1"] = 126, ["z"] = 57, ["name"] = "stairs:slab_desert_stonebrick"}, {["x"] = 0, ["meta"] = {["fields"] = {}, ["inventory"] = {}}, ["y"] = 5, ["param1"] = 142, ["z"] = 58, ["name"] = "stairs:slab_desert_stonebrick"}, {["x"] = 0, ["meta"] = {["fields"] = {}, ["inventory"] = {}}, ["y"] = 5, ["param1"] = 126, ["z"] = 59, ["name"] = "stairs:slab_desert_stonebrick"}, {["x"] = 0, ["meta"] = {["fields"] = {}, ["inventory"] = {}}, ["y"] = 5, ["param1"] = 110, ["z"] = 60, ["name"] = "stairs:slab_desert_stonebrick"}, {["x"] = 0, ["meta"] = {["fields"] = {}, ["inventory"] = {}}, ["y"] = 5, ["param1"] = 94, ["z"] = 61, ["name"] = "stairs:slab_desert_stonebrick"}, {["x"] = 0, ["meta"] = {["fields"] = {}, ["inventory"] = {}}, ["y"] = 5, ["param1"] = 78, ["z"] = 62, ["name"] = "stairs:slab_desert_stonebrick"}, {["x"] = 0, ["meta"] = {["fields"] = {}, ["inventory"] = {}}, ["y"] = 5, ["param1"] = 62, ["z"] = 63, ["name"] = "stairs:slab_desert_stonebrick"}, {["x"] = 0, ["meta"] = {["fields"] = {}, ["inventory"] = {}}, ["y"] = 5, ["param1"] = 46, ["z"] = 64, ["name"] = "stairs:slab_desert_stonebrick"}, {["x"] = 0, ["meta"] = {["fields"] = {}, ["inventory"] = {}}, ["y"] = 5, ["param1"] = 46, ["z"] = 65, ["name"] = "stairs:slab_desert_stonebrick"}, {["x"] = 0, ["meta"] = {["fields"] = {}, ["inventory"] = {}}, ["y"] = 5, ["param1"] = 62, ["z"] = 66, ["name"] = "stairs:slab_desert_stonebrick"}, {["x"] = 0, ["meta"] = {["fields"] = {}, ["inventory"] = {}}, ["y"] = 5, ["param1"] = 78, ["z"] = 67, ["name"] = "stairs:slab_desert_stonebrick"}, {["x"] = 0, ["meta"] = {["fields"] = {}, ["inventory"] = {}}, ["y"] = 5, ["param1"] = 94, ["z"] = 68, ["name"] = "stairs:slab_desert_stonebrick"}, {["x"] = 0, ["meta"] = {["fields"] = {}, ["inventory"] = {}}, ["y"] = 5, ["param1"] = 110, ["z"] = 69, ["name"] = "stairs:slab_desert_stonebrick"}, {["x"] = 0, ["meta"] = {["fields"] = {}, ["inventory"] = {}}, ["y"] = 5, ["param1"] = 94, ["z"] = 70, ["name"] = "stairs:slab_desert_stonebrick"}, {["x"] = 0, ["meta"] = {["fields"] = {}, ["inventory"] = {}}, ["y"] = 5, ["param1"] = 78, ["z"] = 71, ["name"] = "stairs:slab_desert_stonebrick"}, {["x"] = 0, ["meta"] = {["fields"] = {}, ["inventory"] = {}}, ["y"] = 5, ["param1"] = 62, ["z"] = 72, ["name"] = "stairs:slab_desert_stonebrick"}, {["x"] = 0, ["meta"] = {["fields"] = {}, ["inventory"] = {}}, ["y"] = 5, ["param1"] = 46, ["z"] = 73, ["name"] = "stairs:slab_desert_stonebrick"}, {["x"] = 0, ["meta"] = {["fields"] = {}, ["inventory"] = {}}, ["y"] = 5, ["param1"] = 30, ["z"] = 74, ["name"] = "stairs:slab_desert_stonebrick"}, {["x"] = 0, ["meta"] = {["fields"] = {}, ["inventory"] = {}}, ["y"] = 5, ["param1"] = 14, ["z"] = 75, ["name"] = "stairs:slab_desert_stonebrick"}, {["x"] = 0, ["meta"] = {["fields"] = {}, ["inventory"] = {}}, ["y"] = 5, ["param1"] = 14, ["z"] = 76, ["name"] = "stairs:slab_desert_stonebrick"}, {["x"] = 0, ["meta"] = {["fields"] = {}, ["inventory"] = {}}, ["y"] = 5, ["param1"] = 14, ["z"] = 77, ["name"] = "stairs:slab_desert_stonebrick"}, {["x"] = 0, ["meta"] = {["fields"] = {}, ["inventory"] = {}}, ["y"] = 5, ["param1"] = 30, ["z"] = 78, ["name"] = "stairs:slab_desert_stonebrick"}, {["x"] = 0, ["meta"] = {["fields"] = {}, ["inventory"] = {}}, ["y"] = 5, ["param1"] = 46, ["z"] = 79, ["name"] = "stairs:slab_desert_stonebrick"}, {["x"] = 0, ["meta"] = {["fields"] = {}, ["inventory"] = {}}, ["y"] = 5, ["param1"] = 62, ["z"] = 80, ["name"] = "stairs:slab_desert_stonebrick"}, {["x"] = 0, ["meta"] = {["fields"] = {}, ["inventory"] = {}}, ["y"] = 5, ["param1"] = 78, ["z"] = 81, ["name"] = "stairs:slab_desert_stonebrick"}, {["x"] = 0, ["meta"] = {["fields"] = {}, ["inventory"] = {}}, ["y"] = 5, ["param1"] = 94, ["z"] = 82, ["name"] = "stairs:slab_desert_stonebrick"}, {["x"] = 0, ["meta"] = {["fields"] = {}, ["inventory"] = {}}, ["y"] = 5, ["param1"] = 110, ["z"] = 83, ["name"] = "stairs:slab_desert_stonebrick"}, {["x"] = 0, ["meta"] = {["fields"] = {}, ["inventory"] = {}}, ["y"] = 5, ["param1"] = 94, ["z"] = 84, ["name"] = "stairs:slab_desert_stonebrick"}, {["x"] = 0, ["meta"] = {["fields"] = {}, ["inventory"] = {}}, ["y"] = 5, ["param1"] = 78, ["z"] = 85, ["name"] = "stairs:slab_desert_stonebrick"}, {["x"] = 0, ["meta"] = {["fields"] = {}, ["inventory"] = {}}, ["y"] = 5, ["param1"] = 62, ["z"] = 86, ["name"] = "stairs:slab_desert_stonebrick"}, {["x"] = 0, ["meta"] = {["fields"] = {}, ["inventory"] = {}}, ["y"] = 5, ["param1"] = 46, ["z"] = 87, ["name"] = "stairs:slab_desert_stonebrick"}, {["x"] = 0, ["meta"] = {["fields"] = {}, ["inventory"] = {}}, ["y"] = 5, ["param1"] = 30, ["z"] = 88, ["name"] = "stairs:slab_desert_stonebrick"}, {["x"] = 0, ["meta"] = {["fields"] = {}, ["inventory"] = {}}, ["y"] = 5, ["param1"] = 14, ["z"] = 89, ["name"] = "stairs:slab_desert_stonebrick"}, {["x"] = 0, ["meta"] = {["fields"] = {}, ["inventory"] = {}}, ["y"] = 5, ["param1"] = 14, ["z"] = 90, ["name"] = "stairs:slab_desert_stonebrick"}, {["x"] = 0, ["meta"] = {["fields"] = {}, ["inventory"] = {}}, ["y"] = 5, ["param1"] = 14, ["z"] = 91, ["name"] = "stairs:slab_desert_stonebrick"}, {["x"] = 0, ["meta"] = {["fields"] = {}, ["inventory"] = {}}, ["y"] = 5, ["param1"] = 30, ["z"] = 92, ["name"] = "stairs:slab_desert_stonebrick"}, {["x"] = 0, ["meta"] = {["fields"] = {}, ["inventory"] = {}}, ["y"] = 5, ["param1"] = 46, ["z"] = 93, ["name"] = "stairs:slab_desert_stonebrick"}, {["x"] = 0, ["meta"] = {["fields"] = {}, ["inventory"] = {}}, ["y"] = 5, ["param1"] = 62, ["z"] = 94, ["name"] = "stairs:slab_desert_stonebrick"}, {["x"] = 0, ["meta"] = {["fields"] = {}, ["inventory"] = {}}, ["y"] = 5, ["param1"] = 78, ["z"] = 95, ["name"] = "stairs:slab_desert_stonebrick"}, {["x"] = 0, ["meta"] = {["fields"] = {}, ["inventory"] = {}}, ["y"] = 5, ["param1"] = 94, ["z"] = 96, ["name"] = "stairs:slab_desert_stonebrick"}, {["x"] = 0, ["meta"] = {["fields"] = {}, ["inventory"] = {}}, ["y"] = 5, ["param1"] = 110, ["z"] = 97, ["name"] = "stairs:slab_desert_stonebrick"}, {["x"] = 0, ["meta"] = {["fields"] = {}, ["inventory"] = {}}, ["y"] = 5, ["param1"] = 94, ["z"] = 98, ["name"] = "stairs:slab_desert_stonebrick"}, {["x"] = 0, ["meta"] = {["fields"] = {}, ["inventory"] = {}}, ["y"] = 5, ["param1"] = 78, ["z"] = 99, ["name"] = "stairs:slab_desert_stonebrick"}, {["x"] = 0, ["meta"] = {["fields"] = {}, ["inventory"] = {}}, ["y"] = 5, ["param1"] = 62, ["z"] = 100, ["name"] = "stairs:slab_desert_stonebrick"}, {["x"] = 0, ["meta"] = {["fields"] = {}, ["inventory"] = {}}, ["y"] = 5, ["param1"] = 46, ["z"] = 101, ["name"] = "stairs:slab_desert_stonebrick"}, {["x"] = 0, ["meta"] = {["fields"] = {}, ["inventory"] = {}}, ["y"] = 5, ["param1"] = 46, ["z"] = 102, ["name"] = "stairs:slab_desert_stonebrick"}, {["x"] = 0, ["meta"] = {["fields"] = {}, ["inventory"] = {}}, ["y"] = 5, ["param1"] = 62, ["z"] = 103, ["name"] = "stairs:slab_desert_stonebrick"}, {["x"] = 0, ["meta"] = {["fields"] = {}, ["inventory"] = {}}, ["y"] = 5, ["param1"] = 78, ["z"] = 104, ["name"] = "stairs:slab_desert_stonebrick"}, {["x"] = 0, ["meta"] = {["fields"] = {}, ["inventory"] = {}}, ["y"] = 5, ["param1"] = 94, ["z"] = 105, ["name"] = "stairs:slab_desert_stonebrick"}, {["x"] = 0, ["meta"] = {["fields"] = {}, ["inventory"] = {}}, ["y"] = 5, ["param1"] = 110, ["z"] = 106, ["name"] = "stairs:slab_desert_stonebrick"}, {["x"] = 0, ["meta"] = {["fields"] = {}, ["inventory"] = {}}, ["y"] = 5, ["param1"] = 126, ["z"] = 107, ["name"] = "stairs:slab_desert_stonebrick"}, {["x"] = 0, ["meta"] = {["fields"] = {}, ["inventory"] = {}}, ["y"] = 5, ["param1"] = 142, ["z"] = 108, ["name"] = "stairs:slab_desert_stonebrick"}, {["x"] = 0, ["meta"] = {["fields"] = {}, ["inventory"] = {}}, ["y"] = 5, ["param1"] = 126, ["z"] = 109, ["name"] = "stairs:slab_desert_stonebrick"}, {["x"] = 0, ["meta"] = {["fields"] = {}, ["inventory"] = {}}, ["y"] = 5, ["param1"] = 110, ["z"] = 110, ["name"] = "stairs:slab_desert_stonebrick"}, {["x"] = 0, ["meta"] = {["fields"] = {}, ["inventory"] = {}}, ["y"] = 5, ["param1"] = 94, ["z"] = 111, ["name"] = "stairs:slab_desert_stonebrick"}, {["x"] = 0, ["meta"] = {["fields"] = {}, ["inventory"] = {}}, ["y"] = 5, ["param1"] = 78, ["z"] = 112, ["name"] = "stairs:slab_desert_stonebrick"}, {["x"] = 0, ["meta"] = {["fields"] = {}, ["inventory"] = {}}, ["y"] = 5, ["param1"] = 62, ["z"] = 113, ["name"] = "stairs:slab_desert_stonebrick"}, {["x"] = 0, ["meta"] = {["fields"] = {}, ["inventory"] = {}}, ["y"] = 5, ["param1"] = 46, ["z"] = 114, ["name"] = "stairs:slab_desert_stonebrick"}, {["x"] = 0, ["meta"] = {["fields"] = {}, ["inventory"] = {}}, ["y"] = 5, ["param1"] = 30, ["z"] = 115, ["name"] = "stairs:slab_desert_stonebrick"}, {["x"] = 0, ["meta"] = {["fields"] = {}, ["inventory"] = {}}, ["y"] = 5, ["param1"] = 14, ["z"] = 116, ["name"] = "stairs:slab_desert_stonebrick"}, {["x"] = 1, ["meta"] = {["fields"] = {}, ["inventory"] = {}}, ["y"] = 3, ["z"] = 0, ["name"] = "codersea:dirt"}, {["x"] = 1, ["meta"] = {["fields"] = {}, ["inventory"] = {}}, ["y"] = 5, ["param1"] = 30, ["z"] = 0, ["name"] = "stairs:slab_desert_stonebrick"}, {["x"] = 1, ["meta"] = {["fields"] = {}, ["inventory"] = {}}, ["y"] = 5, ["param1"] = 30, ["z"] = 116, ["name"] = "stairs:slab_desert_stonebrick"}, {["x"] = 2, ["meta"] = {["fields"] = {}, ["inventory"] = {}}, ["y"] = 3, ["z"] = 0, ["name"] = "codersea:dirt"}, {["x"] = 2, ["meta"] = {["fields"] = {}, ["inventory"] = {}}, ["y"] = 3, ["z"] = 116, ["name"] = "codersea:dirt"}, {["x"] = 2, ["meta"] = {["fields"] = {}, ["inventory"] = {}}, ["y"] = 5, ["param1"] = 46, ["z"] = 0, ["name"] = "stairs:slab_desert_stonebrick"}, {["x"] = 2, ["meta"] = {["fields"] = {}, ["inventory"] = {}}, ["y"] = 5, ["param1"] = 46, ["z"] = 116, ["name"] = "stairs:slab_desert_stonebrick"}, {["x"] = 3, ["meta"] = {["fields"] = {}, ["inventory"] = {}}, ["y"] = 3, ["z"] = 116, ["name"] = "codersea:dirt"}, {["x"] = 3, ["meta"] = {["fields"] = {}, ["inventory"] = {}}, ["y"] = 5, ["param1"] = 62, ["z"] = 0, ["name"] = "stairs:slab_desert_stonebrick"}, {["x"] = 3, ["meta"] = {["fields"] = {}, ["inventory"] = {}}, ["y"] = 5, ["param1"] = 62, ["z"] = 116, ["name"] = "stairs:slab_desert_stonebrick"}, {["x"] = 4, ["meta"] = {["fields"] = {}, ["inventory"] = {}}, ["y"] = 3, ["z"] = 0, ["name"] = "codersea:dirt"}, {["x"] = 4, ["meta"] = {["fields"] = {}, ["inventory"] = {}}, ["y"] = 3, ["z"] = 116, ["name"] = "codersea:dirt"}, {["x"] = 4, ["meta"] = {["fields"] = {}, ["inventory"] = {}}, ["y"] = 5, ["param1"] = 78, ["z"] = 0, ["name"] = "stairs:slab_desert_stonebrick"}, {["x"] = 4, ["meta"] = {["fields"] = {}, ["inventory"] = {}}, ["y"] = 5, ["param1"] = 78, ["z"] = 116, ["name"] = "stairs:slab_desert_stonebrick"}, {["x"] = 5, ["meta"] = {["fields"] = {}, ["inventory"] = {}}, ["y"] = 2, ["z"] = 12, ["name"] = "codersea:dirt"}, {["x"] = 5, ["meta"] = {["fields"] = {}, ["inventory"] = {}}, ["y"] = 3, ["z"] = 0, ["name"] = "codersea:dirt"}, {["x"] = 5, ["meta"] = {["fields"] = {}, ["inventory"] = {}}, ["y"] = 3, ["z"] = 12, ["name"] = "codersea:dirt"}, {["x"] = 5, ["meta"] = {["fields"] = {}, ["inventory"] = {}}, ["y"] = 3, ["z"] = 116, ["name"] = "codersea:dirt"}, {["x"] = 5, ["meta"] = {["fields"] = {}, ["inventory"] = {}}, ["y"] = 5, ["param1"] = 94, ["z"] = 0, ["name"] = "stairs:slab_desert_stonebrick"}, {["x"] = 5, ["meta"] = {["fields"] = {}, ["inventory"] = {}}, ["y"] = 5, ["param1"] = 94, ["z"] = 116, ["name"] = "stairs:slab_desert_stonebrick"}, {["x"] = 5, ["meta"] = {["fields"] = {}, ["inventory"] = {}}, ["param2"] = 12, ["y"] = 12, ["param1"] = 174, ["z"] = 13, ["name"] = "moreblocks:panel_stonebrick"}, {["x"] = 5, ["meta"] = {["fields"] = {}, ["inventory"] = {}}, ["param2"] = 7, ["y"] = 12, ["param1"] = 174, ["z"] = 53, ["name"] = "moreblocks:panel_stonebrick"}, {["x"] = 5, ["meta"] = {["fields"] = {}, ["inventory"] = {}}, ["param2"] = 12, ["y"] = 12, ["param1"] = 174, ["z"] = 63, ["name"] = "moreblocks:panel_stonebrick"}, {["x"] = 5, ["meta"] = {["fields"] = {}, ["inventory"] = {}}, ["param2"] = 7, ["y"] = 12, ["param1"] = 174, ["z"] = 103, ["name"] = "moreblocks:panel_stonebrick"}, {["x"] = 6, ["meta"] = {["fields"] = {}, ["inventory"] = {}}, ["y"] = 3, ["z"] = 0, ["name"] = "codersea:dirt"}, {["x"] = 6, ["meta"] = {["fields"] = {}, ["inventory"] = {}}, ["y"] = 3, ["z"] = 116, ["name"] = "codersea:dirt"}, {["x"] = 6, ["meta"] = {["fields"] = {}, ["inventory"] = {}}, ["y"] = 5, ["param1"] = 110, ["z"] = 0, ["name"] = "stairs:slab_desert_stonebrick"}, {["x"] = 6, ["meta"] = {["fields"] = {}, ["inventory"] = {}}, ["y"] = 5, ["param1"] = 110, ["z"] = 116, ["name"] = "stairs:slab_desert_stonebrick"}, {["x"] = 7, ["meta"] = {["fields"] = {}, ["inventory"] = {}}, ["y"] = 3, ["z"] = 0, ["name"] = "codersea:dirt"}, {["x"] = 7, ["meta"] = {["fields"] = {}, ["inventory"] = {}}, ["y"] = 5, ["param1"] = 126, ["z"] = 0, ["name"] = "stairs:slab_desert_stonebrick"}, {["x"] = 7, ["meta"] = {["fields"] = {}, ["inventory"] = {}}, ["y"] = 5, ["param1"] = 126, ["z"] = 116, ["name"] = "stairs:slab_desert_stonebrick"}, {["x"] = 8, ["meta"] = {["fields"] = {}, ["inventory"] = {}}, ["y"] = 3, ["z"] = 0, ["name"] = "codersea:dirt"}, {["x"] = 8, ["meta"] = {["fields"] = {}, ["inventory"] = {}}, ["y"] = 3, ["z"] = 116, ["name"] = "codersea:dirt"}, {["x"] = 8, ["meta"] = {["fields"] = {}, ["inventory"] = {}}, ["y"] = 5, ["param1"] = 142, ["z"] = 0, ["name"] = "stairs:slab_desert_stonebrick"}, {["x"] = 8, ["meta"] = {["fields"] = {["owner"] = "singleplayer", ["creative"] = "1", ["infotext"] = "(Smartshop by singleplayer) Stock is unlimited", ["state"] = "0", ["sellall"] = "1", ["type"] = "0"}, ["inventory"] = {["pay3"] = {""}, ["pay4"] = {""}, ["give1"] = {"infinitytools:sword"}, ["pay2"] = {""}, ["pay1"] = {""}, ["give4"] = {""}, ["main"] = {"", "", "", "", "", "", "", "", "", "", "", "", "", "", "", "", "", "", "", "", "", "", "", "", "", "", "", "", "", "", "", ""}, ["give3"] = {""}, ["give2"] = {""}}}, ["param2"] = 2, ["y"] = 5, ["param1"] = 170, ["z"] = 5, ["name"] = "smartshop:shop"}, {["x"] = 8, ["meta"] = {["fields"] = {}, ["inventory"] = {}}, ["y"] = 5, ["param1"] = 142, ["z"] = 116, ["name"] = "stairs:slab_desert_stonebrick"}, {["x"] = 8, ["meta"] = {["fields"] = {}, ["inventory"] = {}}, ["param2"] = 2, ["y"] = 6, ["param1"] = 85, ["z"] = 12, ["name"] = "stoneworks:arches_highstonebrick"}, {["x"] = 8, ["meta"] = {["fields"] = {}, ["inventory"] = {}}, ["param2"] = 2, ["y"] = 6, ["param1"] = 85, ["z"] = 54, ["name"] = "stoneworks:arches_highstonebrick"}, {["x"] = 8, ["meta"] = {["fields"] = {}, ["inventory"] = {}}, ["param2"] = 2, ["y"] = 6, ["param1"] = 85, ["z"] = 62, ["name"] = "stoneworks:arches_highstonebrick"}, {["x"] = 8, ["meta"] = {["fields"] = {}, ["inventory"] = {}}, ["y"] = 6, ["param1"] = 85, ["z"] = 104, ["name"] = "stoneworks:arches_highstonebrick"}, {["x"] = 9, ["meta"] = {["fields"] = {}, ["inventory"] = {}}, ["y"] = 5, ["param1"] = 126, ["z"] = 0, ["name"] = "stairs:slab_desert_stonebrick"}, {["x"] = 9, ["meta"] = {["fields"] = {}, ["inventory"] = {}}, ["y"] = 5, ["param1"] = 126, ["z"] = 116, ["name"] = "stairs:slab_desert_stonebrick"}, {["x"] = 10, ["meta"] = {["fields"] = {}, ["inventory"] = {}}, ["y"] = 5, ["param1"] = 110, ["z"] = 0, ["name"] = "stairs:slab_desert_stonebrick"}, {["x"] = 10, ["meta"] = {["fields"] = {}, ["inventory"] = {}}, ["y"] = 5, ["param1"] = 110, ["z"] = 116, ["name"] = "stairs:slab_desert_stonebrick"}, {["x"] = 11, ["meta"] = {["fields"] = {}, ["inventory"] = {}}, ["y"] = 5, ["param1"] = 94, ["z"] = 0, ["name"] = "stairs:slab_desert_stonebrick"}, {["x"] = 11, ["meta"] = {["fields"] = {["owner"] = "singleplayer", ["creative"] = "1", ["state"] = "0", ["type"] = "0", ["infotext"] = "(Smartshop by singleplayer) Stock is unlimited", ["sellall"] = "1"}, ["inventory"] = {["pay3"] = {""}, ["pay4"] = {""}, ["give1"] = {"technic:geothermal 99"}, ["pay2"] = {""}, ["pay1"] = {""}, ["give4"] = {"technic:mv_grinder 99"}, ["main"] = {"", "", "", "", "", "", "", "", "", "", "", "", "", "", "", "", "", "", "", "", "", "", "", "", "", "", "", "", "", "", "", ""}, ["give3"] = {"technic:mv_electric_furnace 99"}, ["give2"] = {"technic:mv_battery_box0 99"}}}, ["param2"] = 3, ["y"] = 5, ["param1"] = 170, ["z"] = 78, ["name"] = "smartshop:shop"}, {["x"] = 11, ["meta"] = {["fields"] = {["sellall"] = "1", ["creative"] = "1", ["type"] = "0", ["owner"] = "singleplayer", ["infotext"] = "(Smartshop by singleplayer) Stock is unlimited", ["state"] = "0"}, ["inventory"] = {["pay3"] = {""}, ["pay4"] = {""}, ["give1"] = {"technic:solar_array_mv 99"}, ["pay2"] = {""}, ["pay1"] = {""}, ["give4"] = {"ehlphabet:machine 99"}, ["main"] = {"", "", "", "", "", "", "", "", "", "", "", "", "", "", "", "", "", "", "", "", "", "", "", "", "", "", "", "", "", "", "", ""}, ["give3"] = {"moreblocks:circular_saw 99"}, ["give2"] = {"mymillwork:machine 99"}}}, ["param2"] = 3, ["y"] = 5, ["param1"] = 170, ["z"] = 98, ["name"] = "smartshop:shop"}, {["x"] = 11, ["meta"] = {["fields"] = {}, ["inventory"] = {}}, ["y"] = 5, ["param1"] = 94, ["z"] = 116, ["name"] = "stairs:slab_desert_stonebrick"}, {["x"] = 12, ["meta"] = {["fields"] = {}, ["inventory"] = {}}, ["y"] = 3, ["z"] = 0, ["name"] = "codersea:dirt"}, {["x"] = 12, ["meta"] = {["fields"] = {}, ["inventory"] = {}}, ["y"] = 3, ["z"] = 116, ["name"] = "codersea:dirt"}, {["x"] = 12, ["meta"] = {["fields"] = {["state"] = "0", ["infotext"] = "Owned by singleplayer", ["doors_owner"] = "singleplayer"}, ["inventory"] = {}}, ["param2"] = 3, ["y"] = 4, ["param1"] = 102, ["z"] = 58, ["name"] = "doors:door_steel_a"}, {["x"] = 12, ["meta"] = {["fields"] = {}, ["inventory"] = {}}, ["y"] = 5, ["param1"] = 78, ["z"] = 0, ["name"] = "stairs:slab_desert_stonebrick"}, {["x"] = 12, ["meta"] = {["fields"] = {}, ["inventory"] = {}}, ["param2"] = 3, ["y"] = 5, ["param1"] = 119, ["z"] = 58, ["name"] = "doors:hidden"}, {["x"] = 12, ["meta"] = {["fields"] = {}, ["inventory"] = {}}, ["y"] = 5, ["param1"] = 78, ["z"] = 116, ["name"] = "stairs:slab_desert_stonebrick"}, {["x"] = 12, ["meta"] = {["fields"] = {}, ["inventory"] = {}}, ["param2"] = 1, ["y"] = 6, ["param1"] = 136, ["z"] = 58, ["name"] = "stoneworks:arches_highstonebrick"}, {["x"] = 13, ["meta"] = {["fields"] = {["infotext"] = "Spawner Active (codermobs:denny)", ["command"] = "codermobs:denny 2 10 10 10 3", ["formspec"] = "field[text;Mob MinLight MaxLight Amount PlayerDist;${command}]"}, ["inventory"] = {}}, ["y"] = 2, ["z"] = 88, ["name"] = "mobs:spawner"}, {["x"] = 13, ["meta"] = {["fields"] = {}, ["inventory"] = {}}, ["y"] = 3, ["z"] = 0, ["name"] = "codersea:dirt"}, {["x"] = 13, ["meta"] = {["fields"] = {["state"] = "0", ["infotext"] = "Owned by singleplayer", ["doors_owner"] = "singleplayer"}, ["inventory"] = {}}, ["param2"] = 2, ["y"] = 4, ["param1"] = 102, ["z"] = 46, ["name"] = "doors:door_steel_a"}, {["x"] = 13, ["meta"] = {["fields"] = {["infotext"] = "Owned by singleplayer", ["state"] = "0", ["doors_owner"] = "singleplayer"}, ["inventory"] = {}}, ["param2"] = 2, ["y"] = 4, ["param1"] = 102, ["z"] = 86, ["name"] = "doors:door_steel_a"}, {["x"] = 13, ["meta"] = {["fields"] = {["infotext"] = "Owned by singleplayer", ["state"] = "0", ["doors_owner"] = "singleplayer"}, ["inventory"] = {}}, ["y"] = 4, ["param1"] = 102, ["z"] = 90, ["name"] = "doors:door_steel_a"}, {["x"] = 13, ["meta"] = {["fields"] = {}, ["inventory"] = {}}, ["y"] = 5, ["param1"] = 62, ["z"] = 0, ["name"] = "stairs:slab_desert_stonebrick"}, {["x"] = 13, ["meta"] = {["fields"] = {}, ["inventory"] = {}}, ["param2"] = 2, ["y"] = 5, ["param1"] = 119, ["z"] = 46, ["name"] = "doors:hidden"}, {["x"] = 13, ["meta"] = {["fields"] = {}, ["inventory"] = {}}, ["param2"] = 2, ["y"] = 5, ["param1"] = 119, ["z"] = 86, ["name"] = "doors:hidden"}, {["x"] = 13, ["meta"] = {["fields"] = {}, ["inventory"] = {}}, ["y"] = 5, ["param1"] = 119, ["z"] = 90, ["name"] = "doors:hidden"}, {["x"] = 13, ["meta"] = {["fields"] = {}, ["inventory"] = {}}, ["y"] = 5, ["param1"] = 62, ["z"] = 116, ["name"] = "stairs:slab_desert_stonebrick"}, {["x"] = 13, ["meta"] = {["fields"] = {}, ["inventory"] = {}}, ["param2"] = 2, ["y"] = 6, ["param1"] = 136, ["z"] = 46, ["name"] = "stoneworks:arches_highstonebrick"}, {["x"] = 13, ["meta"] = {["fields"] = {}, ["inventory"] = {}}, ["param2"] = 2, ["y"] = 6, ["param1"] = 136, ["z"] = 86, ["name"] = "stoneworks:arches_highstonebrick"}, {["x"] = 13, ["meta"] = {["fields"] = {}, ["inventory"] = {}}, ["param2"] = 2, ["y"] = 6, ["param1"] = 136, ["z"] = 90, ["name"] = "stoneworks:arches_highstonebrick"}, {["x"] = 13, ["meta"] = {["fields"] = {}, ["inventory"] = {}}, ["param2"] = 18, ["y"] = 12, ["param1"] = 110, ["z"] = 9, ["name"] = "moreblocks:panel_stonebrick"}, {["x"] = 13, ["meta"] = {["fields"] = {}, ["inventory"] = {}}, ["param2"] = 9, ["y"] = 12, ["param1"] = 110, ["z"] = 107, ["name"] = "moreblocks:panel_stonebrick"}, {["x"] = 14, ["meta"] = {["fields"] = {["infotext"] = "Spawner Active (codermobs:oerkki)", ["command"] = "codermobs:oerkki 2 10 10 10 3", ["formspec"] = "field[text;Mob MinLight MaxLight Amount PlayerDist;${command}]"}, ["inventory"] = {}}, ["y"] = 2, ["z"] = 57, ["name"] = "mobs:spawner"}, {["x"] = 14, ["meta"] = {["fields"] = {["infotext"] = "Spawner Active (codermobs:silverfish)", ["command"] = "codermobs:silverfish 2 10 10 10 3", ["formspec"] = "field[text;Mob MinLight MaxLight Amount PlayerDist;${command}]"}, ["inventory"] = {}}, ["y"] = 2, ["z"] = 59, ["name"] = "mobs:spawner"}, {["x"] = 14, ["meta"] = {["fields"] = {}, ["inventory"] = {}}, ["y"] = 3, ["z"] = 116, ["name"] = "codersea:dirt"}, {["x"] = 14, ["meta"] = {["fields"] = {["infotext"] = "Copper Locked Chest (owned by singleplayer)", ["owner"] = "singleplayer", ["formspec"] = "size[12,11]label[0,0;Copper Chest]list[context;main;0,1;12,5;]list[current_player;main;2,7;8,4;]background[-0.19,-0.25;12.4,11.75;technic_chest_form_bg.png]background[0,1;12,5;technic_copper_chest_inventory.png]background[2,7;8,4;technic_main_inventory.png]listring[]button[0,6.1;1,0.8;sort;Sort]button[2,6.1;3,0.8;autosort_to_1;Auto-sort is Off]"}, ["inventory"] = {["main"] = {"", "", "", "", "", "", "", "", "", "", "", "", "", "", "", "", "", "", "", "", "", "", "", "", "", "", "", "", "", "", "", "", "", "", "", "", "", "", "", "", "", "", "", "", "", "", "", "", "", "", "", "", "", "", "", "", "", "", "", ""}}}, ["param2"] = 2, ["y"] = 4, ["z"] = 31, ["name"] = "technic:copper_locked_chest"}, {["x"] = 14, ["meta"] = {["fields"] = {}, ["inventory"] = {}}, ["y"] = 5, ["param1"] = 46, ["z"] = 0, ["name"] = "stairs:slab_desert_stonebrick"}, {["x"] = 14, ["meta"] = {["fields"] = {}, ["inventory"] = {}}, ["y"] = 5, ["param1"] = 46, ["z"] = 116, ["name"] = "stairs:slab_desert_stonebrick"}, {["x"] = 15, ["meta"] = {["fields"] = {["infotext"] = "Spawner Active (codermobs:dirt_monster)", ["command"] = "codermobs:dirt_monster 2 10 10 10 3", ["formspec"] = "field[text;Mob MinLight MaxLight Amount PlayerDist;${command}]"}, ["inventory"] = {}}, ["y"] = 2, ["z"] = 15, ["name"] = "mobs:spawner"}, {["x"] = 15, ["meta"] = {["fields"] = {["infotext"] = "Spawner Active (codermobs:mdskeleton)", ["command"] = "codermobs:mdskeleton 2 10 10 10 3", ["formspec"] = "field[text;Mob MinLight MaxLight Amount PlayerDist;${command}]"}, ["inventory"] = {}}, ["y"] = 2, ["z"] = 17, ["name"] = "mobs:spawner"}, {["x"] = 15, ["meta"] = {["fields"] = {["infotext"] = "Spawner Active (codermobs:dirt_monster)", ["command"] = "codermobs:dirt_monster 2 10 10 10 3", ["formspec"] = "field[text;Mob MinLight MaxLight Amount PlayerDist;${command}]"}, ["inventory"] = {}}, ["y"] = 2, ["z"] = 19, ["name"] = "mobs:spawner"}, {["x"] = 15, ["meta"] = {["fields"] = {["infotext"] = "Spawner Active (codermobs:tree_monster)", ["command"] = "codermobs:tree_monster 2 10 10 10 3", ["formspec"] = "field[text;Mob MinLight MaxLight Amount PlayerDist;${command}]"}, ["inventory"] = {}}, ["y"] = 2, ["z"] = 21, ["name"] = "mobs:spawner"}, {["x"] = 15, ["meta"] = {["fields"] = {}, ["inventory"] = {}}, ["y"] = 2, ["z"] = 23, ["name"] = "tsm_pyramids:spawner_mummy"}, {["x"] = 15, ["meta"] = {["fields"] = {["infotext"] = "Spawner Active (codermobs:tree_monster)", ["command"] = "codermobs:tree_monster 2 10 10 10 3", ["formspec"] = "field[text;Mob MinLight MaxLight Amount PlayerDist;${command}]"}, ["inventory"] = {}}, ["y"] = 2, ["z"] = 25, ["name"] = "mobs:spawner"}, {["x"] = 15, ["meta"] = {["fields"] = {["infotext"] = "Spawner Not Active (enter settings)", ["command"] = "codermobs:vombie 2 10 10 10 3", ["formspec"] = "field[text;Mob MinLight MaxLight Amount PlayerDist;${command}]"}, ["inventory"] = {}}, ["y"] = 2, ["z"] = 34, ["name"] = "mobs:spawner"}, {["x"] = 15, ["meta"] = {["fields"] = {["infotext"] = "Spawner Active (codermobs:oerkki)", ["command"] = "codermobs:oerkki 2 10 10 10 3", ["formspec"] = "field[text;Mob MinLight MaxLight Amount PlayerDist;${command}]"}, ["inventory"] = {}}, ["y"] = 2, ["z"] = 38, ["name"] = "mobs:spawner"}, {["x"] = 15, ["meta"] = {["fields"] = {["infotext"] = "Spawner Not Active (enter settings)", ["command"] = "codermobs:vombie 2 10 10 10 3", ["formspec"] = "field[text;Mob MinLight MaxLight Amount PlayerDist;${command}]"}, ["inventory"] = {}}, ["y"] = 2, ["z"] = 41, ["name"] = "mobs:spawner"}, {["x"] = 15, ["meta"] = {["fields"] = {["infotext"] = "Spawner Active (codermobs:oerkki)", ["command"] = "codermobs:oerkki 2 10 10 10 3", ["formspec"] = "field[text;Mob MinLight MaxLight Amount PlayerDist;${command}]"}, ["inventory"] = {}}, ["y"] = 2, ["z"] = 65, ["name"] = "mobs:spawner"}, {["x"] = 15, ["meta"] = {["fields"] = {["infotext"] = "Spawner Active (codermobs:denny)", ["command"] = "codermobs:denny 2 10 10 10 3", ["formspec"] = "field[text;Mob MinLight MaxLight Amount PlayerDist;${command}]"}, ["inventory"] = {}}, ["y"] = 2, ["z"] = 88, ["name"] = "mobs:spawner"}, {["x"] = 15, ["meta"] = {["fields"] = {}, ["inventory"] = {}}, ["y"] = 3, ["z"] = 116, ["name"] = "codersea:dirt"}, {["x"] = 15, ["meta"] = {["fields"] = {["infotext"] = "Copper Locked Chest (owned by singleplayer)", ["owner"] = "singleplayer", ["formspec"] = "size[12,11]label[0,0;Copper Chest]list[context;main;0,1;12,5;]list[current_player;main;2,7;8,4;]background[-0.19,-0.25;12.4,11.75;technic_chest_form_bg.png]background[0,1;12,5;technic_copper_chest_inventory.png]background[2,7;8,4;technic_main_inventory.png]listring[]button[0,6.1;1,0.8;sort;Sort]button[2,6.1;3,0.8;autosort_to_1;Auto-sort is Off]"}, ["inventory"] = {["main"] = {"", "", "", "", "", "", "", "", "", "", "", "", "", "", "", "", "", "", "", "", "", "", "", "", "", "", "", "", "", "", "", "", "", "", "", "", "", "", "", "", "", "", "", "", "", "", "", "", "", "", "", "", "", "", "", "", "", "", "", ""}}}, ["param2"] = 2, ["y"] = 4, ["z"] = 31, ["name"] = "technic:copper_locked_chest"}, {["x"] = 15, ["meta"] = {["fields"] = {}, ["inventory"] = {}}, ["y"] = 5, ["param1"] = 30, ["z"] = 0, ["name"] = "stairs:slab_desert_stonebrick"}, {["x"] = 15, ["meta"] = {["fields"] = {}, ["inventory"] = {}}, ["y"] = 5, ["param1"] = 30, ["z"] = 116, ["name"] = "stairs:slab_desert_stonebrick"}, {["x"] = 16, ["meta"] = {["fields"] = {}, ["inventory"] = {}}, ["y"] = 1, ["z"] = 116, ["name"] = "codersea:dirt"}, {["x"] = 16, ["meta"] = {["fields"] = {}, ["inventory"] = {}}, ["y"] = 2, ["z"] = 116, ["name"] = "codersea:dirt"}, {["x"] = 16, ["meta"] = {["fields"] = {}, ["inventory"] = {}}, ["y"] = 3, ["z"] = 0, ["name"] = "codersea:dirt"}, {["x"] = 16, ["meta"] = {["fields"] = {["infotext"] = "Copper Locked Chest (owned by singleplayer)", ["owner"] = "singleplayer", ["formspec"] = "size[12,11]label[0,0;Copper Chest]list[context;main;0,1;12,5;]list[current_player;main;2,7;8,4;]background[-0.19,-0.25;12.4,11.75;technic_chest_form_bg.png]background[0,1;12,5;technic_copper_chest_inventory.png]background[2,7;8,4;technic_main_inventory.png]listring[]button[0,6.1;1,0.8;sort;Sort]button[2,6.1;3,0.8;autosort_to_1;Auto-sort is Off]"}, ["inventory"] = {["main"] = {"", "", "", "", "", "", "", "", "", "", "", "", "", "", "", "", "", "", "", "", "", "", "", "", "", "", "", "", "", "", "", "", "", "", "", "", "", "", "", "", "", "", "", "", "", "", "", "", "", "", "", "", "", "", "", "", "", "", "", ""}}}, ["param2"] = 2, ["y"] = 4, ["z"] = 31, ["name"] = "technic:copper_locked_chest"}, {["x"] = 16, ["meta"] = {["fields"] = {}, ["inventory"] = {}}, ["y"] = 5, ["param1"] = 14, ["z"] = 0, ["name"] = "stairs:slab_desert_stonebrick"}, {["x"] = 16, ["meta"] = {["fields"] = {}, ["inventory"] = {}}, ["y"] = 5, ["param1"] = 14, ["z"] = 116, ["name"] = "stairs:slab_desert_stonebrick"}, {["x"] = 17, ["meta"] = {["fields"] = {}, ["inventory"] = {}}, ["y"] = 2, ["z"] = 65, ["name"] = "tsm_pyramids:spawner_mummy"}, {["x"] = 17, ["meta"] = {["fields"] = {["infotext"] = "Spawner Active (codermobs:denny)", ["command"] = "codermobs:denny 2 10 10 10 3", ["formspec"] = "field[text;Mob MinLight MaxLight Amount PlayerDist;${command}]"}, ["inventory"] = {}}, ["y"] = 2, ["z"] = 83, ["name"] = "mobs:spawner"}, {["x"] = 17, ["meta"] = {["fields"] = {["infotext"] = "Spawner Active (codermobs:denny)", ["command"] = "codermobs:denny 2 10 10 10 3", ["formspec"] = "field[text;Mob MinLight MaxLight Amount PlayerDist;${command}]"}, ["inventory"] = {}}, ["y"] = 2, ["z"] = 93, ["name"] = "mobs:spawner"}, {["x"] = 17, ["meta"] = {["fields"] = {["infotext"] = "Spawner Active (codermobs:denny)", ["command"] = "codermobs:denny 2 10 10 10 3", ["formspec"] = "field[text;Mob MinLight MaxLight Amount PlayerDist;${command}]"}, ["inventory"] = {}}, ["y"] = 2, ["z"] = 103, ["name"] = "mobs:spawner"}, {["x"] = 17, ["meta"] = {["fields"] = {}, ["inventory"] = {}}, ["y"] = 5, ["param1"] = 14, ["z"] = 0, ["name"] = "stairs:slab_desert_stonebrick"}, {["x"] = 17, ["meta"] = {["fields"] = {}, ["inventory"] = {}}, ["y"] = 5, ["param1"] = 14, ["z"] = 116, ["name"] = "stairs:slab_desert_stonebrick"}, {["x"] = 18, ["meta"] = {["fields"] = {}, ["inventory"] = {}}, ["y"] = 5, ["param1"] = 14, ["z"] = 0, ["name"] = "stairs:slab_desert_stonebrick"}, {["x"] = 18, ["meta"] = {["fields"] = {}, ["inventory"] = {}}, ["y"] = 5, ["param1"] = 14, ["z"] = 116, ["name"] = "stairs:slab_desert_stonebrick"}, {["x"] = 19, ["meta"] = {["fields"] = {["infotext"] = "Spawner Active (codermobs:tree_monster)", ["command"] = "codermobs:tree_monster 2 10 10 10 3", ["formspec"] = "field[text;Mob MinLight MaxLight Amount PlayerDist;${command}]"}, ["inventory"] = {}}, ["y"] = 2, ["z"] = 55, ["name"] = "mobs:spawner"}, {["x"] = 19, ["meta"] = {["fields"] = {["infotext"] = "Spawner Active (codermobs:tree_monster)", ["command"] = "codermobs:tree_monster 2 10 10 10 3", ["formspec"] = "field[text;Mob MinLight MaxLight Amount PlayerDist;${command}]"}, ["inventory"] = {}}, ["y"] = 2, ["z"] = 61, ["name"] = "mobs:spawner"}, {["x"] = 19, ["meta"] = {["fields"] = {["infotext"] = "Spawner Active (codermobs:mdskeleton)", ["command"] = "codermobs:mdskeleton 2 10 10 10 3", ["formspec"] = "field[text;Mob MinLight MaxLight Amount PlayerDist;${command}]"}, ["inventory"] = {}}, ["y"] = 2, ["z"] = 65, ["name"] = "mobs:spawner"}, {["x"] = 19, ["meta"] = {["fields"] = {}, ["inventory"] = {}}, ["y"] = 5, ["param1"] = 14, ["z"] = 0, ["name"] = "stairs:slab_desert_stonebrick"}, {["x"] = 19, ["meta"] = {["fields"] = {}, ["inventory"] = {}}, ["y"] = 5, ["param1"] = 14, ["z"] = 116, ["name"] = "stairs:slab_desert_stonebrick"}, {["x"] = 20, ["meta"] = {["fields"] = {}, ["inventory"] = {}}, ["param2"] = 9, ["y"] = 4, ["param1"] = 187, ["z"] = 18, ["name"] = "moreblocks:panel_sandstonebrick"}, {["x"] = 20, ["meta"] = {["fields"] = {}, ["inventory"] = {}}, ["param2"] = 16, ["y"] = 4, ["param1"] = 204, ["z"] = 19, ["name"] = "stairs:slab_sandstonebrick"}, {["x"] = 20, ["meta"] = {["fields"] = {}, ["inventory"] = {}}, ["param2"] = 16, ["y"] = 4, ["param1"] = 204, ["z"] = 20, ["name"] = "stairs:slab_sandstonebrick"}, {["x"] = 20, ["meta"] = {["fields"] = {}, ["inventory"] = {}}, ["param2"] = 16, ["y"] = 4, ["param1"] = 204, ["z"] = 21, ["name"] = "stairs:slab_sandstonebrick"}, {["x"] = 20, ["meta"] = {["fields"] = {}, ["inventory"] = {}}, ["param2"] = 18, ["y"] = 4, ["param1"] = 187, ["z"] = 22, ["name"] = "moreblocks:panel_sandstonebrick"}, {["x"] = 20, ["meta"] = {["fields"] = {["infotext"] = "Owned by singleplayer", ["state"] = "0", ["doors_owner"] = "singleplayer"}, ["inventory"] = {}}, ["param2"] = 3, ["y"] = 4, ["param1"] = 102, ["z"] = 88, ["name"] = "doors:door_steel_a"}, {["x"] = 20, ["meta"] = {["fields"] = {}, ["inventory"] = {}}, ["y"] = 5, ["param1"] = 30, ["z"] = 0, ["name"] = "stairs:slab_desert_stonebrick"}, {["x"] = 20, ["meta"] = {["fields"] = {}, ["inventory"] = {}}, ["param2"] = 3, ["y"] = 5, ["param1"] = 85, ["z"] = 88, ["name"] = "doors:hidden"}, {["x"] = 20, ["meta"] = {["fields"] = {}, ["inventory"] = {}}, ["y"] = 5, ["param1"] = 30, ["z"] = 116, ["name"] = "stairs:slab_desert_stonebrick"}, {["x"] = 20, ["meta"] = {["fields"] = {}, ["inventory"] = {}}, ["param2"] = 3, ["y"] = 6, ["param1"] = 68, ["z"] = 88, ["name"] = "stoneworks:arches_highstonebrick"}, {["x"] = 21, ["meta"] = {["fields"] = {}, ["inventory"] = {}}, ["param2"] = 3, ["y"] = 4, ["param1"] = 110, ["z"] = 7, ["name"] = "moreblocks:panel_wood"}, {["x"] = 21, ["meta"] = {["fields"] = {}, ["inventory"] = {}}, ["param2"] = 3, ["y"] = 4, ["param1"] = 126, ["z"] = 8, ["name"] = "moreblocks:panel_wood"}, {["x"] = 21, ["meta"] = {["fields"] = {}, ["inventory"] = {}}, ["param2"] = 3, ["y"] = 4, ["param1"] = 141, ["z"] = 9, ["name"] = "moreblocks:panel_wood"}, {["x"] = 21, ["meta"] = {["fields"] = {}, ["inventory"] = {}}, ["param2"] = 8, ["y"] = 4, ["param1"] = 204, ["z"] = 18, ["name"] = "stairs:slab_sandstonebrick"}, {["x"] = 21, ["meta"] = {["fields"] = {}, ["inventory"] = {}}, ["y"] = 4, ["param1"] = 221, ["z"] = 19, ["name"] = "default:water_gel_slope"}, {["x"] = 21, ["meta"] = {["fields"] = {}, ["inventory"] = {}}, ["y"] = 4, ["param1"] = 221, ["z"] = 20, ["name"] = "default:water_gel_slope"}, {["x"] = 21, ["meta"] = {["fields"] = {}, ["inventory"] = {}}, ["y"] = 4, ["param1"] = 221, ["z"] = 21, ["name"] = "default:water_gel_slope"}, {["x"] = 21, ["meta"] = {["fields"] = {}, ["inventory"] = {}}, ["param2"] = 4, ["y"] = 4, ["param1"] = 204, ["z"] = 22, ["name"] = "stairs:slab_sandstonebrick"}, {["x"] = 21, ["meta"] = {["fields"] = {}, ["inventory"] = {}}, ["y"] = 5, ["param1"] = 14, ["z"] = 0, ["name"] = "stairs:slab_desert_stonebrick"}, {["x"] = 21, ["meta"] = {["fields"] = {}, ["inventory"] = {}}, ["y"] = 5, ["param1"] = 221, ["z"] = 20, ["name"] = "default:water_gel_slope"}, {["x"] = 21, ["meta"] = {["fields"] = {}, ["inventory"] = {}}, ["y"] = 5, ["param1"] = 14, ["z"] = 116, ["name"] = "stairs:slab_desert_stonebrick"}, {["x"] = 21, ["meta"] = {["fields"] = {}, ["inventory"] = {}}, ["y"] = 6, ["param1"] = 221, ["z"] = 20, ["name"] = "default:water_gel_slope"}, {["x"] = 22, ["meta"] = {["fields"] = {["state"] = "0", ["infotext"] = "Owned by singleplayer", ["doors_owner"] = "singleplayer"}, ["inventory"] = {}}, ["y"] = 4, ["param1"] = 108, ["z"] = 10, ["name"] = "doors:door_steel_a"}, {["x"] = 22, ["meta"] = {["fields"] = {}, ["inventory"] = {}}, ["param2"] = 8, ["y"] = 4, ["param1"] = 204, ["z"] = 18, ["name"] = "stairs:slab_sandstonebrick"}, {["x"] = 22, ["meta"] = {["fields"] = {}, ["inventory"] = {}}, ["y"] = 4, ["param1"] = 221, ["z"] = 19, ["name"] = "default:water_gel_slope"}, {["x"] = 22, ["meta"] = {["fields"] = {}, ["inventory"] = {}}, ["y"] = 4, ["param1"] = 221, ["z"] = 20, ["name"] = "default:water_gel"}, {["x"] = 22, ["meta"] = {["fields"] = {}, ["inventory"] = {}}, ["y"] = 4, ["param1"] = 221, ["z"] = 21, ["name"] = "default:water_gel_slope"}, {["x"] = 22, ["meta"] = {["fields"] = {}, ["inventory"] = {}}, ["param2"] = 4, ["y"] = 4, ["param1"] = 204, ["z"] = 22, ["name"] = "stairs:slab_sandstonebrick"}, {["x"] = 22, ["meta"] = {["fields"] = {["state"] = "0", ["infotext"] = "Owned by singleplayer", ["doors_owner"] = "singleplayer"}, ["inventory"] = {}}, ["y"] = 4, ["param1"] = 102, ["z"] = 30, ["name"] = "doors:door_steel_a"}, {["x"] = 22, ["meta"] = {["fields"] = {["state"] = "0", ["infotext"] = "Owned by singleplayer", ["doors_owner"] = "singleplayer"}, ["inventory"] = {}}, ["param2"] = 2, ["y"] = 4, ["param1"] = 102, ["z"] = 46, ["name"] = "doors:door_steel_a"}, {["x"] = 22, ["meta"] = {["fields"] = {}, ["inventory"] = {}}, ["y"] = 4, ["param1"] = 102, ["z"] = 66, ["name"] = "stoneworks:arches_low_quadbronzeblock"}, {["x"] = 22, ["meta"] = {["fields"] = {}, ["inventory"] = {}}, ["param2"] = 4, ["y"] = 4, ["param1"] = 85, ["z"] = 67, ["name"] = "moreblocks:slab_bronzeblock_1"}, {["x"] = 22, ["meta"] = {["fields"] = {["infotext"] = "Copper Locked Chest (owned by singleplayer)", ["owner"] = "singleplayer", ["formspec"] = "size[12,11]label[0,0;Copper Chest]list[context;main;0,1;12,5;]list[current_player;main;2,7;8,4;]background[-0.19,-0.25;12.4,11.75;technic_chest_form_bg.png]background[0,1;12,5;technic_copper_chest_inventory.png]background[2,7;8,4;technic_main_inventory.png]listring[]button[0,6.1;1,0.8;sort;Sort]button[2,6.1;3,0.8;autosort_to_1;Auto-sort is Off]"}, ["inventory"] = {["main"] = {"", "", "", "", "", "", "", "", "", "", "", "", "", "", "", "", "", "", "", "", "", "", "", "", "", "", "", "", "", "", "", "", "", "", "", "", "", "", "", "", "", "", "", "", "", "", "", "", "", "", "", "", "", "", "", "", "", "", "", ""}}}, ["y"] = 4, ["z"] = 68, ["name"] = "technic:copper_locked_chest"}, {["x"] = 22, ["meta"] = {["fields"] = {["infotext"] = "Owned by singleplayer", ["state"] = "0", ["doors_owner"] = "singleplayer"}, ["inventory"] = {}}, ["y"] = 4, ["param1"] = 102, ["z"] = 70, ["name"] = "doors:door_steel_a"}, {["x"] = 22, ["meta"] = {["fields"] = {["infotext"] = "Owned by singleplayer", ["state"] = "0", ["doors_owner"] = "singleplayer"}, ["inventory"] = {}}, ["param2"] = 2, ["y"] = 4, ["param1"] = 108, ["z"] = 106, ["name"] = "doors:door_steel_a"}, {["x"] = 22, ["meta"] = {["fields"] = {}, ["inventory"] = {}}, ["y"] = 5, ["param1"] = 124, ["z"] = 10, ["name"] = "doors:hidden"}, {["x"] = 22, ["meta"] = {["fields"] = {}, ["inventory"] = {}}, ["y"] = 5, ["param1"] = 221, ["z"] = 19, ["name"] = "default:water_gel_slope"}, {["x"] = 22, ["meta"] = {["fields"] = {}, ["inventory"] = {}}, ["y"] = 5, ["param1"] = 221, ["z"] = 20, ["name"] = "default:water_gel"}, {["x"] = 22, ["meta"] = {["fields"] = {}, ["inventory"] = {}}, ["y"] = 5, ["param1"] = 221, ["z"] = 21, ["name"] = "default:water_gel_slope"}, {["x"] = 22, ["meta"] = {["fields"] = {}, ["inventory"] = {}}, ["y"] = 5, ["param1"] = 119, ["z"] = 30, ["name"] = "doors:hidden"}, {["x"] = 22, ["meta"] = {["fields"] = {}, ["inventory"] = {}}, ["param2"] = 2, ["y"] = 5, ["param1"] = 119, ["z"] = 46, ["name"] = "doors:hidden"}, {["x"] = 22, ["meta"] = {["fields"] = {}, ["inventory"] = {}}, ["param2"] = 4, ["y"] = 5, ["param1"] = 102, ["z"] = 67, ["name"] = "moreblocks:panel_bronzeblock_1"}, {["x"] = 22, ["meta"] = {["fields"] = {}, ["inventory"] = {}}, ["y"] = 5, ["param1"] = 119, ["z"] = 70, ["name"] = "doors:hidden"}, {["x"] = 22, ["meta"] = {["fields"] = {}, ["inventory"] = {}}, ["param2"] = 2, ["y"] = 5, ["param1"] = 124, ["z"] = 106, ["name"] = "doors:hidden"}, {["x"] = 22, ["meta"] = {["fields"] = {}, ["inventory"] = {}}, ["y"] = 5, ["param1"] = 14, ["z"] = 116, ["name"] = "stairs:slab_desert_stonebrick"}, {["x"] = 22, ["meta"] = {["fields"] = {}, ["inventory"] = {}}, ["param2"] = 2, ["y"] = 6, ["param1"] = 140, ["z"] = 10, ["name"] = "stoneworks:arches_highstonebrick"}, {["x"] = 22, ["meta"] = {["fields"] = {}, ["inventory"] = {}}, ["y"] = 6, ["param1"] = 221, ["z"] = 19, ["name"] = "default:water_gel_slope"}, {["x"] = 22, ["meta"] = {["fields"] = {}, ["inventory"] = {}}, ["y"] = 6, ["param1"] = 221, ["z"] = 20, ["name"] = "default:water_gel"}, {["x"] = 22, ["meta"] = {["fields"] = {}, ["inventory"] = {}}, ["y"] = 6, ["param1"] = 221, ["z"] = 21, ["name"] = "default:water_gel_slope"}, {["x"] = 22, ["meta"] = {["fields"] = {}, ["inventory"] = {}}, ["y"] = 6, ["param1"] = 136, ["z"] = 30, ["name"] = "stoneworks:arches_highstonebrick"}, {["x"] = 22, ["meta"] = {["fields"] = {}, ["inventory"] = {}}, ["y"] = 6, ["param1"] = 136, ["z"] = 46, ["name"] = "stoneworks:arches_highstonebrick"}, {["x"] = 22, ["meta"] = {["fields"] = {}, ["inventory"] = {}}, ["y"] = 6, ["param1"] = 136, ["z"] = 70, ["name"] = "stoneworks:arches_highstonebrick"}, {["x"] = 22, ["meta"] = {["fields"] = {}, ["inventory"] = {}}, ["y"] = 6, ["param1"] = 140, ["z"] = 106, ["name"] = "stoneworks:arches_highstonebrick"}, {["x"] = 23, ["meta"] = {["fields"] = {}, ["inventory"] = {}}, ["param2"] = 1, ["y"] = 4, ["param1"] = 110, ["z"] = 7, ["name"] = "moreblocks:panel_wood"}, {["x"] = 23, ["meta"] = {["fields"] = {}, ["inventory"] = {}}, ["param2"] = 1, ["y"] = 4, ["param1"] = 126, ["z"] = 8, ["name"] = "moreblocks:panel_wood"}, {["x"] = 23, ["meta"] = {["fields"] = {}, ["inventory"] = {}}, ["param2"] = 1, ["y"] = 4, ["param1"] = 141, ["z"] = 9, ["name"] = "moreblocks:panel_wood"}, {["x"] = 23, ["meta"] = {["fields"] = {}, ["inventory"] = {}}, ["param2"] = 8, ["y"] = 4, ["param1"] = 204, ["z"] = 18, ["name"] = "stairs:slab_sandstonebrick"}, {["x"] = 23, ["meta"] = {["fields"] = {}, ["inventory"] = {}}, ["y"] = 4, ["param1"] = 221, ["z"] = 19, ["name"] = "default:water_gel_slope"}, {["x"] = 23, ["meta"] = {["fields"] = {}, ["inventory"] = {}}, ["y"] = 4, ["param1"] = 221, ["z"] = 20, ["name"] = "default:water_gel_slope"}, {["x"] = 23, ["meta"] = {["fields"] = {}, ["inventory"] = {}}, ["y"] = 4, ["param1"] = 221, ["z"] = 21, ["name"] = "default:water_gel_slope"}, {["x"] = 23, ["meta"] = {["fields"] = {}, ["inventory"] = {}}, ["param2"] = 4, ["y"] = 4, ["param1"] = 204, ["z"] = 22, ["name"] = "stairs:slab_sandstonebrick"}, {["x"] = 23, ["meta"] = {["fields"] = {}, ["inventory"] = {}}, ["y"] = 5, ["param1"] = 14, ["z"] = 0, ["name"] = "stairs:slab_desert_stonebrick"}, {["x"] = 23, ["meta"] = {["fields"] = {}, ["inventory"] = {}}, ["y"] = 5, ["param1"] = 221, ["z"] = 20, ["name"] = "default:water_gel_slope"}, {["x"] = 23, ["meta"] = {["fields"] = {}, ["inventory"] = {}}, ["y"] = 5, ["param1"] = 14, ["z"] = 116, ["name"] = "stairs:slab_desert_stonebrick"}, {["x"] = 23, ["meta"] = {["fields"] = {}, ["inventory"] = {}}, ["y"] = 6, ["param1"] = 221, ["z"] = 20, ["name"] = "default:water_gel_slope"}, {["x"] = 24, ["meta"] = {["fields"] = {}, ["inventory"] = {}}, ["param2"] = 12, ["y"] = 4, ["param1"] = 187, ["z"] = 18, ["name"] = "moreblocks:panel_sandstonebrick"}, {["x"] = 24, ["meta"] = {["fields"] = {}, ["inventory"] = {}}, ["param2"] = 12, ["y"] = 4, ["param1"] = 204, ["z"] = 19, ["name"] = "stairs:slab_sandstonebrick"}, {["x"] = 24, ["meta"] = {["fields"] = {}, ["inventory"] = {}}, ["param2"] = 12, ["y"] = 4, ["param1"] = 204, ["z"] = 20, ["name"] = "stairs:slab_sandstonebrick"}, {["x"] = 24, ["meta"] = {["fields"] = {}, ["inventory"] = {}}, ["param2"] = 12, ["y"] = 4, ["param1"] = 204, ["z"] = 21, ["name"] = "stairs:slab_sandstonebrick"}, {["x"] = 24, ["meta"] = {["fields"] = {}, ["inventory"] = {}}, ["param2"] = 7, ["y"] = 4, ["param1"] = 187, ["z"] = 22, ["name"] = "moreblocks:panel_sandstonebrick"}, {["x"] = 24, ["meta"] = {["fields"] = {["infotext"] = "Owned by singleplayer", ["state"] = "0", ["doors_owner"] = "singleplayer"}, ["inventory"] = {}}, ["param2"] = 1, ["y"] = 4, ["param1"] = 102, ["z"] = 88, ["name"] = "doors:door_steel_a"}, {["x"] = 24, ["meta"] = {["fields"] = {}, ["inventory"] = {}}, ["y"] = 5, ["param1"] = 30, ["z"] = 0, ["name"] = "stairs:slab_desert_stonebrick"}, {["x"] = 24, ["meta"] = {["fields"] = {}, ["inventory"] = {}}, ["param2"] = 1, ["y"] = 5, ["param1"] = 85, ["z"] = 88, ["name"] = "doors:hidden"}, {["x"] = 24, ["meta"] = {["fields"] = {}, ["inventory"] = {}}, ["y"] = 5, ["param1"] = 30, ["z"] = 116, ["name"] = "stairs:slab_desert_stonebrick"}, {["x"] = 24, ["meta"] = {["fields"] = {}, ["inventory"] = {}}, ["param2"] = 1, ["y"] = 6, ["param1"] = 68, ["z"] = 88, ["name"] = "stoneworks:arches_highstonebrick"}, {["x"] = 25, ["meta"] = {["fields"] = {["infotext"] = "Spawner Active (codermobs:tree_monster)", ["command"] = "codermobs:tree_monster 2 10 10 10 3", ["formspec"] = "field[text;Mob MinLight MaxLight Amount PlayerDist;${command}]"}, ["inventory"] = {}}, ["y"] = 2, ["z"] = 55, ["name"] = "mobs:spawner"}, {["x"] = 25, ["meta"] = {["fields"] = {["infotext"] = "Spawner Active (codermobs:tree_monster)", ["command"] = "codermobs:tree_monster 2 10 10 10 3", ["formspec"] = "field[text;Mob MinLight MaxLight Amount PlayerDist;${command}]"}, ["inventory"] = {}}, ["y"] = 2, ["z"] = 61, ["name"] = "mobs:spawner"}, {["x"] = 25, ["meta"] = {["fields"] = {["infotext"] = "Spawner Active (codermobs:mdskeleton)", ["command"] = "codermobs:mdskeleton 2 10 10 10 3", ["formspec"] = "field[text;Mob MinLight MaxLight Amount PlayerDist;${command}]"}, ["inventory"] = {}}, ["y"] = 2, ["z"] = 65, ["name"] = "mobs:spawner"}, {["x"] = 25, ["meta"] = {["fields"] = {}, ["inventory"] = {}}, ["y"] = 5, ["param1"] = 14, ["z"] = 0, ["name"] = "stairs:slab_desert_stonebrick"}, {["x"] = 25, ["meta"] = {["fields"] = {}, ["inventory"] = {}}, ["y"] = 5, ["param1"] = 14, ["z"] = 116, ["name"] = "stairs:slab_desert_stonebrick"}, {["x"] = 26, ["meta"] = {["fields"] = {}, ["inventory"] = {}}, ["y"] = 5, ["param1"] = 14, ["z"] = 0, ["name"] = "stairs:slab_desert_stonebrick"}, {["x"] = 26, ["meta"] = {["fields"] = {}, ["inventory"] = {}}, ["y"] = 5, ["param1"] = 14, ["z"] = 116, ["name"] = "stairs:slab_desert_stonebrick"}, {["x"] = 27, ["meta"] = {["fields"] = {}, ["inventory"] = {}}, ["y"] = 2, ["z"] = 65, ["name"] = "tsm_pyramids:spawner_mummy"}, {["x"] = 27, ["meta"] = {["fields"] = {["infotext"] = "Spawner Active (codermobs:denny)", ["command"] = "codermobs:denny 2 10 10 10 3", ["formspec"] = "field[text;Mob MinLight MaxLight Amount PlayerDist;${command}]"}, ["inventory"] = {}}, ["y"] = 2, ["z"] = 83, ["name"] = "mobs:spawner"}, {["x"] = 27, ["meta"] = {["fields"] = {["infotext"] = "Spawner Active (codermobs:denny)", ["command"] = "codermobs:denny 2 10 10 10 3", ["formspec"] = "field[text;Mob MinLight MaxLight Amount PlayerDist;${command}]"}, ["inventory"] = {}}, ["y"] = 2, ["z"] = 93, ["name"] = "mobs:spawner"}, {["x"] = 27, ["meta"] = {["fields"] = {["infotext"] = "Spawner Active (codermobs:denny)", ["command"] = "codermobs:denny 2 10 10 10 3", ["formspec"] = "field[text;Mob MinLight MaxLight Amount PlayerDist;${command}]"}, ["inventory"] = {}}, ["y"] = 2, ["z"] = 102, ["name"] = "mobs:spawner"}, {["x"] = 27, ["meta"] = {["fields"] = {}, ["inventory"] = {}}, ["y"] = 5, ["param1"] = 14, ["z"] = 0, ["name"] = "stairs:slab_desert_stonebrick"}, {["x"] = 27, ["meta"] = {["fields"] = {}, ["inventory"] = {}}, ["y"] = 5, ["param1"] = 14, ["z"] = 116, ["name"] = "stairs:slab_desert_stonebrick"}, {["x"] = 28, ["meta"] = {["fields"] = {}, ["inventory"] = {}}, ["y"] = 1, ["z"] = 116, ["name"] = "codersea:dirt"}, {["x"] = 28, ["meta"] = {["fields"] = {}, ["inventory"] = {}}, ["y"] = 2, ["z"] = 116, ["name"] = "codersea:dirt"}, {["x"] = 28, ["meta"] = {["fields"] = {}, ["inventory"] = {}}, ["y"] = 3, ["z"] = 0, ["name"] = "codersea:dirt"}, {["x"] = 28, ["meta"] = {["fields"] = {}, ["inventory"] = {}}, ["y"] = 3, ["z"] = 116, ["name"] = "codersea:dirt"}, {["x"] = 28, ["meta"] = {["fields"] = {["owner"] = "singleplayer", ["infotext"] = "Copper Locked Chest (owned by singleplayer)", ["formspec"] = "size[12,11]label[0,0;Copper Chest]list[context;main;0,1;12,5;]list[current_player;main;2,7;8,4;]background[-0.19,-0.25;12.4,11.75;technic_chest_form_bg.png]background[0,1;12,5;technic_copper_chest_inventory.png]background[2,7;8,4;technic_main_inventory.png]listring[]button[0,6.1;1,0.8;sort;Sort]button[2,6.1;3,0.8;autosort_to_1;Auto-sort is Off]"}, ["inventory"] = {["main"] = {"", "", "", "", "", "", "", "", "", "", "", "", "", "", "", "", "", "", "", "", "", "", "", "", "", "", "", "", "", "", "", "", "", "", "", "", "", "", "", "", "", "", "", "", "", "", "", "", "", "", "", "", "", "", "", "", "", "", "", ""}}}, ["param2"] = 2, ["y"] = 4, ["z"] = 31, ["name"] = "technic:copper_locked_chest"}, {["x"] = 28, ["meta"] = {["fields"] = {}, ["inventory"] = {}}, ["y"] = 5, ["param1"] = 14, ["z"] = 0, ["name"] = "stairs:slab_desert_stonebrick"}, {["x"] = 28, ["meta"] = {["fields"] = {}, ["inventory"] = {}}, ["y"] = 5, ["param1"] = 14, ["z"] = 116, ["name"] = "stairs:slab_desert_stonebrick"}, {["x"] = 29, ["meta"] = {["fields"] = {["infotext"] = "Spawner Active (codermobs:dirt_monster)", ["command"] = "codermobs:dirt_monster 2 10 10 10 3", ["formspec"] = "field[text;Mob MinLight MaxLight Amount PlayerDist;${command}]"}, ["inventory"] = {}}, ["y"] = 2, ["z"] = 15, ["name"] = "mobs:spawner"}, {["x"] = 29, ["meta"] = {["fields"] = {["infotext"] = "Spawner Active (codermobs:mdskeleton)", ["command"] = "codermobs:mdskeleton 2 10 10 10 3", ["formspec"] = "field[text;Mob MinLight MaxLight Amount PlayerDist;${command}]"}, ["inventory"] = {}}, ["y"] = 2, ["z"] = 17, ["name"] = "mobs:spawner"}, {["x"] = 29, ["meta"] = {["fields"] = {["infotext"] = "Spawner Active (codermobs:dirt_monster)", ["command"] = "codermobs:dirt_monster 2 10 10 10 3", ["formspec"] = "field[text;Mob MinLight MaxLight Amount PlayerDist;${command}]"}, ["inventory"] = {}}, ["y"] = 2, ["z"] = 19, ["name"] = "mobs:spawner"}, {["x"] = 29, ["meta"] = {["fields"] = {["infotext"] = "Spawner Active (codermobs:tree_monster)", ["command"] = "codermobs:tree_monster 2 10 10 10 3", ["formspec"] = "field[text;Mob MinLight MaxLight Amount PlayerDist;${command}]"}, ["inventory"] = {}}, ["y"] = 2, ["z"] = 21, ["name"] = "mobs:spawner"}, {["x"] = 29, ["meta"] = {["fields"] = {}, ["inventory"] = {}}, ["y"] = 2, ["z"] = 23, ["name"] = "tsm_pyramids:spawner_mummy"}, {["x"] = 29, ["meta"] = {["fields"] = {["infotext"] = "Spawner Active (codermobs:tree_monster)", ["command"] = "codermobs:tree_monster 2 10 10 10 3", ["formspec"] = "field[text;Mob MinLight MaxLight Amount PlayerDist;${command}]"}, ["inventory"] = {}}, ["y"] = 2, ["z"] = 25, ["name"] = "mobs:spawner"}, {["x"] = 29, ["meta"] = {["fields"] = {["infotext"] = "Spawner Not Active (enter settings)", ["command"] = "codermobs:vombie 2 10 10 10 3", ["formspec"] = "field[text;Mob MinLight MaxLight Amount PlayerDist;${command}]"}, ["inventory"] = {}}, ["y"] = 2, ["z"] = 35, ["name"] = "mobs:spawner"}, {["x"] = 29, ["meta"] = {["fields"] = {["infotext"] = "Spawner Active (codermobs:oerkki)", ["command"] = "codermobs:oerkki 2 10 10 10 3", ["formspec"] = "field[text;Mob MinLight MaxLight Amount PlayerDist;${command}]"}, ["inventory"] = {}}, ["y"] = 2, ["z"] = 38, ["name"] = "mobs:spawner"}, {["x"] = 29, ["meta"] = {["fields"] = {["infotext"] = "Spawner Not Active (enter settings)", ["command"] = "codermobs:vombie 2 10 10 10 3", ["formspec"] = "field[text;Mob MinLight MaxLight Amount PlayerDist;${command}]"}, ["inventory"] = {}}, ["y"] = 2, ["z"] = 41, ["name"] = "mobs:spawner"}, {["x"] = 29, ["meta"] = {["fields"] = {["infotext"] = "Spawner Active (codermobs:oerkki)", ["command"] = "codermobs:oerkki 2 10 10 10 3", ["formspec"] = "field[text;Mob MinLight MaxLight Amount PlayerDist;${command}]"}, ["inventory"] = {}}, ["y"] = 2, ["z"] = 65, ["name"] = "mobs:spawner"}, {["x"] = 29, ["meta"] = {["fields"] = {["infotext"] = "Spawner Active (codermobs:denny)", ["command"] = "codermobs:denny 2 10 10 10 3", ["formspec"] = "field[text;Mob MinLight MaxLight Amount PlayerDist;${command}]"}, ["inventory"] = {}}, ["y"] = 2, ["z"] = 88, ["name"] = "mobs:spawner"}, {["x"] = 29, ["meta"] = {["fields"] = {}, ["inventory"] = {}}, ["y"] = 3, ["z"] = 0, ["name"] = "codersea:dirt"}, {["x"] = 29, ["meta"] = {["fields"] = {["owner"] = "singleplayer", ["infotext"] = "Copper Locked Chest (owned by singleplayer)", ["formspec"] = "size[12,11]label[0,0;Copper Chest]list[context;main;0,1;12,5;]list[current_player;main;2,7;8,4;]background[-0.19,-0.25;12.4,11.75;technic_chest_form_bg.png]background[0,1;12,5;technic_copper_chest_inventory.png]background[2,7;8,4;technic_main_inventory.png]listring[]button[0,6.1;1,0.8;sort;Sort]button[2,6.1;3,0.8;autosort_to_1;Auto-sort is Off]"}, ["inventory"] = {["main"] = {"", "", "", "", "", "", "", "", "", "", "", "", "", "", "", "", "", "", "", "", "", "", "", "", "", "", "", "", "", "", "", "", "", "", "", "", "", "", "", "", "", "", "", "", "", "", "", "", "", "", "", "", "", "", "", "", "", "", "", ""}}}, ["param2"] = 2, ["y"] = 4, ["z"] = 31, ["name"] = "technic:copper_locked_chest"}, {["x"] = 29, ["meta"] = {["fields"] = {}, ["inventory"] = {}}, ["y"] = 5, ["param1"] = 30, ["z"] = 0, ["name"] = "stairs:slab_desert_stonebrick"}, {["x"] = 29, ["meta"] = {["fields"] = {}, ["inventory"] = {}}, ["y"] = 5, ["param1"] = 30, ["z"] = 116, ["name"] = "stairs:slab_desert_stonebrick"}, {["x"] = 30, ["meta"] = {["fields"] = {["infotext"] = "Spawner Active (codermobs:oerkki)", ["command"] = "codermobs:oerkki 2 10 10 10 3", ["formspec"] = "field[text;Mob MinLight MaxLight Amount PlayerDist;${command}]"}, ["inventory"] = {}}, ["y"] = 2, ["z"] = 57, ["name"] = "mobs:spawner"}, {["x"] = 30, ["meta"] = {["fields"] = {["infotext"] = "Spawner Active (codermobs:silverfish)", ["command"] = "codermobs:silverfish 2 10 10 10 3", ["formspec"] = "field[text;Mob MinLight MaxLight Amount PlayerDist;${command}]"}, ["inventory"] = {}}, ["y"] = 2, ["z"] = 59, ["name"] = "mobs:spawner"}, {["x"] = 30, ["meta"] = {["fields"] = {}, ["inventory"] = {}}, ["y"] = 3, ["z"] = 0, ["name"] = "codersea:dirt"}, {["x"] = 30, ["meta"] = {["fields"] = {}, ["inventory"] = {}}, ["y"] = 3, ["z"] = 116, ["name"] = "codersea:dirt"}, {["x"] = 30, ["meta"] = {["fields"] = {["owner"] = "singleplayer", ["infotext"] = "Copper Locked Chest (owned by singleplayer)", ["formspec"] = "size[12,11]label[0,0;Copper Chest]list[context;main;0,1;12,5;]list[current_player;main;2,7;8,4;]background[-0.19,-0.25;12.4,11.75;technic_chest_form_bg.png]background[0,1;12,5;technic_copper_chest_inventory.png]background[2,7;8,4;technic_main_inventory.png]listring[]button[0,6.1;1,0.8;sort;Sort]button[2,6.1;3,0.8;autosort_to_1;Auto-sort is Off]"}, ["inventory"] = {["main"] = {"", "", "", "", "", "", "", "", "", "", "", "", "", "", "", "", "", "", "", "", "", "", "", "", "", "", "", "", "", "", "", "", "", "", "", "", "", "", "", "", "", "", "", "", "", "", "", "", "", "", "", "", "", "", "", "", "", "", "", ""}}}, ["param2"] = 2, ["y"] = 4, ["z"] = 31, ["name"] = "technic:copper_locked_chest"}, {["x"] = 30, ["meta"] = {["fields"] = {}, ["inventory"] = {}}, ["y"] = 5, ["param1"] = 46, ["z"] = 0, ["name"] = "stairs:slab_desert_stonebrick"}, {["x"] = 30, ["meta"] = {["fields"] = {}, ["inventory"] = {}}, ["y"] = 5, ["param1"] = 46, ["z"] = 116, ["name"] = "stairs:slab_desert_stonebrick"}, {["x"] = 31, ["meta"] = {["fields"] = {["infotext"] = "Spawner Active (codermobs:denny)", ["command"] = "codermobs:denny 2 10 10 10 3", ["formspec"] = "field[text;Mob MinLight MaxLight Amount PlayerDist;${command}]"}, ["inventory"] = {}}, ["y"] = 2, ["z"] = 88, ["name"] = "mobs:spawner"}, {["x"] = 31, ["meta"] = {["fields"] = {}, ["inventory"] = {}}, ["y"] = 3, ["z"] = 0, ["name"] = "codersea:dirt"}, {["x"] = 31, ["meta"] = {["fields"] = {["state"] = "0", ["infotext"] = "Owned by singleplayer", ["doors_owner"] = "singleplayer"}, ["inventory"] = {}}, ["param2"] = 2, ["y"] = 4, ["param1"] = 102, ["z"] = 46, ["name"] = "doors:door_steel_a"}, {["x"] = 31, ["meta"] = {["fields"] = {["infotext"] = "Owned by singleplayer", ["state"] = "0", ["doors_owner"] = "singleplayer"}, ["inventory"] = {}}, ["param2"] = 2, ["y"] = 4, ["param1"] = 102, ["z"] = 86, ["name"] = "doors:door_steel_a"}, {["x"] = 31, ["meta"] = {["fields"] = {["infotext"] = "Owned by singleplayer", ["state"] = "0", ["doors_owner"] = "singleplayer"}, ["inventory"] = {}}, ["y"] = 4, ["param1"] = 102, ["z"] = 90, ["name"] = "doors:door_steel_a"}, {["x"] = 31, ["meta"] = {["fields"] = {}, ["inventory"] = {}}, ["y"] = 5, ["param1"] = 62, ["z"] = 0, ["name"] = "stairs:slab_desert_stonebrick"}, {["x"] = 31, ["meta"] = {["fields"] = {}, ["inventory"] = {}}, ["param2"] = 2, ["y"] = 5, ["param1"] = 119, ["z"] = 46, ["name"] = "doors:hidden"}, {["x"] = 31, ["meta"] = {["fields"] = {}, ["inventory"] = {}}, ["param2"] = 2, ["y"] = 5, ["param1"] = 119, ["z"] = 86, ["name"] = "doors:hidden"}, {["x"] = 31, ["meta"] = {["fields"] = {}, ["inventory"] = {}}, ["y"] = 5, ["param1"] = 119, ["z"] = 90, ["name"] = "doors:hidden"}, {["x"] = 31, ["meta"] = {["fields"] = {}, ["inventory"] = {}}, ["y"] = 5, ["param1"] = 62, ["z"] = 116, ["name"] = "stairs:slab_desert_stonebrick"}, {["x"] = 31, ["meta"] = {["fields"] = {}, ["inventory"] = {}}, ["param2"] = 2, ["y"] = 6, ["param1"] = 136, ["z"] = 46, ["name"] = "stoneworks:arches_highstonebrick"}, {["x"] = 31, ["meta"] = {["fields"] = {}, ["inventory"] = {}}, ["param2"] = 2, ["y"] = 6, ["param1"] = 136, ["z"] = 86, ["name"] = "stoneworks:arches_highstonebrick"}, {["x"] = 31, ["meta"] = {["fields"] = {}, ["inventory"] = {}}, ["y"] = 6, ["param1"] = 136, ["z"] = 90, ["name"] = "stoneworks:arches_highstonebrick"}, {["x"] = 31, ["meta"] = {["fields"] = {}, ["inventory"] = {}}, ["param2"] = 7, ["y"] = 12, ["param1"] = 110, ["z"] = 9, ["name"] = "moreblocks:panel_stonebrick"}, {["x"] = 31, ["meta"] = {["fields"] = {}, ["inventory"] = {}}, ["param2"] = 12, ["y"] = 12, ["param1"] = 110, ["z"] = 107, ["name"] = "moreblocks:panel_stonebrick"}, {["x"] = 32, ["meta"] = {["fields"] = {["infotext"] = "Owned by singleplayer", ["state"] = "0", ["doors_owner"] = "singleplayer"}, ["inventory"] = {}}, ["param2"] = 1, ["y"] = 4, ["param1"] = 102, ["z"] = 58, ["name"] = "doors:door_steel_a"}, {["x"] = 32, ["meta"] = {["fields"] = {}, ["inventory"] = {}}, ["y"] = 5, ["param1"] = 78, ["z"] = 0, ["name"] = "stairs:slab_desert_stonebrick"}, {["x"] = 32, ["meta"] = {["fields"] = {}, ["inventory"] = {}}, ["param2"] = 1, ["y"] = 5, ["param1"] = 119, ["z"] = 58, ["name"] = "doors:hidden"}, {["x"] = 32, ["meta"] = {["fields"] = {}, ["inventory"] = {}}, ["y"] = 5, ["param1"] = 78, ["z"] = 116, ["name"] = "stairs:slab_desert_stonebrick"}, {["x"] = 32, ["meta"] = {["fields"] = {}, ["inventory"] = {}}, ["param2"] = 1, ["y"] = 6, ["param1"] = 136, ["z"] = 58, ["name"] = "stoneworks:arches_highstonebrick"}, {["x"] = 33, ["meta"] = {["fields"] = {}, ["inventory"] = {}}, ["y"] = 3, ["z"] = 0, ["name"] = "codersea:dirt"}, {["x"] = 33, ["meta"] = {["fields"] = {}, ["inventory"] = {}}, ["y"] = 5, ["param1"] = 94, ["z"] = 0, ["name"] = "stairs:slab_desert_stonebrick"}, {["x"] = 33, ["meta"] = {["fields"] = {["owner"] = "singleplayer", ["creative"] = "1", ["state"] = "0", ["type"] = "0", ["infotext"] = "(Smartshop by singleplayer) Stock is unlimited", ["sellall"] = "1"}, ["inventory"] = {["pay3"] = {""}, ["pay4"] = {""}, ["give1"] = {"3d_armor:helmet_steel"}, ["pay2"] = {""}, ["pay1"] = {""}, ["give4"] = {"3d_armor:boots_steel"}, ["main"] = {"", "", "", "", "", "", "", "", "", "", "", "", "", "", "", "", "", "", "", "", "", "", "", "", "", "", "", "", "", "", "", ""}, ["give3"] = {"3d_armor:leggings_steel"}, ["give2"] = {"3d_armor:chestplate_steel"}}}, ["param2"] = 1, ["y"] = 5, ["param1"] = 170, ["z"] = 78, ["name"] = "smartshop:shop"}, {["x"] = 33, ["meta"] = {["fields"] = {["sellall"] = "1", ["creative"] = "1", ["type"] = "0", ["owner"] = "singleplayer", ["infotext"] = "(Smartshop by singleplayer) Stock is unlimited", ["state"] = "0"}, ["inventory"] = {["pay3"] = {""}, ["pay4"] = {""}, ["give1"] = {"default:axe_steel"}, ["pay2"] = {""}, ["pay1"] = {""}, ["give4"] = {"farming:hoe_steel"}, ["main"] = {"", "", "", "", "", "", "", "", "", "", "", "", "", "", "", "", "", "", "", "", "", "", "", "", "", "", "", "", "", "", "", ""}, ["give3"] = {"default:sword_steel"}, ["give2"] = {"default:pick_steel"}}}, ["param2"] = 1, ["y"] = 5, ["param1"] = 170, ["z"] = 98, ["name"] = "smartshop:shop"}, {["x"] = 33, ["meta"] = {["fields"] = {}, ["inventory"] = {}}, ["y"] = 5, ["param1"] = 94, ["z"] = 116, ["name"] = "stairs:slab_desert_stonebrick"}, {["x"] = 34, ["meta"] = {["fields"] = {}, ["inventory"] = {}}, ["y"] = 3, ["z"] = 0, ["name"] = "codersea:dirt"}, {["x"] = 34, ["meta"] = {["fields"] = {}, ["inventory"] = {}}, ["y"] = 5, ["param1"] = 110, ["z"] = 0, ["name"] = "stairs:slab_desert_stonebrick"}, {["x"] = 34, ["meta"] = {["fields"] = {}, ["inventory"] = {}}, ["y"] = 5, ["param1"] = 110, ["z"] = 116, ["name"] = "stairs:slab_desert_stonebrick"}, {["x"] = 35, ["meta"] = {["fields"] = {}, ["inventory"] = {}}, ["y"] = 3, ["z"] = 0, ["name"] = "codersea:dirt"}, {["x"] = 35, ["meta"] = {["fields"] = {}, ["inventory"] = {}}, ["y"] = 3, ["z"] = 116, ["name"] = "codersea:dirt"}, {["x"] = 35, ["meta"] = {["fields"] = {}, ["inventory"] = {}}, ["y"] = 5, ["param1"] = 126, ["z"] = 0, ["name"] = "stairs:slab_desert_stonebrick"}, {["x"] = 35, ["meta"] = {["fields"] = {}, ["inventory"] = {}}, ["y"] = 5, ["param1"] = 126, ["z"] = 116, ["name"] = "stairs:slab_desert_stonebrick"}, {["x"] = 36, ["meta"] = {["fields"] = {}, ["inventory"] = {}}, ["y"] = 3, ["z"] = 0, ["name"] = "codersea:dirt"}, {["x"] = 36, ["meta"] = {["fields"] = {}, ["inventory"] = {}}, ["y"] = 5, ["param1"] = 142, ["z"] = 0, ["name"] = "stairs:slab_desert_stonebrick"}, {["x"] = 36, ["meta"] = {["fields"] = {}, ["inventory"] = {}}, ["y"] = 5, ["param1"] = 142, ["z"] = 116, ["name"] = "stairs:slab_desert_stonebrick"}, {["x"] = 36, ["meta"] = {["fields"] = {}, ["inventory"] = {}}, ["param2"] = 2, ["y"] = 6, ["param1"] = 85, ["z"] = 12, ["name"] = "stoneworks:arches_highstonebrick"}, {["x"] = 36, ["meta"] = {["fields"] = {}, ["inventory"] = {}}, ["param2"] = 2, ["y"] = 6, ["param1"] = 85, ["z"] = 54, ["name"] = "stoneworks:arches_highstonebrick"}, {["x"] = 36, ["meta"] = {["fields"] = {}, ["inventory"] = {}}, ["param2"] = 2, ["y"] = 6, ["param1"] = 85, ["z"] = 62, ["name"] = "stoneworks:arches_highstonebrick"}, {["x"] = 36, ["meta"] = {["fields"] = {}, ["inventory"] = {}}, ["y"] = 6, ["param1"] = 85, ["z"] = 104, ["name"] = "stoneworks:arches_highstonebrick"}, {["x"] = 37, ["meta"] = {["fields"] = {}, ["inventory"] = {}}, ["y"] = 3, ["z"] = 0, ["name"] = "codersea:dirt"}, {["x"] = 37, ["meta"] = {["fields"] = {}, ["inventory"] = {}}, ["y"] = 3, ["z"] = 116, ["name"] = "codersea:dirt"}, {["x"] = 37, ["meta"] = {["fields"] = {}, ["inventory"] = {}}, ["y"] = 5, ["param1"] = 126, ["z"] = 0, ["name"] = "stairs:slab_desert_stonebrick"}, {["x"] = 37, ["meta"] = {["fields"] = {}, ["inventory"] = {}}, ["y"] = 5, ["param1"] = 126, ["z"] = 116, ["name"] = "stairs:slab_desert_stonebrick"}, {["x"] = 38, ["meta"] = {["fields"] = {}, ["inventory"] = {}}, ["y"] = 5, ["param1"] = 110, ["z"] = 0, ["name"] = "stairs:slab_desert_stonebrick"}, {["x"] = 38, ["meta"] = {["fields"] = {}, ["inventory"] = {}}, ["y"] = 5, ["param1"] = 110, ["z"] = 116, ["name"] = "stairs:slab_desert_stonebrick"}, {["x"] = 39, ["meta"] = {["fields"] = {}, ["inventory"] = {}}, ["y"] = 3, ["z"] = 0, ["name"] = "codersea:dirt"}, {["x"] = 39, ["meta"] = {["fields"] = {}, ["inventory"] = {}}, ["y"] = 3, ["z"] = 116, ["name"] = "codersea:dirt"}, {["x"] = 39, ["meta"] = {["fields"] = {}, ["inventory"] = {}}, ["y"] = 5, ["param1"] = 94, ["z"] = 0, ["name"] = "stairs:slab_desert_stonebrick"}, {["x"] = 39, ["meta"] = {["fields"] = {}, ["inventory"] = {}}, ["y"] = 5, ["param1"] = 94, ["z"] = 116, ["name"] = "stairs:slab_desert_stonebrick"}, {["x"] = 39, ["meta"] = {["fields"] = {}, ["inventory"] = {}}, ["param2"] = 9, ["y"] = 12, ["param1"] = 174, ["z"] = 13, ["name"] = "moreblocks:panel_stonebrick"}, {["x"] = 39, ["meta"] = {["fields"] = {}, ["inventory"] = {}}, ["param2"] = 18, ["y"] = 12, ["param1"] = 174, ["z"] = 53, ["name"] = "moreblocks:panel_stonebrick"}, {["x"] = 39, ["meta"] = {["fields"] = {}, ["inventory"] = {}}, ["param2"] = 9, ["y"] = 12, ["param1"] = 174, ["z"] = 63, ["name"] = "moreblocks:panel_stonebrick"}, {["x"] = 39, ["meta"] = {["fields"] = {}, ["inventory"] = {}}, ["param2"] = 18, ["y"] = 12, ["param1"] = 174, ["z"] = 103, ["name"] = "moreblocks:panel_stonebrick"}, {["x"] = 40, ["meta"] = {["fields"] = {}, ["inventory"] = {}}, ["y"] = 5, ["param1"] = 78, ["z"] = 0, ["name"] = "stairs:slab_desert_stonebrick"}, {["x"] = 40, ["meta"] = {["fields"] = {}, ["inventory"] = {}}, ["y"] = 5, ["param1"] = 78, ["z"] = 116, ["name"] = "stairs:slab_desert_stonebrick"}, {["x"] = 41, ["meta"] = {["fields"] = {}, ["inventory"] = {}}, ["y"] = 3, ["z"] = 0, ["name"] = "codersea:dirt"}, {["x"] = 41, ["meta"] = {["fields"] = {}, ["inventory"] = {}}, ["y"] = 5, ["param1"] = 62, ["z"] = 0, ["name"] = "stairs:slab_desert_stonebrick"}, {["x"] = 41, ["meta"] = {["fields"] = {}, ["inventory"] = {}}, ["y"] = 5, ["param1"] = 62, ["z"] = 116, ["name"] = "stairs:slab_desert_stonebrick"}, {["x"] = 42, ["meta"] = {["fields"] = {}, ["inventory"] = {}}, ["y"] = 5, ["param1"] = 46, ["z"] = 0, ["name"] = "stairs:slab_desert_stonebrick"}, {["x"] = 42, ["meta"] = {["fields"] = {}, ["inventory"] = {}}, ["y"] = 5, ["param1"] = 46, ["z"] = 116, ["name"] = "stairs:slab_desert_stonebrick"}, {["x"] = 43, ["meta"] = {["fields"] = {}, ["inventory"] = {}}, ["y"] = 1, ["z"] = 95, ["name"] = "codersea:dirt"}, {["x"] = 43, ["meta"] = {["fields"] = {}, ["inventory"] = {}}, ["y"] = 1, ["z"] = 96, ["name"] = "codersea:dirt"}, {["x"] = 43, ["meta"] = {["fields"] = {}, ["inventory"] = {}}, ["y"] = 1, ["z"] = 97, ["name"] = "codersea:dirt"}, {["x"] = 43, ["meta"] = {["fields"] = {}, ["inventory"] = {}}, ["y"] = 2, ["z"] = 95, ["name"] = "codersea:dirt"}, {["x"] = 43, ["meta"] = {["fields"] = {}, ["inventory"] = {}}, ["y"] = 2, ["z"] = 97, ["name"] = "codersea:dirt"}, {["x"] = 43, ["meta"] = {["fields"] = {}, ["inventory"] = {}}, ["y"] = 3, ["z"] = 0, ["name"] = "codersea:dirt"}, {["x"] = 43, ["meta"] = {["fields"] = {}, ["inventory"] = {}}, ["y"] = 5, ["param1"] = 30, ["z"] = 0, ["name"] = "stairs:slab_desert_stonebrick"}, {["x"] = 43, ["meta"] = {["fields"] = {}, ["inventory"] = {}}, ["y"] = 5, ["param1"] = 30, ["z"] = 116, ["name"] = "stairs:slab_desert_stonebrick"}, {["x"] = 44, ["meta"] = {["fields"] = {}, ["inventory"] = {}}, ["y"] = 1, ["z"] = 50, ["name"] = "codersea:dirt"}, {["x"] = 44, ["meta"] = {["fields"] = {}, ["inventory"] = {}}, ["y"] = 1, ["z"] = 66, ["name"] = "codersea:dirt"}, {["x"] = 44, ["meta"] = {["fields"] = {}, ["inventory"] = {}}, ["y"] = 1, ["z"] = 95, ["name"] = "codersea:dirt"}, {["x"] = 44, ["meta"] = {["fields"] = {}, ["inventory"] = {}}, ["y"] = 1, ["z"] = 96, ["name"] = "codersea:dirt"}, {["x"] = 44, ["meta"] = {["fields"] = {}, ["inventory"] = {}}, ["y"] = 1, ["z"] = 97, ["name"] = "codersea:dirt"}, {["x"] = 44, ["meta"] = {["fields"] = {}, ["inventory"] = {}}, ["y"] = 1, ["z"] = 100, ["name"] = "codersea:dirt"}, {["x"] = 44, ["meta"] = {["fields"] = {}, ["inventory"] = {}}, ["y"] = 1, ["z"] = 116, ["name"] = "codersea:dirt"}, {["x"] = 44, ["meta"] = {["fields"] = {}, ["inventory"] = {}}, ["y"] = 2, ["z"] = 16, ["name"] = "codersea:dirt"}, {["x"] = 44, ["meta"] = {["fields"] = {}, ["inventory"] = {}}, ["y"] = 2, ["z"] = 50, ["name"] = "codersea:dirt"}, {["x"] = 44, ["meta"] = {["fields"] = {}, ["inventory"] = {}}, ["y"] = 2, ["z"] = 66, ["name"] = "codersea:dirt"}, {["x"] = 44, ["meta"] = {["fields"] = {}, ["inventory"] = {}}, ["y"] = 2, ["z"] = 95, ["name"] = "codersea:dirt"}, {["x"] = 44, ["meta"] = {["fields"] = {}, ["inventory"] = {}}, ["y"] = 2, ["z"] = 96, ["name"] = "codersea:dirt"}, {["x"] = 44, ["meta"] = {["fields"] = {}, ["inventory"] = {}}, ["y"] = 2, ["z"] = 97, ["name"] = "codersea:dirt"}, {["x"] = 44, ["meta"] = {["fields"] = {}, ["inventory"] = {}}, ["y"] = 2, ["z"] = 100, ["name"] = "codersea:dirt"}, {["x"] = 44, ["meta"] = {["fields"] = {}, ["inventory"] = {}}, ["y"] = 2, ["z"] = 116, ["name"] = "codersea:dirt"}, {["x"] = 44, ["meta"] = {["fields"] = {}, ["inventory"] = {}}, ["y"] = 3, ["z"] = 0, ["name"] = "codersea:dirt"}, {["x"] = 44, ["meta"] = {["fields"] = {}, ["inventory"] = {}}, ["y"] = 3, ["z"] = 1, ["name"] = "codersea:dirt"}, {["x"] = 44, ["meta"] = {["fields"] = {}, ["inventory"] = {}}, ["y"] = 3, ["z"] = 2, ["name"] = "codersea:dirt"}, {["x"] = 44, ["meta"] = {["fields"] = {}, ["inventory"] = {}}, ["y"] = 3, ["z"] = 4, ["name"] = "codersea:dirt"}, {["x"] = 44, ["meta"] = {["fields"] = {}, ["inventory"] = {}}, ["y"] = 3, ["z"] = 6, ["name"] = "codersea:dirt"}, {["x"] = 44, ["meta"] = {["fields"] = {}, ["inventory"] = {}}, ["y"] = 3, ["z"] = 7, ["name"] = "codersea:dirt"}, {["x"] = 44, ["meta"] = {["fields"] = {}, ["inventory"] = {}}, ["y"] = 3, ["z"] = 8, ["name"] = "codersea:dirt"}, {["x"] = 44, ["meta"] = {["fields"] = {}, ["inventory"] = {}}, ["y"] = 3, ["z"] = 9, ["name"] = "codersea:dirt"}, {["x"] = 44, ["meta"] = {["fields"] = {}, ["inventory"] = {}}, ["y"] = 3, ["z"] = 10, ["name"] = "codersea:dirt"}, {["x"] = 44, ["meta"] = {["fields"] = {}, ["inventory"] = {}}, ["y"] = 3, ["z"] = 11, ["name"] = "codersea:dirt"}, {["x"] = 44, ["meta"] = {["fields"] = {}, ["inventory"] = {}}, ["y"] = 3, ["z"] = 13, ["name"] = "codersea:dirt"}, {["x"] = 44, ["meta"] = {["fields"] = {}, ["inventory"] = {}}, ["y"] = 3, ["z"] = 14, ["name"] = "codersea:dirt"}, {["x"] = 44, ["meta"] = {["fields"] = {}, ["inventory"] = {}}, ["y"] = 3, ["z"] = 15, ["name"] = "codersea:dirt"}, {["x"] = 44, ["meta"] = {["fields"] = {}, ["inventory"] = {}}, ["y"] = 3, ["z"] = 16, ["name"] = "codersea:dirt"}, {["x"] = 44, ["meta"] = {["fields"] = {}, ["inventory"] = {}}, ["y"] = 3, ["z"] = 50, ["name"] = "codersea:dirt"}, {["x"] = 44, ["meta"] = {["fields"] = {}, ["inventory"] = {}}, ["y"] = 3, ["z"] = 53, ["name"] = "codersea:dirt"}, {["x"] = 44, ["meta"] = {["fields"] = {}, ["inventory"] = {}}, ["y"] = 3, ["z"] = 54, ["name"] = "codersea:dirt"}, {["x"] = 44, ["meta"] = {["fields"] = {}, ["inventory"] = {}}, ["y"] = 3, ["z"] = 55, ["name"] = "codersea:dirt"}, {["x"] = 44, ["meta"] = {["fields"] = {}, ["inventory"] = {}}, ["y"] = 3, ["z"] = 56, ["name"] = "codersea:dirt"}, {["x"] = 44, ["meta"] = {["fields"] = {}, ["inventory"] = {}}, ["y"] = 3, ["z"] = 57, ["name"] = "codersea:dirt"}, {["x"] = 44, ["meta"] = {["fields"] = {}, ["inventory"] = {}}, ["y"] = 3, ["z"] = 58, ["name"] = "codersea:dirt"}, {["x"] = 44, ["meta"] = {["fields"] = {}, ["inventory"] = {}}, ["y"] = 3, ["z"] = 59, ["name"] = "codersea:dirt"}, {["x"] = 44, ["meta"] = {["fields"] = {}, ["inventory"] = {}}, ["y"] = 3, ["z"] = 60, ["name"] = "codersea:dirt"}, {["x"] = 44, ["meta"] = {["fields"] = {}, ["inventory"] = {}}, ["y"] = 3, ["z"] = 62, ["name"] = "codersea:dirt"}, {["x"] = 44, ["meta"] = {["fields"] = {}, ["inventory"] = {}}, ["y"] = 3, ["z"] = 63, ["name"] = "codersea:dirt"}, {["x"] = 44, ["meta"] = {["fields"] = {}, ["inventory"] = {}}, ["y"] = 3, ["z"] = 64, ["name"] = "codersea:dirt"}, {["x"] = 44, ["meta"] = {["fields"] = {}, ["inventory"] = {}}, ["y"] = 3, ["z"] = 96, ["name"] = "codersea:dirt"}, {["x"] = 44, ["meta"] = {["fields"] = {}, ["inventory"] = {}}, ["y"] = 3, ["z"] = 101, ["name"] = "codersea:dirt"}, {["x"] = 44, ["meta"] = {["fields"] = {}, ["inventory"] = {}}, ["y"] = 3, ["z"] = 103, ["name"] = "codersea:dirt"}, {["x"] = 44, ["meta"] = {["fields"] = {}, ["inventory"] = {}}, ["y"] = 3, ["z"] = 104, ["name"] = "codersea:dirt"}, {["x"] = 44, ["meta"] = {["fields"] = {}, ["inventory"] = {}}, ["y"] = 3, ["z"] = 107, ["name"] = "codersea:dirt"}, {["x"] = 44, ["meta"] = {["fields"] = {}, ["inventory"] = {}}, ["y"] = 3, ["z"] = 109, ["name"] = "codersea:dirt"}, {["x"] = 44, ["meta"] = {["fields"] = {}, ["inventory"] = {}}, ["y"] = 3, ["z"] = 111, ["name"] = "codersea:dirt"}, {["x"] = 44, ["meta"] = {["fields"] = {}, ["inventory"] = {}}, ["y"] = 3, ["z"] = 116, ["name"] = "codersea:dirt"}, {["x"] = 44, ["meta"] = {["fields"] = {}, ["inventory"] = {}}, ["y"] = 5, ["param1"] = 14, ["z"] = 0, ["name"] = "stairs:slab_desert_stonebrick"}, {["x"] = 44, ["meta"] = {["fields"] = {}, ["inventory"] = {}}, ["y"] = 5, ["param1"] = 30, ["z"] = 1, ["name"] = "stairs:slab_desert_stonebrick"}, {["x"] = 44, ["meta"] = {["fields"] = {}, ["inventory"] = {}}, ["y"] = 5, ["param1"] = 46, ["z"] = 2, ["name"] = "stairs:slab_desert_stonebrick"}, {["x"] = 44, ["meta"] = {["fields"] = {}, ["inventory"] = {}}, ["y"] = 5, ["param1"] = 62, ["z"] = 3, ["name"] = "stairs:slab_desert_stonebrick"}, {["x"] = 44, ["meta"] = {["fields"] = {}, ["inventory"] = {}}, ["y"] = 5, ["param1"] = 78, ["z"] = 4, ["name"] = "stairs:slab_desert_stonebrick"}, {["x"] = 44, ["meta"] = {["fields"] = {}, ["inventory"] = {}}, ["y"] = 5, ["param1"] = 94, ["z"] = 5, ["name"] = "stairs:slab_desert_stonebrick"}, {["x"] = 44, ["meta"] = {["fields"] = {}, ["inventory"] = {}}, ["y"] = 5, ["param1"] = 110, ["z"] = 6, ["name"] = "stairs:slab_desert_stonebrick"}, {["x"] = 44, ["meta"] = {["fields"] = {}, ["inventory"] = {}}, ["y"] = 5, ["param1"] = 126, ["z"] = 7, ["name"] = "stairs:slab_desert_stonebrick"}, {["x"] = 44, ["meta"] = {["fields"] = {}, ["inventory"] = {}}, ["y"] = 5, ["param1"] = 142, ["z"] = 8, ["name"] = "stairs:slab_desert_stonebrick"}, {["x"] = 44, ["meta"] = {["fields"] = {}, ["inventory"] = {}}, ["y"] = 5, ["param1"] = 126, ["z"] = 9, ["name"] = "stairs:slab_desert_stonebrick"}, {["x"] = 44, ["meta"] = {["fields"] = {}, ["inventory"] = {}}, ["y"] = 5, ["param1"] = 110, ["z"] = 10, ["name"] = "stairs:slab_desert_stonebrick"}, {["x"] = 44, ["meta"] = {["fields"] = {}, ["inventory"] = {}}, ["y"] = 5, ["param1"] = 94, ["z"] = 11, ["name"] = "stairs:slab_desert_stonebrick"}, {["x"] = 44, ["meta"] = {["fields"] = {}, ["inventory"] = {}}, ["y"] = 5, ["param1"] = 78, ["z"] = 12, ["name"] = "stairs:slab_desert_stonebrick"}, {["x"] = 44, ["meta"] = {["fields"] = {}, ["inventory"] = {}}, ["y"] = 5, ["param1"] = 62, ["z"] = 13, ["name"] = "stairs:slab_desert_stonebrick"}, {["x"] = 44, ["meta"] = {["fields"] = {}, ["inventory"] = {}}, ["y"] = 5, ["param1"] = 46, ["z"] = 14, ["name"] = "stairs:slab_desert_stonebrick"}, {["x"] = 44, ["meta"] = {["fields"] = {}, ["inventory"] = {}}, ["y"] = 5, ["param1"] = 46, ["z"] = 15, ["name"] = "stairs:slab_desert_stonebrick"}, {["x"] = 44, ["meta"] = {["fields"] = {}, ["inventory"] = {}}, ["y"] = 5, ["param1"] = 62, ["z"] = 16, ["name"] = "stairs:slab_desert_stonebrick"}, {["x"] = 44, ["meta"] = {["fields"] = {}, ["inventory"] = {}}, ["y"] = 5, ["param1"] = 78, ["z"] = 17, ["name"] = "stairs:slab_desert_stonebrick"}, {["x"] = 44, ["meta"] = {["fields"] = {}, ["inventory"] = {}}, ["y"] = 5, ["param1"] = 94, ["z"] = 18, ["name"] = "stairs:slab_desert_stonebrick"}, {["x"] = 44, ["meta"] = {["fields"] = {}, ["inventory"] = {}}, ["y"] = 5, ["param1"] = 110, ["z"] = 19, ["name"] = "stairs:slab_desert_stonebrick"}, {["x"] = 44, ["meta"] = {["fields"] = {}, ["inventory"] = {}}, ["y"] = 5, ["param1"] = 94, ["z"] = 20, ["name"] = "stairs:slab_desert_stonebrick"}, {["x"] = 44, ["meta"] = {["fields"] = {}, ["inventory"] = {}}, ["y"] = 5, ["param1"] = 78, ["z"] = 21, ["name"] = "stairs:slab_desert_stonebrick"}, {["x"] = 44, ["meta"] = {["fields"] = {}, ["inventory"] = {}}, ["y"] = 5, ["param1"] = 62, ["z"] = 22, ["name"] = "stairs:slab_desert_stonebrick"}, {["x"] = 44, ["meta"] = {["fields"] = {}, ["inventory"] = {}}, ["y"] = 5, ["param1"] = 46, ["z"] = 23, ["name"] = "stairs:slab_desert_stonebrick"}, {["x"] = 44, ["meta"] = {["fields"] = {}, ["inventory"] = {}}, ["y"] = 5, ["param1"] = 30, ["z"] = 24, ["name"] = "stairs:slab_desert_stonebrick"}, {["x"] = 44, ["meta"] = {["fields"] = {}, ["inventory"] = {}}, ["y"] = 5, ["param1"] = 14, ["z"] = 25, ["name"] = "stairs:slab_desert_stonebrick"}, {["x"] = 44, ["meta"] = {["fields"] = {}, ["inventory"] = {}}, ["y"] = 5, ["param1"] = 14, ["z"] = 26, ["name"] = "stairs:slab_desert_stonebrick"}, {["x"] = 44, ["meta"] = {["fields"] = {}, ["inventory"] = {}}, ["y"] = 5, ["param1"] = 14, ["z"] = 27, ["name"] = "stairs:slab_desert_stonebrick"}, {["x"] = 44, ["meta"] = {["fields"] = {}, ["inventory"] = {}}, ["y"] = 5, ["param1"] = 30, ["z"] = 28, ["name"] = "stairs:slab_desert_stonebrick"}, {["x"] = 44, ["meta"] = {["fields"] = {}, ["inventory"] = {}}, ["y"] = 5, ["param1"] = 46, ["z"] = 29, ["name"] = "stairs:slab_desert_stonebrick"}, {["x"] = 44, ["meta"] = {["fields"] = {}, ["inventory"] = {}}, ["y"] = 5, ["param1"] = 62, ["z"] = 30, ["name"] = "stairs:slab_desert_stonebrick"}, {["x"] = 44, ["meta"] = {["fields"] = {}, ["inventory"] = {}}, ["y"] = 5, ["param1"] = 78, ["z"] = 31, ["name"] = "stairs:slab_desert_stonebrick"}, {["x"] = 44, ["meta"] = {["fields"] = {}, ["inventory"] = {}}, ["y"] = 5, ["param1"] = 94, ["z"] = 32, ["name"] = "stairs:slab_desert_stonebrick"}, {["x"] = 44, ["meta"] = {["fields"] = {}, ["inventory"] = {}}, ["y"] = 5, ["param1"] = 110, ["z"] = 33, ["name"] = "stairs:slab_desert_stonebrick"}, {["x"] = 44, ["meta"] = {["fields"] = {}, ["inventory"] = {}}, ["y"] = 5, ["param1"] = 94, ["z"] = 34, ["name"] = "stairs:slab_desert_stonebrick"}, {["x"] = 44, ["meta"] = {["fields"] = {}, ["inventory"] = {}}, ["y"] = 5, ["param1"] = 78, ["z"] = 35, ["name"] = "stairs:slab_desert_stonebrick"}, {["x"] = 44, ["meta"] = {["fields"] = {}, ["inventory"] = {}}, ["y"] = 5, ["param1"] = 62, ["z"] = 36, ["name"] = "stairs:slab_desert_stonebrick"}, {["x"] = 44, ["meta"] = {["fields"] = {}, ["inventory"] = {}}, ["y"] = 5, ["param1"] = 46, ["z"] = 37, ["name"] = "stairs:slab_desert_stonebrick"}, {["x"] = 44, ["meta"] = {["fields"] = {}, ["inventory"] = {}}, ["y"] = 5, ["param1"] = 30, ["z"] = 38, ["name"] = "stairs:slab_desert_stonebrick"}, {["x"] = 44, ["meta"] = {["fields"] = {}, ["inventory"] = {}}, ["y"] = 5, ["param1"] = 14, ["z"] = 39, ["name"] = "stairs:slab_desert_stonebrick"}, {["x"] = 44, ["meta"] = {["fields"] = {}, ["inventory"] = {}}, ["y"] = 5, ["param1"] = 14, ["z"] = 40, ["name"] = "stairs:slab_desert_stonebrick"}, {["x"] = 44, ["meta"] = {["fields"] = {}, ["inventory"] = {}}, ["y"] = 5, ["param1"] = 14, ["z"] = 41, ["name"] = "stairs:slab_desert_stonebrick"}, {["x"] = 44, ["meta"] = {["fields"] = {}, ["inventory"] = {}}, ["y"] = 5, ["param1"] = 30, ["z"] = 42, ["name"] = "stairs:slab_desert_stonebrick"}, {["x"] = 44, ["meta"] = {["fields"] = {}, ["inventory"] = {}}, ["y"] = 5, ["param1"] = 46, ["z"] = 43, ["name"] = "stairs:slab_desert_stonebrick"}, {["x"] = 44, ["meta"] = {["fields"] = {}, ["inventory"] = {}}, ["y"] = 5, ["param1"] = 62, ["z"] = 44, ["name"] = "stairs:slab_desert_stonebrick"}, {["x"] = 44, ["meta"] = {["fields"] = {}, ["inventory"] = {}}, ["y"] = 5, ["param1"] = 78, ["z"] = 45, ["name"] = "stairs:slab_desert_stonebrick"}, {["x"] = 44, ["meta"] = {["fields"] = {}, ["inventory"] = {}}, ["y"] = 5, ["param1"] = 94, ["z"] = 46, ["name"] = "stairs:slab_desert_stonebrick"}, {["x"] = 44, ["meta"] = {["fields"] = {}, ["inventory"] = {}}, ["y"] = 5, ["param1"] = 110, ["z"] = 47, ["name"] = "stairs:slab_desert_stonebrick"}, {["x"] = 44, ["meta"] = {["fields"] = {}, ["inventory"] = {}}, ["y"] = 5, ["param1"] = 94, ["z"] = 48, ["name"] = "stairs:slab_desert_stonebrick"}, {["x"] = 44, ["meta"] = {["fields"] = {}, ["inventory"] = {}}, ["y"] = 5, ["param1"] = 78, ["z"] = 49, ["name"] = "stairs:slab_desert_stonebrick"}, {["x"] = 44, ["meta"] = {["fields"] = {}, ["inventory"] = {}}, ["y"] = 5, ["param1"] = 62, ["z"] = 50, ["name"] = "stairs:slab_desert_stonebrick"}, {["x"] = 44, ["meta"] = {["fields"] = {}, ["inventory"] = {}}, ["y"] = 5, ["param1"] = 46, ["z"] = 51, ["name"] = "stairs:slab_desert_stonebrick"}, {["x"] = 44, ["meta"] = {["fields"] = {}, ["inventory"] = {}}, ["y"] = 5, ["param1"] = 46, ["z"] = 52, ["name"] = "stairs:slab_desert_stonebrick"}, {["x"] = 44, ["meta"] = {["fields"] = {}, ["inventory"] = {}}, ["y"] = 5, ["param1"] = 62, ["z"] = 53, ["name"] = "stairs:slab_desert_stonebrick"}, {["x"] = 44, ["meta"] = {["fields"] = {}, ["inventory"] = {}}, ["y"] = 5, ["param1"] = 78, ["z"] = 54, ["name"] = "stairs:slab_desert_stonebrick"}, {["x"] = 44, ["meta"] = {["fields"] = {}, ["inventory"] = {}}, ["y"] = 5, ["param1"] = 94, ["z"] = 55, ["name"] = "stairs:slab_desert_stonebrick"}, {["x"] = 44, ["meta"] = {["fields"] = {}, ["inventory"] = {}}, ["y"] = 5, ["param1"] = 110, ["z"] = 56, ["name"] = "stairs:slab_desert_stonebrick"}, {["x"] = 44, ["meta"] = {["fields"] = {}, ["inventory"] = {}}, ["y"] = 5, ["param1"] = 126, ["z"] = 57, ["name"] = "stairs:slab_desert_stonebrick"}, {["x"] = 44, ["meta"] = {["fields"] = {}, ["inventory"] = {}}, ["y"] = 5, ["param1"] = 142, ["z"] = 58, ["name"] = "stairs:slab_desert_stonebrick"}, {["x"] = 44, ["meta"] = {["fields"] = {}, ["inventory"] = {}}, ["y"] = 5, ["param1"] = 126, ["z"] = 59, ["name"] = "stairs:slab_desert_stonebrick"}, {["x"] = 44, ["meta"] = {["fields"] = {}, ["inventory"] = {}}, ["y"] = 5, ["param1"] = 110, ["z"] = 60, ["name"] = "stairs:slab_desert_stonebrick"}, {["x"] = 44, ["meta"] = {["fields"] = {}, ["inventory"] = {}}, ["y"] = 5, ["param1"] = 94, ["z"] = 61, ["name"] = "stairs:slab_desert_stonebrick"}, {["x"] = 44, ["meta"] = {["fields"] = {}, ["inventory"] = {}}, ["y"] = 5, ["param1"] = 78, ["z"] = 62, ["name"] = "stairs:slab_desert_stonebrick"}, {["x"] = 44, ["meta"] = {["fields"] = {}, ["inventory"] = {}}, ["y"] = 5, ["param1"] = 62, ["z"] = 63, ["name"] = "stairs:slab_desert_stonebrick"}, {["x"] = 44, ["meta"] = {["fields"] = {}, ["inventory"] = {}}, ["y"] = 5, ["param1"] = 46, ["z"] = 64, ["name"] = "stairs:slab_desert_stonebrick"}, {["x"] = 44, ["meta"] = {["fields"] = {}, ["inventory"] = {}}, ["y"] = 5, ["param1"] = 46, ["z"] = 65, ["name"] = "stairs:slab_desert_stonebrick"}, {["x"] = 44, ["meta"] = {["fields"] = {}, ["inventory"] = {}}, ["y"] = 5, ["param1"] = 62, ["z"] = 66, ["name"] = "stairs:slab_desert_stonebrick"}, {["x"] = 44, ["meta"] = {["fields"] = {}, ["inventory"] = {}}, ["y"] = 5, ["param1"] = 78, ["z"] = 67, ["name"] = "stairs:slab_desert_stonebrick"}, {["x"] = 44, ["meta"] = {["fields"] = {}, ["inventory"] = {}}, ["y"] = 5, ["param1"] = 94, ["z"] = 68, ["name"] = "stairs:slab_desert_stonebrick"}, {["x"] = 44, ["meta"] = {["fields"] = {}, ["inventory"] = {}}, ["y"] = 5, ["param1"] = 110, ["z"] = 69, ["name"] = "stairs:slab_desert_stonebrick"}, {["x"] = 44, ["meta"] = {["fields"] = {}, ["inventory"] = {}}, ["y"] = 5, ["param1"] = 94, ["z"] = 70, ["name"] = "stairs:slab_desert_stonebrick"}, {["x"] = 44, ["meta"] = {["fields"] = {}, ["inventory"] = {}}, ["y"] = 5, ["param1"] = 78, ["z"] = 71, ["name"] = "stairs:slab_desert_stonebrick"}, {["x"] = 44, ["meta"] = {["fields"] = {}, ["inventory"] = {}}, ["y"] = 5, ["param1"] = 62, ["z"] = 72, ["name"] = "stairs:slab_desert_stonebrick"}, {["x"] = 44, ["meta"] = {["fields"] = {}, ["inventory"] = {}}, ["y"] = 5, ["param1"] = 46, ["z"] = 73, ["name"] = "stairs:slab_desert_stonebrick"}, {["x"] = 44, ["meta"] = {["fields"] = {}, ["inventory"] = {}}, ["y"] = 5, ["param1"] = 30, ["z"] = 74, ["name"] = "stairs:slab_desert_stonebrick"}, {["x"] = 44, ["meta"] = {["fields"] = {}, ["inventory"] = {}}, ["y"] = 5, ["param1"] = 14, ["z"] = 75, ["name"] = "stairs:slab_desert_stonebrick"}, {["x"] = 44, ["meta"] = {["fields"] = {}, ["inventory"] = {}}, ["y"] = 5, ["param1"] = 14, ["z"] = 76, ["name"] = "stairs:slab_desert_stonebrick"}, {["x"] = 44, ["meta"] = {["fields"] = {}, ["inventory"] = {}}, ["y"] = 5, ["param1"] = 14, ["z"] = 77, ["name"] = "stairs:slab_desert_stonebrick"}, {["x"] = 44, ["meta"] = {["fields"] = {}, ["inventory"] = {}}, ["y"] = 5, ["param1"] = 30, ["z"] = 78, ["name"] = "stairs:slab_desert_stonebrick"}, {["x"] = 44, ["meta"] = {["fields"] = {}, ["inventory"] = {}}, ["y"] = 5, ["param1"] = 46, ["z"] = 79, ["name"] = "stairs:slab_desert_stonebrick"}, {["x"] = 44, ["meta"] = {["fields"] = {}, ["inventory"] = {}}, ["y"] = 5, ["param1"] = 62, ["z"] = 80, ["name"] = "stairs:slab_desert_stonebrick"}, {["x"] = 44, ["meta"] = {["fields"] = {}, ["inventory"] = {}}, ["y"] = 5, ["param1"] = 78, ["z"] = 81, ["name"] = "stairs:slab_desert_stonebrick"}, {["x"] = 44, ["meta"] = {["fields"] = {}, ["inventory"] = {}}, ["y"] = 5, ["param1"] = 94, ["z"] = 82, ["name"] = "stairs:slab_desert_stonebrick"}, {["x"] = 44, ["meta"] = {["fields"] = {}, ["inventory"] = {}}, ["y"] = 5, ["param1"] = 110, ["z"] = 83, ["name"] = "stairs:slab_desert_stonebrick"}, {["x"] = 44, ["meta"] = {["fields"] = {}, ["inventory"] = {}}, ["y"] = 5, ["param1"] = 94, ["z"] = 84, ["name"] = "stairs:slab_desert_stonebrick"}, {["x"] = 44, ["meta"] = {["fields"] = {}, ["inventory"] = {}}, ["y"] = 5, ["param1"] = 78, ["z"] = 85, ["name"] = "stairs:slab_desert_stonebrick"}, {["x"] = 44, ["meta"] = {["fields"] = {}, ["inventory"] = {}}, ["y"] = 5, ["param1"] = 62, ["z"] = 86, ["name"] = "stairs:slab_desert_stonebrick"}, {["x"] = 44, ["meta"] = {["fields"] = {}, ["inventory"] = {}}, ["y"] = 5, ["param1"] = 46, ["z"] = 87, ["name"] = "stairs:slab_desert_stonebrick"}, {["x"] = 44, ["meta"] = {["fields"] = {}, ["inventory"] = {}}, ["y"] = 5, ["param1"] = 30, ["z"] = 88, ["name"] = "stairs:slab_desert_stonebrick"}, {["x"] = 44, ["meta"] = {["fields"] = {}, ["inventory"] = {}}, ["y"] = 5, ["param1"] = 14, ["z"] = 89, ["name"] = "stairs:slab_desert_stonebrick"}, {["x"] = 44, ["meta"] = {["fields"] = {}, ["inventory"] = {}}, ["y"] = 5, ["param1"] = 14, ["z"] = 90, ["name"] = "stairs:slab_desert_stonebrick"}, {["x"] = 44, ["meta"] = {["fields"] = {}, ["inventory"] = {}}, ["y"] = 5, ["param1"] = 14, ["z"] = 91, ["name"] = "stairs:slab_desert_stonebrick"}, {["x"] = 44, ["meta"] = {["fields"] = {}, ["inventory"] = {}}, ["y"] = 5, ["param1"] = 30, ["z"] = 92, ["name"] = "stairs:slab_desert_stonebrick"}, {["x"] = 44, ["meta"] = {["fields"] = {}, ["inventory"] = {}}, ["y"] = 5, ["param1"] = 46, ["z"] = 93, ["name"] = "stairs:slab_desert_stonebrick"}, {["x"] = 44, ["meta"] = {["fields"] = {}, ["inventory"] = {}}, ["y"] = 5, ["param1"] = 62, ["z"] = 94, ["name"] = "stairs:slab_desert_stonebrick"}, {["x"] = 44, ["meta"] = {["fields"] = {}, ["inventory"] = {}}, ["y"] = 5, ["param1"] = 78, ["z"] = 95, ["name"] = "stairs:slab_desert_stonebrick"}, {["x"] = 44, ["meta"] = {["fields"] = {}, ["inventory"] = {}}, ["y"] = 5, ["param1"] = 94, ["z"] = 96, ["name"] = "stairs:slab_desert_stonebrick"}, {["x"] = 44, ["meta"] = {["fields"] = {}, ["inventory"] = {}}, ["y"] = 5, ["param1"] = 110, ["z"] = 97, ["name"] = "stairs:slab_desert_stonebrick"}, {["x"] = 44, ["meta"] = {["fields"] = {}, ["inventory"] = {}}, ["y"] = 5, ["param1"] = 94, ["z"] = 98, ["name"] = "stairs:slab_desert_stonebrick"}, {["x"] = 44, ["meta"] = {["fields"] = {}, ["inventory"] = {}}, ["y"] = 5, ["param1"] = 78, ["z"] = 99, ["name"] = "stairs:slab_desert_stonebrick"}, {["x"] = 44, ["meta"] = {["fields"] = {}, ["inventory"] = {}}, ["y"] = 5, ["param1"] = 62, ["z"] = 100, ["name"] = "stairs:slab_desert_stonebrick"}, {["x"] = 44, ["meta"] = {["fields"] = {}, ["inventory"] = {}}, ["y"] = 5, ["param1"] = 46, ["z"] = 101, ["name"] = "stairs:slab_desert_stonebrick"}, {["x"] = 44, ["meta"] = {["fields"] = {}, ["inventory"] = {}}, ["y"] = 5, ["param1"] = 46, ["z"] = 102, ["name"] = "stairs:slab_desert_stonebrick"}, {["x"] = 44, ["meta"] = {["fields"] = {}, ["inventory"] = {}}, ["y"] = 5, ["param1"] = 62, ["z"] = 103, ["name"] = "stairs:slab_desert_stonebrick"}, {["x"] = 44, ["meta"] = {["fields"] = {}, ["inventory"] = {}}, ["y"] = 5, ["param1"] = 78, ["z"] = 104, ["name"] = "stairs:slab_desert_stonebrick"}, {["x"] = 44, ["meta"] = {["fields"] = {}, ["inventory"] = {}}, ["y"] = 5, ["param1"] = 94, ["z"] = 105, ["name"] = "stairs:slab_desert_stonebrick"}, {["x"] = 44, ["meta"] = {["fields"] = {}, ["inventory"] = {}},