5:return {{["x"] = 0, ["meta"] = {["fields"] = {["palette"] = "ext"}, ["inventory"] = {}}, ["param2"] = 240, ["y"] = 0, ["param1"] = 158, ["z"] = 4, ["name"] = "homedecor:bathroom_tiles_dark"}, {["x"] = 0, ["meta"] = {["fields"] = {["palette"] = "ext"}, ["inventory"] = {}}, ["param2"] = 240, ["y"] = 0, ["param1"] = 142, ["z"] = 5, ["name"] = "homedecor:bathroom_tiles_dark"}, {["x"] = 0, ["meta"] = {["fields"] = {["palette"] = "ext"}, ["inventory"] = {}}, ["param2"] = 240, ["y"] = 0, ["param1"] = 142, ["z"] = 6, ["name"] = "homedecor:bathroom_tiles_dark"}, {["x"] = 0, ["meta"] = {["fields"] = {["palette"] = "ext"}, ["inventory"] = {}}, ["param2"] = 240, ["y"] = 0, ["param1"] = 158, ["z"] = 7, ["name"] = "homedecor:bathroom_tiles_dark"}, {["x"] = 0, ["meta"] = {["fields"] = {["palette"] = "ext"}, ["inventory"] = {}}, ["param2"] = 240, ["y"] = 0, ["param1"] = 173, ["z"] = 8, ["name"] = "homedecor:bathroom_tiles_dark"}, {["x"] = 0, ["meta"] = {["fields"] = {["palette"] = "ext"}, ["inventory"] = {}}, ["param2"] = 240, ["y"] = 0, ["param1"] = 190, ["z"] = 9, ["name"] = "homedecor:bathroom_tiles_dark"}, {["x"] = 0, ["meta"] = {["fields"] = {["palette"] = "ext"}, ["inventory"] = {}}, ["param2"] = 240, ["y"] = 1, ["param1"] = 142, ["z"] = 4, ["name"] = "homedecor:bathroom_tiles_dark"}, {["x"] = 0, ["meta"] = {["fields"] = {["palette"] = "ext"}, ["inventory"] = {}}, ["param2"] = 240, ["y"] = 1, ["param1"] = 126, ["z"] = 5, ["name"] = "homedecor:bathroom_tiles_dark"}, {["x"] = 0, ["meta"] = {["fields"] = {["palette"] = "ext"}, ["inventory"] = {}}, ["param2"] = 240, ["y"] = 1, ["param1"] = 126, ["z"] = 6, ["name"] = "homedecor:bathroom_tiles_dark"}, {["x"] = 0, ["meta"] = {["fields"] = {["palette"] = "ext"}, ["inventory"] = {}}, ["param2"] = 240, ["y"] = 1, ["param1"] = 142, ["z"] = 7, ["name"] = "homedecor:bathroom_tiles_dark"}, {["x"] = 0, ["meta"] = {["fields"] = {["palette"] = "ext"}, ["inventory"] = {}}, ["param2"] = 240, ["y"] = 1, ["param1"] = 157, ["z"] = 8, ["name"] = "homedecor:bathroom_tiles_dark"}, {["x"] = 0, ["meta"] = {["fields"] = {["palette"] = "ext"}, ["inventory"] = {}}, ["param2"] = 240, ["y"] = 1, ["param1"] = 174, ["z"] = 9, ["name"] = "homedecor:bathroom_tiles_dark"}, {["x"] = 0, ["meta"] = {["fields"] = {["palette"] = "ext"}, ["inventory"] = {}}, ["param2"] = 240, ["y"] = 13, ["param1"] = 94, ["z"] = 0, ["name"] = "homedecor:bathroom_tiles_light"}, {["x"] = 0, ["meta"] = {["fields"] = {["palette"] = "ext"}, ["inventory"] = {}}, ["param2"] = 240, ["y"] = 13, ["param1"] = 110, ["z"] = 1, ["name"] = "homedecor:bathroom_tiles_light"}, {["x"] = 0, ["meta"] = {["fields"] = {["palette"] = "ext"}, ["inventory"] = {}}, ["param2"] = 240, ["y"] = 13, ["param1"] = 126, ["z"] = 2, ["name"] = "homedecor:bathroom_tiles_light"}, {["x"] = 0, ["meta"] = {["fields"] = {["palette"] = "ext"}, ["inventory"] = {}}, ["param2"] = 240, ["y"] = 13, ["param1"] = 142, ["z"] = 3, ["name"] = "homedecor:bathroom_tiles_light"}, {["x"] = 0, ["meta"] = {["fields"] = {["palette"] = "ext"}, ["inventory"] = {}}, ["param2"] = 240, ["y"] = 13, ["param1"] = 126, ["z"] = 4, ["name"] = "homedecor:bathroom_tiles_light"}, {["x"] = 0, ["meta"] = {["fields"] = {["palette"] = "ext"}, ["inventory"] = {}}, ["param2"] = 240, ["y"] = 13, ["param1"] = 142, ["z"] = 5, ["name"] = "homedecor:bathroom_tiles_light"}, {["x"] = 0, ["meta"] = {["fields"] = {["palette"] = "ext"}, ["inventory"] = {}}, ["param2"] = 240, ["y"] = 13, ["param1"] = 126, ["z"] = 6, ["name"] = "homedecor:bathroom_tiles_light"}, {["x"] = 1, ["y"] = 0, ["param1"] = 174, ["z"] = 0, ["name"] = "building_blocks:woodglass"}, {["x"] = 1, ["y"] = 0, ["param1"] = 158, ["z"] = 1, ["name"] = "building_blocks:woodglass"}, {["x"] = 1, ["y"] = 0, ["param1"] = 142, ["z"] = 2, ["name"] = "building_blocks:woodglass"}, {["x"] = 1, ["y"] = 0, ["param1"] = 158, ["z"] = 3, ["name"] = "building_blocks:woodglass"}, {["x"] = 1, ["meta"] = {["fields"] = {["palette"] = "ext"}, ["inventory"] = {}}, ["param2"] = 240, ["y"] = 0, ["param1"] = 141, ["z"] = 4, ["name"] = "homedecor:bathroom_tiles_dark"}, {["x"] = 1, ["y"] = 0, ["z"] = 5, ["name"] = "slimenodes:slime_solid_orange"}, {["x"] = 1, ["y"] = 0, ["z"] = 6, ["name"] = "slimenodes:slime_solid_green"}, {["x"] = 1, ["y"] = 0, ["z"] = 7, ["name"] = "slimenodes:slime_solid_cyan"}, {["x"] = 1, ["y"] = 0, ["z"] = 8, ["name"] = "slimenodes:slime_solid_violet"}, {["x"] = 1, ["meta"] = {["fields"] = {["palette"] = "ext"}, ["inventory"] = {}}, ["param2"] = 240, ["y"] = 0, ["param1"] = 205, ["z"] = 9, ["name"] = "homedecor:bathroom_tiles_dark"}, {["x"] = 1, ["meta"] = {["fields"] = {["palette"] = "ext"}, ["inventory"] = {}}, ["param2"] = 240, ["y"] = 1, ["param1"] = 126, ["z"] = 4, ["name"] = "homedecor:bathroom_tiles_dark"}, {["x"] = 1, ["meta"] = {["fields"] = {["infotext"] = "solid slime ", ["formspec"] = "size[6,4]textarea[0,-0.3;6.5,3;text;;${text}]button_exit[2,3.4;2,1;ok;Write]background[-0.5,-0.5;7,5;bg_signs_lib.jpg]", ["__signslib_new_format"] = "1", ["text"] = "solid slime"}, ["inventory"] = {}}, ["param2"] = 3, ["y"] = 1, ["param1"] = 157, ["z"] = 7, ["name"] = "default:sign_wall_wood"}, {["x"] = 1, ["meta"] = {["fields"] = {["palette"] = "ext"}, ["inventory"] = {}}, ["param2"] = 240, ["y"] = 2, ["param1"] = 110, ["z"] = 4, ["name"] = "homedecor:bathroom_tiles_light"}, {["x"] = 1, ["meta"] = {["fields"] = {["palette"] = "ext"}, ["inventory"] = {}}, ["param2"] = 240, ["y"] = 3, ["param1"] = 94, ["z"] = 4, ["name"] = "homedecor:bathroom_tiles_light"}, {["x"] = 1, ["meta"] = {["fields"] = {["palette"] = "ext"}, ["inventory"] = {}}, ["param2"] = 240, ["y"] = 4, ["param1"] = 78, ["z"] = 4, ["name"] = "homedecor:bathroom_tiles_light"}, {["x"] = 1, ["meta"] = {["fields"] = {["palette"] = "ext"}, ["inventory"] = {}}, ["param2"] = 240, ["y"] = 5, ["param1"] = 62, ["z"] = 4, ["name"] = "homedecor:bathroom_tiles_light"}, {["x"] = 1, ["meta"] = {["fields"] = {["palette"] = "ext"}, ["inventory"] = {}}, ["param2"] = 240, ["y"] = 6, ["param1"] = 46, ["z"] = 4, ["name"] = "homedecor:bathroom_tiles_light"}, {["x"] = 1, ["meta"] = {["fields"] = {["palette"] = "ext"}, ["inventory"] = {}}, ["param2"] = 240, ["y"] = 7, ["param1"] = 46, ["z"] = 4, ["name"] = "homedecor:bathroom_tiles_light"}, {["x"] = 1, ["meta"] = {["fields"] = {["palette"] = "ext"}, ["inventory"] = {}}, ["param2"] = 240, ["y"] = 8, ["param1"] = 62, ["z"] = 4, ["name"] = "homedecor:bathroom_tiles_light"}, {["x"] = 1, ["meta"] = {["fields"] = {["palette"] = "ext"}, ["inventory"] = {}}, ["param2"] = 240, ["y"] = 9, ["param1"] = 78, ["z"] = 4, ["name"] = "homedecor:bathroom_tiles_light"}, {["x"] = 1, ["meta"] = {["fields"] = {["palette"] = "ext"}, ["inventory"] = {}}, ["param2"] = 240, ["y"] = 10, ["param1"] = 94, ["z"] = 4, ["name"] = "homedecor:bathroom_tiles_light"}, {["x"] = 1, ["meta"] = {["fields"] = {["palette"] = "ext"}, ["inventory"] = {}}, ["param2"] = 240, ["y"] = 11, ["param1"] = 110, ["z"] = 4, ["name"] = "homedecor:bathroom_tiles_light"}, {["x"] = 1, ["meta"] = {["fields"] = {["palette"] = "ext"}, ["inventory"] = {}}, ["param2"] = 240, ["y"] = 12, ["param1"] = 126, ["z"] = 4, ["name"] = "homedecor:bathroom_tiles_light"}, {["x"] = 1, ["meta"] = {["fields"] = {["palette"] = "ext"}, ["inventory"] = {}}, ["param2"] = 240, ["y"] = 13, ["param1"] = 109, ["z"] = 0, ["name"] = "homedecor:bathroom_tiles_light"}, {["x"] = 1, ["meta"] = {["fields"] = {["palette"] = "ext"}, ["inventory"] = {}}, ["param2"] = 240, ["y"] = 13, ["param1"] = 126, ["z"] = 1, ["name"] = "homedecor:bathroom_tiles_light"}, {["x"] = 1, ["meta"] = {["fields"] = {["palette"] = "ext"}, ["inventory"] = {}}, ["param2"] = 240, ["y"] = 13, ["param1"] = 142, ["z"] = 2, ["name"] = "homedecor:bathroom_tiles_light"}, {["x"] = 1, ["meta"] = {["fields"] = {["palette"] = "ext"}, ["inventory"] = {}}, ["param2"] = 240, ["y"] = 13, ["param1"] = 157, ["z"] = 3, ["name"] = "homedecor:bathroom_tiles_light"}, {["x"] = 1, ["meta"] = {["fields"] = {["palette"] = "ext"}, ["inventory"] = {}}, ["param2"] = 240, ["y"] = 13, ["param1"] = 142, ["z"] = 4, ["name"] = "homedecor:bathroom_tiles_light"}, {["x"] = 1, ["meta"] = {["fields"] = {["palette"] = "ext"}, ["inventory"] = {}}, ["param2"] = 240, ["y"] = 13, ["param1"] = 157, ["z"] = 5, ["name"] = "homedecor:bathroom_tiles_light"}, {["x"] = 1, ["meta"] = {["fields"] = {["palette"] = "ext"}, ["inventory"] = {}}, ["param2"] = 240, ["y"] = 13, ["param1"] = 141, ["z"] = 6, ["name"] = "homedecor:bathroom_tiles_light"}, {["x"] = 1, ["meta"] = {["fields"] = {["palette"] = "ext"}, ["inventory"] = {}}, ["param2"] = 240, ["y"] = 14, ["param1"] = 158, ["z"] = 4, ["name"] = "homedecor:bathroom_tiles_light"}, {["x"] = 1, ["meta"] = {["fields"] = {["palette"] = "ext"}, ["inventory"] = {}}, ["param2"] = 240, ["y"] = 15, ["param1"] = 174, ["z"] = 4, ["name"] = "homedecor:bathroom_tiles_light"}, {["x"] = 1, ["param2"] = 4, ["y"] = 16, ["param1"] = 206, ["z"] = 3, ["name"] = "default:torch_wall"}, {["x"] = 1, ["meta"] = {["fields"] = {["palette"] = "ext"}, ["inventory"] = {}}, ["param2"] = 240, ["y"] = 16, ["param1"] = 190, ["z"] = 4, ["name"] = "homedecor:bathroom_tiles_light"}, {["x"] = 1, ["param2"] = 5, ["y"] = 16, ["param1"] = 206, ["z"] = 5, ["name"] = "default:torch_wall"}, {["x"] = 2, ["y"] = 0, ["param1"] = 190, ["z"] = 0, ["name"] = "building_blocks:woodglass"}, {["x"] = 2, ["y"] = 0, ["param1"] = 174, ["z"] = 1, ["name"] = "slimenodes:slime_liquid_orange"}, {["x"] = 2, ["y"] = 0, ["param1"] = 158, ["z"] = 2, ["name"] = "slimenodes:slime_liquid_orange"}, {["x"] = 2, ["y"] = 0, ["param1"] = 142, ["z"] = 3, ["name"] = "slimenodes:slime_liquid_orange"}, {["x"] = 2, ["y"] = 0, ["param1"] = 126, ["z"] = 4, ["name"] = "slimenodes:slime_liquid_orange"}, {["x"] = 2, ["y"] = 0, ["z"] = 5, ["name"] = "slimenodes:slime_solid_orange"}, {["x"] = 2, ["y"] = 0, ["z"] = 6, ["name"] = "slimenodes:slime_solid_green"}, {["x"] = 2, ["y"] = 0, ["z"] = 7, ["name"] = "slimenodes:slime_solid_cyan"}, {["x"] = 2, ["y"] = 0, ["z"] = 8, ["name"] = "slimenodes:slime_solid_violet"}, {["x"] = 2, ["param2"] = 1, ["y"] = 0, ["param1"] = 221, ["z"] = 9, ["name"] = "homedecor:glowlight_quarter_on"}, {["x"] = 2, ["y"] = 1, ["param1"] = 127, ["z"] = 4, ["name"] = "vines:rope_end"}, {["x"] = 2, ["y"] = 2, ["param1"] = 111, ["z"] = 4, ["name"] = "vines:rope"}, {["x"] = 2, ["y"] = 3, ["param1"] = 95, ["z"] = 4, ["name"] = "vines:rope"}, {["x"] = 2, ["y"] = 4, ["param1"] = 79, ["z"] = 4, ["name"] = "vines:rope"}, {["x"] = 2, ["y"] = 5, ["param1"] = 63, ["z"] = 4, ["name"] = "vines:rope"}, {["x"] = 2, ["y"] = 6, ["param1"] = 47, ["z"] = 4, ["name"] = "vines:rope"}, {["x"] = 2, ["y"] = 7, ["param1"] = 31, ["z"] = 4, ["name"] = "vines:rope"}, {["x"] = 2, ["y"] = 8, ["param1"] = 47, ["z"] = 4, ["name"] = "vines:rope"}, {["x"] = 2, ["y"] = 9, ["param1"] = 63, ["z"] = 4, ["name"] = "vines:rope"}, {["x"] = 2, ["y"] = 10, ["param1"] = 79, ["z"] = 4, ["name"] = "vines:rope"}, {["x"] = 2, ["y"] = 11, ["param1"] = 95, ["z"] = 4, ["name"] = "vines:rope"}, {["x"] = 2, ["y"] = 12, ["param1"] = 111, ["z"] = 4, ["name"] = "vines:rope"}, {["x"] = 2, ["meta"] = {["fields"] = {["palette"] = "ext"}, ["inventory"] = {}}, ["param2"] = 240, ["y"] = 13, ["param1"] = 94, ["z"] = 0, ["name"] = "homedecor:bathroom_tiles_light"}, {["x"] = 2, ["meta"] = {["fields"] = {["palette"] = "ext"}, ["inventory"] = {}}, ["param2"] = 240, ["y"] = 13, ["param1"] = 142, ["z"] = 3, ["name"] = "homedecor:bathroom_tiles_light"}, {["x"] = 2, ["y"] = 13, ["param1"] = 127, ["z"] = 4, ["name"] = "vines:rope"}, {["x"] = 2, ["meta"] = {["fields"] = {["palette"] = "ext"}, ["inventory"] = {}}, ["param2"] = 240, ["y"] = 13, ["param1"] = 142, ["z"] = 5, ["name"] = "homedecor:bathroom_tiles_light"}, {["x"] = 2, ["meta"] = {["fields"] = {["palette"] = "ext"}, ["inventory"] = {}}, ["param2"] = 240, ["y"] = 13, ["param1"] = 126, ["z"] = 6, ["name"] = "homedecor:bathroom_tiles_light"}, {["x"] = 2, ["y"] = 14, ["param1"] = 143, ["z"] = 4, ["name"] = "vines:rope"}, {["x"] = 2, ["y"] = 15, ["param1"] = 159, ["z"] = 4, ["name"] = "vines:rope"}, {["x"] = 2, ["y"] = 16, ["param1"] = 175, ["z"] = 4, ["name"] = "vines:rope_block"}, {["x"] = 3, ["y"] = 0, ["param1"] = 175, ["z"] = 0, ["name"] = "building_blocks:woodglass"}, {["x"] = 3, ["y"] = 0, ["param1"] = 159, ["z"] = 1, ["name"] = "building_blocks:woodglass"}, {["x"] = 3, ["y"] = 0, ["param1"] = 143, ["z"] = 2, ["name"] = "building_blocks:woodglass"}, {["x"] = 3, ["y"] = 0, ["param1"] = 127, ["z"] = 3, ["name"] = "building_blocks:woodglass"}, {["x"] = 3, ["meta"] = {["fields"] = {["palette"] = "ext"}, ["inventory"] = {}}, ["param2"] = 240, ["y"] = 0, ["param1"] = 110, ["z"] = 4, ["name"] = "homedecor:bathroom_tiles_dark"}, {["x"] = 3, ["y"] = 0, ["z"] = 5, ["name"] = "slimenodes:slime_solid_orange"}, {["x"] = 3, ["y"] = 0, ["z"] = 6, ["name"] = "slimenodes:slime_solid_green"}, {["x"] = 3, ["y"] = 0, ["z"] = 7, ["name"] = "slimenodes:slime_solid_cyan"}, {["x"] = 3, ["y"] = 0, ["z"] = 8, ["name"] = "slimenodes:slime_solid_violet"}, {["x"] = 3, ["meta"] = {["fields"] = {["palette"] = "ext"}, ["inventory"] = {}}, ["param2"] = 240, ["y"] = 0, ["param1"] = 206, ["z"] = 9, ["name"] = "homedecor:bathroom_tiles_dark"}, {["x"] = 3, ["meta"] = {["fields"] = {["palette"] = "ext"}, ["inventory"] = {}}, ["param2"] = 240, ["y"] = 1, ["param1"] = 110, ["z"] = 4, ["name"] = "homedecor:bathroom_tiles_dark"}, {["x"] = 3, ["meta"] = {["fields"] = {["palette"] = "ext"}, ["inventory"] = {}}, ["param2"] = 240, ["y"] = 2, ["param1"] = 94, ["z"] = 4, ["name"] = "homedecor:bathroom_tiles_light"}, {["x"] = 3, ["meta"] = {["fields"] = {["palette"] = "ext"}, ["inventory"] = {}}, ["param2"] = 240, ["y"] = 3, ["param1"] = 78, ["z"] = 4, ["name"] = "homedecor:bathroom_tiles_light"}, {["x"] = 3, ["meta"] = {["fields"] = {["palette"] = "ext"}, ["inventory"] = {}}, ["param2"] = 240, ["y"] = 4, ["param1"] = 62, ["z"] = 4, ["name"] = "homedecor:bathroom_tiles_light"}, {["x"] = 3, ["meta"] = {["fields"] = {["palette"] = "ext"}, ["inventory"] = {}}, ["param2"] = 240, ["y"] = 5, ["param1"] = 62, ["z"] = 4, ["name"] = "homedecor:bathroom_tiles_light"}, {["x"] = 3, ["meta"] = {["fields"] = {["palette"] = "ext"}, ["inventory"] = {}}, ["param2"] = 240, ["y"] = 6, ["param1"] = 46, ["z"] = 4, ["name"] = "homedecor:bathroom_tiles_light"}, {["x"] = 3, ["meta"] = {["fields"] = {["palette"] = "ext"}, ["inventory"] = {}}, ["param2"] = 240, ["y"] = 7, ["param1"] = 46, ["z"] = 4, ["name"] = "homedecor:bathroom_tiles_light"}, {["x"] = 3, ["meta"] = {["fields"] = {["palette"] = "ext"}, ["inventory"] = {}}, ["param2"] = 240, ["y"] = 8, ["param1"] = 62, ["z"] = 4, ["name"] = "homedecor:bathroom_tiles_light"}, {["x"] = 3, ["meta"] = {["fields"] = {["palette"] = "ext"}, ["inventory"] = {}}, ["param2"] = 240, ["y"] = 9, ["param1"] = 78, ["z"] = 4, ["name"] = "homedecor:bathroom_tiles_light"}, {["x"] = 3, ["meta"] = {["fields"] = {["palette"] = "ext"}, ["inventory"] = {}}, ["param2"] = 240, ["y"] = 10, ["param1"] = 94, ["z"] = 4, ["name"] = "homedecor:bathroom_tiles_light"}, {["x"] = 3, ["meta"] = {["fields"] = {["palette"] = "ext"}, ["inventory"] = {}}, ["param2"] = 240, ["y"] = 11, ["param1"] = 110, ["z"] = 4, ["name"] = "homedecor:bathroom_tiles_light"}, {["x"] = 3, ["meta"] = {["fields"] = {["palette"] = "ext"}, ["inventory"] = {}}, ["param2"] = 240, ["y"] = 12, ["param1"] = 126, ["z"] = 4, ["name"] = "homedecor:bathroom_tiles_light"}, {["x"] = 3, ["meta"] = {["fields"] = {["palette"] = "ext"}, ["inventory"] = {}}, ["param2"] = 240, ["y"] = 13, ["param1"] = 110, ["z"] = 0, ["name"] = "homedecor:bathroom_tiles_light"}, {["x"] = 3, ["meta"] = {["fields"] = {["palette"] = "ext"}, ["inventory"] = {}}, ["param2"] = 240, ["y"] = 13, ["param1"] = 126, ["z"] = 1, ["name"] = "homedecor:bathroom_tiles_light"}, {["x"] = 3, ["meta"] = {["fields"] = {["palette"] = "ext"}, ["inventory"] = {}}, ["param2"] = 240, ["y"] = 13, ["param1"] = 142, ["z"] = 2, ["name"] = "homedecor:bathroom_tiles_light"}, {["x"] = 3, ["meta"] = {["fields"] = {["palette"] = "ext"}, ["inventory"] = {}}, ["param2"] = 240, ["y"] = 13, ["param1"] = 158, ["z"] = 3, ["name"] = "homedecor:bathroom_tiles_light"}, {["x"] = 3, ["meta"] = {["fields"] = {["palette"] = "ext"}, ["inventory"] = {}}, ["param2"] = 240, ["y"] = 13, ["param1"] = 142, ["z"] = 4, ["name"] = "homedecor:bathroom_tiles_light"}, {["x"] = 3, ["meta"] = {["fields"] = {["palette"] = "ext"}, ["inventory"] = {}}, ["param2"] = 240, ["y"] = 13, ["param1"] = 158, ["z"] = 5, ["name"] = "homedecor:bathroom_tiles_light"}, {["x"] = 3, ["meta"] = {["fields"] = {["palette"] = "ext"}, ["inventory"] = {}}, ["param2"] = 240, ["y"] = 13, ["param1"] = 142, ["z"] = 6, ["name"] = "homedecor:bathroom_tiles_light"}, {["x"] = 3, ["meta"] = {["fields"] = {["palette"] = "ext"}, ["inventory"] = {}}, ["param2"] = 240, ["y"] = 14, ["param1"] = 158, ["z"] = 4, ["name"] = "homedecor:bathroom_tiles_light"}, {["x"] = 3, ["meta"] = {["fields"] = {["palette"] = "ext"}, ["inventory"] = {}}, ["param2"] = 240, ["y"] = 15, ["param1"] = 174, ["z"] = 4, ["name"] = "homedecor:bathroom_tiles_light"}, {["x"] = 3, ["param2"] = 4, ["y"] = 16, ["param1"] = 207, ["z"] = 3, ["name"] = "default:torch_wall"}, {["x"] = 3, ["meta"] = {["fields"] = {["palette"] = "ext"}, ["inventory"] = {}}, ["param2"] = 240, ["y"] = 16, ["param1"] = 190, ["z"] = 4, ["name"] = "homedecor:bathroom_tiles_light"}, {["x"] = 3, ["param2"] = 5, ["y"] = 16, ["param1"] = 207, ["z"] = 5, ["name"] = "default:torch_wall"}, {["x"] = 4, ["meta"] = {["fields"] = {["infotext"] = "liquid slime ", ["formspec"] = "size[6,4]textarea[0,-0.3;6.5,3;text;;${text}]button_exit[2,3.4;2,1;ok;Write]background[-0.5,-0.5;7,5;bg_signs_lib.jpg]", ["text"] = "liquid slime\
", ["__signslib_new_format"] = "1"}, ["inventory"] = {}}, ["param2"] = 3, ["y"] = 0, ["param1"] = 143, ["z"] = 1, ["name"] = "default:sign_wall_wood"}, {["x"] = 4, ["meta"] = {["fields"] = {["palette"] = "ext"}, ["inventory"] = {}}, ["param2"] = 240, ["y"] = 0, ["param1"] = 110, ["z"] = 4, ["name"] = "homedecor:bathroom_tiles_dark"}, {["x"] = 4, ["meta"] = {["fields"] = {["palette"] = "ext"}, ["inventory"] = {}}, ["param2"] = 240, ["y"] = 0, ["param1"] = 126, ["z"] = 5, ["name"] = "homedecor:bathroom_tiles_dark"}, {["x"] = 4, ["meta"] = {["fields"] = {["palette"] = "ext"}, ["inventory"] = {}}, ["param2"] = 240, ["y"] = 0, ["param1"] = 142, ["z"] = 6, ["name"] = "homedecor:bathroom_tiles_dark"}, {["x"] = 4, ["meta"] = {["fields"] = {["palette"] = "ext"}, ["inventory"] = {}}, ["param2"] = 240, ["y"] = 0, ["param1"] = 158, ["z"] = 7, ["name"] = "homedecor:bathroom_tiles_dark"}, {["x"] = 4, ["meta"] = {["fields"] = {["palette"] = "ext"}, ["inventory"] = {}}, ["param2"] = 240, ["y"] = 0, ["param1"] = 173, ["z"] = 8, ["name"] = "homedecor:bathroom_tiles_dark"}, {["x"] = 4, ["meta"] = {["fields"] = {["palette"] = "ext"}, ["inventory"] = {}}, ["param2"] = 240, ["y"] = 0, ["param1"] = 190, ["z"] = 9, ["name"] = "homedecor:bathroom_tiles_dark"}, {["x"] = 4, ["meta"] = {["fields"] = {["palette"] = "ext"}, ["inventory"] = {}}, ["param2"] = 240, ["y"] = 1, ["param1"] = 94, ["z"] = 4, ["name"] = "homedecor:bathroom_tiles_dark"}, {["x"] = 4, ["meta"] = {["fields"] = {["palette"] = "ext"}, ["inventory"] = {}}, ["param2"] = 240, ["y"] = 1, ["param1"] = 110, ["z"] = 5, ["name"] = "homedecor:bathroom_tiles_dark"}, {["x"] = 4, ["meta"] = {["fields"] = {["palette"] = "ext"}, ["inventory"] = {}}, ["param2"] = 240, ["y"] = 1, ["param1"] = 126, ["z"] = 6, ["name"] = "homedecor:bathroom_tiles_dark"}, {["x"] = 4, ["meta"] = {["fields"] = {["palette"] = "ext"}, ["inventory"] = {}}, ["param2"] = 240, ["y"] = 1, ["param1"] = 142, ["z"] = 7, ["name"] = "homedecor:bathroom_tiles_dark"}, {["x"] = 4, ["meta"] = {["fields"] = {["palette"] = "ext"}, ["inventory"] = {}}, ["param2"] = 240, ["y"] = 1, ["param1"] = 157, ["z"] = 8, ["name"] = "homedecor:bathroom_tiles_dark"}, {["x"] = 4, ["meta"] = {["fields"] = {["palette"] = "ext"}, ["inventory"] = {}}, ["param2"] = 240, ["y"] = 1, ["param1"] = 174, ["z"] = 9, ["name"] = "homedecor:bathroom_tiles_dark"}, {["x"] = 4, ["meta"] = {["fields"] = {["palette"] = "ext"}, ["inventory"] = {}}, ["param2"] = 240, ["y"] = 13, ["param1"] = 94, ["z"] = 0, ["name"] = "homedecor:bathroom_tiles_light"}, {["x"] = 4, ["meta"] = {["fields"] = {["palette"] = "ext"}, ["inventory"] = {}}, ["param2"] = 240, ["y"] = 13, ["param1"] = 110, ["z"] = 1, ["name"] = "homedecor:bathroom_tiles_light"}, {["x"] = 4, ["meta"] = {["fields"] = {["palette"] = "ext"}, ["inventory"] = {}}, ["param2"] = 240, ["y"] = 13, ["param1"] = 126, ["z"] = 2, ["name"] = "homedecor:bathroom_tiles_light"}, {["x"] = 4, ["meta"] = {["fields"] = {["palette"] = "ext"}, ["inventory"] = {}}, ["param2"] = 240, ["y"] = 13, ["param1"] = 142, ["z"] = 3, ["name"] = "homedecor:bathroom_tiles_light"}, {["x"] = 4, ["meta"] = {["fields"] = {["palette"] = "ext"}, ["inventory"] = {}}, ["param2"] = 240, ["y"] = 13, ["param1"] = 126, ["z"] = 4, ["name"] = "homedecor:bathroom_tiles_light"}, {["x"] = 4, ["meta"] = {["fields"] = {["palette"] = "ext"}, ["inventory"] = {}}, ["param2"] = 240, ["y"] = 13, ["param1"] = 142, ["z"] = 5, ["name"] = "homedecor:bathroom_tiles_light"}, {["x"] = 4, ["meta"] = {["fields"] = {["palette"] = "ext"}, ["inventory"] = {}}, ["param2"] = 240, ["y"] = 13, ["param1"] = 126, ["z"] = 6, ["name"] = "homedecor:bathroom_tiles_light"}}