5:return {{["x"] = 0, ["param2"] = 1, ["y"] = 0, ["param1"] = 206, ["z"] = 10, ["name"] = "default:torch"}, {["x"] = 0, ["y"] = 3, ["param1"] = 126, ["z"] = 0, ["name"] = "homedecor:shingles_asphalt"}, {["x"] = 0, ["y"] = 3, ["param1"] = 158, ["z"] = 10, ["name"] = "homedecor:shingles_asphalt"}, {["x"] = 0, ["y"] = 4, ["param1"] = 158, ["z"] = 1, ["name"] = "homedecor:shingles_asphalt"}, {["x"] = 0, ["y"] = 4, ["param1"] = 158, ["z"] = 9, ["name"] = "homedecor:shingles_asphalt"}, {["x"] = 0, ["y"] = 5, ["param1"] = 190, ["z"] = 2, ["name"] = "homedecor:shingles_asphalt"}, {["x"] = 0, ["y"] = 5, ["param1"] = 206, ["z"] = 3, ["name"] = "homedecor:shingles_asphalt"}, {["x"] = 0, ["y"] = 5, ["param1"] = 238, ["z"] = 5, ["name"] = "default:mese_post_light"}, {["x"] = 0, ["y"] = 5, ["param1"] = 206, ["z"] = 7, ["name"] = "homedecor:shingles_asphalt"}, {["x"] = 0, ["y"] = 5, ["param1"] = 190, ["z"] = 8, ["name"] = "homedecor:shingles_asphalt"}, {["x"] = 1, ["y"] = 0, ["z"] = 1, ["name"] = "building_blocks:hardwood"}, {["x"] = 1, ["y"] = 0, ["z"] = 2, ["name"] = "building_blocks:hardwood"}, {["x"] = 1, ["y"] = 0, ["z"] = 3, ["name"] = "building_blocks:hardwood"}, {["x"] = 1, ["y"] = 0, ["z"] = 4, ["name"] = "building_blocks:hardwood"}, {["x"] = 1, ["y"] = 0, ["z"] = 5, ["name"] = "building_blocks:hardwood"}, {["x"] = 1, ["y"] = 0, ["z"] = 6, ["name"] = "building_blocks:hardwood"}, {["x"] = 1, ["y"] = 0, ["z"] = 7, ["name"] = "building_blocks:hardwood"}, {["x"] = 1, ["y"] = 0, ["z"] = 8, ["name"] = "building_blocks:hardwood"}, {["x"] = 1, ["y"] = 0, ["z"] = 9, ["name"] = "building_blocks:hardwood"}, {["x"] = 1, ["y"] = 1, ["z"] = 1, ["name"] = "building_blocks:hardwood"}, {["x"] = 1, ["y"] = 1, ["z"] = 2, ["name"] = "building_blocks:hardwood"}, {["x"] = 1, ["y"] = 1, ["z"] = 3, ["name"] = "building_blocks:hardwood"}, {["x"] = 1, ["param2"] = 1, ["y"] = 1, ["param1"] = 140, ["z"] = 4, ["name"] = "doors:wood_glass_mahogany_b"}, {["x"] = 1, ["y"] = 1, ["z"] = 5, ["name"] = "building_blocks:hardwood"}, {["x"] = 1, ["param2"] = 1, ["y"] = 1, ["param1"] = 141, ["z"] = 6, ["name"] = "doors:wood_glass_mahogany_b"}, {["x"] = 1, ["y"] = 1, ["z"] = 7, ["name"] = "building_blocks:hardwood"}, {["x"] = 1, ["y"] = 1, ["z"] = 8, ["name"] = "building_blocks:hardwood"}, {["x"] = 1, ["y"] = 1, ["z"] = 9, ["name"] = "building_blocks:hardwood"}, {["x"] = 1, ["y"] = 2, ["z"] = 1, ["name"] = "building_blocks:hardwood"}, {["x"] = 1, ["y"] = 2, ["z"] = 2, ["name"] = "building_blocks:hardwood"}, {["x"] = 1, ["y"] = 2, ["z"] = 3, ["name"] = "building_blocks:hardwood"}, {["x"] = 1, ["y"] = 2, ["param1"] = 156, ["z"] = 4, ["name"] = "doors:hidden"}, {["x"] = 1, ["y"] = 2, ["z"] = 5, ["name"] = "building_blocks:hardwood"}, {["x"] = 1, ["y"] = 2, ["param1"] = 157, ["z"] = 6, ["name"] = "doors:hidden"}, {["x"] = 1, ["y"] = 2, ["z"] = 7, ["name"] = "building_blocks:hardwood"}, {["x"] = 1, ["y"] = 2, ["z"] = 8, ["name"] = "building_blocks:hardwood"}, {["x"] = 1, ["y"] = 2, ["z"] = 9, ["name"] = "building_blocks:hardwood"}, {["x"] = 1, ["y"] = 3, ["param1"] = 110, ["z"] = 0, ["name"] = "homedecor:shingles_asphalt"}, {["x"] = 1, ["y"] = 3, ["z"] = 1, ["name"] = "building_blocks:hardwood"}, {["x"] = 1, ["y"] = 3, ["z"] = 2, ["name"] = "building_blocks:hardwood"}, {["x"] = 1, ["y"] = 3, ["z"] = 3, ["name"] = "building_blocks:hardwood"}, {["x"] = 1, ["y"] = 3, ["z"] = 4, ["name"] = "building_blocks:hardwood"}, {["x"] = 1, ["y"] = 3, ["z"] = 5, ["name"] = "building_blocks:hardwood"}, {["x"] = 1, ["y"] = 3, ["z"] = 6, ["name"] = "building_blocks:hardwood"}, {["x"] = 1, ["y"] = 3, ["z"] = 7, ["name"] = "building_blocks:hardwood"}, {["x"] = 1, ["y"] = 3, ["z"] = 8, ["name"] = "building_blocks:hardwood"}, {["x"] = 1, ["y"] = 3, ["z"] = 9, ["name"] = "building_blocks:hardwood"}, {["x"] = 1, ["y"] = 3, ["param1"] = 142, ["z"] = 10, ["name"] = "homedecor:shingles_asphalt"}, {["x"] = 1, ["y"] = 4, ["param1"] = 142, ["z"] = 1, ["name"] = "homedecor:shingles_asphalt"}, {["x"] = 1, ["y"] = 4, ["z"] = 2, ["name"] = "building_blocks:hardwood"}, {["x"] = 1, ["y"] = 4, ["z"] = 3, ["name"] = "building_blocks:hardwood"}, {["x"] = 1, ["y"] = 4, ["z"] = 4, ["name"] = "building_blocks:hardwood"}, {["x"] = 1, ["param2"] = 3, ["y"] = 4, ["param1"] = 204, ["z"] = 5, ["name"] = "homedecor:window_quartered"}, {["x"] = 1, ["y"] = 4, ["z"] = 6, ["name"] = "building_blocks:hardwood"}, {["x"] = 1, ["y"] = 4, ["z"] = 7, ["name"] = "building_blocks:hardwood"}, {["x"] = 1, ["y"] = 4, ["z"] = 8, ["name"] = "building_blocks:hardwood"}, {["x"] = 1, ["y"] = 4, ["param1"] = 142, ["z"] = 9, ["name"] = "homedecor:shingles_asphalt"}, {["x"] = 1, ["y"] = 5, ["param1"] = 174, ["z"] = 2, ["name"] = "homedecor:shingles_asphalt"}, {["x"] = 1, ["y"] = 5, ["param1"] = 190, ["z"] = 3, ["name"] = "homedecor:shingles_asphalt"}, {["x"] = 1, ["y"] = 5, ["z"] = 4, ["name"] = "building_blocks:hardwood"}, {["x"] = 1, ["y"] = 5, ["z"] = 5, ["name"] = "building_blocks:hardwood"}, {["x"] = 1, ["y"] = 5, ["z"] = 6, ["name"] = "building_blocks:hardwood"}, {["x"] = 1, ["y"] = 5, ["param1"] = 190, ["z"] = 7, ["name"] = "homedecor:shingles_asphalt"}, {["x"] = 1, ["y"] = 5, ["param1"] = 174, ["z"] = 8, ["name"] = "homedecor:shingles_asphalt"}, {["x"] = 2, ["y"] = 0, ["z"] = 1, ["name"] = "building_blocks:hardwood"}, {["x"] = 2, ["y"] = 0, ["z"] = 9, ["name"] = "building_blocks:hardwood"}, {["x"] = 2, ["y"] = 1, ["z"] = 1, ["name"] = "building_blocks:hardwood"}, {["x"] = 2, ["y"] = 1, ["z"] = 9, ["name"] = "building_blocks:hardwood"}, {["x"] = 2, ["y"] = 2, ["z"] = 1, ["name"] = "building_blocks:hardwood"}, {["x"] = 2, ["y"] = 2, ["z"] = 9, ["name"] = "building_blocks:hardwood"}, {["x"] = 2, ["y"] = 3, ["param1"] = 126, ["z"] = 0, ["name"] = "homedecor:shingles_asphalt"}, {["x"] = 2, ["y"] = 3, ["z"] = 1, ["name"] = "building_blocks:hardwood"}, {["x"] = 2, ["y"] = 3, ["z"] = 2, ["name"] = "building_blocks:hardwood"}, {["x"] = 2, ["y"] = 3, ["z"] = 3, ["name"] = "building_blocks:hardwood"}, {["x"] = 2, ["y"] = 3, ["z"] = 4, ["name"] = "building_blocks:hardwood"}, {["x"] = 2, ["y"] = 3, ["z"] = 5, ["name"] = "building_blocks:hardwood"}, {["x"] = 2, ["y"] = 3, ["z"] = 6, ["name"] = "building_blocks:hardwood"}, {["x"] = 2, ["y"] = 3, ["z"] = 7, ["name"] = "building_blocks:hardwood"}, {["x"] = 2, ["y"] = 3, ["z"] = 8, ["name"] = "building_blocks:hardwood"}, {["x"] = 2, ["y"] = 3, ["z"] = 9, ["name"] = "building_blocks:hardwood"}, {["x"] = 2, ["y"] = 3, ["param1"] = 126, ["z"] = 10, ["name"] = "homedecor:shingles_asphalt"}, {["x"] = 2, ["y"] = 4, ["param1"] = 126, ["z"] = 1, ["name"] = "homedecor:shingles_asphalt"}, {["x"] = 2, ["y"] = 4, ["z"] = 2, ["name"] = "building_blocks:hardwood"}, {["x"] = 2, ["y"] = 4, ["z"] = 3, ["name"] = "building_blocks:hardwood"}, {["x"] = 2, ["y"] = 4, ["z"] = 7, ["name"] = "building_blocks:hardwood"}, {["x"] = 2, ["y"] = 4, ["z"] = 8, ["name"] = "building_blocks:hardwood"}, {["x"] = 2, ["y"] = 4, ["param1"] = 126, ["z"] = 9, ["name"] = "homedecor:shingles_asphalt"}, {["x"] = 2, ["y"] = 5, ["param1"] = 158, ["z"] = 2, ["name"] = "homedecor:shingles_asphalt"}, {["x"] = 2, ["y"] = 5, ["param1"] = 174, ["z"] = 3, ["name"] = "homedecor:shingles_asphalt"}, {["x"] = 2, ["y"] = 5, ["z"] = 4, ["name"] = "building_blocks:hardwood"}, {["x"] = 2, ["y"] = 5, ["z"] = 5, ["name"] = "building_blocks:hardwood"}, {["x"] = 2, ["y"] = 5, ["z"] = 6, ["name"] = "building_blocks:hardwood"}, {["x"] = 2, ["param2"] = 2, ["y"] = 5, ["param1"] = 174, ["z"] = 7, ["name"] = "homedecor:shingle_side_asphalt"}, {["x"] = 2, ["y"] = 5, ["param1"] = 158, ["z"] = 8, ["name"] = "homedecor:shingles_asphalt"}, {["x"] = 3, ["y"] = 0, ["z"] = 1, ["name"] = "building_blocks:hardwood"}, {["x"] = 3, ["meta"] = {["fields"] = {["infotext"] = "Zircon\
(December) ", ["text"] = "Zircon\
(December)", ["formspec"] = "size[6,4]textarea[0,-0.3;6.5,3;text;;${text}]button_exit[2,3.4;2,1;ok;Write]background[-0.5,-0.5;7,5;bg_signs_lib.jpg]", ["__signslib_new_format"] = "1"}, ["inventory"] = {}}, ["param2"] = 5, ["y"] = 0, ["param1"] = 153, ["z"] = 2, ["name"] = "default:sign_wall_steel"}, {["x"] = 3, ["y"] = 0, ["z"] = 9, ["name"] = "building_blocks:hardwood"}, {["x"] = 3, ["y"] = 1, ["z"] = 1, ["name"] = "building_blocks:hardwood"}, {["x"] = 3, ["meta"] = {["fields"] = {["infotext"] = "Item frame (owned by poikilos)", ["item"] = "birthstones:zircon", ["owner"] = "poikilos"}, ["inventory"] = {}}, ["param2"] = 2, ["y"] = 1, ["param1"] = 170, ["z"] = 2, ["name"] = "itemframes:frame"}, {["x"] = 3, ["y"] = 1, ["z"] = 9, ["name"] = "building_blocks:hardwood"}, {["x"] = 3, ["y"] = 2, ["z"] = 1, ["name"] = "building_blocks:hardwood"}, {["x"] = 3, ["y"] = 2, ["z"] = 9, ["name"] = "building_blocks:hardwood"}, {["x"] = 3, ["y"] = 3, ["param1"] = 142, ["z"] = 0, ["name"] = "homedecor:shingles_asphalt"}, {["x"] = 3, ["y"] = 3, ["z"] = 1, ["name"] = "building_blocks:hardwood"}, {["x"] = 3, ["y"] = 3, ["z"] = 9, ["name"] = "building_blocks:hardwood"}, {["x"] = 3, ["y"] = 3, ["param1"] = 142, ["z"] = 10, ["name"] = "homedecor:shingles_asphalt"}, {["x"] = 3, ["y"] = 4, ["param1"] = 110, ["z"] = 1, ["name"] = "homedecor:shingles_asphalt"}, {["x"] = 3, ["y"] = 4, ["z"] = 2, ["name"] = "building_blocks:hardwood"}, {["x"] = 3, ["y"] = 4, ["z"] = 3, ["name"] = "building_blocks:hardwood"}, {["x"] = 3, ["y"] = 4, ["z"] = 7, ["name"] = "building_blocks:hardwood"}, {["x"] = 3, ["y"] = 4, ["z"] = 8, ["name"] = "building_blocks:hardwood"}, {["x"] = 3, ["y"] = 4, ["param1"] = 110, ["z"] = 9, ["name"] = "homedecor:shingles_asphalt"}, {["x"] = 3, ["y"] = 5, ["param1"] = 142, ["z"] = 2, ["name"] = "homedecor:shingles_asphalt"}, {["x"] = 3, ["y"] = 5, ["param1"] = 158, ["z"] = 3, ["name"] = "homedecor:shingles_asphalt"}, {["x"] = 3, ["y"] = 5, ["z"] = 4, ["name"] = "building_blocks:hardwood"}, {["x"] = 3, ["y"] = 5, ["z"] = 5, ["name"] = "building_blocks:hardwood"}, {["x"] = 3, ["y"] = 5, ["z"] = 6, ["name"] = "building_blocks:hardwood"}, {["x"] = 3, ["y"] = 5, ["param1"] = 158, ["z"] = 7, ["name"] = "homedecor:shingles_asphalt"}, {["x"] = 3, ["y"] = 5, ["param1"] = 142, ["z"] = 8, ["name"] = "homedecor:shingles_asphalt"}, {["x"] = 4, ["y"] = 0, ["z"] = 1, ["name"] = "building_blocks:hardwood"}, {["x"] = 4, ["meta"] = {["fields"] = {["infotext"] = "Topaz\
(November) ", ["text"] = "Topaz\
(November)", ["formspec"] = "size[6,4]textarea[0,-0.3;6.5,3;text;;${text}]button_exit[2,3.4;2,1;ok;Write]background[-0.5,-0.5;7,5;bg_signs_lib.jpg]", ["__signslib_new_format"] = "1"}, ["inventory"] = {}}, ["param2"] = 5, ["y"] = 0, ["param1"] = 170, ["z"] = 2, ["name"] = "default:sign_wall_steel"}, {["x"] = 4, ["y"] = 0, ["z"] = 9, ["name"] = "building_blocks:hardwood"}, {["x"] = 4, ["y"] = 1, ["z"] = 1, ["name"] = "building_blocks:hardwood"}, {["x"] = 4, ["meta"] = {["fields"] = {["infotext"] = "Item frame (owned by poikilos)", ["item"] = "birthstones:topaz", ["owner"] = "poikilos"}, ["inventory"] = {}}, ["param2"] = 2, ["y"] = 1, ["param1"] = 187, ["z"] = 2, ["name"] = "itemframes:frame"}, {["x"] = 4, ["y"] = 1, ["z"] = 9, ["name"] = "building_blocks:hardwood"}, {["x"] = 4, ["y"] = 2, ["z"] = 1, ["name"] = "building_blocks:hardwood"}, {["x"] = 4, ["y"] = 2, ["z"] = 9, ["name"] = "building_blocks:hardwood"}, {["x"] = 4, ["y"] = 3, ["param1"] = 158, ["z"] = 0, ["name"] = "homedecor:shingles_asphalt"}, {["x"] = 4, ["y"] = 3, ["z"] = 1, ["name"] = "building_blocks:hardwood"}, {["x"] = 4, ["y"] = 3, ["param1"] = 221, ["z"] = 2, ["name"] = "homedecor:glowlight_small_cube_on"}, {["x"] = 4, ["y"] = 3, ["z"] = 9, ["name"] = "building_blocks:hardwood"}, {["x"] = 4, ["y"] = 3, ["param1"] = 158, ["z"] = 10, ["name"] = "homedecor:shingles_asphalt"}, {["x"] = 4, ["y"] = 4, ["param1"] = 126, ["z"] = 1, ["name"] = "homedecor:shingles_asphalt"}, {["x"] = 4, ["y"] = 4, ["z"] = 2, ["name"] = "building_blocks:hardwood"}, {["x"] = 4, ["y"] = 4, ["z"] = 3, ["name"] = "building_blocks:hardwood"}, {["x"] = 4, ["y"] = 4, ["z"] = 7, ["name"] = "building_blocks:hardwood"}, {["x"] = 4, ["y"] = 4, ["z"] = 8, ["name"] = "building_blocks:hardwood"}, {["x"] = 4, ["y"] = 4, ["param1"] = 126, ["z"] = 9, ["name"] = "homedecor:shingles_asphalt"}, {["x"] = 4, ["y"] = 5, ["param1"] = 126, ["z"] = 2, ["name"] = "homedecor:shingles_asphalt"}, {["x"] = 4, ["y"] = 5, ["param1"] = 142, ["z"] = 3, ["name"] = "homedecor:shingles_asphalt"}, {["x"] = 4, ["y"] = 5, ["z"] = 4, ["name"] = "building_blocks:hardwood"}, {["x"] = 4, ["y"] = 5, ["z"] = 5, ["name"] = "building_blocks:hardwood"}, {["x"] = 4, ["y"] = 5, ["z"] = 6, ["name"] = "building_blocks:hardwood"}, {["x"] = 4, ["y"] = 5, ["param1"] = 142, ["z"] = 7, ["name"] = "homedecor:shingles_asphalt"}, {["x"] = 4, ["y"] = 5, ["param1"] = 126, ["z"] = 8, ["name"] = "homedecor:shingles_asphalt"}, {["x"] = 5, ["y"] = 0, ["z"] = 1, ["name"] = "building_blocks:hardwood"}, {["x"] = 5, ["meta"] = {["fields"] = {["infotext"] = "Opal\
(September) ", ["text"] = "Opal\
(September)", ["formspec"] = "size[6,4]textarea[0,-0.3;6.5,3;text;;${text}]button_exit[2,3.4;2,1;ok;Write]background[-0.5,-0.5;7,5;bg_signs_lib.jpg]", ["__signslib_new_format"] = "1"}, ["inventory"] = {}}, ["param2"] = 5, ["y"] = 0, ["param1"] = 153, ["z"] = 2, ["name"] = "default:sign_wall_steel"}, {["x"] = 5, ["y"] = 0, ["z"] = 9, ["name"] = "building_blocks:hardwood"}, {["x"] = 5, ["y"] = 1, ["z"] = 1, ["name"] = "building_blocks:hardwood"}, {["x"] = 5, ["meta"] = {["fields"] = {["infotext"] = "Item frame (owned by poikilos)", ["item"] = "birthstones:opal", ["owner"] = "poikilos"}, ["inventory"] = {}}, ["param2"] = 2, ["y"] = 1, ["param1"] = 170, ["z"] = 2, ["name"] = "itemframes:frame"}, {["x"] = 5, ["y"] = 1, ["z"] = 9, ["name"] = "building_blocks:hardwood"}, {["x"] = 5, ["param2"] = 5, ["y"] = 1, ["param1"] = 206, ["z"] = 10, ["name"] = "default:torch_wall"}, {["x"] = 5, ["y"] = 2, ["z"] = 1, ["name"] = "building_blocks:hardwood"}, {["x"] = 5, ["y"] = 2, ["z"] = 9, ["name"] = "building_blocks:hardwood"}, {["x"] = 5, ["y"] = 3, ["param1"] = 174, ["z"] = 0, ["name"] = "homedecor:shingles_asphalt"}, {["x"] = 5, ["y"] = 3, ["z"] = 1, ["name"] = "building_blocks:hardwood"}, {["x"] = 5, ["y"] = 3, ["z"] = 9, ["name"] = "building_blocks:hardwood"}, {["x"] = 5, ["y"] = 3, ["param1"] = 174, ["z"] = 10, ["name"] = "homedecor:shingles_asphalt"}, {["x"] = 5, ["y"] = 4, ["param1"] = 142, ["z"] = 1, ["name"] = "homedecor:shingles_asphalt"}, {["x"] = 5, ["y"] = 4, ["z"] = 2, ["name"] = "building_blocks:hardwood"}, {["x"] = 5, ["y"] = 4, ["z"] = 3, ["name"] = "building_blocks:hardwood"}, {["x"] = 5, ["y"] = 4, ["z"] = 7, ["name"] = "building_blocks:hardwood"}, {["x"] = 5, ["y"] = 4, ["z"] = 8, ["name"] = "building_blocks:hardwood"}, {["x"] = 5, ["y"] = 4, ["param1"] = 142, ["z"] = 9, ["name"] = "homedecor:shingles_asphalt"}, {["x"] = 5, ["y"] = 5, ["param1"] = 110, ["z"] = 2, ["name"] = "homedecor:shingles_asphalt"}, {["x"] = 5, ["y"] = 5, ["param1"] = 126, ["z"] = 3, ["name"] = "homedecor:shingles_asphalt"}, {["x"] = 5, ["y"] = 5, ["z"] = 4, ["name"] = "building_blocks:hardwood"}, {["x"] = 5, ["y"] = 5, ["z"] = 5, ["name"] = "building_blocks:hardwood"}, {["x"] = 5, ["y"] = 5, ["z"] = 6, ["name"] = "building_blocks:hardwood"}, {["x"] = 5, ["y"] = 5, ["param1"] = 126, ["z"] = 7, ["name"] = "homedecor:shingles_asphalt"}, {["x"] = 5, ["y"] = 5, ["param1"] = 110, ["z"] = 8, ["name"] = "homedecor:shingles_asphalt"}, {["x"] = 6, ["y"] = 0, ["z"] = 1, ["name"] = "building_blocks:hardwood"}, {["x"] = 6, ["meta"] = {["fields"] = {["infotext"] = "Sapphire\
(September) ", ["text"] = "Sapphire\
(September)", ["formspec"] = "size[6,4]textarea[0,-0.3;6.5,3;text;;${text}]button_exit[2,3.4;2,1;ok;Write]background[-0.5,-0.5;7,5;bg_signs_lib.jpg]", ["__signslib_new_format"] = "1"}, ["inventory"] = {}}, ["param2"] = 5, ["y"] = 0, ["param1"] = 153, ["z"] = 2, ["name"] = "default:sign_wall_steel"}, {["x"] = 6, ["y"] = 0, ["z"] = 9, ["name"] = "building_blocks:hardwood"}, {["x"] = 6, ["y"] = 1, ["z"] = 1, ["name"] = "building_blocks:hardwood"}, {["x"] = 6, ["meta"] = {["fields"] = {["infotext"] = "Item frame (owned by poikilos)", ["item"] = "birthstones:sapphire", ["owner"] = "poikilos"}, ["inventory"] = {}}, ["param2"] = 2, ["y"] = 1, ["param1"] = 170, ["z"] = 2, ["name"] = "itemframes:frame"}, {["x"] = 6, ["y"] = 1, ["z"] = 9, ["name"] = "building_blocks:hardwood"}, {["x"] = 6, ["param2"] = 4, ["y"] = 2, ["param1"] = 206, ["z"] = 0, ["name"] = "default:torch_wall"}, {["x"] = 6, ["y"] = 2, ["z"] = 1, ["name"] = "building_blocks:hardwood"}, {["x"] = 6, ["y"] = 2, ["z"] = 9, ["name"] = "building_blocks:hardwood"}, {["x"] = 6, ["y"] = 3, ["param1"] = 190, ["z"] = 0, ["name"] = "homedecor:shingles_asphalt"}, {["x"] = 6, ["y"] = 3, ["z"] = 1, ["name"] = "building_blocks:hardwood"}, {["x"] = 6, ["y"] = 3, ["z"] = 9, ["name"] = "building_blocks:hardwood"}, {["x"] = 6, ["y"] = 3, ["param1"] = 158, ["z"] = 10, ["name"] = "homedecor:shingles_asphalt"}, {["x"] = 6, ["y"] = 4, ["param1"] = 158, ["z"] = 1, ["name"] = "homedecor:shingles_asphalt"}, {["x"] = 6, ["y"] = 4, ["z"] = 2, ["name"] = "building_blocks:hardwood"}, {["x"] = 6, ["y"] = 4, ["z"] = 3, ["name"] = "building_blocks:hardwood"}, {["x"] = 6, ["y"] = 4, ["z"] = 7, ["name"] = "building_blocks:hardwood"}, {["x"] = 6, ["y"] = 4, ["z"] = 8, ["name"] = "building_blocks:hardwood"}, {["x"] = 6, ["y"] = 4, ["param1"] = 126, ["z"] = 9, ["name"] = "homedecor:shingles_asphalt"}, {["x"] = 6, ["y"] = 5, ["param1"] = 126, ["z"] = 2, ["name"] = "homedecor:shingles_asphalt"}, {["x"] = 6, ["y"] = 5, ["param1"] = 110, ["z"] = 3, ["name"] = "homedecor:shingles_asphalt"}, {["x"] = 6, ["y"] = 5, ["z"] = 4, ["name"] = "building_blocks:hardwood"}, {["x"] = 6, ["y"] = 5, ["z"] = 5, ["name"] = "building_blocks:hardwood"}, {["x"] = 6, ["y"] = 5, ["z"] = 6, ["name"] = "building_blocks:hardwood"}, {["x"] = 6, ["y"] = 5, ["param1"] = 110, ["z"] = 7, ["name"] = "homedecor:shingles_asphalt"}, {["x"] = 6, ["y"] = 5, ["param1"] = 94, ["z"] = 8, ["name"] = "homedecor:shingles_asphalt"}, {["x"] = 7, ["y"] = 0, ["z"] = 1, ["name"] = "building_blocks:hardwood"}, {["x"] = 7, ["meta"] = {["fields"] = {["infotext"] = "Peridot\
(August) ", ["text"] = "Peridot\
(August)", ["formspec"] = "size[6,4]textarea[0,-0.3;6.5,3;text;;${text}]button_exit[2,3.4;2,1;ok;Write]background[-0.5,-0.5;7,5;bg_signs_lib.jpg]", ["__signslib_new_format"] = "1"}, ["inventory"] = {}}, ["param2"] = 5, ["y"] = 0, ["param1"] = 170, ["z"] = 2, ["name"] = "default:sign_wall_steel"}, {["x"] = 7, ["y"] = 0, ["z"] = 9, ["name"] = "building_blocks:hardwood"}, {["x"] = 7, ["y"] = 1, ["z"] = 1, ["name"] = "building_blocks:hardwood"}, {["x"] = 7, ["meta"] = {["fields"] = {["infotext"] = "Item frame (owned by poikilos)", ["item"] = "birthstones:peridot", ["owner"] = "poikilos"}, ["inventory"] = {}}, ["param2"] = 2, ["y"] = 1, ["param1"] = 187, ["z"] = 2, ["name"] = "itemframes:frame"}, {["x"] = 7, ["y"] = 1, ["z"] = 9, ["name"] = "building_blocks:hardwood"}, {["x"] = 7, ["y"] = 2, ["z"] = 1, ["name"] = "building_blocks:hardwood"}, {["x"] = 7, ["y"] = 2, ["z"] = 9, ["name"] = "building_blocks:hardwood"}, {["x"] = 7, ["y"] = 3, ["param1"] = 174, ["z"] = 0, ["name"] = "homedecor:shingles_asphalt"}, {["x"] = 7, ["y"] = 3, ["z"] = 1, ["name"] = "building_blocks:hardwood"}, {["x"] = 7, ["y"] = 3, ["param1"] = 221, ["z"] = 2, ["name"] = "homedecor:glowlight_small_cube_on"}, {["x"] = 7, ["y"] = 3, ["z"] = 9, ["name"] = "building_blocks:hardwood"}, {["x"] = 7, ["y"] = 3, ["param1"] = 142, ["z"] = 10, ["name"] = "homedecor:shingles_asphalt"}, {["x"] = 7, ["y"] = 4, ["param1"] = 142, ["z"] = 1, ["name"] = "homedecor:shingles_asphalt"}, {["x"] = 7, ["y"] = 4, ["z"] = 2, ["name"] = "building_blocks:hardwood"}, {["x"] = 7, ["y"] = 4, ["z"] = 3, ["name"] = "building_blocks:hardwood"}, {["x"] = 7, ["y"] = 4, ["z"] = 7, ["name"] = "building_blocks:hardwood"}, {["x"] = 7, ["y"] = 4, ["z"] = 8, ["name"] = "building_blocks:hardwood"}, {["x"] = 7, ["y"] = 4, ["param1"] = 110, ["z"] = 9, ["name"] = "homedecor:shingles_asphalt"}, {["x"] = 7, ["y"] = 5, ["param1"] = 110, ["z"] = 2, ["name"] = "homedecor:shingles_asphalt"}, {["x"] = 7, ["y"] = 5, ["param1"] = 94, ["z"] = 3, ["name"] = "homedecor:shingles_asphalt"}, {["x"] = 7, ["y"] = 5, ["z"] = 4, ["name"] = "building_blocks:hardwood"}, {["x"] = 7, ["y"] = 5, ["z"] = 5, ["name"] = "building_blocks:hardwood"}, {["x"] = 7, ["y"] = 5, ["z"] = 6, ["name"] = "building_blocks:hardwood"}, {["x"] = 7, ["param2"] = 2, ["y"] = 5, ["param1"] = 94, ["z"] = 7, ["name"] = "homedecor:shingle_side_asphalt"}, {["x"] = 7, ["y"] = 5, ["param1"] = 78, ["z"] = 8, ["name"] = "homedecor:shingles_asphalt"}, {["x"] = 8, ["y"] = 0, ["z"] = 1, ["name"] = "building_blocks:hardwood"}, {["x"] = 8, ["meta"] = {["fields"] = {["infotext"] = "Ruby\
(July) ", ["text"] = "Ruby\
(July)", ["formspec"] = "size[6,4]textarea[0,-0.3;6.5,3;text;;${text}]button_exit[2,3.4;2,1;ok;Write]background[-0.5,-0.5;7,5;bg_signs_lib.jpg]", ["__signslib_new_format"] = "1"}, ["inventory"] = {}}, ["param2"] = 5, ["y"] = 0, ["param1"] = 153, ["z"] = 2, ["name"] = "default:sign_wall_steel"}, {["x"] = 8, ["y"] = 0, ["z"] = 9, ["name"] = "building_blocks:hardwood"}, {["x"] = 8, ["y"] = 1, ["z"] = 1, ["name"] = "building_blocks:hardwood"}, {["x"] = 8, ["meta"] = {["fields"] = {["infotext"] = "Item frame (owned by poikilos)", ["item"] = "birthstones:ruby", ["owner"] = "poikilos"}, ["inventory"] = {}}, ["param2"] = 2, ["y"] = 1, ["param1"] = 170, ["z"] = 2, ["name"] = "itemframes:frame"}, {["x"] = 8, ["y"] = 1, ["z"] = 9, ["name"] = "building_blocks:hardwood"}, {["x"] = 8, ["y"] = 2, ["z"] = 1, ["name"] = "building_blocks:hardwood"}, {["x"] = 8, ["y"] = 2, ["z"] = 9, ["name"] = "building_blocks:hardwood"}, {["x"] = 8, ["y"] = 3, ["param1"] = 157, ["z"] = 0, ["name"] = "homedecor:shingles_asphalt"}, {["x"] = 8, ["y"] = 3, ["z"] = 1, ["name"] = "building_blocks:hardwood"}, {["x"] = 8, ["y"] = 3, ["z"] = 9, ["name"] = "building_blocks:hardwood"}, {["x"] = 8, ["y"] = 3, ["param1"] = 125, ["z"] = 10, ["name"] = "homedecor:shingles_asphalt"}, {["x"] = 8, ["y"] = 4, ["param1"] = 125, ["z"] = 1, ["name"] = "homedecor:shingles_asphalt"}, {["x"] = 8, ["y"] = 4, ["z"] = 2, ["name"] = "building_blocks:hardwood"}, {["x"] = 8, ["y"] = 4, ["z"] = 3, ["name"] = "building_blocks:hardwood"}, {["x"] = 8, ["y"] = 4, ["z"] = 7, ["name"] = "building_blocks:hardwood"}, {["x"] = 8, ["y"] = 4, ["z"] = 8, ["name"] = "building_blocks:hardwood"}, {["x"] = 8, ["y"] = 4, ["param1"] = 93, ["z"] = 9, ["name"] = "homedecor:shingles_asphalt"}, {["x"] = 8, ["y"] = 5, ["param1"] = 93, ["z"] = 2, ["name"] = "homedecor:shingles_asphalt"}, {["x"] = 8, ["y"] = 5, ["param1"] = 77, ["z"] = 3, ["name"] = "homedecor:shingles_asphalt"}, {["x"] = 8, ["y"] = 5, ["z"] = 4, ["name"] = "building_blocks:hardwood"}, {["x"] = 8, ["y"] = 5, ["z"] = 5, ["name"] = "building_blocks:hardwood"}, {["x"] = 8, ["y"] = 5, ["z"] = 6, ["name"] = "building_blocks:hardwood"}, {["x"] = 8, ["y"] = 5, ["param1"] = 77, ["z"] = 7, ["name"] = "homedecor:shingles_asphalt"}, {["x"] = 8, ["y"] = 5, ["param1"] = 61, ["z"] = 8, ["name"] = "homedecor:shingles_asphalt"}, {["x"] = 9, ["y"] = 0, ["z"] = 1, ["name"] = "building_blocks:hardwood"}, {["x"] = 9, ["meta"] = {["fields"] = {["infotext"] = "Alexandrite\
(June) ", ["text"] = "Alexandrite\
(June)\
", ["formspec"] = "size[6,4]textarea[0,-0.3;6.5,3;text;;${text}]button_exit[2,3.4;2,1;ok;Write]background[-0.5,-0.5;7,5;bg_signs_lib.jpg]", ["__signslib_new_format"] = "1"}, ["inventory"] = {}}, ["param2"] = 5, ["y"] = 0, ["param1"] = 153, ["z"] = 2, ["name"] = "default:sign_wall_steel"}, {["x"] = 9, ["y"] = 0, ["z"] = 9, ["name"] = "building_blocks:hardwood"}, {["x"] = 9, ["y"] = 1, ["z"] = 1, ["name"] = "building_blocks:hardwood"}, {["x"] = 9, ["meta"] = {["fields"] = {["infotext"] = "Item frame (owned by poikilos)", ["item"] = "birthstones:alexandrite", ["owner"] = "poikilos"}, ["inventory"] = {}}, ["param2"] = 2, ["y"] = 1, ["param1"] = 170, ["z"] = 2, ["name"] = "itemframes:frame"}, {["x"] = 9, ["y"] = 1, ["z"] = 9, ["name"] = "building_blocks:hardwood"}, {["x"] = 9, ["y"] = 2, ["z"] = 1, ["name"] = "building_blocks:hardwood"}, {["x"] = 9, ["meta"] = {["fields"] = {["infotext"] = "\
\
Birthstones ", ["text"] = " \
 \
Birthstones", ["formspec"] = "size[6,4]textarea[0,-0.3;6.5,3;text;;${text}]button_exit[2,3.4;2,1;ok;Write]background[-0.5,-0.5;7,5;bg_signs_lib.jpg]", ["__signslib_new_format"] = "1"}, ["inventory"] = {}}, ["param2"] = 5, ["y"] = 2, ["param1"] = 187, ["z"] = 2, ["name"] = "default:sign_wall_wood"}, {["x"] = 9, ["y"] = 2, ["z"] = 9, ["name"] = "building_blocks:hardwood"}, {["x"] = 9, ["y"] = 3, ["param1"] = 142, ["z"] = 0, ["name"] = "homedecor:shingles_asphalt"}, {["x"] = 9, ["y"] = 3, ["z"] = 1, ["name"] = "building_blocks:hardwood"}, {["x"] = 9, ["y"] = 3, ["z"] = 9, ["name"] = "building_blocks:hardwood"}, {["x"] = 9, ["y"] = 3, ["param1"] = 125, ["z"] = 10, ["name"] = "homedecor:shingles_asphalt"}, {["x"] = 9, ["y"] = 4, ["param1"] = 110, ["z"] = 1, ["name"] = "homedecor:shingles_asphalt"}, {["x"] = 9, ["y"] = 4, ["z"] = 2, ["name"] = "building_blocks:hardwood"}, {["x"] = 9, ["y"] = 4, ["z"] = 3, ["name"] = "building_blocks:hardwood"}, {["x"] = 9, ["y"] = 4, ["z"] = 7, ["name"] = "building_blocks:hardwood"}, {["x"] = 9, ["y"] = 4, ["z"] = 8, ["name"] = "building_blocks:hardwood"}, {["x"] = 9, ["y"] = 4, ["param1"] = 93, ["z"] = 9, ["name"] = "homedecor:shingles_asphalt"}, {["x"] = 9, ["y"] = 5, ["param1"] = 78, ["z"] = 2, ["name"] = "homedecor:shingles_asphalt"}, {["x"] = 9, ["y"] = 5, ["param1"] = 78, ["z"] = 3, ["name"] = "homedecor:shingles_asphalt"}, {["x"] = 9, ["y"] = 5, ["z"] = 4, ["name"] = "building_blocks:hardwood"}, {["x"] = 9, ["y"] = 5, ["z"] = 5, ["name"] = "building_blocks:hardwood"}, {["x"] = 9, ["y"] = 5, ["z"] = 6, ["name"] = "building_blocks:hardwood"}, {["x"] = 9, ["y"] = 5, ["param1"] = 77, ["z"] = 7, ["name"] = "homedecor:shingles_asphalt"}, {["x"] = 9, ["y"] = 5, ["param1"] = 61, ["z"] = 8, ["name"] = "homedecor:shingles_asphalt"}, {["x"] = 10, ["y"] = 0, ["z"] = 1, ["name"] = "building_blocks:hardwood"}, {["x"] = 10, ["meta"] = {["fields"] = {["infotext"] = "Emerald\
(May) ", ["text"] = "Emerald\
(May)", ["formspec"] = "size[6,4]textarea[0,-0.3;6.5,3;text;;${text}]button_exit[2,3.4;2,1;ok;Write]background[-0.5,-0.5;7,5;bg_signs_lib.jpg]", ["__signslib_new_format"] = "1"}, ["inventory"] = {}}, ["param2"] = 5, ["y"] = 0, ["param1"] = 170, ["z"] = 2, ["name"] = "default:sign_wall_steel"}, {["x"] = 10, ["y"] = 0, ["z"] = 9, ["name"] = "building_blocks:hardwood"}, {["x"] = 10, ["y"] = 1, ["z"] = 1, ["name"] = "building_blocks:hardwood"}, {["x"] = 10, ["meta"] = {["fields"] = {["infotext"] = "Item frame (owned by poikilos)", ["item"] = "birthstones:emerald", ["owner"] = "poikilos"}, ["inventory"] = {}}, ["param2"] = 2, ["y"] = 1, ["param1"] = 187, ["z"] = 2, ["name"] = "itemframes:frame"}, {["x"] = 10, ["y"] = 1, ["z"] = 9, ["name"] = "building_blocks:hardwood"}, {["x"] = 10, ["y"] = 2, ["z"] = 1, ["name"] = "building_blocks:hardwood"}, {["x"] = 10, ["y"] = 2, ["z"] = 9, ["name"] = "building_blocks:hardwood"}, {["x"] = 10, ["y"] = 3, ["param1"] = 158, ["z"] = 0, ["name"] = "homedecor:shingles_asphalt"}, {["x"] = 10, ["y"] = 3, ["z"] = 1, ["name"] = "building_blocks:hardwood"}, {["x"] = 10, ["y"] = 3, ["param1"] = 221, ["z"] = 2, ["name"] = "homedecor:glowlight_small_cube_on"}, {["x"] = 10, ["y"] = 3, ["param1"] = 221, ["z"] = 7, ["name"] = "homedecor:glowlight_small_cube_on"}, {["x"] = 10, ["y"] = 3, ["z"] = 9, ["name"] = "building_blocks:hardwood"}, {["x"] = 10, ["y"] = 3, ["param1"] = 142, ["z"] = 10, ["name"] = "homedecor:shingles_asphalt"}, {["x"] = 10, ["y"] = 4, ["param1"] = 126, ["z"] = 1, ["name"] = "homedecor:shingles_asphalt"}, {["x"] = 10, ["y"] = 4, ["z"] = 2, ["name"] = "building_blocks:hardwood"}, {["x"] = 10, ["y"] = 4, ["z"] = 3, ["name"] = "building_blocks:hardwood"}, {["x"] = 10, ["y"] = 4, ["z"] = 7, ["name"] = "building_blocks:hardwood"}, {["x"] = 10, ["y"] = 4, ["z"] = 8, ["name"] = "building_blocks:hardwood"}, {["x"] = 10, ["y"] = 4, ["param1"] = 110, ["z"] = 9, ["name"] = "homedecor:shingles_asphalt"}, {["x"] = 10, ["y"] = 5, ["param1"] = 94, ["z"] = 2, ["name"] = "homedecor:shingles_asphalt"}, {["x"] = 10, ["y"] = 5, ["param1"] = 94, ["z"] = 3, ["name"] = "homedecor:shingles_asphalt"}, {["x"] = 10, ["y"] = 5, ["z"] = 4, ["name"] = "building_blocks:hardwood"}, {["x"] = 10, ["y"] = 5, ["z"] = 5, ["name"] = "building_blocks:hardwood"}, {["x"] = 10, ["y"] = 5, ["z"] = 6, ["name"] = "building_blocks:hardwood"}, {["x"] = 10, ["y"] = 5, ["param1"] = 94, ["z"] = 7, ["name"] = "homedecor:shingles_asphalt"}, {["x"] = 10, ["y"] = 5, ["param1"] = 78, ["z"] = 8, ["name"] = "homedecor:shingles_asphalt"}, {["x"] = 11, ["y"] = 0, ["z"] = 1, ["name"] = "building_blocks:hardwood"}, {["x"] = 11, ["meta"] = {["fields"] = {["infotext"] = "Diamond\
(April) ", ["text"] = "Diamond\
(April)", ["formspec"] = "size[6,4]textarea[0,-0.3;6.5,3;text;;${text}]button_exit[2,3.4;2,1;ok;Write]background[-0.5,-0.5;7,5;bg_signs_lib.jpg]", ["__signslib_new_format"] = "1"}, ["inventory"] = {}}, ["param2"] = 5, ["y"] = 0, ["param1"] = 153, ["z"] = 2, ["name"] = "default:sign_wall_steel"}, {["x"] = 11, ["y"] = 0, ["z"] = 9, ["name"] = "building_blocks:hardwood"}, {["x"] = 11, ["y"] = 1, ["z"] = 1, ["name"] = "building_blocks:hardwood"}, {["x"] = 11, ["meta"] = {["fields"] = {["infotext"] = "Item frame (owned by poikilos)", ["item"] = "birthstones:diamond", ["owner"] = "poikilos"}, ["inventory"] = {}}, ["param2"] = 2, ["y"] = 1, ["param1"] = 170, ["z"] = 2, ["name"] = "itemframes:frame"}, {["x"] = 11, ["y"] = 1, ["z"] = 9, ["name"] = "building_blocks:hardwood"}, {["x"] = 11, ["y"] = 2, ["z"] = 1, ["name"] = "building_blocks:hardwood"}, {["x"] = 11, ["y"] = 2, ["z"] = 9, ["name"] = "building_blocks:hardwood"}, {["x"] = 11, ["y"] = 3, ["param1"] = 174, ["z"] = 0, ["name"] = "homedecor:shingles_asphalt"}, {["x"] = 11, ["y"] = 3, ["z"] = 1, ["name"] = "building_blocks:hardwood"}, {["x"] = 11, ["y"] = 3, ["z"] = 9, ["name"] = "building_blocks:hardwood"}, {["x"] = 11, ["y"] = 3, ["param1"] = 158, ["z"] = 10, ["name"] = "homedecor:shingles_asphalt"}, {["x"] = 11, ["y"] = 4, ["param1"] = 142, ["z"] = 1, ["name"] = "homedecor:shingles_asphalt"}, {["x"] = 11, ["y"] = 4, ["z"] = 2, ["name"] = "building_blocks:hardwood"}, {["x"] = 11, ["y"] = 4, ["z"] = 3, ["name"] = "building_blocks:hardwood"}, {["x"] = 11, ["y"] = 4, ["z"] = 7, ["name"] = "building_blocks:hardwood"}, {["x"] = 11, ["y"] = 4, ["z"] = 8, ["name"] = "building_blocks:hardwood"}, {["x"] = 11, ["y"] = 4, ["param1"] = 126, ["z"] = 9, ["name"] = "homedecor:shingles_asphalt"}, {["x"] = 11, ["y"] = 5, ["param1"] = 110, ["z"] = 2, ["name"] = "homedecor:shingles_asphalt"}, {["x"] = 11, ["y"] = 5, ["param1"] = 110, ["z"] = 3, ["name"] = "homedecor:shingles_asphalt"}, {["x"] = 11, ["y"] = 5, ["z"] = 4, ["name"] = "building_blocks:hardwood"}, {["x"] = 11, ["y"] = 5, ["z"] = 5, ["name"] = "building_blocks:hardwood"}, {["x"] = 11, ["y"] = 5, ["z"] = 6, ["name"] = "building_blocks:hardwood"}, {["x"] = 11, ["y"] = 5, ["param1"] = 110, ["z"] = 7, ["name"] = "homedecor:shingles_asphalt"}, {["x"] = 11, ["y"] = 5, ["param1"] = 94, ["z"] = 8, ["name"] = "homedecor:shingles_asphalt"}, {["x"] = 12, ["y"] = 0, ["z"] = 1, ["name"] = "building_blocks:hardwood"}, {["x"] = 12, ["meta"] = {["fields"] = {["infotext"] = "Aquamarine\
(March) ", ["text"] = "Aquamarine\
(March)", ["formspec"] = "size[6,4]textarea[0,-0.3;6.5,3;text;;${text}]button_exit[2,3.4;2,1;ok;Write]background[-0.5,-0.5;7,5;bg_signs_lib.jpg]", ["__signslib_new_format"] = "1"}, ["inventory"] = {}}, ["param2"] = 5, ["y"] = 0, ["param1"] = 153, ["z"] = 2, ["name"] = "default:sign_wall_steel"}, {["x"] = 12, ["y"] = 0, ["z"] = 9, ["name"] = "building_blocks:hardwood"}, {["x"] = 12, ["y"] = 1, ["z"] = 1, ["name"] = "building_blocks:hardwood"}, {["x"] = 12, ["meta"] = {["fields"] = {["infotext"] = "Item frame (owned by poikilos)", ["item"] = "birthstones:aquamarine", ["owner"] = "poikilos"}, ["inventory"] = {}}, ["param2"] = 2, ["y"] = 1, ["param1"] = 170, ["z"] = 2, ["name"] = "itemframes:frame"}, {["x"] = 12, ["y"] = 1, ["z"] = 9, ["name"] = "building_blocks:hardwood"}, {["x"] = 12, ["param2"] = 5, ["y"] = 1, ["param1"] = 206, ["z"] = 10, ["name"] = "default:torch_wall"}, {["x"] = 12, ["param2"] = 4, ["y"] = 2, ["param1"] = 206, ["z"] = 0, ["name"] = "default:torch_wall"}, {["x"] = 12, ["y"] = 2, ["z"] = 1, ["name"] = "building_blocks:hardwood"}, {["x"] = 12, ["y"] = 2, ["z"] = 9, ["name"] = "building_blocks:hardwood"}, {["x"] = 12, ["y"] = 3, ["param1"] = 190, ["z"] = 0, ["name"] = "homedecor:shingles_asphalt"}, {["x"] = 12, ["y"] = 3, ["z"] = 1, ["name"] = "building_blocks:hardwood"}, {["x"] = 12, ["y"] = 3, ["z"] = 9, ["name"] = "building_blocks:hardwood"}, {["x"] = 12, ["y"] = 3, ["param1"] = 174, ["z"] = 10, ["name"] = "homedecor:shingles_asphalt"}, {["x"] = 12, ["y"] = 4, ["param1"] = 158, ["z"] = 1, ["name"] = "homedecor:shingles_asphalt"}, {["x"] = 12, ["y"] = 4, ["z"] = 2, ["name"] = "building_blocks:hardwood"}, {["x"] = 12, ["y"] = 4, ["z"] = 3, ["name"] = "building_blocks:hardwood"}, {["x"] = 12, ["y"] = 4, ["z"] = 7, ["name"] = "building_blocks:hardwood"}, {["x"] = 12, ["y"] = 4, ["z"] = 8, ["name"] = "building_blocks:hardwood"}, {["x"] = 12, ["y"] = 4, ["param1"] = 142, ["z"] = 9, ["name"] = "homedecor:shingles_asphalt"}, {["x"] = 12, ["y"] = 5, ["param1"] = 126, ["z"] = 2, ["name"] = "homedecor:shingles_asphalt"}, {["x"] = 12, ["y"] = 5, ["param1"] = 126, ["z"] = 3, ["name"] = "homedecor:shingles_asphalt"}, {["x"] = 12, ["y"] = 5, ["z"] = 4, ["name"] = "building_blocks:hardwood"}, {["x"] = 12, ["y"] = 5, ["z"] = 5, ["name"] = "building_blocks:hardwood"}, {["x"] = 12, ["y"] = 5, ["z"] = 6, ["name"] = "building_blocks:hardwood"}, {["x"] = 12, ["param2"] = 2, ["y"] = 5, ["param1"] = 126, ["z"] = 7, ["name"] = "homedecor:shingle_side_asphalt"}, {["x"] = 12, ["y"] = 5, ["param1"] = 110, ["z"] = 8, ["name"] = "homedecor:shingles_asphalt"}, {["x"] = 13, ["y"] = 0, ["z"] = 1, ["name"] = "building_blocks:hardwood"}, {["x"] = 13, ["meta"] = {["fields"] = {["infotext"] = "Amethyst\
(February) ", ["text"] = "Amethyst\
(February)", ["formspec"] = "size[6,4]textarea[0,-0.3;6.5,3;text;;${text}]button_exit[2,3.4;2,1;ok;Write]background[-0.5,-0.5;7,5;bg_signs_lib.jpg]", ["__signslib_new_format"] = "1"}, ["inventory"] = {}}, ["param2"] = 5, ["y"] = 0, ["param1"] = 170, ["z"] = 2, ["name"] = "default:sign_wall_steel"}, {["x"] = 13, ["y"] = 0, ["z"] = 9, ["name"] = "building_blocks:hardwood"}, {["x"] = 13, ["y"] = 1, ["z"] = 1, ["name"] = "building_blocks:hardwood"}, {["x"] = 13, ["meta"] = {["fields"] = {["infotext"] = "Item frame (owned by poikilos)", ["item"] = "birthstones:amethyst", ["owner"] = "poikilos"}, ["inventory"] = {}}, ["param2"] = 2, ["y"] = 1, ["param1"] = 187, ["z"] = 2, ["name"] = "itemframes:frame"}, {["x"] = 13, ["y"] = 1, ["z"] = 9, ["name"] = "building_blocks:hardwood"}, {["x"] = 13, ["y"] = 2, ["z"] = 1, ["name"] = "building_blocks:hardwood"}, {["x"] = 13, ["y"] = 2, ["z"] = 9, ["name"] = "building_blocks:hardwood"}, {["x"] = 13, ["y"] = 3, ["param1"] = 174, ["z"] = 0, ["name"] = "homedecor:shingles_asphalt"}, {["x"] = 13, ["y"] = 3, ["z"] = 1, ["name"] = "building_blocks:hardwood"}, {["x"] = 13, ["y"] = 3, ["param1"] = 221, ["z"] = 2, ["name"] = "homedecor:glowlight_small_cube_on"}, {["x"] = 13, ["y"] = 3, ["z"] = 9, ["name"] = "building_blocks:hardwood"}, {["x"] = 13, ["y"] = 3, ["param1"] = 158, ["z"] = 10, ["name"] = "homedecor:shingles_asphalt"}, {["x"] = 13, ["y"] = 4, ["param1"] = 142, ["z"] = 1, ["name"] = "homedecor:shingles_asphalt"}, {["x"] = 13, ["y"] = 4, ["z"] = 2, ["name"] = "building_blocks:hardwood"}, {["x"] = 13, ["y"] = 4, ["z"] = 3, ["name"] = "building_blocks:hardwood"}, {["x"] = 13, ["y"] = 4, ["z"] = 7, ["name"] = "building_blocks:hardwood"}, {["x"] = 13, ["y"] = 4, ["z"] = 8, ["name"] = "building_blocks:hardwood"}, {["x"] = 13, ["y"] = 4, ["param1"] = 126, ["z"] = 9, ["name"] = "homedecor:shingles_asphalt"}, {["x"] = 13, ["y"] = 5, ["param1"] = 126, ["z"] = 2, ["name"] = "homedecor:shingles_asphalt"}, {["x"] = 13, ["y"] = 5, ["param1"] = 142, ["z"] = 3, ["name"] = "homedecor:shingles_asphalt"}, {["x"] = 13, ["y"] = 5, ["z"] = 4, ["name"] = "building_blocks:hardwood"}, {["x"] = 13, ["y"] = 5, ["z"] = 5, ["name"] = "building_blocks:hardwood"}, {["x"] = 13, ["y"] = 5, ["z"] = 6, ["name"] = "building_blocks:hardwood"}, {["x"] = 13, ["y"] = 5, ["param1"] = 142, ["z"] = 7, ["name"] = "homedecor:shingles_asphalt"}, {["x"] = 13, ["y"] = 5, ["param1"] = 126, ["z"] = 8, ["name"] = "homedecor:shingles_asphalt"}, {["x"] = 14, ["y"] = 0, ["z"] = 1, ["name"] = "building_blocks:hardwood"}, {["x"] = 14, ["meta"] = {["fields"] = {["infotext"] = "Garnet\
(January) ", ["text"] = "Garnet\
(January)", ["formspec"] = "size[6,4]textarea[0,-0.3;6.5,3;text;;${text}]button_exit[2,3.4;2,1;ok;Write]background[-0.5,-0.5;7,5;bg_signs_lib.jpg]", ["__signslib_new_format"] = "1"}, ["inventory"] = {}}, ["param2"] = 5, ["y"] = 0, ["param1"] = 153, ["z"] = 2, ["name"] = "default:sign_wall_steel"}, {["x"] = 14, ["y"] = 0, ["z"] = 9, ["name"] = "building_blocks:hardwood"}, {["x"] = 14, ["y"] = 1, ["z"] = 1, ["name"] = "building_blocks:hardwood"}, {["x"] = 14, ["meta"] = {["fields"] = {["infotext"] = "Item frame (owned by poikilos)", ["item"] = "birthstones:garnet", ["owner"] = "poikilos"}, ["inventory"] = {}}, ["param2"] = 2, ["y"] = 1, ["param1"] = 170, ["z"] = 2, ["name"] = "itemframes:frame"}, {["x"] = 14, ["y"] = 1, ["z"] = 9, ["name"] = "building_blocks:hardwood"}, {["x"] = 14, ["y"] = 2, ["z"] = 1, ["name"] = "building_blocks:hardwood"}, {["x"] = 14, ["y"] = 2, ["z"] = 9, ["name"] = "building_blocks:hardwood"}, {["x"] = 14, ["y"] = 3, ["param1"] = 158, ["z"] = 0, ["name"] = "homedecor:shingles_asphalt"}, {["x"] = 14, ["y"] = 3, ["z"] = 1, ["name"] = "building_blocks:hardwood"}, {["x"] = 14, ["y"] = 3, ["z"] = 9, ["name"] = "building_blocks:hardwood"}, {["x"] = 14, ["y"] = 3, ["param1"] = 142, ["z"] = 10, ["name"] = "homedecor:shingles_asphalt"}, {["x"] = 14, ["y"] = 4, ["param1"] = 126, ["z"] = 1, ["name"] = "homedecor:shingles_asphalt"}, {["x"] = 14, ["y"] = 4, ["z"] = 2, ["name"] = "building_blocks:hardwood"}, {["x"] = 14, ["y"] = 4, ["z"] = 3, ["name"] = "building_blocks:hardwood"}, {["x"] = 14, ["y"] = 4, ["z"] = 7, ["name"] = "building_blocks:hardwood"}, {["x"] = 14, ["y"] = 4, ["z"] = 8, ["name"] = "building_blocks:hardwood"}, {["x"] = 14, ["y"] = 4, ["param1"] = 110, ["z"] = 9, ["name"] = "homedecor:shingles_asphalt"}, {["x"] = 14, ["y"] = 5, ["param1"] = 142, ["z"] = 2, ["name"] = "homedecor:shingles_asphalt"}, {["x"] = 14, ["y"] = 5, ["param1"] = 158, ["z"] = 3, ["name"] = "homedecor:shingles_asphalt"}, {["x"] = 14, ["y"] = 5, ["z"] = 4, ["name"] = "building_blocks:hardwood"}, {["x"] = 14, ["y"] = 5, ["z"] = 5, ["name"] = "building_blocks:hardwood"}, {["x"] = 14, ["y"] = 5, ["z"] = 6, ["name"] = "building_blocks:hardwood"}, {["x"] = 14, ["y"] = 5, ["param1"] = 158, ["z"] = 7, ["name"] = "homedecor:shingles_asphalt"}, {["x"] = 14, ["y"] = 5, ["param1"] = 142, ["z"] = 8, ["name"] = "homedecor:shingles_asphalt"}, {["x"] = 15, ["y"] = 0, ["z"] = 1, ["name"] = "building_blocks:hardwood"}, {["x"] = 15, ["y"] = 0, ["z"] = 9, ["name"] = "building_blocks:hardwood"}, {["x"] = 15, ["y"] = 1, ["z"] = 1, ["name"] = "building_blocks:hardwood"}, {["x"] = 15, ["y"] = 1, ["z"] = 9, ["name"] = "building_blocks:hardwood"}, {["x"] = 15, ["y"] = 2, ["z"] = 1, ["name"] = "building_blocks:hardwood"}, {["x"] = 15, ["y"] = 2, ["z"] = 9, ["name"] = "building_blocks:hardwood"}, {["x"] = 15, ["y"] = 3, ["param1"] = 142, ["z"] = 0, ["name"] = "homedecor:shingles_asphalt"}, {["x"] = 15, ["y"] = 3, ["z"] = 1, ["name"] = "building_blocks:hardwood"}, {["x"] = 15, ["y"] = 3, ["z"] = 2, ["name"] = "building_blocks:hardwood"}, {["x"] = 15, ["y"] = 3, ["z"] = 3, ["name"] = "building_blocks:hardwood"}, {["x"] = 15, ["y"] = 3, ["z"] = 4, ["name"] = "building_blocks:hardwood"}, {["x"] = 15, ["y"] = 3, ["z"] = 5, ["name"] = "building_blocks:hardwood"}, {["x"] = 15, ["y"] = 3, ["z"] = 6, ["name"] = "building_blocks:hardwood"}, {["x"] = 15, ["y"] = 3, ["z"] = 7, ["name"] = "building_blocks:hardwood"}, {["x"] = 15, ["y"] = 3, ["z"] = 8, ["name"] = "building_blocks:hardwood"}, {["x"] = 15, ["y"] = 3, ["z"] = 9, ["name"] = "building_blocks:hardwood"}, {["x"] = 15, ["y"] = 3, ["param1"] = 126, ["z"] = 10, ["name"] = "homedecor:shingles_asphalt"}, {["x"] = 15, ["y"] = 4, ["param1"] = 126, ["z"] = 1, ["name"] = "homedecor:shingles_asphalt"}, {["x"] = 15, ["y"] = 4, ["z"] = 2, ["name"] = "building_blocks:hardwood"}, {["x"] = 15, ["y"] = 4, ["z"] = 3, ["name"] = "building_blocks:hardwood"}, {["x"] = 15, ["y"] = 4, ["z"] = 7, ["name"] = "building_blocks:hardwood"}, {["x"] = 15, ["y"] = 4, ["z"] = 8, ["name"] = "building_blocks:hardwood"}, {["x"] = 15, ["y"] = 4, ["param1"] = 126, ["z"] = 9, ["name"] = "homedecor:shingles_asphalt"}, {["x"] = 15, ["y"] = 5, ["param1"] = 158, ["z"] = 2, ["name"] = "homedecor:shingles_asphalt"}, {["x"] = 15, ["y"] = 5, ["param1"] = 174, ["z"] = 3, ["name"] = "homedecor:shingles_asphalt"}, {["x"] = 15, ["y"] = 5, ["z"] = 4, ["name"] = "building_blocks:hardwood"}, {["x"] = 15, ["y"] = 5, ["z"] = 5, ["name"] = "building_blocks:hardwood"}, {["x"] = 15, ["y"] = 5, ["z"] = 6, ["name"] = "building_blocks:hardwood"}, {["x"] = 15, ["y"] = 5, ["param1"] = 174, ["z"] = 7, ["name"] = "homedecor:shingles_asphalt"}, {["x"] = 15, ["y"] = 5, ["param1"] = 158, ["z"] = 8, ["name"] = "homedecor:shingles_asphalt"}, {["x"] = 16, ["y"] = 0, ["z"] = 1, ["name"] = "building_blocks:hardwood"}, {["x"] = 16, ["y"] = 0, ["z"] = 2, ["name"] = "building_blocks:hardwood"}, {["x"] = 16, ["y"] = 0, ["z"] = 3, ["name"] = "building_blocks:hardwood"}, {["x"] = 16, ["y"] = 0, ["z"] = 4, ["name"] = "building_blocks:hardwood"}, {["x"] = 16, ["y"] = 0, ["z"] = 5, ["name"] = "building_blocks:hardwood"}, {["x"] = 16, ["param2"] = 2, ["y"] = 0, ["param1"] = 141, ["z"] = 6, ["name"] = "doors:woodglass_a"}, {["x"] = 16, ["y"] = 0, ["z"] = 7, ["name"] = "building_blocks:hardwood"}, {["x"] = 16, ["y"] = 0, ["z"] = 8, ["name"] = "building_blocks:hardwood"}, {["x"] = 16, ["y"] = 0, ["z"] = 9, ["name"] = "building_blocks:hardwood"}, {["x"] = 16, ["y"] = 1, ["z"] = 1, ["name"] = "building_blocks:hardwood"}, {["x"] = 16, ["y"] = 1, ["z"] = 2, ["name"] = "building_blocks:hardwood"}, {["x"] = 16, ["y"] = 1, ["z"] = 3, ["name"] = "building_blocks:hardwood"}, {["x"] = 16, ["param2"] = 3, ["y"] = 1, ["param1"] = 141, ["z"] = 4, ["name"] = "doors:wood_glass_mahogany_b"}, {["x"] = 16, ["y"] = 1, ["z"] = 5, ["name"] = "building_blocks:hardwood"}, {["x"] = 16, ["y"] = 1, ["param1"] = 157, ["z"] = 6, ["name"] = "doors:hidden"}, {["x"] = 16, ["y"] = 1, ["z"] = 7, ["name"] = "building_blocks:hardwood"}, {["x"] = 16, ["y"] = 1, ["z"] = 8, ["name"] = "building_blocks:hardwood"}, {["x"] = 16, ["y"] = 1, ["z"] = 9, ["name"] = "building_blocks:hardwood"}, {["x"] = 16, ["y"] = 2, ["z"] = 1, ["name"] = "building_blocks:hardwood"}, {["x"] = 16, ["y"] = 2, ["z"] = 2, ["name"] = "building_blocks:hardwood"}, {["x"] = 16, ["y"] = 2, ["z"] = 3, ["name"] = "building_blocks:hardwood"}, {["x"] = 16, ["y"] = 2, ["param1"] = 157, ["z"] = 4, ["name"] = "doors:hidden"}, {["x"] = 16, ["y"] = 2, ["z"] = 5, ["name"] = "building_blocks:hardwood"}, {["x"] = 16, ["y"] = 2, ["z"] = 6, ["name"] = "building_blocks:hardwood"}, {["x"] = 16, ["y"] = 2, ["z"] = 7, ["name"] = "building_blocks:hardwood"}, {["x"] = 16, ["y"] = 2, ["z"] = 8, ["name"] = "building_blocks:hardwood"}, {["x"] = 16, ["y"] = 2, ["z"] = 9, ["name"] = "building_blocks:hardwood"}, {["x"] = 16, ["y"] = 3, ["param1"] = 126, ["z"] = 0, ["name"] = "homedecor:shingles_asphalt"}, {["x"] = 16, ["y"] = 3, ["z"] = 1, ["name"] = "building_blocks:hardwood"}, {["x"] = 16, ["y"] = 3, ["z"] = 2, ["name"] = "building_blocks:hardwood"}, {["x"] = 16, ["y"] = 3, ["z"] = 3, ["name"] = "building_blocks:hardwood"}, {["x"] = 16, ["y"] = 3, ["z"] = 4, ["name"] = "building_blocks:hardwood"}, {["x"] = 16, ["y"] = 3, ["z"] = 5, ["name"] = "building_blocks:hardwood"}, {["x"] = 16, ["y"] = 3, ["z"] = 6, ["name"] = "building_blocks:hardwood"}, {["x"] = 16, ["y"] = 3, ["z"] = 7, ["name"] = "building_blocks:hardwood"}, {["x"] = 16, ["y"] = 3, ["z"] = 8, ["name"] = "building_blocks:hardwood"}, {["x"] = 16, ["y"] = 3, ["z"] = 9, ["name"] = "building_blocks:hardwood"}, {["x"] = 16, ["y"] = 3, ["param1"] = 110, ["z"] = 10, ["name"] = "homedecor:shingles_asphalt"}, {["x"] = 16, ["y"] = 4, ["param1"] = 142, ["z"] = 1, ["name"] = "homedecor:shingles_asphalt"}, {["x"] = 16, ["y"] = 4, ["z"] = 2, ["name"] = "building_blocks:hardwood"}, {["x"] = 16, ["y"] = 4, ["z"] = 3, ["name"] = "building_blocks:hardwood"}, {["x"] = 16, ["y"] = 4, ["z"] = 4, ["name"] = "building_blocks:hardwood"}, {["x"] = 16, ["param2"] = 3, ["y"] = 4, ["param1"] = 204, ["z"] = 5, ["name"] = "homedecor:window_quartered"}, {["x"] = 16, ["y"] = 4, ["z"] = 6, ["name"] = "building_blocks:hardwood"}, {["x"] = 16, ["y"] = 4, ["z"] = 7, ["name"] = "building_blocks:hardwood"}, {["x"] = 16, ["y"] = 4, ["z"] = 8, ["name"] = "building_blocks:hardwood"}, {["x"] = 16, ["y"] = 4, ["param1"] = 142, ["z"] = 9, ["name"] = "homedecor:shingles_asphalt"}, {["x"] = 16, ["y"] = 5, ["param1"] = 174, ["z"] = 2, ["name"] = "homedecor:shingles_asphalt"}, {["x"] = 16, ["y"] = 5, ["param1"] = 190, ["z"] = 3, ["name"] = "homedecor:shingles_asphalt"}, {["x"] = 16, ["y"] = 5, ["z"] = 4, ["name"] = "building_blocks:hardwood"}, {["x"] = 16, ["y"] = 5, ["z"] = 5, ["name"] = "building_blocks:hardwood"}, {["x"] = 16, ["y"] = 5, ["z"] = 6, ["name"] = "building_blocks:hardwood"}, {["x"] = 16, ["y"] = 5, ["param1"] = 190, ["z"] = 7, ["name"] = "homedecor:shingles_asphalt"}, {["x"] = 16, ["y"] = 5, ["param1"] = 174, ["z"] = 8, ["name"] = "homedecor:shingles_asphalt"}, {["x"] = 17, ["param2"] = 3, ["y"] = 1, ["param1"] = 190, ["z"] = 7, ["name"] = "homedecor:wall_lamp"}, {["x"] = 17, ["meta"] = {["fields"] = {["infotext"] = "\
\
Gemology Museum ", ["__signslib_new_format"] = "1", ["formspec"] = "size[6,4]textarea[0,-0.3;6.5,3;text;;${text}]button_exit[2,3.4;2,1;ok;Write]background[-0.5,-0.5;7,5;bg_signs_lib.jpg]", ["text"] = " \
 \
Gemology Museum"}, ["inventory"] = {}}, ["param2"] = 3, ["y"] = 2, ["param1"] = 174, ["z"] = 6, ["name"] = "default:sign_wall_wood"}, {["x"] = 17, ["y"] = 3, ["param1"] = 126, ["z"] = 0, ["name"] = "homedecor:shingles_asphalt"}, {["x"] = 17, ["y"] = 3, ["param1"] = 126, ["z"] = 10, ["name"] = "homedecor:shingles_asphalt"}, {["x"] = 17, ["y"] = 4, ["param1"] = 158, ["z"] = 1, ["name"] = "homedecor:shingles_asphalt"}, {["x"] = 17, ["y"] = 4, ["param1"] = 158, ["z"] = 9, ["name"] = "homedecor:shingles_asphalt"}, {["x"] = 17, ["y"] = 5, ["param1"] = 190, ["z"] = 2, ["name"] = "homedecor:shingles_asphalt"}, {["x"] = 17, ["y"] = 5, ["param1"] = 206, ["z"] = 3, ["name"] = "homedecor:shingles_asphalt"}, {["x"] = 17, ["y"] = 5, ["param1"] = 238, ["z"] = 5, ["name"] = "default:mese_post_light"}, {["x"] = 17, ["y"] = 5, ["param1"] = 206, ["z"] = 7, ["name"] = "homedecor:shingles_asphalt"}, {["x"] = 17, ["y"] = 5, ["param1"] = 190, ["z"] = 8, ["name"] = "homedecor:shingles_asphalt"}}
