5:return {{["x"] = 0, ["meta"] = {["fields"] = {["infotext"] = "Carrot ", ["__signslib_new_format"] = "1", ["formspec"] = "size[6,4]textarea[0,-0.3;6.5,3;text;;${text}]button_exit[2,3.4;2,1;ok;Write]background[-0.5,-0.5;7,5;bg_signs_lib.jpg]", ["text"] = "Carrot"}, ["inventory"] = {}}, ["param2"] = 2, ["y"] = 0, ["param1"] = 175, ["z"] = 0, ["name"] = "default:sign_wall_wood"}, {["x"] = 0, ["param2"] = 1, ["y"] = 0, ["param1"] = 159, ["z"] = 1, ["name"] = "moreblocks:stair_stone"}, {["x"] = 0, ["meta"] = {["fields"] = {["infotext"] = "Corn ", ["__signslib_new_format"] = "1", ["formspec"] = "size[6,4]textarea[0,-0.3;6.5,3;text;;${text}]button_exit[2,3.4;2,1;ok;Write]background[-0.5,-0.5;7,5;bg_signs_lib.jpg]", ["text"] = "Corn\
"}, ["inventory"] = {}}, ["param2"] = 2, ["y"] = 0, ["param1"] = 175, ["z"] = 2, ["name"] = "default:sign_wall_wood"}, {["x"] = 0, ["meta"] = {["fields"] = {["infotext"] = "Rhubarb ", ["__signslib_new_format"] = "1", ["formspec"] = "size[6,4]textarea[0,-0.3;6.5,3;text;;${text}]button_exit[2,3.4;2,1;ok;Write]background[-0.5,-0.5;7,5;bg_signs_lib.jpg]", ["text"] = "Rhubarb"}, ["inventory"] = {}}, ["param2"] = 2, ["y"] = 0, ["param1"] = 159, ["z"] = 3, ["name"] = "default:sign_wall_wood"}, {["x"] = 0, ["meta"] = {["fields"] = {["infotext"] = "Green Bean ", ["__signslib_new_format"] = "1", ["formspec"] = "size[6,4]textarea[0,-0.3;6.5,3;text;;${text}]button_exit[2,3.4;2,1;ok;Write]background[-0.5,-0.5;7,5;bg_signs_lib.jpg]", ["text"] = "Green Bean"}, ["inventory"] = {}}, ["param2"] = 2, ["y"] = 0, ["param1"] = 143, ["z"] = 4, ["name"] = "default:sign_wall_wood"}, {["x"] = 0, ["meta"] = {["fields"] = {["infotext"] = "Cucumber ", ["__signslib_new_format"] = "1", ["formspec"] = "size[6,4]textarea[0,-0.3;6.5,3;text;;${text}]button_exit[2,3.4;2,1;ok;Write]background[-0.5,-0.5;7,5;bg_signs_lib.jpg]", ["text"] = "Cucumber"}, ["inventory"] = {}}, ["param2"] = 2, ["y"] = 0, ["param1"] = 143, ["z"] = 5, ["name"] = "default:sign_wall_wood"}, {["x"] = 0, ["meta"] = {["fields"] = {["infotext"] = "Pumpkin ", ["__signslib_new_format"] = "1", ["formspec"] = "size[6,4]textarea[0,-0.3;6.5,3;text;;${text}]button_exit[2,3.4;2,1;ok;Write]background[-0.5,-0.5;7,5;bg_signs_lib.jpg]", ["text"] = "Pumpkin"}, ["inventory"] = {}}, ["param2"] = 2, ["y"] = 0, ["param1"] = 158, ["z"] = 6, ["name"] = "default:sign_wall_wood"}, {["x"] = 0, ["meta"] = {["fields"] = {["infotext"] = "Potato ", ["text"] = "Potato", ["__signslib_new_format"] = "1", ["formspec"] = "size[6,4]textarea[0,-0.3;6.5,3;text;;${text}]button_exit[2,3.4;2,1;ok;Write]background[-0.5,-0.5;7,5;bg_signs_lib.jpg]"}, ["inventory"] = {}}, ["param2"] = 2, ["y"] = 0, ["param1"] = 174, ["z"] = 7, ["name"] = "default:sign_wall_wood"}, {["x"] = 0, ["meta"] = {["fields"] = {["infotext"] = "Melon ", ["text"] = "Melon", ["__signslib_new_format"] = "1", ["formspec"] = "size[6,4]textarea[0,-0.3;6.5,3;text;;${text}]button_exit[2,3.4;2,1;ok;Write]background[-0.5,-0.5;7,5;bg_signs_lib.jpg]"}, ["inventory"] = {}}, ["param2"] = 2, ["y"] = 0, ["param1"] = 143, ["z"] = 11, ["name"] = "default:sign_wall_wood"}, {["x"] = 0, ["meta"] = {["fields"] = {["infotext"] = "Grape ", ["text"] = "Grape", ["__signslib_new_format"] = "1", ["formspec"] = "size[6,4]textarea[0,-0.3;6.5,3;text;;${text}]button_exit[2,3.4;2,1;ok;Write]background[-0.5,-0.5;7,5;bg_signs_lib.jpg]"}, ["inventory"] = {}}, ["param2"] = 2, ["y"] = 0, ["param1"] = 127, ["z"] = 12, ["name"] = "default:sign_wall_wood"}, {["x"] = 0, ["meta"] = {["fields"] = {["infotext"] = "Cotton ", ["text"] = "Cotton\
", ["__signslib_new_format"] = "1", ["formspec"] = "size[6,4]textarea[0,-0.3;6.5,3;text;;${text}]button_exit[2,3.4;2,1;ok;Write]background[-0.5,-0.5;7,5;bg_signs_lib.jpg]"}, ["inventory"] = {}}, ["param2"] = 2, ["y"] = 0, ["param1"] = 111, ["z"] = 13, ["name"] = "default:sign_wall_wood"}, {["x"] = 0, ["meta"] = {["fields"] = {["infotext"] = "Wheat ", ["text"] = "Wheat", ["__signslib_new_format"] = "1", ["formspec"] = "size[6,4]textarea[0,-0.3;6.5,3;text;;${text}]button_exit[2,3.4;2,1;ok;Write]background[-0.5,-0.5;7,5;bg_signs_lib.jpg]"}, ["inventory"] = {}}, ["param2"] = 2, ["y"] = 0, ["param1"] = 95, ["z"] = 14, ["name"] = "default:sign_wall_wood"}, {["x"] = 0, ["meta"] = {["fields"] = {["infotext"] = "Barley ", ["text"] = "Barley", ["__signslib_new_format"] = "1", ["formspec"] = "size[6,4]textarea[0,-0.3;6.5,3;text;;${text}]button_exit[2,3.4;2,1;ok;Write]background[-0.5,-0.5;7,5;bg_signs_lib.jpg]"}, ["inventory"] = {}}, ["param2"] = 2, ["y"] = 0, ["param1"] = 79, ["z"] = 15, ["name"] = "default:sign_wall_wood"}, {["x"] = 0, ["param2"] = 2, ["y"] = 1, ["param1"] = 175, ["z"] = 1, ["name"] = "doors:wrought_iron_a"}, {["x"] = 0, ["param2"] = 2, ["y"] = 2, ["param1"] = 207, ["z"] = 0, ["name"] = "default:torch_wall"}, {["x"] = 0, ["y"] = 2, ["param1"] = 191, ["z"] = 1, ["name"] = "doors:hidden"}, {["x"] = 0, ["param2"] = 2, ["y"] = 2, ["param1"] = 207, ["z"] = 2, ["name"] = "default:torch_wall"}, {["x"] = 1, ["y"] = 0, ["z"] = 0, ["name"] = "default:brick"}, {["x"] = 1, ["y"] = 0, ["z"] = 1, ["name"] = "default:brick"}, {["x"] = 1, ["y"] = 0, ["z"] = 2, ["name"] = "default:brick"}, {["x"] = 1, ["y"] = 0, ["z"] = 3, ["name"] = "default:brick"}, {["x"] = 1, ["y"] = 0, ["z"] = 4, ["name"] = "default:brick"}, {["x"] = 1, ["y"] = 0, ["z"] = 5, ["name"] = "default:brick"}, {["x"] = 1, ["y"] = 0, ["z"] = 6, ["name"] = "default:brick"}, {["x"] = 1, ["y"] = 0, ["z"] = 7, ["name"] = "default:brick"}, {["x"] = 1, ["y"] = 0, ["z"] = 8, ["name"] = "default:brick"}, {["x"] = 1, ["y"] = 0, ["z"] = 9, ["name"] = "default:brick"}, {["x"] = 1, ["y"] = 0, ["z"] = 10, ["name"] = "default:brick"}, {["x"] = 1, ["y"] = 0, ["z"] = 11, ["name"] = "default:brick"}, {["x"] = 1, ["y"] = 0, ["z"] = 12, ["name"] = "default:brick"}, {["x"] = 1, ["y"] = 0, ["z"] = 13, ["name"] = "default:brick"}, {["x"] = 1, ["y"] = 0, ["z"] = 14, ["name"] = "default:brick"}, {["x"] = 1, ["y"] = 0, ["z"] = 15, ["name"] = "default:brick"}, {["x"] = 1, ["y"] = 0, ["z"] = 16, ["name"] = "default:brick"}, {["x"] = 1, ["y"] = 1, ["z"] = 0, ["name"] = "default:brick"}, {["x"] = 1, ["y"] = 1, ["z"] = 2, ["name"] = "default:brick"}, {["x"] = 1, ["y"] = 1, ["param1"] = 159, ["z"] = 3, ["name"] = "default:obsidian_glass"}, {["x"] = 1, ["y"] = 1, ["param1"] = 159, ["z"] = 4, ["name"] = "default:obsidian_glass"}, {["x"] = 1, ["y"] = 1, ["param1"] = 175, ["z"] = 5, ["name"] = "default:obsidian_glass"}, {["x"] = 1, ["y"] = 1, ["param1"] = 190, ["z"] = 6, ["name"] = "default:obsidian_glass"}, {["x"] = 1, ["y"] = 1, ["param1"] = 205, ["z"] = 7, ["name"] = "default:obsidian_glass"}, {["x"] = 1, ["y"] = 1, ["z"] = 8, ["name"] = "default:brick"}, {["x"] = 1, ["y"] = 1, ["param1"] = 207, ["z"] = 9, ["name"] = "default:obsidian_glass"}, {["x"] = 1, ["y"] = 1, ["param1"] = 191, ["z"] = 10, ["name"] = "default:obsidian_glass"}, {["x"] = 1, ["y"] = 1, ["param1"] = 175, ["z"] = 11, ["name"] = "default:obsidian_glass"}, {["x"] = 1, ["y"] = 1, ["param1"] = 159, ["z"] = 12, ["name"] = "default:obsidian_glass"}, {["x"] = 1, ["y"] = 1, ["param1"] = 143, ["z"] = 13, ["name"] = "default:obsidian_glass"}, {["x"] = 1, ["y"] = 1, ["param1"] = 127, ["z"] = 14, ["name"] = "default:obsidian_glass"}, {["x"] = 1, ["y"] = 1, ["param1"] = 111, ["z"] = 15, ["name"] = "default:obsidian_glass"}, {["x"] = 1, ["y"] = 1, ["z"] = 16, ["name"] = "default:brick"}, {["x"] = 1, ["y"] = 2, ["z"] = 0, ["name"] = "default:brick"}, {["x"] = 1, ["y"] = 2, ["z"] = 2, ["name"] = "default:brick"}, {["x"] = 1, ["y"] = 2, ["param1"] = 175, ["z"] = 3, ["name"] = "default:obsidian_glass"}, {["x"] = 1, ["y"] = 2, ["param1"] = 159, ["z"] = 4, ["name"] = "default:obsidian_glass"}, {["x"] = 1, ["y"] = 2, ["param1"] = 159, ["z"] = 5, ["name"] = "default:obsidian_glass"}, {["x"] = 1, ["y"] = 2, ["param1"] = 174, ["z"] = 6, ["name"] = "default:obsidian_glass"}, {["x"] = 1, ["y"] = 2, ["param1"] = 189, ["z"] = 7, ["name"] = "default:obsidian_glass"}, {["x"] = 1, ["y"] = 2, ["z"] = 8, ["name"] = "default:brick"}, {["x"] = 1, ["y"] = 2, ["param1"] = 191, ["z"] = 9, ["name"] = "default:obsidian_glass"}, {["x"] = 1, ["y"] = 2, ["param1"] = 175, ["z"] = 10, ["name"] = "default:obsidian_glass"}, {["x"] = 1, ["y"] = 2, ["param1"] = 159, ["z"] = 11, ["name"] = "default:obsidian_glass"}, {["x"] = 1, ["y"] = 2, ["param1"] = 143, ["z"] = 12, ["name"] = "default:obsidian_glass"}, {["x"] = 1, ["y"] = 2, ["param1"] = 127, ["z"] = 13, ["name"] = "default:obsidian_glass"}, {["x"] = 1, ["y"] = 2, ["param1"] = 111, ["z"] = 14, ["name"] = "default:obsidian_glass"}, {["x"] = 1, ["y"] = 2, ["param1"] = 95, ["z"] = 15, ["name"] = "default:obsidian_glass"}, {["x"] = 1, ["y"] = 2, ["z"] = 16, ["name"] = "default:brick"}, {["x"] = 1, ["y"] = 3, ["z"] = 0, ["name"] = "default:brick"}, {["x"] = 1, ["y"] = 3, ["z"] = 1, ["name"] = "default:brick"}, {["x"] = 1, ["y"] = 3, ["z"] = 2, ["name"] = "default:brick"}, {["x"] = 1, ["y"] = 3, ["param1"] = 159, ["z"] = 3, ["name"] = "default:obsidian_glass"}, {["x"] = 1, ["y"] = 3, ["param1"] = 143, ["z"] = 4, ["name"] = "default:obsidian_glass"}, {["x"] = 1, ["y"] = 3, ["param1"] = 143, ["z"] = 5, ["name"] = "default:obsidian_glass"}, {["x"] = 1, ["y"] = 3, ["param1"] = 158, ["z"] = 6, ["name"] = "default:obsidian_glass"}, {["x"] = 1, ["y"] = 3, ["param1"] = 173, ["z"] = 7, ["name"] = "default:obsidian_glass"}, {["x"] = 1, ["y"] = 3, ["z"] = 8, ["name"] = "default:brick"}, {["x"] = 1, ["y"] = 3, ["param1"] = 175, ["z"] = 9, ["name"] = "default:obsidian_glass"}, {["x"] = 1, ["y"] = 3, ["param1"] = 159, ["z"] = 10, ["name"] = "default:obsidian_glass"}, {["x"] = 1, ["y"] = 3, ["param1"] = 143, ["z"] = 11, ["name"] = "default:obsidian_glass"}, {["x"] = 1, ["y"] = 3, ["param1"] = 127, ["z"] = 12, ["name"] = "default:obsidian_glass"}, {["x"] = 1, ["y"] = 3, ["param1"] = 111, ["z"] = 13, ["name"] = "default:obsidian_glass"}, {["x"] = 1, ["y"] = 3, ["param1"] = 95, ["z"] = 14, ["name"] = "default:obsidian_glass"}, {["x"] = 1, ["y"] = 3, ["param1"] = 79, ["z"] = 15, ["name"] = "default:obsidian_glass"}, {["x"] = 1, ["y"] = 3, ["z"] = 16, ["name"] = "default:brick"}, {["x"] = 1, ["y"] = 4, ["param1"] = 206, ["z"] = 0, ["name"] = "building_blocks:grate"}, {["x"] = 1, ["y"] = 4, ["param1"] = 191, ["z"] = 1, ["name"] = "building_blocks:grate"}, {["x"] = 1, ["y"] = 4, ["param1"] = 175, ["z"] = 2, ["name"] = "building_blocks:grate"}, {["x"] = 1, ["y"] = 4, ["param1"] = 159, ["z"] = 3, ["name"] = "building_blocks:grate"}, {["x"] = 1, ["y"] = 4, ["param1"] = 143, ["z"] = 4, ["name"] = "building_blocks:grate"}, {["x"] = 1, ["y"] = 4, ["param1"] = 127, ["z"] = 5, ["name"] = "building_blocks:grate"}, {["x"] = 1, ["y"] = 4, ["param1"] = 142, ["z"] = 6, ["name"] = "building_blocks:grate"}, {["x"] = 1, ["y"] = 4, ["param1"] = 158, ["z"] = 7, ["name"] = "building_blocks:grate"}, {["x"] = 1, ["y"] = 4, ["param1"] = 175, ["z"] = 8, ["name"] = "building_blocks:grate"}, {["x"] = 1, ["y"] = 4, ["param1"] = 159, ["z"] = 9, ["name"] = "building_blocks:grate"}, {["x"] = 1, ["y"] = 4, ["param1"] = 143, ["z"] = 10, ["name"] = "building_blocks:grate"}, {["x"] = 1, ["y"] = 4, ["param1"] = 127, ["z"] = 11, ["name"] = "building_blocks:grate"}, {["x"] = 1, ["y"] = 4, ["param1"] = 111, ["z"] = 12, ["name"] = "building_blocks:grate"}, {["x"] = 1, ["y"] = 4, ["param1"] = 95, ["z"] = 13, ["name"] = "building_blocks:grate"}, {["x"] = 1, ["y"] = 4, ["param1"] = 79, ["z"] = 14, ["name"] = "building_blocks:grate"}, {["x"] = 1, ["y"] = 4, ["param1"] = 63, ["z"] = 15, ["name"] = "building_blocks:grate"}, {["x"] = 1, ["y"] = 4, ["param1"] = 78, ["z"] = 16, ["name"] = "building_blocks:grate"}, {["x"] = 1, ["param2"] = 1, ["y"] = 5, ["param1"] = 222, ["z"] = 0, ["name"] = "homedecor:glowlight_quarter_on"}, {["x"] = 1, ["param2"] = 1, ["y"] = 5, ["param1"] = 94, ["z"] = 16, ["name"] = "homedecor:glowlight_quarter_off"}, {["x"] = 2, ["y"] = 0, ["z"] = 0, ["name"] = "default:brick"}, {["x"] = 2, ["y"] = 0, ["z"] = 1, ["name"] = "farming:soil_wet"}, {["x"] = 2, ["y"] = 0, ["z"] = 2, ["name"] = "farming:soil_wet"}, {["x"] = 2, ["y"] = 0, ["z"] = 3, ["name"] = "farming:soil_wet"}, {["x"] = 2, ["y"] = 0, ["z"] = 4, ["name"] = "farming:soil_wet"}, {["x"] = 2, ["y"] = 0, ["z"] = 5, ["name"] = "farming:soil_wet"}, {["x"] = 2, ["y"] = 0, ["z"] = 6, ["name"] = "farming:soil_wet"}, {["x"] = 2, ["y"] = 0, ["z"] = 7, ["name"] = "farming:soil_wet"}, {["x"] = 2, ["y"] = 0, ["z"] = 8, ["name"] = "default:wood"}, {["x"] = 2, ["y"] = 0, ["z"] = 9, ["name"] = "farming:soil_wet"}, {["x"] = 2, ["y"] = 0, ["z"] = 10, ["name"] = "farming:soil_wet"}, {["x"] = 2, ["y"] = 0, ["z"] = 11, ["name"] = "farming:soil_wet"}, {["x"] = 2, ["y"] = 0, ["z"] = 12, ["name"] = "farming:soil_wet"}, {["x"] = 2, ["y"] = 0, ["z"] = 13, ["name"] = "farming:soil_wet"}, {["x"] = 2, ["y"] = 0, ["z"] = 14, ["name"] = "farming:soil_wet"}, {["x"] = 2, ["y"] = 0, ["z"] = 15, ["name"] = "farming:soil_wet"}, {["x"] = 2, ["y"] = 0, ["z"] = 16, ["name"] = "default:brick"}, {["x"] = 2, ["y"] = 1, ["param1"] = 143, ["z"] = 0, ["name"] = "default:obsidian_glass"}, {["x"] = 2, ["y"] = 1, ["param1"] = 143, ["z"] = 1, ["name"] = "farming:carrot_8"}, {["x"] = 2, ["y"] = 1, ["param1"] = 143, ["z"] = 2, ["name"] = "farming:corn_8"}, {["x"] = 2, ["y"] = 1, ["param1"] = 159, ["z"] = 3, ["name"] = "farming:rhubarb_3"}, {["x"] = 2, ["y"] = 1, ["param1"] = 175, ["z"] = 4, ["name"] = "farming:beanpole_5"}, {["x"] = 2, ["y"] = 1, ["param1"] = 190, ["z"] = 5, ["name"] = "farming:cucumber_4"}, {["x"] = 2, ["y"] = 1, ["param1"] = 205, ["z"] = 6, ["name"] = "farming:pumpkin_8"}, {["x"] = 2, ["y"] = 1, ["param1"] = 221, ["z"] = 7, ["name"] = "farming:potato_4"}, {["x"] = 2, ["param2"] = 1, ["y"] = 1, ["param1"] = 238, ["z"] = 8, ["name"] = "homedecor:glowlight_half_on"}, {["x"] = 2, ["param2"] = 1, ["y"] = 1, ["param1"] = 222, ["z"] = 9, ["name"] = "farming:cucumber_4"}, {["x"] = 2, ["y"] = 1, ["param1"] = 207, ["z"] = 10, ["name"] = "farming:pepper_5"}, {["x"] = 2, ["y"] = 1, ["param1"] = 191, ["z"] = 11, ["name"] = "farming:melon_8"}, {["x"] = 2, ["y"] = 1, ["param1"] = 175, ["z"] = 12, ["name"] = "farming:grapes_8"}, {["x"] = 2, ["y"] = 1, ["param1"] = 159, ["z"] = 13, ["name"] = "farming:cotton_8"}, {["x"] = 2, ["y"] = 1, ["param1"] = 143, ["z"] = 14, ["name"] = "farming:wheat_8"}, {["x"] = 2, ["y"] = 1, ["param1"] = 127, ["z"] = 15, ["name"] = "farming:barley_7"}, {["x"] = 2, ["y"] = 1, ["param1"] = 111, ["z"] = 16, ["name"] = "default:obsidian_glass"}, {["x"] = 2, ["y"] = 2, ["param1"] = 159, ["z"] = 0, ["name"] = "default:obsidian_glass"}, {["x"] = 2, ["y"] = 2, ["param1"] = 95, ["z"] = 16, ["name"] = "default:obsidian_glass"}, {["x"] = 2, ["y"] = 3, ["param1"] = 175, ["z"] = 0, ["name"] = "default:obsidian_glass"}, {["x"] = 2, ["y"] = 3, ["param1"] = 79, ["z"] = 16, ["name"] = "default:obsidian_glass"}, {["x"] = 2, ["y"] = 4, ["param1"] = 191, ["z"] = 0, ["name"] = "building_blocks:grate"}, {["x"] = 2, ["y"] = 4, ["param1"] = 175, ["z"] = 1, ["name"] = "default:obsidian_glass"}, {["x"] = 2, ["y"] = 4, ["param1"] = 159, ["z"] = 2, ["name"] = "default:obsidian_glass"}, {["x"] = 2, ["y"] = 4, ["param1"] = 143, ["z"] = 3, ["name"] = "default:obsidian_glass"}, {["x"] = 2, ["y"] = 4, ["param1"] = 127, ["z"] = 4, ["name"] = "default:obsidian_glass"}, {["x"] = 2, ["y"] = 4, ["param1"] = 143, ["z"] = 5, ["name"] = "default:obsidian_glass"}, {["x"] = 2, ["y"] = 4, ["param1"] = 158, ["z"] = 6, ["name"] = "default:obsidian_glass"}, {["x"] = 2, ["y"] = 4, ["param1"] = 174, ["z"] = 7, ["name"] = "default:obsidian_glass"}, {["x"] = 2, ["y"] = 4, ["param1"] = 191, ["z"] = 8, ["name"] = "building_blocks:grate"}, {["x"] = 2, ["y"] = 4, ["param1"] = 175, ["z"] = 9, ["name"] = "default:obsidian_glass"}, {["x"] = 2, ["y"] = 4, ["param1"] = 159, ["z"] = 10, ["name"] = "default:obsidian_glass"}, {["x"] = 2, ["y"] = 4, ["param1"] = 143, ["z"] = 11, ["name"] = "default:obsidian_glass"}, {["x"] = 2, ["y"] = 4, ["param1"] = 127, ["z"] = 12, ["name"] = "default:obsidian_glass"}, {["x"] = 2, ["y"] = 4, ["param1"] = 111, ["z"] = 13, ["name"] = "default:obsidian_glass"}, {["x"] = 2, ["y"] = 4, ["param1"] = 95, ["z"] = 14, ["name"] = "default:obsidian_glass"}, {["x"] = 2, ["y"] = 4, ["param1"] = 79, ["z"] = 15, ["name"] = "default:obsidian_glass"}, {["x"] = 2, ["y"] = 4, ["param1"] = 95, ["z"] = 16, ["name"] = "building_blocks:grate"}, {["x"] = 3, ["y"] = 0, ["z"] = 0, ["name"] = "default:brick"}, {["x"] = 3, ["y"] = 0, ["z"] = 1, ["name"] = "farming:soil_wet"}, {["x"] = 3, ["y"] = 0, ["z"] = 2, ["name"] = "farming:soil_wet"}, {["x"] = 3, ["y"] = 0, ["z"] = 3, ["name"] = "farming:soil_wet"}, {["x"] = 3, ["y"] = 0, ["z"] = 4, ["name"] = "farming:soil_wet"}, {["x"] = 3, ["y"] = 0, ["z"] = 5, ["name"] = "farming:soil_wet"}, {["x"] = 3, ["y"] = 0, ["z"] = 6, ["name"] = "farming:soil_wet"}, {["x"] = 3, ["y"] = 0, ["z"] = 7, ["name"] = "farming:soil_wet"}, {["x"] = 3, ["y"] = 0, ["z"] = 8, ["name"] = "default:wood"}, {["x"] = 3, ["y"] = 0, ["z"] = 9, ["name"] = "farming:soil_wet"}, {["x"] = 3, ["y"] = 0, ["z"] = 10, ["name"] = "farming:soil_wet"}, {["x"] = 3, ["y"] = 0, ["z"] = 11, ["name"] = "farming:soil_wet"}, {["x"] = 3, ["y"] = 0, ["z"] = 12, ["name"] = "farming:soil_wet"}, {["x"] = 3, ["y"] = 0, ["z"] = 13, ["name"] = "farming:soil_wet"}, {["x"] = 3, ["y"] = 0, ["z"] = 14, ["name"] = "farming:soil_wet"}, {["x"] = 3, ["y"] = 0, ["z"] = 15, ["name"] = "farming:soil_wet"}, {["x"] = 3, ["y"] = 0, ["z"] = 16, ["name"] = "default:brick"}, {["x"] = 3, ["y"] = 1, ["param1"] = 127, ["z"] = 0, ["name"] = "default:obsidian_glass"}, {["x"] = 3, ["y"] = 1, ["param1"] = 127, ["z"] = 1, ["name"] = "farming:carrot_8"}, {["x"] = 3, ["y"] = 1, ["param1"] = 127, ["z"] = 2, ["name"] = "farming:corn_8"}, {["x"] = 3, ["y"] = 1, ["param1"] = 143, ["z"] = 3, ["name"] = "farming:rhubarb_3"}, {["x"] = 3, ["y"] = 1, ["param1"] = 159, ["z"] = 4, ["name"] = "farming:beanpole_5"}, {["x"] = 3, ["y"] = 1, ["param1"] = 174, ["z"] = 5, ["name"] = "farming:cucumber_4"}, {["x"] = 3, ["y"] = 1, ["param1"] = 189, ["z"] = 6, ["name"] = "farming:pumpkin_8"}, {["x"] = 3, ["y"] = 1, ["param1"] = 206, ["z"] = 7, ["name"] = "farming:potato_4"}, {["x"] = 3, ["param2"] = 1, ["y"] = 1, ["param1"] = 207, ["z"] = 9, ["name"] = "farming:corn_8"}, {["x"] = 3, ["param2"] = 3, ["y"] = 1, ["param1"] = 191, ["z"] = 10, ["name"] = "farming:garlic_5"}, {["x"] = 3, ["y"] = 1, ["param1"] = 175, ["z"] = 11, ["name"] = "farming:melon_8"}, {["x"] = 3, ["y"] = 1, ["param1"] = 159, ["z"] = 12, ["name"] = "farming:grapes_8"}, {["x"] = 3, ["y"] = 1, ["param1"] = 143, ["z"] = 13, ["name"] = "farming:cotton_8"}, {["x"] = 3, ["y"] = 1, ["param1"] = 127, ["z"] = 14, ["name"] = "farming:wheat_8"}, {["x"] = 3, ["y"] = 1, ["param1"] = 111, ["z"] = 15, ["name"] = "farming:barley_7"}, {["x"] = 3, ["y"] = 1, ["param1"] = 95, ["z"] = 16, ["name"] = "default:obsidian_glass"}, {["x"] = 3, ["y"] = 2, ["param1"] = 143, ["z"] = 0, ["name"] = "default:obsidian_glass"}, {["x"] = 3, ["y"] = 2, ["param1"] = 79, ["z"] = 16, ["name"] = "default:obsidian_glass"}, {["x"] = 3, ["y"] = 3, ["param1"] = 159, ["z"] = 0, ["name"] = "default:obsidian_glass"}, {["x"] = 3, ["y"] = 3, ["param1"] = 95, ["z"] = 16, ["name"] = "default:obsidian_glass"}, {["x"] = 3, ["y"] = 4, ["param1"] = 175, ["z"] = 0, ["name"] = "building_blocks:grate"}, {["x"] = 3, ["y"] = 4, ["param1"] = 159, ["z"] = 1, ["name"] = "default:obsidian_glass"}, {["x"] = 3, ["y"] = 4, ["param1"] = 143, ["z"] = 2, ["name"] = "default:obsidian_glass"}, {["x"] = 3, ["y"] = 4, ["param1"] = 127, ["z"] = 3, ["name"] = "default:obsidian_glass"}, {["x"] = 3, ["y"] = 4, ["param1"] = 111, ["z"] = 4, ["name"] = "default:obsidian_glass"}, {["x"] = 3, ["y"] = 4, ["param1"] = 127, ["z"] = 5, ["name"] = "default:obsidian_glass"}, {["x"] = 3, ["y"] = 4, ["param1"] = 142, ["z"] = 6, ["name"] = "default:obsidian_glass"}, {["x"] = 3, ["y"] = 4, ["param1"] = 158, ["z"] = 7, ["name"] = "default:obsidian_glass"}, {["x"] = 3, ["y"] = 4, ["param1"] = 175, ["z"] = 8, ["name"] = "building_blocks:grate"}, {["x"] = 3, ["y"] = 4, ["param1"] = 159, ["z"] = 9, ["name"] = "default:obsidian_glass"}, {["x"] = 3, ["y"] = 4, ["param1"] = 143, ["z"] = 10, ["name"] = "default:obsidian_glass"}, {["x"] = 3, ["y"] = 4, ["param1"] = 127, ["z"] = 11, ["name"] = "default:obsidian_glass"}, {["x"] = 3, ["y"] = 4, ["param1"] = 111, ["z"] = 12, ["name"] = "default:obsidian_glass"}, {["x"] = 3, ["y"] = 4, ["param1"] = 95, ["z"] = 13, ["name"] = "default:obsidian_glass"}, {["x"] = 3, ["y"] = 4, ["param1"] = 79, ["z"] = 14, ["name"] = "default:obsidian_glass"}, {["x"] = 3, ["y"] = 4, ["param1"] = 95, ["z"] = 15, ["name"] = "default:obsidian_glass"}, {["x"] = 3, ["y"] = 4, ["param1"] = 111, ["z"] = 16, ["name"] = "building_blocks:grate"}, {["x"] = 4, ["y"] = 0, ["z"] = 0, ["name"] = "default:brick"}, {["x"] = 4, ["y"] = 0, ["z"] = 1, ["name"] = "farming:soil_wet"}, {["x"] = 4, ["y"] = 0, ["z"] = 2, ["name"] = "farming:soil_wet"}, {["x"] = 4, ["y"] = 0, ["z"] = 3, ["name"] = "farming:soil_wet"}, {["x"] = 4, ["y"] = 0, ["z"] = 4, ["name"] = "farming:soil_wet"}, {["x"] = 4, ["y"] = 0, ["z"] = 5, ["name"] = "farming:soil_wet"}, {["x"] = 4, ["y"] = 0, ["z"] = 6, ["name"] = "farming:soil_wet"}, {["x"] = 4, ["y"] = 0, ["z"] = 7, ["name"] = "farming:soil_wet"}, {["x"] = 4, ["y"] = 0, ["z"] = 8, ["name"] = "default:wood"}, {["x"] = 4, ["y"] = 0, ["z"] = 9, ["name"] = "farming:soil_wet"}, {["x"] = 4, ["y"] = 0, ["z"] = 10, ["name"] = "farming:soil_wet"}, {["x"] = 4, ["y"] = 0, ["z"] = 11, ["name"] = "farming:soil_wet"}, {["x"] = 4, ["y"] = 0, ["z"] = 12, ["name"] = "farming:soil_wet"}, {["x"] = 4, ["y"] = 0, ["z"] = 13, ["name"] = "farming:soil_wet"}, {["x"] = 4, ["y"] = 0, ["z"] = 14, ["name"] = "farming:soil_wet"}, {["x"] = 4, ["y"] = 0, ["z"] = 15, ["name"] = "farming:soil_wet"}, {["x"] = 4, ["y"] = 0, ["z"] = 16, ["name"] = "default:brick"}, {["x"] = 4, ["y"] = 1, ["param1"] = 111, ["z"] = 0, ["name"] = "default:obsidian_glass"}, {["x"] = 4, ["y"] = 1, ["param1"] = 111, ["z"] = 1, ["name"] = "farming:carrot_8"}, {["x"] = 4, ["y"] = 1, ["param1"] = 111, ["z"] = 2, ["name"] = "farming:corn_8"}, {["x"] = 4, ["y"] = 1, ["param1"] = 127, ["z"] = 3, ["name"] = "farming:rhubarb_3"}, {["x"] = 4, ["y"] = 1, ["param1"] = 143, ["z"] = 4, ["name"] = "farming:beanpole_5"}, {["x"] = 4, ["y"] = 1, ["param1"] = 174, ["z"] = 6, ["name"] = "farming:pumpkin_8"}, {["x"] = 4, ["y"] = 1, ["param1"] = 190, ["z"] = 7, ["name"] = "farming:potato_4"}, {["x"] = 4, ["param2"] = 1, ["y"] = 1, ["param1"] = 191, ["z"] = 9, ["name"] = "farming:rhubarb_3"}, {["x"] = 4, ["param2"] = 1, ["y"] = 1, ["param1"] = 175, ["z"] = 10, ["name"] = "farming:tomato_8"}, {["x"] = 4, ["y"] = 1, ["param1"] = 159, ["z"] = 11, ["name"] = "farming:melon_8"}, {["x"] = 4, ["y"] = 1, ["param1"] = 143, ["z"] = 12, ["name"] = "farming:grapes_8"}, {["x"] = 4, ["y"] = 1, ["param1"] = 127, ["z"] = 13, ["name"] = "farming:cotton_8"}, {["x"] = 4, ["y"] = 1, ["param1"] = 111, ["z"] = 14, ["name"] = "farming:wheat_8"}, {["x"] = 4, ["y"] = 1, ["param1"] = 95, ["z"] = 15, ["name"] = "farming:barley_7"}, {["x"] = 4, ["y"] = 1, ["param1"] = 79, ["z"] = 16, ["name"] = "default:obsidian_glass"}, {["x"] = 4, ["y"] = 2, ["param1"] = 127, ["z"] = 0, ["name"] = "default:obsidian_glass"}, {["x"] = 4, ["y"] = 2, ["param1"] = 95, ["z"] = 16, ["name"] = "default:obsidian_glass"}, {["x"] = 4, ["y"] = 3, ["param1"] = 143, ["z"] = 0, ["name"] = "default:obsidian_glass"}, {["x"] = 4, ["y"] = 3, ["param1"] = 111, ["z"] = 16, ["name"] = "default:obsidian_glass"}, {["x"] = 4, ["y"] = 4, ["param1"] = 159, ["z"] = 0, ["name"] = "building_blocks:grate"}, {["x"] = 4, ["y"] = 4, ["param1"] = 143, ["z"] = 1, ["name"] = "default:obsidian_glass"}, {["x"] = 4, ["y"] = 4, ["param1"] = 127, ["z"] = 2, ["name"] = "default:obsidian_glass"}, {["x"] = 4, ["y"] = 4, ["param1"] = 111, ["z"] = 3, ["name"] = "default:obsidian_glass"}, {["x"] = 4, ["y"] = 4, ["param1"] = 95, ["z"] = 4, ["name"] = "default:obsidian_glass"}, {["x"] = 4, ["y"] = 4, ["param1"] = 111, ["z"] = 5, ["name"] = "default:obsidian_glass"}, {["x"] = 4, ["y"] = 4, ["param1"] = 126, ["z"] = 6, ["name"] = "default:obsidian_glass"}, {["x"] = 4, ["y"] = 4, ["param1"] = 142, ["z"] = 7, ["name"] = "default:obsidian_glass"}, {["x"] = 4, ["y"] = 4, ["param1"] = 159, ["z"] = 8, ["name"] = "building_blocks:grate"}, {["x"] = 4, ["y"] = 4, ["param1"] = 143, ["z"] = 9, ["name"] = "default:obsidian_glass"}, {["x"] = 4, ["y"] = 4, ["param1"] = 127, ["z"] = 10, ["name"] = "default:obsidian_glass"}, {["x"] = 4, ["y"] = 4, ["param1"] = 111, ["z"] = 11, ["name"] = "default:obsidian_glass"}, {["x"] = 4, ["y"] = 4, ["param1"] = 95, ["z"] = 12, ["name"] = "default:obsidian_glass"}, {["x"] = 4, ["y"] = 4, ["param1"] = 79, ["z"] = 13, ["name"] = "default:obsidian_glass"}, {["x"] = 4, ["y"] = 4, ["param1"] = 95, ["z"] = 14, ["name"] = "default:obsidian_glass"}, {["x"] = 4, ["y"] = 4, ["param1"] = 111, ["z"] = 15, ["name"] = "default:obsidian_glass"}, {["x"] = 4, ["y"] = 4, ["param1"] = 127, ["z"] = 16, ["name"] = "building_blocks:grate"}, {["x"] = 5, ["y"] = 0, ["z"] = 0, ["name"] = "default:brick"}, {["x"] = 5, ["y"] = 0, ["z"] = 1, ["name"] = "farming:soil_wet"}, {["x"] = 5, ["y"] = 0, ["z"] = 2, ["name"] = "farming:soil_wet"}, {["x"] = 5, ["y"] = 0, ["z"] = 3, ["name"] = "farming:soil_wet"}, {["x"] = 5, ["y"] = 0, ["param1"] = 110, ["z"] = 4, ["name"] = "default:water_source"}, {["x"] = 5, ["y"] = 0, ["z"] = 5, ["name"] = "farming:soil_wet"}, {["x"] = 5, ["y"] = 0, ["z"] = 6, ["name"] = "farming:soil_wet"}, {["x"] = 5, ["y"] = 0, ["z"] = 7, ["name"] = "farming:soil_wet"}, {["x"] = 5, ["y"] = 0, ["z"] = 8, ["name"] = "default:wood"}, {["x"] = 5, ["y"] = 0, ["z"] = 9, ["name"] = "farming:soil_wet"}, {["x"] = 5, ["y"] = 0, ["z"] = 10, ["name"] = "farming:soil_wet"}, {["x"] = 5, ["y"] = 0, ["z"] = 11, ["name"] = "farming:soil_wet"}, {["x"] = 5, ["y"] = 0, ["param1"] = 110, ["z"] = 12, ["name"] = "default:water_source"}, {["x"] = 5, ["y"] = 0, ["z"] = 13, ["name"] = "farming:soil_wet"}, {["x"] = 5, ["y"] = 0, ["z"] = 14, ["name"] = "farming:soil_wet"}, {["x"] = 5, ["y"] = 0, ["z"] = 15, ["name"] = "farming:soil_wet"}, {["x"] = 5, ["y"] = 0, ["z"] = 16, ["name"] = "default:brick"}, {["x"] = 5, ["y"] = 1, ["param1"] = 95, ["z"] = 0, ["name"] = "default:obsidian_glass"}, {["x"] = 5, ["y"] = 1, ["param1"] = 95, ["z"] = 1, ["name"] = "farming:carrot_8"}, {["x"] = 5, ["y"] = 1, ["param1"] = 95, ["z"] = 2, ["name"] = "farming:corn_8"}, {["x"] = 5, ["y"] = 1, ["param1"] = 111, ["z"] = 3, ["name"] = "farming:rhubarb_3"}, {["x"] = 5, ["y"] = 1, ["param1"] = 158, ["z"] = 6, ["name"] = "farming:pumpkin_8"}, {["x"] = 5, ["y"] = 1, ["param1"] = 174, ["z"] = 7, ["name"] = "farming:potato_4"}, {["x"] = 5, ["param2"] = 1, ["y"] = 1, ["param1"] = 175, ["z"] = 9, ["name"] = "farming:carrot_8"}, {["x"] = 5, ["param2"] = 1, ["y"] = 1, ["param1"] = 159, ["z"] = 10, ["name"] = "farming:pepper_5"}, {["x"] = 5, ["y"] = 1, ["param1"] = 143, ["z"] = 11, ["name"] = "farming:melon_8"}, {["x"] = 5, ["y"] = 1, ["param1"] = 111, ["z"] = 13, ["name"] = "farming:cotton_8"}, {["x"] = 5, ["y"] = 1, ["param1"] = 95, ["z"] = 14, ["name"] = "farming:wheat_8"}, {["x"] = 5, ["y"] = 1, ["param1"] = 79, ["z"] = 15, ["name"] = "farming:barley_7"}, {["x"] = 5, ["y"] = 1, ["param1"] = 95, ["z"] = 16, ["name"] = "default:obsidian_glass"}, {["x"] = 5, ["y"] = 2, ["param1"] = 111, ["z"] = 0, ["name"] = "default:obsidian_glass"}, {["x"] = 5, ["y"] = 2, ["param1"] = 111, ["z"] = 16, ["name"] = "default:obsidian_glass"}, {["x"] = 5, ["y"] = 3, ["param1"] = 127, ["z"] = 0, ["name"] = "default:obsidian_glass"}, {["x"] = 5, ["y"] = 3, ["param1"] = 127, ["z"] = 16, ["name"] = "default:obsidian_glass"}, {["x"] = 5, ["y"] = 4, ["param1"] = 143, ["z"] = 0, ["name"] = "building_blocks:grate"}, {["x"] = 5, ["y"] = 4, ["param1"] = 127, ["z"] = 1, ["name"] = "default:obsidian_glass"}, {["x"] = 5, ["y"] = 4, ["param1"] = 111, ["z"] = 2, ["name"] = "default:obsidian_glass"}, {["x"] = 5, ["y"] = 4, ["param1"] = 95, ["z"] = 3, ["name"] = "default:obsidian_glass"}, {["x"] = 5, ["y"] = 4, ["param1"] = 79, ["z"] = 4, ["name"] = "default:obsidian_glass"}, {["x"] = 5, ["y"] = 4, ["param1"] = 95, ["z"] = 5, ["name"] = "default:obsidian_glass"}, {["x"] = 5, ["y"] = 4, ["param1"] = 110, ["z"] = 6, ["name"] = "default:obsidian_glass"}, {["x"] = 5, ["y"] = 4, ["param1"] = 126, ["z"] = 7, ["name"] = "default:obsidian_glass"}, {["x"] = 5, ["y"] = 4, ["param1"] = 143, ["z"] = 8, ["name"] = "building_blocks:grate"}, {["x"] = 5, ["y"] = 4, ["param1"] = 127, ["z"] = 9, ["name"] = "default:obsidian_glass"}, {["x"] = 5, ["y"] = 4, ["param1"] = 111, ["z"] = 10, ["name"] = "default:obsidian_glass"}, {["x"] = 5, ["y"] = 4, ["param1"] = 95, ["z"] = 11, ["name"] = "default:obsidian_glass"}, {["x"] = 5, ["y"] = 4, ["param1"] = 79, ["z"] = 12, ["name"] = "default:obsidian_glass"}, {["x"] = 5, ["y"] = 4, ["param1"] = 95, ["z"] = 13, ["name"] = "default:obsidian_glass"}, {["x"] = 5, ["y"] = 4, ["param1"] = 111, ["z"] = 14, ["name"] = "default:obsidian_glass"}, {["x"] = 5, ["y"] = 4, ["param1"] = 127, ["z"] = 15, ["name"] = "default:obsidian_glass"}, {["x"] = 5, ["y"] = 4, ["param1"] = 143, ["z"] = 16, ["name"] = "building_blocks:grate"}, {["x"] = 6, ["y"] = 0, ["z"] = 0, ["name"] = "default:brick"}, {["x"] = 6, ["y"] = 0, ["z"] = 1, ["name"] = "farming:soil_wet"}, {["x"] = 6, ["y"] = 0, ["z"] = 2, ["name"] = "farming:soil_wet"}, {["x"] = 6, ["y"] = 0, ["z"] = 3, ["name"] = "farming:soil_wet"}, {["x"] = 6, ["y"] = 0, ["z"] = 4, ["name"] = "farming:soil_wet"}, {["x"] = 6, ["y"] = 0, ["z"] = 5, ["name"] = "farming:soil_wet"}, {["x"] = 6, ["y"] = 0, ["z"] = 6, ["name"] = "farming:soil_wet"}, {["x"] = 6, ["y"] = 0, ["z"] = 7, ["name"] = "farming:soil_wet"}, {["x"] = 6, ["y"] = 0, ["z"] = 8, ["name"] = "default:wood"}, {["x"] = 6, ["y"] = 0, ["z"] = 9, ["name"] = "farming:soil_wet"}, {["x"] = 6, ["y"] = 0, ["z"] = 10, ["name"] = "farming:soil_wet"}, {["x"] = 6, ["y"] = 0, ["z"] = 11, ["name"] = "farming:soil_wet"}, {["x"] = 6, ["y"] = 0, ["z"] = 12, ["name"] = "farming:soil_wet"}, {["x"] = 6, ["y"] = 0, ["z"] = 13, ["name"] = "farming:soil_wet"}, {["x"] = 6, ["y"] = 0, ["z"] = 14, ["name"] = "farming:soil_wet"}, {["x"] = 6, ["y"] = 0, ["z"] = 15, ["name"] = "farming:soil_wet"}, {["x"] = 6, ["y"] = 0, ["z"] = 16, ["name"] = "default:brick"}, {["x"] = 6, ["y"] = 1, ["param1"] = 111, ["z"] = 0, ["name"] = "default:obsidian_glass"}, {["x"] = 6, ["y"] = 1, ["param1"] = 95, ["z"] = 1, ["name"] = "farming:carrot_8"}, {["x"] = 6, ["y"] = 1, ["param1"] = 111, ["z"] = 2, ["name"] = "farming:corn_8"}, {["x"] = 6, ["y"] = 1, ["param1"] = 127, ["z"] = 3, ["name"] = "farming:rhubarb_3"}, {["x"] = 6, ["y"] = 1, ["param1"] = 174, ["z"] = 6, ["name"] = "farming:pumpkin_8"}, {["x"] = 6, ["y"] = 1, ["param1"] = 190, ["z"] = 7, ["name"] = "farming:potato_4"}, {["x"] = 6, ["y"] = 1, ["param1"] = 191, ["z"] = 9, ["name"] = "farming:beanpole"}, {["x"] = 6, ["param2"] = 1, ["y"] = 1, ["param1"] = 175, ["z"] = 10, ["name"] = "farming:potato_4"}, {["x"] = 6, ["y"] = 1, ["param1"] = 159, ["z"] = 11, ["name"] = "farming:pepper_5"}, {["x"] = 6, ["y"] = 1, ["param1"] = 143, ["z"] = 12, ["name"] = "farming:grapes_8"}, {["x"] = 6, ["y"] = 1, ["param1"] = 127, ["z"] = 13, ["name"] = "farming:cotton_8"}, {["x"] = 6, ["y"] = 1, ["param1"] = 111, ["z"] = 14, ["name"] = "farming:wheat_8"}, {["x"] = 6, ["y"] = 1, ["param1"] = 95, ["z"] = 15, ["name"] = "farming:barley_7"}, {["x"] = 6, ["y"] = 1, ["param1"] = 111, ["z"] = 16, ["name"] = "default:obsidian_glass"}, {["x"] = 6, ["y"] = 2, ["param1"] = 127, ["z"] = 0, ["name"] = "default:obsidian_glass"}, {["x"] = 6, ["y"] = 2, ["param1"] = 127, ["z"] = 16, ["name"] = "default:obsidian_glass"}, {["x"] = 6, ["y"] = 3, ["param1"] = 143, ["z"] = 0, ["name"] = "default:obsidian_glass"}, {["x"] = 6, ["y"] = 3, ["param1"] = 143, ["z"] = 16, ["name"] = "default:obsidian_glass"}, {["x"] = 6, ["y"] = 4, ["param1"] = 159, ["z"] = 0, ["name"] = "building_blocks:grate"}, {["x"] = 6, ["y"] = 4, ["param1"] = 143, ["z"] = 1, ["name"] = "default:obsidian_glass"}, {["x"] = 6, ["y"] = 4, ["param1"] = 127, ["z"] = 2, ["name"] = "default:obsidian_glass"}, {["x"] = 6, ["y"] = 4, ["param1"] = 111, ["z"] = 3, ["name"] = "default:obsidian_glass"}, {["x"] = 6, ["y"] = 4, ["param1"] = 95, ["z"] = 4, ["name"] = "default:obsidian_glass"}, {["x"] = 6, ["y"] = 4, ["param1"] = 111, ["z"] = 5, ["name"] = "default:obsidian_glass"}, {["x"] = 6, ["y"] = 4, ["param1"] = 126, ["z"] = 6, ["name"] = "default:obsidian_glass"}, {["x"] = 6, ["y"] = 4, ["param1"] = 142, ["z"] = 7, ["name"] = "default:obsidian_glass"}, {["x"] = 6, ["y"] = 4, ["param1"] = 159, ["z"] = 8, ["name"] = "building_blocks:grate"}, {["x"] = 6, ["y"] = 4, ["param1"] = 143, ["z"] = 9, ["name"] = "default:obsidian_glass"}, {["x"] = 6, ["y"] = 4, ["param1"] = 127, ["z"] = 10, ["name"] = "default:obsidian_glass"}, {["x"] = 6, ["y"] = 4, ["param1"] = 111, ["z"] = 11, ["name"] = "default:obsidian_glass"}, {["x"] = 6, ["y"] = 4, ["param1"] = 95, ["z"] = 12, ["name"] = "default:obsidian_glass"}, {["x"] = 6, ["y"] = 4, ["param1"] = 111, ["z"] = 13, ["name"] = "default:obsidian_glass"}, {["x"] = 6, ["y"] = 4, ["param1"] = 127, ["z"] = 14, ["name"] = "default:obsidian_glass"}, {["x"] = 6, ["y"] = 4, ["param1"] = 143, ["z"] = 15, ["name"] = "default:obsidian_glass"}, {["x"] = 6, ["y"] = 4, ["param1"] = 159, ["z"] = 16, ["name"] = "building_blocks:grate"}, {["x"] = 7, ["y"] = 0, ["z"] = 0, ["name"] = "default:brick"}, {["x"] = 7, ["y"] = 0, ["z"] = 1, ["name"] = "farming:soil_wet"}, {["x"] = 7, ["y"] = 0, ["z"] = 2, ["name"] = "farming:soil_wet"}, {["x"] = 7, ["y"] = 0, ["z"] = 3, ["name"] = "farming:soil_wet"}, {["x"] = 7, ["y"] = 0, ["z"] = 4, ["name"] = "farming:soil_wet"}, {["x"] = 7, ["y"] = 0, ["z"] = 5, ["name"] = "farming:soil_wet"}, {["x"] = 7, ["y"] = 0, ["z"] = 6, ["name"] = "farming:soil_wet"}, {["x"] = 7, ["y"] = 0, ["z"] = 7, ["name"] = "farming:soil_wet"}, {["x"] = 7, ["y"] = 0, ["z"] = 8, ["name"] = "default:wood"}, {["x"] = 7, ["y"] = 0, ["z"] = 9, ["name"] = "farming:soil_wet"}, {["x"] = 7, ["y"] = 0, ["z"] = 10, ["name"] = "farming:soil_wet"}, {["x"] = 7, ["y"] = 0, ["z"] = 11, ["name"] = "farming:soil_wet"}, {["x"] = 7, ["y"] = 0, ["z"] = 12, ["name"] = "farming:soil_wet"}, {["x"] = 7, ["y"] = 0, ["z"] = 13, ["name"] = "farming:soil_wet"}, {["x"] = 7, ["y"] = 0, ["z"] = 14, ["name"] = "farming:soil_wet"}, {["x"] = 7, ["y"] = 0, ["z"] = 15, ["name"] = "farming:soil_wet"}, {["x"] = 7, ["y"] = 0, ["z"] = 16, ["name"] = "default:brick"}, {["x"] = 7, ["y"] = 1, ["param1"] = 126, ["z"] = 0, ["name"] = "default:obsidian_glass"}, {["x"] = 7, ["y"] = 1, ["param1"] = 110, ["z"] = 1, ["name"] = "farming:carrot_8"}, {["x"] = 7, ["y"] = 1, ["param1"] = 126, ["z"] = 2, ["name"] = "farming:corn_8"}, {["x"] = 7, ["y"] = 1, ["param1"] = 142, ["z"] = 3, ["name"] = "farming:rhubarb_3"}, {["x"] = 7, ["y"] = 1, ["param1"] = 189, ["z"] = 6, ["name"] = "farming:pumpkin_8"}, {["x"] = 7, ["y"] = 1, ["param1"] = 205, ["z"] = 7, ["name"] = "farming:potato_4"}, {["x"] = 7, ["y"] = 1, ["param1"] = 206, ["z"] = 9, ["name"] = "farming:beanpole"}, {["x"] = 7, ["param2"] = 1, ["y"] = 1, ["param1"] = 190, ["z"] = 10, ["name"] = "farming:coffee_5"}, {["x"] = 7, ["y"] = 1, ["param1"] = 174, ["z"] = 11, ["name"] = "farming:melon_8"}, {["x"] = 7, ["y"] = 1, ["param1"] = 158, ["z"] = 12, ["name"] = "farming:grapes_8"}, {["x"] = 7, ["y"] = 1, ["param1"] = 142, ["z"] = 13, ["name"] = "farming:cotton_8"}, {["x"] = 7, ["y"] = 1, ["param1"] = 126, ["z"] = 14, ["name"] = "farming:wheat_8"}, {["x"] = 7, ["y"] = 1, ["param1"] = 110, ["z"] = 15, ["name"] = "farming:barley_7"}, {["x"] = 7, ["y"] = 1, ["param1"] = 126, ["z"] = 16, ["name"] = "default:obsidian_glass"}, {["x"] = 7, ["y"] = 2, ["param1"] = 142, ["z"] = 0, ["name"] = "default:obsidian_glass"}, {["x"] = 7, ["y"] = 2, ["param1"] = 142, ["z"] = 16, ["name"] = "default:obsidian_glass"}, {["x"] = 7, ["y"] = 3, ["param1"] = 158, ["z"] = 0, ["name"] = "default:obsidian_glass"}, {["x"] = 7, ["y"] = 3, ["param1"] = 158, ["z"] = 16, ["name"] = "default:obsidian_glass"}, {["x"] = 7, ["y"] = 4, ["param1"] = 174, ["z"] = 0, ["name"] = "building_blocks:grate"}, {["x"] = 7, ["y"] = 4, ["param1"] = 158, ["z"] = 1, ["name"] = "default:obsidian_glass"}, {["x"] = 7, ["y"] = 4, ["param1"] = 142, ["z"] = 2, ["name"] = "default:obsidian_glass"}, {["x"] = 7, ["y"] = 4, ["param1"] = 126, ["z"] = 3, ["name"] = "default:obsidian_glass"}, {["x"] = 7, ["y"] = 4, ["param1"] = 110, ["z"] = 4, ["name"] = "default:obsidian_glass"}, {["x"] = 7, ["y"] = 4, ["param1"] = 126, ["z"] = 5, ["name"] = "default:obsidian_glass"}, {["x"] = 7, ["y"] = 4, ["param1"] = 141, ["z"] = 6, ["name"] = "default:obsidian_glass"}, {["x"] = 7, ["y"] = 4, ["param1"] = 157, ["z"] = 7, ["name"] = "default:obsidian_glass"}, {["x"] = 7, ["y"] = 4, ["param1"] = 174, ["z"] = 8, ["name"] = "building_blocks:grate"}, {["x"] = 7, ["y"] = 4, ["param1"] = 158, ["z"] = 9, ["name"] = "default:obsidian_glass"}, {["x"] = 7, ["y"] = 4, ["param1"] = 142, ["z"] = 10, ["name"] = "default:obsidian_glass"}, {["x"] = 7, ["y"] = 4, ["param1"] = 126, ["z"] = 11, ["name"] = "default:obsidian_glass"}, {["x"] = 7, ["y"] = 4, ["param1"] = 110, ["z"] = 12, ["name"] = "default:obsidian_glass"}, {["x"] = 7, ["y"] = 4, ["param1"] = 126, ["z"] = 13, ["name"] = "default:obsidian_glass"}, {["x"] = 7, ["y"] = 4, ["param1"] = 142, ["z"] = 14, ["name"] = "default:obsidian_glass"}, {["x"] = 7, ["y"] = 4, ["param1"] = 158, ["z"] = 15, ["name"] = "default:obsidian_glass"}, {["x"] = 7, ["y"] = 4, ["param1"] = 174, ["z"] = 16, ["name"] = "building_blocks:grate"}, {["x"] = 8, ["y"] = 0, ["z"] = 0, ["name"] = "default:brick"}, {["x"] = 8, ["y"] = 0, ["z"] = 1, ["name"] = "farming:soil_wet"}, {["x"] = 8, ["y"] = 0, ["z"] = 2, ["name"] = "farming:soil_wet"}, {["x"] = 8, ["y"] = 0, ["z"] = 3, ["name"] = "farming:soil_wet"}, {["x"] = 8, ["y"] = 0, ["z"] = 4, ["name"] = "farming:soil_wet"}, {["x"] = 8, ["y"] = 0, ["z"] = 5, ["name"] = "farming:soil_wet"}, {["x"] = 8, ["y"] = 0, ["z"] = 6, ["name"] = "farming:soil_wet"}, {["x"] = 8, ["y"] = 0, ["z"] = 7, ["name"] = "farming:soil_wet"}, {["x"] = 8, ["y"] = 0, ["z"] = 8, ["name"] = "default:wood"}, {["x"] = 8, ["y"] = 0, ["z"] = 9, ["name"] = "farming:soil_wet"}, {["x"] = 8, ["y"] = 0, ["z"] = 10, ["name"] = "farming:soil_wet"}, {["x"] = 8, ["y"] = 0, ["z"] = 11, ["name"] = "farming:soil_wet"}, {["x"] = 8, ["y"] = 0, ["z"] = 12, ["name"] = "farming:soil_wet"}, {["x"] = 8, ["y"] = 0, ["z"] = 13, ["name"] = "farming:soil_wet"}, {["x"] = 8, ["y"] = 0, ["z"] = 14, ["name"] = "farming:soil_wet"}, {["x"] = 8, ["y"] = 0, ["z"] = 15, ["name"] = "farming:soil_wet"}, {["x"] = 8, ["y"] = 0, ["z"] = 16, ["name"] = "default:brick"}, {["x"] = 8, ["y"] = 1, ["param1"] = 141, ["z"] = 0, ["name"] = "default:obsidian_glass"}, {["x"] = 8, ["y"] = 1, ["param1"] = 126, ["z"] = 1, ["name"] = "farming:carrot_8"}, {["x"] = 8, ["y"] = 1, ["param1"] = 142, ["z"] = 2, ["name"] = "farming:corn_8"}, {["x"] = 8, ["y"] = 1, ["param1"] = 158, ["z"] = 3, ["name"] = "farming:rhubarb_3"}, {["x"] = 8, ["y"] = 1, ["param1"] = 205, ["z"] = 6, ["name"] = "farming:pumpkin_8"}, {["x"] = 8, ["y"] = 1, ["param1"] = 221, ["z"] = 7, ["name"] = "farming:potato_4"}, {["x"] = 8, ["param2"] = 1, ["y"] = 1, ["param1"] = 238, ["z"] = 8, ["name"] = "homedecor:glowlight_half_on"}, {["x"] = 8, ["y"] = 1, ["param1"] = 222, ["z"] = 9, ["name"] = "farming:trellis"}, {["x"] = 8, ["param2"] = 1, ["y"] = 1, ["param1"] = 206, ["z"] = 10, ["name"] = "farming:chili_8"}, {["x"] = 8, ["y"] = 1, ["param1"] = 190, ["z"] = 11, ["name"] = "farming:melon_8"}, {["x"] = 8, ["y"] = 1, ["param1"] = 174, ["z"] = 12, ["name"] = "farming:grapes_8"}, {["x"] = 8, ["y"] = 1, ["param1"] = 158, ["z"] = 13, ["name"] = "farming:cotton_8"}, {["x"] = 8, ["y"] = 1, ["param1"] = 142, ["z"] = 14, ["name"] = "farming:wheat_8"}, {["x"] = 8, ["y"] = 1, ["param1"] = 126, ["z"] = 15, ["name"] = "farming:barley_7"}, {["x"] = 8, ["y"] = 1, ["param1"] = 141, ["z"] = 16, ["name"] = "default:obsidian_glass"}, {["x"] = 8, ["y"] = 2, ["param1"] = 157, ["z"] = 0, ["name"] = "default:obsidian_glass"}, {["x"] = 8, ["y"] = 2, ["param1"] = 157, ["z"] = 16, ["name"] = "default:obsidian_glass"}, {["x"] = 8, ["y"] = 3, ["param1"] = 173, ["z"] = 0, ["name"] = "default:obsidian_glass"}, {["x"] = 8, ["y"] = 3, ["param1"] = 173, ["z"] = 16, ["name"] = "default:obsidian_glass"}, {["x"] = 8, ["y"] = 4, ["param1"] = 189, ["z"] = 0, ["name"] = "building_blocks:grate"}, {["x"] = 8, ["y"] = 4, ["param1"] = 174, ["z"] = 1, ["name"] = "default:obsidian_glass"}, {["x"] = 8, ["y"] = 4, ["param1"] = 158, ["z"] = 2, ["name"] = "default:obsidian_glass"}, {["x"] = 8, ["y"] = 4, ["param1"] = 142, ["z"] = 3, ["name"] = "default:obsidian_glass"}, {["x"] = 8, ["y"] = 4, ["param1"] = 126, ["z"] = 4, ["name"] = "default:obsidian_glass"}, {["x"] = 8, ["y"] = 4, ["param1"] = 142, ["z"] = 5, ["name"] = "default:obsidian_glass"}, {["x"] = 8, ["y"] = 4, ["param1"] = 157, ["z"] = 6, ["name"] = "default:obsidian_glass"}, {["x"] = 8, ["y"] = 4, ["param1"] = 173, ["z"] = 7, ["name"] = "default:obsidian_glass"}, {["x"] = 8, ["y"] = 4, ["param1"] = 190, ["z"] = 8, ["name"] = "building_blocks:grate"}, {["x"] = 8, ["y"] = 4, ["param1"] = 174, ["z"] = 9, ["name"] = "default:obsidian_glass"}, {["x"] = 8, ["y"] = 4, ["param1"] = 158, ["z"] = 10, ["name"] = "default:obsidian_glass"}, {["x"] = 8, ["y"] = 4, ["param1"] = 142, ["z"] = 11, ["name"] = "default:obsidian_glass"}, {["x"] = 8, ["y"] = 4, ["param1"] = 126, ["z"] = 12, ["name"] = "default:obsidian_glass"}, {["x"] = 8, ["y"] = 4, ["param1"] = 142, ["z"] = 13, ["name"] = "default:obsidian_glass"}, {["x"] = 8, ["y"] = 4, ["param1"] = 158, ["z"] = 14, ["name"] = "default:obsidian_glass"}, {["x"] = 8, ["y"] = 4, ["param1"] = 174, ["z"] = 15, ["name"] = "default:obsidian_glass"}, {["x"] = 8, ["y"] = 4, ["param1"] = 189, ["z"] = 16, ["name"] = "building_blocks:grate"}, {["x"] = 9, ["y"] = 0, ["z"] = 0, ["name"] = "default:brick"}, {["x"] = 9, ["y"] = 0, ["z"] = 1, ["name"] = "default:brick"}, {["x"] = 9, ["y"] = 0, ["z"] = 2, ["name"] = "default:brick"}, {["x"] = 9, ["y"] = 0, ["z"] = 3, ["name"] = "default:brick"}, {["x"] = 9, ["y"] = 0, ["z"] = 4, ["name"] = "default:brick"}, {["x"] = 9, ["y"] = 0, ["z"] = 5, ["name"] = "default:brick"}, {["x"] = 9, ["y"] = 0, ["z"] = 6, ["name"] = "default:brick"}, {["x"] = 9, ["y"] = 0, ["z"] = 7, ["name"] = "default:brick"}, {["x"] = 9, ["y"] = 0, ["z"] = 8, ["name"] = "default:brick"}, {["x"] = 9, ["y"] = 0, ["z"] = 9, ["name"] = "default:brick"}, {["x"] = 9, ["y"] = 0, ["z"] = 10, ["name"] = "default:brick"}, {["x"] = 9, ["y"] = 0, ["z"] = 11, ["name"] = "default:brick"}, {["x"] = 9, ["y"] = 0, ["z"] = 12, ["name"] = "default:brick"}, {["x"] = 9, ["y"] = 0, ["z"] = 13, ["name"] = "default:brick"}, {["x"] = 9, ["y"] = 0, ["z"] = 14, ["name"] = "default:brick"}, {["x"] = 9, ["y"] = 0, ["z"] = 15, ["name"] = "default:brick"}, {["x"] = 9, ["y"] = 0, ["z"] = 16, ["name"] = "default:brick"}, {["x"] = 9, ["y"] = 1, ["z"] = 0, ["name"] = "default:brick"}, {["x"] = 9, ["y"] = 1, ["param1"] = 143, ["z"] = 1, ["name"] = "default:obsidian_glass"}, {["x"] = 9, ["y"] = 1, ["param1"] = 127, ["z"] = 2, ["name"] = "default:obsidian_glass"}, {["x"] = 9, ["y"] = 1, ["param1"] = 143, ["z"] = 3, ["name"] = "default:obsidian_glass"}, {["x"] = 9, ["y"] = 1, ["param1"] = 159, ["z"] = 4, ["name"] = "default:obsidian_glass"}, {["x"] = 9, ["y"] = 1, ["param1"] = 175, ["z"] = 5, ["name"] = "default:obsidian_glass"}, {["x"] = 9, ["y"] = 1, ["param1"] = 190, ["z"] = 6, ["name"] = "default:obsidian_glass"}, {["x"] = 9, ["y"] = 1, ["param1"] = 205, ["z"] = 7, ["name"] = "default:obsidian_glass"}, {["x"] = 9, ["y"] = 1, ["z"] = 8, ["name"] = "default:brick"}, {["x"] = 9, ["y"] = 1, ["param1"] = 207, ["z"] = 9, ["name"] = "default:obsidian_glass"}, {["x"] = 9, ["y"] = 1, ["param1"] = 191, ["z"] = 10, ["name"] = "default:obsidian_glass"}, {["x"] = 9, ["y"] = 1, ["param1"] = 175, ["z"] = 11, ["name"] = "default:obsidian_glass"}, {["x"] = 9, ["y"] = 1, ["param1"] = 159, ["z"] = 12, ["name"] = "default:obsidian_glass"}, {["x"] = 9, ["y"] = 1, ["param1"] = 143, ["z"] = 13, ["name"] = "default:obsidian_glass"}, {["x"] = 9, ["y"] = 1, ["param1"] = 127, ["z"] = 14, ["name"] = "default:obsidian_glass"}, {["x"] = 9, ["y"] = 1, ["param1"] = 143, ["z"] = 15, ["name"] = "default:obsidian_glass"}, {["x"] = 9, ["y"] = 1, ["z"] = 16, ["name"] = "default:brick"}, {["x"] = 9, ["y"] = 2, ["z"] = 0, ["name"] = "default:brick"}, {["x"] = 9, ["y"] = 2, ["param1"] = 159, ["z"] = 1, ["name"] = "default:obsidian_glass"}, {["x"] = 9, ["y"] = 2, ["param1"] = 143, ["z"] = 2, ["name"] = "default:obsidian_glass"}, {["x"] = 9, ["y"] = 2, ["param1"] = 127, ["z"] = 3, ["name"] = "default:obsidian_glass"}, {["x"] = 9, ["y"] = 2, ["param1"] = 143, ["z"] = 4, ["name"] = "default:obsidian_glass"}, {["x"] = 9, ["y"] = 2, ["param1"] = 159, ["z"] = 5, ["name"] = "default:obsidian_glass"}, {["x"] = 9, ["y"] = 2, ["param1"] = 174, ["z"] = 6, ["name"] = "default:obsidian_glass"}, {["x"] = 9, ["y"] = 2, ["param1"] = 189, ["z"] = 7, ["name"] = "default:obsidian_glass"}, {["x"] = 9, ["y"] = 2, ["z"] = 8, ["name"] = "default:brick"}, {["x"] = 9, ["y"] = 2, ["param1"] = 191, ["z"] = 9, ["name"] = "default:obsidian_glass"}, {["x"] = 9, ["y"] = 2, ["param1"] = 175, ["z"] = 10, ["name"] = "default:obsidian_glass"}, {["x"] = 9, ["y"] = 2, ["param1"] = 159, ["z"] = 11, ["name"] = "default:obsidian_glass"}, {["x"] = 9, ["y"] = 2, ["param1"] = 143, ["z"] = 12, ["name"] = "default:obsidian_glass"}, {["x"] = 9, ["y"] = 2, ["param1"] = 127, ["z"] = 13, ["name"] = "default:obsidian_glass"}, {["x"] = 9, ["y"] = 2, ["param1"] = 143, ["z"] = 14, ["name"] = "default:obsidian_glass"}, {["x"] = 9, ["y"] = 2, ["param1"] = 159, ["z"] = 15, ["name"] = "default:obsidian_glass"}, {["x"] = 9, ["y"] = 2, ["z"] = 16, ["name"] = "default:brick"}, {["x"] = 9, ["y"] = 3, ["z"] = 0, ["name"] = "default:brick"}, {["x"] = 9, ["y"] = 3, ["param1"] = 175, ["z"] = 1, ["name"] = "default:obsidian_glass"}, {["x"] = 9, ["y"] = 3, ["param1"] = 159, ["z"] = 2, ["name"] = "default:obsidian_glass"}, {["x"] = 9, ["y"] = 3, ["param1"] = 143, ["z"] = 3, ["name"] = "default:obsidian_glass"}, {["x"] = 9, ["y"] = 3, ["param1"] = 127, ["z"] = 4, ["name"] = "default:obsidian_glass"}, {["x"] = 9, ["y"] = 3, ["param1"] = 143, ["z"] = 5, ["name"] = "default:obsidian_glass"}, {["x"] = 9, ["y"] = 3, ["param1"] = 158, ["z"] = 6, ["name"] = "default:obsidian_glass"}, {["x"] = 9, ["y"] = 3, ["param1"] = 173, ["z"] = 7, ["name"] = "default:obsidian_glass"}, {["x"] = 9, ["y"] = 3, ["z"] = 8, ["name"] = "default:brick"}, {["x"] = 9, ["y"] = 3, ["param1"] = 175, ["z"] = 9, ["name"] = "default:obsidian_glass"}, {["x"] = 9, ["y"] = 3, ["param1"] = 159, ["z"] = 10, ["name"] = "default:obsidian_glass"}, {["x"] = 9, ["y"] = 3, ["param1"] = 143, ["z"] = 11, ["name"] = "default:obsidian_glass"}, {["x"] = 9, ["y"] = 3, ["param1"] = 127, ["z"] = 12, ["name"] = "default:obsidian_glass"}, {["x"] = 9, ["y"] = 3, ["param1"] = 143, ["z"] = 13, ["name"] = "default:obsidian_glass"}, {["x"] = 9, ["y"] = 3, ["param1"] = 159, ["z"] = 14, ["name"] = "default:obsidian_glass"}, {["x"] = 9, ["y"] = 3, ["param1"] = 175, ["z"] = 15, ["name"] = "default:obsidian_glass"}, {["x"] = 9, ["y"] = 3, ["z"] = 16, ["name"] = "default:brick"}, {["x"] = 9, ["y"] = 4, ["param1"] = 206, ["z"] = 0, ["name"] = "building_blocks:grate"}, {["x"] = 9, ["y"] = 4, ["param1"] = 191, ["z"] = 1, ["name"] = "building_blocks:grate"}, {["x"] = 9, ["y"] = 4, ["param1"] = 175, ["z"] = 2, ["name"] = "building_blocks:grate"}, {["x"] = 9, ["y"] = 4, ["param1"] = 159, ["z"] = 3, ["name"] = "building_blocks:grate"}, {["x"] = 9, ["y"] = 4, ["param1"] = 143, ["z"] = 4, ["name"] = "building_blocks:grate"}, {["x"] = 9, ["y"] = 4, ["param1"] = 127, ["z"] = 5, ["name"] = "building_blocks:grate"}, {["x"] = 9, ["y"] = 4, ["param1"] = 142, ["z"] = 6, ["name"] = "building_blocks:grate"}, {["x"] = 9, ["y"] = 4, ["param1"] = 158, ["z"] = 7, ["name"] = "building_blocks:grate"}, {["x"] = 9, ["y"] = 4, ["param1"] = 175, ["z"] = 8, ["name"] = "building_blocks:grate"}, {["x"] = 9, ["y"] = 4, ["param1"] = 159, ["z"] = 9, ["name"] = "building_blocks:grate"}, {["x"] = 9, ["y"] = 4, ["param1"] = 143, ["z"] = 10, ["name"] = "building_blocks:grate"}, {["x"] = 9, ["y"] = 4, ["param1"] = 127, ["z"] = 11, ["name"] = "building_blocks:grate"}, {["x"] = 9, ["y"] = 4, ["param1"] = 143, ["z"] = 12, ["name"] = "building_blocks:grate"}, {["x"] = 9, ["y"] = 4, ["param1"] = 159, ["z"] = 13, ["name"] = "building_blocks:grate"}, {["x"] = 9, ["y"] = 4, ["param1"] = 175, ["z"] = 14, ["name"] = "building_blocks:grate"}, {["x"] = 9, ["y"] = 4, ["param1"] = 191, ["z"] = 15, ["name"] = "building_blocks:grate"}, {["x"] = 9, ["y"] = 4, ["param1"] = 206, ["z"] = 16, ["name"] = "building_blocks:grate"}, {["x"] = 9, ["param2"] = 1, ["y"] = 5, ["param1"] = 222, ["z"] = 0, ["name"] = "homedecor:glowlight_quarter_on"}, {["x"] = 9, ["param2"] = 1, ["y"] = 5, ["param1"] = 222, ["z"] = 16, ["name"] = "homedecor:glowlight_quarter_on"}}