5:return {{["x"] = 0, ["y"] = 0, ["param1"] = 111, ["z"] = 0, ["name"] = "bakedclay:white"}, {["x"] = 0, ["y"] = 0, ["param1"] = 127, ["z"] = 1, ["name"] = "bakedclay:white"}, {["x"] = 0, ["y"] = 0, ["param1"] = 127, ["z"] = 2, ["name"] = "bakedclay:white"}, {["x"] = 0, ["y"] = 0, ["param1"] = 143, ["z"] = 3, ["name"] = "bakedclay:white"}, {["x"] = 0, ["y"] = 0, ["param1"] = 159, ["z"] = 4, ["name"] = "bakedclay:white"}, {["x"] = 0, ["y"] = 0, ["param1"] = 175, ["z"] = 5, ["name"] = "bakedclay:white"}, {["x"] = 0, ["y"] = 0, ["param1"] = 190, ["z"] = 6, ["name"] = "bakedclay:white"}, {["x"] = 0, ["y"] = 0, ["param1"] = 175, ["z"] = 7, ["name"] = "bakedclay:white"}, {["x"] = 0, ["y"] = 0, ["param1"] = 159, ["z"] = 8, ["name"] = "bakedclay:white"}, {["x"] = 0, ["y"] = 1, ["param1"] = 95, ["z"] = 0, ["name"] = "bakedclay:white"}, {["x"] = 0, ["y"] = 1, ["param1"] = 111, ["z"] = 1, ["name"] = "bakedclay:white"}, {["x"] = 0, ["y"] = 1, ["param1"] = 111, ["z"] = 2, ["name"] = "bakedclay:white"}, {["x"] = 0, ["y"] = 1, ["param1"] = 127, ["z"] = 3, ["name"] = "bakedclay:white"}, {["x"] = 0, ["y"] = 1, ["param1"] = 143, ["z"] = 4, ["name"] = "bakedclay:white"}, {["x"] = 0, ["y"] = 1, ["param1"] = 159, ["z"] = 5, ["name"] = "bakedclay:white"}, {["x"] = 0, ["y"] = 1, ["param1"] = 174, ["z"] = 6, ["name"] = "bakedclay:white"}, {["x"] = 0, ["y"] = 1, ["param1"] = 159, ["z"] = 7, ["name"] = "bakedclay:white"}, {["x"] = 0, ["y"] = 1, ["param1"] = 143, ["z"] = 8, ["name"] = "bakedclay:white"}, {["x"] = 0, ["y"] = 2, ["param1"] = 79, ["z"] = 0, ["name"] = "bakedclay:white"}, {["x"] = 0, ["y"] = 2, ["param1"] = 95, ["z"] = 1, ["name"] = "bakedclay:white"}, {["x"] = 0, ["y"] = 2, ["param1"] = 95, ["z"] = 2, ["name"] = "bakedclay:white"}, {["x"] = 0, ["y"] = 2, ["param1"] = 111, ["z"] = 3, ["name"] = "bakedclay:white"}, {["x"] = 0, ["y"] = 2, ["param1"] = 127, ["z"] = 4, ["name"] = "bakedclay:white"}, {["x"] = 0, ["y"] = 2, ["param1"] = 143, ["z"] = 5, ["name"] = "bakedclay:white"}, {["x"] = 0, ["y"] = 2, ["param1"] = 158, ["z"] = 6, ["name"] = "bakedclay:white"}, {["x"] = 0, ["y"] = 2, ["param1"] = 143, ["z"] = 7, ["name"] = "bakedclay:white"}, {["x"] = 0, ["y"] = 2, ["param1"] = 127, ["z"] = 8, ["name"] = "bakedclay:white"}, {["x"] = 0, ["y"] = 3, ["param1"] = 63, ["z"] = 0, ["name"] = "bakedclay:white"}, {["x"] = 0, ["y"] = 3, ["param1"] = 79, ["z"] = 1, ["name"] = "bakedclay:white"}, {["x"] = 0, ["y"] = 3, ["param1"] = 79, ["z"] = 2, ["name"] = "bakedclay:white"}, {["x"] = 0, ["y"] = 3, ["param1"] = 95, ["z"] = 3, ["name"] = "bakedclay:white"}, {["x"] = 0, ["y"] = 3, ["param1"] = 111, ["z"] = 4, ["name"] = "bakedclay:white"}, {["x"] = 0, ["y"] = 3, ["param1"] = 127, ["z"] = 5, ["name"] = "bakedclay:white"}, {["x"] = 0, ["y"] = 3, ["param1"] = 142, ["z"] = 6, ["name"] = "bakedclay:white"}, {["x"] = 0, ["y"] = 3, ["param1"] = 127, ["z"] = 7, ["name"] = "bakedclay:white"}, {["x"] = 0, ["y"] = 3, ["param1"] = 111, ["z"] = 8, ["name"] = "bakedclay:white"}, {["x"] = 0, ["y"] = 4, ["param1"] = 63, ["z"] = 0, ["name"] = "bakedclay:white"}, {["x"] = 0, ["y"] = 4, ["param1"] = 63, ["z"] = 1, ["name"] = "bakedclay:white"}, {["x"] = 0, ["y"] = 4, ["param1"] = 63, ["z"] = 2, ["name"] = "bakedclay:white"}, {["x"] = 0, ["y"] = 4, ["param1"] = 79, ["z"] = 3, ["name"] = "bakedclay:white"}, {["x"] = 0, ["y"] = 4, ["param1"] = 95, ["z"] = 4, ["name"] = "bakedclay:white"}, {["x"] = 0, ["y"] = 4, ["param1"] = 111, ["z"] = 5, ["name"] = "bakedclay:white"}, {["x"] = 0, ["y"] = 4, ["param1"] = 126, ["z"] = 6, ["name"] = "bakedclay:white"}, {["x"] = 0, ["y"] = 4, ["param1"] = 111, ["z"] = 7, ["name"] = "bakedclay:white"}, {["x"] = 0, ["y"] = 4, ["param1"] = 95, ["z"] = 8, ["name"] = "bakedclay:white"}, {["x"] = 1, ["y"] = 0, ["param1"] = 111, ["z"] = 0, ["name"] = "bakedclay:white"}, {["x"] = 1, ["y"] = 0, ["param1"] = 175, ["z"] = 8, ["name"] = "bakedclay:white"}, {["x"] = 1, ["y"] = 1, ["param1"] = 95, ["z"] = 0, ["name"] = "bakedclay:white"}, {["x"] = 1, ["y"] = 1, ["param1"] = 159, ["z"] = 8, ["name"] = "bakedclay:white"}, {["x"] = 1, ["y"] = 2, ["param1"] = 79, ["z"] = 0, ["name"] = "bakedclay:white"}, {["x"] = 1, ["y"] = 2, ["param1"] = 143, ["z"] = 8, ["name"] = "bakedclay:white"}, {["x"] = 1, ["y"] = 3, ["param1"] = 63, ["z"] = 0, ["name"] = "bakedclay:white"}, {["x"] = 1, ["y"] = 3, ["param1"] = 189, ["z"] = 2, ["name"] = "moreblocks:glow_glass"}, {["x"] = 1, ["y"] = 3, ["param1"] = 205, ["z"] = 3, ["name"] = "moreblocks:glow_glass"}, {["x"] = 1, ["y"] = 3, ["param1"] = 238, ["z"] = 5, ["name"] = "moreblocks:super_glow_glass"}, {["x"] = 1, ["y"] = 3, ["param1"] = 238, ["z"] = 6, ["name"] = "moreblocks:super_glow_glass"}, {["x"] = 1, ["y"] = 3, ["param1"] = 127, ["z"] = 8, ["name"] = "bakedclay:white"}, {["x"] = 1, ["y"] = 4, ["param1"] = 47, ["z"] = 0, ["name"] = "bakedclay:white"}, {["x"] = 1, ["y"] = 4, ["z"] = 1, ["name"] = "bakedclay:white"}, {["x"] = 1, ["y"] = 4, ["param1"] = 79, ["z"] = 2, ["name"] = "bakedclay:white"}, {["x"] = 1, ["y"] = 4, ["param1"] = 95, ["z"] = 3, ["name"] = "bakedclay:white"}, {["x"] = 1, ["y"] = 4, ["param1"] = 111, ["z"] = 4, ["name"] = "bakedclay:white"}, {["x"] = 1, ["y"] = 4, ["param1"] = 127, ["z"] = 5, ["name"] = "bakedclay:white"}, {["x"] = 1, ["y"] = 4, ["param1"] = 142, ["z"] = 6, ["name"] = "bakedclay:white"}, {["x"] = 1, ["y"] = 4, ["param1"] = 127, ["z"] = 7, ["name"] = "bakedclay:white"}, {["x"] = 1, ["y"] = 4, ["param1"] = 111, ["z"] = 8, ["name"] = "bakedclay:white"}, {["x"] = 2, ["y"] = 0, ["param1"] = 127, ["z"] = 0, ["name"] = "bakedclay:white"}, {["x"] = 2, ["y"] = 0, ["param1"] = 191, ["z"] = 8, ["name"] = "bakedclay:white"}, {["x"] = 2, ["y"] = 1, ["param1"] = 111, ["z"] = 0, ["name"] = "bakedclay:white"}, {["x"] = 2, ["y"] = 1, ["param1"] = 175, ["z"] = 8, ["name"] = "bakedclay:white"}, {["x"] = 2, ["y"] = 2, ["param1"] = 95, ["z"] = 0, ["name"] = "bakedclay:white"}, {["x"] = 2, ["y"] = 2, ["param1"] = 159, ["z"] = 8, ["name"] = "bakedclay:white"}, {["x"] = 2, ["y"] = 3, ["param1"] = 79, ["z"] = 0, ["name"] = "bakedclay:white"}, {["x"] = 2, ["meta"] = {["fields"] = {["infotext"] = "Glow Glass ", ["text"] = "Glow Glass", ["__signslib_new_format"] = "1", ["formspec"] = "size[6,4]textarea[0,-0.3;6.5,3;text;;${text}]button_exit[2,3.4;2,1;ok;Write]background[-0.5,-0.5;7,5;bg_signs_lib.jpg]"}, ["inventory"] = {}}, ["param2"] = 3, ["y"] = 3, ["param1"] = 190, ["z"] = 3, ["name"] = "signs:sign_wall_white_black"}, {["x"] = 2, ["meta"] = {["fields"] = {["infotext"] = "Super Glow Glass ", ["text"] = "Super Glow Glass", ["__signslib_new_format"] = "1", ["formspec"] = "size[6,4]textarea[0,-0.3;6.5,3;text;;${text}]button_exit[2,3.4;2,1;ok;Write]background[-0.5,-0.5;7,5;bg_signs_lib.jpg]"}, ["inventory"] = {}}, ["param2"] = 3, ["y"] = 3, ["param1"] = 222, ["z"] = 5, ["name"] = "signs:sign_wall_white_black"}, {["x"] = 2, ["y"] = 3, ["param1"] = 143, ["z"] = 8, ["name"] = "bakedclay:white"}, {["x"] = 2, ["y"] = 4, ["param1"] = 63, ["z"] = 0, ["name"] = "bakedclay:white"}, {["x"] = 2, ["y"] = 4, ["param1"] = 79, ["z"] = 1, ["name"] = "bakedclay:white"}, {["x"] = 2, ["y"] = 4, ["param1"] = 95, ["z"] = 2, ["name"] = "bakedclay:white"}, {["x"] = 2, ["y"] = 4, ["param1"] = 111, ["z"] = 3, ["name"] = "bakedclay:white"}, {["x"] = 2, ["y"] = 4, ["param1"] = 127, ["z"] = 4, ["name"] = "bakedclay:white"}, {["x"] = 2, ["y"] = 4, ["param1"] = 143, ["z"] = 5, ["name"] = "bakedclay:white"}, {["x"] = 2, ["y"] = 4, ["param1"] = 158, ["z"] = 6, ["name"] = "bakedclay:white"}, {["x"] = 2, ["y"] = 4, ["param1"] = 143, ["z"] = 7, ["name"] = "bakedclay:white"}, {["x"] = 2, ["y"] = 4, ["param1"] = 127, ["z"] = 8, ["name"] = "bakedclay:white"}, {["x"] = 3, ["y"] = 0, ["param1"] = 111, ["z"] = 0, ["name"] = "bakedclay:white"}, {["x"] = 3, ["meta"] = {["fields"] = {["infotext"] = "Owned by poikilos", ["owner"] = "poikilos", ["state"] = "2"}, ["inventory"] = {}}, ["param2"] = 2, ["y"] = 0, ["param1"] = 94, ["z"] = 1, ["name"] = "doors:door_steel_b"}, {["x"] = 3, ["y"] = 0, ["param1"] = 175, ["z"] = 8, ["name"] = "bakedclay:white"}, {["x"] = 3, ["y"] = 1, ["param1"] = 127, ["z"] = 0, ["name"] = "bakedclay:white"}, {["x"] = 3, ["param2"] = 1, ["y"] = 1, ["param1"] = 110, ["z"] = 1, ["name"] = "doors:hidden"}, {["x"] = 3, ["y"] = 1, ["param1"] = 159, ["z"] = 8, ["name"] = "bakedclay:white"}, {["x"] = 3, ["y"] = 2, ["param1"] = 111, ["z"] = 0, ["name"] = "bakedclay:white"}, {["x"] = 3, ["meta"] = {["fields"] = {["state"] = "2"}, ["inventory"] = {}}, ["param2"] = 2, ["y"] = 2, ["param1"] = 126, ["z"] = 1, ["name"] = "doors:door_wood_b"}, {["x"] = 3, ["y"] = 2, ["param1"] = 143, ["z"] = 8, ["name"] = "bakedclay:white"}, {["x"] = 3, ["y"] = 3, ["param1"] = 95, ["z"] = 0, ["name"] = "bakedclay:white"}, {["x"] = 3, ["param2"] = 1, ["y"] = 3, ["param1"] = 142, ["z"] = 1, ["name"] = "doors:hidden"}, {["x"] = 3, ["meta"] = {["fields"] = {["infotext"] = "Clean Glass ", ["text"] = "Clean Glass", ["__signslib_new_format"] = "1", ["formspec"] = "size[6,4]textarea[0,-0.3;6.5,3;text;;${text}]button_exit[2,3.4;2,1;ok;Write]background[-0.5,-0.5;7,5;bg_signs_lib.jpg]"}, ["inventory"] = {}}, ["param2"] = 2, ["y"] = 3, ["param1"] = 175, ["z"] = 3, ["name"] = "signs:sign_wall_white_black"}, {["x"] = 3, ["meta"] = {["fields"] = {["infotext"] = "Iron Glass ", ["text"] = "Iron Glass", ["__signslib_new_format"] = "1", ["formspec"] = "size[6,4]textarea[0,-0.3;6.5,3;text;;${text}]button_exit[2,3.4;2,1;ok;Write]background[-0.5,-0.5;7,5;bg_signs_lib.jpg]"}, ["inventory"] = {}}, ["y"] = 3, ["param1"] = 207, ["z"] = 5, ["name"] = "signs:sign_wall_white_black"}, {["x"] = 3, ["y"] = 3, ["param1"] = 127, ["z"] = 8, ["name"] = "bakedclay:white"}, {["x"] = 3, ["y"] = 4, ["param1"] = 79, ["z"] = 0, ["name"] = "bakedclay:white"}, {["x"] = 3, ["y"] = 4, ["param1"] = 63, ["z"] = 1, ["name"] = "bakedclay:white"}, {["x"] = 3, ["y"] = 4, ["param1"] = 143, ["z"] = 2, ["name"] = "moreblocks:clean_glass"}, {["x"] = 3, ["y"] = 4, ["param1"] = 159, ["z"] = 3, ["name"] = "moreblocks:clean_glass"}, {["x"] = 3, ["y"] = 4, ["z"] = 4, ["name"] = "bakedclay:white"}, {["x"] = 3, ["y"] = 4, ["param1"] = 191, ["z"] = 5, ["name"] = "moreblocks:iron_glass"}, {["x"] = 3, ["y"] = 4, ["param1"] = 190, ["z"] = 6, ["name"] = "moreblocks:iron_glass"}, {["x"] = 3, ["y"] = 4, ["param1"] = 127, ["z"] = 7, ["name"] = "bakedclay:white"}, {["x"] = 3, ["y"] = 4, ["param1"] = 111, ["z"] = 8, ["name"] = "bakedclay:white"}, {["x"] = 4, ["y"] = 0, ["param1"] = 127, ["z"] = 0, ["name"] = "bakedclay:white"}, {["x"] = 4, ["meta"] = {["fields"] = {["infotext"] = "Owned by poikilos", ["owner"] = "poikilos", ["state"] = "0"}, ["inventory"] = {}}, ["param2"] = 2, ["y"] = 0, ["param1"] = 77, ["z"] = 1, ["name"] = "doors:door_steel_a"}, {["x"] = 4, ["y"] = 0, ["param1"] = 159, ["z"] = 8, ["name"] = "bakedclay:white"}, {["x"] = 4, ["y"] = 1, ["param1"] = 143, ["z"] = 0, ["name"] = "bakedclay:white"}, {["x"] = 4, ["param2"] = 2, ["y"] = 1, ["param1"] = 93, ["z"] = 1, ["name"] = "doors:hidden"}, {["x"] = 4, ["y"] = 1, ["param1"] = 143, ["z"] = 8, ["name"] = "bakedclay:white"}, {["x"] = 4, ["y"] = 2, ["param1"] = 127, ["z"] = 0, ["name"] = "bakedclay:white"}, {["x"] = 4, ["meta"] = {["fields"] = {["state"] = "0"}, ["inventory"] = {}}, ["param2"] = 2, ["y"] = 2, ["param1"] = 109, ["z"] = 1, ["name"] = "doors:door_wood_a"}, {["x"] = 4, ["y"] = 2, ["param1"] = 127, ["z"] = 8, ["name"] = "bakedclay:white"}, {["x"] = 4, ["y"] = 3, ["param1"] = 111, ["z"] = 0, ["name"] = "bakedclay:white"}, {["x"] = 4, ["param2"] = 2, ["y"] = 3, ["param1"] = 125, ["z"] = 1, ["name"] = "doors:hidden"}, {["x"] = 4, ["y"] = 3, ["param1"] = 111, ["z"] = 8, ["name"] = "bakedclay:white"}, {["x"] = 4, ["y"] = 4, ["param1"] = 95, ["z"] = 0, ["name"] = "bakedclay:white"}, {["x"] = 4, ["y"] = 4, ["param1"] = 79, ["z"] = 1, ["name"] = "bakedclay:white"}, {["x"] = 4, ["y"] = 4, ["param1"] = 63, ["z"] = 2, ["name"] = "bakedclay:white"}, {["x"] = 4, ["y"] = 4, ["z"] = 3, ["name"] = "bakedclay:white"}, {["x"] = 4, ["y"] = 4, ["z"] = 4, ["name"] = "bakedclay:white"}, {["x"] = 4, ["y"] = 4, ["z"] = 5, ["name"] = "bakedclay:white"}, {["x"] = 4, ["y"] = 4, ["param1"] = 126, ["z"] = 6, ["name"] = "bakedclay:white"}, {["x"] = 4, ["y"] = 4, ["param1"] = 111, ["z"] = 7, ["name"] = "bakedclay:white"}, {["x"] = 4, ["y"] = 4, ["param1"] = 95, ["z"] = 8, ["name"] = "bakedclay:white"}, {["x"] = 5, ["y"] = 0, ["param1"] = 111, ["z"] = 0, ["name"] = "bakedclay:white"}, {["x"] = 5, ["y"] = 0, ["param1"] = 159, ["z"] = 8, ["name"] = "bakedclay:white"}, {["x"] = 5, ["y"] = 1, ["param1"] = 127, ["z"] = 0, ["name"] = "bakedclay:white"}, {["x"] = 5, ["y"] = 1, ["param1"] = 143, ["z"] = 8, ["name"] = "bakedclay:white"}, {["x"] = 5, ["y"] = 2, ["param1"] = 111, ["z"] = 0, ["name"] = "bakedclay:white"}, {["x"] = 5, ["y"] = 2, ["param1"] = 127, ["z"] = 8, ["name"] = "bakedclay:white"}, {["x"] = 5, ["y"] = 3, ["param1"] = 95, ["z"] = 0, ["name"] = "bakedclay:white"}, {["x"] = 5, ["meta"] = {["fields"] = {["infotext"] = "Coal Glass ", ["text"] = "Coal Glass", ["__signslib_new_format"] = "1", ["formspec"] = "size[6,4]textarea[0,-0.3;6.5,3;text;;${text}]button_exit[2,3.4;2,1;ok;Write]background[-0.5,-0.5;7,5;bg_signs_lib.jpg]"}, ["inventory"] = {}}, ["param2"] = 2, ["y"] = 3, ["param1"] = 143, ["z"] = 3, ["name"] = "signs:sign_wall_white_black"}, {["x"] = 5, ["meta"] = {["fields"] = {["infotext"] = "Glass ", ["text"] = "Glass", ["__signslib_new_format"] = "1", ["formspec"] = "size[6,4]textarea[0,-0.3;6.5,3;text;;${text}]button_exit[2,3.4;2,1;ok;Write]background[-0.5,-0.5;7,5;bg_signs_lib.jpg]"}, ["inventory"] = {}}, ["y"] = 3, ["param1"] = 175, ["z"] = 5, ["name"] = "signs:sign_wall_white_black"}, {["x"] = 5, ["y"] = 3, ["param1"] = 111, ["z"] = 8, ["name"] = "bakedclay:white"}, {["x"] = 5, ["y"] = 4, ["param1"] = 79, ["z"] = 0, ["name"] = "bakedclay:white"}, {["x"] = 5, ["y"] = 4, ["param1"] = 63, ["z"] = 1, ["name"] = "bakedclay:white"}, {["x"] = 5, ["y"] = 4, ["param1"] = 111, ["z"] = 2, ["name"] = "moreblocks:coal_glass"}, {["x"] = 5, ["y"] = 4, ["param1"] = 127, ["z"] = 3, ["name"] = "moreblocks:coal_glass"}, {["x"] = 5, ["y"] = 4, ["z"] = 4, ["name"] = "bakedclay:white"}, {["x"] = 5, ["y"] = 4, ["param1"] = 159, ["z"] = 5, ["name"] = "default:glass"}, {["x"] = 5, ["y"] = 4, ["param1"] = 158, ["z"] = 6, ["name"] = "default:glass"}, {["x"] = 5, ["y"] = 4, ["param1"] = 111, ["z"] = 7, ["name"] = "bakedclay:white"}, {["x"] = 5, ["y"] = 4, ["param1"] = 95, ["z"] = 8, ["name"] = "bakedclay:white"}, {["x"] = 6, ["y"] = 0, ["param1"] = 111, ["z"] = 0, ["name"] = "bakedclay:white"}, {["x"] = 6, ["y"] = 0, ["param1"] = 175, ["z"] = 8, ["name"] = "bakedclay:white"}, {["x"] = 6, ["y"] = 1, ["param1"] = 111, ["z"] = 0, ["name"] = "bakedclay:white"}, {["x"] = 6, ["y"] = 1, ["param1"] = 159, ["z"] = 8, ["name"] = "bakedclay:white"}, {["x"] = 6, ["y"] = 2, ["param1"] = 95, ["z"] = 0, ["name"] = "bakedclay:white"}, {["x"] = 6, ["y"] = 2, ["param1"] = 143, ["z"] = 8, ["name"] = "bakedclay:white"}, {["x"] = 6, ["y"] = 3, ["param1"] = 79, ["z"] = 0, ["name"] = "bakedclay:white"}, {["x"] = 6, ["meta"] = {["fields"] = {["infotext"] = "Items starting here should\
be connected (glass will only\
connect with connected glass\
option) ", ["text"] = "Items starting here should\
be connected (glass will only\
connect with connected glass\
option)", ["__signslib_new_format"] = "1", ["formspec"] = "size[6,4]textarea[0,-0.3;6.5,3;text;;${text}]button_exit[2,3.4;2,1;ok;Write]background[-0.5,-0.5;7,5;bg_signs_lib.jpg]"}, ["inventory"] = {}}, ["param2"] = 2, ["y"] = 3, ["param1"] = 93, ["z"] = 1, ["name"] = "signs:sign_wall_orange"}, {["x"] = 6, ["y"] = 3, ["param1"] = 127, ["z"] = 8, ["name"] = "bakedclay:white"}, {["x"] = 6, ["y"] = 4, ["param1"] = 63, ["z"] = 0, ["name"] = "bakedclay:white"}, {["x"] = 6, ["y"] = 4, ["param1"] = 63, ["z"] = 1, ["name"] = "bakedclay:white"}, {["x"] = 6, ["y"] = 4, ["param1"] = 79, ["z"] = 2, ["name"] = "bakedclay:white"}, {["x"] = 6, ["y"] = 4, ["param1"] = 95, ["z"] = 3, ["name"] = "bakedclay:white"}, {["x"] = 6, ["y"] = 4, ["param1"] = 111, ["z"] = 4, ["name"] = "bakedclay:white"}, {["x"] = 6, ["y"] = 4, ["param1"] = 127, ["z"] = 5, ["name"] = "bakedclay:white"}, {["x"] = 6, ["y"] = 4, ["param1"] = 142, ["z"] = 6, ["name"] = "bakedclay:white"}, {["x"] = 6, ["y"] = 4, ["param1"] = 127, ["z"] = 7, ["name"] = "bakedclay:white"}, {["x"] = 6, ["y"] = 4, ["param1"] = 111, ["z"] = 8, ["name"] = "bakedclay:white"}, {["x"] = 7, ["y"] = 0, ["param1"] = 126, ["z"] = 0, ["name"] = "bakedclay:white"}, {["x"] = 7, ["meta"] = {["fields"] = {["infotext"] = "Owned by poikilos", ["owner"] = "poikilos", ["state"] = "0"}, ["inventory"] = {}}, ["param2"] = 2, ["y"] = 0, ["param1"] = 60, ["z"] = 1, ["name"] = "doors:door_steel_a"}, {["x"] = 7, ["y"] = 0, ["param1"] = 191, ["z"] = 8, ["name"] = "bakedclay:white"}, {["x"] = 7, ["y"] = 1, ["param1"] = 110, ["z"] = 0, ["name"] = "bakedclay:white"}, {["x"] = 7, ["param2"] = 2, ["y"] = 1, ["param1"] = 76, ["z"] = 1, ["name"] = "doors:hidden"}, {["x"] = 7, ["y"] = 1, ["param1"] = 175, ["z"] = 8, ["name"] = "bakedclay:white"}, {["x"] = 7, ["y"] = 2, ["param1"] = 94, ["z"] = 0, ["name"] = "bakedclay:white"}, {["x"] = 7, ["param2"] = 2, ["y"] = 2, ["param1"] = 92, ["z"] = 1, ["name"] = "homedecor:door_japanese_closed"}, {["x"] = 7, ["y"] = 2, ["param1"] = 159, ["z"] = 8, ["name"] = "bakedclay:white"}, {["x"] = 7, ["y"] = 3, ["param1"] = 78, ["z"] = 0, ["name"] = "bakedclay:white"}, {["x"] = 7, ["meta"] = {["fields"] = {["infotext"] = "Japanese-style door ", ["text"] = "Japanese-style door", ["__signslib_new_format"] = "1", ["formspec"] = "size[6,4]textarea[0,-0.3;6.5,3;text;;${text}]button_exit[2,3.4;2,1;ok;Write]background[-0.5,-0.5;7,5;bg_signs_lib.jpg]"}, ["inventory"] = {}}, ["param2"] = 2, ["y"] = 3, ["param1"] = 125, ["z"] = 2, ["name"] = "signs:sign_wall_white_black"}, {["x"] = 7, ["y"] = 3, ["param1"] = 143, ["z"] = 8, ["name"] = "bakedclay:white"}, {["x"] = 7, ["y"] = 4, ["param1"] = 62, ["z"] = 0, ["name"] = "bakedclay:white"}, {["x"] = 7, ["y"] = 4, ["param1"] = 78, ["z"] = 1, ["name"] = "bakedclay:white"}, {["x"] = 7, ["y"] = 4, ["param1"] = 94, ["z"] = 2, ["name"] = "bakedclay:white"}, {["x"] = 7, ["y"] = 4, ["param1"] = 93, ["z"] = 3, ["name"] = "homedecor:skylight"}, {["x"] = 7, ["y"] = 4, ["param1"] = 110, ["z"] = 4, ["name"] = "homedecor:skylight"}, {["x"] = 7, ["y"] = 4, ["param1"] = 126, ["z"] = 5, ["name"] = "homedecor:skylight"}, {["x"] = 7, ["y"] = 4, ["param1"] = 158, ["z"] = 6, ["name"] = "bakedclay:white"}, {["x"] = 7, ["y"] = 4, ["param1"] = 143, ["z"] = 7, ["name"] = "bakedclay:white"}, {["x"] = 7, ["y"] = 4, ["param1"] = 127, ["z"] = 8, ["name"] = "bakedclay:white"}, {["x"] = 8, ["y"] = 0, ["param1"] = 110, ["z"] = 0, ["name"] = "bakedclay:white"}, {["x"] = 8, ["param2"] = 2, ["y"] = 0, ["param1"] = 76, ["z"] = 1, ["name"] = "protector:door_steel_b_1"}, {["x"] = 8, ["y"] = 0, ["param1"] = 175, ["z"] = 8, ["name"] = "bakedclay:white"}, {["x"] = 8, ["y"] = 1, ["param1"] = 94, ["z"] = 0, ["name"] = "bakedclay:white"}, {["x"] = 8, ["param2"] = 2, ["y"] = 1, ["param1"] = 92, ["z"] = 1, ["name"] = "protector:door_steel_t_1"}, {["x"] = 8, ["y"] = 1, ["param1"] = 159, ["z"] = 8, ["name"] = "bakedclay:white"}, {["x"] = 8, ["y"] = 2, ["param1"] = 78, ["z"] = 0, ["name"] = "bakedclay:white"}, {["x"] = 8, ["param2"] = 2, ["y"] = 2, ["param1"] = 108, ["z"] = 1, ["name"] = "homedecor:door_japanese_closed"}, {["x"] = 8, ["y"] = 2, ["param1"] = 143, ["z"] = 8, ["name"] = "bakedclay:white"}, {["x"] = 8, ["y"] = 3, ["param1"] = 62, ["z"] = 0, ["name"] = "bakedclay:white"}, {["x"] = 8, ["meta"] = {["fields"] = {["infotext"] = "Glass Skylight ", ["text"] = "Glass Skylight", ["__signslib_new_format"] = "1", ["formspec"] = "size[6,4]textarea[0,-0.3;6.5,3;text;;${text}]button_exit[2,3.4;2,1;ok;Write]background[-0.5,-0.5;7,5;bg_signs_lib.jpg]"}, ["inventory"] = {}}, ["param2"] = 2, ["y"] = 3, ["param1"] = 126, ["z"] = 3, ["name"] = "signs:sign_wall_white_black"}, {["x"] = 8, ["y"] = 3, ["param1"] = 127, ["z"] = 8, ["name"] = "bakedclay:white"}, {["x"] = 8, ["y"] = 4, ["param1"] = 46, ["z"] = 0, ["name"] = "bakedclay:white"}, {["x"] = 8, ["y"] = 4, ["param1"] = 62, ["z"] = 1, ["name"] = "bakedclay:white"}, {["x"] = 8, ["y"] = 4, ["param1"] = 78, ["z"] = 2, ["name"] = "bakedclay:white"}, {["x"] = 8, ["y"] = 4, ["param1"] = 109, ["z"] = 3, ["name"] = "homedecor:skylight"}, {["x"] = 8, ["y"] = 4, ["param1"] = 110, ["z"] = 4, ["name"] = "homedecor:skylight"}, {["x"] = 8, ["y"] = 4, ["param1"] = 110, ["z"] = 5, ["name"] = "homedecor:skylight"}, {["x"] = 8, ["y"] = 4, ["param1"] = 143, ["z"] = 6, ["name"] = "bakedclay:white"}, {["x"] = 8, ["y"] = 4, ["param1"] = 127, ["z"] = 7, ["name"] = "bakedclay:white"}, {["x"] = 8, ["y"] = 4, ["param1"] = 111, ["z"] = 8, ["name"] = "bakedclay:white"}, {["x"] = 9, ["y"] = 0, ["z"] = 0, ["name"] = "bakedclay:white"}, {["x"] = 9, ["param2"] = 2, ["y"] = 0, ["param1"] = 91, ["z"] = 1, ["name"] = "protector:door_wood_b_1"}, {["x"] = 9, ["y"] = 0, ["param1"] = 159, ["z"] = 8, ["name"] = "bakedclay:white"}, {["x"] = 9, ["y"] = 1, ["param1"] = 111, ["z"] = 0, ["name"] = "bakedclay:white"}, {["x"] = 9, ["param2"] = 2, ["y"] = 1, ["param1"] = 107, ["z"] = 1, ["name"] = "protector:door_wood_t_1"}, {["x"] = 9, ["y"] = 1, ["param1"] = 143, ["z"] = 8, ["name"] = "bakedclay:white"}, {["x"] = 9, ["y"] = 2, ["param1"] = 95, ["z"] = 0, ["name"] = "bakedclay:white"}, {["x"] = 9, ["y"] = 2, ["param1"] = 127, ["z"] = 8, ["name"] = "bakedclay:white"}, {["x"] = 9, ["y"] = 3, ["param1"] = 79, ["z"] = 0, ["name"] = "bakedclay:white"}, {["x"] = 9, ["y"] = 3, ["param1"] = 111, ["z"] = 8, ["name"] = "bakedclay:white"}, {["x"] = 9, ["y"] = 4, ["param1"] = 63, ["z"] = 0, ["name"] = "bakedclay:white"}, {["x"] = 9, ["y"] = 4, ["param1"] = 47, ["z"] = 1, ["name"] = "bakedclay:white"}, {["x"] = 9, ["y"] = 4, ["param1"] = 63, ["z"] = 2, ["name"] = "bakedclay:white"}, {["x"] = 9, ["y"] = 4, ["param1"] = 126, ["z"] = 3, ["name"] = "homedecor:skylight"}, {["x"] = 9, ["y"] = 4, ["param1"] = 126, ["z"] = 4, ["name"] = "homedecor:skylight"}, {["x"] = 9, ["y"] = 4, ["param1"] = 126, ["z"] = 5, ["name"] = "homedecor:skylight"}, {["x"] = 9, ["y"] = 4, ["param1"] = 127, ["z"] = 6, ["name"] = "bakedclay:white"}, {["x"] = 9, ["y"] = 4, ["param1"] = 111, ["z"] = 7, ["name"] = "bakedclay:white"}, {["x"] = 9, ["y"] = 4, ["param1"] = 95, ["z"] = 8, ["name"] = "bakedclay:white"}, {["x"] = 10, ["y"] = 0, ["z"] = 0, ["name"] = "bakedclay:white"}, {["x"] = 10, ["param2"] = 2, ["y"] = 0, ["param1"] = 107, ["z"] = 1, ["name"] = "protector:door_wood_b_1"}, {["x"] = 10, ["y"] = 0, ["param1"] = 143, ["z"] = 8, ["name"] = "bakedclay:white"}, {["x"] = 10, ["y"] = 1, ["param1"] = 127, ["z"] = 0, ["name"] = "bakedclay:white"}, {["x"] = 10, ["param2"] = 2, ["y"] = 1, ["param1"] = 123, ["z"] = 1, ["name"] = "protector:door_wood_t_1"}, {["x"] = 10, ["y"] = 1, ["param1"] = 127, ["z"] = 8, ["name"] = "bakedclay:white"}, {["x"] = 10, ["y"] = 2, ["param1"] = 111, ["z"] = 0, ["name"] = "bakedclay:white"}, {["x"] = 10, ["y"] = 2, ["param1"] = 111, ["z"] = 8, ["name"] = "bakedclay:white"}, {["x"] = 10, ["y"] = 3, ["param1"] = 95, ["z"] = 0, ["name"] = "bakedclay:white"}, {["x"] = 10, ["meta"] = {["fields"] = {["infotext"] = "Connection Tests:\
These don't usually work\
even with connected glass\
option. ", ["text"] = "Connection Tests:\
These don't usually work\
even with connected glass\
option.", ["__signslib_new_format"] = "1", ["formspec"] = "size[6,4]textarea[0,-0.3;6.5,3;text;;${text}]button_exit[2,3.4;2,1;ok;Write]background[-0.5,-0.5;7,5;bg_signs_lib.jpg]"}, ["inventory"] = {}}, ["param2"] = 2, ["y"] = 3, ["param1"] = 155, ["z"] = 1, ["name"] = "signs:sign_wall_orange"}, {["x"] = 10, ["y"] = 3, ["param1"] = 95, ["z"] = 8, ["name"] = "bakedclay:white"}, {["x"] = 10, ["y"] = 4, ["param1"] = 79, ["z"] = 0, ["name"] = "bakedclay:white"}, {["x"] = 10, ["y"] = 4, ["param1"] = 63, ["z"] = 1, ["name"] = "bakedclay:white"}, {["x"] = 10, ["y"] = 4, ["param1"] = 47, ["z"] = 2, ["name"] = "bakedclay:white"}, {["x"] = 10, ["y"] = 4, ["param1"] = 63, ["z"] = 3, ["name"] = "bakedclay:white"}, {["x"] = 10, ["y"] = 4, ["param1"] = 79, ["z"] = 4, ["name"] = "bakedclay:white"}, {["x"] = 10, ["y"] = 4, ["param1"] = 95, ["z"] = 5, ["name"] = "bakedclay:white"}, {["x"] = 10, ["y"] = 4, ["param1"] = 111, ["z"] = 6, ["name"] = "bakedclay:white"}, {["x"] = 10, ["y"] = 4, ["param1"] = 95, ["z"] = 7, ["name"] = "bakedclay:white"}, {["x"] = 10, ["y"] = 4, ["param1"] = 79, ["z"] = 8, ["name"] = "bakedclay:white"}, {["x"] = 11, ["y"] = 0, ["param1"] = 127, ["z"] = 0, ["name"] = "bakedclay:white"}, {["x"] = 11, ["y"] = 0, ["param1"] = 122, ["z"] = 1, ["name"] = "building_blocks:woodglass"}, {["x"] = 11, ["y"] = 0, ["param1"] = 159, ["z"] = 8, ["name"] = "bakedclay:white"}, {["x"] = 11, ["y"] = 1, ["param1"] = 143, ["z"] = 0, ["name"] = "bakedclay:white"}, {["x"] = 11, ["y"] = 1, ["param1"] = 138, ["z"] = 1, ["name"] = "building_blocks:woodglass"}, {["x"] = 11, ["y"] = 1, ["param1"] = 143, ["z"] = 8, ["name"] = "bakedclay:white"}, {["x"] = 11, ["y"] = 2, ["param1"] = 127, ["z"] = 0, ["name"] = "bakedclay:white"}, {["x"] = 11, ["y"] = 2, ["param1"] = 127, ["z"] = 8, ["name"] = "bakedclay:white"}, {["x"] = 11, ["y"] = 3, ["param1"] = 111, ["z"] = 0, ["name"] = "bakedclay:white"}, {["x"] = 11, ["meta"] = {["fields"] = {["infotext"] = "Glass Skylight Frosted ", ["text"] = "Glass Skylight Frosted", ["__signslib_new_format"] = "1", ["formspec"] = "size[6,4]textarea[0,-0.3;6.5,3;text;;${text}]button_exit[2,3.4;2,1;ok;Write]background[-0.5,-0.5;7,5;bg_signs_lib.jpg]"}, ["inventory"] = {}}, ["param2"] = 2, ["y"] = 3, ["param1"] = 188, ["z"] = 2, ["name"] = "signs:sign_wall_white_black"}, {["x"] = 11, ["y"] = 3, ["param1"] = 111, ["z"] = 8, ["name"] = "bakedclay:white"}, {["x"] = 11, ["y"] = 4, ["param1"] = 95, ["z"] = 0, ["name"] = "bakedclay:white"}, {["x"] = 11, ["y"] = 4, ["param1"] = 79, ["z"] = 1, ["name"] = "bakedclay:white"}, {["x"] = 11, ["y"] = 4, ["param1"] = 63, ["z"] = 2, ["name"] = "bakedclay:white"}, {["x"] = 11, ["y"] = 4, ["param1"] = 158, ["z"] = 3, ["name"] = "homedecor:skylight_frosted"}, {["x"] = 11, ["y"] = 4, ["param1"] = 158, ["z"] = 4, ["name"] = "homedecor:skylight_frosted"}, {["x"] = 11, ["y"] = 4, ["param1"] = 158, ["z"] = 5, ["name"] = "homedecor:skylight_frosted"}, {["x"] = 11, ["y"] = 4, ["param1"] = 127, ["z"] = 6, ["name"] = "bakedclay:white"}, {["x"] = 11, ["y"] = 4, ["param1"] = 111, ["z"] = 7, ["name"] = "bakedclay:white"}, {["x"] = 11, ["y"] = 4, ["param1"] = 95, ["z"] = 8, ["name"] = "bakedclay:white"}, {["x"] = 12, ["y"] = 0, ["param1"] = 111, ["z"] = 0, ["name"] = "bakedclay:white"}, {["x"] = 12, ["y"] = 0, ["param1"] = 139, ["z"] = 1, ["name"] = "building_blocks:woodglass"}, {["x"] = 12, ["y"] = 0, ["param1"] = 175, ["z"] = 8, ["name"] = "bakedclay:white"}, {["x"] = 12, ["y"] = 1, ["param1"] = 127, ["z"] = 0, ["name"] = "bakedclay:white"}, {["x"] = 12, ["y"] = 1, ["param1"] = 155, ["z"] = 1, ["name"] = "building_blocks:woodglass"}, {["x"] = 12, ["meta"] = {["fields"] = {["infotext"] = "Wood Framed Glass ", ["text"] = "Wood Framed Glass", ["__signslib_new_format"] = "1", ["formspec"] = "size[6,4]textarea[0,-0.3;6.5,3;text;;${text}]button_exit[2,3.4;2,1;ok;Write]background[-0.5,-0.5;7,5;bg_signs_lib.jpg]"}, ["inventory"] = {}}, ["param2"] = 2, ["y"] = 1, ["param1"] = 172, ["z"] = 2, ["name"] = "signs:sign_wall_white_black"}, {["x"] = 12, ["y"] = 1, ["param1"] = 159, ["z"] = 8, ["name"] = "bakedclay:white"}, {["x"] = 12, ["y"] = 2, ["param1"] = 111, ["z"] = 0, ["name"] = "bakedclay:white"}, {["x"] = 12, ["param2"] = 2, ["y"] = 2, ["param1"] = 171, ["z"] = 1, ["name"] = "homedecor:stained_glass"}, {["x"] = 12, ["y"] = 2, ["param1"] = 143, ["z"] = 8, ["name"] = "bakedclay:white"}, {["x"] = 12, ["y"] = 3, ["param1"] = 95, ["z"] = 0, ["name"] = "bakedclay:white"}, {["x"] = 12, ["param2"] = 2, ["y"] = 3, ["param1"] = 187, ["z"] = 1, ["name"] = "homedecor:stained_glass"}, {["x"] = 12, ["y"] = 3, ["param1"] = 127, ["z"] = 8, ["name"] = "bakedclay:white"}, {["x"] = 12, ["y"] = 4, ["param1"] = 79, ["z"] = 0, ["name"] = "bakedclay:white"}, {["x"] = 12, ["y"] = 4, ["param1"] = 63, ["z"] = 1, ["name"] = "bakedclay:white"}, {["x"] = 12, ["y"] = 4, ["param1"] = 79, ["z"] = 2, ["name"] = "bakedclay:white"}, {["x"] = 12, ["y"] = 4, ["param1"] = 174, ["z"] = 3, ["name"] = "homedecor:skylight_frosted"}, {["x"] = 12, ["y"] = 4, ["param1"] = 174, ["z"] = 4, ["name"] = "homedecor:skylight_frosted"}, {["x"] = 12, ["y"] = 4, ["param1"] = 174, ["z"] = 5, ["name"] = "homedecor:skylight_frosted"}, {["x"] = 12, ["y"] = 4, ["param1"] = 143, ["z"] = 6, ["name"] = "bakedclay:white"}, {["x"] = 12, ["y"] = 4, ["param1"] = 127, ["z"] = 7, ["name"] = "bakedclay:white"}, {["x"] = 12, ["y"] = 4, ["param1"] = 111, ["z"] = 8, ["name"] = "bakedclay:white"}, {["x"] = 13, ["y"] = 0, ["param1"] = 127, ["z"] = 0, ["name"] = "bakedclay:white"}, {["x"] = 13, ["y"] = 0, ["param1"] = 156, ["z"] = 1, ["name"] = "building_blocks:smoothglass"}, {["x"] = 13, ["y"] = 0, ["param1"] = 191, ["z"] = 8, ["name"] = "bakedclay:white"}, {["x"] = 13, ["y"] = 1, ["param1"] = 111, ["z"] = 0, ["name"] = "bakedclay:white"}, {["x"] = 13, ["y"] = 1, ["param1"] = 172, ["z"] = 1, ["name"] = "building_blocks:smoothglass"}, {["x"] = 13, ["meta"] = {["fields"] = {["infotext"] = "Streak Free Glass ", ["text"] = "Streak Free Glass", ["__signslib_new_format"] = "1", ["formspec"] = "size[6,4]textarea[0,-0.3;6.5,3;text;;${text}]button_exit[2,3.4;2,1;ok;Write]background[-0.5,-0.5;7,5;bg_signs_lib.jpg]"}, ["inventory"] = {}}, ["param2"] = 2, ["y"] = 1, ["param1"] = 189, ["z"] = 2, ["name"] = "signs:sign_wall_white_black"}, {["x"] = 13, ["y"] = 1, ["param1"] = 175, ["z"] = 8, ["name"] = "bakedclay:white"}, {["x"] = 13, ["y"] = 2, ["param1"] = 95, ["z"] = 0, ["name"] = "bakedclay:white"}, {["x"] = 13, ["param2"] = 2, ["y"] = 2, ["param1"] = 188, ["z"] = 1, ["name"] = "homedecor:stained_glass"}, {["x"] = 13, ["y"] = 2, ["param1"] = 159, ["z"] = 8, ["name"] = "bakedclay:white"}, {["x"] = 13, ["y"] = 3, ["param1"] = 79, ["z"] = 0, ["name"] = "bakedclay:white"}, {["x"] = 13, ["param2"] = 2, ["y"] = 3, ["param1"] = 204, ["z"] = 1, ["name"] = "homedecor:stained_glass"}, {["x"] = 13, ["y"] = 3, ["param1"] = 221, ["z"] = 2, ["name"] = "homedecor:glowlight_small_cube_on"}, {["x"] = 13, ["y"] = 3, ["param1"] = 222, ["z"] = 6, ["name"] = "homedecor:glowlight_small_cube_on"}, {["x"] = 13, ["y"] = 3, ["param1"] = 143, ["z"] = 8, ["name"] = "bakedclay:white"}, {["x"] = 13, ["y"] = 4, ["param1"] = 63, ["z"] = 0, ["name"] = "bakedclay:white"}, {["x"] = 13, ["y"] = 4, ["param1"] = 79, ["z"] = 1, ["name"] = "bakedclay:white"}, {["x"] = 13, ["y"] = 4, ["param1"] = 95, ["z"] = 2, ["name"] = "bakedclay:white"}, {["x"] = 13, ["y"] = 4, ["param1"] = 111, ["z"] = 3, ["name"] = "bakedclay:white"}, {["x"] = 13, ["y"] = 4, ["param1"] = 127, ["z"] = 4, ["name"] = "bakedclay:white"}, {["x"] = 13, ["y"] = 4, ["param1"] = 143, ["z"] = 5, ["name"] = "bakedclay:white"}, {["x"] = 13, ["y"] = 4, ["param1"] = 159, ["z"] = 6, ["name"] = "bakedclay:white"}, {["x"] = 13, ["y"] = 4, ["param1"] = 143, ["z"] = 7, ["name"] = "bakedclay:white"}, {["x"] = 13, ["y"] = 4, ["param1"] = 127, ["z"] = 8, ["name"] = "bakedclay:white"}, {["x"] = 14, ["y"] = 0, ["param1"] = 127, ["z"] = 0, ["name"] = "bakedclay:white"}, {["x"] = 14, ["y"] = 0, ["param1"] = 156, ["z"] = 1, ["name"] = "building_blocks:smoothglass"}, {["x"] = 14, ["y"] = 0, ["param1"] = 175, ["z"] = 8, ["name"] = "bakedclay:white"}, {["x"] = 14, ["y"] = 1, ["param1"] = 111, ["z"] = 0, ["name"] = "bakedclay:white"}, {["x"] = 14, ["y"] = 1, ["param1"] = 173, ["z"] = 1, ["name"] = "building_blocks:smoothglass"}, {["x"] = 14, ["y"] = 1, ["param1"] = 159, ["z"] = 8, ["name"] = "bakedclay:white"}, {["x"] = 14, ["y"] = 2, ["param1"] = 95, ["z"] = 0, ["name"] = "bakedclay:white"}, {["x"] = 14, ["meta"] = {["fields"] = {["infotext"] = "Glass Pane ", ["text"] = "Glass Pane", ["__signslib_new_format"] = "1", ["formspec"] = "size[6,4]textarea[0,-0.3;6.5,3;text;;${text}]button_exit[2,3.4;2,1;ok;Write]background[-0.5,-0.5;7,5;bg_signs_lib.jpg]"}, ["inventory"] = {}}, ["param2"] = 1, ["y"] = 2, ["param1"] = 204, ["z"] = 2, ["name"] = "signs:sign_wall_white_black"}, {["x"] = 14, ["y"] = 2, ["param1"] = 143, ["z"] = 8, ["name"] = "bakedclay:white"}, {["x"] = 14, ["y"] = 3, ["param1"] = 79, ["z"] = 0, ["name"] = "bakedclay:white"}, {["x"] = 14, ["meta"] = {["fields"] = {["infotext"] = "Stained Glass ", ["text"] = "Stained Glass", ["__signslib_new_format"] = "1", ["formspec"] = "size[6,4]textarea[0,-0.3;6.5,3;text;;${text}]button_exit[2,3.4;2,1;ok;Write]background[-0.5,-0.5;7,5;bg_signs_lib.jpg]"}, ["inventory"] = {}}, ["param2"] = 2, ["y"] = 3, ["param1"] = 204, ["z"] = 1, ["name"] = "signs:sign_wall_white_black"}, {["x"] = 14, ["y"] = 3, ["param1"] = 221, ["z"] = 2, ["name"] = "homedecor:glowlight_small_cube_on"}, {["x"] = 14, ["y"] = 3, ["param1"] = 222, ["z"] = 4, ["name"] = "homedecor:glowlight_small_cube_on"}, {["x"] = 14, ["y"] = 3, ["param1"] = 222, ["z"] = 6, ["name"] = "homedecor:glowlight_small_cube_on"}, {["x"] = 14, ["y"] = 3, ["param1"] = 127, ["z"] = 8, ["name"] = "bakedclay:white"}, {["x"] = 14, ["y"] = 4, ["param1"] = 63, ["z"] = 0, ["name"] = "bakedclay:white"}, {["x"] = 14, ["y"] = 4, ["param1"] = 79, ["z"] = 1, ["name"] = "bakedclay:white"}, {["x"] = 14, ["y"] = 4, ["param1"] = 79, ["z"] = 2, ["name"] = "bakedclay:white"}, {["x"] = 14, ["y"] = 4, ["param1"] = 95, ["z"] = 3, ["name"] = "bakedclay:white"}, {["x"] = 14, ["y"] = 4, ["param1"] = 111, ["z"] = 4, ["name"] = "bakedclay:white"}, {["x"] = 14, ["y"] = 4, ["param1"] = 127, ["z"] = 5, ["name"] = "bakedclay:white"}, {["x"] = 14, ["y"] = 4, ["param1"] = 143, ["z"] = 6, ["name"] = "bakedclay:white"}, {["x"] = 14, ["y"] = 4, ["z"] = 7, ["name"] = "bakedclay:white"}, {["x"] = 14, ["y"] = 4, ["param1"] = 111, ["z"] = 8, ["name"] = "bakedclay:white"}, {["x"] = 15, ["y"] = 0, ["param1"] = 143, ["z"] = 0, ["name"] = "bakedclay:white"}, {["x"] = 15, ["y"] = 0, ["param1"] = 159, ["z"] = 1, ["name"] = "bakedclay:white"}, {["x"] = 15, ["y"] = 0, ["param1"] = 143, ["z"] = 2, ["name"] = "bakedclay:white"}, {["x"] = 15, ["y"] = 0, ["param1"] = 143, ["z"] = 3, ["name"] = "bakedclay:white"}, {["x"] = 15, ["y"] = 0, ["param1"] = 159, ["z"] = 4, ["name"] = "bakedclay:white"}, {["x"] = 15, ["meta"] = {["fields"] = {["state"] = "1", ["infotext"] = "Owned by poikilos", ["owner"] = "poikilos"}, ["inventory"] = {}}, ["y"] = 0, ["param1"] = 142, ["z"] = 5, ["name"] = "doors:door_steel_b"}, {["x"] = 15, ["meta"] = {["fields"] = {["state"] = "2", ["infotext"] = "Owned by poikilos", ["owner"] = "poikilos"}, ["inventory"] = {}}, ["param2"] = 3, ["y"] = 0, ["param1"] = 157, ["z"] = 6, ["name"] = "doors:door_steel_b"}, {["x"] = 15, ["y"] = 0, ["param1"] = 175, ["z"] = 7, ["name"] = "bakedclay:white"}, {["x"] = 15, ["y"] = 0, ["param1"] = 159, ["z"] = 8, ["name"] = "bakedclay:white"}, {["x"] = 15, ["y"] = 1, ["param1"] = 127, ["z"] = 0, ["name"] = "bakedclay:white"}, {["x"] = 15, ["param2"] = 1, ["y"] = 1, ["param1"] = 158, ["z"] = 1, ["name"] = "xpanes:pane_flat"}, {["x"] = 15, ["param2"] = 3, ["y"] = 1, ["param1"] = 174, ["z"] = 2, ["name"] = "xpanes:pane_flat"}, {["x"] = 15, ["y"] = 1, ["param1"] = 127, ["z"] = 3, ["name"] = "bakedclay:white"}, {["x"] = 15, ["y"] = 1, ["param1"] = 143, ["z"] = 4, ["name"] = "bakedclay:white"}, {["x"] = 15, ["param2"] = 3, ["y"] = 1, ["param1"] = 158, ["z"] = 5, ["name"] = "doors:hidden"}, {["x"] = 15, ["param2"] = 2, ["y"] = 1, ["param1"] = 173, ["z"] = 6, ["name"] = "doors:hidden"}, {["x"] = 15, ["y"] = 1, ["param1"] = 159, ["z"] = 7, ["name"] = "bakedclay:white"}, {["x"] = 15, ["y"] = 1, ["param1"] = 143, ["z"] = 8, ["name"] = "bakedclay:white"}, {["x"] = 15, ["y"] = 2, ["param1"] = 111, ["z"] = 0, ["name"] = "bakedclay:white"}, {["x"] = 15, ["y"] = 2, ["param1"] = 127, ["z"] = 1, ["name"] = "bakedclay:white"}, {["x"] = 15, ["y"] = 2, ["param1"] = 111, ["z"] = 2, ["name"] = "bakedclay:white"}, {["x"] = 15, ["y"] = 2, ["param1"] = 111, ["z"] = 3, ["name"] = "bakedclay:white"}, {["x"] = 15, ["y"] = 2, ["param1"] = 127, ["z"] = 4, ["name"] = "bakedclay:white"}, {["x"] = 15, ["y"] = 2, ["param1"] = 143, ["z"] = 5, ["name"] = "bakedclay:white"}, {["x"] = 15, ["y"] = 2, ["param1"] = 159, ["z"] = 6, ["name"] = "bakedclay:white"}, {["x"] = 15, ["y"] = 2, ["param1"] = 143, ["z"] = 7, ["name"] = "bakedclay:white"}, {["x"] = 15, ["y"] = 2, ["param1"] = 127, ["z"] = 8, ["name"] = "bakedclay:white"}, {["x"] = 15, ["y"] = 3, ["param1"] = 95, ["z"] = 0, ["name"] = "bakedclay:white"}, {["x"] = 15, ["y"] = 3, ["param1"] = 111, ["z"] = 1, ["name"] = "bakedclay:white"}, {["x"] = 15, ["y"] = 3, ["param1"] = 95, ["z"] = 2, ["name"] = "bakedclay:white"}, {["x"] = 15, ["y"] = 3, ["param1"] = 95, ["z"] = 3, ["name"] = "bakedclay:white"}, {["x"] = 15, ["y"] = 3, ["param1"] = 111, ["z"] = 4, ["name"] = "bakedclay:white"}, {["x"] = 15, ["y"] = 3, ["param1"] = 127, ["z"] = 5, ["name"] = "bakedclay:white"}, {["x"] = 15, ["y"] = 3, ["param1"] = 143, ["z"] = 6, ["name"] = "bakedclay:white"}, {["x"] = 15, ["y"] = 3, ["param1"] = 127, ["z"] = 7, ["name"] = "bakedclay:white"}, {["x"] = 15, ["y"] = 3, ["param1"] = 111, ["z"] = 8, ["name"] = "bakedclay:white"}, {["x"] = 15, ["y"] = 4, ["param1"] = 79, ["z"] = 0, ["name"] = "bakedclay:white"}, {["x"] = 15, ["y"] = 4, ["param1"] = 95, ["z"] = 1, ["name"] = "bakedclay:white"}, {["x"] = 15, ["y"] = 4, ["param1"] = 79, ["z"] = 2, ["name"] = "bakedclay:white"}, {["x"] = 15, ["y"] = 4, ["param1"] = 79, ["z"] = 3, ["name"] = "bakedclay:white"}, {["x"] = 15, ["y"] = 4, ["param1"] = 95, ["z"] = 4, ["name"] = "bakedclay:white"}, {["x"] = 15, ["y"] = 4, ["param1"] = 111, ["z"] = 5, ["name"] = "bakedclay:white"}, {["x"] = 15, ["y"] = 4, ["param1"] = 127, ["z"] = 6, ["name"] = "bakedclay:white"}, {["x"] = 15, ["y"] = 4, ["param1"] = 111, ["z"] = 7, ["name"] = "bakedclay:white"}, {["x"] = 15, ["y"] = 4, ["param1"] = 95, ["z"] = 8, ["name"] = "bakedclay:white"}, {["x"] = 16, ["meta"] = {["fields"] = {["infotext"] = "Workshop ", ["text"] = "Workshop", ["__signslib_new_format"] = "1", ["formspec"] = "size[6,4]textarea[0,-0.3;6.5,3;text;;${text}]button_exit[2,3.4;2,1;ok;Write]background[-0.5,-0.5;7,5;bg_signs_lib.jpg]"}, ["inventory"] = {}}, ["param2"] = 3, ["y"] = 2, ["param1"] = 127, ["z"] = 5, ["name"] = "signs:sign_wall_white_black"}}
