5:return {{["x"] = 0, ["y"] = 7, ["z"] = 21, ["name"] = "default:wood"}, {["x"] = 0, ["y"] = 7, ["z"] = 22, ["name"] = "default:wood"}, {["x"] = 0, ["y"] = 7, ["z"] = 23, ["name"] = "default:wood"}, {["x"] = 0, ["y"] = 7, ["z"] = 24, ["name"] = "default:wood"}, {["x"] = 0, ["y"] = 7, ["z"] = 25, ["name"] = "default:wood"}, {["x"] = 0, ["y"] = 7, ["z"] = 26, ["name"] = "default:wood"}, {["x"] = 0, ["y"] = 7, ["z"] = 27, ["name"] = "default:wood"}, {["x"] = 0, ["y"] = 7, ["z"] = 28, ["name"] = "default:wood"}, {["x"] = 0, ["y"] = 7, ["z"] = 29, ["name"] = "default:wood"}, {["x"] = 0, ["y"] = 7, ["z"] = 30, ["name"] = "default:wood"}, {["x"] = 0, ["y"] = 7, ["z"] = 31, ["name"] = "default:wood"}, {["x"] = 1, ["y"] = 7, ["z"] = 21, ["name"] = "default:wood"}, {["x"] = 1, ["y"] = 7, ["z"] = 22, ["name"] = "default:wood"}, {["x"] = 1, ["y"] = 7, ["z"] = 23, ["name"] = "default:wood"}, {["x"] = 1, ["y"] = 7, ["z"] = 24, ["name"] = "default:wood"}, {["x"] = 1, ["y"] = 7, ["z"] = 25, ["name"] = "default:wood"}, {["x"] = 1, ["y"] = 7, ["z"] = 26, ["name"] = "default:wood"}, {["x"] = 1, ["y"] = 7, ["z"] = 27, ["name"] = "default:wood"}, {["x"] = 1, ["y"] = 7, ["z"] = 28, ["name"] = "default:wood"}, {["x"] = 1, ["y"] = 7, ["z"] = 29, ["name"] = "default:wood"}, {["x"] = 1, ["y"] = 7, ["z"] = 30, ["name"] = "default:wood"}, {["x"] = 1, ["y"] = 7, ["z"] = 31, ["name"] = "default:wood"}, {["x"] = 2, ["y"] = 5, ["param1"] = 15, ["z"] = 25, ["name"] = "default:stone"}, {["x"] = 2, ["y"] = 5, ["param1"] = 15, ["z"] = 26, ["name"] = "default:stone"}, {["x"] = 2, ["y"] = 5, ["param1"] = 15, ["z"] = 27, ["name"] = "default:stone"}, {["x"] = 2, ["y"] = 6, ["param1"] = 15, ["z"] = 24, ["name"] = "default:stone"}, {["x"] = 2, ["y"] = 6, ["param1"] = 15, ["z"] = 25, ["name"] = "default:stone"}, {["x"] = 2, ["y"] = 6, ["param1"] = 15, ["z"] = 26, ["name"] = "default:stone"}, {["x"] = 2, ["y"] = 6, ["param1"] = 15, ["z"] = 27, ["name"] = "default:stone"}, {["x"] = 2, ["y"] = 6, ["param1"] = 15, ["z"] = 28, ["name"] = "default:stone"}, {["x"] = 2, ["y"] = 7, ["z"] = 21, ["name"] = "default:wood"}, {["x"] = 2, ["y"] = 7, ["z"] = 22, ["name"] = "default:wood"}, {["x"] = 2, ["y"] = 7, ["z"] = 23, ["name"] = "default:wood"}, {["x"] = 2, ["y"] = 7, ["param1"] = 15, ["z"] = 24, ["name"] = "default:dirt_with_grass"}, {["x"] = 2, ["y"] = 7, ["param1"] = 15, ["z"] = 25, ["name"] = "default:dirt_with_grass"}, {["x"] = 2, ["y"] = 7, ["param1"] = 15, ["z"] = 26, ["name"] = "default:dirt_with_grass"}, {["x"] = 2, ["y"] = 7, ["param1"] = 15, ["z"] = 27, ["name"] = "default:dirt_with_grass"}, {["x"] = 2, ["y"] = 7, ["param1"] = 15, ["z"] = 28, ["name"] = "default:dirt_with_grass"}, {["x"] = 2, ["y"] = 7, ["z"] = 29, ["name"] = "default:wood"}, {["x"] = 2, ["y"] = 7, ["z"] = 30, ["name"] = "default:wood"}, {["x"] = 2, ["y"] = 7, ["z"] = 31, ["name"] = "default:wood"}, {["x"] = 2, ["meta"] = {["fields"] = {["station_name"] = "Sky Island", ["formspec"] = "size[12,10]label[3.3,0.0;Travelnet-Box:]label[6.3,0.0;Punch box to update target list.]label[0.3,0.4;Name of this station:]label[6.3,0.4;Sky Island]label[0.3,0.8;Assigned to Network:]label[6.3,0.8;Air2]label[0.3,1.2;Owned by:]label[6.3,1.2;poikilos]label[3.3,1.6;Click on target to travel there:]button_exit[4,2.5;4,0.5;target;Stern at Air 2]button_exit[4,3.5;1,0.5;open_door;<>]label[4.9,3.35;Sky Island]", ["infotext"] = "Station 'Sky Island' on travelnet 'Air2' (owned by poikilos) ready for usage. Right-click to travel, punch to update.", ["timestamp"] = "1493154008", ["station_network"] = "Air2", ["owner"] = "poikilos"}, ["inventory"] = {}}, ["param2"] = 3, ["y"] = 8, ["param1"] = 175, ["z"] = 26, ["name"] = "travelnet:travelnet"}, {["x"] = 3, ["y"] = 4, ["param1"] = 15, ["z"] = 24, ["name"] = "default:stone"}, {["x"] = 3, ["y"] = 4, ["param1"] = 15, ["z"] = 25, ["name"] = "default:stone"}, {["x"] = 3, ["y"] = 4, ["param1"] = 15, ["z"] = 26, ["name"] = "default:stone"}, {["x"] = 3, ["y"] = 4, ["param1"] = 15, ["z"] = 27, ["name"] = "default:stone"}, {["x"] = 3, ["y"] = 4, ["param1"] = 15, ["z"] = 28, ["name"] = "default:stone"}, {["x"] = 3, ["y"] = 5, ["param1"] = 15, ["z"] = 23, ["name"] = "default:stone"}, {["x"] = 3, ["y"] = 5, ["param1"] = 15, ["z"] = 24, ["name"] = "default:stone"}, {["x"] = 3, ["y"] = 5, ["param1"] = 15, ["z"] = 25, ["name"] = "default:stone"}, {["x"] = 3, ["y"] = 5, ["param1"] = 15, ["z"] = 26, ["name"] = "default:stone"}, {["x"] = 3, ["y"] = 5, ["param1"] = 15, ["z"] = 27, ["name"] = "default:stone"}, {["x"] = 3, ["y"] = 5, ["param1"] = 15, ["z"] = 28, ["name"] = "default:stone"}, {["x"] = 3, ["y"] = 5, ["param1"] = 15, ["z"] = 29, ["name"] = "default:stone"}, {["x"] = 3, ["y"] = 6, ["param1"] = 15, ["z"] = 23, ["name"] = "default:stone"}, {["x"] = 3, ["y"] = 6, ["param1"] = 15, ["z"] = 24, ["name"] = "default:stone"}, {["x"] = 3, ["y"] = 6, ["param1"] = 15, ["z"] = 25, ["name"] = "default:stone"}, {["x"] = 3, ["y"] = 6, ["param1"] = 15, ["z"] = 26, ["name"] = "default:stone"}, {["x"] = 3, ["y"] = 6, ["param1"] = 15, ["z"] = 27, ["name"] = "default:stone"}, {["x"] = 3, ["y"] = 6, ["param1"] = 15, ["z"] = 28, ["name"] = "default:stone"}, {["x"] = 3, ["y"] = 6, ["param1"] = 15, ["z"] = 29, ["name"] = "default:stone"}, {["x"] = 3, ["y"] = 7, ["z"] = 21, ["name"] = "default:wood"}, {["x"] = 3, ["y"] = 7, ["z"] = 22, ["name"] = "default:wood"}, {["x"] = 3, ["y"] = 7, ["param1"] = 15, ["z"] = 23, ["name"] = "default:dirt_with_grass"}, {["x"] = 3, ["y"] = 7, ["param1"] = 15, ["z"] = 24, ["name"] = "default:dirt_with_grass"}, {["x"] = 3, ["y"] = 7, ["param1"] = 15, ["z"] = 25, ["name"] = "default:dirt_with_grass"}, {["x"] = 3, ["y"] = 7, ["param1"] = 15, ["z"] = 26, ["name"] = "default:dirt_with_grass"}, {["x"] = 3, ["y"] = 7, ["param1"] = 15, ["z"] = 27, ["name"] = "default:dirt_with_grass"}, {["x"] = 3, ["y"] = 7, ["param1"] = 15, ["z"] = 28, ["name"] = "default:dirt_with_grass"}, {["x"] = 3, ["y"] = 7, ["param1"] = 15, ["z"] = 29, ["name"] = "default:dirt_with_grass"}, {["x"] = 3, ["y"] = 7, ["z"] = 30, ["name"] = "default:wood"}, {["x"] = 3, ["y"] = 7, ["z"] = 31, ["name"] = "default:wood"}, {["x"] = 4, ["y"] = 3, ["param1"] = 15, ["z"] = 24, ["name"] = "default:stone"}, {["x"] = 4, ["y"] = 3, ["param1"] = 15, ["z"] = 25, ["name"] = "default:stone"}, {["x"] = 4, ["y"] = 3, ["param1"] = 15, ["z"] = 26, ["name"] = "default:stone"}, {["x"] = 4, ["y"] = 3, ["param1"] = 15, ["z"] = 27, ["name"] = "default:stone"}, {["x"] = 4, ["y"] = 3, ["param1"] = 15, ["z"] = 28, ["name"] = "default:stone"}, {["x"] = 4, ["y"] = 4, ["param1"] = 15, ["z"] = 23, ["name"] = "default:stone"}, {["x"] = 4, ["y"] = 4, ["param1"] = 15, ["z"] = 24, ["name"] = "default:stone"}, {["x"] = 4, ["y"] = 4, ["param1"] = 15, ["z"] = 25, ["name"] = "default:stone"}, {["x"] = 4, ["y"] = 4, ["param1"] = 15, ["z"] = 26, ["name"] = "default:stone"}, {["x"] = 4, ["y"] = 4, ["param1"] = 15, ["z"] = 27, ["name"] = "default:stone"}, {["x"] = 4, ["y"] = 4, ["param1"] = 15, ["z"] = 28, ["name"] = "default:stone"}, {["x"] = 4, ["y"] = 4, ["param1"] = 15, ["z"] = 29, ["name"] = "default:stone"}, {["x"] = 4, ["y"] = 5, ["param1"] = 15, ["z"] = 22, ["name"] = "default:stone"}, {["x"] = 4, ["y"] = 5, ["param1"] = 15, ["z"] = 23, ["name"] = "default:stone"}, {["x"] = 4, ["y"] = 5, ["param1"] = 15, ["z"] = 24, ["name"] = "default:stone"}, {["x"] = 4, ["y"] = 5, ["param1"] = 15, ["z"] = 25, ["name"] = "default:stone"}, {["x"] = 4, ["y"] = 5, ["param1"] = 15, ["z"] = 26, ["name"] = "default:stone"}, {["x"] = 4, ["y"] = 5, ["param1"] = 15, ["z"] = 27, ["name"] = "default:stone"}, {["x"] = 4, ["y"] = 5, ["param1"] = 15, ["z"] = 28, ["name"] = "default:stone"}, {["x"] = 4, ["y"] = 5, ["param1"] = 15, ["z"] = 29, ["name"] = "default:stone"}, {["x"] = 4, ["y"] = 5, ["param1"] = 15, ["z"] = 30, ["name"] = "default:stone"}, {["x"] = 4, ["y"] = 6, ["param1"] = 15, ["z"] = 22, ["name"] = "default:stone"}, {["x"] = 4, ["y"] = 6, ["param1"] = 15, ["z"] = 23, ["name"] = "default:stone"}, {["x"] = 4, ["y"] = 6, ["param1"] = 15, ["z"] = 24, ["name"] = "default:stone"}, {["x"] = 4, ["y"] = 6, ["param1"] = 15, ["z"] = 25, ["name"] = "default:stone"}, {["x"] = 4, ["y"] = 6, ["param1"] = 15, ["z"] = 26, ["name"] = "default:stone"}, {["x"] = 4, ["y"] = 6, ["param1"] = 15, ["z"] = 27, ["name"] = "default:stone"}, {["x"] = 4, ["y"] = 6, ["param1"] = 15, ["z"] = 28, ["name"] = "default:stone"}, {["x"] = 4, ["y"] = 6, ["param1"] = 15, ["z"] = 29, ["name"] = "default:stone"}, {["x"] = 4, ["y"] = 6, ["param1"] = 15, ["z"] = 30, ["name"] = "default:stone"}, {["x"] = 4, ["y"] = 7, ["z"] = 21, ["name"] = "default:wood"}, {["x"] = 4, ["y"] = 7, ["param1"] = 15, ["z"] = 22, ["name"] = "default:dirt_with_grass"}, {["x"] = 4, ["y"] = 7, ["param1"] = 15, ["z"] = 23, ["name"] = "default:dirt_with_grass"}, {["x"] = 4, ["y"] = 7, ["param1"] = 15, ["z"] = 24, ["name"] = "default:dirt_with_grass"}, {["x"] = 4, ["y"] = 7, ["param1"] = 15, ["z"] = 25, ["name"] = "default:dirt_with_grass"}, {["x"] = 4, ["y"] = 7, ["param1"] = 15, ["z"] = 26, ["name"] = "default:dirt_with_grass"}, {["x"] = 4, ["y"] = 7, ["param1"] = 15, ["z"] = 27, ["name"] = "default:dirt_with_grass"}, {["x"] = 4, ["y"] = 7, ["param1"] = 15, ["z"] = 28, ["name"] = "default:dirt_with_grass"}, {["x"] = 4, ["y"] = 7, ["param1"] = 15, ["z"] = 29, ["name"] = "default:dirt_with_grass"}, {["x"] = 4, ["y"] = 7, ["param1"] = 15, ["z"] = 30, ["name"] = "default:dirt_with_grass"}, {["x"] = 4, ["y"] = 7, ["z"] = 31, ["name"] = "default:wood"}, {["x"] = 5, ["y"] = 2, ["param1"] = 15, ["z"] = 25, ["name"] = "default:stone"}, {["x"] = 5, ["y"] = 2, ["param1"] = 15, ["z"] = 26, ["name"] = "default:stone"}, {["x"] = 5, ["y"] = 2, ["param1"] = 15, ["z"] = 27, ["name"] = "default:stone"}, {["x"] = 5, ["y"] = 3, ["param1"] = 15, ["z"] = 23, ["name"] = "default:stone"}, {["x"] = 5, ["y"] = 3, ["param1"] = 15, ["z"] = 24, ["name"] = "default:stone"}, {["x"] = 5, ["y"] = 3, ["param1"] = 15, ["z"] = 25, ["name"] = "default:stone"}, {["x"] = 5, ["y"] = 3, ["param1"] = 15, ["z"] = 26, ["name"] = "default:stone"}, {["x"] = 5, ["y"] = 3, ["param1"] = 15, ["z"] = 27, ["name"] = "default:stone"}, {["x"] = 5, ["y"] = 3, ["param1"] = 15, ["z"] = 28, ["name"] = "default:stone"}, {["x"] = 5, ["y"] = 3, ["param1"] = 15, ["z"] = 29, ["name"] = "default:stone"}, {["x"] = 5, ["y"] = 4, ["param1"] = 15, ["z"] = 22, ["name"] = "default:stone"}, {["x"] = 5, ["y"] = 4, ["param1"] = 15, ["z"] = 23, ["name"] = "default:stone"}, {["x"] = 5, ["y"] = 4, ["param1"] = 15, ["z"] = 24, ["name"] = "default:stone"}, {["x"] = 5, ["y"] = 4, ["param1"] = 15, ["z"] = 25, ["name"] = "default:stone"}, {["x"] = 5, ["y"] = 4, ["param1"] = 15, ["z"] = 26, ["name"] = "default:stone"}, {["x"] = 5, ["y"] = 4, ["param1"] = 15, ["z"] = 27, ["name"] = "default:stone"}, {["x"] = 5, ["y"] = 4, ["param1"] = 15, ["z"] = 28, ["name"] = "default:stone"}, {["x"] = 5, ["y"] = 4, ["param1"] = 15, ["z"] = 29, ["name"] = "default:stone"}, {["x"] = 5, ["y"] = 4, ["param1"] = 15, ["z"] = 30, ["name"] = "default:stone"}, {["x"] = 5, ["y"] = 5, ["param1"] = 15, ["z"] = 22, ["name"] = "default:stone"}, {["x"] = 5, ["y"] = 5, ["param1"] = 15, ["z"] = 23, ["name"] = "default:stone"}, {["x"] = 5, ["y"] = 5, ["param1"] = 15, ["z"] = 24, ["name"] = "default:stone"}, {["x"] = 5, ["y"] = 5, ["param1"] = 15, ["z"] = 25, ["name"] = "default:stone"}, {["x"] = 5, ["y"] = 5, ["param1"] = 15, ["z"] = 26, ["name"] = "default:stone"}, {["x"] = 5, ["y"] = 5, ["param1"] = 15, ["z"] = 27, ["name"] = "default:stone"}, {["x"] = 5, ["y"] = 5, ["param1"] = 15, ["z"] = 28, ["name"] = "default:stone"}, {["x"] = 5, ["y"] = 5, ["param1"] = 15, ["z"] = 29, ["name"] = "default:stone"}, {["x"] = 5, ["y"] = 5, ["param1"] = 15, ["z"] = 30, ["name"] = "default:stone"}, {["x"] = 5, ["y"] = 6, ["param1"] = 15, ["z"] = 21, ["name"] = "default:stone"}, {["x"] = 5, ["y"] = 6, ["param1"] = 15, ["z"] = 22, ["name"] = "default:stone"}, {["x"] = 5, ["y"] = 6, ["param1"] = 15, ["z"] = 23, ["name"] = "default:stone"}, {["x"] = 5, ["y"] = 6, ["param1"] = 15, ["z"] = 24, ["name"] = "default:stone"}, {["x"] = 5, ["y"] = 6, ["param1"] = 15, ["z"] = 25, ["name"] = "default:stone"}, {["x"] = 5, ["y"] = 6, ["param1"] = 15, ["z"] = 26, ["name"] = "default:stone"}, {["x"] = 5, ["y"] = 6, ["param1"] = 15, ["z"] = 27, ["name"] = "default:stone"}, {["x"] = 5, ["y"] = 6, ["param1"] = 15, ["z"] = 28, ["name"] = "default:stone"}, {["x"] = 5, ["y"] = 6, ["param1"] = 15, ["z"] = 29, ["name"] = "default:stone"}, {["x"] = 5, ["y"] = 6, ["param1"] = 15, ["z"] = 30, ["name"] = "default:stone"}, {["x"] = 5, ["y"] = 6, ["param1"] = 15, ["z"] = 31, ["name"] = "default:stone"}, {["x"] = 5, ["y"] = 7, ["param1"] = 15, ["z"] = 21, ["name"] = "default:dirt_with_grass"}, {["x"] = 5, ["y"] = 7, ["param1"] = 15, ["z"] = 22, ["name"] = "default:dirt_with_grass"}, {["x"] = 5, ["y"] = 7, ["param1"] = 15, ["z"] = 23, ["name"] = "default:dirt_with_grass"}, {["x"] = 5, ["y"] = 7, ["param1"] = 15, ["z"] = 24, ["name"] = "default:dirt_with_grass"}, {["x"] = 5, ["y"] = 7, ["param1"] = 15, ["z"] = 25, ["name"] = "default:dirt_with_grass"}, {["x"] = 5, ["y"] = 7, ["param1"] = 15, ["z"] = 26, ["name"] = "default:dirt_with_grass"}, {["x"] = 5, ["y"] = 7, ["param1"] = 15, ["z"] = 27, ["name"] = "default:dirt_with_grass"}, {["x"] = 5, ["y"] = 7, ["param1"] = 15, ["z"] = 28, ["name"] = "default:dirt_with_grass"}, {["x"] = 5, ["y"] = 7, ["param1"] = 15, ["z"] = 29, ["name"] = "default:dirt_with_grass"}, {["x"] = 5, ["y"] = 7, ["param1"] = 15, ["z"] = 30, ["name"] = "default:dirt_with_grass"}, {["x"] = 5, ["y"] = 7, ["param1"] = 15, ["z"] = 31, ["name"] = "default:dirt_with_grass"}, {["x"] = 6, ["y"] = 2, ["param1"] = 15, ["z"] = 24, ["name"] = "default:stone"}, {["x"] = 6, ["y"] = 2, ["param1"] = 15, ["z"] = 25, ["name"] = "default:stone"}, {["x"] = 6, ["y"] = 2, ["param1"] = 15, ["z"] = 26, ["name"] = "default:stone"}, {["x"] = 6, ["y"] = 2, ["param1"] = 15, ["z"] = 27, ["name"] = "default:stone"}, {["x"] = 6, ["y"] = 2, ["param1"] = 15, ["z"] = 28, ["name"] = "default:stone"}, {["x"] = 6, ["y"] = 3, ["param1"] = 15, ["z"] = 23, ["name"] = "default:stone"}, {["x"] = 6, ["y"] = 3, ["param1"] = 15, ["z"] = 24, ["name"] = "default:stone"}, {["x"] = 6, ["y"] = 3, ["param1"] = 15, ["z"] = 25, ["name"] = "default:stone"}, {["x"] = 6, ["y"] = 3, ["param1"] = 15, ["z"] = 26, ["name"] = "default:stone"}, {["x"] = 6, ["y"] = 3, ["param1"] = 15, ["z"] = 27, ["name"] = "default:stone"}, {["x"] = 6, ["y"] = 3, ["param1"] = 15, ["z"] = 28, ["name"] = "default:stone"}, {["x"] = 6, ["y"] = 3, ["param1"] = 15, ["z"] = 29, ["name"] = "default:stone"}, {["x"] = 6, ["y"] = 4, ["param1"] = 15, ["z"] = 22, ["name"] = "default:stone"}, {["x"] = 6, ["y"] = 4, ["param1"] = 15, ["z"] = 23, ["name"] = "default:stone"}, {["x"] = 6, ["y"] = 4, ["param1"] = 15, ["z"] = 24, ["name"] = "default:stone"}, {["x"] = 6, ["y"] = 4, ["param1"] = 15, ["z"] = 25, ["name"] = "default:stone"}, {["x"] = 6, ["y"] = 4, ["param1"] = 15, ["z"] = 26, ["name"] = "default:stone"}, {["x"] = 6, ["y"] = 4, ["param1"] = 15, ["z"] = 27, ["name"] = "default:stone"}, {["x"] = 6, ["y"] = 4, ["param1"] = 15, ["z"] = 28, ["name"] = "default:stone"}, {["x"] = 6, ["y"] = 4, ["param1"] = 15, ["z"] = 29, ["name"] = "default:stone"}, {["x"] = 6, ["y"] = 4, ["param1"] = 15, ["z"] = 30, ["name"] = "default:stone"}, {["x"] = 6, ["y"] = 5, ["param1"] = 15, ["z"] = 21, ["name"] = "default:stone"}, {["x"] = 6, ["y"] = 5, ["param1"] = 15, ["z"] = 22, ["name"] = "default:stone"}, {["x"] = 6, ["y"] = 5, ["param1"] = 15, ["z"] = 23, ["name"] = "default:stone"}, {["x"] = 6, ["y"] = 5, ["param1"] = 15, ["z"] = 24, ["name"] = "default:stone"}, {["x"] = 6, ["y"] = 5, ["param1"] = 15, ["z"] = 25, ["name"] = "default:stone"}, {["x"] = 6, ["y"] = 5, ["param1"] = 15, ["z"] = 26, ["name"] = "default:stone"}, {["x"] = 6, ["y"] = 5, ["param1"] = 15, ["z"] = 27, ["name"] = "default:stone"}, {["x"] = 6, ["y"] = 5, ["param1"] = 15, ["z"] = 28, ["name"] = "default:stone"}, {["x"] = 6, ["y"] = 5, ["param1"] = 15, ["z"] = 29, ["name"] = "default:stone"}, {["x"] = 6, ["y"] = 5, ["param1"] = 15, ["z"] = 30, ["name"] = "default:stone"}, {["x"] = 6, ["y"] = 5, ["param1"] = 15, ["z"] = 31, ["name"] = "default:stone"}, {["x"] = 6, ["y"] = 6, ["param1"] = 15, ["z"] = 21, ["name"] = "default:stone"}, {["x"] = 6, ["y"] = 6, ["param1"] = 15, ["z"] = 22, ["name"] = "default:stone"}, {["x"] = 6, ["y"] = 6, ["param1"] = 15, ["z"] = 23, ["name"] = "default:stone"}, {["x"] = 6, ["y"] = 6, ["param1"] = 15, ["z"] = 24, ["name"] = "default:stone"}, {["x"] = 6, ["y"] = 6, ["param1"] = 15, ["z"] = 25, ["name"] = "default:stone"}, {["x"] = 6, ["y"] = 6, ["param1"] = 15, ["z"] = 26, ["name"] = "default:stone"}, {["x"] = 6, ["y"] = 6, ["param1"] = 15, ["z"] = 27, ["name"] = "default:stone"}, {["x"] = 6, ["y"] = 6, ["param1"] = 15, ["z"] = 28, ["name"] = "default:stone"}, {["x"] = 6, ["y"] = 6, ["param1"] = 15, ["z"] = 29, ["name"] = "default:stone"}, {["x"] = 6, ["y"] = 6, ["param1"] = 15, ["z"] = 30, ["name"] = "default:stone"}, {["x"] = 6, ["y"] = 6, ["param1"] = 15, ["z"] = 31, ["name"] = "default:stone"}, {["x"] = 6, ["y"] = 7, ["param1"] = 15, ["z"] = 21, ["name"] = "default:dirt_with_grass"}, {["x"] = 6, ["y"] = 7, ["param1"] = 15, ["z"] = 22, ["name"] = "default:dirt_with_grass"}, {["x"] = 6, ["y"] = 7, ["param1"] = 15, ["z"] = 23, ["name"] = "default:dirt_with_grass"}, {["x"] = 6, ["y"] = 7, ["param1"] = 15, ["z"] = 24, ["name"] = "default:dirt_with_grass"}, {["x"] = 6, ["y"] = 7, ["param1"] = 15, ["z"] = 25, ["name"] = "default:dirt_with_grass"}, {["x"] = 6, ["y"] = 7, ["param1"] = 15, ["z"] = 26, ["name"] = "default:dirt_with_grass"}, {["x"] = 6, ["y"] = 7, ["param1"] = 15, ["z"] = 27, ["name"] = "default:dirt_with_grass"}, {["x"] = 6, ["y"] = 7, ["param1"] = 15, ["z"] = 28, ["name"] = "default:dirt_with_grass"}, {["x"] = 6, ["y"] = 7, ["param1"] = 15, ["z"] = 29, ["name"] = "default:dirt_with_grass"}, {["x"] = 6, ["y"] = 7, ["param1"] = 15, ["z"] = 30, ["name"] = "default:dirt_with_grass"}, {["x"] = 6, ["y"] = 7, ["param1"] = 15, ["z"] = 31, ["name"] = "default:dirt_with_grass"}, {["x"] = 6, ["meta"] = {["fields"] = {["owner"] = "thefox963", ["members"] = "yelby", ["infotext"] = "Protection (owned by thefox963)"}, ["inventory"] = {}}, ["param2"] = 1, ["y"] = 8, ["param1"] = 111, ["z"] = 26, ["name"] = "protector:protect2"}, {["x"] = 7, ["y"] = 2, ["param1"] = 15, ["z"] = 24, ["name"] = "default:stone"}, {["x"] = 7, ["y"] = 2, ["param1"] = 15, ["z"] = 25, ["name"] = "default:stone"}, {["x"] = 7, ["y"] = 2, ["param1"] = 14, ["z"] = 26, ["name"] = "default:stone"}, {["x"] = 7, ["y"] = 2, ["param1"] = 15, ["z"] = 27, ["name"] = "default:stone"}, {["x"] = 7, ["y"] = 2, ["param1"] = 15, ["z"] = 28, ["name"] = "default:stone"}, {["x"] = 7, ["y"] = 3, ["param1"] = 15, ["z"] = 23, ["name"] = "default:stone"}, {["x"] = 7, ["y"] = 3, ["param1"] = 15, ["z"] = 24, ["name"] = "default:stone"}, {["x"] = 7, ["y"] = 3, ["param1"] = 15, ["z"] = 25, ["name"] = "default:stone"}, {["x"] = 7, ["y"] = 3, ["param1"] = 14, ["z"] = 26, ["name"] = "default:stone"}, {["x"] = 7, ["y"] = 3, ["param1"] = 15, ["z"] = 27, ["name"] = "default:stone"}, {["x"] = 7, ["y"] = 3, ["param1"] = 15, ["z"] = 28, ["name"] = "default:stone"}, {["x"] = 7, ["y"] = 3, ["param1"] = 15, ["z"] = 29, ["name"] = "default:stone"}, {["x"] = 7, ["y"] = 4, ["param1"] = 15, ["z"] = 22, ["name"] = "default:stone"}, {["x"] = 7, ["y"] = 4, ["param1"] = 15, ["z"] = 23, ["name"] = "default:stone"}, {["x"] = 7, ["y"] = 4, ["param1"] = 15, ["z"] = 24, ["name"] = "default:stone"}, {["x"] = 7, ["y"] = 4, ["param1"] = 15, ["z"] = 25, ["name"] = "default:stone"}, {["x"] = 7, ["y"] = 4, ["param1"] = 14, ["z"] = 26, ["name"] = "default:stone"}, {["x"] = 7, ["y"] = 4, ["param1"] = 15, ["z"] = 27, ["name"] = "default:stone"}, {["x"] = 7, ["y"] = 4, ["param1"] = 15, ["z"] = 28, ["name"] = "default:stone"}, {["x"] = 7, ["y"] = 4, ["param1"] = 15, ["z"] = 29, ["name"] = "default:stone"}, {["x"] = 7, ["y"] = 4, ["param1"] = 15, ["z"] = 30, ["name"] = "default:stone"}, {["x"] = 7, ["y"] = 5, ["param1"] = 15, ["z"] = 21, ["name"] = "default:stone"}, {["x"] = 7, ["y"] = 5, ["param1"] = 15, ["z"] = 22, ["name"] = "default:stone"}, {["x"] = 7, ["y"] = 5, ["param1"] = 15, ["z"] = 23, ["name"] = "default:stone"}, {["x"] = 7, ["y"] = 5, ["param1"] = 15, ["z"] = 24, ["name"] = "default:stone"}, {["x"] = 7, ["y"] = 5, ["param1"] = 15, ["z"] = 25, ["name"] = "default:stone"}, {["x"] = 7, ["y"] = 5, ["param1"] = 14, ["z"] = 26, ["name"] = "default:stone"}, {["x"] = 7, ["y"] = 5, ["param1"] = 15, ["z"] = 27, ["name"] = "default:stone"}, {["x"] = 7, ["y"] = 5, ["param1"] = 15, ["z"] = 28, ["name"] = "default:stone"}, {["x"] = 7, ["y"] = 5, ["param1"] = 15, ["z"] = 29, ["name"] = "default:stone"}, {["x"] = 7, ["y"] = 5, ["param1"] = 15, ["z"] = 30, ["name"] = "default:stone"}, {["x"] = 7, ["y"] = 5, ["param1"] = 15, ["z"] = 31, ["name"] = "default:stone"}, {["x"] = 7, ["y"] = 6, ["param1"] = 15, ["z"] = 21, ["name"] = "default:stone"}, {["x"] = 7, ["y"] = 6, ["param1"] = 15, ["z"] = 22, ["name"] = "default:stone"}, {["x"] = 7, ["y"] = 6, ["param1"] = 15, ["z"] = 23, ["name"] = "default:stone"}, {["x"] = 7, ["y"] = 6, ["param1"] = 15, ["z"] = 24, ["name"] = "default:stone"}, {["x"] = 7, ["y"] = 6, ["param1"] = 15, ["z"] = 25, ["name"] = "default:stone"}, {["x"] = 7, ["y"] = 6, ["param1"] = 14, ["z"] = 26, ["name"] = "default:stone"}, {["x"] = 7, ["y"] = 6, ["param1"] = 15, ["z"] = 27, ["name"] = "default:stone"}, {["x"] = 7, ["y"] = 6, ["param1"] = 15, ["z"] = 28, ["name"] = "default:stone"}, {["x"] = 7, ["y"] = 6, ["param1"] = 15, ["z"] = 29, ["name"] = "default:stone"}, {["x"] = 7, ["y"] = 6, ["param1"] = 15, ["z"] = 30, ["name"] = "default:stone"}, {["x"] = 7, ["y"] = 6, ["param1"] = 15, ["z"] = 31, ["name"] = "default:stone"}, {["x"] = 7, ["y"] = 7, ["param1"] = 15, ["z"] = 21, ["name"] = "default:dirt_with_grass"}, {["x"] = 7, ["y"] = 7, ["param1"] = 15, ["z"] = 22, ["name"] = "default:dirt_with_grass"}, {["x"] = 7, ["y"] = 7, ["param1"] = 15, ["z"] = 23, ["name"] = "default:dirt_with_grass"}, {["x"] = 7, ["y"] = 7, ["param1"] = 15, ["z"] = 24, ["name"] = "default:dirt_with_grass"}, {["x"] = 7, ["y"] = 7, ["param1"] = 15, ["z"] = 25, ["name"] = "default:dirt_with_grass"}, {["x"] = 7, ["y"] = 7, ["z"] = 26, ["name"] = "default:dirt_with_grass"}, {["x"] = 7, ["y"] = 7, ["z"] = 27, ["name"] = "default:dirt_with_grass"}, {["x"] = 7, ["y"] = 7, ["z"] = 28, ["name"] = "default:dirt_with_grass"}, {["x"] = 7, ["y"] = 7, ["param1"] = 15, ["z"] = 29, ["name"] = "default:dirt_with_grass"}, {["x"] = 7, ["y"] = 7, ["param1"] = 15, ["z"] = 30, ["name"] = "default:dirt_with_grass"}, {["x"] = 7, ["y"] = 7, ["param1"] = 15, ["z"] = 31, ["name"] = "default:dirt_with_grass"}, {["x"] = 8, ["y"] = 2, ["param1"] = 15, ["z"] = 24, ["name"] = "default:stone"}, {["x"] = 8, ["y"] = 2, ["param1"] = 15, ["z"] = 25, ["name"] = "default:stone"}, {["x"] = 8, ["y"] = 2, ["param1"] = 14, ["z"] = 26, ["name"] = "default:stone"}, {["x"] = 8, ["y"] = 2, ["param1"] = 15, ["z"] = 27, ["name"] = "default:stone"}, {["x"] = 8, ["y"] = 2, ["param1"] = 15, ["z"] = 28, ["name"] = "default:stone"}, {["x"] = 8, ["y"] = 3, ["param1"] = 15, ["z"] = 23, ["name"] = "default:stone"}, {["x"] = 8, ["y"] = 3, ["param1"] = 15, ["z"] = 24, ["name"] = "default:stone"}, {["x"] = 8, ["y"] = 3, ["param1"] = 15, ["z"] = 25, ["name"] = "default:stone"}, {["x"] = 8, ["y"] = 3, ["param1"] = 14, ["z"] = 26, ["name"] = "default:stone"}, {["x"] = 8, ["y"] = 3, ["param1"] = 15, ["z"] = 27, ["name"] = "default:stone"}, {["x"] = 8, ["y"] = 3, ["param1"] = 15, ["z"] = 28, ["name"] = "default:stone"}, {["x"] = 8, ["y"] = 3, ["param1"] = 15, ["z"] = 29, ["name"] = "default:stone"}, {["x"] = 8, ["y"] = 4, ["param1"] = 15, ["z"] = 22, ["name"] = "default:stone"}, {["x"] = 8, ["y"] = 4, ["param1"] = 15, ["z"] = 23, ["name"] = "default:stone"}, {["x"] = 8, ["y"] = 4, ["param1"] = 15, ["z"] = 24, ["name"] = "default:stone"}, {["x"] = 8, ["y"] = 4, ["param1"] = 15, ["z"] = 25, ["name"] = "default:stone"}, {["x"] = 8, ["y"] = 4, ["param1"] = 14, ["z"] = 26, ["name"] = "default:stone"}, {["x"] = 8, ["y"] = 4, ["param1"] = 15, ["z"] = 27, ["name"] = "default:stone"}, {["x"] = 8, ["y"] = 4, ["param1"] = 15, ["z"] = 28, ["name"] = "default:stone"}, {["x"] = 8, ["y"] = 4, ["param1"] = 15, ["z"] = 29, ["name"] = "default:stone"}, {["x"] = 8, ["y"] = 4, ["param1"] = 15, ["z"] = 30, ["name"] = "default:stone"}, {["x"] = 8, ["y"] = 5, ["param1"] = 15, ["z"] = 21, ["name"] = "default:stone"}, {["x"] = 8, ["y"] = 5, ["param1"] = 15, ["z"] = 22, ["name"] = "default:stone"}, {["x"] = 8, ["y"] = 5, ["param1"] = 15, ["z"] = 23, ["name"] = "default:stone"}, {["x"] = 8, ["y"] = 5, ["param1"] = 15, ["z"] = 24, ["name"] = "default:stone"}, {["x"] = 8, ["y"] = 5, ["param1"] = 15, ["z"] = 25, ["name"] = "default:stone"}, {["x"] = 8, ["y"] = 5, ["param1"] = 14, ["z"] = 26, ["name"] = "default:stone"}, {["x"] = 8, ["y"] = 5, ["param1"] = 15, ["z"] = 27, ["name"] = "default:stone"}, {["x"] = 8, ["y"] = 5, ["param1"] = 15, ["z"] = 28, ["name"] = "default:stone"}, {["x"] = 8, ["y"] = 5, ["param1"] = 15, ["z"] = 29, ["name"] = "default:stone"}, {["x"] = 8, ["y"] = 5, ["param1"] = 15, ["z"] = 30, ["name"] = "default:stone"}, {["x"] = 8, ["y"] = 5, ["param1"] = 15, ["z"] = 31, ["name"] = "default:stone"}, {["x"] = 8, ["y"] = 6, ["param1"] = 15, ["z"] = 21, ["name"] = "default:stone"}, {["x"] = 8, ["y"] = 6, ["param1"] = 15, ["z"] = 22, ["name"] = "default:stone"}, {["x"] = 8, ["y"] = 6, ["param1"] = 15, ["z"] = 23, ["name"] = "default:stone"}, {["x"] = 8, ["y"] = 6, ["param1"] = 15, ["z"] = 24, ["name"] = "default:stone"}, {["x"] = 8, ["y"] = 6, ["param1"] = 15, ["z"] = 25, ["name"] = "default:stone"}, {["x"] = 8, ["y"] = 6, ["param1"] = 14, ["z"] = 26, ["name"] = "default:stone"}, {["x"] = 8, ["y"] = 6, ["z"] = 27, ["name"] = "default:cobble"}, {["x"] = 8, ["y"] = 6, ["param1"] = 15, ["z"] = 28, ["name"] = "default:stone"}, {["x"] = 8, ["y"] = 6, ["param1"] = 15, ["z"] = 29, ["name"] = "default:stone"}, {["x"] = 8, ["y"] = 6, ["param1"] = 15, ["z"] = 30, ["name"] = "default:stone"}, {["x"] = 8, ["y"] = 6, ["param1"] = 15, ["z"] = 31, ["name"] = "default:stone"}, {["x"] = 8, ["y"] = 7, ["param1"] = 15, ["z"] = 21, ["name"] = "default:dirt_with_grass"}, {["x"] = 8, ["y"] = 7, ["param1"] = 15, ["z"] = 22, ["name"] = "default:dirt_with_grass"}, {["x"] = 8, ["y"] = 7, ["param1"] = 15, ["z"] = 23, ["name"] = "default:dirt_with_grass"}, {["x"] = 8, ["y"] = 7, ["param1"] = 15, ["z"] = 24, ["name"] = "default:dirt_with_grass"}, {["x"] = 8, ["y"] = 7, ["z"] = 25, ["name"] = "default:dirt_with_grass"}, {["x"] = 8, ["y"] = 7, ["z"] = 26, ["name"] = "default:dirt_with_grass"}, {["x"] = 8, ["y"] = 7, ["z"] = 27, ["name"] = "default:dirt_with_grass"}, {["x"] = 8, ["y"] = 7, ["z"] = 28, ["name"] = "default:dirt_with_grass"}, {["x"] = 8, ["y"] = 7, ["param1"] = 15, ["z"] = 29, ["name"] = "default:dirt_with_grass"}, {["x"] = 8, ["y"] = 7, ["param1"] = 15, ["z"] = 30, ["name"] = "default:dirt_with_grass"}, {["x"] = 8, ["y"] = 7, ["param1"] = 15, ["z"] = 31, ["name"] = "default:dirt_with_grass"}, {["x"] = 9, ["y"] = 2, ["param1"] = 15, ["z"] = 25, ["name"] = "default:stone"}, {["x"] = 9, ["y"] = 2, ["param1"] = 14, ["z"] = 26, ["name"] = "default:stone"}, {["x"] = 9, ["y"] = 2, ["param1"] = 15, ["z"] = 27, ["name"] = "default:stone"}, {["x"] = 9, ["y"] = 3, ["param1"] = 15, ["z"] = 23, ["name"] = "default:stone"}, {["x"] = 9, ["y"] = 3, ["param1"] = 15, ["z"] = 24, ["name"] = "default:stone"}, {["x"] = 9, ["y"] = 3, ["param1"] = 15, ["z"] = 25, ["name"] = "default:stone"}, {["x"] = 9, ["y"] = 3, ["param1"] = 14, ["z"] = 26, ["name"] = "default:stone"}, {["x"] = 9, ["y"] = 3, ["param1"] = 15, ["z"] = 27, ["name"] = "default:stone"}, {["x"] = 9, ["y"] = 3, ["param1"] = 15, ["z"] = 28, ["name"] = "default:stone"}, {["x"] = 9, ["y"] = 3, ["param1"] = 15, ["z"] = 29, ["name"] = "default:stone"}, {["x"] = 9, ["y"] = 4, ["param1"] = 15, ["z"] = 22, ["name"] = "default:stone"}, {["x"] = 9, ["y"] = 4, ["param1"] = 15, ["z"] = 23, ["name"] = "default:stone"}, {["x"] = 9, ["y"] = 4, ["param1"] = 15, ["z"] = 24, ["name"] = "default:stone"}, {["x"] = 9, ["y"] = 4, ["param1"] = 15, ["z"] = 25, ["name"] = "default:stone"}, {["x"] = 9, ["y"] = 4, ["param1"] = 14, ["z"] = 26, ["name"] = "default:stone"}, {["x"] = 9, ["y"] = 4, ["param1"] = 15, ["z"] = 27, ["name"] = "default:stone"}, {["x"] = 9, ["y"] = 4, ["param1"] = 15, ["z"] = 28, ["name"] = "default:stone"}, {["x"] = 9, ["y"] = 4, ["param1"] = 15, ["z"] = 29, ["name"] = "default:stone"}, {["x"] = 9, ["y"] = 4, ["param1"] = 15, ["z"] = 30, ["name"] = "default:stone"}, {["x"] = 9, ["y"] = 5, ["param1"] = 15, ["z"] = 22, ["name"] = "default:stone"}, {["x"] = 9, ["y"] = 5, ["param1"] = 15, ["z"] = 23, ["name"] = "default:stone"}, {["x"] = 9, ["y"] = 5, ["param1"] = 15, ["z"] = 24, ["name"] = "default:stone"}, {["x"] = 9, ["y"] = 5, ["param1"] = 15, ["z"] = 25, ["name"] = "default:stone"}, {["x"] = 9, ["y"] = 5, ["param1"] = 14, ["z"] = 26, ["name"] = "default:stone"}, {["x"] = 9, ["y"] = 5, ["param1"] = 15, ["z"] = 27, ["name"] = "default:stone"}, {["x"] = 9, ["y"] = 5, ["param1"] = 15, ["z"] = 28, ["name"] = "default:stone"}, {["x"] = 9, ["y"] = 5, ["param1"] = 15, ["z"] = 29, ["name"] = "default:stone"}, {["x"] = 9, ["y"] = 5, ["param1"] = 15, ["z"] = 30, ["name"] = "default:stone"}, {["x"] = 9, ["y"] = 6, ["param1"] = 15, ["z"] = 21, ["name"] = "default:stone"}, {["x"] = 9, ["y"] = 6, ["param1"] = 15, ["z"] = 22, ["name"] = "default:stone"}, {["x"] = 9, ["y"] = 6, ["param1"] = 15, ["z"] = 23, ["name"] = "default:stone"}, {["x"] = 9, ["y"] = 6, ["param1"] = 15, ["z"] = 24, ["name"] = "default:stone"}, {["x"] = 9, ["y"] = 6, ["param1"] = 15, ["z"] = 25, ["name"] = "default:stone"}, {["x"] = 9, ["y"] = 6, ["param1"] = 14, ["z"] = 26, ["name"] = "default:stone"}, {["x"] = 9, ["y"] = 6, ["param1"] = 15, ["z"] = 27, ["name"] = "default:stone"}, {["x"] = 9, ["y"] = 6, ["param1"] = 15, ["z"] = 28, ["name"] = "default:stone"}, {["x"] = 9, ["y"] = 6, ["param1"] = 15, ["z"] = 29, ["name"] = "default:stone"}, {["x"] = 9, ["y"] = 6, ["param1"] = 15, ["z"] = 30, ["name"] = "default:stone"}, {["x"] = 9, ["y"] = 6, ["param1"] = 15, ["z"] = 31, ["name"] = "default:stone"}, {["x"] = 9, ["y"] = 7, ["param1"] = 15, ["z"] = 21, ["name"] = "default:dirt_with_grass"}, {["x"] = 9, ["y"] = 7, ["param1"] = 15, ["z"] = 22, ["name"] = "default:dirt_with_grass"}, {["x"] = 9, ["y"] = 7, ["param1"] = 15, ["z"] = 23, ["name"] = "default:dirt_with_grass"}, {["x"] = 9, ["y"] = 7, ["param1"] = 15, ["z"] = 24, ["name"] = "default:dirt_with_grass"}, {["x"] = 9, ["y"] = 7, ["param1"] = 15, ["z"] = 25, ["name"] = "default:dirt_with_grass"}, {["x"] = 9, ["y"] = 7, ["z"] = 26, ["name"] = "default:dirt_with_grass"}, {["x"] = 9, ["y"] = 7, ["z"] = 27, ["name"] = "default:dirt_with_grass"}, {["x"] = 9, ["y"] = 7, ["z"] = 28, ["name"] = "default:dirt_with_grass"}, {["x"] = 9, ["y"] = 7, ["param1"] = 15, ["z"] = 29, ["name"] = "default:dirt_with_grass"}, {["x"] = 9, ["y"] = 7, ["param1"] = 15, ["z"] = 30, ["name"] = "default:dirt_with_grass"}, {["x"] = 9, ["y"] = 7, ["param1"] = 15, ["z"] = 31, ["name"] = "default:dirt_with_grass"}, {["x"] = 10, ["y"] = 3, ["param1"] = 15, ["z"] = 24, ["name"] = "default:stone"}, {["x"] = 10, ["y"] = 3, ["param1"] = 15, ["z"] = 25, ["name"] = "default:stone"}, {["x"] = 10, ["y"] = 3, ["param1"] = 14, ["z"] = 26, ["name"] = "default:stone"}, {["x"] = 10, ["y"] = 3, ["param1"] = 15, ["z"] = 27, ["name"] = "default:stone"}, {["x"] = 10, ["y"] = 3, ["param1"] = 15, ["z"] = 28, ["name"] = "default:stone"}, {["x"] = 10, ["y"] = 4, ["param1"] = 15, ["z"] = 23, ["name"] = "default:stone"}, {["x"] = 10, ["y"] = 4, ["param1"] = 15, ["z"] = 24, ["name"] = "default:stone"}, {["x"] = 10, ["y"] = 4, ["param1"] = 15, ["z"] = 25, ["name"] = "default:stone"}, {["x"] = 10, ["y"] = 4, ["param1"] = 14, ["z"] = 26, ["name"] = "default:stone"}, {["x"] = 10, ["y"] = 4, ["param1"] = 15, ["z"] = 27, ["name"] = "default:stone"}, {["x"] = 10, ["y"] = 4, ["param1"] = 15, ["z"] = 28, ["name"] = "default:stone"}, {["x"] = 10, ["y"] = 4, ["param1"] = 15, ["z"] = 29, ["name"] = "default:stone"}, {["x"] = 10, ["y"] = 5, ["param1"] = 15, ["z"] = 22, ["name"] = "default:stone"}, {["x"] = 10, ["y"] = 5, ["param1"] = 15, ["z"] = 23, ["name"] = "default:stone"}, {["x"] = 10, ["y"] = 5, ["param1"] = 15, ["z"] = 24, ["name"] = "default:stone"}, {["x"] = 10, ["y"] = 5, ["param1"] = 15, ["z"] = 25, ["name"] = "default:stone"}, {["x"] = 10, ["y"] = 5, ["param1"] = 14, ["z"] = 26, ["name"] = "default:stone"}, {["x"] = 10, ["y"] = 5, ["param1"] = 15, ["z"] = 27, ["name"] = "default:stone"}, {["x"] = 10, ["y"] = 5, ["param1"] = 15, ["z"] = 28, ["name"] = "default:stone"}, {["x"] = 10, ["y"] = 5, ["param1"] = 15, ["z"] = 29, ["name"] = "default:stone"}, {["x"] = 10, ["y"] = 5, ["param1"] = 15, ["z"] = 30, ["name"] = "default:stone"}, {["x"] = 10, ["y"] = 6, ["param1"] = 15, ["z"] = 22, ["name"] = "default:stone"}, {["x"] = 10, ["y"] = 6, ["param1"] = 15, ["z"] = 23, ["name"] = "default:stone"}, {["x"] = 10, ["y"] = 6, ["param1"] = 15, ["z"] = 24, ["name"] = "default:stone"}, {["x"] = 10, ["y"] = 6, ["param1"] = 15, ["z"] = 25, ["name"] = "default:stone"}, {["x"] = 10, ["y"] = 6, ["param1"] = 14, ["z"] = 26, ["name"] = "default:stone"}, {["x"] = 10, ["y"] = 6, ["param1"] = 15, ["z"] = 27, ["name"] = "default:stone"}, {["x"] = 10, ["y"] = 6, ["param1"] = 15, ["z"] = 28, ["name"] = "default:stone"}, {["x"] = 10, ["y"] = 6, ["param1"] = 15, ["z"] = 29, ["name"] = "default:stone"}, {["x"] = 10, ["y"] = 6, ["param1"] = 15, ["z"] = 30, ["name"] = "default:stone"}, {["x"] = 10, ["y"] = 7, ["param1"] = 15, ["z"] = 22, ["name"] = "default:dirt_with_grass"}, {["x"] = 10, ["y"] = 7, ["param1"] = 15, ["z"] = 23, ["name"] = "default:dirt_with_grass"}, {["x"] = 10, ["y"] = 7, ["param1"] = 15, ["z"] = 24, ["name"] = "default:dirt_with_grass"}, {["x"] = 10, ["y"] = 7, ["z"] = 25, ["name"] = "default:dirt_with_grass"}, {["x"] = 10, ["y"] = 7, ["z"] = 26, ["name"] = "default:dirt_with_grass"}, {["x"] = 10, ["y"] = 7, ["param1"] = 15, ["z"] = 27, ["name"] = "default:dirt_with_grass"}, {["x"] = 10, ["y"] = 7, ["param1"] = 15, ["z"] = 28, ["name"] = "default:dirt_with_grass"}, {["x"] = 10, ["y"] = 7, ["param1"] = 15, ["z"] = 29, ["name"] = "default:dirt_with_grass"}, {["x"] = 10, ["y"] = 7, ["param1"] = 15, ["z"] = 30, ["name"] = "default:dirt_with_grass"}, {["x"] = 11, ["y"] = 4, ["param1"] = 15, ["z"] = 24, ["name"] = "default:stone"}, {["x"] = 11, ["y"] = 4, ["param1"] = 15, ["z"] = 25, ["name"] = "default:stone"}, {["x"] = 11, ["y"] = 4, ["param1"] = 14, ["z"] = 26, ["name"] = "default:stone"}, {["x"] = 11, ["y"] = 4, ["param1"] = 15, ["z"] = 27, ["name"] = "default:stone"}, {["x"] = 11, ["y"] = 4, ["param1"] = 15, ["z"] = 28, ["name"] = "default:stone"}, {["x"] = 11, ["y"] = 5, ["param1"] = 15, ["z"] = 23, ["name"] = "default:stone"}, {["x"] = 11, ["y"] = 5, ["param1"] = 15, ["z"] = 24, ["name"] = "default:stone"}, {["x"] = 11, ["y"] = 5, ["param1"] = 15, ["z"] = 25, ["name"] = "default:stone"}, {["x"] = 11, ["y"] = 5, ["param1"] = 14, ["z"] = 26, ["name"] = "default:stone"}, {["x"] = 11, ["y"] = 5, ["param1"] = 15, ["z"] = 27, ["name"] = "default:stone"}, {["x"] = 11, ["y"] = 5, ["param1"] = 15, ["z"] = 28, ["name"] = "default:stone"}, {["x"] = 11, ["y"] = 5, ["param1"] = 15, ["z"] = 29, ["name"] = "default:stone"}, {["x"] = 11, ["y"] = 6, ["param1"] = 15, ["z"] = 23, ["name"] = "default:stone"}, {["x"] = 11, ["y"] = 6, ["param1"] = 15, ["z"] = 24, ["name"] = "default:stone"}, {["x"] = 11, ["y"] = 6, ["param1"] = 15, ["z"] = 25, ["name"] = "default:stone"}, {["x"] = 11, ["y"] = 6, ["param1"] = 14, ["z"] = 26, ["name"] = "default:stone"}, {["x"] = 11, ["y"] = 6, ["param1"] = 15, ["z"] = 27, ["name"] = "default:stone"}, {["x"] = 11, ["y"] = 6, ["param1"] = 15, ["z"] = 28, ["name"] = "default:stone"}, {["x"] = 11, ["y"] = 6, ["param1"] = 15, ["z"] = 29, ["name"] = "default:stone"}, {["x"] = 11, ["y"] = 7, ["param1"] = 15, ["z"] = 23, ["name"] = "default:dirt_with_grass"}, {["x"] = 11, ["y"] = 7, ["param1"] = 15, ["z"] = 24, ["name"] = "default:dirt_with_grass"}, {["x"] = 11, ["y"] = 7, ["param1"] = 15, ["z"] = 25, ["name"] = "default:dirt_with_grass"}, {["x"] = 11, ["y"] = 7, ["z"] = 26, ["name"] = "default:dirt_with_grass"}, {["x"] = 11, ["y"] = 7, ["param1"] = 15, ["z"] = 27, ["name"] = "default:dirt_with_grass"}, {["x"] = 11, ["y"] = 7, ["param1"] = 15, ["z"] = 28, ["name"] = "default:dirt_with_grass"}, {["x"] = 11, ["y"] = 7, ["param1"] = 15, ["z"] = 29, ["name"] = "default:dirt_with_grass"}, {["x"] = 12, ["y"] = 5, ["param1"] = 15, ["z"] = 25, ["name"] = "default:stone"}, {["x"] = 12, ["y"] = 5, ["param1"] = 14, ["z"] = 26, ["name"] = "default:stone"}, {["x"] = 12, ["y"] = 5, ["param1"] = 15, ["z"] = 27, ["name"] = "default:stone"}, {["x"] = 12, ["y"] = 6, ["param1"] = 15, ["z"] = 24, ["name"] = "default:stone"}, {["x"] = 12, ["y"] = 6, ["param1"] = 15, ["z"] = 25, ["name"] = "default:stone"}, {["x"] = 12, ["y"] = 6, ["param1"] = 14, ["z"] = 26, ["name"] = "default:stone"}, {["x"] = 12, ["y"] = 6, ["param1"] = 15, ["z"] = 27, ["name"] = "default:stone"}, {["x"] = 12, ["y"] = 6, ["param1"] = 15, ["z"] = 28, ["name"] = "default:stone"}, {["x"] = 12, ["y"] = 7, ["param1"] = 15, ["z"] = 24, ["name"] = "default:dirt_with_grass"}, {["x"] = 12, ["y"] = 7, ["param1"] = 15, ["z"] = 25, ["name"] = "default:dirt_with_grass"}, {["x"] = 12, ["y"] = 7, ["z"] = 26, ["name"] = "default:dirt_with_grass"}, {["x"] = 12, ["y"] = 7, ["param1"] = 15, ["z"] = 27, ["name"] = "default:dirt_with_grass"}, {["x"] = 12, ["y"] = 7, ["param1"] = 15, ["z"] = 28, ["name"] = "default:dirt_with_grass"}, {["x"] = 13, ["param2"] = 20, ["y"] = 7, ["param1"] = 15, ["z"] = 25, ["name"] = "moreblocks:slab_wood"}, {["x"] = 13, ["param2"] = 20, ["y"] = 7, ["param1"] = 15, ["z"] = 26, ["name"] = "moreblocks:slab_wood"}, {["x"] = 13, ["param2"] = 20, ["y"] = 7, ["param1"] = 15, ["z"] = 27, ["name"] = "moreblocks:slab_wood"}, {["x"] = 14, ["y"] = 7, ["param1"] = 31, ["z"] = 25, ["name"] = "moreblocks:slab_wood"}, {["x"] = 14, ["y"] = 7, ["param1"] = 15, ["z"] = 26, ["name"] = "moreblocks:slab_wood"}, {["x"] = 14, ["y"] = 7, ["param1"] = 31, ["z"] = 27, ["name"] = "moreblocks:slab_wood"}, {["x"] = 15, ["param2"] = 20, ["y"] = 6, ["param1"] = 31, ["z"] = 25, ["name"] = "moreblocks:slab_wood"}, {["x"] = 15, ["param2"] = 20, ["y"] = 6, ["param1"] = 15, ["z"] = 26, ["name"] = "moreblocks:slab_wood"}, {["x"] = 15, ["param2"] = 20, ["y"] = 6, ["param1"] = 31, ["z"] = 27, ["name"] = "moreblocks:slab_wood"}, {["x"] = 16, ["param2"] = 20, ["y"] = 6, ["param1"] = 47, ["z"] = 25, ["name"] = "moreblocks:slab_wood"}, {["x"] = 16, ["param2"] = 20, ["y"] = 6, ["param1"] = 31, ["z"] = 26, ["name"] = "moreblocks:slab_wood"}, {["x"] = 16, ["param2"] = 20, ["y"] = 6, ["param1"] = 47, ["z"] = 27, ["name"] = "moreblocks:slab_wood"}, {["x"] = 17, ["y"] = 2, ["param1"] = 15, ["z"] = 25, ["name"] = "mesecons_extrawires:vertical_bottom_off"}, {["x"] = 17, ["y"] = 2, ["param1"] = 15, ["z"] = 26, ["name"] = "mesecons_extrawires:vertical_bottom_off"}, {["x"] = 17, ["y"] = 2, ["param1"] = 15, ["z"] = 27, ["name"] = "mesecons_extrawires:vertical_bottom_off"}, {["x"] = 17, ["y"] = 3, ["param1"] = 15, ["z"] = 25, ["name"] = "mesecons_extrawires:vertical_off"}, {["x"] = 17, ["y"] = 3, ["param1"] = 15, ["z"] = 26, ["name"] = "mesecons_extrawires:vertical_off"}, {["x"] = 17, ["y"] = 3, ["param1"] = 15, ["z"] = 27, ["name"] = "mesecons_extrawires:vertical_off"}, {["x"] = 17, ["y"] = 4, ["param1"] = 31, ["z"] = 25, ["name"] = "mesecons_extrawires:vertical_off"}, {["x"] = 17, ["y"] = 4, ["param1"] = 15, ["z"] = 26, ["name"] = "mesecons_extrawires:vertical_off"}, {["x"] = 17, ["y"] = 4, ["param1"] = 31, ["z"] = 27, ["name"] = "mesecons_extrawires:vertical_off"}, {["x"] = 17, ["y"] = 5, ["param1"] = 47, ["z"] = 25, ["name"] = "mesecons_extrawires:vertical_top_off"}, {["x"] = 17, ["y"] = 5, ["param1"] = 31, ["z"] = 26, ["name"] = "mesecons_extrawires:vertical_top_off"}, {["x"] = 17, ["y"] = 5, ["param1"] = 47, ["z"] = 27, ["name"] = "mesecons_extrawires:vertical_top_off"}, {["x"] = 17, ["param2"] = 20, ["y"] = 6, ["param1"] = 63, ["z"] = 25, ["name"] = "moreblocks:slab_wood"}, {["x"] = 17, ["param2"] = 20, ["y"] = 6, ["param1"] = 47, ["z"] = 26, ["name"] = "moreblocks:slab_wood"}, {["x"] = 17, ["param2"] = 20, ["y"] = 6, ["param1"] = 63, ["z"] = 27, ["name"] = "moreblocks:slab_wood"}, {["x"] = 18, ["y"] = 2, ["param1"] = 15, ["z"] = 26, ["name"] = "mesecons:wire_10101000_off"}, {["x"] = 18, ["y"] = 5, ["param1"] = 63, ["z"] = 25, ["name"] = "mesecons_extrawires:vertical_bottom_off"}, {["x"] = 18, ["y"] = 5, ["param1"] = 47, ["z"] = 26, ["name"] = "mesecons_extrawires:vertical_bottom_off"}, {["x"] = 18, ["y"] = 5, ["param1"] = 63, ["z"] = 27, ["name"] = "mesecons_extrawires:vertical_bottom_off"}, {["x"] = 18, ["y"] = 6, ["param1"] = 79, ["z"] = 25, ["name"] = "mesecons_extrawires:vertical_top_off"}, {["x"] = 18, ["y"] = 6, ["param1"] = 63, ["z"] = 26, ["name"] = "mesecons_extrawires:vertical_top_off"}, {["x"] = 18, ["y"] = 6, ["param1"] = 79, ["z"] = 27, ["name"] = "mesecons_extrawires:vertical_top_off"}, {["x"] = 18, ["y"] = 7, ["param1"] = 95, ["z"] = 25, ["name"] = "moreblocks:slab_wood"}, {["x"] = 18, ["y"] = 7, ["param1"] = 79, ["z"] = 26, ["name"] = "moreblocks:slab_wood"}, {["x"] = 18, ["y"] = 7, ["param1"] = 95, ["z"] = 27, ["name"] = "moreblocks:slab_wood"}, {["x"] = 19, ["param2"] = 4, ["y"] = 2, ["z"] = 26, ["name"] = "mesecons_pistons:piston_sticky_off"}, {["x"] = 19, ["y"] = 3, ["param1"] = 30, ["z"] = 26, ["name"] = "mesecons:wire_10100000_off"}, {["x"] = 19, ["y"] = 6, ["param1"] = 94, ["z"] = 25, ["name"] = "mesecons_extrawires:vertical_bottom_off"}, {["x"] = 19, ["y"] = 6, ["param1"] = 78, ["z"] = 26, ["name"] = "mesecons_extrawires:vertical_bottom_off"}, {["x"] = 19, ["y"] = 6, ["param1"] = 94, ["z"] = 27, ["name"] = "mesecons_extrawires:vertical_bottom_off"}, {["x"] = 19, ["param2"] = 20, ["y"] = 7, ["param1"] = 110, ["z"] = 25, ["name"] = "moreblocks:slab_wood"}, {["x"] = 19, ["param2"] = 20, ["y"] = 7, ["param1"] = 94, ["z"] = 26, ["name"] = "moreblocks:slab_wood"}, {["x"] = 19, ["param2"] = 20, ["y"] = 7, ["param1"] = 110, ["z"] = 27, ["name"] = "moreblocks:slab_wood"}, {["x"] = 19, ["y"] = 8, ["param1"] = 126, ["z"] = 25, ["name"] = "mesecons_pressureplates:pressure_plate_wood_off"}, {["x"] = 19, ["y"] = 8, ["param1"] = 110, ["z"] = 26, ["name"] = "mesecons_pressureplates:pressure_plate_wood_off"}, {["x"] = 19, ["y"] = 8, ["param1"] = 126, ["z"] = 27, ["name"] = "mesecons_pressureplates:pressure_plate_wood_off"}, {["x"] = 20, ["y"] = 3, ["param1"] = 15, ["z"] = 22, ["name"] = "mesecons_extrawires:vertical_bottom_off"}, {["x"] = 20, ["y"] = 3, ["param1"] = 15, ["z"] = 23, ["name"] = "mesecons:wire_01010000_off"}, {["x"] = 20, ["y"] = 3, ["param1"] = 14, ["z"] = 24, ["name"] = "mesecons:wire_01010000_off"}, {["x"] = 20, ["y"] = 3, ["param1"] = 29, ["z"] = 25, ["name"] = "mesecons:wire_01010000_off"}, {["x"] = 20, ["y"] = 3, ["param1"] = 13, ["z"] = 26, ["name"] = "mesecons:wire_11110000_off"}, {["x"] = 20, ["y"] = 3, ["param1"] = 29, ["z"] = 27, ["name"] = "mesecons:wire_01010000_off"}, {["x"] = 20, ["y"] = 3, ["param1"] = 14, ["z"] = 28, ["name"] = "mesecons:wire_01010000_off"}, {["x"] = 20, ["y"] = 3, ["param1"] = 15, ["z"] = 29, ["name"] = "mesecons:wire_01010000_off"}, {["x"] = 20, ["y"] = 3, ["param1"] = 15, ["z"] = 30, ["name"] = "mesecons_extrawires:vertical_bottom_off"}, {["x"] = 20, ["y"] = 4, ["param1"] = 15, ["z"] = 22, ["name"] = "mesecons_extrawires:vertical_off"}, {["x"] = 20, ["y"] = 4, ["param1"] = 15, ["z"] = 30, ["name"] = "mesecons_extrawires:vertical_off"}, {["x"] = 20, ["y"] = 5, ["param1"] = 15, ["z"] = 22, ["name"] = "mesecons_extrawires:vertical_off"}, {["x"] = 20, ["y"] = 5, ["param1"] = 15, ["z"] = 30, ["name"] = "mesecons_extrawires:vertical_off"}, {["x"] = 20, ["y"] = 6, ["param1"] = 31, ["z"] = 22, ["name"] = "mesecons_extrawires:vertical_off"}, {["x"] = 20, ["y"] = 6, ["param1"] = 31, ["z"] = 30, ["name"] = "mesecons_extrawires:vertical_off"}, {["x"] = 20, ["y"] = 7, ["param1"] = 47, ["z"] = 22, ["name"] = "mesecons_extrawires:vertical_off"}, {["x"] = 20, ["y"] = 7, ["param1"] = 15, ["z"] = 24, ["name"] = "default:stone"}, {["x"] = 20, ["y"] = 7, ["param1"] = 15, ["z"] = 25, ["name"] = "default:stone"}, {["x"] = 20, ["y"] = 7, ["param1"] = 15, ["z"] = 26, ["name"] = "default:stone"}, {["x"] = 20, ["y"] = 7, ["param1"] = 15, ["z"] = 27, ["name"] = "default:stone"}, {["x"] = 20, ["y"] = 7, ["param1"] = 15, ["z"] = 28, ["name"] = "default:stone"}, {["x"] = 20, ["y"] = 7, ["param1"] = 47, ["z"] = 30, ["name"] = "mesecons_extrawires:vertical_off"}, {["x"] = 20, ["y"] = 8, ["param1"] = 63, ["z"] = 22, ["name"] = "mesecons_extrawires:vertical_off"}, {["x"] = 20, ["meta"] = {["fields"] = {["infotext"] = "Constructor Mk2", ["formspec"] = "size[8,9;]label[0,0;Constructor Mk2]list[current_player;main;0,5;8,4;]label[5,0;Slot 1]list[current_name;slot1;6,0;1,1;]label[5,1;Slot 2]list[current_name;slot2;6,1;1,1;]"}, ["inventory"] = {["slot1"] = {""}, ["slot2"] = {""}}}, ["param2"] = 2, ["y"] = 8, ["z"] = 24, ["name"] = "technic:constructor_mk2_off"}, {["x"] = 20, ["param2"] = 2, ["y"] = 8, ["param1"] = 141, ["z"] = 25, ["name"] = "default:obsidian_glass"}, {["x"] = 20, ["param2"] = 2, ["y"] = 8, ["param1"] = 125, ["z"] = 26, ["name"] = "default:obsidian_glass"}, {["x"] = 20, ["y"] = 8, ["param1"] = 141, ["z"] = 27, ["name"] = "default:obsidian_glass"}, {["x"] = 20, ["meta"] = {["fields"] = {["infotext"] = "Constructor Mk1", ["formspec"] = "size[8,9;]label[0,0;Constructor Mk1]list[current_player;main;0,5;8,4;]label[5,0;Slot 1]list[current_name;slot1;6,0;1,1;]"}, ["inventory"] = {["slot1"] = {""}}}, ["y"] = 8, ["z"] = 28, ["name"] = "technic:constructor_mk1_off"}, {["x"] = 20, ["y"] = 8, ["param1"] = 63, ["z"] = 30, ["name"] = "mesecons_extrawires:vertical_off"}, {["x"] = 20, ["y"] = 9, ["param1"] = 79, ["z"] = 22, ["name"] = "mesecons_extrawires:vertical_top_off"}, {["x"] = 20, ["y"] = 9, ["param1"] = 95, ["z"] = 23, ["name"] = "mesecons:wire_01010100_off"}, {["x"] = 20, ["meta"] = {["fields"] = {["infotext"] = "Constructor Mk1", ["formspec"] = "size[8,9;]label[0,0;Constructor Mk1]list[current_player;main;0,5;8,4;]label[5,0;Slot 1]list[current_name;slot1;6,0;1,1;]"}, ["inventory"] = {["slot1"] = {""}}}, ["param2"] = 2, ["y"] = 9, ["z"] = 24, ["name"] = "technic:constructor_mk1_off"}, {["x"] = 20, ["param2"] = 2, ["y"] = 9, ["param1"] = 158, ["z"] = 25, ["name"] = "default:obsidian_glass"}, {["x"] = 20, ["y"] = 9, ["param1"] = 142, ["z"] = 26, ["name"] = "default:obsidian_glass"}, {["x"] = 20, ["y"] = 9, ["param1"] = 158, ["z"] = 27, ["name"] = "default:obsidian_glass"}, {["x"] = 20, ["meta"] = {["fields"] = {["infotext"] = "Constructor Mk2", ["formspec"] = "size[8,9;]label[0,0;Constructor Mk2]list[current_player;main;0,5;8,4;]label[5,0;Slot 1]list[current_name;slot1;6,0;1,1;]label[5,1;Slot 2]list[current_name;slot2;6,1;1,1;]"}, ["inventory"] = {["slot1"] = {""}, ["slot2"] = {""}}}, ["y"] = 9, ["z"] = 28, ["name"] = "technic:constructor_mk2_off"}, {["x"] = 20, ["y"] = 9, ["param1"] = 95, ["z"] = 29, ["name"] = "mesecons:wire_01010001_off"}, {["x"] = 20, ["y"] = 9, ["param1"] = 79, ["z"] = 30, ["name"] = "mesecons_extrawires:vertical_top_off"}, {["x"] = 20, ["meta"] = {["fields"] = {["infotext"] = "Constructor Mk2", ["formspec"] = "size[8,9;]label[0,0;Constructor Mk2]list[current_player;main;0,5;8,4;]label[5,0;Slot 1]list[current_name;slot1;6,0;1,1;]label[5,1;Slot 2]list[current_name;slot2;6,1;1,1;]"}, ["inventory"] = {["slot1"] = {""}, ["slot2"] = {""}}}, ["param2"] = 2, ["y"] = 10, ["z"] = 24, ["name"] = "technic:constructor_mk2_off"}, {["x"] = 20, ["param2"] = 2, ["y"] = 10, ["param1"] = 174, ["z"] = 25, ["name"] = "default:obsidian_glass"}, {["x"] = 20, ["param2"] = 2, ["y"] = 10, ["param1"] = 158, ["z"] = 26, ["name"] = "default:obsidian_glass"}, {["x"] = 20, ["y"] = 10, ["param1"] = 174, ["z"] = 27, ["name"] = "default:obsidian_glass"}, {["x"] = 20, ["meta"] = {["fields"] = {["infotext"] = "Constructor Mk1", ["formspec"] = "size[8,9;]label[0,0;Constructor Mk1]list[current_player;main;0,5;8,4;]label[5,0;Slot 1]list[current_name;slot1;6,0;1,1;]"}, ["inventory"] = {["slot1"] = {""}}}, ["y"] = 10, ["z"] = 28, ["name"] = "technic:constructor_mk1_off"}, {["x"] = 20, ["y"] = 11, ["param1"] = 15, ["z"] = 24, ["name"] = "default:stone"}, {["x"] = 20, ["y"] = 11, ["param1"] = 15, ["z"] = 25, ["name"] = "default:stone"}, {["x"] = 20, ["y"] = 11, ["param1"] = 15, ["z"] = 26, ["name"] = "default:stone"}, {["x"] = 20, ["y"] = 11, ["param1"] = 15, ["z"] = 27, ["name"] = "default:stone"}, {["x"] = 20, ["y"] = 11, ["param1"] = 15, ["z"] = 28, ["name"] = "default:stone"}, {["x"] = 21, ["param2"] = 4, ["y"] = 2, ["z"] = 26, ["name"] = "mesecons_pistons:piston_sticky_off"}, {["x"] = 21, ["y"] = 3, ["param1"] = 12, ["z"] = 26, ["name"] = "mesecons:wire_10100000_off"}, {["x"] = 21, ["y"] = 5, ["param1"] = 15, ["z"] = 24, ["name"] = "default:stone"}, {["x"] = 21, ["y"] = 5, ["param1"] = 15, ["z"] = 25, ["name"] = "default:stone"}, {["x"] = 21, ["y"] = 5, ["z"] = 26, ["name"] = "default:stone"}, {["x"] = 21, ["y"] = 5, ["param1"] = 15, ["z"] = 27, ["name"] = "default:stone"}, {["x"] = 21, ["y"] = 5, ["param1"] = 15, ["z"] = 28, ["name"] = "default:stone"}, {["x"] = 21, ["y"] = 6, ["param1"] = 15, ["z"] = 23, ["name"] = "default:stone"}, {["x"] = 21, ["y"] = 6, ["param1"] = 15, ["z"] = 24, ["name"] = "default:stone"}, {["x"] = 21, ["y"] = 6, ["param1"] = 60, ["z"] = 25, ["name"] = "mesecons_extrawires:vertical_bottom_off"}, {["x"] = 21, ["y"] = 6, ["param1"] = 44, ["z"] = 26, ["name"] = "mesecons_extrawires:vertical_bottom_off"}, {["x"] = 21, ["y"] = 6, ["param1"] = 60, ["z"] = 27, ["name"] = "mesecons_extrawires:vertical_bottom_off"}, {["x"] = 21, ["y"] = 6, ["param1"] = 15, ["z"] = 28, ["name"] = "default:stone"}, {["x"] = 21, ["y"] = 6, ["param1"] = 15, ["z"] = 29, ["name"] = "default:stone"}, {["x"] = 21, ["y"] = 7, ["param1"] = 15, ["z"] = 22, ["name"] = "default:stone"}, {["x"] = 21, ["y"] = 7, ["param1"] = 15, ["z"] = 23, ["name"] = "default:stone"}, {["x"] = 21, ["y"] = 7, ["param1"] = 15, ["z"] = 24, ["name"] = "default:stone"}, {["x"] = 21, ["y"] = 7, ["param1"] = 15, ["z"] = 25, ["name"] = "default:stone"}, {["x"] = 21, ["y"] = 7, ["z"] = 26, ["name"] = "default:stone"}, {["x"] = 21, ["y"] = 7, ["param1"] = 15, ["z"] = 27, ["name"] = "default:stone"}, {["x"] = 21, ["y"] = 7, ["param1"] = 15, ["z"] = 28, ["name"] = "default:stone"}, {["x"] = 21, ["y"] = 7, ["param1"] = 15, ["z"] = 29, ["name"] = "default:stone"}, {["x"] = 21, ["y"] = 7, ["param1"] = 15, ["z"] = 30, ["name"] = "default:stone"}, {["x"] = 21, ["y"] = 8, ["param1"] = 15, ["z"] = 22, ["name"] = "default:stone"}, {["x"] = 21, ["y"] = 8, ["param1"] = 15, ["z"] = 23, ["name"] = "default:stone"}, {["x"] = 21, ["y"] = 8, ["param1"] = 156, ["z"] = 25, ["name"] = "mesecons_pressureplates:pressure_plate_stone_off"}, {["x"] = 21, ["y"] = 8, ["param1"] = 140, ["z"] = 26, ["name"] = "mesecons_pressureplates:pressure_plate_stone_off"}, {["x"] = 21, ["y"] = 8, ["param1"] = 156, ["z"] = 27, ["name"] = "mesecons_pressureplates:pressure_plate_stone_off"}, {["x"] = 21, ["y"] = 8, ["param1"] = 15, ["z"] = 29, ["name"] = "default:stone"}, {["x"] = 21, ["y"] = 8, ["param1"] = 15, ["z"] = 30, ["name"] = "default:stone"}, {["x"] = 21, ["y"] = 9, ["param1"] = 15, ["z"] = 22, ["name"] = "default:stone"}, {["x"] = 21, ["y"] = 9, ["param1"] = 15, ["z"] = 23, ["name"] = "default:stone"}, {["x"] = 21, ["meta"] = {["fields"] = {["owner"] = "thefox963", ["members"] = "yelby", ["infotext"] = "Protection (owned by thefox963)"}, ["inventory"] = {}}, ["param2"] = 3, ["y"] = 9, ["param1"] = 188, ["z"] = 28, ["name"] = "protector:protect2"}, {["x"] = 21, ["y"] = 9, ["param1"] = 15, ["z"] = 29, ["name"] = "default:stone"}, {["x"] = 21, ["y"] = 9, ["param1"] = 15, ["z"] = 30, ["name"] = "default:stone"}, {["x"] = 21, ["y"] = 10, ["param1"] = 15, ["z"] = 22, ["name"] = "default:stone"}, {["x"] = 21, ["y"] = 10, ["param1"] = 15, ["z"] = 23, ["name"] = "default:stone"}, {["x"] = 21, ["y"] = 10, ["param1"] = 15, ["z"] = 29, ["name"] = "default:stone"}, {["x"] = 21, ["y"] = 10, ["param1"] = 15, ["z"] = 30, ["name"] = "default:stone"}, {["x"] = 21, ["y"] = 11, ["param1"] = 15, ["z"] = 22, ["name"] = "default:stone"}, {["x"] = 21, ["y"] = 11, ["param1"] = 15, ["z"] = 23, ["name"] = "default:stone"}, {["x"] = 21, ["y"] = 11, ["param1"] = 221, ["z"] = 24, ["name"] = "homedecor:glowlight_small_cube_on"}, {["x"] = 21, ["y"] = 11, ["param1"] = 221, ["z"] = 28, ["name"] = "homedecor:glowlight_small_cube_on"}, {["x"] = 21, ["y"] = 11, ["param1"] = 15, ["z"] = 29, ["name"] = "default:stone"}, {["x"] = 21, ["y"] = 11, ["param1"] = 15, ["z"] = 30, ["name"] = "default:stone"}, {["x"] = 21, ["y"] = 12, ["param1"] = 15, ["z"] = 23, ["name"] = "default:stone"}, {["x"] = 21, ["y"] = 12, ["param1"] = 15, ["z"] = 24, ["name"] = "default:stone"}, {["x"] = 21, ["y"] = 12, ["param1"] = 15, ["z"] = 25, ["name"] = "default:stone"}, {["x"] = 21, ["y"] = 12, ["param1"] = 15, ["z"] = 26, ["name"] = "default:stone"}, {["x"] = 21, ["y"] = 12, ["param1"] = 15, ["z"] = 27, ["name"] = "default:stone"}, {["x"] = 21, ["y"] = 12, ["param1"] = 15, ["z"] = 28, ["name"] = "default:stone"}, {["x"] = 21, ["y"] = 12, ["param1"] = 15, ["z"] = 29, ["name"] = "default:stone"}, {["x"] = 21, ["y"] = 13, ["param1"] = 15, ["z"] = 24, ["name"] = "default:stone"}, {["x"] = 21, ["y"] = 13, ["param1"] = 15, ["z"] = 25, ["name"] = "default:stone"}, {["x"] = 21, ["y"] = 13, ["param1"] = 15, ["z"] = 26, ["name"] = "default:stone"}, {["x"] = 21, ["y"] = 13, ["param1"] = 15, ["z"] = 27, ["name"] = "default:stone"}, {["x"] = 21, ["y"] = 13, ["param1"] = 15, ["z"] = 28, ["name"] = "default:stone"}, {["x"] = 22, ["y"] = 2, ["param1"] = 10, ["z"] = 26, ["name"] = "mesecons:wire_10100010_off"}, {["x"] = 22, ["y"] = 3, ["z"] = 26, ["name"] = "default:stone"}, {["x"] = 22, ["y"] = 4, ["param1"] = 15, ["z"] = 23, ["name"] = "default:stone"}, {["x"] = 22, ["y"] = 4, ["param1"] = 15, ["z"] = 24, ["name"] = "default:stone"}, {["x"] = 22, ["y"] = 4, ["param1"] = 15, ["z"] = 25, ["name"] = "default:stone"}, {["x"] = 22, ["y"] = 4, ["param1"] = 15, ["z"] = 26, ["name"] = "default:stone"}, {["x"] = 22, ["y"] = 4, ["param1"] = 15, ["z"] = 27, ["name"] = "default:stone"}, {["x"] = 22, ["y"] = 4, ["param1"] = 15, ["z"] = 28, ["name"] = "default:stone"}, {["x"] = 22, ["y"] = 4, ["param1"] = 15, ["z"] = 29, ["name"] = "default:stone"}, {["x"] = 22, ["y"] = 5, ["param1"] = 15, ["z"] = 22, ["name"] = "default:stone"}, {["x"] = 22, ["y"] = 5, ["param1"] = 15, ["z"] = 23, ["name"] = "default:stone"}, {["x"] = 22, ["y"] = 5, ["param1"] = 15, ["z"] = 24, ["name"] = "default:stone"}, {["x"] = 22, ["y"] = 5, ["param1"] = 26, ["z"] = 25, ["name"] = "mesecons_extrawires:vertical_bottom_off"}, {["x"] = 22, ["y"] = 5, ["param1"] = 10, ["z"] = 26, ["name"] = "mesecons_extrawires:vertical_bottom_off"}, {["x"] = 22, ["y"] = 5, ["param1"] = 26, ["z"] = 27, ["name"] = "mesecons_extrawires:vertical_bottom_off"}, {["x"] = 22, ["y"] = 5, ["param1"] = 15, ["z"] = 28, ["name"] = "default:stone"}, {["x"] = 22, ["y"] = 5, ["param1"] = 15, ["z"] = 29, ["name"] = "default:stone"}, {["x"] = 22, ["y"] = 5, ["param1"] = 15, ["z"] = 30, ["name"] = "default:stone"}, {["x"] = 22, ["y"] = 6, ["param1"] = 15, ["z"] = 21, ["name"] = "default:stone"}, {["x"] = 22, ["y"] = 6, ["param1"] = 15, ["z"] = 22, ["name"] = "default:stone"}, {["x"] = 22, ["y"] = 6, ["param1"] = 15, ["z"] = 23, ["name"] = "default:stone"}, {["x"] = 22, ["y"] = 6, ["param1"] = 15, ["z"] = 24, ["name"] = "default:stone"}, {["x"] = 22, ["y"] = 6, ["param1"] = 43, ["z"] = 25, ["name"] = "mesecons_extrawires:vertical_top_off"}, {["x"] = 22, ["y"] = 6, ["param1"] = 27, ["z"] = 26, ["name"] = "mesecons_extrawires:vertical_top_off"}, {["x"] = 22, ["y"] = 6, ["param1"] = 43, ["z"] = 27, ["name"] = "mesecons_extrawires:vertical_top_off"}, {["x"] = 22, ["y"] = 6, ["param1"] = 15, ["z"] = 28, ["name"] = "default:stone"}, {["x"] = 22, ["y"] = 6, ["param1"] = 15, ["z"] = 29, ["name"] = "default:stone"}, {["x"] = 22, ["y"] = 6, ["param1"] = 15, ["z"] = 30, ["name"] = "default:stone"}, {["x"] = 22, ["y"] = 6, ["param1"] = 15, ["z"] = 31, ["name"] = "default:stone"}, {["x"] = 22, ["y"] = 7, ["param1"] = 15, ["z"] = 21, ["name"] = "default:stone"}, {["x"] = 22, ["y"] = 7, ["param1"] = 15, ["z"] = 22, ["name"] = "default:stone"}, {["x"] = 22, ["y"] = 7, ["param1"] = 15, ["z"] = 23, ["name"] = "default:stone"}, {["x"] = 22, ["y"] = 7, ["param1"] = 15, ["z"] = 24, ["name"] = "default:stone"}, {["x"] = 22, ["y"] = 7, ["param1"] = 15, ["z"] = 25, ["name"] = "default:stone"}, {["x"] = 22, ["y"] = 7, ["param1"] = 15, ["z"] = 26, ["name"] = "default:stone"}, {["x"] = 22, ["y"] = 7, ["param1"] = 15, ["z"] = 27, ["name"] = "default:stone"}, {["x"] = 22, ["y"] = 7, ["param1"] = 15, ["z"] = 28, ["name"] = "default:stone"}, {["x"] = 22, ["y"] = 7, ["param1"] = 15, ["z"] = 29, ["name"] = "default:stone"}, {["x"] = 22, ["y"] = 7, ["param1"] = 15, ["z"] = 30, ["name"] = "default:stone"}, {["x"] = 22, ["y"] = 7, ["param1"] = 15, ["z"] = 31, ["name"] = "default:stone"}, {["x"] = 22, ["y"] = 8, ["param1"] = 15, ["z"] = 21, ["name"] = "default:stone"}, {["x"] = 22, ["y"] = 8, ["param1"] = 15, ["z"] = 31, ["name"] = "default:stone"}, {["x"] = 22, ["y"] = 9, ["param1"] = 15, ["z"] = 20, ["name"] = "default:stone"}, {["x"] = 22, ["y"] = 9, ["param1"] = 15, ["z"] = 21, ["name"] = "default:stone"}, {["x"] = 22, ["y"] = 9, ["param1"] = 15, ["z"] = 31, ["name"] = "default:stone"}, {["x"] = 22, ["y"] = 9, ["param1"] = 15, ["z"] = 32, ["name"] = "default:stone"}, {["x"] = 22, ["y"] = 10, ["param1"] = 15, ["z"] = 21, ["name"] = "default:stone"}, {["x"] = 22, ["y"] = 10, ["param1"] = 15, ["z"] = 31, ["name"] = "default:stone"}, {["x"] = 22, ["y"] = 11, ["param1"] = 15, ["z"] = 21, ["name"] = "default:stone"}, {["x"] = 22, ["y"] = 11, ["param1"] = 15, ["z"] = 31, ["name"] = "default:stone"}, {["x"] = 22, ["y"] = 12, ["param1"] = 15, ["z"] = 21, ["name"] = "default:stone"}, {["x"] = 22, ["y"] = 12, ["param1"] = 15, ["z"] = 22, ["name"] = "default:stone"}, {["x"] = 22, ["y"] = 12, ["z"] = 30, ["name"] = "default:stone"}, {["x"] = 22, ["y"] = 12, ["param1"] = 15, ["z"] = 31, ["name"] = "default:stone"}, {["x"] = 22, ["y"] = 13, ["param1"] = 15, ["z"] = 22, ["name"] = "default:stone"}, {["x"] = 22, ["y"] = 13, ["param1"] = 15, ["z"] = 23, ["name"] = "default:stone"}, {["x"] = 22, ["y"] = 13, ["z"] = 29, ["name"] = "default:stone"}, {["x"] = 22, ["y"] = 13, ["param1"] = 15, ["z"] = 30, ["name"] = "default:stone"}, {["x"] = 22, ["y"] = 14, ["param1"] = 15, ["z"] = 23, ["name"] = "default:stone"}, {["x"] = 22, ["y"] = 14, ["param1"] = 15, ["z"] = 24, ["name"] = "default:stone"}, {["x"] = 22, ["y"] = 14, ["param1"] = 15, ["z"] = 25, ["name"] = "default:stone"}, {["x"] = 22, ["y"] = 14, ["param1"] = 15, ["z"] = 26, ["name"] = "default:stone"}, {["x"] = 22, ["y"] = 14, ["param1"] = 15, ["z"] = 27, ["name"] = "default:stone"}, {["x"] = 22, ["y"] = 14, ["param1"] = 15, ["z"] = 28, ["name"] = "default:stone"}, {["x"] = 22, ["y"] = 14, ["param1"] = 15, ["z"] = 29, ["name"] = "default:stone"}, {["x"] = 22, ["y"] = 15, ["param1"] = 15, ["z"] = 26, ["name"] = "default:stone"}, {["x"] = 23, ["y"] = 2, ["param1"] = 10, ["z"] = 25, ["name"] = "mesecons_extrawires:vertical_bottom_off"}, {["x"] = 23, ["y"] = 2, ["param1"] = 10, ["z"] = 26, ["name"] = "mesecons_extrawires:vertical_bottom_off"}, {["x"] = 23, ["y"] = 2, ["param1"] = 10, ["z"] = 27, ["name"] = "mesecons_extrawires:vertical_bottom_off"}, {["x"] = 23, ["y"] = 3, ["param1"] = 15, ["z"] = 23, ["name"] = "default:stone"}, {["x"] = 23, ["y"] = 3, ["param1"] = 15, ["z"] = 24, ["name"] = "default:stone"}, {["x"] = 23, ["y"] = 3, ["param1"] = 10, ["z"] = 25, ["name"] = "mesecons_extrawires:vertical_off"}, {["x"] = 23, ["y"] = 3, ["param1"] = 9, ["z"] = 26, ["name"] = "mesecons_extrawires:vertical_off"}, {["x"] = 23, ["y"] = 3, ["param1"] = 10, ["z"] = 27, ["name"] = "mesecons_extrawires:vertical_off"}, {["x"] = 23, ["y"] = 3, ["param1"] = 15, ["z"] = 28, ["name"] = "default:stone"}, {["x"] = 23, ["y"] = 3, ["param1"] = 15, ["z"] = 29, ["name"] = "default:stone"}, {["x"] = 23, ["y"] = 4, ["param1"] = 15, ["z"] = 22, ["name"] = "default:stone"}, {["x"] = 23, ["y"] = 4, ["param1"] = 15, ["z"] = 23, ["name"] = "default:stone"}, {["x"] = 23, ["y"] = 4, ["param1"] = 15, ["z"] = 24, ["name"] = "default:stone"}, {["x"] = 23, ["y"] = 4, ["param1"] = 9, ["z"] = 25, ["name"] = "mesecons_extrawires:vertical_off"}, {["x"] = 23, ["y"] = 4, ["param1"] = 8, ["z"] = 26, ["name"] = "mesecons_extrawires:vertical_off"}, {["x"] = 23, ["y"] = 4, ["param1"] = 9, ["z"] = 27, ["name"] = "mesecons_extrawires:vertical_off"}, {["x"] = 23, ["y"] = 4, ["param1"] = 15, ["z"] = 28, ["name"] = "default:stone"}, {["x"] = 23, ["y"] = 4, ["param1"] = 15, ["z"] = 29, ["name"] = "default:stone"}, {["x"] = 23, ["y"] = 4, ["param1"] = 15, ["z"] = 30, ["name"] = "default:stone"}, {["x"] = 23, ["y"] = 5, ["param1"] = 15, ["z"] = 4, ["name"] = "default:stone"}, {["x"] = 23, ["y"] = 5, ["param1"] = 15, ["z"] = 5, ["name"] = "default:stone"}, {["x"] = 23, ["y"] = 5, ["param1"] = 15, ["z"] = 6, ["name"] = "default:stone"}, {["x"] = 23, ["y"] = 5, ["param1"] = 15, ["z"] = 21, ["name"] = "default:stone"}, {["x"] = 23, ["y"] = 5, ["param1"] = 15, ["z"] = 22, ["name"] = "default:stone"}, {["x"] = 23, ["y"] = 5, ["param1"] = 15, ["z"] = 23, ["name"] = "default:stone"}, {["x"] = 23, ["y"] = 5, ["param1"] = 15, ["z"] = 24, ["name"] = "default:stone"}, {["x"] = 23, ["y"] = 5, ["param1"] = 9, ["z"] = 25, ["name"] = "mesecons_extrawires:vertical_top_off"}, {["x"] = 23, ["y"] = 5, ["param1"] = 9, ["z"] = 26, ["name"] = "mesecons_extrawires:vertical_top_off"}, {["x"] = 23, ["y"] = 5, ["param1"] = 9, ["z"] = 27, ["name"] = "mesecons_extrawires:vertical_top_off"}, {["x"] = 23, ["y"] = 5, ["param1"] = 15, ["z"] = 28, ["name"] = "default:stone"}, {["x"] = 23, ["y"] = 5, ["param1"] = 15, ["z"] = 29, ["name"] = "default:stone"}, {["x"] = 23, ["y"] = 5, ["param1"] = 15, ["z"] = 30, ["name"] = "default:stone"}, {["x"] = 23, ["y"] = 5, ["param1"] = 15, ["z"] = 31, ["name"] = "default:stone"}, {["x"] = 23, ["y"] = 5, ["param1"] = 15, ["z"] = 46, ["name"] = "default:stone"}, {["x"] = 23, ["y"] = 5, ["param1"] = 15, ["z"] = 47, ["name"] = "default:stone"}, {["x"] = 23, ["y"] = 5, ["param1"] = 15, ["z"] = 48, ["name"] = "default:stone"}, {["x"] = 23, ["y"] = 6, ["param1"] = 15, ["z"] = 3, ["name"] = "default:stone"}, {["x"] = 23, ["y"] = 6, ["param1"] = 15, ["z"] = 4, ["name"] = "default:stone"}, {["x"] = 23, ["y"] = 6, ["param1"] = 15, ["z"] = 5, ["name"] = "default:stone"}, {["x"] = 23, ["y"] = 6, ["param1"] = 15, ["z"] = 6, ["name"] = "default:stone"}, {["x"] = 23, ["y"] = 6, ["param1"] = 15, ["z"] = 7, ["name"] = "default:stone"}, {["x"] = 23, ["y"] = 6, ["param1"] = 15, ["z"] = 20, ["name"] = "default:stone"}, {["x"] = 23, ["y"] = 6, ["param1"] = 15, ["z"] = 21, ["name"] = "default:stone"}, {["x"] = 23, ["y"] = 6, ["param1"] = 15, ["z"] = 22, ["name"] = "default:stone"}, {["x"] = 23, ["y"] = 6, ["param1"] = 15, ["z"] = 23, ["name"] = "default:stone"}, {["x"] = 23, ["y"] = 6, ["param1"] = 15, ["z"] = 24, ["name"] = "default:stone"}, {["x"] = 23, ["y"] = 6, ["param1"] = 15, ["z"] = 25, ["name"] = "default:stone"}, {["x"] = 23, ["y"] = 6, ["param1"] = 15, ["z"] = 26, ["name"] = "default:stone"}, {["x"] = 23, ["y"] = 6, ["param1"] = 15, ["z"] = 27, ["name"] = "default:stone"}, {["x"] = 23, ["y"] = 6, ["param1"] = 15, ["z"] = 28, ["name"] = "default:stone"}, {["x"] = 23, ["y"] = 6, ["param1"] = 15, ["z"] = 29, ["name"] = "default:stone"}, {["x"] = 23, ["y"] = 6, ["param1"] = 15, ["z"] = 30, ["name"] = "default:stone"}, {["x"] = 23, ["y"] = 6, ["param1"] = 15, ["z"] = 31, ["name"] = "default:stone"}, {["x"] = 23, ["y"] = 6, ["param1"] = 15, ["z"] = 32, ["name"] = "default:stone"}, {["x"] = 23, ["y"] = 6, ["param1"] = 15, ["z"] = 45, ["name"] = "default:stone"}, {["x"] = 23, ["y"] = 6, ["param1"] = 15, ["z"] = 46, ["name"] = "default:stone"}, {["x"] = 23, ["y"] = 6, ["param1"] = 15, ["z"] = 47, ["name"] = "default:stone"}, {["x"] = 23, ["y"] = 6, ["param1"] = 15, ["z"] = 48, ["name"] = "default:stone"}, {["x"] = 23, ["y"] = 6, ["param1"] = 15, ["z"] = 49, ["name"] = "default:stone"}, {["x"] = 23, ["y"] = 7, ["param1"] = 15, ["z"] = 3, ["name"] = "default:dirt_with_grass"}, {["x"] = 23, ["y"] = 7, ["param1"] = 15, ["z"] = 4, ["name"] = "default:dirt_with_grass"}, {["x"] = 23, ["y"] = 7, ["param1"] = 15, ["z"] = 5, ["name"] = "default:dirt_with_grass"}, {["x"] = 23, ["y"] = 7, ["param1"] = 15, ["z"] = 6, ["name"] = "default:dirt_with_grass"}, {["x"] = 23, ["y"] = 7, ["param1"] = 15, ["z"] = 7, ["name"] = "default:dirt_with_grass"}, {["x"] = 23, ["y"] = 7, ["param1"] = 15, ["z"] = 20, ["name"] = "default:stone"}, {["x"] = 23, ["y"] = 7, ["param1"] = 15, ["z"] = 21, ["name"] = "default:stone"}, {["x"] = 23, ["y"] = 7, ["param1"] = 15, ["z"] = 22, ["name"] = "default:stone"}, {["x"] = 23, ["y"] = 7, ["param1"] = 15, ["z"] = 23, ["name"] = "default:stone"}, {["x"] = 23, ["y"] = 7, ["param1"] = 15, ["z"] = 24, ["name"] = "default:stone"}, {["x"] = 23, ["y"] = 7, ["param1"] = 15, ["z"] = 25, ["name"] = "default:stone"}, {["x"] = 23, ["y"] = 7, ["param1"] = 15, ["z"] = 26, ["name"] = "default:stone"}, {["x"] = 23, ["y"] = 7, ["param1"] = 15, ["z"] = 27, ["name"] = "default:stone"}, {["x"] = 23, ["y"] = 7, ["param1"] = 15, ["z"] = 28, ["name"] = "default:stone"}, {["x"] = 23, ["y"] = 7, ["param1"] = 15, ["z"] = 29, ["name"] = "default:stone"}, {["x"] = 23, ["y"] = 7, ["param1"] = 15, ["z"] = 30, ["name"] = "default:stone"}, {["x"] = 23, ["y"] = 7, ["param1"] = 15, ["z"] = 31, ["name"] = "default:stone"}, {["x"] = 23, ["y"] = 7, ["param1"] = 15, ["z"] = 32, ["name"] = "default:stone"}, {["x"] = 23, ["y"] = 7, ["param1"] = 15, ["z"] = 45, ["name"] = "default:dirt_with_grass"}, {["x"] = 23, ["y"] = 7, ["param1"] = 15, ["z"] = 46, ["name"] = "default:dirt_with_grass"}, {["x"] = 23, ["y"] = 7, ["param1"] = 15, ["z"] = 47, ["name"] = "default:dirt_with_grass"}, {["x"] = 23, ["y"] = 7, ["param1"] = 15, ["z"] = 48, ["name"] = "default:dirt_with_grass"}, {["x"] = 23, ["y"] = 7, ["param1"] = 15, ["z"] = 49, ["name"] = "default:dirt_with_grass"}, {["x"] = 23, ["y"] = 8, ["param1"] = 15, ["z"] = 20, ["name"] = "default:stone"}, {["x"] = 23, ["y"] = 8, ["param1"] = 15, ["z"] = 32, ["name"] = "default:stone"}, {["x"] = 23, ["y"] = 9, ["param1"] = 15, ["z"] = 20, ["name"] = "default:stone"}, {["x"] = 23, ["y"] = 9, ["z"] = 32, ["name"] = "default:stone"}, {["x"] = 23, ["y"] = 10, ["param1"] = 15, ["z"] = 20, ["name"] = "default:stone"}, {["x"] = 23, ["y"] = 10, ["param1"] = 15, ["z"] = 32, ["name"] = "default:stone"}, {["x"] = 23, ["y"] = 11, ["param1"] = 15, ["z"] = 20, ["name"] = "default:stone"}, {["x"] = 23, ["y"] = 11, ["param1"] = 221, ["z"] = 21, ["name"] = "homedecor:glowlight_small_cube_on"}, {["x"] = 23, ["y"] = 11, ["param1"] = 221, ["z"] = 31, ["name"] = "homedecor:glowlight_small_cube_on"}, {["x"] = 23, ["y"] = 11, ["param1"] = 15, ["z"] = 32, ["name"] = "default:stone"}, {["x"] = 23, ["y"] = 12, ["param1"] = 15, ["z"] = 20, ["name"] = "default:stone"}, {["x"] = 23, ["y"] = 12, ["param1"] = 15, ["z"] = 21, ["name"] = "default:stone"}, {["x"] = 23, ["y"] = 12, ["param1"] = 15, ["z"] = 31, ["name"] = "default:stone"}, {["x"] = 23, ["y"] = 12, ["param1"] = 15, ["z"] = 32, ["name"] = "default:stone"}, {["x"] = 23, ["y"] = 13, ["param1"] = 15, ["z"] = 21, ["name"] = "default:stone"}, {["x"] = 23, ["y"] = 13, ["param1"] = 15, ["z"] = 31, ["name"] = "default:stone"}, {["x"] = 23, ["y"] = 14, ["param1"] = 15, ["z"] = 22, ["name"] = "default:stone"}, {["x"] = 23, ["y"] = 14, ["param1"] = 15, ["z"] = 30, ["name"] = "default:stone"}, {["x"] = 23, ["y"] = 15, ["param1"] = 15, ["z"] = 23, ["name"] = "default:stone"}, {["x"] = 23, ["y"] = 15, ["param1"] = 15, ["z"] = 24, ["name"] = "default:stone"}, {["x"] = 23, ["y"] = 15, ["param1"] = 15, ["z"] = 25, ["name"] = "default:stone"}, {["x"] = 23, ["y"] = 15, ["param1"] = 15, ["z"] = 26, ["name"] = "default:stone"}, {["x"] = 23, ["y"] = 15, ["param1"] = 15, ["z"] = 27, ["name"] = "default:stone"}, {["x"] = 23, ["y"] = 15, ["param1"] = 15, ["z"] = 28, ["name"] = "default:stone"}, {["x"] = 23, ["y"] = 15, ["param1"] = 15, ["z"] = 29, ["name"] = "default:stone"}, {["x"] = 24, ["y"] = 2, ["param1"] = 15, ["z"] = 24, ["name"] = "default:stone"}, {["x"] = 24, ["y"] = 2, ["param1"] = 15, ["z"] = 25, ["name"] = "default:stone"}, {["x"] = 24, ["y"] = 2, ["param1"] = 15, ["z"] = 26, ["name"] = "default:stone"}, {["x"] = 24, ["y"] = 2, ["param1"] = 15, ["z"] = 27, ["name"] = "default:stone"}, {["x"] = 24, ["y"] = 2, ["param1"] = 15, ["z"] = 28, ["name"] = "default:stone"}, {["x"] = 24, ["y"] = 3, ["param1"] = 15, ["z"] = 18, ["name"] = "mesecons_extrawires:vertical_bottom_off"}, {["x"] = 24, ["y"] = 3, ["param1"] = 15, ["z"] = 22, ["name"] = "default:stone"}, {["x"] = 24, ["y"] = 3, ["param1"] = 15, ["z"] = 23, ["name"] = "default:stone"}, {["x"] = 24, ["y"] = 3, ["param1"] = 15, ["z"] = 24, ["name"] = "default:stone"}, {["x"] = 24, ["y"] = 3, ["param1"] = 15, ["z"] = 25, ["name"] = "default:stone"}, {["x"] = 24, ["y"] = 3, ["param1"] = 15, ["z"] = 26, ["name"] = "default:stone"}, {["x"] = 24, ["y"] = 3, ["param1"] = 15, ["z"] = 27, ["name"] = "default:stone"}, {["x"] = 24, ["y"] = 3, ["param1"] = 15, ["z"] = 28, ["name"] = "default:stone"}, {["x"] = 24, ["y"] = 3, ["param1"] = 15, ["z"] = 29, ["name"] = "default:stone"}, {["x"] = 24, ["y"] = 3, ["param1"] = 15, ["z"] = 30, ["name"] = "default:stone"}, {["x"] = 24, ["y"] = 3, ["param1"] = 15, ["z"] = 34, ["name"] = "mesecons_extrawires:vertical_bottom_off"}, {["x"] = 24, ["y"] = 4, ["param1"] = 15, ["z"] = 3, ["name"] = "default:stone"}, {["x"] = 24, ["y"] = 4, ["param1"] = 15, ["z"] = 4, ["name"] = "default:stone"}, {["x"] = 24, ["y"] = 4, ["param1"] = 15, ["z"] = 5, ["name"] = "default:stone"}, {["x"] = 24, ["y"] = 4, ["param1"] = 15, ["z"] = 6, ["name"] = "default:stone"}, {["x"] = 24, ["y"] = 4, ["param1"] = 15, ["z"] = 7, ["name"] = "default:stone"}, {["x"] = 24, ["y"] = 4, ["param1"] = 15, ["z"] = 18, ["name"] = "mesecons_extrawires:vertical_off"}, {["x"] = 24, ["y"] = 4, ["param1"] = 15, ["z"] = 21, ["name"] = "default:stone"}, {["x"] = 24, ["y"] = 4, ["param1"] = 15, ["z"] = 22, ["name"] = "default:stone"}, {["x"] = 24, ["y"] = 4, ["param1"] = 15, ["z"] = 23, ["name"] = "default:stone"}, {["x"] = 24, ["y"] = 4, ["param1"] = 15, ["z"] = 24, ["name"] = "default:stone"}, {["x"] = 24, ["y"] = 4, ["param1"] = 15, ["z"] = 25, ["name"] = "default:stone"}, {["x"] = 24, ["y"] = 4, ["param1"] = 15, ["z"] = 26, ["name"] = "default:stone"}, {["x"] = 24, ["y"] = 4, ["param1"] = 15, ["z"] = 27, ["name"] = "default:stone"}, {["x"] = 24, ["y"] = 4, ["param1"] = 15, ["z"] = 28, ["name"] = "default:stone"}, {["x"] = 24, ["y"] = 4, ["param1"] = 15, ["z"] = 29, ["name"] = "default:stone"}, {["x"] = 24, ["y"] = 4, ["param1"] = 15, ["z"] = 30, ["name"] = "default:stone"}, {["x"] = 24, ["y"] = 4, ["param1"] = 15, ["z"] = 31, ["name"] = "default:stone"}, {["x"] = 24, ["y"] = 4, ["param1"] = 15, ["z"] = 34, ["name"] = "mesecons_extrawires:vertical_off"}, {["x"] = 24, ["y"] = 4, ["param1"] = 15, ["z"] = 45, ["name"] = "default:stone"}, {["x"] = 24, ["y"] = 4, ["param1"] = 15, ["z"] = 46, ["name"] = "default:stone"}, {["x"] = 24, ["y"] = 4, ["param1"] = 15, ["z"] = 47, ["name"] = "default:stone"}, {["x"] = 24, ["y"] = 4, ["param1"] = 15, ["z"] = 48, ["name"] = "default:stone"}, {["x"] = 24, ["y"] = 4, ["param1"] = 15, ["z"] = 49, ["name"] = "default:stone"}, {["x"] = 24, ["y"] = 5, ["param1"] = 15, ["z"] = 2, ["name"] = "default:stone"}, {["x"] = 24, ["y"] = 5, ["param1"] = 15, ["z"] = 3, ["name"] = "default:stone"}, {["x"] = 24, ["y"] = 5, ["param1"] = 15, ["z"] = 4, ["name"] = "default:stone"}, {["x"] = 24, ["y"] = 5, ["param1"] = 15, ["z"] = 5, ["name"] = "default:stone"}, {["x"] = 24, ["y"] = 5, ["param1"] = 15, ["z"] = 6, ["name"] = "default:stone"}, {["x"] = 24, ["y"] = 5, ["param1"] = 15, ["z"] = 7, ["name"] = "default:stone"}, {["x"] = 24, ["y"] = 5, ["param1"] = 15, ["z"] = 8, ["name"] = "default:stone"}, {["x"] = 24, ["y"] = 5, ["param1"] = 15, ["z"] = 18, ["name"] = "mesecons_extrawires:vertical_off"}, {["x"] = 24, ["y"] = 5, ["param1"] = 15, ["z"] = 20, ["name"] = "default:stone"}, {["x"] = 24, ["y"] = 5, ["param1"] = 15, ["z"] = 21, ["name"] = "default:stone"}, {["x"] = 24, ["y"] = 5, ["param1"] = 15, ["z"] = 22, ["name"] = "default:stone"}, {["x"] = 24, ["y"] = 5, ["param1"] = 15, ["z"] = 23, ["name"] = "default:stone"}, {["x"] = 24, ["y"] = 5, ["param1"] = 15, ["z"] = 24, ["name"] = "default:stone"}, {["x"] = 24, ["y"] = 5, ["param1"] = 15, ["z"] = 25, ["name"] = "default:stone"}, {["x"] = 24, ["y"] = 5, ["param1"] = 15, ["z"] = 26, ["name"] = "default:stone"}, {["x"] = 24, ["y"] = 5, ["param1"] = 15, ["z"] = 27, ["name"] = "default:stone"}, {["x"] = 24, ["y"] = 5, ["param1"] = 15, ["z"] = 28, ["name"] = "default:stone"}, {["x"] = 24, ["y"] = 5, ["param1"] = 15, ["z"] = 29, ["name"] = "default:stone"}, {["x"] = 24, ["y"] = 5, ["param1"] = 15, ["z"] = 30, ["name"] = "default:stone"}, {["x"] = 24, ["y"] = 5, ["param1"] = 15, ["z"] = 31, ["name"] = "default:stone"}, {["x"] = 24, ["y"] = 5, ["param1"] = 15, ["z"] = 32, ["name"] = "default:stone"}, {["x"] = 24, ["y"] = 5, ["param1"] = 15, ["z"] = 34, ["name"] = "mesecons_extrawires:vertical_off"}, {["x"] = 24, ["y"] = 5, ["param1"] = 15, ["z"] = 44, ["name"] = "default:stone"}, {["x"] = 24, ["y"] = 5, ["param1"] = 15, ["z"] = 45, ["name"] = "default:stone"}, {["x"] = 24, ["y"] = 5, ["param1"] = 15, ["z"] = 46, ["name"] = "default:stone"}, {["x"] = 24, ["y"] = 5, ["param1"] = 15, ["z"] = 47, ["name"] = "default:stone"}, {["x"] = 24, ["y"] = 5, ["param1"] = 15, ["z"] = 48, ["name"] = "default:stone"}, {["x"] = 24, ["y"] = 5, ["param1"] = 15, ["z"] = 49, ["name"] = "default:stone"}, {["x"] = 24, ["y"] = 5, ["param1"] = 15, ["z"] = 50, ["name"] = "default:stone"}, {["x"] = 24, ["y"] = 6, ["param1"] = 15, ["z"] = 2, ["name"] = "default:stone"}, {["x"] = 24, ["y"] = 6, ["param1"] = 15, ["z"] = 3, ["name"] = "default:stone"}, {["x"] = 24, ["y"] = 6, ["param1"] = 15, ["z"] = 4, ["name"] = "default:stone"}, {["x"] = 24, ["y"] = 6, ["param1"] = 15, ["z"] = 5, ["name"] = "default:stone"}, {["x"] = 24, ["y"] = 6, ["param1"] = 15, ["z"] = 6, ["name"] = "default:stone"}, {["x"] = 24, ["y"] = 6, ["param1"] = 15, ["z"] = 7, ["name"] = "default:stone"}, {["x"] = 24, ["y"] = 6, ["param1"] = 15, ["z"] = 8, ["name"] = "default:stone"}, {["x"] = 24, ["y"] = 6, ["param1"] = 31, ["z"] = 18, ["name"] = "mesecons_extrawires:vertical_off"}, {["x"] = 24, ["y"] = 6, ["param1"] = 15, ["z"] = 20, ["name"] = "default:stone"}, {["x"] = 24, ["y"] = 6, ["param1"] = 15, ["z"] = 21, ["name"] = "default:stone"}, {["x"] = 24, ["y"] = 6, ["param1"] = 15, ["z"] = 22, ["name"] = "default:stone"}, {["x"] = 24, ["y"] = 6, ["param1"] = 15, ["z"] = 23, ["name"] = "default:stone"}, {["x"] = 24, ["y"] = 6, ["param1"] = 15, ["z"] = 24, ["name"] = "default:stone"}, {["x"] = 24, ["y"] = 6, ["param1"] = 15, ["z"] = 25, ["name"] = "default:stone"}, {["x"] = 24, ["y"] = 6, ["param1"] = 15, ["z"] = 26, ["name"] = "default:stone"}, {["x"] = 24, ["y"] = 6, ["param1"] = 15, ["z"] = 27, ["name"] = "default:stone"}, {["x"] = 24, ["y"] = 6, ["param1"] = 15, ["z"] = 28, ["name"] = "default:stone"}, {["x"] = 24, ["y"] = 6, ["param1"] = 15, ["z"] = 29, ["name"] = "default:stone"}, {["x"] = 24, ["y"] = 6, ["param1"] = 15, ["z"] = 30, ["name"] = "default:stone"}, {["x"] = 24, ["y"] = 6, ["param1"] = 15, ["z"] = 31, ["name"] = "default:stone"}, {["x"] = 24, ["y"] = 6, ["param1"] = 15, ["z"] = 32, ["name"] = "default:stone"}, {["x"] = 24, ["y"] = 6, ["param1"] = 31, ["z"] = 34, ["name"] = "mesecons_extrawires:vertical_off"}, {["x"] = 24, ["y"] = 6, ["param1"] = 15, ["z"] = 44, ["name"] = "default:stone"}, {["x"] = 24, ["y"] = 6, ["param1"] = 15, ["z"] = 45, ["name"] = "default:stone"}, {["x"] = 24, ["y"] = 6, ["param1"] = 15, ["z"] = 46, ["name"] = "default:stone"}, {["x"] = 24, ["y"] = 6, ["param1"] = 15, ["z"] = 47, ["name"] = "default:stone"}, {["x"] = 24, ["y"] = 6, ["param1"] = 15, ["z"] = 48, ["name"] = "default:stone"}, {["x"] = 24, ["y"] = 6, ["param1"] = 15, ["z"] = 49, ["name"] = "default:stone"}, {["x"] = 24, ["y"] = 6, ["param1"] = 15, ["z"] = 50, ["name"] = "default:stone"}, {["x"] = 24, ["y"] = 7, ["param1"] = 15, ["z"] = 2, ["name"] = "default:dirt_with_grass"}, {["x"] = 24, ["y"] = 7, ["param1"] = 15, ["z"] = 3, ["name"] = "default:dirt_with_grass"}, {["x"] = 24, ["y"] = 7, ["param1"] = 15, ["z"] = 4, ["name"] = "default:dirt_with_grass"}, {["x"] = 24, ["y"] = 7, ["param1"] = 15, ["z"] = 5, ["name"] = "default:dirt_with_grass"}, {["x"] = 24, ["y"] = 7, ["param1"] = 15, ["z"] = 6, ["name"] = "default:dirt_with_grass"}, {["x"] = 24, ["y"] = 7, ["param1"] = 15, ["z"] = 7, ["name"] = "default:dirt_with_grass"}, {["x"] = 24, ["y"] = 7, ["param1"] = 15, ["z"] = 8, ["name"] = "default:dirt_with_grass"}, {["x"] = 24, ["y"] = 7, ["param1"] = 47, ["z"] = 18, ["name"] = "mesecons_extrawires:vertical_off"}, {["x"] = 24, ["y"] = 7, ["param1"] = 15, ["z"] = 19, ["name"] = "default:stone"}, {["x"] = 24, ["y"] = 7, ["param1"] = 15, ["z"] = 20, ["name"] = "default:stone"}, {["x"] = 24, ["y"] = 7, ["param1"] = 15, ["z"] = 21, ["name"] = "default:stone"}, {["x"] = 24, ["y"] = 7, ["param1"] = 15, ["z"] = 22, ["name"] = "default:stone"}, {["x"] = 24, ["y"] = 7, ["param1"] = 15, ["z"] = 23, ["name"] = "default:stone"}, {["x"] = 24, ["y"] = 7, ["param1"] = 15, ["z"] = 24, ["name"] = "default:stone"}, {["x"] = 24, ["y"] = 7, ["param1"] = 15, ["z"] = 25, ["name"] = "default:stone"}, {["x"] = 24, ["y"] = 7, ["param1"] = 15, ["z"] = 26, ["name"] = "default:stone"}, {["x"] = 24, ["y"] = 7, ["param1"] = 15, ["z"] = 27, ["name"] = "default:stone"}, {["x"] = 24, ["y"] = 7, ["param1"] = 15, ["z"] = 28, ["name"] = "default:stone"}, {["x"] = 24, ["y"] = 7, ["param1"] = 15, ["z"] = 29, ["name"] = "default:stone"}, {["x"] = 24, ["y"] = 7, ["param1"] = 15, ["z"] = 30, ["name"] = "default:stone"}, {["x"] = 24, ["y"] = 7, ["param1"] = 15, ["z"] = 31, ["name"] = "default:stone"}, {["x"] = 24, ["y"] = 7, ["param1"] = 15, ["z"] = 32, ["name"] = "default:stone"}, {["x"] = 24, ["y"] = 7, ["param1"] = 15, ["z"] = 33, ["name"] = "default:stone"}, {["x"] = 24, ["y"] = 7, ["param1"] = 47, ["z"] = 34, ["name"] = "mesecons_extrawires:vertical_off"}, {["x"] = 24, ["y"] = 7, ["param1"] = 15, ["z"] = 44, ["name"] = "default:dirt_with_grass"}, {["x"] = 24, ["y"] = 7, ["param1"] = 15, ["z"] = 45, ["name"] = "default:dirt_with_grass"}, {["x"] = 24, ["y"] = 7, ["param1"] = 15, ["z"] = 46, ["name"] = "default:dirt_with_grass"}, {["x"] = 24, ["y"] = 7, ["param1"] = 15, ["z"] = 47, ["name"] = "default:dirt_with_grass"}, {["x"] = 24, ["y"] = 7, ["param1"] = 15, ["z"] = 48, ["name"] = "default:dirt_with_grass"}, {["x"] = 24, ["y"] = 7, ["param1"] = 15, ["z"] = 49, ["name"] = "default:dirt_with_grass"}, {["x"] = 24, ["y"] = 7, ["param1"] = 15, ["z"] = 50, ["name"] = "default:dirt_with_grass"}, {["x"] = 24, ["y"] = 8, ["param1"] = 63, ["z"] = 18, ["name"] = "mesecons_extrawires:vertical_off"}, {["x"] = 24, ["y"] = 8, ["param1"] = 15, ["z"] = 19, ["name"] = "default:stone"}, {["x"] = 24, ["y"] = 8, ["param1"] = 15, ["z"] = 33, ["name"] = "default:stone"}, {["x"] = 24, ["y"] = 8, ["param1"] = 63, ["z"] = 34, ["name"] = "mesecons_extrawires:vertical_off"}, {["x"] = 24, ["y"] = 9, ["param1"] = 79, ["z"] = 18, ["name"] = "mesecons_extrawires:vertical_top_off"}, {["x"] = 24, ["y"] = 9, ["param1"] = 15, ["z"] = 19, ["name"] = "default:stone"}, {["x"] = 24, ["y"] = 9, ["param1"] = 15, ["z"] = 33, ["name"] = "default:stone"}, {["x"] = 24, ["y"] = 9, ["param1"] = 79, ["z"] = 34, ["name"] = "mesecons_extrawires:vertical_top_off"}, {["x"] = 24, ["y"] = 10, ["param1"] = 15, ["z"] = 19, ["name"] = "default:stone"}, {["x"] = 24, ["y"] = 10, ["param1"] = 15, ["z"] = 33, ["name"] = "default:stone"}, {["x"] = 24, ["y"] = 11, ["param1"] = 15, ["z"] = 19, ["name"] = "default:stone"}, {["x"] = 24, ["y"] = 11, ["param1"] = 15, ["z"] = 33, ["name"] = "default:stone"}, {["x"] = 24, ["y"] = 12, ["param1"] = 15, ["z"] = 20, ["name"] = "default:stone"}, {["x"] = 24, ["y"] = 12, ["z"] = 32, ["name"] = "default:stone"}, {["x"] = 24, ["y"] = 13, ["param1"] = 15, ["z"] = 20, ["name"] = "default:stone"}, {["x"] = 24, ["y"] = 13, ["param1"] = 15, ["z"] = 32, ["name"] = "default:stone"}, {["x"] = 24, ["y"] = 14, ["param1"] = 15, ["z"] = 21, ["name"] = "default:stone"}, {["x"] = 24, ["y"] = 14, ["param1"] = 15, ["z"] = 31, ["name"] = "default:stone"}, {["x"] = 24, ["y"] = 15, ["param1"] = 15, ["z"] = 22, ["name"] = "default:stone"}, {["x"] = 24, ["y"] = 15, ["param1"] = 15, ["z"] = 23, ["name"] = "default:stone"}, {["x"] = 24, ["y"] = 15, ["param1"] = 15, ["z"] = 29, ["name"] = "default:stone"}, {["x"] = 24, ["y"] = 15, ["param1"] = 15, ["z"] = 30, ["name"] = "default:stone"}, {["x"] = 24, ["y"] = 16, ["param1"] = 15, ["z"] = 24, ["name"] = "default:stone"}, {["x"] = 24, ["y"] = 16, ["param1"] = 15, ["z"] = 25, ["name"] = "default:stone"}, {["x"] = 24, ["y"] = 16, ["param1"] = 15, ["z"] = 26, ["name"] = "default:stone"}, {["x"] = 24, ["y"] = 16, ["param1"] = 15, ["z"] = 27, ["name"] = "default:stone"}, {["x"] = 24, ["y"] = 16, ["param1"] = 15, ["z"] = 28, ["name"] = "default:stone"}, {["x"] = 25, ["y"] = 2, ["param1"] = 15, ["z"] = 23, ["name"] = "default:stone"}, {["x"] = 25, ["y"] = 2, ["param1"] = 15, ["z"] = 24, ["name"] = "default:stone"}, {["x"] = 25, ["y"] = 2, ["param1"] = 15, ["z"] = 25, ["name"] = "default:stone"}, {["x"] = 25, ["y"] = 2, ["param1"] = 15, ["z"] = 26, ["name"] = "default:stone"}, {["x"] = 25, ["y"] = 2, ["param1"] = 15, ["z"] = 27, ["name"] = "default:stone"}, {["x"] = 25, ["y"] = 2, ["param1"] = 15, ["z"] = 28, ["name"] = "default:stone"}, {["x"] = 25, ["y"] = 2, ["param1"] = 15, ["z"] = 29, ["name"] = "default:stone"}, {["x"] = 25, ["y"] = 3, ["param1"] = 15, ["z"] = 3, ["name"] = "default:stone"}, {["x"] = 25, ["y"] = 3, ["param1"] = 15, ["z"] = 4, ["name"] = "default:stone"}, {["x"] = 25, ["y"] = 3, ["param1"] = 15, ["z"] = 5, ["name"] = "default:stone"}, {["x"] = 25, ["y"] = 3, ["param1"] = 15, ["z"] = 6, ["name"] = "default:stone"}, {["x"] = 25, ["y"] = 3, ["param1"] = 15, ["z"] = 7, ["name"] = "default:stone"}, {["x"] = 25, ["y"] = 3, ["param1"] = 15, ["z"] = 18, ["name"] = "mesecons:wire_10100000_off"}, {["x"] = 25, ["y"] = 3, ["param1"] = 15, ["z"] = 21, ["name"] = "default:stone"}, {["x"] = 25, ["y"] = 3, ["param1"] = 15, ["z"] = 22, ["name"] = "default:stone"}, {["x"] = 25, ["y"] = 3, ["param1"] = 15, ["z"] = 23, ["name"] = "default:stone"}, {["x"] = 25, ["y"] = 3, ["param1"] = 15, ["z"] = 24, ["name"] = "default:stone"}, {["x"] = 25, ["y"] = 3, ["param1"] = 15, ["z"] = 25, ["name"] = "default:stone"}, {["x"] = 25, ["y"] = 3, ["param1"] = 15, ["z"] = 26, ["name"] = "default:stone"}, {["x"] = 25, ["y"] = 3, ["param1"] = 15, ["z"] = 27, ["name"] = "default:stone"}, {["x"] = 25, ["y"] = 3, ["param1"] = 15, ["z"] = 28, ["name"] = "default:stone"}, {["x"] = 25, ["y"] = 3, ["param1"] = 15, ["z"] = 29, ["name"] = "default:stone"}, {["x"] = 25, ["y"] = 3, ["param1"] = 15, ["z"] = 30, ["name"] = "default:stone"}, {["x"] = 25, ["y"] = 3, ["param1"] = 15, ["z"] = 31, ["name"] = "default:stone"}, {["x"] = 25, ["y"] = 3, ["param1"] = 15, ["z"] = 34, ["name"] = "mesecons:wire_10100000_off"}, {["x"] = 25, ["y"] = 3, ["param1"] = 15, ["z"] = 45, ["name"] = "default:stone"}, {["x"] = 25, ["y"] = 3, ["param1"] = 15, ["z"] = 46, ["name"] = "default:stone"}, {["x"] = 25, ["y"] = 3, ["param1"] = 15, ["z"] = 47, ["name"] = "default:stone"}, {["x"] = 25, ["y"] = 3, ["param1"] = 15, ["z"] = 48, ["name"] = "default:stone"}, {["x"] = 25, ["y"] = 3, ["param1"] = 15, ["z"] = 49, ["name"] = "default:stone"}, {["x"] = 25, ["y"] = 4, ["param1"] = 15, ["z"] = 2, ["name"] = "default:stone"}, {["x"] = 25, ["y"] = 4, ["param1"] = 15, ["z"] = 3, ["name"] = "default:stone"}, {["x"] = 25, ["y"] = 4, ["param1"] = 15, ["z"] = 4, ["name"] = "default:stone"}, {["x"] = 25, ["y"] = 4, ["param1"] = 15, ["z"] = 5, ["name"] = "default:stone"}, {["x"] = 25, ["y"] = 4, ["param1"] = 15, ["z"] = 6, ["name"] = "default:stone"}, {["x"] = 25, ["y"] = 4, ["param1"] = 15, ["z"] = 7, ["name"] = "default:stone"}, {["x"] = 25, ["y"] = 4, ["param1"] = 15, ["z"] = 8, ["name"] = "default:stone"}, {["x"] = 25, ["y"] = 4, ["param1"] = 15, ["z"] = 20, ["name"] = "default:stone"}, {["x"] = 25, ["y"] = 4, ["param1"] = 15, ["z"] = 21, ["name"] = "default:stone"}, {["x"] = 25, ["y"] = 4, ["param1"] = 15, ["z"] = 22, ["name"] = "default:stone"}, {["x"] = 25, ["y"] = 4, ["param1"] = 15, ["z"] = 23, ["name"] = "default:stone"}, {["x"] = 25, ["y"] = 4, ["param1"] = 15, ["z"] = 24, ["name"] = "default:stone"}, {["x"] = 25, ["y"] = 4, ["param1"] = 15, ["z"] = 25, ["name"] = "default:stone"}, {["x"] = 25, ["y"] = 4, ["param1"] = 15, ["z"] = 26, ["name"] = "default:stone"}, {["x"] = 25, ["y"] = 4, ["param1"] = 15, ["z"] = 27, ["name"] = "default:stone"}, {["x"] = 25, ["y"] = 4, ["param1"] = 15, ["z"] = 28, ["name"] = "default:stone"}, {["x"] = 25, ["y"] = 4, ["param1"] = 15, ["z"] = 29, ["name"] = "default:stone"}, {["x"] = 25, ["y"] = 4, ["param1"] = 15, ["z"] = 30, ["name"] = "default:stone"}, {["x"] = 25, ["y"] = 4, ["param1"] = 15, ["z"] = 31, ["name"] = "default:stone"}, {["x"] = 25, ["y"] = 4, ["param1"] = 15, ["z"] = 32, ["name"] = "default:stone"}, {["x"] = 25, ["y"] = 4, ["param1"] = 15, ["z"] = 44, ["name"] = "default:stone"}, {["x"] = 25, ["y"] = 4, ["param1"] = 15, ["z"] = 45, ["name"] = "default:stone"}, {["x"] = 25, ["y"] = 4, ["param1"] = 15, ["z"] = 46, ["name"] = "default:stone"}, {["x"] = 25, ["y"] = 4, ["param1"] = 15, ["z"] = 47, ["name"] = "default:stone"}, {["x"] = 25, ["y"] = 4, ["param1"] = 15, ["z"] = 48, ["name"] = "default:stone"}, {["x"] = 25, ["y"] = 4, ["param1"] = 15, ["z"] = 49, ["name"] = "default:stone"}, {["x"] = 25, ["y"] = 4, ["param1"] = 15, ["z"] = 50, ["name"] = "default:stone"}, {["x"] = 25, ["y"] = 5, ["param1"] = 15, ["z"] = 1, ["name"] = "default:stone"}, {["x"] = 25, ["y"] = 5, ["param1"] = 15, ["z"] = 2, ["name"] = "default:stone"}, {["x"] = 25, ["y"] = 5, ["param1"] = 15, ["z"] = 3, ["name"] = "default:stone"}, {["x"] = 25, ["y"] = 5, ["param1"] = 15, ["z"] = 4, ["name"] = "default:stone"}, {["x"] = 25, ["y"] = 5, ["param1"] = 15, ["z"] = 5, ["name"] = "default:stone"}, {["x"] = 25, ["y"] = 5, ["param1"] = 15, ["z"] = 6, ["name"] = "default:stone"}, {["x"] = 25, ["y"] = 5, ["param1"] = 15, ["z"] = 7, ["name"] = "default:stone"}, {["x"] = 25, ["y"] = 5, ["param1"] = 15, ["z"] = 8, ["name"] = "default:stone"}, {["x"] = 25, ["y"] = 5, ["param1"] = 15, ["z"] = 9, ["name"] = "default:stone"}, {["x"] = 25, ["y"] = 5, ["param1"] = 15, ["z"] = 20, ["name"] = "default:stone"}, {["x"] = 25, ["y"] = 5, ["param1"] = 15, ["z"] = 21, ["name"] = "default:stone"}, {["x"] = 25, ["y"] = 5, ["param1"] = 15, ["z"] = 22, ["name"] = "default:stone"}, {["x"] = 25, ["y"] = 5, ["param1"] = 15, ["z"] = 23, ["name"] = "default:stone"}, {["x"] = 25, ["y"] = 5, ["param1"] = 15, ["z"] = 24, ["name"] = "default:stone"}, {["x"] = 25, ["y"] = 5, ["param1"] = 15, ["z"] = 25, ["name"] = "default:stone"}, {["x"] = 25, ["y"] = 5, ["param1"] = 15, ["z"] = 26, ["name"] = "default:stone"}, {["x"] = 25, ["y"] = 5, ["param1"] = 15, ["z"] = 27, ["name"] = "default:stone"}, {["x"] = 25, ["y"] = 5, ["param1"] = 15, ["z"] = 28, ["name"] = "default:stone"}, {["x"] = 25, ["y"] = 5, ["param1"] = 15, ["z"] = 29, ["name"] = "default:stone"}, {["x"] = 25, ["y"] = 5, ["param1"] = 15, ["z"] = 30, ["name"] = "default:stone"}, {["x"] = 25, ["y"] = 5, ["param1"] = 15, ["z"] = 31, ["name"] = "default:stone"}, {["x"] = 25, ["y"] = 5, ["param1"] = 15, ["z"] = 32, ["name"] = "default:stone"}, {["x"] = 25, ["y"] = 5, ["param1"] = 15, ["z"] = 43, ["name"] = "default:stone"}, {["x"] = 25, ["y"] = 5, ["param1"] = 15, ["z"] = 44, ["name"] = "default:stone"}, {["x"] = 25, ["y"] = 5, ["param1"] = 15, ["z"] = 45, ["name"] = "default:stone"}, {["x"] = 25, ["y"] = 5, ["param1"] = 15, ["z"] = 46, ["name"] = "default:stone"}, {["x"] = 25, ["y"] = 5, ["param1"] = 15, ["z"] = 47, ["name"] = "default:stone"}, {["x"] = 25, ["y"] = 5, ["param1"] = 15, ["z"] = 48, ["name"] = "default:stone"}, {["x"] = 25, ["y"] = 5, ["param1"] = 15, ["z"] = 49, ["name"] = "default:stone"}, {["x"] = 25, ["y"] = 5, ["param1"] = 15, ["z"] = 50, ["name"] = "default:stone"}, {["x"] = 25, ["y"] = 5, ["param1"] = 15, ["z"] = 51, ["name"] = "default:stone"}, {["x"] = 25, ["y"] = 6, ["param1"] = 15, ["z"] = 1, ["name"] = "default:stone"}, {["x"] = 25, ["y"] = 6, ["param1"] = 15, ["z"] = 2, ["name"] = "default:stone"}, {["x"] = 25, ["y"] = 6, ["param1"] = 15, ["z"] = 3, ["name"] = "default:stone"}, {["x"] = 25, ["y"] = 6, ["param1"] = 15, ["z"] = 4, ["name"] = "default:stone"}, {["x"] = 25, ["y"] = 6, ["param1"] = 15, ["z"] = 5, ["name"] = "default:stone"}, {["x"] = 25, ["y"] = 6, ["param1"] = 15, ["z"] = 6, ["name"] = "default:stone"}, {["x"] = 25, ["y"] = 6, ["param1"] = 15, ["z"] = 7, ["name"] = "default:stone"}, {["x"] = 25, ["y"] = 6, ["param1"] = 15, ["z"] = 8, ["name"] = "default:stone"}, {["x"] = 25, ["y"] = 6, ["param1"] = 15, ["z"] = 9, ["name"] = "default:stone"}, {["x"] = 25, ["y"] = 6, ["param1"] = 15, ["z"] = 19, ["name"] = "default:stone"}, {["x"] = 25, ["y"] = 6, ["param1"] = 15, ["z"] = 20, ["name"] = "default:stone"}, {["x"] = 25, ["y"] = 6, ["param1"] = 15, ["z"] = 21, ["name"] = "default:stone"}, {["x"] = 25, ["y"] = 6, ["param1"] = 15, ["z"] = 22, ["name"] = "default:stone"}, {["x"] = 25, ["y"] = 6, ["param1"] = 15, ["z"] = 23, ["name"] = "default:stone"}, {["x"] = 25, ["y"] = 6, ["param1"] = 15, ["z"] = 24, ["name"] = "default:stone"}, {["x"] = 25, ["y"] = 6, ["param1"] = 15, ["z"] = 25, ["name"] = "default:stone"}, {["x"] = 25, ["y"] = 6, ["param1"] = 15, ["z"] = 26, ["name"] = "default:stone"}, {["x"] = 25, ["y"] = 6, ["param1"] = 15, ["z"] = 27, ["name"] = "default:stone"}, {["x"] = 25, ["y"] = 6, ["param1"] = 15, ["z"] = 28, ["name"] = "default:stone"}, {["x"] = 25, ["y"] = 6, ["param1"] = 15, ["z"] = 29, ["name"] = "default:stone"}, {["x"] = 25, ["y"] = 6, ["param1"] = 15, ["z"] = 30, ["name"] = "default:stone"}, {["x"] = 25, ["y"] = 6, ["param1"] = 15, ["z"] = 31, ["name"] = "default:stone"}, {["x"] = 25, ["y"] = 6, ["param1"] = 15, ["z"] = 32, ["name"] = "default:stone"}, {["x"] = 25, ["y"] = 6, ["param1"] = 15, ["z"] = 33, ["name"] = "default:stone"}, {["x"] = 25, ["y"] = 6, ["param1"] = 15, ["z"] = 43, ["name"] = "default:stone"}, {["x"] = 25, ["y"] = 6, ["param1"] = 15, ["z"] = 44, ["name"] = "default:stone"}, {["x"] = 25, ["y"] = 6, ["param1"] = 15, ["z"] = 45, ["name"] = "default:stone"}, {["x"] = 25, ["y"] = 6, ["param1"] = 15, ["z"] = 46, ["name"] = "default:stone"}, {["x"] = 25, ["y"] = 6, ["param1"] = 15, ["z"] = 47, ["name"] = "default:stone"}, {["x"] = 25, ["y"] = 6, ["param1"] = 15, ["z"] = 48, ["name"] = "default:stone"}, {["x"] = 25, ["y"] = 6, ["param1"] = 15, ["z"] = 49, ["name"] = "default:stone"}, {["x"] = 25, ["y"] = 6, ["param1"] = 15, ["z"] = 50, ["name"] = "default:stone"}, {["x"] = 25, ["y"] = 6, ["param1"] = 15, ["z"] = 51, ["name"] = "default:stone"}, {["x"] = 25, ["y"] = 7, ["param1"] = 15, ["z"] = 1, ["name"] = "default:dirt_with_grass"}, {["x"] = 25, ["y"] = 7, ["param1"] = 15, ["z"] = 2, ["name"] = "default:dirt_with_grass"}, {["x"] = 25, ["y"] = 7, ["param1"] = 15, ["z"] = 3, ["name"] = "default:dirt_with_grass"}, {["x"] = 25, ["y"] = 7, ["param1"] = 15, ["z"] = 4, ["name"] = "default:dirt_with_grass"}, {["x"] = 25, ["y"] = 7, ["param1"] = 15, ["z"] = 5, ["name"] = "default:dirt_with_grass"}, {["x"] = 25, ["y"] = 7, ["param1"] = 15, ["z"] = 6, ["name"] = "default:dirt_with_grass"}, {["x"] = 25, ["y"] = 7, ["param1"] = 15, ["z"] = 7, ["name"] = "default:dirt_with_grass"}, {["x"] = 25, ["y"] = 7, ["param1"] = 15, ["z"] = 8, ["name"] = "default:dirt_with_grass"}, {["x"] = 25, ["y"] = 7, ["param1"] = 15, ["z"] = 9, ["name"] = "default:dirt_with_grass"}, {["x"] = 25, ["y"] = 7, ["param1"] = 15, ["z"] = 19, ["name"] = "default:stone"}, {["x"] = 25, ["y"] = 7, ["param1"] = 15, ["z"] = 20, ["name"] = "default:stone"}, {["x"] = 25, ["y"] = 7, ["param1"] = 15, ["z"] = 21, ["name"] = "default:stone"}, {["x"] = 25, ["y"] = 7, ["param1"] = 15, ["z"] = 22, ["name"] = "default:stone"}, {["x"] = 25, ["y"] = 7, ["param1"] = 15, ["z"] = 23, ["name"] = "default:stone"}, {["x"] = 25, ["y"] = 7, ["param1"] = 15, ["z"] = 24, ["name"] = "default:stone"}, {["x"] = 25, ["y"] = 7, ["param1"] = 15, ["z"] = 25, ["name"] = "default:stone"}, {["x"] = 25, ["y"] = 7, ["param1"] = 15, ["z"] = 26, ["name"] = "default:stone"}, {["x"] = 25, ["y"] = 7, ["param1"] = 15, ["z"] = 27, ["name"] = "default:stone"}, {["x"] = 25, ["y"] = 7, ["param1"] = 15, ["z"] = 28, ["name"] = "default:stone"}, {["x"] = 25, ["y"] = 7, ["param1"] = 15, ["z"] = 29, ["name"] = "default:stone"}, {["x"] = 25, ["y"] = 7, ["param1"] = 15, ["z"] = 30, ["name"] = "default:stone"}, {["x"] = 25, ["y"] = 7, ["param1"] = 15, ["z"] = 31, ["name"] = "default:stone"}, {["x"] = 25, ["y"] = 7, ["param1"] = 15, ["z"] = 32, ["name"] = "default:stone"}, {["x"] = 25, ["y"] = 7, ["param1"] = 15, ["z"] = 33, ["name"] = "default:stone"}, {["x"] = 25, ["y"] = 7, ["param1"] = 15, ["z"] = 43, ["name"] = "default:dirt_with_grass"}, {["x"] = 25, ["y"] = 7, ["param1"] = 15, ["z"] = 44, ["name"] = "default:dirt_with_grass"}, {["x"] = 25, ["y"] = 7, ["param1"] = 15, ["z"] = 45, ["name"] = "default:dirt_with_grass"}, {["x"] = 25, ["y"] = 7, ["param1"] = 15, ["z"] = 46, ["name"] = "default:dirt_with_grass"}, {["x"] = 25, ["y"] = 7, ["param1"] = 15, ["z"] = 47, ["name"] = "default:dirt_with_grass"}, {["x"] = 25, ["y"] = 7, ["param1"] = 15, ["z"] = 48, ["name"] = "default:dirt_with_grass"}, {["x"] = 25, ["y"] = 7, ["param1"] = 15, ["z"] = 49, ["name"] = "default:dirt_with_grass"}, {["x"] = 25, ["y"] = 7, ["param1"] = 15, ["z"] = 50, ["name"] = "default:dirt_with_grass"}, {["x"] = 25, ["y"] = 7, ["param1"] = 15, ["z"] = 51, ["name"] = "default:dirt_with_grass"}, {["x"] = 25, ["y"] = 8, ["param1"] = 15, ["z"] = 19, ["name"] = "default:stone"}, {["x"] = 25, ["y"] = 8, ["param1"] = 15, ["z"] = 33, ["name"] = "default:stone"}, {["x"] = 25, ["y"] = 9, ["param1"] = 95, ["z"] = 18, ["name"] = "mesecons:wire_10101000_off"}, {["x"] = 25, ["y"] = 9, ["z"] = 19, ["name"] = "default:stone"}, {["x"] = 25, ["y"] = 9, ["z"] = 33, ["name"] = "default:stone"}, {["x"] = 25, ["y"] = 9, ["param1"] = 95, ["z"] = 34, ["name"] = "mesecons:wire_10101000_off"}, {["x"] = 25, ["y"] = 10, ["param1"] = 15, ["z"] = 19, ["name"] = "default:stone"}, {["x"] = 25, ["y"] = 10, ["z"] = 33, ["name"] = "default:stone"}, {["x"] = 25, ["y"] = 11, ["param1"] = 15, ["z"] = 19, ["name"] = "default:stone"}, {["x"] = 25, ["y"] = 11, ["param1"] = 15, ["z"] = 33, ["name"] = "default:stone"}, {["x"] = 25, ["y"] = 12, ["param1"] = 15, ["z"] = 19, ["name"] = "default:stone"}, {["x"] = 25, ["y"] = 12, ["param1"] = 15, ["z"] = 33, ["name"] = "default:stone"}, {["x"] = 25, ["y"] = 13, ["param1"] = 15, ["z"] = 20, ["name"] = "default:stone"}, {["x"] = 25, ["y"] = 13, ["z"] = 32, ["name"] = "default:stone"}, {["x"] = 25, ["y"] = 14, ["param1"] = 15, ["z"] = 20, ["name"] = "default:stone"}, {["x"] = 25, ["y"] = 14, ["param1"] = 15, ["z"] = 32, ["name"] = "default:stone"}, {["x"] = 25, ["y"] = 15, ["param1"] = 15, ["z"] = 21, ["name"] = "default:stone"}, {["x"] = 25, ["y"] = 15, ["param1"] = 15, ["z"] = 22, ["name"] = "default:stone"}, {["x"] = 25, ["y"] = 15, ["param1"] = 15, ["z"] = 30, ["name"] = "default:stone"}, {["x"] = 25, ["y"] = 15, ["param1"] = 15, ["z"] = 31, ["name"] = "default:stone"}, {["x"] = 25, ["y"] = 16, ["param1"] = 15, ["z"] = 23, ["name"] = "default:stone"}, {["x"] = 25, ["y"] = 16, ["param1"] = 15, ["z"] = 24, ["name"] = "default:stone"}, {["x"] = 25, ["y"] = 16, ["param1"] = 15, ["z"] = 25, ["name"] = "default:stone"}, {["x"] = 25, ["y"] = 16, ["param1"] = 15, ["z"] = 26, ["name"] = "default:stone"}, {["x"] = 25, ["y"] = 16, ["param1"] = 15, ["z"] = 27, ["name"] = "default:stone"}, {["x"] = 25, ["y"] = 16, ["param1"] = 15, ["z"] = 28, ["name"] = "default:stone"}, {["x"] = 25, ["y"] = 16, ["param1"] = 15, ["z"] = 29, ["name"] = "default:stone"}, {["x"] = 26, ["y"] = 1, ["param1"] = 15, ["z"] = 24, ["name"] = "default:stone"}, {["x"] = 26, ["y"] = 1, ["param1"] = 15, ["z"] = 25, ["name"] = "default:stone"}, {["x"] = 26, ["y"] = 1, ["param1"] = 15, ["z"] = 26, ["name"] = "default:stone"}, {["x"] = 26, ["y"] = 1, ["param1"] = 15, ["z"] = 27, ["name"] = "default:stone"}, {["x"] = 26, ["y"] = 1, ["param1"] = 15, ["z"] = 28, ["name"] = "default:stone"}, {["x"] = 26, ["y"] = 2, ["param1"] = 15, ["z"] = 4, ["name"] = "default:stone"}, {["x"] = 26, ["y"] = 2, ["param1"] = 15, ["z"] = 5, ["name"] = "default:stone"}, {["x"] = 26, ["y"] = 2, ["param1"] = 15, ["z"] = 6, ["name"] = "default:stone"}, {["x"] = 26, ["y"] = 2, ["param1"] = 15, ["z"] = 22, ["name"] = "default:stone"}, {["x"] = 26, ["y"] = 2, ["param1"] = 15, ["z"] = 23, ["name"] = "default:stone"}, {["x"] = 26, ["y"] = 2, ["param1"] = 15, ["z"] = 24, ["name"] = "default:stone"}, {["x"] = 26, ["y"] = 2, ["param1"] = 15, ["z"] = 25, ["name"] = "default:stone"}, {["x"] = 26, ["y"] = 2, ["param1"] = 15, ["z"] = 26, ["name"] = "default:stone"}, {["x"] = 26, ["y"] = 2, ["param1"] = 15, ["z"] = 27, ["name"] = "default:stone"}, {["x"] = 26, ["y"] = 2, ["param1"] = 15, ["z"] = 28, ["name"] = "default:stone"}, {["x"] = 26, ["y"] = 2, ["param1"] = 15, ["z"] = 29, ["name"] = "default:stone"}, {["x"] = 26, ["y"] = 2, ["param1"] = 15, ["z"] = 30, ["name"] = "default:stone"}, {["x"] = 26, ["y"] = 2, ["param1"] = 15, ["z"] = 46, ["name"] = "default:stone"}, {["x"] = 26, ["y"] = 2, ["param1"] = 15, ["z"] = 47, ["name"] = "default:stone"}, {["x"] = 26, ["y"] = 2, ["param1"] = 15, ["z"] = 48, ["name"] = "default:stone"}, {["x"] = 26, ["y"] = 3, ["param1"] = 15, ["z"] = 2, ["name"] = "default:stone"}, {["x"] = 26, ["y"] = 3, ["param1"] = 15, ["z"] = 3, ["name"] = "default:stone"}, {["x"] = 26, ["y"] = 3, ["param1"] = 15, ["z"] = 4, ["name"] = "default:stone"}, {["x"] = 26, ["y"] = 3, ["param1"] = 15, ["z"] = 5, ["name"] = "default:stone"}, {["x"] = 26, ["y"] = 3, ["param1"] = 15, ["z"] = 6, ["name"] = "default:stone"}, {["x"] = 26, ["y"] = 3, ["param1"] = 15, ["z"] = 7, ["name"] = "default:stone"}, {["x"] = 26, ["y"] = 3, ["param1"] = 15, ["z"] = 8, ["name"] = "default:stone"}, {["x"] = 26, ["y"] = 3, ["param1"] = 14, ["z"] = 18, ["name"] = "mesecons:wire_10100000_off"}, {["x"] = 26, ["y"] = 3, ["param1"] = 15, ["z"] = 21, ["name"] = "default:stone"}, {["x"] = 26, ["y"] = 3, ["param1"] = 15, ["z"] = 22, ["name"] = "default:stone"}, {["x"] = 26, ["y"] = 3, ["param1"] = 15, ["z"] = 23, ["name"] = "default:stone"}, {["x"] = 26, ["y"] = 3, ["param1"] = 15, ["z"] = 24, ["name"] = "default:stone"}, {["x"] = 26, ["y"] = 3, ["param1"] = 15, ["z"] = 25, ["name"] = "default:stone"}, {["x"] = 26, ["y"] = 3, ["param1"] = 15, ["z"] = 26, ["name"] = "default:stone"}, {["x"] = 26, ["y"] = 3, ["param1"] = 15, ["z"] = 27, ["name"] = "default:stone"}, {["x"] = 26, ["y"] = 3, ["param1"] = 15, ["z"] = 28, ["name"] = "default:stone"}, {["x"] = 26, ["y"] = 3, ["param1"] = 15, ["z"] = 29, ["name"] = "default:stone"},